Workbook

Sheet ACCESS
C3: ACCESSES TO DIFFERENT USERS
C4: ADMIN | D4: ESTABLISHMENT | E4: EMPLOYER | F4: EMPLOYEE | G4: AUDITOR
C5: (PROGRAMMING &EVERY MODIFICATION ) | D5: (FOR REGISTRATION LOG IN DETAILS) | E5: (ENTRIES UPLOAD) | F5: (PARTICULAR EMPLOYEE ONLY) | G5: (FINAL REGISTERS VIEW,PENDING& APRROVAL)
E6: Database sheet upload | F6: EMPLOYMENT CARDS
E7: Attendance sheet upload | F7: SERVICE CERTIFICATE
E8: BANK TRANSFER,EPF,ESI,PT Upload | F8: LEAVE REGISTER
F9: WAGE SLIPS
F10: PAYSLIP
F12: CHECK & SIGN

Sheet Workmen Reg
A1: FORM - XIII REGISTER OF WORKMEN EMPLOYED BY CONTRACTOR
A2: (Vide rule 75 of Contract labour(Regulation and Abolition) Central/A.P.{T.S.} Rules 1971)
A3: Name and address of Contractor: | F3: =Master!F5 -> GROTECH LANDSCAPE DEVELOPERS PVT. LTD.
F4: =Master!F6 -> 290/E, Khanapur Village, Gandipet Mandal, Ranga Reddy, Hyderabad-500075 T.S. | M4: =Master!AK10 -> Name and address of the Principle Employer | N4: =Master!AN10 -> INDIAN SCHOOL OF BUSINESS
A5: Nature and location of work: | F5: =Master!F8 -> GARDENING SERVICES&ISB HYDERABAD | N5: =Master!AN11 -> Opp.Infosys Limited,Gachibowli,Hyderabad
A8: Serial No. | B8: Name and surname of Workman | C8: Date of Birth | D8: Sex | E8: Father's /Husband Name | F8: Nature of Employment/ Designation | G8: Permanent Address-1 (H.No.&Street Name) | H8: Permanent Address-2 (Village Name) | I8: Permanent Address-3 (Mandal&District Name) | J8: Local Address-1 (H.No.&Street Name) | K8: Local Address-2 (Village Name) | L8: Local Address-3 (Mandal&District Name) | M8: Date of Commencement of Employment | N8: Signature or thumb impression of Workman | O8: Date of termination of Employment | P8: Reasons for termination | Q8: Remarks
A10: 1 | B10: 2 | C10: 3 | E10: 4 | F10: 5 | G10: 6 | J10: 7 | M10: 8 | N10: 9 | O10: 10 | P10: 11 | Q10: 12
A11: =[1]Master!A16 -> 1 | B11: VIKAS SHARMA | C11: 32739 | D11: Male | E11: Nandkishor sharma | F11: Horticulture Manager | G11: House No. A-168, Street no. 07, Near power house, | H11: Meet Nagar shahadra, | I11: North East, Delhi - 110094 | J11: Gachibowli Village | K11: Hyderabad | L11: Telangana State | M11: 43850 | O11: 31st May 2020 | P11: Resignation
A12: =[1]Master!A17 -> 2 | B12: ARJUN | C12: 31413 | D12: Male | E12: kallu | F12: Supervisor | G12: Village - Dharai | H12: Amethi | I12: Uttar pradesh - 229127 | J12: Gachibowli Village | K12: Hyderabad | L12: Telangana State | M12: 43850 | O12: 31st May 2020 | P12: Resignation
A13: =[1]Master!A18 -> 3 | B13: GAJAN SINGH | C13: 29587 | D13: Male | E13: Chandrapal singh | F13: Supervisor | G13: Village - Uncha gaon, Pikhani, | H13: Bulandshahr, | I13: Uttar pradesh - 202398 | J13: Gachibowli Village | K13: Hyderabad | L13: Telangana State | M13: 43850
A14: =[1]Master!A19 -> 4 | B14: GUDALA RUSHESHWAR SWAMY | C14: 31345 | D14: Male | E14: GUDALA KRISHANA MURTHY | F14: Supervisor | G14: House no. - 8-153 Kottapeta | H14: Gummaluru, west godavari | I14: Andhra pradesh - 534267 | J14: Gachibowli Village | K14: Hyderabad | L14: Telangana State | M14: 43850
A15: =[1]Master!A20 -> 5 | B15: GOLLA KRISHNAIAH | C15: 28/7/1984 | D15: Male | E15: G BHIMANNA | F15: Organic Waste | G15: House No. 11-106 krishna nagar, Atmakur mandal | H15: Amarchinta, Amerchinta, Mahbubnagar | I15: Andhra pradesh - 509130 | J15: Gachibowli Village | K15: Hyderabad | L15: Telangana State | M15: 43850 | O15: 21-01-2020 | P15: Resignation
A16: =[1]Master!A21 -> 6 | B16: KASALA NARSIMLU | C16: 21919 | D16: Male | E16: KASALA POCHAIAH | F16: Semi Skilled Gardner | G16: =[1]Master!F20 -> Semi Skilled Gardner | H16: Mwdharam,Medhak | I16: =[1]Master!H20 -> Mwdharam,Medhak | J16: Gachibowli Village | K16: Hyderabad | L16: Telangana State | M16: 43850
A17: =[1]Master!A22 -> 7 | B17: PITANI SATHYA NARAYANA | C17: 24473 | D17: Male | E17: P SURYANARAYANA | F17: Semi Skilled Gardner | G17: =[1]Master!F22 -> Semi Skilled Gardner | H17: Near church,serilingampally | I17: =[1]Master!H22 -> Near church,serilingampally | J17: Gachibowli Village | K17: Hyderabad | L17: Telangana State | M17: 43850
A18: =[1]Master!A23 -> 8 | B18: SANGOLLA ASHOK | C18: 21/6/1988 | D18: Male | E18: SANGOLLA ESWARAIAH | F18: Semi Skilled Gardner | G18: =[1]Master!F23 -> Semi Skilled Gardner | H18: Patancheru,Sulthanpur | I18: =[1]Master!H23 -> Patancheru,Sulthanpur | J18: Gachibowli Village | K18: Hyderabad | L18: Telangana State | M18: 43850
A19: =[1]Master!A24 -> 9 | B19: ASHOK LINGURAM GAIKWAD | C19: 29832 | D19: Male | E19: M LINGRAM | F19: Semi Skilled Gardner | G19: =[1]Master!F24 -> Semi Skilled Gardner | H19: Post-sawargaon,Mukhed,Nanded, | I19: =[1]Master!H24 -> Post-sawargaon,Mukhed,Nanded, | J19: Gachibowli Village | K19: Hyderabad | L19: Telangana State | M19: 43850
A20: =[1]Master!A25 -> 10 | B20: MADHUKAR KAMTAM | C20: 26665 | D20: Male | E20: KAMTAM KISHAN | F20: Semi Skilled Gardner | G20: =[1]Master!F25 -> Semi Skilled Gardner | H20: opp Hanuman temple | I20: =[1]Master!H25 -> opp Hanuman temple | J20: Gachibowli Village | K20: Hyderabad | L20: Telangana State | M20: 43850
A21: =[1]Master!A26 -> 11 | B21: BONIGA MARIYA KUMAR | C21: 24838 | D21: Male | E21: BONIGA PRASAD RAO | F21: Semi Skilled Gardner | G21: =[1]Master!F26 -> Semi Skilled Gardner | H21: Bapu nagar,Lingampally | I21: =[1]Master!H26 -> Bapu nagar,Lingampally | J21: Gachibowli Village | K21: Hyderabad | L21: Telangana State | M21: 43850 | O21: 31-01-2020 | P21: Resignation
A22: =[1]Master!A27 -> 12 | B22: Ningolla Raju | C22: 21/5/1975 | D22: Male | E22: ningolla pochaiah | F22: Semi Skilled Gardner | G22: =[1]Master!F27 -> Semi Skilled Gardner | H22: patancherusultanpur,medhak | I22: =[1]Master!H27 -> patancherusultanpur,medhak | J22: Gachibowli Village | K22: Hyderabad | L22: Telangana State | M22: 43850
A23: =[1]Master!A28 -> 13 | B23: Nagani pochaiah | C23: 24108 | D23: Male | E23: Nagani mallaiah | F23: Semi Skilled Gardner | G23: =[1]Master!F28 -> Semi Skilled Gardner | H23: Madaram,Medhak | I23: =[1]Master!H28 -> Madaram,Medhak | J23: Gachibowli Village | K23: Hyderabad | L23: Telangana State | M23: 43850
A24: =[1]Master!A29 -> 14 | B24: Mutholla Mallesh | C24: 36161 | D24: Male | E24: Mutholla balaiah | F24: Semi Skilled Gardner | G24: =[1]Master!F29 -> Semi Skilled Gardner | H24: sulthanpur,Medhak | I24: =[1]Master!H29 -> sulthanpur,Medhak | J24: Gachibowli Village | K24: Hyderabad | L24: Telangana State | M24: 43850
A25: =[1]Master!A30 -> 15 | B25: ALIJANA JAYARAMI REDDY | C25: 36439 | D25: Male | E25: ALIJANA OBULU REDDY | F25: Semi Skilled Gardner | G25: =[1]Master!F30 -> Semi Skilled Gardner | H25: Parnapalle,Cuddaph | I25: =[1]Master!H30 -> Parnapalle,Cuddaph | J25: Gachibowli Village | K25: Hyderabad | L25: Telangana State | M25: 43850
A26: =[1]Master!A31 -> 16 | B26: Kapil | C26: 36162 | D26: Male | E26: Ganesh lal | F26: Semi Skilled Gardner | G26: =[1]Master!F31 -> Semi Skilled Gardner | H26: reabarelli,Khamariya,naiani amethi | I26: =[1]Master!H31 -> reabarelli,Khamariya,naiani amethi | J26: Gachibowli Village | K26: Hyderabad | L26: Telangana State | M26: 43850
A27: =[1]Master!A32 -> 17 | B27: Bablu kumar | C27: 27948 | D27: Male | E27: Harilal | F27: Semi Skilled Gardner | G27: =[1]Master!F32 -> Semi Skilled Gardner | H27: Khamariya pure Kushal,amethi,nini | I27: =[1]Master!H32 -> Khamariya pure Kushal,amethi,nini | J27: Gachibowli Village | K27: Hyderabad | L27: Telangana State | M27: 43850
A28: =[1]Master!A33 -> 18 | B28: Pradeep kumar | C28: 16/9/1977 | D28: Male | E28: Jagdev | F28: Semi Skilled Gardner | G28: =[1]Master!F33 -> Semi Skilled Gardner | H28: Khamariya pure Kushal,amethi,nini | I28: =[1]Master!H33 -> Khamariya pure Kushal,amethi,nini | J28: Gachibowli Village | K28: Hyderabad | L28: Telangana State | M28: 43850
A29: =[1]Master!A34 -> 19 | B29: SHAIK KULSUM BEE | C29: 27762 | D29: Female | E29: SHAIK LALA | F29: Unskilled Gardner | G29: =[1]Master!F34 -> Unskilled Gardner | H29: KONDAPUR,SERILINGAMPALLY | I29: =[1]Master!H34 -> KONDAPUR,SERILINGAMPALLY | J29: Gachibowli Village | K29: Hyderabad | L29: Telangana State | M29: 43850
A30: =[1]Master!A35 -> 20 | B30: S GOWRI | C30: 33239 | D30: Female | E30: S SURYANARAYANA | F30: Unskilled Gardner | G30: =[1]Master!F35 -> Unskilled Gardner | H30: ,Gutkal,Ananthpur | I30: =[1]Master!H35 -> ,Gutkal,Ananthpur | J30: Gachibowli Village | K30: Hyderabad | L30: Telangana State | M30: 43850
A31: =[1]Master!A36 -> 21 | B31: FARZANA BEGUM | C31: 31048 | D31: Female | E31: SHAIK MASTAN WALI | F31: Unskilled Gardner | G31: =[1]Master!F36 -> Unskilled Gardner | H31: HAKEEMPET,THOLICHOUK,GOLUKOND | I31: =[1]Master!H36 -> HAKEEMPET,THOLICHOUK,GOLUKOND | J31: Gachibowli Village | K31: Hyderabad | L31: Telangana State | M31: 43850
A32: =[1]Master!A37 -> 22 | B32: MANAGALI SUHASINI | C32: 29221 | D32: Female | E32: MANGALI RAJU | F32: Unskilled Gardner | G32: =[1]Master!F37 -> Unskilled Gardner | H32: Medharam,medak | I32: =[1]Master!H37 -> Medharam,medak | J32: Gachibowli Village | K32: Hyderabad | L32: Telangana State | M32: 43850
A33: =[1]Master!A38 -> 23 | B33: KONA SUJATHA | C33: 25934 | D33: Female | E33: KONA SURYANARAYANA | F33: Unskilled Gardner | G33: =[1]Master!F38 -> Unskilled Gardner | H33: .guntkal,anthapuram | I33: =[1]Master!H38 -> .guntkal,anthapuram | J33: Gachibowli Village | K33: Hyderabad | L33: Telangana State | M33: 43850
A34: =[1]Master!A39 -> 24 | B34: GOLLA UMA | C34: 30562 | D34: Female | E34: GOLLA ONURU SWAMY | F34: Unskilled Gardner | G34: =[1]Master!F39 -> Unskilled Gardner | H34: GUTAL,ANANTHAPURM | I34: =[1]Master!H39 -> GUTAL,ANANTHAPURM | J34: Gachibowli Village | K34: Hyderabad | L34: Telangana State | M34: 43850
A35: =[1]Master!A40 -> 25 | B35: SINGARAM BHAGYAMMA | C35: 18/5/1964 | D35: Female | E35: SINGARAM NARSIMULU | F35: Unskilled Gardner | G35: =[1]Master!F40 -> Unskilled Gardner | H35: Krishnareddipet,Medak | I35: =[1]Master!H40 -> Krishnareddipet,Medak | J35: Gachibowli Village | K35: Hyderabad | L35: Telangana State | M35: 43850
A36: =[1]Master!A41 -> 26 | B36: BONIGA MARIYAMMA | C36: 32183 | D36: Female | E36: MARIYA KUMAR | F36: Unskilled Gardner | G36: =[1]Master!F41 -> Unskilled Gardner | H36: Bapu nagar,Lingampally, | I36: =[1]Master!H41 -> Bapu nagar,Lingampally, | J36: Gachibowli Village | K36: Hyderabad | L36: Telangana State | M36: 43850 | O36: 43860 | P36: Resignation
A37: =[1]Master!A42 -> 27 | B37: KODICHERLA INDIRAMMA | C37: 32418 | D37: Female | E37: BABAIAH | F37: Unskilled Gardner | G37: =[1]Master!F42 -> Unskilled Gardner | H37: Kondapoor,Serilinampally | I37: =[1]Master!H42 -> Kondapoor,Serilinampally | J37: Gachibowli Village | K37: Hyderabad | L37: Telangana State | M37: 43850
A38: =[1]Master!A43 -> 28 | B38: SANGOLLA LAVANYA | C38: 26299 | D38: Female | E38: SANGOLLA ASHOK | F38: Unskilled Gardner | G38: =[1]Master!F43 -> Unskilled Gardner | H38: Patancheru,Medak | I38: =[1]Master!H43 -> Patancheru,Medak | J38: Gachibowli Village | K38: Hyderabad | L38: Telangana State | M38: 43850
A39: =[1]Master!A44 -> 29 | B39: MANGALI LAVANYA | C39: 14/3/1985 | D39: Female | E39: MANGALI PANDU | F39: Unskilled Gardner | G39: =[1]Master!F44 -> Unskilled Gardner | H39: Madhavaram,madharam,Medhak | I39: =[1]Master!H44 -> Madhavaram,madharam,Medhak | J39: Gachibowli Village | K39: Hyderabad | L39: Telangana State | M39: 43850
A40: =[1]Master!A45 -> 30 | B40: MANGLI CHANDRAMMA | C40: 25/3/1969 | D40: Female | E40: MANGALI VENKATESH | F40: Unskilled Gardner | G40: House no. - 3-33 Madharam, | H40: MADHARAM,MEDHAK | I40: Andhra pradesh - 502319 | J40: Gachibowli Village | K40: Hyderabad | L40: Telangana State | M40: 43850
A41: =[1]Master!A46 -> 31 | B41: DASARI SUVARNA | C41: 32509 | D41: Female | E41: DASARI RAVINDAR | F41: Unskilled Gardner | G41: =[1]Master!F46 -> Unskilled Gardner | H41: NEAR GVT SCHOOL LINGAMPALLI, | I41: =[1]Master!H46 -> NEAR GVT SCHOOL LINGAMPALLI, | J41: Gachibowli Village | K41: Hyderabad | L41: Telangana State | M41: 43850
A42: =[1]Master!A47 -> 32 | B42: MARATHI CHANDRAKALA | C42: 31413 | D42: Female | E42: M ASHOKS | F42: Unskilled Gardner | G42: =[1]Master!F47 -> Unskilled Gardner | H42: patancheru,sultanpur,Medak | I42: =[1]Master!H47 -> patancheru,sultanpur,Medak | J42: Gachibowli Village | K42: Hyderabad | L42: Telangana State | M42: 43850
A43: =[1]Master!A48 -> 33 | B43: ANKAGALLA YADAMMA | C43: 32509 | D43: Female | E43: ANKAGALLA YADAGIRI | F43: Unskilled Gardner | G43: =[1]Master!F48 -> Unskilled Gardner | H43: Sulthanpoor,patancheru,Sulthanpur | I43: =[1]Master!H48 -> Sulthanpoor,patancheru,Sulthanpur | J43: Gachibowli Village | K43: Hyderabad | L43: Telangana State | M43: 43850
...

Sheet Master
C3: EMPLOYEE DATABASE
C5: Name and address of Contractor: | F5: GROTECH LANDSCAPE DEVELOPERS PVT. LTD. | AF5: Name and address of Establishemnt in/ under which contract is carried on: | AN5: =F5 -> GROTECH LANDSCAPE DEVELOPERS PVT. LTD.
F6: 290/E, Khanapur Village, Gandipet Mandal, Ranga Reddy, Hyderabad-500075 T.S. | AN6: =F6 -> 290/E, Khanapur Village, Gandipet Mandal, Ranga Reddy, Hyderabad-500075 T.S.
C8: Nature and location of work: | F8: GARDENING SERVICES&ISB HYDERABAD
C10: Wage period: Monthly | F10: 44652 | AK10: Name and address of the Principle Employer | AN10: INDIAN SCHOOL OF BUSINESS
AN11: Opp.Infosys Limited,Gachibowli,Hyderabad
A14: Serial No | B14: Employee ID | C14: Serial No. in the Register of Workmen | D14: Name of Workman | E14: Age | F14: Sex | G14: Father Name | H14: Husband/Wife Name | I14: Department | J14: Designation / Nature of Work Done | K14: Permanent Address-1 (H.No.&Street Name) | L14: Permanent Address-2 (Village Name) | M14: Permanent Address-3 (Mandal&District Name) | N14: Permanent Address-4 (State with PIN code) | O14: Present Address-1 (H.No.&Street Name) | P14: Present Address-2 (Village Name) | Q14: Present Address-3 (Mandal&District Name) | R14: Present Address-4 (State with PIN code) | S14: Date of Joining | T14: Signature or thumb impression of Workman | U14: Date of termination of Employment | V14: Reasons for termination | W14: Remarks | X14: EPF Number | Y14: ESI Number | Z14: Name of Work man | AA14: Payble Days | AB14: Unit of Work done | AC14: Monthly rate of wages | AD14: Basic Wages | AE14: Dearness Allowances | AF14: Overtime | AG14: HRA | AH14: BONUS | AI14: LTA | AJ14: SPECIAL ALLOWNANCES | AK14: Total Amount | AL14: ESI | AM14: PF | AN14: PT | AO14: TDS | AP14: ADV | AQ14: Total Deductions | AR14: Net Salary | AS14: Date of Payment | AT14: Bank Name | AU14: Bank Account Number
A15: 1 | B15: GLDPL/EMP/079 | C15: 2 | D15: ARJUN KUMAR | E15: 31413 | F15: Male | G15: kallu | I15: Nursery | J15: Supervisor | K15: Village - Dharai | L15: Amethi | M15: Uttar pradesh - 229127 | O15: Gachibowli Village | P15: Hyderabad | Q15: Telangana State | S15: 43850 | X15: N/A | Y15: 2016384651 | Z15: =D15 -> ARJUN KUMAR | AA15: 30 | AB15: 0 | AC15: 20000 | AD15: 20000 | AE15: 0 | AF15: 0 | AG15: 0 | AH15: 0 | AI15: 0 | AJ15: 0 | AK15: =AD15+AE15+AF15+AG15+AH15+AI15+AJ15 -> 20000 | AL15: 150 | AM15: 0 | AN15: 150 | AO15: 0 | AP15: 0 | AQ15: =AL15+AM15+AN15+AO15+AP15 -> 300 | AR15: =AK15-AQ15 -> 19700 | AS15: 7th May 2020 | AT15: KKBK0000205 | AU15: 6912137285
A16: 2 | B16: GLDPL/EMP/142 | C16: 3 | D16: GAJAN SINGH | E16: 29587 | F16: Male | G16: Chandrapal singh | I16: Nursery | J16: Supervisor | K16: Village - Uncha gaon, Pikhani, | L16: Bulandshahr, | M16: Uttar pradesh - 202398 | O16: Gachibowli Village | P16: Hyderabad | Q16: Telangana State | S16: 43850 | X16: 101252819921 | Y16: 2017795829 | Z16: =D16 -> GAJAN SINGH | AA16: 30 | AB16: 0 | AC16: 14900 | AD16: 11900 | AE16: 0 | AF16: 0 | AG16: 0 | AH16: 0 | AI16: 0 | AJ16: 3000 | AK16: =AD16+AE16+AF16+AG16+AH16+AI16+AJ16 -> 14900 | AL16: 112 | AM16: 1788 | AN16: 0 | AO16: 0 | AP16: 0 | AQ16: =AL16+AM16+AN16+AO16+AP16 -> 1900 | AR16: =AK16-AQ16 -> 13000 | AS16: 7th May 2020 | AT16: KKBK0000205 | AU16: 7513074030
A17: 3 | B17: GLDPL/EMP/141 | C17: 4 | D17: GUDALA RUSHESHWAR SWAMY | E17: 31345 | F17: Male | G17: GUDALA KRISHANA MURTHY | I17: Nursery | J17: Supervisor | K17: House no. - 8-153 Kottapeta | L17: Gummaluru, west godavari | M17: Andhra pradesh - 534267 | O17: Gachibowli Village | P17: Hyderabad | Q17: Telangana State | S17: 43850 | X17: 100025787555 | Y17: 5216113872 | Z17: =D17 -> GUDALA RUSHESHWAR SWAMY | AA17: 30 | AB17: 0 | AC17: 17918 | AD17: 11802 | AE17: 0 | AF17: 0 | AG17: 4721 | AH17: 0 | AI17: 0 | AJ17: 1395 | AK17: =AD17+AE17+AF17+AG17+AH17+AI17+AJ17 -> 17918 | AL17: 135 | AM17: 1584 | AN17: 150 | AO17: 0 | AP17: 0 | AQ17: =AL17+AM17+AN17+AO17+AP17 -> 1869 | AR17: =AK17-AQ17 -> 16049 | AS17: 7th May 2020 | AT17: KKBK0007476 | AU17: 1912391941
A18: 4 | B18: GLDPL/LB/9002 | C18: 6 | D18: KASALA NARSIMLU | E18: 21919 | F18: Male | G18: KASALA POCHAIAH | I18: Nursery | J18: Semi Skilled Gardner | K18: H.no.3-90, | L18: Mwdharam,Medhak | M18: TS-502319 | O18: Gachibowli Village | P18: Hyderabad | Q18: Telangana State | S18: 43850 | X18: 101335495091 | Y18: 5216248033 | Z18: =D18 -> KASALA NARSIMLU | AA18: 26 | AB18: 0 | AC18: 13753 | AD18: 3844 | AE18: 4931.3333 | AF18: 0 | AG18: 0 | AH18: 730.6 | AI18: 425.53333 | AJ18: 1988.1333 | AK18: =AD18+AE18+AF18+AG18+AH18+AI18+AJ18 -> 11919.6 | AL18: 90 | AM18: 1430 | AN18: 0 | AO18: 0 | AP18: 0 | AQ18: =AL18+AM18+AN18+AO18+AP18 -> 1520 | AR18: =AK18-AQ18 -> 10399.6 | AS18: 7th May 2020 | AT18: ICIC0000202 | AU18: 20201585355
A19: 5 | B19: GLDPL/LB/9003 | C19: 7 | D19: PITANI SATHYA NARAYANA | E19: 24473 | F19: Male | G19: P SURYANARAYANA | I19: Nursery | J19: Semi Skilled Gardner | K19: H.no 12-60/3,Gopinagar colony, | L19: Near church,serilingampally | M19: KV R.R,TS-500019 | O19: Gachibowli Village | P19: Hyderabad | Q19: Telangana State | S19: 43850 | X19: 101423797426 | Y19: 5215982488 | Z19: =D19 -> PITANI SATHYA NARAYANA | AA19: 26 | AB19: 0 | AC19: 11459 | AD19: 3844 | AE19: 4931.3333 | AF19: 0 | AG19: 0 | AH19: 730.6 | AI19: 425.53333 | AJ19: 0 | AK19: =AD19+AE19+AF19+AG19+AH19+AI19+AJ19+1 -> 9932.4667 | AL19: 75 | AM19: 1192 | AN19: 0 | AO19: 0 | AP19: 0 | AQ19: =AL19+AM19+AN19+AO19+AP19 -> 1267 | AR19: =AK19-AQ19 -> 8665.4667 | AS19: 7th May 2020 | AT19: ANDB0001414 | AU19: 141410100131316
A20: 6 | B20: GLDPL/LB/9004 | C20: 8 | D20: SANGOLLA ASHOK | E20: 21/6/1988 | F20: Male | G20: SANGOLLA ESWARAIAH | I20: Nursery | J20: Semi Skilled Gardner | K20: 3-35,Jankampet, | L20: Patancheru,Sulthanpur | M20: TS-502319 | O20: Gachibowli Village | P20: Hyderabad | Q20: Telangana State | S20: 43850 | X20: 100321400080 | Y20: 5210317860 | Z20: =D20 -> SANGOLLA ASHOK | AA20: 26 | AB20: 0 | AC20: 11459 | AD20: 3844 | AE20: 4931.3333 | AF20: 0 | AG20: 0 | AH20: 730.6 | AI20: 425.53333 | AJ20: 0 | AK20: =AD20+AE20+AF20+AG20+AH20+AI20+AJ20+1 -> 9932.4667 | AL20: 75 | AM20: 1192 | AN20: 0 | AO20: 0 | AP20: 0 | AQ20: =AL20+AM20+AN20+AO20+AP20 -> 1267 | AR20: =AK20-AQ20 -> 8665.4667 | AS20: 7th May 2020 | AT20: SBIN0020106 | AU20: 62135175705
A21: 7 | B21: GLDPL/LB/9005 | C21: 9 | D21: ASHOK LINGURAM GAIKWAD | E21: 29832 | F21: Male | G21: M LINGRAM | I21: Nursery | J21: Semi Skilled Gardner | K21: Gaikwada at sangavi bu | L21: Post-sawargaon,Mukhed,Nanded, | M21: Mahrastra-431715 | O21: Gachibowli Village | P21: Hyderabad | Q21: Telangana State | S21: 43850 | X21: 100807941415 | Y21: 5211196939 | Z21: =D21 -> ASHOK LINGURAM GAIKWAD | AA21: 26 | AB21: 0 | AC21: 11459 | AD21: 3844 | AE21: 4931.3333 | AF21: 0 | AG21: 0 | AH21: 730.6 | AI21: 425.53333 | AJ21: 0 | AK21: =AD21+AE21+AF21+AG21+AH21+AI21+AJ21+1 -> 9932.4667 | AL21: 75 | AM21: 1192 | AN21: 0 | AO21: 0 | AP21: 0 | AQ21: =AL21+AM21+AN21+AO21+AP21 -> 1267 | AR21: =AK21-AQ21 -> 8665.4667 | AS21: 7th May 2020 | AT21: SBIN0014234 | AU21: 35398345250
A22: 8 | B22: GLDPL/LB/9006 | C22: 10 | D22: MADHUKAR KAMTAM | E22: 26665 | F22: Male | G22: KAMTAM KISHAN | I22: Nursery | J22: Semi Skilled Gardner | K22: 9-41,Serilingampally,Gopinagar colony, | L22: opp Hanuman temple | M22: R.R-TS,500084 | O22: Gachibowli Village | P22: Hyderabad | Q22: Telangana State | S22: 43850 | X22: 101438575409 | Y22: 5216116351 | Z22: =D22 -> MADHUKAR KAMTAM | AA22: 26 | AB22: 0 | AC22: 11459 | AD22: 3844 | AE22: 4931.3333 | AF22: 0 | AG22: 0 | AH22: 730.6 | AI22: 425.53333 | AJ22: 0 | AK22: =AD22+AE22+AF22+AG22+AH22+AI22+AJ22+1 -> 9932.4667 | AL22: 75 | AM22: 1192 | AN22: 0 | AO22: 0 | AP22: 0 | AQ22: =AL22+AM22+AN22+AO22+AP22 -> 1267 | AR22: =AK22-AQ22 -> 8665.4667 | AS22: 7th May 2020 | AT22: IDIB000N116 | AU22: 923249324
A23: 9 | B23: GLDPL/LB/9009 | C23: 12 | D23: Ningolla Raju | E23: 21/5/1975 | F23: Male | G23: ningolla pochaiah | I23: Nursery | J23: Semi Skilled Gardner | K23: 3-27/1,janakampet, | L23: patancherusultanpur,medhak | M23: TS-502319 | O23: Gachibowli Village | P23: Hyderabad | Q23: Telangana State | S23: 43850 | X23: 100043556888 | Y23: 5216340446 | Z23: =D23 -> Ningolla Raju | AA23: 26 | AB23: 0 | AC23: 11459 | AD23: 3844 | AE23: 4931.3333 | AF23: 0 | AG23: 0 | AH23: 730.6 | AI23: 425.53333 | AJ23: 0 | AK23: =AD23+AE23+AF23+AG23+AH23+AI23+AJ23+1 -> 9932.4667 | AL23: 75 | AM23: 1192 | AN23: 0 | AO23: 0 | AP23: 0 | AQ23: =AL23+AM23+AN23+AO23+AP23 -> 1267 | AR23: =AK23-AQ23 -> 8665.4667 | AS23: 7th May 2020 | AT23: BKID0008614 | AU23: 861410110009223
A24: 10 | B24: GLDPL/LB/9010 | C24: 13 | D24: Nagani pochaiah | E24: 24108 | F24: Male | G24: Nagani mallaiah | I24: Nursery | J24: Semi Skilled Gardner | K24: H.no.3-18, | L24: Madaram,Medhak | M24: TS-502319 | O24: Gachibowli Village | P24: Hyderabad | Q24: Telangana State | S24: 43850 | X24: 100993759408 | Y24: 5212759307 | Z24: =D24 -> Nagani pochaiah | AA24: 26 | AB24: 0 | AC24: 11459 | AD24: 3844 | AE24: 4931.3333 | AF24: 0 | AG24: 0 | AH24: 730.6 | AI24: 425.53333 | AJ24: 0 | AK24: =AD24+AE24+AF24+AG24+AH24+AI24+AJ24+1 -> 9932.4667 | AL24: 75 | AM24: 1192 | AN24: 0 | AO24: 0 | AP24: 0 | AQ24: =AL24+AM24+AN24+AO24+AP24 -> 1267 | AR24: =AK24-AQ24 -> 8665.4667 | AS24: 7th May 2020 | AT24: SBIN0014234 | AU24: 38228069327
A25: 11 | B25: GLDPL/LB/9011 | C25: 14 | D25: Mutholla Mallesh | E25: 36161 | F25: Male | G25: Mutholla balaiah | I25: Nursery | J25: Semi Skilled Gardner | K25: 3-37,Jnakapet, | L25: sulthanpur,Medhak | M25: TS-502319 | O25: Gachibowli Village | P25: Hyderabad | Q25: Telangana State | S25: 43850 | X25: 101196116055 | Y25: 5216340493 | Z25: =D25 -> Mutholla Mallesh | AA25: 26 | AB25: 0 | AC25: 11459 | AD25: 3844 | AE25: 4931.3333 | AF25: 0 | AG25: 0 | AH25: 730.6 | AI25: 425.53333 | AJ25: 0 | AK25: =AD25+AE25+AF25+AG25+AH25+AI25+AJ25+1 -> 9932.4667 | AL25: 75 | AM25: 1192 | AN25: 0 | AO25: 0 | AP25: 0 | AQ25: =AL25+AM25+AN25+AO25+AP25 -> 1267 | AR25: =AK25-AQ25 -> 8665.4667 | AS25: 7th May 2020 | AT25: SBIN0014234 | AU25: 20176301430
A26: 12 | B26: GLDPL/LB/9008 | C26: 15 | D26: ALIJANA JAYARAMI REDDY | E26: 36439 | F26: Male | G26: ALIJANA OBULU REDDY | I26: Nursery | J26: Semi Skilled Gardner | K26: 5/126, | L26: Parnapalle,Cuddaph | M26: AP-516396 | O26: Gachibowli Village | P26: Hyderabad | Q26: Telangana State | S26: 43850 | X26: 100844389108 | Y26: 5211482351 | Z26: =D26 -> ALIJANA JAYARAMI REDDY | AA26: 26 | AB26: 0 | AC26: 11459 | AD26: 3844 | AE26: 4931.3333 | AF26: 0 | AG26: 0 | AH26: 730.6 | AI26: 425.53333 | AJ26: 0 | AK26: =AD26+AE26+AF26+AG26+AH26+AI26+AJ26+1 -> 9932.4667 | AL26: 75 | AM26: 1192 | AN26: 0 | AO26: 0 | AP26: 0 | AQ26: =AL26+AM26+AN26+AO26+AP26 -> 1267 | AR26: =AK26-AQ26 -> 8665.4667 | AS26: 7th May 2020 | AT26: SBIN0008495 | AU26: 33412525880
A27: 13 | B27: GLDPL/LB/9012 | C27: 16 | D27: Kapil | E27: 36162 | F27: Male | G27: Ganesh lal | I27: Nursery | J27: Semi Skilled Gardner | K27: Khamiriya,Puru kusal,Jilla, | L27: reabarelli,Khamariya,naiani amethi | M27: U.P-229127 | O27: Gachibowli Village | P27: Hyderabad | Q27: Telangana State | S27: 43850 | X27: 101554508977 | Y27: 5216340520 | Z27: =D27 -> Kapil | AA27: 0 | AB27: 0 | AC27: 11459 | AD27: 0 | AE27: 0 | AF27: 0 | AG27: 0 | AH27: 0 | AI27: 0 | AJ27: 0 | AK27: =AD27+AE27+AF27+AG27+AH27+AI27+AJ27 -> 0 | AL27: 0 | AM27: 0 | AN27: 0 | AO27: 0 | AP27: 0 | AQ27: =AL27+AM27+AN27+AO27+AP27 -> 0 | AR27: =AK27-AQ27 -> 0 | AS27: 7th May 2020 | AT27: KKBK0007466 | AU27: 8512913818
A28: 14 | B28: GLDPL/LB/9013 | C28: 17 | D28: Bablu kumar | E28: 27948 | F28: Male | G28: Harilal | I28: Nursery | J28: Semi Skilled Gardner | K28: Nayan,Saion, | L28: Khamariya pure Kushal,amethi,nini | M28: U.P-229127 | O28: Gachibowli Village | P28: Hyderabad | Q28: Telangana State | S28: 43850 | X28: 101554509007 | Y28: 5216340547 | Z28: =D28 -> Bablu kumar | AA28: 0 | AB28: 0 | AC28: 11459 | AD28: 0 | AE28: 0 | AF28: 0 | AG28: 0 | AH28: 0 | AI28: 0 | AJ28: 0 | AK28: =AD28+AE28+AF28+AG28+AH28+AI28+AJ28 -> 0 | AL28: 0 | AM28: 0 | AN28: 0 | AO28: 0 | AP28: 0 | AQ28: =AL28+AM28+AN28+AO28+AP28 -> 0 | AR28: =AK28-AQ28 -> 0 | AS28: 7th May 2020 | AT28: KKBK0007466 | AU28: 8512913542
A29: 15 | B29: GLDPL/LB/9014 | C29: 18 | D29: Pradeep kumar | E29: 16/9/1977 | F29: Male | G29: Jagdev | I29: Nursery | J29: Semi Skilled Gardner | K29: Nayan,Saion, | L29: Khamariya pure Kushal,amethi,nini | M29: U.P-229127 | O29: Gachibowli Village | P29: Hyderabad | Q29: Telangana State | S29: 43850 | X29: 101554508996 | Y29: 5216340569 | Z29: =D29 -> Pradeep kumar | AA29: 0 | AB29: 0 | AC29: 11459 | AD29: 0 | AE29: 0 | AF29: 0 | AG29: 0 | AH29: 0 | AI29: 0 | AJ29: 0 | AK29: =AD29+AE29+AF29+AG29+AH29+AI29+AJ29 -> 0 | AL29: 0 | AM29: 0 | AN29: 0 | AO29: 0 | AP29: 0 | AQ29: =AL29+AM29+AN29+AO29+AP29 -> 0 | AR29: =AK29-AQ29 -> 0 | AS29: 7th May 2020 | AT29: KKBK0007466 | AU29: 8512913528
A30: 16 | B30: GLDPL/LB/9015 | C30: 19 | D30: SHAIK KULSUM BEE | E30: 27762 | F30: Female | G30: SHAIK LALA | I30: Nursery | J30: Unskilled Gardner | K30: PLOT.NO.175,MASID BAND, | L30: KONDAPUR,SERILINGAMPALLY | M30: R.R-TS,500084 | O30: Gachibowli Village | P30: Hyderabad | Q30: Telangana State | S30: 43850 | X30: 100201354809 | Y30: 5210209502 | Z30: =D30 -> SHAIK KULSUM BEE | AA30: 26 | AB30: 0 | AC30: 10627 | AD30: 3207 | AE30: 4931.3333 | AF30: 0 | AG30: 0 | AH30: 677.73333 | AI30: 394.33333 | AJ30: 0 | AK30: =AD30+AE30+AF30+AG30+AH30+AI30+AJ30 -> 9210.4 | AL30: 70 | AM30: 1105 | AN30: 0 | AO30: 0 | AP30: 0 | AQ30: =AL30+AM30+AN30+AO30+AP30 -> 1175 | AR30: =AK30-AQ30 -> 8035.4 | AS30: 7th May 2020 | AT30: SBIN0005916 | AU30: 30144397282
A31: 17 | B31: GLDPL/LB/9016 | C31: 20 | D31: S GOWRI | E31: 33239 | F31: Female | G31: S SURYANARAYANA | I31: Nursery | J31: Unskilled Gardner | K31: 2/686,Modinabad | L31: ,Gutkal,Ananthpur | M31: AP-515801 | O31: Gachibowli Village | P31: Hyderabad | Q31: Telangana State | S31: 43850 | X31: 101412580029 | Y31: 5215258577 | Z31: =D31 -> S GOWRI | AA31: 26 | AB31: 0 | AC31: 10627 | AD31: 3207 | AE31: 4931.3333 | AF31: 0 | AG31: 0 | AH31: 677.73333 | AI31: 394.33333 | AJ31: 0 | AK31: =AD31+AE31+AF31+AG31+AH31+AI31+AJ31 -> 9210.4 | AL31: 70 | AM31: 1105 | AN31: 0 | AO31: 0 | AP31: 0 | AQ31: =AL31+AM31+AN31+AO31+AP31 -> 1175 | AR31: =AK31-AQ31 -> 8035.4 | AS31: 7th May 2020 | AT31: SBIN0000957 | AU31: 35855410947
A32: 18 | B32: GLDPL/LB/9017 | C32: 21 | D32: FARZANA BEGUM | E32: 31048 | F32: Female | G32: SHAIK MASTAN WALI | I32: Nursery | J32: Unskilled Gardner | K32: 9-4-57/7/D/10/2/B43, | L32: HAKEEMPET,THOLICHOUK,GOLUKOND | M32: HYDERABAD,TS-500008 | O32: Gachibowli Village | P32: Hyderabad | Q32: Telangana State | S32: 43850 | X32: 100146756163 | Y32: 5206265912 | Z32: =D32 -> FARZANA BEGUM | AA32: 26 | AB32: 0 | AC32: 10627 | AD32: 3207 | AE32: 4931.3333 | AF32: 0 | AG32: 0 | AH32: 677.73333 | AI32: 394.33333 | AJ32: 0 | AK32: =AD32+AE32+AF32+AG32+AH32+AI32+AJ32 -> 9210.4 | AL32: 70 | AM32: 1105 | AN32: 0 | AO32: 0 | AP32: 0 | AQ32: =AL32+AM32+AN32+AO32+AP32 -> 1175 | AR32: =AK32-AQ32 -> 8035.4 | AS32: 7th May 2020 | AT32: ANDB0001306 | AU32: 130610100075445
A33: 19 | B33: GLDPL/LB/9018 | C33: 22 | D33: MANAGALI SUHASINI | E33: 29221 | F33: Female | G33: MANGALI RAJU | I33: Nursery | J33: Unskilled Gardner | K33: H.no.2-36, | L33: Medharam,medak | M33: TS-502319 | O33: Gachibowli Village | P33: Hyderabad | Q33: Telangana State | S33: 43850 | X33: 101257341492 | Y33: 5214635168 | Z33: =D33 -> MANAGALI SUHASINI | AA33: 26 | AB33: 0 | AC33: 10627 | AD33: 3207 | AE33: 4931.3333 | AF33: 0 | AG33: 0 | AH33: 677.73333 | AI33: 394.33333 | AJ33: 0 | AK33: =AD33+AE33+AF33+AG33+AH33+AI33+AJ33 -> 9210.4 | AL33: 70 | AM33: 1105 | AN33: 0 | AO33: 0 | AP33: 0 | AQ33: =AL33+AM33+AN33+AO33+AP33 -> 1175 | AR33: =AK33-AQ33 -> 8035.4 | AS33: 7th May 2020 | AT33: APGV0008110 | AU33: 73138780593
A34: 20 | B34: GLDPL/LB/9019 | C34: 23 | D34: KONA SUJATHA | E34: 25934 | F34: Female | G34: KONA SURYANARAYANA | I34: Nursery | J34: Unskilled Gardner | K34: 2-503/A,modinabad | L34: .guntkal,anthapuram | M34: AP-515801 | O34: Gachibowli Village | P34: Hyderabad | Q34: Telangana State | S34: 43850 | X34: 101421043457 | Y34: 5215374381 | Z34: =D34 -> KONA SUJATHA | AA34: 26 | AB34: 0 | AC34: 10627 | AD34: 3207 | AE34: 4931.3333 | AF34: 0 | AG34: 0 | AH34: 677.73333 | AI34: 394.33333 | AJ34: 0 | AK34: =AD34+AE34+AF34+AG34+AH34+AI34+AJ34 -> 9210.4 | AL34: 70 | AM34: 1105 | AN34: 0 | AO34: 0 | AP34: 0 | AQ34: =AL34+AM34+AN34+AO34+AP34 -> 1175 | AR34: =AK34-AQ34 -> 8035.4 | AS34: 7th May 2020 | AT34: SBIN0000957 | AU34: 30534600258
A35: 21 | B35: GLDPL/LB/9020 | C35: 24 | D35: GOLLA UMA | E35: 30562 | F35: Female | G35: GOLLA ONURU SWAMY | I35: Nursery | J35: Unskilled Gardner | K35: 2-503-B,MODINABAD, | L35: GUTAL,ANANTHAPURM | M35: AP-515801 | O35: Gachibowli Village | P35: Hyderabad | Q35: Telangana State | S35: 43850 | X35: 101412580017 | Y35: 5215258539 | Z35: =D35 -> GOLLA UMA | AA35: 26 | AB35: 0 | AC35: 10627 | AD35: 3207 | AE35: 4931.3333 | AF35: 0 | AG35: 0 | AH35: 677.73333 | AI35: 394.33333 | AJ35: 0 | AK35: =AD35+AE35+AF35+AG35+AH35+AI35+AJ35 -> 9210.4 | AL35: 70 | AM35: 1105 | AN35: 0 | AO35: 0 | AP35: 0 | AQ35: =AL35+AM35+AN35+AO35+AP35 -> 1175 | AR35: =AK35-AQ35 -> 8035.4 | AS35: 7th May 2020 | AT35: SBIN0000957 | AU35: 11107141688
A36: 22 | B36: GLDPL/LB/9021 | C36: 25 | D36: SINGARAM BHAGYAMMA | E36: 18/5/1964 | F36: Female | G36: SINGARAM NARSIMULU | I36: Nursery | J36: Unskilled Gardner | K36: 1-43,patancheru-mndl, | L36: Krishnareddipet,Medak | M36: TS-502319 | O36: Gachibowli Village | P36: Hyderabad | Q36: Telangana State | S36: 43850 | X36: 100118386595 | Y36: 5216279786 | Z36: =D36 -> SINGARAM BHAGYAMMA | AA36: 26 | AB36: 0 | AC36: 10627 | AD36: 3207 | AE36: 4931.3333 | AF36: 0 | AG36: 0 | AH36: 677.73333 | AI36: 394.33333 | AJ36: 0 | AK36: =AD36+AE36+AF36+AG36+AH36+AI36+AJ36 -> 9210.4 | AL36: 70 | AM36: 1105 | AN36: 0 | AO36: 0 | AP36: 0 | AQ36: =AL36+AM36+AN36+AO36+AP36 -> 1175 | AR36: =AK36-AQ36 -> 8035.4 | AS36: 7th May 2020 | AT36: SBIN0014234 | AU36: 36363257786
A37: 23 | B37: GLDPL/LB/9023 | C37: 27 | D37: KODICHERLA INDIRAMMA | E37: 32418 | F37: Female | G37: BABAIAH | I37: Nursery | J37: Unskilled Gardner | K37: 1-92,maseed banda-Vill | L37: Kondapoor,Serilinampally | M37: R.R-TS,500032 | O37: Gachibowli Village | P37: Hyderabad | Q37: Telangana State | S37: 43850 | X37: 100181240855 | Y37: 5209811859 | Z37: =D37 -> KODICHERLA INDIRAMMA | AA37: 26 | AB37: 0 | AC37: 10627 | AD37: 3207 | AE37: 4931.3333 | AF37: 0 | AG37: 0 | AH37: 677.73333 | AI37: 394.33333 | AJ37: 0 | AK37: =AD37+AE37+AF37+AG37+AH37+AI37+AJ37 -> 9210.4 | AL37: 70 | AM37: 1105 | AN37: 0 | AO37: 0 | AP37: 0 | AQ37: =AL37+AM37+AN37+AO37+AP37 -> 1175 | AR37: =AK37-AQ37 -> 8035.4 | AS37: 7th May 2020 | AT37: SBIN0005916 | AU37: 30181587428
A38: 24 | B38: GLDPL/LB/9024 | C38: 28 | D38: SANGOLLA LAVANYA | E38: 26299 | F38: Female | G38: SANGOLLA ASHOK | I38: Nursery | J38: Unskilled Gardner | K38: 3-35,janakapet, | L38: Patancheru,Medak | M38: TS-502319 | O38: Gachibowli Village | P38: Hyderabad | Q38: Telangana State | S38: 43850 | X38: 100993758799 | Y38: 5212759301 | Z38: =D38 -> SANGOLLA LAVANYA | AA38: 26 | AB38: 0 | AC38: 10627 | AD38: 3207 | AE38: 4931.3333 | AF38: 0 | AG38: 0 | AH38: 677.73333 | AI38: 394.33333 | AJ38: 0 | AK38: =AD38+AE38+AF38+AG38+AH38+AI38+AJ38 -> 9210.4 | AL38: 70 | AM38: 1105 | AN38: 0 | AO38: 0 | AP38: 0 | AQ38: =AL38+AM38+AN38+AO38+AP38 -> 1175 | AR38: =AK38-AQ38 -> 8035.4 | AS38: 7th May 2020 | AT38: SBIN0014234 | AU38: 36071152580
A39: 25 | B39: GLDPL/LB/9025 | C39: 29 | D39: MANGALI LAVANYA | E39: 14/3/1985 | F39: Female | G39: MANGALI PANDU | I39: Nursery | J39: Unskilled Gardner | K39: H.no.3-10, | L39: Madhavaram,madharam,Medhak | M39: TS-502319 | O39: Gachibowli Village | P39: Hyderabad | Q39: Telangana State | S39: 43850 | X39: 101269710584 | Y39: 5214535728 | Z39: =D39 -> MANGALI LAVANYA | AA39: 26 | AB39: 0 | AC39: 10627 | AD39: 3207 | AE39: 4931.3333 | AF39: 0 | AG39: 0 | AH39: 677.73333 | AI39: 394.33333 | AJ39: 0 | AK39: =AD39+AE39+AF39+AG39+AH39+AI39+AJ39 -> 9210.4 | AL39: 70 | AM39: 1105 | AN39: 0 | AO39: 0 | AP39: 0 | AQ39: =AL39+AM39+AN39+AO39+AP39 -> 1175 | AR39: =AK39-AQ39 -> 8035.4 | AS39: 7th May 2020 | AT39: SBIN0014234 | AU39: 36071152502
A40: 26 | B40: GLDPL/LB/9026 | C40: 30 | D40: MANGLI CHANDRAMMA | E40: 25/3/1969 | F40: Female | G40: MANGALI VENKATESH | I40: Nursery | J40: Unskilled Gardner | K40: House no. - 3-33 Madharam, | L40: MADHARAM,MEDHAK | M40: Andhra pradesh - 502319 | O40: Gachibowli Village | P40: Hyderabad | Q40: Telangana State | S40: 43850 | X40: 101554508983 | Y40: 5216340615 | Z40: =D40 -> MANGLI CHANDRAMMA | AA40: 26 | AB40: 0 | AC40: 10627 | AD40: 3207 | AE40: 4931.3333 | AF40: 0 | AG40: 0 | AH40: 677.73333 | AI40: 394.33333 | AJ40: 0 | AK40: =AD40+AE40+AF40+AG40+AH40+AI40+AJ40 -> 9210.4 | AL40: 70 | AM40: 1105 | AN40: 0 | AO40: 0 | AP40: 0 | AQ40: =AL40+AM40+AN40+AO40+AP40 -> 1175 | AR40: =AK40-AQ40 -> 8035.4 | AS40: 7th May 2020 | AT40: APGV0008110 | AU40: 73100389136
A41: 27 | B41: GLDPL/LB/9027 | C41: 31 | D41: DASARI SUVARNA | E41: 32509 | F41: Female | G41: DASARI RAVINDAR | I41: Nursery | J41: Unskilled Gardner | K41: H.NO.11-50,GOPINAGAR,SERILINGMPLLI | L41: NEAR GVT SCHOOL LINGAMPALLI, | M41: KV R.R,TS-500019 | O41: Gachibowli Village | P41: Hyderabad | Q41: Telangana State | S41: 43850 | X41: 101521098686 | Y41: 5216116294 | Z41: =D41 -> DASARI SUVARNA | AA41: 0 | AB41: 0 | AC41: 10627 | AD41: 0 | AE41: 0 | AF41: 0 | AG41: 0 | AH41: 0 | AI41: 0 | AJ41: 0 | AK41: =AD41+AE41+AF41+AG41+AH41+AI41+AJ41 -> 0 | AL41: 0 | AM41: 0 | AN41: 0 | AO41: 0 | AP41: 0 | AQ41: =AL41+AM41+AN41+AO41+AP41 -> 0 | AR41: =AK41-AQ41 -> 0 | AS41: 7th May 2020 | AT41: ANDB0001414 | AU41: 141410100016831
A42: 28 | B42: GLDPL/LB/9028 | C42: 32 | D42: MARATHI CHANDRAKALA | E42: 31413 | F42: Female | G42: M ASHOKS | I42: Nursery | J42: Unskilled Gardner | K42: 3/32,janagampet | L42: patancheru,sultanpur,Medak | M42: TS-502319 | O42: Gachibowli Village | P42: Hyderabad | Q42: Telangana State | S42: 43850 | X42: 100127755377 | Y42: 5210266822 | Z42: =D42 -> MARATHI CHANDRAKALA | AA42: 26 | AB42: 0 | AC42: 10627 | AD42: 3207 | AE42: 4931.3333 | AF42: 0 | AG42: 0 | AH42: 677.73333 | AI42: 394.33333 | AJ42: 0 | AK42: =AD42+AE42+AF42+AG42+AH42+AI42+AJ42 -> 9210.4 | AL42: 70 | AM42: 1105 | AN42: 0 | AO42: 0 | AP42: 0 | AQ42: =AL42+AM42+AN42+AO42+AP42 -> 1175 | AR42: =AK42-AQ42 -> 8035.4 | AS42: 7th May 2020 | AT42: SBIN0014234 | AU42: 36363257797
A43: 29 | B43: GLDPL/LB/9029 | C43: 33 | D43: ANKAGALLA YADAMMA | E43: 32509 | F43: Female | G43: ANKAGALLA YADAGIRI | I43: Nursery | J43: Unskilled Gardner | K43: 26330 | L43: Sulthanpoor,patancheru,Sulthanpur | M43: TS-502319 | O43: Gachibowli Village | P43: Hyderabad | Q43: Telangana State | S43: 43850 | X43: 101553811711 | Y43: 5216340696 | Z43: =D43 -> ANKAGALLA YADAMMA | AA43: 26 | AB43: 0 | AC43: 10627 | AD43: 3207 | AE43: 4931.3333 | AF43: 0 | AG43: 0 | AH43: 677.73333 | AI43: 394.33333 | AJ43: 0 | AK43: =AD43+AE43+AF43+AG43+AH43+AI43+AJ43 -> 9210.4 | AL43: 70 | AM43: 1105 | AN43: 0 | AO43: 0 | AP43: 0 | AQ43: =AL43+AM43+AN43+AO43+AP43 -> 1175 | AR43: =AK43-AQ43 -> 8035.4 | AS43: 7th May 2020 | AT43: SBIN0014234 | AU43: 20176302412
A44: 30 | B44: GLDPL/LB/9030 | C44: 34 | D44: NINGAMMA | E44: 27395 | F44: Female | G44: RAMANNA | I44: Nursery | J44: Unskilled Gardner | K44: 5/4/256 | L44: Janatha colony,Bhalki,Bidar | M44: karnataka-585328 | O44: Gachibowli Village | P44: Hyderabad | Q44: Telangana State | S44: 43850 | X44: 101381353296 | Y44: 5215200706 | Z44: =D44 -> NINGAMMA | AA44: 26 | AB44: 0 | AC44: 10627 | AD44: 3207 | AE44: 4931.3333 | AF44: 0 | AG44: 0 | AH44: 677.73333 | AI44: 394.33333 | AJ44: 0 | AK44: =AD44+AE44+AF44+AG44+AH44+AI44+AJ44 -> 9210.4 | AL44: 70 | AM44: 1105 | AN44: 0 | AO44: 0 | AP44: 0 | AQ44: =AL44+AM44+AN44+AO44+AP44 -> 1175 | AR44: =AK44-AQ44 -> 8035.4 | AS44: 7th May 2020 | AT44: FDRL0001605 | AU44: 16050100039723
A45: 31 | B45: GLDPL/LB/9031 | C45: 35 | D45: V AMBAMMA | E45: 20/11/1980 | F45: Female | G45: V YELLAIAH | I45: Nursery | J45: Unskilled Gardner | K45: H.no.6-199/1 | L45: Narra basthi,Patancheru,Medak | M45: TS-502319 | O45: Gachibowli Village | P45: Hyderabad | Q45: Telangana State | S45: 43850 | X45: 101362702317 | Y45: 5216116335 | Z45: =D45 -> V AMBAMMA | AA45: 26 | AB45: 0 | AC45: 10627 | AD45: 3207 | AE45: 4931.3333 | AF45: 0 | AG45: 0 | AH45: 677.73333 | AI45: 394.33333 | AJ45: 0 | AK45: =AD45+AE45+AF45+AG45+AH45+AI45+AJ45 -> 9210.4 | AL45: 70 | AM45: 1105 | AN45: 0 | AO45: 0 | AP45: 0 | AQ45: =AL45+AM45+AN45+AO45+AP45 -> 1175 | AR45: =AK45-AQ45 -> 8035.4 | AS45: 7th May 2020 | AT45: ICIC0001111 | AU45: 111101515392
A46: 32 | B46: GLDPL/LB/9032 | C46: 36 | D46: PALLAPU LAXMI | E46: 21/3/1966 | F46: Female | G46: VENAKAIAH | I46: Nursery | J46: Unskilled Gardner | K46: 21245 | L46: Nagdar,kalher,medak | M46: AP-502371 | O46: Gachibowli Village | P46: Hyderabad | Q46: Telangana State | S46: 43850 | X46: 101362702340 | Y46: 5215200729 | Z46: =D46 -> PALLAPU LAXMI | AA46: 26 | AB46: 0 | AC46: 10627 | AD46: 3207 | AE46: 4931.3333 | AF46: 0 | AG46: 0 | AH46: 677.73333 | AI46: 394.33333 | AJ46: 0 | AK46: =AD46+AE46+AF46+AG46+AH46+AI46+AJ46 -> 9210.4 | AL46: 70 | AM46: 1105 | AN46: 0 | AO46: 0 | AP46: 0 | AQ46: =AL46+AM46+AN46+AO46+AP46 -> 1175 | AR46: =AK46-AQ46 -> 8035.4 | AS46: 7th May 2020 | AT46: APGV0008163 | AU46: 7310404993-5
A47: 33 | B47: GLDPL/LB/9033 | C47: 37 | D47: Nagani laxmi | E47: 27395 | F47: Female | G47: Nagani pochaiah | I47: Nursery | J47: Unskilled Gardner | K47: H.NO.3-18 | L47: MADHARAM,MEDHAK | M47: TS-502319 | O47: Gachibowli Village | P47: Hyderabad | Q47: Telangana State | S47: 43850 | X47: 100245723121 | Y47: 5213565032 | Z47: =D47 -> Nagani laxmi | AA47: 26 | AB47: 0 | AC47: 10627 | AD47: 3207 | AE47: 4931.3333 | AF47: 0 | AG47: 0 | AH47: 677.73333 | AI47: 394.33333 | AJ47: 0 | AK47: =AD47+AE47+AF47+AG47+AH47+AI47+AJ47 -> 9210.4 | AL47: 70 | AM47: 1105 | AN47: 0 | AO47: 0 | AP47: 0 | AQ47: =AL47+AM47+AN47+AO47+AP47 -> 1175 | AR47: =AK47-AQ47 -> 8035.4 | AS47: 7th May 2020 | AT47: SBIN0014234 | AU47: 38228068404
...

Sheet Employment Cards
B1: FORM XIV
B2: EMPLOYMENT CUM WAGE CARD
B3: (Vide Rule 76 of Contract Labour (R&A) Central & A.P{T.S.} Rules, 1971)
B4: Name and Address of the Contractor | H4: Name and Address of the Establishment in/under which Contract is carried on:
B7: =Master!F5 -> GROTECH LANDSCAPE DEVELOPERS PVT. LTD. | H7: =Master!AN5 -> GROTECH LANDSCAPE DEVELOPERS PVT. LTD.
B9: =Master!F6 -> 290/E, Khanapur Village, Gandipet Mandal, Ranga Reddy, Hyderabad-500075 T.S. | H9: =Master!AN6 -> 290/E, Khanapur Village, Gandipet Mandal, Ranga Reddy, Hyderabad-500075 T.S.
B12: Nature of work and location of work: | H12: Name and address of Principal Employer:
H15: ='Muster Roll'!Z6 -> INDIAN SCHOOL OF BUSINESS
B16: ='Muster Roll'!D4 -> GARDENING SERVICES&ISB HYDERABAD
H17: ='Muster Roll'!Z7 -> Opp.Infosys Limited,Gachibowli,Hyderabad
B19: 1. Name of the Workman and address | H19: =Master!D15 -> ARJUN KUMAR
H20: =Master!K15 -> Village - Dharai
H21: =Master!L15 -> Amethi
H22: =Master!M15 -> Uttar pradesh - 229127
H23: =Master!N15 -> 0
B24: 2. S.No. in the Register of Workmen Employed | H24: =Master!C15 -> 2
B25: 3. Nature of Employment /Designation | H25: =Master!J15 -> Supervisor
B26: 4. Date of entry into service | H26: =Master!S15 -> 43850
B27: 5. ESI No. | H27: =Master!Y15 -> 2016384651
B28: 6.PF No. | H28: =Master!X15 -> N/A
B29: 7. Wage rate (With particulars of unit in case of piece - work) | H29: =Master!AC15 -> 20000
B30: 8. Wage period | H30: =Master!F10 -> 44652
B31: 9. Tenure of Employment | H31: AS PER CONTRACT
B32: 10.No. of days worked in a month | H32: =Master!AA15 -> 30
B33: 11. No. of units worked in case of piece rate workers | H33: N/A
B34: 12. Rate of daily wages / piece rate | H34: 0
B35: 13. Amount of overtime wages | H35: 0
B36: 14. Gross wages payable | J36: =Master!AK15 -> 20000 | L36: ADVANCE
B37: 15. Deductions, if any, | D37: PF | E37: =Master!AM15 -> 0 | F37: ESI | G37: =Master!AL15 -> 150 | H37: PT | I37: =Master!AN15 -> 150 | J37: TDS | K37: =Master!AO15 -> 0 | L37: =Master!AP15 -> 0
B38: 16. Net amount of wages paid | J38: =Master!AR15 -> 19700
B39: Signature of the Representative
B40: of Contractor
B45: FORM XIV
B46: EMPLOYMENT CUM WAGE CARD
B47: (Vide Rule 76 of Contract Labour (R&A) Central & A.P{T.S.} Rules, 1971)
B48: Name and Address of the Contractor | H48: Name and Address of the Establishment in/under which Contract is carried on:
B51: =Master!F5 -> GROTECH LANDSCAPE DEVELOPERS PVT. LTD. | H51: =Master!AN5 -> GROTECH LANDSCAPE DEVELOPERS PVT. LTD.
B53: =Master!F6 -> 290/E, Khanapur Village, Gandipet Mandal, Ranga Reddy, Hyderabad-500075 T.S. | H53: =Master!AN6 -> 290/E, Khanapur Village, Gandipet Mandal, Ranga Reddy, Hyderabad-500075 T.S.
B56: Nature of work and location of work: | H56: Name and address of Principal Employer:
H59: =Master!AN10 -> INDIAN SCHOOL OF BUSINESS
...

Sheet Serive Certificate
B2: FORM XV
B3: [Vide rule 77 of Contract Labour (Regul. & Abolition) Central & A.P.{T.S.} Rules, 1971]
B4: SERVICE CERTIFICATE
B6: Name and address of Contractor : | G6: Name and address of establishment in / under which contract is caried on :
B8: =Master!F5 -> GROTECH LANDSCAPE DEVELOPERS PVT. LTD. | G8: =Master!AN5 -> GROTECH LANDSCAPE DEVELOPERS PVT. LTD.
B10: =Master!F6 -> 290/E, Khanapur Village, Gandipet Mandal, Ranga Reddy, Hyderabad-500075 T.S. | G10: =Master!AN6 -> 290/E, Khanapur Village, Gandipet Mandal, Ranga Reddy, Hyderabad-500075 T.S.
B14: Nature and Location of work: | G14: Name and address of Principal Employer :
G16: =Master!AN10 -> INDIAN SCHOOL OF BUSINESS
B18: =Master!F8 -> GARDENING SERVICES&ISB HYDERABAD | G18: =Master!AN11 -> Opp.Infosys Limited,Gachibowli,Hyderabad
B21: Name and address of the workman : | G21: =Master!D15 -> ARJUN KUMAR
G22: =Master!K15 -> Village - Dharai
G23: =Master!L15 -> Amethi
G24: =Master!M15 -> Uttar pradesh - 229127
B25: Age or date of Birth : | G25: =Master!E15 -> 31413
B26: Identification Marks :
B28: Father's / Husband's Name : | G28: =Master!G15 -> kallu
B30: Sl.No. | C30: Total period for which employed | E30: Nature of work done | G30: Rate of wage ( with particulars of units in case of piece work) | J30: Remarks
C32: From | D32: To
B33: 1 | C33: 2 | D33: 3 | E33: 4 | G33: 5 | J33: 6
B34: =Master!C15 -> 2 | C34: =Master!S15 -> 43850 | D34: ='Workmen Reg'!O12 -> 31st May 2020 | E34: =Master!J15 -> Supervisor | G34: =Master!AC15 -> 20000 | J34: =Master!V15 -> 0
H47: Signature of the Employer with Seal

Sheet Muster Roll
A1: FORM - XVI MUSTER ROLL [Vide Rule 78 (1) (a) (i) of Contract Labour (Reg. & Abolition) Central & AP{TS} Rules 1971]
A2: Name and address of Contractor: | D2: =Master!F5 -> GROTECH LANDSCAPE DEVELOPERS PVT. LTD. | J2: Name and address of Establishemnt in/ under which contract is carried on: | Z2: =Master!AN5 -> GROTECH LANDSCAPE DEVELOPERS PVT. LTD.
D3: =Master!F6 -> 290/E, Khanapur Village, Gandipet Mandal, Ranga Reddy, Hyderabad-500075 T.S. | Z3: =Master!AN6 -> 290/E, Khanapur Village, Gandipet Mandal, Ranga Reddy, Hyderabad-500075 T.S.
A4: Nature and location of work: | D4: =Master!F8 -> GARDENING SERVICES&ISB HYDERABAD
A6: Wage period: Monthly | D6: =Master!F10 -> 44652 | J6: Name and address of Principal Employer: | Z6: =Master!AN10 -> INDIAN SCHOOL OF BUSINESS
Z7: =Master!AN11 -> Opp.Infosys Limited,Gachibowli,Hyderabad
A8: S.No | B8: Name of Workman | C8: Father's/ Husband's Name | D8: Sex | AJ8: Remarks
E9: 1 | F9: 2 | G9: 3 | H9: 4 | I9: 5 | J9: 6 | K9: 7 | L9: 8 | M9: 9 | N9: 10 | O9: 11 | P9: 12 | Q9: 13 | R9: 14 | S9: 15 | T9: 16 | U9: 17 | V9: 18 | W9: 19 | X9: 20 | Y9: 21 | Z9: 22 | AA9: 23 | AB9: 24 | AC9: 25 | AD9: 26 | AE9: 27 | AF9: 28 | AG9: 29 | AH9: 30 | AI9: 31
A10: 1 | B10: =Master!D15 -> ARJUN KUMAR | C10: =Master!G15 -> kallu | D10: =Master!F15 -> Male | E10: p | F10: p | G10: p | H10: p | I10: w/o | J10: p | K10: p | L10: p | M10: p | N10: p | O10: p | P10: w/o | Q10: p | R10: p | S10: p | T10: p | U10: p | V10: p | W10: w/o | X10: p | Y10: p | Z10: p | AA10: p | AB10: p | AC10: p | AD10: w/o | AE10: p | AF10: p | AG10: p | AH10: p | AJ10: =Master!AA15 -> 30
A11: 2 | B11: =Master!D16 -> GAJAN SINGH | C11: =Master!G16 -> Chandrapal singh | D11: =Master!F16 -> Male | E11: p | F11: p | G11: p | H11: p | I11: w/o | J11: p | K11: p | L11: p | M11: p | N11: p | O11: p | P11: w/o | Q11: p | R11: p | S11: p | T11: p | U11: p | V11: p | W11: w/o | X11: p | Y11: p | Z11: p | AA11: p | AB11: p | AC11: p | AD11: w/o | AE11: p | AF11: p | AG11: p | AH11: p | AJ11: =Master!AA16 -> 30
A12: 3 | B12: =Master!D17 -> GUDALA RUSHESHWAR SWAMY | C12: =Master!G17 -> GUDALA KRISHANA MURTHY | D12: =Master!F17 -> Male | E12: c | F12: C | G12: c | H12: c | I12: w/o | J12: c | K12: c | L12: c | M12: c | N12: c | O12: c | P12: w/o | Q12: c | R12: c | S12: C | T12: c | U12: c | V12: c | W12: w/o | X12: c | Y12: c | Z12: c | AA12: C | AB12: c | AC12: c | AD12: w/o | AE12: c | AF12: c | AG12: c | AH12: c | AJ12: =Master!AA17 -> 30
A13: 4 | B13: =Master!D18 -> KASALA NARSIMLU | C13: =Master!G18 -> KASALA POCHAIAH | D13: =Master!F18 -> Male | E13: c | F13: C | G13: c | H13: c | I13: w/o | J13: c | K13: c | L13: c | M13: c | N13: c | O13: c | P13: w/o | Q13: c | R13: c | S13: C | T13: c | U13: c | V13: c | W13: w/o | X13: c | Y13: c | Z13: c | AA13: C | AB13: c | AC13: c | AD13: w/o | AE13: c | AF13: c | AG13: C | AH13: c | AJ13: =Master!AA18 -> 26
A14: 5 | B14: =Master!D19 -> PITANI SATHYA NARAYANA | C14: =Master!G19 -> P SURYANARAYANA | D14: =Master!F19 -> Male | E14: c | F14: C | G14: c | H14: c | I14: w/o | J14: c | K14: c | L14: c | M14: c | N14: c | O14: c | P14: w/o | Q14: c | R14: c | S14: C | T14: c | U14: c | V14: c | W14: w/o | X14: c | Y14: c | Z14: c | AA14: C | AB14: c | AC14: c | AD14: w/o | AE14: c | AF14: c | AG14: C | AH14: c | AJ14: =Master!AA19 -> 26
A15: 6 | B15: =Master!D20 -> SANGOLLA ASHOK | C15: =Master!G20 -> SANGOLLA ESWARAIAH | D15: =Master!F20 -> Male | E15: c | F15: C | G15: c | H15: c | I15: w/o | J15: c | K15: c | L15: c | M15: c | N15: c | O15: c | P15: w/o | Q15: c | R15: c | S15: C | T15: c | U15: c | V15: c | W15: w/o | X15: c | Y15: c | Z15: c | AA15: C | AB15: c | AC15: c | AD15: w/o | AE15: c | AF15: c | AG15: C | AH15: c | AJ15: =Master!AA20 -> 26
A16: 7 | B16: =Master!D21 -> ASHOK LINGURAM GAIKWAD | C16: =Master!G21 -> M LINGRAM | D16: =Master!F21 -> Male | E16: c | F16: C | G16: c | H16: c | I16: w/o | J16: c | K16: c | L16: c | M16: c | N16: c | O16: c | P16: w/o | Q16: c | R16: c | S16: C | T16: c | U16: c | V16: c | W16: w/o | X16: c | Y16: c | Z16: c | AA16: C | AB16: c | AC16: c | AD16: w/o | AE16: c | AF16: c | AG16: C | AH16: c | AJ16: =Master!AA21 -> 26
A17: 8 | B17: =Master!D22 -> MADHUKAR KAMTAM | C17: =Master!G22 -> KAMTAM KISHAN | D17: =Master!F22 -> Male | E17: c | F17: C | G17: c | H17: c | I17: w/o | J17: c | K17: c | L17: c | M17: c | N17: c | O17: c | P17: w/o | Q17: c | R17: c | S17: C | T17: c | U17: c | V17: c | W17: w/o | X17: c | Y17: c | Z17: c | AA17: C | AB17: c | AC17: c | AD17: w/o | AE17: c | AF17: c | AG17: C | AH17: c | AJ17: =Master!AA22 -> 26
A18: 9 | B18: =Master!D23 -> Ningolla Raju | C18: =Master!G23 -> ningolla pochaiah | D18: =Master!F23 -> Male | E18: c | F18: C | G18: c | H18: c | I18: w/o | J18: c | K18: c | L18: c | M18: c | N18: c | O18: c | P18: w/o | Q18: c | R18: c | S18: C | T18: c | U18: c | V18: c | W18: w/o | X18: c | Y18: c | Z18: c | AA18: C | AB18: c | AC18: c | AD18: w/o | AE18: c | AF18: c | AG18: C | AH18: c | AJ18: =Master!AA23 -> 26
A19: 10 | B19: =Master!D24 -> Nagani pochaiah | C19: =Master!G24 -> Nagani mallaiah | D19: =Master!F24 -> Male | E19: c | F19: C | G19: c | H19: c | I19: w/o | J19: c | K19: c | L19: c | M19: c | N19: c | O19: c | P19: w/o | Q19: c | R19: c | S19: C | T19: c | U19: c | V19: c | W19: w/o | X19: c | Y19: c | Z19: c | AA19: C | AB19: c | AC19: c | AD19: w/o | AE19: c | AF19: c | AG19: C | AH19: c | AJ19: =Master!AA24 -> 26
A20: 11 | B20: =Master!D25 -> Mutholla Mallesh | C20: =Master!G25 -> Mutholla balaiah | D20: =Master!F25 -> Male | E20: c | F20: C | G20: c | H20: c | I20: w/o | J20: c | K20: c | L20: c | M20: c | N20: c | O20: c | P20: w/o | Q20: c | R20: c | S20: C | T20: c | U20: c | V20: c | W20: w/o | X20: c | Y20: c | Z20: c | AA20: C | AB20: c | AC20: c | AD20: w/o | AE20: c | AF20: c | AG20: C | AH20: c | AJ20: =Master!AA25 -> 26
A21: 12 | B21: =Master!D26 -> ALIJANA JAYARAMI REDDY | C21: =Master!G26 -> ALIJANA OBULU REDDY | D21: =Master!F26 -> Male | E21: c | F21: C | G21: c | H21: c | I21: w/o | J21: c | K21: c | L21: c | M21: c | N21: c | O21: c | P21: w/o | Q21: c | R21: c | S21: C | T21: c | U21: c | V21: c | W21: w/o | X21: c | Y21: c | Z21: c | AA21: C | AB21: c | AC21: c | AD21: w/o | AE21: c | AF21: c | AG21: C | AH21: c | AJ21: =Master!AA26 -> 26
A22: 13 | B22: =Master!D27 -> Kapil | C22: =Master!G27 -> Ganesh lal | D22: =Master!F27 -> Male | AJ22: =Master!AA27 -> 0
A23: 14 | B23: =Master!D28 -> Bablu kumar | C23: =Master!G28 -> Harilal | D23: =Master!F28 -> Male | AJ23: =Master!AA28 -> 0
A24: 15 | B24: =Master!D29 -> Pradeep kumar | C24: =Master!G29 -> Jagdev | D24: =Master!F29 -> Male | AJ24: =Master!AA29 -> 0
A25: 16 | B25: =Master!D30 -> SHAIK KULSUM BEE | C25: =Master!G30 -> SHAIK LALA | D25: =Master!F30 -> Female | E25: c | F25: C | G25: c | H25: c | I25: w/o | J25: c | K25: c | L25: c | M25: c | N25: c | O25: c | P25: w/o | Q25: c | R25: c | S25: C | T25: c | U25: c | V25: c | W25: w/o | X25: c | Y25: c | Z25: c | AA25: C | AB25: c | AC25: c | AD25: w/o | AE25: c | AF25: c | AG25: C | AH25: c | AJ25: =Master!AA30 -> 26
A26: 17 | B26: =Master!D31 -> S GOWRI | C26: =Master!G31 -> S SURYANARAYANA | D26: =Master!F31 -> Female | E26: c | F26: C | G26: c | H26: c | I26: w/o | J26: c | K26: c | L26: c | M26: c | N26: c | O26: c | P26: w/o | Q26: c | R26: c | S26: C | T26: c | U26: c | V26: c | W26: w/o | X26: c | Y26: c | Z26: c | AA26: C | AB26: c | AC26: c | AD26: w/o | AE26: c | AF26: c | AG26: C | AH26: c | AJ26: =Master!AA31 -> 26
A27: 18 | B27: =Master!D32 -> FARZANA BEGUM | C27: =Master!G32 -> SHAIK MASTAN WALI | D27: =Master!F32 -> Female | E27: c | F27: C | G27: c | H27: c | I27: w/o | J27: c | K27: c | L27: c | M27: c | N27: c | O27: c | P27: w/o | Q27: c | R27: c | S27: C | T27: c | U27: c | V27: c | W27: w/o | X27: c | Y27: c | Z27: c | AA27: C | AB27: c | AC27: c | AD27: w/o | AE27: c | AF27: c | AG27: C | AH27: c | AJ27: =Master!AA32 -> 26
A28: 19 | B28: =Master!D33 -> MANAGALI SUHASINI | C28: =Master!G33 -> MANGALI RAJU | D28: =Master!F33 -> Female | E28: c | F28: C | G28: c | H28: c | I28: w/o | J28: c | K28: c | L28: c | M28: c | N28: c | O28: c | P28: w/o | Q28: c | R28: c | S28: C | T28: c | U28: c | V28: c | W28: w/o | X28: c | Y28: c | Z28: c | AA28: C | AB28: c | AC28: c | AD28: w/o | AE28: c | AF28: c | AG28: C | AH28: c | AJ28: =Master!AA33 -> 26
A29: 20 | B29: =Master!D34 -> KONA SUJATHA | C29: =Master!G34 -> KONA SURYANARAYANA | D29: =Master!F34 -> Female | E29: c | F29: C | G29: c | H29: c | I29: w/o | J29: c | K29: c | L29: c | M29: c | N29: c | O29: c | P29: w/o | Q29: c | R29: c | S29: C | T29: c | U29: c | V29: c | W29: w/o | X29: c | Y29: c | Z29: c | AA29: C | AB29: c | AC29: c | AD29: w/o | AE29: c | AF29: c | AG29: C | AH29: c | AJ29: =Master!AA34 -> 26
A30: 21 | B30: =Master!D35 -> GOLLA UMA | C30: =Master!G35 -> GOLLA ONURU SWAMY | D30: =Master!F35 -> Female | E30: c | F30: C | G30: c | H30: c | I30: w/o | J30: c | K30: c | L30: c | M30: c | N30: c | O30: c | P30: w/o | Q30: c | R30: c | S30: C | T30: c | U30: c | V30: c | W30: w/o | X30: c | Y30: c | Z30: c | AA30: C | AB30: c | AC30: c | AD30: w/o | AE30: c | AF30: c | AG30: C | AH30: c | AJ30: =Master!AA35 -> 26
A31: 22 | B31: =Master!D36 -> SINGARAM BHAGYAMMA | C31: =Master!G36 -> SINGARAM NARSIMULU | D31: =Master!F36 -> Female | E31: c | F31: C | G31: c | H31: c | I31: w/o | J31: c | K31: c | L31: c | M31: c | N31: c | O31: c | P31: w/o | Q31: c | R31: c | S31: C | T31: c | U31: c | V31: c | W31: w/o | X31: c | Y31: c | Z31: c | AA31: C | AB31: c | AC31: c | AD31: w/o | AE31: c | AF31: c | AG31: C | AH31: c | AJ31: =Master!AA36 -> 26
A32: 23 | B32: =Master!D37 -> KODICHERLA INDIRAMMA | C32: =Master!G37 -> BABAIAH | D32: =Master!F37 -> Female | E32: c | F32: C | G32: c | H32: c | I32: w/o | J32: c | K32: c | L32: c | M32: c | N32: c | O32: c | P32: w/o | Q32: c | R32: c | S32: C | T32: c | U32: c | V32: c | W32: w/o | X32: c | Y32: c | Z32: c | AA32: C | AB32: c | AC32: c | AD32: w/o | AE32: c | AF32: c | AG32: C | AH32: c | AJ32: =Master!AA37 -> 26
A33: 24 | B33: =Master!D38 -> SANGOLLA LAVANYA | C33: =Master!G38 -> SANGOLLA ASHOK | D33: =Master!F38 -> Female | E33: c | F33: C | G33: c | H33: c | I33: w/o | J33: c | K33: c | L33: c | M33: c | N33: c | O33: c | P33: w/o | Q33: c | R33: c | S33: C | T33: c | U33: c | V33: c | W33: w/o | X33: c | Y33: c | Z33: c | AA33: C | AB33: c | AC33: c | AD33: w/o | AE33: c | AF33: c | AG33: C | AH33: c | AJ33: =Master!AA38 -> 26
A34: 25 | B34: =Master!D39 -> MANGALI LAVANYA | C34: =Master!G39 -> MANGALI PANDU | D34: =Master!F39 -> Female | E34: c | F34: C | G34: c | H34: c | I34: w/o | J34: c | K34: c | L34: c | M34: c | N34: c | O34: c | P34: w/o | Q34: c | R34: c | S34: C | T34: c | U34: c | V34: c | W34: w/o | X34: c | Y34: c | Z34: c | AA34: C | AB34: c | AC34: c | AD34: w/o | AE34: c | AF34: c | AG34: C | AH34: c | AJ34: =Master!AA39 -> 26
A35: 26 | B35: =Master!D40 -> MANGLI CHANDRAMMA | C35: =Master!G40 -> MANGALI VENKATESH | D35: =Master!F40 -> Female | E35: c | F35: C | G35: c | H35: c | I35: w/o | J35: c | K35: c | L35: c | M35: c | N35: c | O35: c | P35: w/o | Q35: c | R35: c | S35: C | T35: c | U35: c | V35: c | W35: w/o | X35: c | Y35: c | Z35: c | AA35: C | AB35: c | AC35: c | AD35: w/o | AE35: c | AF35: c | AG35: C | AH35: c | AJ35: =Master!AA40 -> 26
A36: 27 | B36: =Master!D41 -> DASARI SUVARNA | C36: =Master!G41 -> DASARI RAVINDAR | D36: =Master!F41 -> Female | AJ36: =Master!AA41 -> 0
A37: 28 | B37: =Master!D42 -> MARATHI CHANDRAKALA | C37: =Master!G42 -> M ASHOKS | D37: =Master!F42 -> Female | E37: c | F37: C | G37: c | H37: c | I37: w/o | J37: c | K37: c | L37: c | M37: c | N37: c | O37: c | P37: w/o | Q37: c | R37: c | S37: C | T37: c | U37: c | V37: c | W37: w/o | X37: c | Y37: c | Z37: c | AA37: C | AB37: c | AC37: c | AD37: w/o | AE37: c | AF37: c | AG37: C | AH37: c | AJ37: =Master!AA42 -> 26
A38: 29 | B38: =Master!D43 -> ANKAGALLA YADAMMA | C38: =Master!G43 -> ANKAGALLA YADAGIRI | D38: =Master!F43 -> Female | E38: c | F38: C | G38: c | H38: c | I38: w/o | J38: c | K38: c | L38: c | M38: c | N38: c | O38: c | P38: w/o | Q38: c | R38: c | S38: C | T38: c | U38: c | V38: c | W38: w/o | X38: c | Y38: c | Z38: c | AA38: C | AB38: c | AC38: c | AD38: w/o | AE38: c | AF38: c | AG38: C | AH38: c | AJ38: =Master!AA43 -> 26
A39: 30 | B39: =Master!D44 -> NINGAMMA | C39: =Master!G44 -> RAMANNA | D39: =Master!F44 -> Female | E39: c | F39: C | G39: c | H39: c | I39: w/o | J39: c | K39: c | L39: c | M39: c | N39: c | O39: c | P39: w/o | Q39: c | R39: c | S39: C | T39: c | U39: c | V39: c | W39: w/o | X39: c | Y39: c | Z39: c | AA39: C | AB39: c | AC39: c | AD39: w/o | AE39: c | AF39: c | AG39: C | AH39: c | AJ39: =Master!AA44 -> 26
A40: 31 | B40: =Master!D45 -> V AMBAMMA | C40: =Master!G45 -> V YELLAIAH | D40: =Master!F45 -> Female | E40: c | F40: C | G40: c | H40: c | I40: w/o | J40: c | K40: c | L40: c | M40: c | N40: c | O40: c | P40: w/o | Q40: c | R40: c | S40: C | T40: c | U40: c | V40: c | W40: w/o | X40: c | Y40: c | Z40: c | AA40: C | AB40: c | AC40: c | AD40: w/o | AE40: c | AF40: c | AG40: C | AH40: c | AJ40: =Master!AA45 -> 26
A41: 32 | B41: =Master!D46 -> PALLAPU LAXMI | C41: =Master!G46 -> VENAKAIAH | D41: =Master!F46 -> Female | E41: c | F41: C | G41: c | H41: c | I41: w/o | J41: c | K41: c | L41: c | M41: c | N41: c | O41: c | P41: w/o | Q41: c | R41: c | S41: C | T41: c | U41: c | V41: c | W41: w/o | X41: c | Y41: c | Z41: c | AA41: C | AB41: c | AC41: c | AD41: w/o | AE41: c | AF41: c | AG41: C | AH41: c | AJ41: =Master!AA46 -> 26
...

Sheet Leave register
B1: FORM XXV- REGISTER OF LEAVE
B3: (Vide Rule 29(6) of A.P.{T.S.} Shops & Establishments Rules,1990)
B4: Name and address of the Establishment/Shop: | F4: =Master!F5 -> GROTECH LANDSCAPE DEVELOPERS PVT. LTD. | I4: Name of the Employee:
C5: =Master!F6 -> 290/E, Khanapur Village, Gandipet Mandal, Ranga Reddy, Hyderabad-500075 T.S. | I5: =Master!D15 -> ARJUN KUMAR
B7: Registration Number:
I8: Father’s / Husband’s Name:
I9: =Master!G15 -> kallu
I10: Date of appointment : | L10: =Master!S15 -> 43850
B11: Date of Application | C11: APPLIED | F11: No. of Days to which the employee is entitled | G11: LEAVE GRANTED | J11: Balance | K11: IF REFUSED IN PART OR FULL | N11: REASONS | O11: SIGNATURE OF
C12: Form(Date) | D12: To(Date) | E12: No. of Days | G12: Form(Date) | H12: To(Date) | I12: No. of Days | K12: Form(Date) | L12: To(Date) | M12: No. of Days | O12: Employee | P12: Employer
B13: 1 | C13: 2 | D13: 3 | E13: 4 | F13: 5 | G13: 6 | H13: 7 | I13: 8 | J13: 9 | K13: 10 | L13: 11 | M13: 12 | N13: 13 | O13: 14 | P13: 15
B14: LEAVE WITH WAGES
B15: JAN'20 | C15: 0 | D15: 0 | E15: 0 | F15: 1 | G15: 0 | H15: 0 | I15: 0 | J15: 1 | K15: NO | L15: N/A | M15: N/A | N15: N/A
B23: SICK LEAVE
B27: CASUAL LEAVE

Sheet wages Reg
A1: FORM - XVII REGISTER OF WAGES [Vide Rule 78 (1) (a) (i) of Contract Labour (Reg. & Abolition) Central & A.P.{T.S.}.Rules 1971]
A3: Name and address of Contractor: | D3: =Master!F5 -> GROTECH LANDSCAPE DEVELOPERS PVT. LTD. | O3: Name and address of Establishemnt in/ under which contract is carried on: | U3: =Master!AN5 -> GROTECH LANDSCAPE DEVELOPERS PVT. LTD.
D4: =Master!F6 -> 290/E, Khanapur Village, Gandipet Mandal, Ranga Reddy, Hyderabad-500075 T.S. | U4: =Master!AN6 -> 290/E, Khanapur Village, Gandipet Mandal, Ranga Reddy, Hyderabad-500075 T.S.
A5: Nature and location of work: | D5: =Master!F8 -> GARDENING SERVICES&ISB HYDERABAD
A7: Wage period: Monthly | D7: =Master!F10 -> 44652 | O7: Name and address of Principal Employer: | U7: =Master!AN10 -> INDIAN SCHOOL OF BUSINESS
U8: =Master!AN11 -> Opp.Infosys Limited,Gachibowli,Hyderabad
A10: S.No | B10: Name of Workman | C10: Serial No. in the Register of Workmen | D10: Designation / Nature of Work Done | E10: No.of Days worked | F10: Unit of work done | G10: Monthly rate of wages/ piece rate | H10: Basic wages | I10: Dearness Allowances | J10: Over time | K10: (Other cash payments(Nature of payments to be indicated) | O10: TOTAL AMOUNT | P10: Deductions, if any, (Indicate nature) | V10: Net Amount paid | W10: Time and Date of Payment | X10: Place of Payment | Y10: Signature/Thumb Impression of workman | Z10: Initial of Contractor or his representative
K11: HRA | L11: BONUS | M11: LTA | N11: SPECIAL ALLOWNANCES | P11: ESI | Q11: PF | R11: PT | S11: TDS | T11: Advance | U11: Total Deductions
