Workbook

Sheet HYD SEZ-APRIL -22WM Reg
A1: FORM - XIII REGISTER OF WORKMEN EMPLOYED BY CONTRACTOR
A2: (Vide Rule 75 of Contract Labour (Regulation and Abolition) Central/Telangana/A.P. Rules 1971)
A3: Name and address of Contractor: | F3: Burgeon IT Services Pvt.Ltd. | J3: Name and address of Establishemnt in/under which contract is carried on: | K3: Burgeon IT Services Pvt.Ltd.
F4: Siri Mansion LIGB 436 Dr.A S Rao Nagar,Hyderabad | K4: Siri Mansion LIGB 436 Dr.A S Rao Nagar,Hyderabad
A5: Nature and location of work: | F5: IT SUPPORTIVE SERVICES & HYDERABAD SEZ
A7: Wage period: Monthly | J7: Name and address of Principal Employer: | K7: INFOSYS LTD.HYDERABAD-STP
K8: Sy.No 210,Manikonda Village,Serilingampally Mandal,RR District,TS
A11: Serial No. in the Register of Workmen | B11: Name of Workman | C11: Age | D11: Sex | E11: Father's /Husband Name | F11: Designation / Nature of Work Done | G11: Permanent Address | H11: Local Address | I11: Date of Commencement of Employment | J11: Signature or thumb impression of Workman | K11: Date of termination of Employment | L11: Reasons for termination | M11: Remarks
A13: 13 | B13: Sameer Sheikh | C13: 02.10.1986 | D13: Male | E13: Mahaboob Shaikh | F13: TECHNICAL CONSULTATNT | G13: Room No.4,Kalbhor nagar,Opp: Ansari White ,Chinchwada , | H13: Pocharam,Ghatkesaer,Hyderabad,TS | I13: 16.04.2018 | K13: 43205 | L13: Resigned
A14: 14 | B14: Satish Makena | C14: 05.08.1979 | D14: Male | E14: M N Parthrudu | F14: TECHNICAL CONSULTATNT | G14: Door No.58-18-28/1, Near Ravindra Bharat School,N A D Kotla Road,Vizag 530027 | H14: S R T# 573,3rd Floor,Sanath nagar,Hyderabad,TS | I14: 01.06.2018 | K14: 43676 | L14: Resigned
A15: 15 | B15: SANDEEP CHARY BANALA | C15: 04.03.1991 | D15: Male | E15: RAMACHARI | F15: TECHNICAL CONSULTATNT | G15: #12-1-105/46, Sreenivasa nagar colony,bandlaguda,hyderabad,TS | H15: #12-1-105/46, Sreenivasa nagar colony,Bandlaguda,HYD,TS | I15: 25.06.2018 | K15: 30.6.2019 | L15: Resigned
A16: 16 | B16: Venkatarami reddy Naga | C16: 19.01.1986 | D16: Male | E16: Ramana Reddy | F16: TECHNICAL CONSULTATNT | G16: 10-31, Chemuduru Street, Badvel, Caddapah, Ap 516227 | H16: 8-3-136, Pallebalayya Nilayam, Yousufguda, Hyderabad 500045 | I16: 43276 | K16: 43371 | L16: Resigned
A17: 17 | B17: Burra Rajkumar vishal kumar | C17: 19.01.1986 | D17: Male | E17: B RAJKUMAR | F17: TECHNICAL CONSULTATNT | G17: Plot No 13, Kasthuri Cooperative Housing Society,Secunderabad | H17: Plot No 13, Kasthuri Cooperative Housing Society,Old Bowenpally,Secunderabad,TS | I17: 43290 | K17: 43734 | L17: Resigned
A18: 18 | B18: Benjamine Lee | C18: 19.10.1980 | D18: Male | E18: RICHARD LEE | F18: TECHNICAL CONSULTATNT | G18: #509, Tower G,PBEL City,Old Bowenpally,Peeramchervu,Rajendra nagar Mandal,Hyderabad | H18: #509, Tower G,PBEL City,Peeramchervu,Rajendra nagar Mandal, | I18: 43291 | K18: 43602 | L18: Resigned
A19: 19 | B19: DHARANIPARAGADA KEERTHI KIRIT | C19: 27.04.1987 | D19: Male | E19: SESHAGIRI RAO | F19: TECHNICAL CONSULTATNT | G19: #8-3-1020/1, Plot No 25,Srinagar Colony,Yella reddy guda,hyderabad | H19: #8-3-1020/1, Plot No 25,Srinagar Colony,Yella reddy guda,Hyderabad ,TS | I19: 43292 | K19: 43738 | L19: Resigned
A20: 20 | B20: Sreejith Nair | C20: 02.06.1991 | D20: Male | E20: SREEDHARAN | F20: TECHNICAL CONSULTATNT | G20: B-803,Raheja vistas,Road No.12,IDA nacharam,hyderabad | H20: B-803,Raheja vistas,Road No.12,IDA Nacharam,Hyderabad | I20: 43313 | K20: 43738 | L20: Resigned
A21: 21 | B21: S BHARADWAJ KOLLURU | C21: 01.08.1985 | D21: Male | E21: KAMESHWARA SHARMA | F21: TECHNICAL CONSULTATNT | G21: #4-110/24,Plot No.6 BNR Enclave,Nagaram,RR | H21: #4-110/24,Plot No.6 BNR Enclave,Nagaram,HYDEARAD,TS | I21: 43313 | K21: 43637 | L21: Resigned
A22: 22 | B22: Mamidala Rakesh Reddy | C22: 25.02.1987 | D22: Male | E22: RAVINDRA REDDY | F22: TECHNICAL CONSULTATNT | G22: #10-4-183, Road No.3 Dharmapuri Colony,SAROOR NAGAR,HYDERABAD | H22: Plot No.130, H.No 12-1-256/133,Road No.5,Krushinagar Colony,Bandlaguda,HYDEARAD,TS | I22: 43319 | K22: 43665 | L22: Resigned
A23: 23 | B23: Allwyn Bangera | C23: 7.9.1987 | D23: Male | E23: Prabhakar | F23: TECHNICAL CONSULTATNT | G23: Flat No 32077, Janapriya Apts, Attapur, Hyderabad | H23: A-403, Jigar Apartments, Yogidham, Kalyan | I23: 43321 | K23: 43434 | L23: Resigned
A24: 24 | B24: Nandan Sujati | C24: 08.11.1985 | D24: Male | E24: ASHWANI SUJATI | F24: TECHNICAL CONSULTATNT | G24: 37,Suncity I ,ROPAR,PUNJAB,1400001 | H24: GE-Block -A Jain Shrikar Auroville,Near N-Convention centre,HYDEARAAD,TS | I24: 43326 | K24: 43665 | L24: Resigned
A25: 25 | B25: AMIT MOHAN | C25: 09.09.1985 | D25: Male | E25: BIJAY KUMAR MALLIK | F25: TECHNICAL CONSULTATNT | G25: L N Nagar,Mujafar pur,BIHAR,843116 | H25: #407, Gerbera Bhanu Township,Miyapur,Hyderabad,TS | I25: 43271 | K25: 43677 | L25: Resigned
A26: 26 | B26: Bharath Dommaraju | C26: 01.07.1978 | D26: Male | E26: CHENCHURAJU DOMMARAJU | F26: TECHNICAL CONSULTATNT | G26: H No 505, 2nd Floor 1st Main,5th east,NGEF kasthuri nagar,bangalore | H26: Flat no 201,Sri nilayam appartments,Street No.7 Patrikanagar Madhapur,HYD,TS | I26: 43362 | K26: 43494 | L26: Resigned
A27: 27 | B27: Ritesh Solomon | C27: 10.09.1985 | D27: Male | E27: NADHAN SOLOMON | F27: TECHNICAL CONSULTATNT | G27: 134/67, Chaklal Mohammad,NAINI,ALAHABAD | H27: Room 402,H No 1-57/93, Rajiv nagar,Gachibowli,HYD,TS | I27: 43346 | K27: 43738 | L27: Resigned
... A32: 33 | B32: Prakruthi K Murthy | C32: 28.05.1994 | D32: Female | E32: KRISHNA MURTHY | F32: TECHNICAL CONSULTATNT | G32: #24/6, Sree rama Mandir road,Basavanna gudi,bongalore,karnataka560004 | H32: #1204, Raheja vistas Road no.12 ,IDA Nacharam,HYD,TS | I32: 43416 | K32: 43714 | L32: Resigned
A33: 34 | B33: Arun Kohli8 | C33: 22.4.1984 | D33: Male | E33: Kewal Kohli | F33: TECHNICAL CONSULTATNT | G33: Gk pride Apts, Flat No 304, Block 6, Balaji Nagar road, Yapral, Secunderabad -87 | H33: Flat nO 505,5th Floor, khanamet village, GHMC serilingampally, Rangareddy, Hyderabad | I33: 7.1-2019 | K33: 43714 | L33: Resigned
A34: 35 | B34: Sravan Kumar Mupparaju | C34: 10.05.1991 | D34: Male | E34: RAMBABU | F34: TECHNICAL CONSULTATNT | G34: #8-5 Vishnalayam Street | H34: HIG-27, Krishna Nilayam,KPHB Colony,HYD,TS | I34: 43493 | K34: 43646 | L34: Resigned
A35: 36 | B35: Vidyasagar Rao Annamaneni | C35: 13.08.1984 | D35: Male | E35: SUDHAKAR RAO | F35: TECHNICAL CONSULTATNT | G35: #2-35,Narayanapur | H35: Plot No. 1064&1065, Flat No.203,Sai Kuteer Appts.,Pragathinagar,Kukatpally,Hyderabad | I35: 43503 | K35: 43553 | L35: Resigned
A36: 37 | B36: Nagarjuna Sriramoju | C36: 19.12.1990 | D36: Male | E36: Sathyanarayana Sriramoju | F36: TECHNICAL CONSULTATNT | G36: 9-4-582,Sapthagiri Colony,Karimnagar,5050001 | H36: EWS, 767&768, Road No : 3,KPHB Colony, Hyderabad,TS | I36: 43619 | J36: STP Branch | K36: 44035 | L36: Resigned
A37: 38 | B37: Gopi Bollu | C37: 13.06.1982 | D37: Male | E37: YADAIAH YADHAV | F37: SERVICE DELIEVARY SPECIALIST | G37: #10-3-365/5 Michael Mansion 1st Phase,edan colony,bidar ,,karnataka | H37: #1-9-318,Shakuntha nivas Flat No 402,Vidyanagar,HYDERABAD,TS | I37: 43647 | L37: Resigned
A38: 39 | B38: Bharath Varma P | C38: 15.07.1994 | D38: Male | E38: Trinath Raju | F38: Technical consultant | G38: D No 3-141, Elampod,anakoderu post West godavari 534208 | H38: plot no 432, Road No 14/6, Vasanth Nagar, KPHB, Hyderabad, Telangana | I38: 43801
A39: 40 | B39: Prashanth Inti | C39: 11-06-1990 | D39: Male | E39: TVS suryanarayana | F39: SALESFORCE DEVOLOPERS | G39: 18-175/1, road number: 4, Hanmanupet, Malkajagiri,Hyderabad-500047 | H39: 18-175/1, road number: 4, Hanmanupet, Malkajagiri,Hyderabad-500047 | I39: 10-12-2019
A40: 41 | B40: kaja Venkat Ragavendra | C40: 26-05-1990 | D40: Male | E40: Kaja Suresh Babu | F40: SR.Application Consultant | G40: Kidambi Residency, Flat no 6, Agraharam, Guntur, 522003 | H40: Reddy's Avenue, Road no 28, HNO 59, Nizampet, Hyderabad 500090 | I40: 03-02-2020 | Q40: 1
A41: 42 | B41: Ramu Yetukuri | C41: 05-10-1992 | D41: Male | E41: Yetukuri Ravi | F41: SALESFORCE CONSULTANT | G41: H.NO : 2-19,Kotapadu Village,Raghunadhapalem(M), Khammam,507182 | H41: SaiBaba Hostel, roomno: 501, Near :Infosys, Pocharam ,Hyderabad, 500088 | I41: 24-02-2020 | K41: 27-01-2020 | L41: Resigned
A42: 43 | B42: Srinivas Marukurthi | C42: 06-07-1980 | D42: Male | E42: VEERRAJU | F42: Technical conusltant | G42: DOOR-NO: 2-226,RICE MILL STREET ,DUPPALAPUDI VILLAGE, ANPARTHI MANDAL,EAST GODAVARI DISTRICT,AP | H42: FLAT-NO: 102,SHRIKA & SRIDHA TERA ENCLAVE,SRI RAM NAGAR COLONY,BESIDE GOWTHAMI MODEL SCHOOL,MANIKONDA,HYD,TS | I42: 24-02-2020 | K42: 30-4-2020 | L42: Resigned
A43: 44 | B43: Devanand Jorige | C43: 27/12/1995 | D43: Male | E43: Chinnamurthi | F43: Mainframe Scheduler | G43: #24-222 AVR COLONY VELPUR,THANUKU.MND,WEST GODHAVARI,AP | H43: MIG-II 253,3RD FLOUR,KPHP 9TH PHASE,HYD | I43: 02-03-2020 | K43: 15-1-2020 | L43: Resigned
A44: 45 | B44: Fareeda Tarannum | C44: 23/05/1979 | D44: Female | E44: shaidd noor ahmed | F44: Qlikviev Devoloper | G44: Flot no.501,AR rahim opportment,taramount colony.tollychouk hyderabad | H44: flot no.501,AR rahim opportment,taramount colony.tollychouk hyderabad | I44: 08-04-2020 | K44: 30-2-2021 | L44: Resigned
A45: 46 | B45: Pulipati Kaushik | C45: 08-05-1994 | D45: Male | E45: Venkataramana | F45: Dynamic CRM Devoloper | G45: #3-29-10/A,krishnanagar 3rd lane,guntur.AP | H45: 303,3rd flour,vamshireddy recidancy,youshafguda checkposr hyderabad | I45: 22-04-2020 | K45: 08-04-2020 | L45: Resigned
A46: 47 | B46: JAHNVI SINGH | C46: 13/03/1993 | D46: Female | E46: Jitendra Bahadur singh | F46: Team Lead | G46: HNo. 177, Shanti Nagar, Bharuhana, Mirzapur, 231001, UP | H46: 1372, Arun Vihar,Sector 37, Noida,201301 | I46: 06-05-2020 | K46: 31-5-2020 | L46: Resigned
A47: 48 | B47: Saikumar Ramisetty | C47: 03-12-1994 | D47: Male | E47: Anjaneyulu R | F47: BI Developer | G47: D.NO: 2-250-A-3-1-15, Raja Nagar, N G Palle, Madanapalle, Chittoor(Dist), ANDHRA PRADESH-517325 | H47: Flat# 319, MVV Ozone, Midhilapuri Vuda Colony, P.M Palem, Visakhapatnam, ANDHRA PRADESH-530041. | I47: 11-05-2020 | K47: 11-9-2020 | L47: Resigned
A48: 49 | B48: Gurram Gayathri | C48: 15-06-1992 | D48: Female | E48: Gurrram Naga Prasad | F48: Software Developer | G48: Plot no-307,2nd floor,201,Roadno-3,Gokul plots,Near vasanth nagar,KPHB Colony 9th phase,Telangana,500085 | H48: Plot no-307,2nd floor,201,Roadno-3,Gokul plots,Near vasanth nagar,KPHB Colony 9th phase,Telangana,500085 | I48: 13-05-2020 | K48: 30-6-2020 | L48: Resigned
...

Sheet 04-22-Master
A3: FORM - XIII REGISTER OF WORKMEN EMPLOYED BY CONTRACTOR
B4: (Vide Rule 75 of Contract Labour (Regulation and Abolition) Central/Telangana/A.P. Rules 1971)
A5: Name and address of Contractor: | F5: Burgeon IT Services Pvt.Ltd. | V5: Name and address of Establishemnt in/ under which contract is carried on: | AJ5: =F5 -> Burgeon IT Services Pvt.Ltd.
F6: Siri Mansion LIGB 436 Dr.A S Rao Nagar,Hyderabad | AJ6: =F6 -> Siri Mansion LIGB 436 Dr.A S Rao Nagar,Hyderabad
A8: Nature and location of work: | F8: IT SUPPORTIVE SERVICES & HYDERABAD SEZ
A10: Wage period: Monthly | D10: 44652 | AE10: Name and address of Principal Employer: | AJ10: INFOSYS LTD.IL Hyderabad SEZ
AJ11: Sy.No 42,Pocharam Village,Gatkesar Mandal
B13: 1 | C13: 2 | D13: 3 | E13: 4 | F13: 5 | G13: 6 | H13: 7 | I13: 8 | J13: 9 | K13: 10 | L13: 11 | M13: 12 | N13: 13 | O13: 14 | P13: 15 | Q13: 16 | R13: 17 | S13: 18 | T13: 19 | U13: 20 | V13: 21 | W13: 22 | X13: 23 | Y13: 24 | Z13: 25 | AA13: 26 | AB13: 27 | AC13: 28 | AD13: 29 | AE13: 30 | AF13: 31 | AG13: 32 | AH13: 33 | AI13: 34 | AJ13: 35 | AK13: 36 | AL13: 37 | AM13: 38 | AN13: 39 | AO13: 40 | AP13: 41 | AQ13: 42 | AR13: 43 | AS13: 44 | AT13: 45 | AU13: 46
B14: Name of Workman | C14: Age | D14: Sex | E14: Father's /Husband Name | F14: Designation / Nature of Work Done | G14: Permanent Address | H14: Local Address | I14: Date of Commencement of Employment | J14: Signature or thumb impression of Workman | K14: Date of termination of Employment | L14: Reasons for termination | M14: Remarks | N14: EPF Number | O14: ESI Number | P14: Name of Workman | Q14: No.of Days worked | R14: Unit of work done | S14: Monthly rate of wages/ piece rate | T14: Basic wages | U14: Dearness Allowances | V14: Over time | W14: Other cash payments (Nature of payments to be indicated) | X14: HRA | Y14: CONVEYANCE | Z14: MEDICAL ALLOWANCES | AA14: SPECIAL ALLOWNANCES | AB14: Total | AC14: BONUS | AD14: GRATUITY | AE14: LTA/L.E | AF14: ARREAR AMOUNT | AG14: TOTAL AMOUNT | AH14: Deductions, if any, (Indicate nature) | AO14: Net Amount paid | AP14: Time and Date of Payment | AQ14: Place of Payment | AR14: Signature/Thumb Impression of workman | AS14: Initial of Contractor or his representative | AT14: Serial No. in the Register of Workmen
AH15: ESI | AI15: PF | AJ15: PT | AK15: TDS | AL15: MED | AM15: OTHERS | AN15: Total Deductions
A16: BITS-432 | B16: kaja Venkat Ragavendra | C16: 33019 | D16: Male | E16: Kaja Suresh Babu | F16: SR.Application Consultant | G16: Kidambi Residency, Flat no 6, Agraharam, Guntur, 522003 | H16: Reddy's Avenue, Road no 28, HNO 59, Nizampet, Hyderabad 500090 | I16: 43864 | N16: 101308550178 | O16: N/A | P16: =B16 -> kaja Venkat Ragavendra | Q16: =VLOOKUP(A16,'[1]Pay sheet-APRIL- 2022'!$C$4:$AF$140,10,0) -> 30 | R16: N/A | S16: 84913 | T16: =VLOOKUP(A16,'[1]Pay sheet-APRIL- 2022'!$C$4:$AF$140,11,0) -> 50947.8 | U16: 0 | V16: 0 | W16: 0 | X16: =VLOOKUP(A16,'[1]Pay sheet-APRIL- 2022'!$C$4:$AF$140,12,0) -> 20379.12 | Y16: =VLOOKUP(A16,'[1]Pay sheet-APRIL- 2022'!$C$4:$AF$140,13,0) -> 2083 | Z16: =VLOOKUP(A16,'[1]Pay sheet-APRIL- 2022'!$C$4:$AF$140,14,0) -> 2083 | AA16: =VLOOKUP(A16,'[1]Pay sheet-APRIL- 2022'!$C$4:$AF$140,15,0) -> 9533.08 | AB16: =SUM(T16:AA16) -> 85026 | AC16: =VLOOKUP(A16,'[1]Pay sheet-APRIL- 2022'!$C$4:$AF$140,18,0) -> 1554.609 | AD16: =VLOOKUP(A16,'[1]Pay sheet-APRIL- 2022'!$C$4:$AF$140,19,0) -> 2450.5892 | AE16: =VLOOKUP(A16,'[1]Pay sheet-APRIL- 2022'!$C$4:$AF$140,20,0) -> 4245.65 | AF16: 0 | AG16: =AB16+AC16+AD16+AE16+AF16 -> 93276.848 | AH16: 0 | AI16: =VLOOKUP(A16,'[1]Pay sheet-APRIL- 2022'!$C$4:$AF$140,26,0) -> 1800 | AJ16: =VLOOKUP(A16,'[1]Pay sheet-APRIL- 2022'!$C$4:$AF$140,25,0) -> 200 | AK16: =VLOOKUP(A16,'[1]Pay sheet-APRIL- 2022'!$C$4:$AF$140,24,0) -> 0 | AL16: =VLOOKUP(A16,'[1]Pay sheet-APRIL- 2022'!$C$4:$AF$140,27,0) -> 391.78785 | AN16: =AH16+AI16+AJ16+AK16+AL16+AM16 -> 2391.7878 | AO16: =AG16-AN16 -> 90885.06 | AP16: 44686 | AQ16: KMB | AR16: A/C'6812236194 | AT16: 41 | AU16: 1
A17: BITS-528 | B17: VeerendraBabu Galam | C17: 15-02-1992 | D17: Male | E17: Gopal Rao | F17: Senior Test Engineer | G17: 1-66, Lakshmipuram Village, Kallur mandal, Khammam Dist, Telangana 507209 | H17: 1-66, Lakshmipuram Village, Kallur mandal, Khammam Dist, Telangana 507209 | I17: 18-03-2021 | N17: 100916499521 | O17: N/A | P17: =B17 -> VeerendraBabu Galam | Q17: =VLOOKUP(A17,'[1]Pay sheet-APRIL- 2022'!$C$4:$AF$140,10,0) -> 30 | R17: N/A | S17: 66374 | T17: =VLOOKUP(A17,'[1]Pay sheet-APRIL- 2022'!$C$4:$AF$140,11,0) -> 39824.4 | U17: 0 | V17: 0 | W17: 0 | X17: =VLOOKUP(A17,'[1]Pay sheet-APRIL- 2022'!$C$4:$AF$140,12,0) -> 15929.76 | Y17: =VLOOKUP(A17,'[1]Pay sheet-APRIL- 2022'!$C$4:$AF$140,13,0) -> 2083 | Z17: =VLOOKUP(A17,'[1]Pay sheet-APRIL- 2022'!$C$4:$AF$140,14,0) -> 2083 | AA17: =VLOOKUP(A17,'[1]Pay sheet-APRIL- 2022'!$C$4:$AF$140,15,0) -> 6566.84 | AB17: =SUM(T17:AA17) -> 66487 | AC17: =VLOOKUP(A17,'[1]Pay sheet-APRIL- 2022'!$C$4:$AF$140,18,0) -> 1554.609 | AD17: =VLOOKUP(A17,'[1]Pay sheet-APRIL- 2022'!$C$4:$AF$140,19,0) -> 1915.5536 | AE17: =VLOOKUP(A17,'[1]Pay sheet-APRIL- 2022'!$C$4:$AF$140,20,0) -> 3318.7 | AF17: =VLOOKUP(A17,'[2]Pay sheet-MARCH- 2022'!$C$4:$AF$150,22,0) -> 0 | AG17: =AB17+AC17+AD17+AE17+AF17 -> 73275.863 | AH17: 0 | AI17: =VLOOKUP(A17,'[1]Pay sheet-APRIL- 2022'!$C$4:$AF$140,26,0) -> 1800 | AJ17: =VLOOKUP(A17,'[1]Pay sheet-APRIL- 2022'!$C$4:$AF$140,25,0) -> 200 | AK17: =VLOOKUP(A17,'[1]Pay sheet-APRIL- 2022'!$C$4:$AF$140,24,0) -> 0 | AL17: =VLOOKUP(A17,'[1]Pay sheet-APRIL- 2022'!$C$4:$AF$140,27,0) -> 391.78785 | AN17: =AH17+AI17+AJ17+AK17+AL17+AM17 -> 2391.7878 | AO17: =AG17-AN17 -> 70884.075 | AP17: 44686 | AQ17: Standard chartered Bank | AR17: A/C'44511140919 | AT17: 68 | AU17: 2
A18: BITS-568 | B18: RUKNUDEEN S | C18: 32172 | D18: Male | E18: SIRBUDIN.T | F18: Technical consultant | G18: WARD 5-2-46/7,PTR COLONY ,UTHAMAPALAYAM,THENI,TAMILNADU-625533 | H18: WARD 5-2-46/7,PTR COLONY ,UTHAMAPALAYAM,THENI,TAMILNADU-625533 | I18: 44330 | N18: 101695261761 | O18: N/A | P18: =B18 -> RUKNUDEEN S | Q18: =VLOOKUP(A18,'[1]Pay sheet-APRIL- 2022'!$C$4:$AF$140,10,0) -> 30 | R18: N/A | S18: 89547 | T18: =VLOOKUP(A18,'[1]Pay sheet-APRIL- 2022'!$C$4:$AF$140,11,0) -> 53728.2 | U18: 0 | V18: 0 | W18: 0 | X18: =VLOOKUP(A18,'[1]Pay sheet-APRIL- 2022'!$C$4:$AF$140,12,0) -> 21491.28 | Y18: =VLOOKUP(A18,'[1]Pay sheet-APRIL- 2022'!$C$4:$AF$140,13,0) -> 2083 | Z18: =VLOOKUP(A18,'[1]Pay sheet-APRIL- 2022'!$C$4:$AF$140,14,0) -> 2083 | AA18: =VLOOKUP(A18,'[1]Pay sheet-APRIL- 2022'!$C$4:$AF$140,15,0) -> 10274.52 | AB18: =SUM(T18:AA18) -> 89660 | AC18: =VLOOKUP(A18,'[1]Pay sheet-APRIL- 2022'!$C$4:$AF$140,18,0) -> 1554.609 | AD18: =VLOOKUP(A18,'[1]Pay sheet-APRIL- 2022'!$C$4:$AF$140,19,0) -> 2584.3264 | AE18: =VLOOKUP(A18,'[1]Pay sheet-APRIL- 2022'!$C$4:$AF$140,20,0) -> 4477.35 | AF18: =VLOOKUP(A18,'[2]Pay sheet-MARCH- 2022'!$C$4:$AF$150,22,0) -> 0 | AG18: =AB18+AC18+AD18+AE18+AF18 -> 98276.285 | AH18: 0 | AI18: =VLOOKUP(A18,'[1]Pay sheet-APRIL- 2022'!$C$4:$AF$140,26,0) -> 1800 | AJ18: =VLOOKUP(A18,'[1]Pay sheet-APRIL- 2022'!$C$4:$AF$140,25,0) -> 200 | AK18: =VLOOKUP(A18,'[1]Pay sheet-APRIL- 2022'!$C$4:$AF$140,24,0) -> 0 | AL18: =VLOOKUP(A18,'[1]Pay sheet-APRIL- 2022'!$C$4:$AF$140,27,0) -> 391.78785 | AN18: =AH18+AI18+AJ18+AK18+AL18+AM18 -> 2391.7878 | AO18: =AG18-AN18 -> 95884.498 | AP18: 44686 | AQ18: SBI | AR18: 39203094887 | AT18: 75 | AU18: 3
A19: BITS-597 | B19: Srikanth Thota | C19: 29937 | D19: Male | E19: Vasudha thota | F19: PMO Manager | G19: Plot No 779,Defence colony Sainikpuri Secunderabad 500094 | H19: Plot No 779,Defence colony Sainikpuri Secunderabad 500094 | I19: 44378 | J19: OOOO | N19: 100362420499 | O19: N/A | P19: =B19 -> Srikanth Thota | Q19: =VLOOKUP(A19,'[1]Pay sheet-APRIL- 2022'!$C$4:$AF$140,10,0) -> 30 | R19: N/A | S19: 103451 | T19: =VLOOKUP(A19,'[1]Pay sheet-APRIL- 2022'!$C$4:$AF$140,11,0) -> 62070.6 | U19: 0 | V19: 0 | W19: 0 | X19: =VLOOKUP(A19,'[1]Pay sheet-APRIL- 2022'!$C$4:$AF$140,12,0) -> 24828.24 | Y19: =VLOOKUP(A19,'[1]Pay sheet-APRIL- 2022'!$C$4:$AF$140,13,0) -> 2083 | Z19: =VLOOKUP(A19,'[1]Pay sheet-APRIL- 2022'!$C$4:$AF$140,14,0) -> 2083 | AA19: =VLOOKUP(A19,'[1]Pay sheet-APRIL- 2022'!$C$4:$AF$140,15,0) -> 12499.16 | AB19: =SUM(T19:AA19) -> 103564 | AC19: =VLOOKUP(A19,'[1]Pay sheet-APRIL- 2022'!$C$4:$AF$140,18,0) -> 1554.609 | AD19: =VLOOKUP(A19,'[1]Pay sheet-APRIL- 2022'!$C$4:$AF$140,19,0) -> 2985.5959 | AE19: =VLOOKUP(A19,'[1]Pay sheet-APRIL- 2022'!$C$4:$AF$140,20,0) -> 5172.55 | AF19: =VLOOKUP(A19,'[2]Pay sheet-MARCH- 2022'!$C$4:$AF$150,22,0) -> 0 | AG19: =AB19+AC19+AD19+AE19+AF19 -> 113276.75 | AH19: 0 | AI19: =VLOOKUP(A19,'[1]Pay sheet-APRIL- 2022'!$C$4:$AF$140,26,0) -> 1800 | AJ19: =VLOOKUP(A19,'[1]Pay sheet-APRIL- 2022'!$C$4:$AF$140,25,0) -> 200 | AK19: =VLOOKUP(A19,'[1]Pay sheet-APRIL- 2022'!$C$4:$AF$140,24,0) -> 0 | AL19: =VLOOKUP(A19,'[1]Pay sheet-APRIL- 2022'!$C$4:$AF$140,27,0) -> 377 | AN19: =AH19+AI19+AJ19+AK19+AL19+AM19 -> 2377 | AO19: =AG19-AN19 -> 110899.75 | AP19: 44686 | AQ19: ICICI BANK | AR19: 020201513961 | AT19: 80 | AU19: 4
A20: BITS-600 | B20: Shekhar Panchal | C20: 34305 | D20: Male | E20: Naresh Kumar Panchal | F20: Sr. Network Security Engineer | G20: V.P.O. ANANDPURI, DIST- BANSWARA, RAJASTHAN-327021 | H20: V.P.O. ANANDPURI, DIST- BANSWARA, RAJASTHAN-327021 | I20: 44388 | J20: OOOO | N20: 101185605036 | O20: N/A | P20: =B20 -> Shekhar Panchal | Q20: =VLOOKUP(A20,'[1]Pay sheet-APRIL- 2022'!$C$4:$AF$140,10,0) -> 30 | R20: N/A | S20: 66374 | T20: =VLOOKUP(A20,'[1]Pay sheet-APRIL- 2022'!$C$4:$AF$140,11,0) -> 39824.4 | U20: 0 | V20: 0 | W20: 0 | X20: =VLOOKUP(A20,'[1]Pay sheet-APRIL- 2022'!$C$4:$AF$140,12,0) -> 15929.76 | Y20: =VLOOKUP(A20,'[1]Pay sheet-APRIL- 2022'!$C$4:$AF$140,13,0) -> 2083 | Z20: =VLOOKUP(A20,'[1]Pay sheet-APRIL- 2022'!$C$4:$AF$140,14,0) -> 2083 | AA20: =VLOOKUP(A20,'[1]Pay sheet-APRIL- 2022'!$C$4:$AF$140,15,0) -> 6566.84 | AB20: =SUM(T20:AA20) -> 66487 | AC20: =VLOOKUP(A20,'[1]Pay sheet-APRIL- 2022'!$C$4:$AF$140,18,0) -> 1554.609 | AD20: =VLOOKUP(A20,'[1]Pay sheet-APRIL- 2022'!$C$4:$AF$140,19,0) -> 1915.5536 | AE20: =VLOOKUP(A20,'[1]Pay sheet-APRIL- 2022'!$C$4:$AF$140,20,0) -> 3318.7 | AF20: =VLOOKUP(A20,'[2]Pay sheet-MARCH- 2022'!$C$4:$AF$150,22,0) -> 0 | AG20: =AB20+AC20+AD20+AE20+AF20 -> 73275.863 | AH20: 0 | AI20: =VLOOKUP(A20,'[1]Pay sheet-APRIL- 2022'!$C$4:$AF$140,26,0) -> 1800 | AJ20: =VLOOKUP(A20,'[1]Pay sheet-APRIL- 2022'!$C$4:$AF$140,25,0) -> 200 | AK20: =VLOOKUP(A20,'[1]Pay sheet-APRIL- 2022'!$C$4:$AF$140,24,0) -> 0 | AL20: =VLOOKUP(A20,'[1]Pay sheet-APRIL- 2022'!$C$4:$AF$140,27,0) -> 336 | AN20: =AH20+AI20+AJ20+AK20+AL20+AM20 -> 2336 | AO20: =AG20-AN20 -> 70939.863 | AP20: 44686 | AQ20: ICICI BANK | AR20: 346801502975 | AT20: 81 | AU20: 5
A21: BITS-630 | B21: Gangadhar Yarabham | C21: 29958 | D21: Male | E21: Yarabham Savaraiah | F21: Senior Specialist | G21: Flat.No:P1, MVGK Vaishnavy Residency, Kondapur-500084 | H21: H.No:1-112, Thummalur post, Pamulapadu mandal, Kurnool-518401 | I21: 44431 | J21: OOOO | N21: 101348551716 | O21: N/A | P21: =B21 -> Gangadhar Yarabham | Q21: =VLOOKUP(A21,'[1]Pay sheet-APRIL- 2022'!$C$4:$AF$140,10,0) -> 30 | R21: N/A | S21: 84912 | T21: =VLOOKUP(A21,'[1]Pay sheet-APRIL- 2022'!$C$4:$AF$140,11,0) -> 50947.2 | U21: 0 | V21: 0 | W21: 0 | X21: =VLOOKUP(A21,'[1]Pay sheet-APRIL- 2022'!$C$4:$AF$140,12,0) -> 20378.88 | Y21: =VLOOKUP(A21,'[1]Pay sheet-APRIL- 2022'!$C$4:$AF$140,13,0) -> 2083 | Z21: =VLOOKUP(A21,'[1]Pay sheet-APRIL- 2022'!$C$4:$AF$140,14,0) -> 2083 | AA21: =VLOOKUP(A21,'[1]Pay sheet-APRIL- 2022'!$C$4:$AF$140,15,0) -> 9532.92 | AB21: =SUM(T21:AA21) -> 85025 | AC21: =VLOOKUP(A21,'[1]Pay sheet-APRIL- 2022'!$C$4:$AF$140,18,0) -> 1554.609 | AD21: =VLOOKUP(A21,'[1]Pay sheet-APRIL- 2022'!$C$4:$AF$140,19,0) -> 2450.5603 | AE21: =VLOOKUP(A21,'[1]Pay sheet-APRIL- 2022'!$C$4:$AF$140,20,0) -> 4245.6 | AF21: =VLOOKUP(A21,'[2]Pay sheet-MARCH- 2022'!$C$4:$AF$150,22,0) -> 0 | AG21: =AB21+AC21+AD21+AE21+AF21 -> 93275.769 | AH21: 0 | AI21: =VLOOKUP(A21,'[1]Pay sheet-APRIL- 2022'!$C$4:$AF$140,26,0) -> 1800 | AJ21: =VLOOKUP(A21,'[1]Pay sheet-APRIL- 2022'!$C$4:$AF$140,25,0) -> 200 | AK21: =VLOOKUP(A21,'[1]Pay sheet-APRIL- 2022'!$C$4:$AF$140,24,0) -> 0 | AL21: =VLOOKUP(A21,'[1]Pay sheet-APRIL- 2022'!$C$4:$AF$140,27,0) -> 377 | AM21: 0 | AN21: =AH21+AI21+AJ21+AK21+AL21+AM21 -> 2377 | AO21: =AG21-AN21 -> 90898.769 | AP21: 44686 | AQ21: KOTAK BANK | AR21: A/C NUM:0745780762 | AT21: 83 | AU21: 6
A22: BITS-675 | B22: Nikhila Kaveri | C22: 09/10/1994 | D22: FEMALE | E22: Sreehari | F22: TECHNICAL SOLUTION CONSULTANT | G22: 5-6-98/37, Sriharivasam, Behind Dal Factory, Lakshmipuram, Hindupur, AP 515201 | H22: 5-6-98/37, Sriharivasam, Behind Dal Factory, Lakshmipuram, Hindupur, AP 515201 | I22: 44529 | J22: OOOO | N22: 100929123434 | O22: N/A | P22: Nikhila Kaveri | Q22: =VLOOKUP(A22,'[1]Pay sheet-APRIL- 2022'!$C$4:$AF$140,10,0) -> 30 | R22: N/A | S22: 108085 | T22: =VLOOKUP(A22,'[1]Pay sheet-APRIL- 2022'!$C$4:$AF$140,11,0) -> 64851 | U22: 0 | V22: 0 | W22: 0 | X22: =VLOOKUP(A22,'[1]Pay sheet-APRIL- 2022'!$C$4:$AF$140,12,0) -> 25940.4 | Y22: =VLOOKUP(A22,'[1]Pay sheet-APRIL- 2022'!$C$4:$AF$140,13,0) -> 2083 | Z22: =VLOOKUP(A22,'[1]Pay sheet-APRIL- 2022'!$C$4:$AF$140,14,0) -> 2083 | AA22: =VLOOKUP(A22,'[1]Pay sheet-APRIL- 2022'!$C$4:$AF$140,15,0) -> 13240.6 | AB22: =SUM(T22:AA22) -> 108198 | AC22: =VLOOKUP(A22,'[1]Pay sheet-APRIL- 2022'!$C$4:$AF$140,18,0) -> 1554.609 | AD22: =VLOOKUP(A22,'[1]Pay sheet-APRIL- 2022'!$C$4:$AF$140,19,0) -> 3119.3331 | AE22: =VLOOKUP(A22,'[1]Pay sheet-APRIL- 2022'!$C$4:$AF$140,20,0) -> 5404.25 | AF22: =VLOOKUP(A22,'[2]Pay sheet-MARCH- 2022'!$C$4:$AF$150,22,0) -> 0 | AG22: =AB22+AC22+AD22+AE22+AF22 -> 118276.19 | AH22: 0 | AI22: =VLOOKUP(A22,'[1]Pay sheet-APRIL- 2022'!$C$4:$AF$140,26,0) -> 1800 | AJ22: =VLOOKUP(A22,'[1]Pay sheet-APRIL- 2022'!$C$4:$AF$140,25,0) -> 200 | AK22: =VLOOKUP(A22,'[1]Pay sheet-APRIL- 2022'!$C$4:$AF$140,24,0) -> 0 | AL22: =VLOOKUP(A22,'[1]Pay sheet-APRIL- 2022'!$C$4:$AF$140,27,0) -> 252 | AN22: =AH22+AI22+AJ22+AK22+AL22+AM22 -> 2252 | AO22: =AG22-AN22 -> 116024.19 | AP22: 44686 | AQ22: HDFC BANK | AR22: HDFC0002770 | AT22: 89 | AU22: 7
A23: BITS-690 | B23: Thaposh Ghosh | C23: 12/05/1987 | D23: MALE | E23: CH Divya Vani | F23: Incident Governance Manager | G23: Mayflower Grande, Block-D,D003, Mallapur,Hyderabad | H23: Mayflower Grande, Block-D,D003, Mallapur,Hyderabad | I23: 44564 | J23: OOOO | N23: 100605733434 | O23: N/A | P23: Thaposh Ghosh | Q23: =VLOOKUP(A23,'[1]Pay sheet-APRIL- 2022'!$C$4:$AF$140,10,0) -> 30 | R23: N/A | S23: 140526 | T23: =VLOOKUP(A23,'[1]Pay sheet-APRIL- 2022'!$C$4:$AF$140,11,0) -> 84315.6 | U23: 0 | V23: 0 | W23: 0 | X23: =VLOOKUP(A23,'[1]Pay sheet-APRIL- 2022'!$C$4:$AF$140,12,0) -> 33726.24 | Y23: =VLOOKUP(A23,'[1]Pay sheet-APRIL- 2022'!$C$4:$AF$140,13,0) -> 2083 | Z23: =VLOOKUP(A23,'[1]Pay sheet-APRIL- 2022'!$C$4:$AF$140,14,0) -> 2083 | AA23: =VLOOKUP(A23,'[1]Pay sheet-APRIL- 2022'!$C$4:$AF$140,15,0) -> 18431.16 | AB23: =SUM(T23:AA23) -> 140639 | AC23: =VLOOKUP(A23,'[1]Pay sheet-APRIL- 2022'!$C$4:$AF$140,18,0) -> 1554.609 | AD23: =VLOOKUP(A23,'[1]Pay sheet-APRIL- 2022'!$C$4:$AF$140,19,0) -> 4055.5804 | AE23: =VLOOKUP(A23,'[1]Pay sheet-APRIL- 2022'!$C$4:$AF$140,20,0) -> 7026.3 | AF23: =VLOOKUP(A23,'[2]Pay sheet-MARCH- 2022'!$C$4:$AF$150,22,0) -> 0 | AG23: =AB23+AC23+AD23+AE23+AF23 -> 153275.49 | AH23: 0 | AI23: =VLOOKUP(A23,'[1]Pay sheet-APRIL- 2022'!$C$4:$AF$140,26,0) -> 1800 | AJ23: =VLOOKUP(A23,'[1]Pay sheet-APRIL- 2022'!$C$4:$AF$140,25,0) -> 200 | AK23: =VLOOKUP(A23,'[1]Pay sheet-APRIL- 2022'!$C$4:$AF$140,24,0) -> 0 | AL23: =VLOOKUP(A23,'[1]Pay sheet-APRIL- 2022'!$C$4:$AF$140,27,0) -> 283 | AN23: =AH23+AI23+AJ23+AK23+AL23+AM23 -> 2283 | AO23: =AG23-AN23 -> 150992.49 | AP23: 44686 | AQ23: AXIS BANK | AR23: 914010012727732 | AT23: 90 | AU23: 8
A24: BITS-695 | B24: Nagashree Narayan | C24: 05/05/1981 | D24: FEMALE | E24: KANTHA KAMBAIAH LAKSHMI | F24: Technical Lead | G24: Flat Number: 1302, Building: I-2 (Manchester), Puranik City, Ghodbunder Road, Thane West, Thane, Maharastra Pin Code: 400615 | H24: 2nd Floor, Number 24, 1st Cross, 1st Main, Behind Fortune Central Park Apartment, Anand Layout, Kodigehalli, Bangalore North, PO: Chikkabettahalli. District: Bangaluru, Pin Code: 560097 | I24: 44571 | J24: OOOO | N24: 101780502399 | O24: N/A | P24: Nagashree Narayan | Q24: =VLOOKUP(A24,'[1]Pay sheet-APRIL- 2022'!$C$4:$AF$140,10,0) -> 29 | R24: N/A | S24: 98816 | T24: =VLOOKUP(A24,'[1]Pay sheet-APRIL- 2022'!$C$4:$AF$140,11,0) -> 57313.28 | U24: 0 | V24: 0 | W24: 0 | X24: =VLOOKUP(A24,'[1]Pay sheet-APRIL- 2022'!$C$4:$AF$140,12,0) -> 22925.312 | Y24: =VLOOKUP(A24,'[1]Pay sheet-APRIL- 2022'!$C$4:$AF$140,13,0) -> 2014 | Z24: =VLOOKUP(A24,'[1]Pay sheet-APRIL- 2022'!$C$4:$AF$140,14,0) -> 2014 | AA24: =VLOOKUP(A24,'[1]Pay sheet-APRIL- 2022'!$C$4:$AF$140,15,0) -> 11368.541 | AB24: =SUM(T24:AA24) -> 95635.133 | AC24: =VLOOKUP(A24,'[1]Pay sheet-APRIL- 2022'!$C$4:$AF$140,18,0) -> 1554.609 | AD24: =VLOOKUP(A24,'[1]Pay sheet-APRIL- 2022'!$C$4:$AF$140,19,0) -> 2756.7688 | AE24: =VLOOKUP(A24,'[1]Pay sheet-APRIL- 2022'!$C$4:$AF$140,20,0) -> 4776.1067 | AF24: =VLOOKUP(A24,'[2]Pay sheet-MARCH- 2022'!$C$4:$AF$150,22,0) -> 0 | AG24: =AB24+AC24+AD24+AE24+AF24 -> 104722.62 | AH24: 0 | AI24: =VLOOKUP(A24,'[1]Pay sheet-APRIL- 2022'!$C$4:$AF$140,26,0) -> 1800 | AJ24: =VLOOKUP(A24,'[1]Pay sheet-APRIL- 2022'!$C$4:$AF$140,25,0) -> 200 | AK24: =VLOOKUP(A24,'[1]Pay sheet-APRIL- 2022'!$C$4:$AF$140,24,0) -> 0 | AL24: =VLOOKUP(A24,'[1]Pay sheet-APRIL- 2022'!$C$4:$AF$140,27,0) -> 283 | AN24: =AH24+AI24+AJ24+AK24+AL24+AM24 -> 2283 | AO24: =AG24-AN24 -> 102439.62 | AP24: 44686 | AQ24: ICICI BANK | AR24: 098601510169 | AT24: 91 | AU24: 9
A25: BITS-719 | B25: ROOPINI CHIYYARAPU | C25: 35254 | D25: FEMALE | E25: C.ChandraReddy | F25: Service Now Developer | G25: Abbinaidi palli(v),L.G palli(p),Settigunta,Rly Kodur(m),Kadapa(dist),516101. | H25: plot:31,H.no:12-2-54/1,j.p nagar,moosapet,Bharat Nagar,Hyderabad,500018. | I25: 44610 | J25: OOOO | N25: 101792969219 | O25: N/A | P25: ROOPINI CHIYYARAPU | Q25: =VLOOKUP(A25,'[1]Pay sheet-APRIL- 2022'!$C$4:$AF$140,10,0) -> 30 | R25: N/A | S25: 75643 | T25: =VLOOKUP(A25,'[1]Pay sheet-APRIL- 2022'!$C$4:$AF$140,11,0) -> 45385.8 | U25: 0 | V25: 0 | W25: 0 | X25: =VLOOKUP(A25,'[1]Pay sheet-APRIL- 2022'!$C$4:$AF$140,12,0) -> 18154.32 | Y25: =VLOOKUP(A25,'[1]Pay sheet-APRIL- 2022'!$C$4:$AF$140,13,0) -> 2083 | Z25: =VLOOKUP(A25,'[1]Pay sheet-APRIL- 2022'!$C$4:$AF$140,14,0) -> 2083 | AA25: =VLOOKUP(A25,'[1]Pay sheet-APRIL- 2022'!$C$4:$AF$140,15,0) -> 8049.88 | AB25: =SUM(T25:AA25) -> 75756 | AC25: =VLOOKUP(A25,'[1]Pay sheet-APRIL- 2022'!$C$4:$AF$140,18,0) -> 1554.609 | AD25: =VLOOKUP(A25,'[1]Pay sheet-APRIL- 2022'!$C$4:$AF$140,19,0) -> 2183.057 | AE25: =VLOOKUP(A25,'[1]Pay sheet-APRIL- 2022'!$C$4:$AF$140,20,0) -> 3782.15 | AF25: =VLOOKUP(A25,'[2]Pay sheet-MARCH- 2022'!$C$4:$AF$150,22,0) -> 0 | AG25: =AB25+AC25+AD25+AE25+AF25 -> 83275.816 | AH25: 0 | AI25: =VLOOKUP(A25,'[1]Pay sheet-APRIL- 2022'!$C$4:$AF$140,26,0) -> 1800 | AJ25: =VLOOKUP(A25,'[1]Pay sheet-APRIL- 2022'!$C$4:$AF$140,25,0) -> 200 | AK25: =VLOOKUP(A25,'[1]Pay sheet-APRIL- 2022'!$C$4:$AF$140,24,0) -> 0 | AL25: =VLOOKUP(A25,'[1]Pay sheet-APRIL- 2022'!$C$4:$AF$140,27,0) -> 283 | AN25: =AH25+AI25+AJ25+AK25+AL25+AM25 -> 2283 | AO25: =AG25-AN25 -> 80992.816 | AP25: 44686 | AQ25: SBI | AR25: 39504382024 | AT25: 92 | AU25: 10
A26: BITS-723 | B26: D.Santhoshi | C26: 34838 | D26: FEMALE | E26: Srinivasu | F26: SAP Basis Consultant | G26: 6-56, Nekkantivari street, alamuru East godavari Dist | H26: 6-56, Nekkantivari street, alamuru East godavari Dist | I26: 44615 | J26: OOOO | N26: 101284342568 | O26: N/A | P26: D.Santhoshi | Q26: =VLOOKUP(A26,'[1]Pay sheet-APRIL- 2022'!$C$4:$AF$140,10,0) -> 30 | R26: N/A | S26: 38567 | T26: =VLOOKUP(A26,'[1]Pay sheet-APRIL- 2022'!$C$4:$AF$140,11,0) -> 23140.2 | U26: 0 | V26: 0 | W26: 0 | X26: =VLOOKUP(A26,'[1]Pay sheet-APRIL- 2022'!$C$4:$AF$140,12,0) -> 9256.08 | Y26: =VLOOKUP(A26,'[1]Pay sheet-APRIL- 2022'!$C$4:$AF$140,13,0) -> 2083 | Z26: =VLOOKUP(A26,'[1]Pay sheet-APRIL- 2022'!$C$4:$AF$140,14,0) -> 2083 | AA26: =VLOOKUP(A26,'[1]Pay sheet-APRIL- 2022'!$C$4:$AF$140,15,0) -> 2117.72 | AB26: =SUM(T26:AA26) -> 38680 | AC26: =VLOOKUP(A26,'[1]Pay sheet-APRIL- 2022'!$C$4:$AF$140,18,0) -> 1554.609 | AD26: =VLOOKUP(A26,'[1]Pay sheet-APRIL- 2022'!$C$4:$AF$140,19,0) -> 1113.0436 | AE26: =VLOOKUP(A26,'[1]Pay sheet-APRIL- 2022'!$C$4:$AF$140,20,0) -> 1928.35 | AF26: =VLOOKUP(A26,'[2]Pay sheet-MARCH- 2022'!$C$4:$AF$150,22,0) -> 0 | AG26: =AB26+AC26+AD26+AE26+AF26 -> 43276.003 | AH26: 0 | AI26: =VLOOKUP(A26,'[1]Pay sheet-APRIL- 2022'!$C$4:$AF$140,26,0) -> 1800 | AJ26: =VLOOKUP(A26,'[1]Pay sheet-APRIL- 2022'!$C$4:$AF$140,25,0) -> 200 | AK26: =VLOOKUP(A26,'[1]Pay sheet-APRIL- 2022'!$C$4:$AF$140,24,0) -> 0 | AL26: =VLOOKUP(A26,'[1]Pay sheet-APRIL- 2022'!$C$4:$AF$140,27,0) -> 283 | AN26: =AH26+AI26+AJ26+AK26+AL26+AM26 -> 2283 | AO26: =AG26-AN26 -> 40993.003 | AP26: 44686 | AQ26: INDIAN BANK | AR26: 6108665097 | AT26: 93 | AU26: 11
A27: BITS-724 | B27: Bharath Pal | C27: 35368 | D27: Male | E27: Mani ram | F27: SAP Basis Consultant | G27: village - Bagpur, post. office. - Mohna, Teh & Distt. Palwal, (Haryana) pin code - 121004 | H27: village - Bagpur, post. office. - Mohna, Teh & Distt. Palwal, (Haryana) pin code - 121004 | I27: 44615 | J27: OOOO | N27: 101711677279 | O27: N/A | P27: Bharath | Q27: =VLOOKUP(A27,'[1]Pay sheet-APRIL- 2022'!$C$4:$AF$140,10,0) -> 30 | R27: N/A | S27: 24636 | T27: =VLOOKUP(A27,'[1]Pay sheet-APRIL- 2022'!$C$4:$AF$140,11,0) -> 14781.6 | U27: 0 | V27: 0 | W27: 0 | X27: =VLOOKUP(A27,'[1]Pay sheet-APRIL- 2022'!$C$4:$AF$140,12,0) -> 5912.64 | Y27: =VLOOKUP(A27,'[1]Pay sheet-APRIL- 2022'!$C$4:$AF$140,13,0) -> 1500 | Z27: =VLOOKUP(A27,'[1]Pay sheet-APRIL- 2022'!$C$4:$AF$140,14,0) -> 1500 | AA27: =VLOOKUP(A27,'[1]Pay sheet-APRIL- 2022'!$C$4:$AF$140,15,0) -> 1054.76 | AB27: =SUM(T27:AA27) -> 24749 | AC27: =VLOOKUP(A27,'[1]Pay sheet-APRIL- 2022'!$C$4:$AF$140,18,0) -> 1554.609 | AD27: =VLOOKUP(A27,'[1]Pay sheet-APRIL- 2022'!$C$4:$AF$140,19,0) -> 710.99496 | AE27: =VLOOKUP(A27,'[1]Pay sheet-APRIL- 2022'!$C$4:$AF$140,20,0) -> 1231.8 | AF27: =VLOOKUP(A27,'[2]Pay sheet-MARCH- 2022'!$C$4:$AF$150,22,0) -> 0 | AG27: =AB27+AC27+AD27+AE27+AF27 -> 28246.404 | AH27: 0 | AI27: =VLOOKUP(A27,'[1]Pay sheet-APRIL- 2022'!$C$4:$AF$140,26,0) -> 1774 | AJ27: =VLOOKUP(A27,'[1]Pay sheet-APRIL- 2022'!$C$4:$AF$140,25,0) -> 200 | AK27: =VLOOKUP(A27,'[1]Pay sheet-APRIL- 2022'!$C$4:$AF$140,24,0) -> 0 | AL27: =VLOOKUP(A27,'[1]Pay sheet-APRIL- 2022'!$C$4:$AF$140,27,0) -> 283 | AN27: =AH27+AI27+AJ27+AK27+AL27+AM27 -> 2257 | AO27: =AG27-AN27 -> 25989.404 | AP27: 44686 | AQ27: SBI | AR27: 34997967265 | AT27: 94 | AU27: 12
A28: BITS-725 | B28: NEERUDU SAI KUMAR | C28: 34185 | D28: Male | E28: UMA | F28: SAP Basis Consultant | G28: H NO 5-4-46, Seetharam Street, Maripeda bangla, Maripeda, Mahabubabad 506315 | H28: H NO 5-4-46, Seetharam Street, Maripeda bangla, Maripeda, Mahabubabad 506315 | I28: 44615 | J28: OOOO | N28: 101792969242 | O28: N/A | P28: NEERUDU SAI KUMAR | Q28: =VLOOKUP(A28,'[1]Pay sheet-APRIL- 2022'!$C$4:$AF$140,10,0) -> 30 | R28: N/A | S28: 38567 | T28: =VLOOKUP(A28,'[1]Pay sheet-APRIL- 2022'!$C$4:$AF$140,11,0) -> 23140.2 | U28: 0 | V28: 0 | W28: 0 | X28: =VLOOKUP(A28,'[1]Pay sheet-APRIL- 2022'!$C$4:$AF$140,12,0) -> 9256.08 | Y28: =VLOOKUP(A28,'[1]Pay sheet-APRIL- 2022'!$C$4:$AF$140,13,0) -> 2083 | Z28: =VLOOKUP(A28,'[1]Pay sheet-APRIL- 2022'!$C$4:$AF$140,14,0) -> 2083 | AA28: =VLOOKUP(A28,'[1]Pay sheet-APRIL- 2022'!$C$4:$AF$140,15,0) -> 2117.72 | AB28: =SUM(T28:AA28) -> 38680 | AC28: =VLOOKUP(A28,'[1]Pay sheet-APRIL- 2022'!$C$4:$AF$140,18,0) -> 1554.609 | AD28: =VLOOKUP(A28,'[1]Pay sheet-APRIL- 2022'!$C$4:$AF$140,19,0) -> 1113.0436 | AE28: =VLOOKUP(A28,'[1]Pay sheet-APRIL- 2022'!$C$4:$AF$140,20,0) -> 1928.35 | AF28: =VLOOKUP(A28,'[2]Pay sheet-MARCH- 2022'!$C$4:$AF$150,22,0) -> 0 | AG28: =AB28+AC28+AD28+AE28+AF28 -> 43276.003 | AH28: 0 | AI28: =VLOOKUP(A28,'[1]Pay sheet-APRIL- 2022'!$C$4:$AF$140,26,0) -> 1800 | AJ28: =VLOOKUP(A28,'[1]Pay sheet-APRIL- 2022'!$C$4:$AF$140,25,0) -> 200 | AK28: =VLOOKUP(A28,'[1]Pay sheet-APRIL- 2022'!$C$4:$AF$140,24,0) -> 0 | AL28: =VLOOKUP(A28,'[1]Pay sheet-APRIL- 2022'!$C$4:$AF$140,27,0) -> 283 | AN28: =AH28+AI28+AJ28+AK28+AL28+AM28 -> 2283 | AO28: =AG28-AN28 -> 40993.003 | AP28: 44686 | AQ28: HDFC | AR28: 50100450339212 | AT28: 95 | AU28: 13
A29: BITS-726 | B29: Ramineni Abhilash | C29: 35670 | D29: Male | E29: Bhulokarao | F29: SAP Basis Consultant | G29: H No 18-626, Flat no 206, Raghavendra Towers, Ashok Nagar, Miryalaguda, | H29: H NO 3-12-92/12, Flat No 202, Saimaruthi Residency, Rock town colony,near Gare function hall, Hyderabad | I29: 44615 | J29: OOOO | N29: 101793033177 | O29: N/A | P29: Ramineni Abhilash | Q29: =VLOOKUP(A29,'[1]Pay sheet-APRIL- 2022'!$C$4:$AF$140,10,0) -> 30 | R29: N/A | S29: 38567 | T29: =VLOOKUP(A29,'[1]Pay sheet-APRIL- 2022'!$C$4:$AF$140,11,0) -> 23140.2 | U29: 0 | V29: 0 | W29: 0 | X29: =VLOOKUP(A29,'[1]Pay sheet-APRIL- 2022'!$C$4:$AF$140,12,0) -> 9256.08 | Y29: =VLOOKUP(A29,'[1]Pay sheet-APRIL- 2022'!$C$4:$AF$140,13,0) -> 2083 | Z29: =VLOOKUP(A29,'[1]Pay sheet-APRIL- 2022'!$C$4:$AF$140,14,0) -> 2083 | AA29: =VLOOKUP(A29,'[1]Pay sheet-APRIL- 2022'!$C$4:$AF$140,15,0) -> 2117.72 | AB29: =SUM(T29:AA29) -> 38680 | AC29: =VLOOKUP(A29,'[1]Pay sheet-APRIL- 2022'!$C$4:$AF$140,18,0) -> 1554.609 | AD29: =VLOOKUP(A29,'[1]Pay sheet-APRIL- 2022'!$C$4:$AF$140,19,0) -> 1113.0436 | AE29: =VLOOKUP(A29,'[1]Pay sheet-APRIL- 2022'!$C$4:$AF$140,20,0) -> 1928.35 | AF29: =VLOOKUP(A29,'[2]Pay sheet-MARCH- 2022'!$C$4:$AF$150,22,0) -> 0 | AG29: =AB29+AC29+AD29+AE29+AF29 -> 43276.003 | AH29: 0 | AI29: =VLOOKUP(A29,'[1]Pay sheet-APRIL- 2022'!$C$4:$AF$140,26,0) -> 1800 | AJ29: =VLOOKUP(A29,'[1]Pay sheet-APRIL- 2022'!$C$4:$AF$140,25,0) -> 200 | AK29: =VLOOKUP(A29,'[1]Pay sheet-APRIL- 2022'!$C$4:$AF$140,24,0) -> 0 | AL29: =VLOOKUP(A29,'[1]Pay sheet-APRIL- 2022'!$C$4:$AF$140,27,0) -> 283 | AN29: =AH29+AI29+AJ29+AK29+AL29+AM29 -> 2283 | AO29: =AG29-AN29 -> 40993.003 | AP29: 44686 | AQ29: IDBI | AR29: 1169104000110723 | AT29: 96 | AU29: 14
A30: BITS-727 | B30: B SRILATHA | C30: 33606 | D30: FEMALE | E30: Anjaneya Reddy | F30: Data Engineer | G30: 2-177,Main road,Ramavaram post,Nuzendla mandal,Guntur 522660 | H30: 2-177,Main road,Ramavaram post,Nuzendla mandal,Guntur 522660 | I30: 44621 | J30: OOOO | N30: 101194018795 | O30: N/A | P30: B SRILATHA | Q30: =VLOOKUP(A30,'[1]Pay sheet-APRIL- 2022'!$C$4:$AF$140,10,0) -> 30 | R30: N/A | S30: 103450 | T30: =VLOOKUP(A30,'[1]Pay sheet-APRIL- 2022'!$C$4:$AF$140,11,0) -> 62070 | U30: 0 | V30: 0 | W30: 0 | X30: =VLOOKUP(A30,'[1]Pay sheet-APRIL- 2022'!$C$4:$AF$140,12,0) -> 24828 | Y30: =VLOOKUP(A30,'[1]Pay sheet-APRIL- 2022'!$C$4:$AF$140,13,0) -> 2083 | Z30: =VLOOKUP(A30,'[1]Pay sheet-APRIL- 2022'!$C$4:$AF$140,14,0) -> 2083 | AA30: =VLOOKUP(A30,'[1]Pay sheet-APRIL- 2022'!$C$4:$AF$140,15,0) -> 12499 | AB30: =SUM(T30:AA30) -> 103563 | AC30: =VLOOKUP(A30,'[1]Pay sheet-APRIL- 2022'!$C$4:$AF$140,18,0) -> 1554.609 | AD30: =VLOOKUP(A30,'[1]Pay sheet-APRIL- 2022'!$C$4:$AF$140,19,0) -> 2985.567 | AE30: =VLOOKUP(A30,'[1]Pay sheet-APRIL- 2022'!$C$4:$AF$140,20,0) -> 5172.5 | AF30: =VLOOKUP(A30,'[2]Pay sheet-MARCH- 2022'!$C$4:$AF$150,22,0) -> 0 | AG30: =AB30+AC30+AD30+AE30+AF30 -> 113275.68 | AH30: 0 | AI30: =VLOOKUP(A30,'[1]Pay sheet-APRIL- 2022'!$C$4:$AF$140,26,0) -> 1800 | AJ30: =VLOOKUP(A30,'[1]Pay sheet-APRIL- 2022'!$C$4:$AF$140,25,0) -> 200 | AK30: =VLOOKUP(A30,'[1]Pay sheet-APRIL- 2022'!$C$4:$AF$140,24,0) -> 0 | AL30: =VLOOKUP(A30,'[1]Pay sheet-APRIL- 2022'!$C$4:$AF$140,27,0) -> 283 | AN30: =AH30+AI30+AJ30+AK30+AL30+AM30 -> 2283 | AO30: =AG30-AN30 -> 110992.68 | AP30: 44686 | AQ30: SBI | AR30: 33161877369 | AT30: 97 | AU30: 15
A31: BITS-735 | B31: SURESH Kumar KOLA | C31: 08-09-1989 | D31: Male | E31: BHAVANI KOLA | F31: SOFTWARE ENGINEER | G31: H No 2-4-123/1/5/F/3,Street No1,seven hills colony,Uppal,Hyderabad 500039 | H31: H No 2-4-123/1/5/F/3,Street No1,seven hills colony,Uppal,Hyderabad 500039 | I31: 44637 | J31: OOOO | N31: 101739029576 | O31: N/A | P31: SURESH Kumar KOLA | Q31: =VLOOKUP(A31,'[1]Pay sheet-APRIL- 2022'!$C$4:$AF$140,10,0) -> 30 | R31: N/A | S31: 80278 | T31: =VLOOKUP(A31,'[1]Pay sheet-APRIL- 2022'!$C$4:$AF$140,11,0) -> 48166.8 | U31: 0 | V31: 0 | W31: 0 | X31: =VLOOKUP(A31,'[1]Pay sheet-APRIL- 2022'!$C$4:$AF$140,12,0) -> 19266.72 | Y31: =VLOOKUP(A31,'[1]Pay sheet-APRIL- 2022'!$C$4:$AF$140,13,0) -> 2083 | Z31: =VLOOKUP(A31,'[1]Pay sheet-APRIL- 2022'!$C$4:$AF$140,14,0) -> 2083 | AA31: =VLOOKUP(A31,'[1]Pay sheet-APRIL- 2022'!$C$4:$AF$140,15,0) -> 8791.48 | AB31: =SUM(T31:AA31) -> 80391 | AC31: =VLOOKUP(A31,'[1]Pay sheet-APRIL- 2022'!$C$4:$AF$140,18,0) -> 1554.609 | AD31: =VLOOKUP(A31,'[1]Pay sheet-APRIL- 2022'!$C$4:$AF$140,19,0) -> 2316.8231 | AE31: =VLOOKUP(A31,'[1]Pay sheet-APRIL- 2022'!$C$4:$AF$140,20,0) -> 4013.9 | AF31: =VLOOKUP(A31,'[2]Pay sheet-MARCH- 2022'!$C$4:$AF$150,22,0) -> 0 | AG31: =AB31+AC31+AD31+AE31+AF31 -> 88276.332 | AH31: 0 | AI31: =VLOOKUP(A31,'[1]Pay sheet-APRIL- 2022'!$C$4:$AF$140,26,0) -> 1800 | AJ31: =VLOOKUP(A31,'[1]Pay sheet-APRIL- 2022'!$C$4:$AF$140,25,0) -> 200 | AK31: =VLOOKUP(A31,'[1]Pay sheet-APRIL- 2022'!$C$4:$AF$140,24,0) -> 0 | AL31: =VLOOKUP(A31,'[1]Pay sheet-APRIL- 2022'!$C$4:$AF$140,27,0) -> 283 | AN31: =AH31+AI31+AJ31+AK31+AL31+AM31 -> 2283 | AO31: =AG31-AN31 -> 85993.332 | AP31: 44686 | AQ31: BANK OF BARODA | AR31: 83270100000529 | AT31: 98 | AU31: 16
A32: BITS-740 | B32: MUMMANA ANILKUMAR | C32: 31261 | D32: Male | E32: MUMMANA VENKATESWARLU | F32: Sr Developer technical lead | G32: G2,subhashini manson,road no 20, alkapur township,manikonda,Hyderabad 500089 | H32: G2,subhashini manson,road no 20, alkapur township,manikonda,Hyderabad 500089 | I32: 44648 | J32: OOOO | N32: 100084289127 | O32: N/A | P32: ANILKUMAR MUMMANA | Q32: =VLOOKUP(A32,'[1]Pay sheet-APRIL- 2022'!$C$4:$AF$140,10,0) -> 30 | R32: N/A | S32: 131257 | T32: =VLOOKUP(A32,'[1]Pay sheet-APRIL- 2022'!$C$4:$AF$140,11,0) -> 78754.2 | U32: 0 | V32: 0 | W32: 0 | X32: =VLOOKUP(A32,'[1]Pay sheet-APRIL- 2022'!$C$4:$AF$140,12,0) -> 31501.68 | Y32: =VLOOKUP(A32,'[1]Pay sheet-APRIL- 2022'!$C$4:$AF$140,13,0) -> 2083 | Z32: =VLOOKUP(A32,'[1]Pay sheet-APRIL- 2022'!$C$4:$AF$140,14,0) -> 2083 | AA32: =VLOOKUP(A32,'[1]Pay sheet-APRIL- 2022'!$C$4:$AF$140,15,0) -> 16948.12 | AB32: =SUM(T32:AA32) -> 131370 | AC32: =VLOOKUP(A32,'[1]Pay sheet-APRIL- 2022'!$C$4:$AF$140,18,0) -> 1554.609 | AD32: =VLOOKUP(A32,'[1]Pay sheet-APRIL- 2022'!$C$4:$AF$140,19,0) -> 3788.077 | AE32: =VLOOKUP(A32,'[1]Pay sheet-APRIL- 2022'!$C$4:$AF$140,20,0) -> 6562.85 | AF32: =VLOOKUP(A32,'[2]Pay sheet-MARCH- 2022'!$C$4:$AF$150,22,0) -> 0 | AG32: =AB32+AC32+AD32+AE32+AF32 -> 143275.54 | AH32: 0 | AI32: =VLOOKUP(A32,'[1]Pay sheet-APRIL- 2022'!$C$4:$AF$140,26,0) -> 1800 | AJ32: =VLOOKUP(A32,'[1]Pay sheet-APRIL- 2022'!$C$4:$AF$140,25,0) -> 200 | AK32: =VLOOKUP(A32,'[1]Pay sheet-APRIL- 2022'!$C$4:$AF$140,24,0) -> 0 | AL32: =VLOOKUP(A32,'[1]Pay sheet-APRIL- 2022'!$C$4:$AF$140,27,0) -> 283 | AN32: =AH32+AI32+AJ32+AK32+AL32+AM32 -> 2283 | AO32: =AG32-AN32 -> 140992.54 | AP32: 44686 | AQ32: HDFC | AR32: 50100480501513 | AT32: 99 | AU32: 17
A33: BITS-742 | B33: Ravi Gande | C33: 30103 | D33: Male | E33: Narsimhulu | F33: JAVA DEVELOPER | G33: 14-1-90/434,60ft road,Gayatri nagar,Telangana,Hyderabad 500018 | H33: 14-1-90/434,60ft road,Gayatri nagar,Telangana,Hyderabad 500018 | I33: 44648 | J33: OOOO | N33: 100310765422 | O33: N/A | P33: Ravi Gande | Q33: =VLOOKUP(A33,'[1]Pay sheet-APRIL- 2022'!$C$4:$AF$140,10,0) -> 30 | R33: N/A | S33: 68182 | T33: =VLOOKUP(A33,'[1]Pay sheet-APRIL- 2022'!$C$4:$AF$140,11,0) -> 40909.2 | U33: 0 | V33: 0 | W33: 0 | X33: =VLOOKUP(A33,'[1]Pay sheet-APRIL- 2022'!$C$4:$AF$140,12,0) -> 16363.68 | Y33: =VLOOKUP(A33,'[1]Pay sheet-APRIL- 2022'!$C$4:$AF$140,13,0) -> 2083 | Z33: =VLOOKUP(A33,'[1]Pay sheet-APRIL- 2022'!$C$4:$AF$140,14,0) -> 2083 | AA33: =VLOOKUP(A33,'[1]Pay sheet-APRIL- 2022'!$C$4:$AF$140,15,0) -> 6856.12 | AB33: =SUM(T33:AA33) -> 68295 | AC33: =VLOOKUP(A33,'[1]Pay sheet-APRIL- 2022'!$C$4:$AF$140,18,0) -> 1441.609 | AD33: =VLOOKUP(A33,'[1]Pay sheet-APRIL- 2022'!$C$4:$AF$140,19,0) -> 1967.7325 | AE33: =VLOOKUP(A33,'[1]Pay sheet-APRIL- 2022'!$C$4:$AF$140,20,0) -> 3409.1 | AF33: =VLOOKUP(A33,'[2]Pay sheet-MARCH- 2022'!$C$4:$AF$150,22,0) -> 0 | AG33: =AB33+AC33+AD33+AE33+AF33 -> 75113.442 | AH33: 0 | AI33: =VLOOKUP(A33,'[1]Pay sheet-APRIL- 2022'!$C$4:$AF$140,26,0) -> 0 | AJ33: =VLOOKUP(A33,'[1]Pay sheet-APRIL- 2022'!$C$4:$AF$140,25,0) -> 200 | AK33: =VLOOKUP(A33,'[1]Pay sheet-APRIL- 2022'!$C$4:$AF$140,24,0) -> 0 | AL33: =VLOOKUP(A33,'[1]Pay sheet-APRIL- 2022'!$C$4:$AF$140,27,0) -> 0 | AN33: =AH33+AI33+AJ33+AK33+AL33+AM33 -> 200 | AO33: =AG33-AN33 -> 74913.442 | AP33: 44686 | AQ33: ICICI BANK | AR33: 038201510552 | AT33: 100 | AU33: 18
A34: BITS-745 | B34: NarsiReddy Venna | C34: 25-07-1986 | D34: Male | E34: Krishna Reddy | F34: Senior Administrator | G34: Flat No 26B,Street No.1,HUDA colony,Saroor nagar,Near Kothapet signal,Hyderabda TS | H34: Flat No 26B,Street No.1,HUDA colony,Saroor nagar,Near Kothapet signal,Hyderabda TS | I34: 44655 | J34: OOOO | N34: 101322850601 | O34: N/A | P34: NarsiReddy Venna | Q34: =VLOOKUP(A34,'[1]Pay sheet-APRIL- 2022'!$C$4:$AF$140,10,0) -> 27 | S34: 112719 | T34: =VLOOKUP(A34,'[1]Pay sheet-APRIL- 2022'!$C$4:$AF$140,11,0) -> 60868.26 | U34: 0 | V34: 0 | W34: 0 | X34: =VLOOKUP(A34,'[1]Pay sheet-APRIL- 2022'!$C$4:$AF$140,12,0) -> 24347.304 | Y34: =VLOOKUP(A34,'[1]Pay sheet-APRIL- 2022'!$C$4:$AF$140,13,0) -> 1875 | Z34: =VLOOKUP(A34,'[1]Pay sheet-APRIL- 2022'!$C$4:$AF$140,14,0) -> 1875 | AA34: =VLOOKUP(A34,'[1]Pay sheet-APRIL- 2022'!$C$4:$AF$140,15,0) -> 12594.536 | AB34: =SUM(T34:AA34) -> 101560.1 | AC34: =VLOOKUP(A34,'[1]Pay sheet-APRIL- 2022'!$C$4:$AF$140,18,0) -> 1554.609 | AD34: =VLOOKUP(A34,'[1]Pay sheet-APRIL- 2022'!$C$4:$AF$140,19,0) -> 2927.7633 | AE34: =VLOOKUP(A34,'[1]Pay sheet-APRIL- 2022'!$C$4:$AF$140,20,0) -> 5072.355 | AF34: 0 | AG34: =AB34+AC34+AD34+AE34+AF34 -> 111114.83 | AH34: 0 | AI34: =VLOOKUP(A34,'[1]Pay sheet-APRIL- 2022'!$C$4:$AF$140,26,0) -> 1800 | AJ34: =VLOOKUP(A34,'[1]Pay sheet-APRIL- 2022'!$C$4:$AF$140,25,0) -> 200 | AK34: =VLOOKUP(A34,'[1]Pay sheet-APRIL- 2022'!$C$4:$AF$140,24,0) -> 0 | AL34: =VLOOKUP(A34,'[1]Pay sheet-APRIL- 2022'!$C$4:$AF$140,27,0) -> 0 | AN34: =AH34+AI34+AJ34+AK34+AL34+AM34 -> 2000 | AO34: =AG34-AN34 -> 109114.83 | AP34: 44686 | AQ34: CITI Bank | AR34: 5708925554 | AT34: 101 | AU34: 19
A35: BITS-750 | B35: AbdulSaleem Sunkesula | C35: 10-05-1993 | D35: Male | E35: Sunkesula Sowdayya | F35: Technical Consultant | G35: 19/76,Papireddygari palle,Ramapuram,Hasanapuram,Kadapa,AP 516504 | H35: 19/76,Papireddygari palle,Ramapuram,Hasanapuram,Kadapa,AP 516504 | I35: 44671 | J35: OOOO | N35: 101814583013 | O35: N/A | P35: AbdulSaleem Sunkesula | Q35: =VLOOKUP(A35,'[1]Pay sheet-APRIL- 2022'!$C$4:$AF$140,10,0) -> 11 | S35: 75643 | T35: =VLOOKUP(A35,'[1]Pay sheet-APRIL- 2022'!$C$4:$AF$140,11,0) -> 16641.46 | U35: 0 | V35: 0 | W35: 0 | X35: =VLOOKUP(A35,'[1]Pay sheet-APRIL- 2022'!$C$4:$AF$140,12,0) -> 6656.584 | Y35: =VLOOKUP(A35,'[1]Pay sheet-APRIL- 2022'!$C$4:$AF$140,13,0) -> 764 | Z35: =VLOOKUP(A35,'[1]Pay sheet-APRIL- 2022'!$C$4:$AF$140,14,0) -> 764 | AA35: =VLOOKUP(A35,'[1]Pay sheet-APRIL- 2022'!$C$4:$AF$140,15,0) -> 3022.7227 | AB35: =SUM(T35:AA35) -> 27848.767 | AC35: =VLOOKUP(A35,'[1]Pay sheet-APRIL- 2022'!$C$4:$AF$140,18,0) -> 1554.609 | AD35: =VLOOKUP(A35,'[1]Pay sheet-APRIL- 2022'!$C$4:$AF$140,19,0) -> 800.45423 | AE35: =VLOOKUP(A35,'[1]Pay sheet-APRIL- 2022'!$C$4:$AF$140,20,0) -> 1386.7883 | AF35: 0 | AG35: =AB35+AC35+AD35+AE35+AF35 -> 31590.618 | AH35: 0 | AI35: =VLOOKUP(A35,'[1]Pay sheet-APRIL- 2022'!$C$4:$AF$140,26,0) -> 1800 | AJ35: =VLOOKUP(A35,'[1]Pay sheet-APRIL- 2022'!$C$4:$AF$140,25,0) -> 200 | AK35: =VLOOKUP(A35,'[1]Pay sheet-APRIL- 2022'!$C$4:$AF$140,24,0) -> 0 | AL35: =VLOOKUP(A35,'[1]Pay sheet-APRIL- 2022'!$C$4:$AF$140,27,0) -> 0 | AN35: =AH35+AI35+AJ35+AK35+AL35+AM35 -> 2000 | AO35: =AG35-AN35 -> 29590.618 | AP35: 44686 | AQ35: SBI | AR35: 20029285687 | AT35: 102 | AU35: 20
A36: BITS-752 | B36: SADHAM HUSSAIN | C36: 16-04-1991 | D36: Male | E36: Shahul Hameed | F36: Security Administrator | G36: 10/8,Amman pagoda lane,7 Hills,Chennai,Tamilnadu 600001 | H36: 10/8,Amman pagoda lane,7 Hills,Chennai,Tamilnadu 600001 | I36: 44676 | J36: OOOO | N36: 100554328630 | O36: N/A | P36: SADHAMHUSSAIN | Q36: =VLOOKUP(A36,'[1]Pay sheet-APRIL- 2022'!$C$4:$AF$140,10,0) -> 6 | S36: 135892 | T36: =VLOOKUP(A36,'[1]Pay sheet-APRIL- 2022'!$C$4:$AF$140,11,0) -> 16307.04 | U36: 0 | V36: 0 | W36: 0 | X36: =VLOOKUP(A36,'[1]Pay sheet-APRIL- 2022'!$C$4:$AF$140,12,0) -> 6522.816 | Y36: =VLOOKUP(A36,'[1]Pay sheet-APRIL- 2022'!$C$4:$AF$140,13,0) -> 417 | Z36: =VLOOKUP(A36,'[1]Pay sheet-APRIL- 2022'!$C$4:$AF$140,14,0) -> 417 | AA36: =VLOOKUP(A36,'[1]Pay sheet-APRIL- 2022'!$C$4:$AF$140,15,0) -> 3627.544 | AB36: =SUM(T36:AA36) -> 27291.4 | AC36: =VLOOKUP(A36,'[1]Pay sheet-APRIL- 2022'!$C$4:$AF$140,18,0) -> 1554.609 | AD36: =VLOOKUP(A36,'[1]Pay sheet-APRIL- 2022'!$C$4:$AF$140,19,0) -> 784.36862 | AE36: =VLOOKUP(A36,'[1]Pay sheet-APRIL- 2022'!$C$4:$AF$140,20,0) -> 1358.92 | AF36: 0 | AG36: =AB36+AC36+AD36+AE36+AF36 -> 30989.298 | AH36: 0 | AI36: =VLOOKUP(A36,'[1]Pay sheet-APRIL- 2022'!$C$4:$AF$140,26,0) -> 1800 | AJ36: =VLOOKUP(A36,'[1]Pay sheet-APRIL- 2022'!$C$4:$AF$140,25,0) -> 200 | AK36: =VLOOKUP(A36,'[1]Pay sheet-APRIL- 2022'!$C$4:$AF$140,24,0) -> 0 | AL36: =VLOOKUP(A36,'[1]Pay sheet-APRIL- 2022'!$C$4:$AF$140,27,0) -> 0 | AN36: =AH36+AI36+AJ36+AK36+AL36+AM36 -> 2000 | AO36: =AG36-AN36 -> 28989.298 | AP36: 44686 | AQ36: HDFC BANK | AR36: 50100271012409 | AT36: 103 | AU36: 21
X37: =SUM(X16:X36) -> 382850.98 | Y37: =SUM(Y16:Y36) -> 39898 | Z37: =SUM(Z16:Z36) -> 39898 | AA37: =SUM(AA16:AA36) -> 177810.98 | AB37: =SUM(AB16:AB36) -> 1597585.4 | AC37: =SUM(AC16:AC36) -> 32533.789 | AD37: =SUM(AD16:AD36) -> 46037.83 | AE37: =SUM(AE16:AE36) -> 79760.62 | AG37: =SUM(AG16:AG36) -> 1755917.6 | AI37: =SUM(AI16:AI36) -> 35974 | AJ37: =SUM(AJ16:AJ36) -> 4200 | AK37: =SUM(AK16:AK36) -> 0 | AL37: =SUM(AL16:AL36) -> 5347.3635 | AN37: =SUM(AN16:AN36) -> 45521.364 | AO37: =SUM(AO16:AO36) -> 1710396.3
Q38: =SUM(Q16:Q37) -> 583 | T38: =SUM(T16:T37) -> 957127.44
H667: ='04-22-Master'!I259 -> 0

Sheet Eql remon
A1: Form D
A2: (See rule 6)
A4: Register to be maintained by the employer under rule 6 of the Equal Remuneration Rules, 1976
D6: ='04-22-Master'!D10 -> 44652
A8: Name and address of Contractor : | F8: ='04-22-Master'!F5 -> Burgeon IT Services Pvt.Ltd.
A10: Name and address of establishment in/under which contract is carried on : | F10: ='04-22-Master'!AJ5 -> Burgeon IT Services Pvt.Ltd.
F11: ='04-22-Master'!AJ6 -> Siri Mansion LIGB 436 Dr.A S Rao Nagar,Hyderabad
A12: Name and address of Principal Employer : | F12: ='04-22-Master'!AJ10 -> INFOSYS LTD.IL Hyderabad SEZ
F13: ='04-22-Master'!AJ11 -> Sy.No 42,Pocharam Village,Gatkesar Mandal
A14: Total number of men workers employed | C14: =D41 -> 16
A16: Total number of women workers employed | C16: =C41 -> 5
C18: Components of remuneration
A19: Category of workers | B19: Brief Description of work | C19: No of women employed | D19: No. of men employed | E19: Rate or remuneration paid | F19: Basic wage & Dearness Allowance | G19: House Rent allowance | H19: Other allowances | I19: Cash value of concessional supply of essential commodities | J19: Name of the Client | K19: Primary Work Place/ Location
A20: ='04-22-Master'!F16 -> SR.Application Consultant | B20: IT SUPPORTIVE SERVICES | C20: 0 | D20: 1 | E20: ='04-22-Master'!S16 -> 84913 | F20: ='04-22-Master'!T16 -> 50947.8 | G20: ='04-22-Master'!X16 -> 20379.12 | H20: =E20-(F20+G20) -> 13586.08 | I20: 0 | J20: INFOSYS LTD | K20: HYDERABAD
A21: ='04-22-Master'!F17 -> Senior Test Engineer | B21: IT SUPPORTIVE SERVICES | C21: 0 | D21: 1 | E21: ='04-22-Master'!S17 -> 66374 | F21: ='04-22-Master'!T17 -> 39824.4 | G21: ='04-22-Master'!X17 -> 15929.76 | H21: =E21-(F21+G21) -> 10619.84 | I21: 0 | K21: SEZ
A22: ='04-22-Master'!F18 -> Technical consultant | B22: IT SUPPORTIVE SERVICES | C22: 0 | D22: 1 | E22: ='04-22-Master'!S18 -> 89547 | F22: ='04-22-Master'!T18 -> 53728.2 | G22: ='04-22-Master'!X18 -> 21491.28 | H22: =E22-(F22+G22) -> 14327.52 | I22: 0
A23: ='04-22-Master'!F19 -> PMO Manager | B23: IT SUPPORTIVE SERVICES | C23: 0 | D23: 1 | E23: ='04-22-Master'!S19 -> 103451 | F23: ='04-22-Master'!T19 -> 62070.6 | G23: ='04-22-Master'!X19 -> 24828.24 | H23: =E23-(F23+G23) -> 16552.16 | I23: 0
A24: ='04-22-Master'!F20 -> Sr. Network Security Engineer | B24: IT SUPPORTIVE SERVICES | C24: 0 | D24: 1 | E24: ='04-22-Master'!S20 -> 66374 | F24: ='04-22-Master'!T20 -> 39824.4 | G24: ='04-22-Master'!X20 -> 15929.76 | H24: =E24-(F24+G24) -> 10619.84 | I24: 0
A25: ='04-22-Master'!F21 -> Senior Specialist | B25: IT SUPPORTIVE SERVICES | C25: 0 | D25: 1 | E25: ='04-22-Master'!S21 -> 84912 | F25: ='04-22-Master'!T21 -> 50947.2 | G25: ='04-22-Master'!X21 -> 20378.88 | H25: =E25-(F25+G25) -> 13585.92 | I25: 0
A26: ='04-22-Master'!F22 -> TECHNICAL SOLUTION CONSULTANT | B26: IT SUPPORTIVE SERVICES | C26: 1 | D26: 0 | E26: ='04-22-Master'!S22 -> 108085 | F26: ='04-22-Master'!T22 -> 64851 | G26: ='04-22-Master'!X22 -> 25940.4 | H26: =E26-(F26+G26) -> 17293.6 | I26: 0
A27: ='04-22-Master'!F23 -> Incident Governance Manager | B27: IT SUPPORTIVE SERVICES | C27: 0 | D27: 1 | E27: ='04-22-Master'!S23 -> 140526 | F27: ='04-22-Master'!T23 -> 84315.6 | G27: ='04-22-Master'!X23 -> 33726.24 | H27: =E27-(F27+G27) -> 22484.16 | I27: 0
A28: ='04-22-Master'!F24 -> Technical Lead | B28: IT SUPPORTIVE SERVICES | C28: 1 | D28: 0 | E28: ='04-22-Master'!S24 -> 98816 | F28: ='04-22-Master'!T24 -> 57313.28 | G28: ='04-22-Master'!X24 -> 22925.312 | H28: =E28-(F28+G28) -> 18577.408 | I28: 0
A29: ='04-22-Master'!F25 -> Service Now Developer | B29: IT SUPPORTIVE SERVICES | C29: 1 | D29: 0 | E29: ='04-22-Master'!S25 -> 75643 | F29: ='04-22-Master'!T25 -> 45385.8 | G29: ='04-22-Master'!X25 -> 18154.32 | H29: =E29-(F29+G29) -> 12102.88 | I29: 0
A30: ='04-22-Master'!F26 -> SAP Basis Consultant | B30: IT SUPPORTIVE SERVICES | C30: 1 | D30: 0 | E30: ='04-22-Master'!S26 -> 38567 | F30: ='04-22-Master'!T26 -> 23140.2 | G30: ='04-22-Master'!X26 -> 9256.08 | H30: =E30-(F30+G30) -> 6170.72 | I30: 0
A31: ='04-22-Master'!F27 -> SAP Basis Consultant | B31: IT SUPPORTIVE SERVICES | C31: 0 | D31: 1 | E31: ='04-22-Master'!S27 -> 24636 | F31: ='04-22-Master'!T27 -> 14781.6 | G31: ='04-22-Master'!X27 -> 5912.64 | H31: =E31-(F31+G31) -> 3941.76 | I31: 0
A32: ='04-22-Master'!F28 -> SAP Basis Consultant | B32: IT SUPPORTIVE SERVICES | C32: 0 | D32: 1 | E32: ='04-22-Master'!S28 -> 38567 | F32: ='04-22-Master'!T28 -> 23140.2 | G32: ='04-22-Master'!X28 -> 9256.08 | H32: =E32-(F32+G32) -> 6170.72 | I32: 0
A33: ='04-22-Master'!F29 -> SAP Basis Consultant | B33: IT SUPPORTIVE SERVICES | C33: 0 | D33: 1 | E33: ='04-22-Master'!S29 -> 38567 | F33: ='04-22-Master'!T29 -> 23140.2 | G33: ='04-22-Master'!X29 -> 9256.08 | H33: =E33-(F33+G33) -> 6170.72 | I33: 0
... A40: ='04-22-Master'!F36 -> Security Administrator | B40: IT SUPPORTIVE SERVICES | C40: 0 | D40: 1 | E40: ='04-22-Master'!S36 -> 135892 | F40: ='04-22-Master'!T36 -> 16307.04 | G40: ='04-22-Master'!X36 -> 6522.816 | H40: =E40-(F40+G40) -> 113062.14 | I40: 0
C41: =SUM(C20:C40) -> 5 | D41: =SUM(D20:D40) -> 16
I47: Signature of the Contractor with Seal

Sheet 04-22-TMur Roll
A1: FORM - XVI MUSTER ROLL [Vide Rule 78 (1) (P) (i) of ContrPct LPbour (Reg. & Pbolition) CentrPl & TPPngPnP Rules 1971]
A3: NPme Pnd Pddress of ContrPctor: | D3: ='04-22-Master'!F5 -> Burgeon IT Services Pvt.Ltd. | J3: Name and address of Establishemnt in/ under which contract is carried on: | Z3: ='04-22-Master'!AJ5 -> Burgeon IT Services Pvt.Ltd.
D4: ='04-22-Master'!F6 -> Siri Mansion LIGB 436 Dr.A S Rao Nagar,Hyderabad | Z4: ='04-22-Master'!AJ6 -> Siri Mansion LIGB 436 Dr.A S Rao Nagar,Hyderabad
A5: Nature and location of work: | D5: ='[3]HYD-Master-JULY21'!F8 -> IT Support Services & Hyderabad
A6: Wage period: Monthly | D6: ='04-22-Master'!D10 -> 44652 | J6: Name and address of Principal Employer: | Z6: ='04-22-Master'!AJ10 -> INFOSYS LTD.IL Hyderabad SEZ
Z7: ='04-22-Master'!AJ11 -> Sy.No 42,Pocharam Village,Gatkesar Mandal
A10: S.No | B10: Name of Workman | C10: Father's/ Husband's Name | D10: Sex
E11: 1 | F11: 2 | G11: 3 | H11: 4 | I11: 5 | J11: 6 | K11: 7 | L11: 8 | M11: 9 | N11: 10 | O11: 11 | P11: 12 | Q11: 13 | R11: 14 | S11: 15 | T11: 16 | U11: 17 | V11: 18 | W11: 19 | X11: 20 | Y11: 21 | Z11: 22 | AA11: 23 | AB11: 24 | AC11: 25 | AD11: 26 | AE11: 27 | AF11: 28 | AG11: 29 | AH11: 30 | AI11: P Days | AJ11: Remarks
A12: 1 | B12: ='04-22-Master'!B16 -> kaja Venkat Ragavendra | C12: ='04-22-Master'!E16 -> Kaja Suresh Babu | D12: ='04-22-Master'!D16 -> Male | E12: P | F12: WO | G12: WO | H12: P | I12: P | J12: P | K12: P | L12: EL | M12: WO | N12: WO | O12: P | P12: P | Q12: P | R12: P | S12: H | T12: WO | U12: WO | V12: P | W12: P | X12: P | Y12: P | Z12: P | AA12: WO | AB12: WO | AC12: P | AD12: P | AE12: P | AF12: P | AG12: P | AH12: WO | AI12: ='04-22-Master'!Q16 -> 30
A13: 2 | B13: ='04-22-Master'!B17 -> VeerendraBabu Galam | C13: ='04-22-Master'!E17 -> Gopal Rao | D13: ='04-22-Master'!D17 -> Male | E13: P | F13: WO | G13: WO | H13: P | I13: P | J13: P | K13: P | L13: P | M13: WO | N13: WO | O13: EL | P13: P | Q13: P | R13: P | S13: H | T13: WO | U13: WO | V13: P | W13: P | X13: P | Y13: P | Z13: P | AA13: WO | AB13: WO | AC13: P | AD13: P | AE13: P | AF13: P | AG13: P | AH13: WO | AI13: ='04-22-Master'!Q17 -> 30
A14: 3 | B14: ='04-22-Master'!B18 -> RUKNUDEEN S | C14: ='04-22-Master'!E18 -> SIRBUDIN.T | D14: ='04-22-Master'!D18 -> Male | E14: P | F14: WO | G14: WO | H14: P | I14: P | J14: P | K14: P | L14: P | M14: WO | N14: WO | O14: P | P14: P | Q14: P | R14: EL | S14: H | T14: WO | U14: WO | V14: P | W14: P | X14: P | Y14: P | Z14: P | AA14: WO | AB14: WO | AC14: P | AD14: P | AE14: P | AF14: P | AG14: P | AH14: WO | AI14: ='04-22-Master'!Q18 -> 30
A15: 4 | B15: ='04-22-Master'!B19 -> Srikanth Thota | C15: ='04-22-Master'!E19 -> Vasudha thota | D15: ='04-22-Master'!D19 -> Male | E15: P | F15: WO | G15: WO | H15: P | I15: P | J15: P | K15: P | L15: P | M15: WO | N15: WO | O15: P | P15: P | Q15: P | R15: P | S15: H | T15: WO | U15: WO | V15: P | W15: P | X15: P | Y15: P | Z15: P | AA15: WO | AB15: WO | AC15: P | AD15: P | AE15: P | AF15: P | AG15: EL | AH15: WO | AI15: ='04-22-Master'!Q19 -> 30
A16: 5 | B16: ='04-22-Master'!B20 -> Shekhar Panchal | C16: ='04-22-Master'!E20 -> Naresh Kumar Panchal | D16: ='04-22-Master'!D20 -> Male | E16: P | F16: WO | G16: WO | H16: P | I16: P | J16: P | K16: P | L16: P | M16: WO | N16: WO | O16: P | P16: P | Q16: P | R16: P | S16: H | T16: WO | U16: WO | V16: P | W16: P | X16: P | Y16: P | Z16: P | AA16: WO | AB16: WO | AC16: P | AD16: P | AE16: P | AF16: P | AG16: P | AH16: WO | AI16: ='04-22-Master'!Q20 -> 30
A17: 6 | B17: ='04-22-Master'!B21 -> Gangadhar Yarabham | C17: ='04-22-Master'!E21 -> Yarabham Savaraiah | D17: ='04-22-Master'!D21 -> Male | E17: P | F17: WO | G17: WO | H17: P | I17: P | J17: P | K17: P | L17: P | M17: WO | N17: WO | O17: P | P17: P | Q17: P | R17: P | S17: H | T17: WO | U17: WO | V17: P | W17: P | X17: P | Y17: P | Z17: P | AA17: WO | AB17: WO | AC17: P | AD17: P | AE17: P | AF17: P | AG17: P | AH17: WO | AI17: ='04-22-Master'!Q21 -> 30
A18: 7 | B18: ='04-22-Master'!B22 -> Nikhila Kaveri | C18: ='04-22-Master'!E22 -> Sreehari | D18: ='04-22-Master'!D22 -> FEMALE | E18: P | F18: WO | G18: WO | H18: P | I18: P | J18: P | K18: P | L18: P | M18: WO | N18: WO | O18: P | P18: P | Q18: P | R18: P | S18: H | T18: WO | U18: WO | V18: P | W18: P | X18: P | Y18: P | Z18: P | AA18: WO | AB18: WO | AC18: P | AD18: P | AE18: P | AF18: P | AG18: P | AH18: WO | AI18: ='04-22-Master'!Q22 -> 30
A19: 8 | B19: ='04-22-Master'!B23 -> Thaposh Ghosh | C19: ='04-22-Master'!E23 -> CH Divya Vani | D19: ='04-22-Master'!D23 -> MALE | E19: P | F19: WO | G19: WO | H19: P | I19: P | J19: P | K19: P | L19: P | M19: WO | N19: WO | O19: P | P19: P | Q19: P | R19: P | S19: H | T19: WO | U19: WO | V19: P | W19: P | X19: P | Y19: P | Z19: P | AA19: WO | AB19: WO | AC19: P | AD19: P | AE19: P | AF19: P | AG19: P | AH19: WO | AI19: ='04-22-Master'!Q23 -> 30
A20: 9 | B20: ='04-22-Master'!B24 -> Nagashree Narayan | C20: ='04-22-Master'!E24 -> KANTHA KAMBAIAH LAKSHMI | D20: ='04-22-Master'!D24 -> FEMALE | E20: P | F20: WO | G20: WO | H20: P | I20: P | J20: P | K20: P | L20: P | M20: WO | N20: WO | O20: EL | P20: A | Q20: P | R20: P | S20: H | T20: WO | U20: WO | V20: P | W20: P | X20: P | Y20: P | Z20: P | AA20: WO | AB20: WO | AC20: P | AD20: P | AE20: P | AF20: P | AG20: P | AH20: WO | AI20: ='04-22-Master'!Q24 -> 29
