Workbook
Name _edn1: 'Leave Reg'!#REF!
Name _ednref1: 'Leave Reg'!#REF!

Sheet ORRISA APRIL 22WM Reg
A1: FORM - IX REGISTER OF WORKMEN EMPLOYED BY CONTRACTOR
I2: (Vide Rule 74 of Contract Labour (Regulation and Abolition) act Odisha. Rules 1975)
A3: Name and address of Contractor: | F3: ='0422Master'!AO5 -> Burgeon IT Services Pvt.Ltd. | L3: Name and address of Establishemnt in/ under which conctract is carried on:
F4: ='0422Master'!F6 -> Siri Mansion LIGB 436 Dr.A S Rao Nagar,Hyderabad
A5: Nature and location of work: | F5: ='0422Master'!F8 -> IT SUPPORTIVE SERVICES & BHUBANESWAR
L7: Name and address of Principal Employer: | N7: Name of the Principle | O7: ='0422Master'!AO8 -> INFOSYS LIMITED, IL BHUBANESHWAR-STP,UNIT-II
N8: Employer | O8: ='0422Master'!AO10 -> Plot No E/4,Info city,Chandaka Industrial, Bhubaneswar,Odisha - 751024
A11: Serial No. in the Register of Workmen | B11: Name of Workman | C11: Age | D11: Sex | E11: Father's /Husband Name | F11: Designation / Nature of Work Done | G11: Permanent Address | J11: Present Address | N11: Date of Commencement of Employment | O11: ='0422Master'!O12 -> Date of termination of Employment | P11: ='0422Master'!P12 -> Reasons for termination | Q11: ='0422Master'!Q12 -> Signature or thumb impression of Workman | R11: Remarks
A13: ='0422Master'!A14 -> 1 | B13: ='0422Master'!B14 -> KRANTHI KUMAR VEDULLA | C13: ='0422Master'!C14 -> 05.02.1992 | D13: ='0422Master'!D14 -> Male | E13: ='0422Master'!E14 -> Kamini Venkatarami Reddy | F13: ='0422Master'!F14 -> Senior Network Engineer | G13: ='0422Master'!G14 -> 1/93 , Sanagala Guduru, Putluru (M), Anantapur (D), Andhra pradesh, 515411 | H13: ='0422Master'!H14 -> 0 | ... N13: ='0422Master'!N14 -> 44181
A14: ='0422Master'!A15 -> 2 | B14: ='0422Master'!B15 -> Vipin U.N | C14: ='0422Master'!C15 -> 28/02/1991 | D14: ='0422Master'!D15 -> Male | E14: ='0422Master'!E15 -> GANGA G | F14: ='0422Master'!F15 -> Senior IT Endpoint Engineer | G14: ='0422Master'!G15 -> #30 "Rajeevam" Ground Floor 2nd cross,Green Garden Layout,12th Main NRI Layout Varanasi,Jinekethimmanahali, Ramamurthy Nagar ,Bangalore - 560036 | H14: ='0422Master'!H15 -> 0 | ... N14: ='0422Master'!N15 -> 44181
O27: Signature of the Contractor with Seal
A44: ='0422Master'!#REF! -> #REF! | B44: ='0422Master'!#REF! -> #REF! | C44: ='0422Master'!#REF! -> #REF! | D44: ='0422Master'!#REF! -> #REF! | E44: ='0422Master'!#REF! -> #REF! | F44: ='0422Master'!#REF! -> #REF! | G44: ='0422Master'!#REF! -> #REF! | H44: ='0422Master'!#REF! -> #REF! | ... Q44: ='0422Master'!#REF! -> #REF!

Sheet 0422Master
A3: FORM - XIII REGISTER OF WORKMEN EMPLOYED BY CONTRACTOR
B4: (Vide Rule 75 of Contract Labour (Regulation and Abolition) Act Odisha Rules 1975)
A5: Name and address of Contractor: | F5: Burgeon IT Services Pvt.Ltd. | AA5: Name and address of Establishemnt in/ under which contract is carried on: | AO5: Burgeon IT Services Pvt.Ltd.
F6: Siri Mansion LIGB 436 Dr.A S Rao Nagar,Hyderabad | AO6: Siri Mansion LIGB 436 Dr.A S Rao Nagar,Hyderabad
A8: Nature and location of work: | F8: IT SUPPORTIVE SERVICES & BHUBANESWAR | AJ8: Name and address of Principal Employer: | AO8: INFOSYS LIMITED, IL BHUBANESHWAR-STP,UNIT-II
A9: Wage period: Monthly | D9: 44652
AO10: Plot No E/4,Info city,Chandaka Industrial, Bhubaneswar,Odisha - 751024
F11: software Engineer
A12: Serial No. in the Register of Workmen | B12: Name of Workman | C12: Age | D12: Sex | E12: Father's /Husband Name | F12: Designation / Nature of Work Done | G12: Permanent Address | J12: Present Address | N12: Date of Commencement of Employment | O12: Date of termination of Employment | P12: Reasons for termination | Q12: Signature or thumb impression of Workman | R12: Remarks | S12: EPF Number | T12: ESI Number | U12: Name of Workman | V12: No.of Days worked | W12: Unit of work done | X12: Monthly rate of wages/ piece rate | Y12: Basic wages | Z12: Dearness Allowances | AA12: Over time | AB12: Other cash payments (Nature of payments to be indicated) | AC12: HRA | AD12: CONVEYANCE | AE12: MEDICAL ALLOWANCES | AF12: SPECIAL ALLOWNANCES | AG12: Total | AH12: BONUS | AI12: GRATUITY | AJ12: LTA/L.E | AK12: ARREAR AMOUNT | AL12: TOTAL AMOUNT | AM12: Deductions, if any, (Indicate nature) | AS12: Net Amount paid | AT12: Time and Date of Payment | AU12: Place of Payment | AV12: Signature/Thumb Impression of workman | AW12: Initial of Contractor or his representative
AM13: ESI | AN13: PF | AO13: PT | AP13: TDS | AQ13: MEDICAL/Advance | AR13: Total Deductions
A14: 1 | B14: KRANTHI KUMAR VEDULLA | C14: 05.02.1992 | D14: Male | E14: Kamini Venkatarami Reddy | F14: Senior Network Engineer | G14: 1/93 , Sanagala Guduru, Putluru (M), Anantapur (D), Andhra pradesh, 515411 | J14: 1/93 , Sanagala Guduru, Putluru (M), Anantapur (D), Andhra pradesh, 515411 | N14: 44181 | S14: 101135871959 | T14: NA | U14: =B14 -> KRANTHI KUMAR VEDULLA | V14: 30 | X14: 84912 | Y14: 50947.2 | Z14: 0 | AA14: 0 | AC14: 20378.88 | AD14: 2083 | AE14: 2083 | AF14: 9532.92 | AG14: =Y14+AC14+AD14+AE14+AF14 -> 85025 | AH14: 1554.609 | AI14: 2450.5603 | AJ14: 4245.6 | AK14: 0 | AL14: =AG14+AH14+AI14+AJ14+AK14 -> 93275.769 | AN14: 1800 | AO14: 200 | AQ14: 392 | AR14: =SUM(AM14:AQ14) -> 2392 | AS14: =AL14-AR14 -> 90883.769 | AT14: 44686 | AU14: ICICI | AV14: A/C'403901506350
A15: 2 | B15: Vipin U.N | C15: 28/02/1991 | D15: Male | E15: GANGA G | F15: Senior IT Endpoint Engineer | G15: #30 "Rajeevam" Ground Floor 2nd cross,Green Garden Layout,12th Main NRI Layout Varanasi,Jinekethimmanahali, Ramamurthy Nagar ,Bangalore - 560036 | J15: #30 "Rajeevam" Ground Floor 2nd cross,Green Garden Layout,12th Main NRI Layout Varanasi,Jinekethimmanahali, Ramamurthy Nagar ,Bangalore - 560036 | N15: 44181 | S15: 101329723141 | T15: NA | U15: =B15 -> Vipin U.N | V15: 8 | X15: 105304 | Y15: 16848.64 | Z15: 0 | AA15: 0 | AC15: 6739.456 | AD15: 555 | AE15: 555 | AF15: 3495.9707 | AG15: =Y15+AC15+AD15+AE15+AF15 -> 28194.067 | AH15: 1554.609 | AI15: 810.41958 | AJ15: 1404.0533 | AK15: 0 | AL15: =AG15+AH15+AI15+AJ15+AK15 -> 31963.149 | AN15: 1800 | AO15: 200 | AQ15: 392 | AR15: =SUM(AM15:AQ15) -> 2392 | AS15: =AL15-AR15 -> 29571.149 | AT15: 44686 | AU15: ICICI | AV15: A/C025201526367
X16: =SUM(X14:X15) -> 190216 | Y16: =SUM(Y14:Y15) -> 67795.84 | AC16: =SUM(AC14:AC15) -> 27118.336 | AD16: =SUM(AD14:AD15) -> 2638 | AE16: =SUM(AE14:AE15) -> 2638 | AF16: =SUM(AF14:AF15) -> 13028.891 | AG16: =SUM(AG14:AG15) -> 113219.07 | AH16: =SUM(AH14:AH15) -> 3109.218 | AI16: =SUM(AI14:AI15) -> 3260.9799 | AJ16: =SUM(AJ14:AJ15) -> 5649.6533 | AL16: =SUM(AL14:AL15) -> 125238.92 | AN16: =SUM(AN14:AN15) -> 3600 | AO16: =SUM(AO14:AO15) -> 400 | AP16: =SUM(AP14:AP15) -> 0 | AQ16: =SUM(AQ14:AQ15) -> 784 | AR16: =SUM(AR14:AR15) -> 4784 | AS16: =SUM(AS14:AS15) -> 120454.92
AL17: =AL15+1950 -> 33913.149

Sheet 04-22Equal remu
A1: Form D
A2: (See rule 6)
A4: Register to be maintained by the employer under rule 6 of the Equal Remuneration Rules, 1976
D6: ='0422Master'!D9 -> 44652
A8: Name and address of Contractor : | F8: ='0422Master'!F5 -> Burgeon IT Services Pvt.Ltd.
F9: ='0422Master'!AO6 -> Siri Mansion LIGB 436 Dr.A S Rao Nagar,Hyderabad
A10: Name and address of establishment in/under which contract is carried on :
A12: Name and address of Principal Employer : | F12: ='0422Master'!AO8 -> INFOSYS LIMITED, IL BHUBANESHWAR-STP,UNIT-II
F13: ='0422Master'!AO10 -> Plot No E/4,Info city,Chandaka Industrial, Bhubaneswar,Odisha - 751024
A14: Total number of men workers employed | C14: =D22 -> 2
A16: Total number of women workers employed | C16: =C22 -> 0
C18: Components of remuneration
A19: Category of workers | B19: Brief Description of work | C19: No of women employed | D19: No. of men employed | E19: Rate or remuneration paid | F19: Basic wage & Dearness Allowance | G19: House Rent allowance | H19: Other allowances | I19: Cash value of concessional supply of essential commodities | J19: Name of the Client | K19: Primary Work Place/ Location
A20: ='0422Master'!F14 -> Senior Network Engineer | B20: IT SUPPORTIVE SERVICES | C20: 0 | D20: 1 | E20: ='0422Master'!X14 -> 84912 | F20: ='0422Master'!Y14 -> 50947.2 | G20: ='0422Master'!AC14 -> 20378.88 | H20: =E20-(F20+G20) -> 13585.92 | I20: 0 | J20: Infosys Limited | K20: Bhubaneswar
A21: ='0422Master'!F15 -> Senior IT Endpoint Engineer | B21: IT SUPPORTIVE SERVICES | C21: 0 | D21: 1 | E21: ='0422Master'!X15 -> 105304 | F21: ='0422Master'!Y15 -> 16848.64 | G21: ='0422Master'!AC15 -> 6739.456 | H21: =E21-(F21+G21) -> 81715.904 | I21: 0 | J21: Infosys Limited | K21: Bhubaneswar
C22: =SUM(C20:C21) -> 0 | D22: =SUM(D20:D21) -> 2 | P22: ,
E26: Signature of the Contractor with Seal

Sheet 04-22M Roll
A3: FORM - XII MUSTER ROLL [Vide Rule 77 (2) (a) (i) of Contract Labour (Reg. & Abolition) act Odisha Rules 1975]
A5: Name and address of Contractor: | D5: ='0422Master'!F5 -> Burgeon IT Services Pvt.Ltd. | J5: Name and address of Establishemnt in/ under which contract is carried on:
D6: ='0422Master'!F6 -> Siri Mansion LIGB 436 Dr.A S Rao Nagar,Hyderabad
A7: Nature and location of work: | D7: ='0422Master'!F8 -> IT SUPPORTIVE SERVICES & BHUBANESWAR
A9: Wage period: Monthly | D9: ='0422Master'!D9 -> 44652 | M9: Name and address of Principal Employer: | Z9: ='0422Master'!AO8 -> INFOSYS LIMITED, IL BHUBANESHWAR-STP,UNIT-II
Z10: ='0422Master'!AO10 -> Plot No E/4,Info city,Chandaka Industrial, Bhubaneswar,Odisha - 751024
A13: S.No | B13: Name of Workman | C13: Father's/ Husband's Name | D13: Sex
E14: 1 | F14: 2 | G14: 3 | H14: 4 | I14: 5 | J14: 6 | K14: 7 | L14: 8 | M14: 9 | N14: 10 | O14: 11 | P14: 12 | Q14: 13 | R14: 14 | S14: 15 | T14: 16 | U14: 17 | V14: 18 | W14: 19 | X14: 20 | Y14: 21 | Z14: 22 | AA14: 23 | AB14: 24 | AC14: 25 | AD14: 26 | AE14: 27 | AF14: 28 | AG14: 29 | AH14: 30 | AI14: Remarks
A15: 1 | B15: ='0422Master'!U14 -> KRANTHI KUMAR VEDULLA | C15: ='0422Master'!E14 -> Kamini Venkatarami Reddy | D15: ='0422Master'!D14 -> Male | E15: P | F15: WO | G15: WO | H15: P | I15: P | J15: P | K15: P | L15: P | M15: WO | N15: WO | O15: P | P15: P | Q15: P | R15: P | S15: H | T15: WO | U15: WO | V15: P | W15: P | X15: P | Y15: P | Z15: P | AA15: WO | AB15: WO | AC15: P | AD15: P | AE15: P | AF15: P | AG15: P | AH15: WO | AI15: ='0422Master'!V14 -> 30
A16: 2 | B16: ='0422Master'!U15 -> Vipin U.N | C16: ='0422Master'!E15 -> GANGA G | D16: ='0422Master'!D15 -> Male | E16: P | F16: WO | G16: WO | H16: P | I16: P | J16: P | K16: P | L16: P | AI16: ='0422Master'!V15 -> 8
A17: 3
A18: 4
J25: Signature of the Contractor with Seal

Sheet Leave Reg
A1: FORM 8 REGISTER OF LEAVE
A3: (Vide Rule 15(2) Odisha Shops & Establishment Rules 1958 )
A4: Name of the Employer/Establishment: | D4: ='0422Master'!F5 -> Burgeon IT Services Pvt.Ltd. | H4: Name of the Employee:
B5: ='0422Master'!F6 -> Siri Mansion LIGB 436 Dr.A S Rao Nagar,Hyderabad | H5: ='0422Master'!B14 -> KRANTHI KUMAR VEDULLA
B6: ='0422Master'!F7 -> 0
A7: Registration Certificate Number:
H8: Adult, male or female, or child…………. | L8: ='0422Master'!D14 -> Male
H9: Adult
A11: Name of employment, if any | B11: Monthly or weekly rate of pay or wages | C11: Date of employment | F11: Leave earned | I11: Period of leave refused to be carried over | J11: Leave availed | M11: Balance of leave at credit | N11: Sickness leave | Q11: Balance after each occasion | R11: Signature or thumb impression of the employee | S11: Signature of employer | T11: Remarks
C12: From | D12: To | E12: Number of days | F12: At credit | G12: Earned | H12: Total | J12: From | K12: To | L12: Number of days | N12: From | O12: To | P12: Number of days availed
A13: 1 | B13: 2 | C13: 3 | D13: 4 | E13: 5 | F13: 6 | G13: 7 | H13: 8 | I13: 9 | J13: 10 | K13: 11 | L13: 12 | M13: 13 | N13: 14 | O13: 15 | P13: 16 | Q13: 17 | R13: 18 | S13: 19 | T13: 20
A15: ='0422Master'!F14 -> Senior Network Engineer | B15: 84912 | C15: 44562 | D15: 44592 | E15: 31 | F15: 13.5 | G15: 1.5 | H15: 15 | I15: 0 | J15: 0 | K15: 0 | L15: 0 | M15: 15
A16: ='0422Master'!F15 -> Senior IT Endpoint Engineer | B16: 105304 | C16: 44593 | D16: 44620 | E16: 28 | F16: 15 | G16: 1.5 | H16: 16.5 | I16: 0 | J16: 0 | K16: 0 | L16: 0 | M16: =M15+G16-L16 -> 16.5
A17: Senior IT Endpoint Engineer | B17: 105304 | C17: 44621 | D17: 44651 | E17: 31 | F17: 16.5 | G17: 1.5 | H17: 18 | I17: 0 | J17: 0 | K17: 0 | L17: 0 | M17: =M16+G17-L17 -> 18
A18: Senior IT Endpoint Engineer | B18: 105305 | C18: 44652 | D18: 44681 | E18: 30 | F18: 18 | G18: 1.5 | H18: 19.5 | I18: 0 | J18: 0 | K18: 0 | L18: 0 | M18: =M17+G18-L18 -> 19.5
A45: FORM 8 REGISTER OF LEAVE
A47: (Vide Rule 15(2) Odisha Shops & Establishment Rules 1958 )
A48: Name of the Employer/Establishment: | D48: ='0422Master'!F5 -> Burgeon IT Services Pvt.Ltd. | H48: Name of the Employee:
B49: ='0422Master'!F6 -> Siri Mansion LIGB 436 Dr.A S Rao Nagar,Hyderabad | H49: ='0422Master'!B15 -> Vipin U.N
B50: ='0422Master'!F7 -> 0
A51: Registration Certificate Number:
H52: Adult, male or female, or child…………. | L52: ='0422Master'!D15 -> Male
H53: Adult
A55: Name of employment, if any | B55: Monthly or weekly rate of pay or wages | C55: Date of employment | F55: Leave earned | I55: Period of leave refused to be carried over | J55: Leave availed | M55: Balance of leave at credit | N55: Sickness leave | Q55: Balance after each occasion | R55: Signature or thumb impression of the employee | S55: Signature of employer | T55: Remarks
C56: From | D56: To | E56: Number of days | F56: At credit | G56: Earned | H56: Total | J56: From | K56: To | L56: Number of days | N56: From | O56: To | P56: Number of days availed
A57: 1 | B57: 2 | C57: 3 | D57: 4 | E57: 5 | F57: 6 | G57: 7 | H57: 8 | I57: 9 | J57: 10 | K57: 11 | L57: 12 | M57: 13 | N57: 14 | O57: 15 | P57: 16 | Q57: 17 | R57: 18 | S57: 19 | T57: 20
A60: ='0422Master'!F15 -> Senior IT Endpoint Engineer | B60: 105304 | C60: 44562 | D60: 44592 | E60: 31 | F60: 13.5 | G60: 1.5 | H60: 15 | I60: 0 | J60: 0 | K60: 0 | L60: 0 | M60: 15
A61: ='0422Master'!F15 -> Senior IT Endpoint Engineer | B61: 105304 | C61: 44593 | D61: 44620 | E61: 28 | F61: 15 | G61: 1.5 | H61: =H60+G61 -> 16.5 | I61: 0 | J61: 0 | K61: 0 | L61: 0 | M61: =M60+G61-L61 -> 16.5
A62: Senior IT Endpoint Engineer | B62: 105304 | C62: 44621 | D62: 44651 | E62: 31 | F62: 16.5 | G62: 1.5 | H62: =H61+G62 -> 18 | I62: 0 | J62: 44627 | K62: 44627 | L62: 0 | M62: =M61+1.5-L62 -> 18
A63: Senior IT Endpoint Engineer | B63: 105304 | C63: 44652 | D63: 44659 | E63: 8 | F63: 18 | G63: 0 | H63: =H62+G63 -> 18 | I63: 0 | J63: 0 | K63: 0 | L63: 0 | M63: 18 | Q63: LESS DAYS

Sheet wages Reg
A3: FORM - XIII REGISTER OF WAGES [Vide Rule 77 (2) (a) (i) of Contract Labour (Reg. & Abolition) Act Odisha Rules 1975]
A5: Name and address of Contractor: | D5: ='0422Master'!F5 -> Burgeon IT Services Pvt.Ltd. | U5: Name and address of Establishemnt in/ under which contract is carried on:
D6: ='0422Master'!F6 -> Siri Mansion LIGB 436 Dr.A S Rao Nagar,Hyderabad
A7: Nature and location of work: | D7: ='0422Master'!F8 -> IT SUPPORTIVE SERVICES & BHUBANESWAR
A9: Wage period: Monthly | D9: ='0422Master'!D9 -> 44652 | V9: Name and address of Principal Employer: | AA9: ='0422Master'!AO8 -> INFOSYS LIMITED, IL BHUBANESHWAR-STP,UNIT-II
AA10: ='0422Master'!AO10 -> Plot No E/4,Info city,Chandaka Industrial, Bhubaneswar,Odisha - 751024
A13: S.No | B13: Name of Workman | C13: Serial No. in the Register of Workmen | D13: Designation / Nature of Work Done | E13: No.of Days worked | F13: Unit of work done | G13: Monthly rate of wages/ piece rate | H13: Basic wages | I13: Dearness Allowances | J13: Over time | K13: Other cash payments (Nature of payments to be indicated) | L13: HRA | M13: CONVEYANCE | N13: MEDICAL ALLOWANCES | O13: SPECIAL ALLOWNANCES | P13: Total | Q13: BONUS | R13: GRATUITY | S13: LTA/L.E | T13: ARREAR AMOUNT | U13: TOTAL AMOUNT | V13: Deductions, if any, (Indicate nature) | AB13: Net Amount paid | AC13: Time and Date of Payment | AD13: Place of Payment | AE13: Signature/Thumb Impression of workman | AF13: Initial of Contractor or his representative
V14: ESI | W14: PF | X14: PT | Y14: TDS | Z14: Advance | AA14: Total Deductions
A15: 1 | B15: ='0422Master'!U14 -> KRANTHI KUMAR VEDULLA | C15: ='0422Master'!A14 -> 1 | D15: ='0422Master'!F14 -> Senior Network Engineer | E15: ='0422Master'!V14 -> 30 | F15: ='0422Master'!W14 -> 0 | G15: ='0422Master'!X14 -> 84912 | H15: ='0422Master'!Y14 -> 50947.2 | I15: ='0422Master'!Z14 -> 0 | J15: ='0422Master'!AA14 -> 0 | K15: =L15+M15+N15+O15 -> 34077.8 | L15: ='0422Master'!AC14 -> 20378.88 | M15: ='0422Master'!AD14 -> 2083 | N15: ='0422Master'!AE14 -> 2083 | O15: ='0422Master'!AF14 -> 9532.92 | P15: ='0422Master'!AG14 -> 85025 | Q15: ='0422Master'!AH14 -> 1554.609 | R15: ='0422Master'!AI14 -> 2450.5603 | S15: ='0422Master'!AJ14 -> 4245.6 | ... Z15: ='0422Master'!AQ14 -> 392 | AA15: =V15+W15+X15+Y15+Z15 -> 2392 | AB15: =U15-AA15 -> 90883.769 | AC15: ='0422Master'!AT14 -> 44686 | AD15: ='0422Master'!AU14 -> ICICI | AE15: ='0422Master'!AV14 -> A/C'403901506350
A16: 2 | B16: ='0422Master'!U15 -> Vipin U.N | C16: ='0422Master'!A15 -> 2 | D16: ='0422Master'!F15 -> Senior IT Endpoint Engineer | E16: ='0422Master'!V15 -> 8 | F16: ='0422Master'!W15 -> 0 | G16: ='0422Master'!X15 -> 105304 | H16: ='0422Master'!Y15 -> 16848.64 | I16: ='0422Master'!Z15 -> 0 | J16: ='0422Master'!AA15 -> 0 | K16: =L16+M16+N16+O16 -> 11345.427 | L16: ='0422Master'!AC15 -> 6739.456 | M16: ='0422Master'!AD15 -> 555 | N16: ='0422Master'!AE15 -> 555 | O16: ='0422Master'!AF15 -> 3495.9707 | P16: ='0422Master'!AG15 -> 28194.067 | Q16: ='0422Master'!AH15 -> 1554.609 | R16: ='0422Master'!AI15 -> 810.41958 | S16: ='0422Master'!AJ15 -> 1404.0533 | ... Z16: ='0422Master'!AQ15 -> 392 | AA16: =V16+W16+X16+Y16+Z16 -> 2392 | AB16: =U16-AA16 -> 29571.149 | AC16: ='0422Master'!AT15 -> 44686 | AD16: ='0422Master'!AU15 -> ICICI | AE16: ='0422Master'!AV15 -> A/C025201526367
H17: =SUM(H15:H16) -> 67795.84 | I17: =SUM(I15:I16) -> 0 | J17: =SUM(J15:J16) -> 0 | K17: =SUM(K15:K16) -> 45423.227 | L17: =SUM(L15:L16) -> 27118.336 | M17: =SUM(M15:M16) -> 2638 | N17: =SUM(N15:N16) -> 2638 | O17: =SUM(O15:O16) -> 13028.891 | ... AB17: =SUM(AB15:AB16) -> 120454.92
J20: Signature of the Contractor with Seal

Sheet Emp Cards
B1: FORM X
B2: EMPLOYMENT CARD
B3: (Vide Rule 75 of Contract Labour (R&A) act Odisha Rules, 1975)
B4: Name and Address of the Contractor | H4: Name and Address of the Establishment in/under which Contract is carried on:
B7: ='0422Master'!F5 -> Burgeon IT Services Pvt.Ltd. | H7: ='0422Master'!AO5 -> Burgeon IT Services Pvt.Ltd.
B8: ='0422Master'!F6 -> Siri Mansion LIGB 436 Dr.A S Rao Nagar,Hyderabad | H8: ='0422Master'!AO6 -> Siri Mansion LIGB 436 Dr.A S Rao Nagar,Hyderabad
B12: Nature of work and location of work: | H12: Name and address of Principal Employer:
H15: ='0422Master'!AO8 -> INFOSYS LIMITED, IL BHUBANESHWAR-STP,UNIT-II
B16: ='0422Master'!F8 -> IT SUPPORTIVE SERVICES & BHUBANESWAR
H17: ='0422Master'!AO10 -> Plot No E/4,Info city,Chandaka Industrial, Bhubaneswar,Odisha - 751024
B19: 1. Name of the Workman and address | H19: ='0422Master'!B14 -> KRANTHI KUMAR VEDULLA
B20: 2. S.No. in the Register of Workmen Employed | H20: ='0422Master'!A14 -> 1
B21: 3. Nature of Employment /Designation | H21: ='0422Master'!F14 -> Senior Network Engineer
B22: 4. Date of entry into service | H22: ='0422Master'!N14 -> 44181
B23: 5. ESI No. | H23: ='0422Master'!T14 -> NA
B24: 6.PF No. | H24: ='0422Master'!S14 -> 101135871959
B25: 7. Wage rate (With particulars of unit in case of piece - work) | H25: ='0422Master'!X14 -> 84912
B26: 8. Wage period | H26: ='0422Master'!D9 -> 44652
B27: 9. Tenure of Employment | H27: AS PER CONTRACT
B28: 10.No. of days worked in a month | J28: ='0422Master'!V14 -> 30
B29: 11. No. of units worked in case of piece rate workers | J29: N/A
B30: 12. Rate of daily wages / piece rate | J30: 0
B31: 13. Amount of overtime wages | J31: 0
B32: 14. Gross wages payable | J32: ='0422Master'!AL14 -> 93275.769 | L32: MED
B33: 15. Deductions, if any, | D33: PF | E33: ='0422Master'!AN14 -> 1800 | F33: ESI | G33: ='0422Master'!AM14 -> 0 | H33: PT | I33: ='0422Master'!AO14 -> 200 | J33: TDS | K33: ='0422Master'!AP14 -> 0 | L33: ='0422Master'!AQ14 -> 392
B34: 16. Net amount of wages paid | J34: ='0422Master'!AS14 -> 90883.769
B35: Signature of the Representative
B36: of Contractor
B56: FORM X
B57: EMPLOYMENT CARD
B58: (Vide Rule 75 of Contract Labour (R&A) act Odisha Rules, 1975)
B59: Name and Address of the Contractor | H59: Name and Address of the Establishment in/under which Contract is carried on:
B62: ='0422Master'!F5 -> Burgeon IT Services Pvt.Ltd. | H62: ='0422Master'!AO5 -> Burgeon IT Services Pvt.Ltd.
B63: ='0422Master'!F6 -> Siri Mansion LIGB 436 Dr.A S Rao Nagar,Hyderabad | H63: ='0422Master'!AO6 -> Siri Mansion LIGB 436 Dr.A S Rao Nagar,Hyderabad
B67: Nature of work and location of work: | H67: Name and address of Principal Employer:
H70: ='0422Master'!AO8 -> INFOSYS LIMITED, IL BHUBANESHWAR-STP,UNIT-II
B71: ='0422Master'!F8 -> IT SUPPORTIVE SERVICES & BHUBANESWAR | E71: ODISSA
H72: ='0422Master'!AO10 -> Plot No E/4,Info city,Chandaka Industrial, Bhubaneswar,Odisha - 751024
B74: 1. Name of the Workman and address | H74: ='0422Master'!B15 -> Vipin U.N
B75: 2. S.No. in the Register of Workmen Employed | H75: ='0422Master'!A15 -> 2
...

Sheet wage sllips
A1: Form XV - WAGE SLIP | K1: =A1 -> Form XV - WAGE SLIP
A2: [Vide rule 77 (2) (b) of the Contract Labour (Regulation and Abolition) act Odisha Rules, 1975] | K2: =A2 -> [Vide rule 77 (2) (b) of the Contract Labour (Regulation and Abolition) act Odisha Rules, 1975]
A4: Name and address of Contractor | D4: ='0422Master'!F5 -> Burgeon IT Services Pvt.Ltd. | K4: Name and address of Contractor | N4: =D4 -> Burgeon IT Services Pvt.Ltd.
B5: ='0422Master'!F6 -> Siri Mansion LIGB 436 Dr.A S Rao Nagar,Hyderabad | L5: =B5 -> Siri Mansion LIGB 436 Dr.A S Rao Nagar,Hyderabad
B6: ='0422Master'!F7 -> 0 | L6: =B6 -> 0
A7: Name and Father's / Husband's name of the workman | K7: Name and Father's / Husband's name of the workman
E8: ='0422Master'!U14 -> KRANTHI KUMAR VEDULLA | H8: ='0422Master'!E14 -> Kamini Venkatarami Reddy | O8: =E8 -> KRANTHI KUMAR VEDULLA | R8: =H8 -> Kamini Venkatarami Reddy
A10: Nature and location of work | E10: ='0422Master'!F8 -> IT SUPPORTIVE SERVICES & BHUBANESWAR | K10: Nature and location of work | O10: =E10 -> IT SUPPORTIVE SERVICES & BHUBANESWAR
A12: For the Week / Fortnight / Month ending | E12: ='0422Master'!D9 -> 44652 | K12: For the Week / Fortnight / Month ending | O12: =E12 -> 44652
A14: 1 | B14: No. of days worked | E14: ='0422Master'!V14 -> 30 | K14: 1 | L14: No. of days worked | O14: =E14 -> 30
A16: 2 | B16: No. of units worked in case of piece rate workers : | K16: 2 | L16: No. of units worked in case of piece rate workers :
E17: N/A | O17: N/A
A19: 3 | B19: Rate of daily wages / piece rate | E19: N/A | K19: 3 | L19: Rate of daily wages / piece rate | O19: =E19 -> N/A
A21: 4 | B21: Amount of overtime wages | E21: Nil | K21: 4 | L21: Amount of overtime wages | O21: Nil
A23: 5 | B23: Gross wages payble | E23: ='0422Master'!AL14 -> 93275.769 | K23: 5 | L23: Gross wages payble | O23: =E23 -> 93275.769
D24: EPF | E24: ESI | F24: PT | G24: TDS | H24: MEDICAL | I24: TOTAL | N24: EPF | O24: ESI | P24: PT | Q24: TDS | R24: MEDICAL | S24: TOTAL
A25: 6 | B25: Deductions, if any | D25: ='0422Master'!AN14 -> 1800 | E25: ='0422Master'!AM14 -> 0 | F25: ='0422Master'!AO14 -> 200 | G25: ='0422Master'!AP14 -> 0 | H25: ='0422Master'!AQ14 -> 392 | I25: ='0422Master'!AR14 -> 2392 | K25: 6 | L25: Deductions, if any | N25: =D25 -> 1800 | O25: =E25 -> 0 | P25: =F25 -> 200 | Q25: =G25 -> 0 | R25: =H25 -> 392 | S25: =I25 -> 2392
A27: 7 | B27: Actual wages paid | E27: =E23-I25 -> 90883.769 | K27: 7 | L27: =B27 -> Actual wages paid | O27: =E27 -> 90883.769
E31: Initial of the Contractor or his representative | O31: Initial of the Contractor or his representative
A44: Form XV - WAGE SLIP | K44: =A44 -> Form XV - WAGE SLIP
A45: [Vide rule 77 (2) (b) of the Contract Labour (Regulation and Abolition) act Odisha Rules, 1975] | K45: =A45 -> [Vide rule 77 (2) (b) of the Contract Labour (Regulation and Abolition) act Odisha Rules, 1975]
A47: Name and address of Contractor | D47: ='0422Master'!F5 -> Burgeon IT Services Pvt.Ltd. | K47: Name and address of Contractor | N47: =D47 -> Burgeon IT Services Pvt.Ltd.
B48: ='0422Master'!F6 -> Siri Mansion LIGB 436 Dr.A S Rao Nagar,Hyderabad | L48: =B48 -> Siri Mansion LIGB 436 Dr.A S Rao Nagar,Hyderabad
B49: ='0422Master'!F7 -> 0 | L49: =B49 -> 0
A50: Name and Father's / Husband's name of the workman | K50: Name and Father's / Husband's name of the workman
E51: ='0422Master'!U15 -> Vipin U.N | H51: ='0422Master'!E15 -> GANGA G | O51: =E51 -> Vipin U.N | R51: =H51 -> GANGA G
A53: Nature and location of work | E53: ='0422Master'!F8 -> IT SUPPORTIVE SERVICES & BHUBANESWAR | K53: Nature and location of work | O53: =E53 -> IT SUPPORTIVE SERVICES & BHUBANESWAR
A55: For the Week / Fortnight / Month ending | E55: ='0422Master'!D9 -> 44652 | K55: For the Week / Fortnight / Month ending | O55: =E55 -> 44652
A57: 1 | B57: No. of days worked | E57: ='0422Master'!V15 -> 8 | K57: 1 | L57: No. of days worked | O57: =E57 -> 8
A59: 2 | B59: No. of units worked in case of piece rate workers : | K59: 2 | L59: No. of units worked in case of piece rate workers :
E60: N/A | O60: N/A
A62: 3 | B62: Rate of daily wages / piece rate | E62: N/A | K62: 3 | L62: Rate of daily wages / piece rate | O62: =E62 -> N/A
A64: 4 | B64: Amount of overtime wages | E64: Nil | K64: 4 | L64: Amount of overtime wages | O64: Nil
A66: 5 | B66: Gross wages payble | E66: ='0422Master'!AL15 -> 31963.149 | K66: 5 | L66: Gross wages payble | O66: =E66 -> 31963.149
D67: EPF | E67: ESI | F67: PT | G67: TDS | H67: MEDICAL | I67: TOTAL | N67: EPF | O67: ESI | P67: PT | Q67: TDS | R67: MEDICAL | S67: TOTAL
A68: 6 | B68: Deductions, if any | D68: ='0422Master'!AN15 -> 1800 | E68: ='0422Master'!AM15 -> 0 | F68: ='0422Master'!AO15 -> 200 | G68: ='0422Master'!AP15 -> 0 | H68: ='0422Master'!AQ15 -> 392 | I68: =D68+E68+F68+G68+H68 -> 2392 | K68: 6 | L68: Deductions, if any | N68: =D68 -> 1800 | O68: =E68 -> 0 | P68: =F68 -> 200 | Q68: =G68 -> 0 | R68: =H68 -> 392 | S68: =I68 -> 2392
A70: 7 | B70: Actual wages paid | E70: =E66-I68 -> 29571.149 | K70: 7 | L70: =B70 -> Actual wages paid | O70: =E70 -> 29571.149
E74: Initial of the Contractor or his representative | O74: Initial of the Contractor or his representative

Sheet APRIL 22Bonus
A1: BONUS REGISTER
A3: FORM "c" ( See rule 4 [c] )
M4: ='0422Master'!D9 -> 44652
A5: Name of the Establishment : _____________________________ | D5: ='0422Master'!F5 -> Burgeon IT Services Pvt.Ltd. | K5: Financial year _____ | M5: 2022-23
A7: Sr. No | B7: Name of the Employee | C7: Father's Name / Husband's Name | D7: Whether he has completed 15 yrs of age at the beginning of the accounting year | E7: Designation | F7: No. of days worked in the month | G7: Total Salary or wages in the year | H7: Amt. of bonus payable under section 10 or section 11 as the case may be Ex gratia | I7: DEDUCTIONS | L7: Total Sum Deducted (Col. 9,10 and 11) | M7: Net Amount payable (Col. 8 minus Col. 12) | N7: Amount Actually paid | O7: Date on which paid | P7: Signature / Thumb impression of the employee
I8: Puja Bonus or other customary bonus paid during the accounting year | J8: Interim Bonus or bonus paid in advance | K8: Deduction on account of financial loss if any caused by misconduct of the employee | Q8: Account Number
A9: 1 | B9: 2 | C9: 3 | D9: 4 | E9: 5 | F9: 6 | H9: 8 | I9: 9 | J9: 10 | K9: 11 | L9: 12 | M9: 13 | N9: 14 | O9: 15 | P9: 16
A10: 1 | B10: ='0422Master'!B14 -> KRANTHI KUMAR VEDULLA | C10: ='0422Master'!E14 -> Kamini Venkatarami Reddy | D10: YES | E10: ='0422Master'!F14 -> Senior Network Engineer | F10: ='0422Master'!V14 -> 30 | G10: ='0422Master'!AL14 -> 93275.769 | H10: ='0422Master'!AH14 -> 1554.609 | I10: N/A | J10: N/A | K10: N/A | L10: N/A | M10: ='0422Master'!AH14 -> 1554.609 | N10: ='0422Master'!AH14 -> 1554.609 | O10: ='0422Master'!AT14 -> 44686 | P10: ='0422Master'!AU14 -> ICICI | Q10: ='0422Master'!AV14 -> A/C'403901506350
A11: 2 | B11: ='0422Master'!B15 -> Vipin U.N | C11: ='0422Master'!E15 -> GANGA G | D11: YES | E11: ='0422Master'!F15 -> Senior IT Endpoint Engineer | F11: ='0422Master'!V15 -> 8 | G11: ='0422Master'!AL15 -> 31963.149 | H11: ='0422Master'!AH15 -> 1554.609 | I11: N/A | J11: N/A | K11: N/A | L11: N/A | M11: ='0422Master'!AH15 -> 1554.609 | N11: ='0422Master'!AH15 -> 1554.609 | O11: ='0422Master'!AT15 -> 44686 | P11: ='0422Master'!AU15 -> ICICI | Q11: ='0422Master'!AV15 -> A/C025201526367
A12: 4
A13: 5
A14: 6
A15: 7
A16: 8
A17: 9
A18: 10
A19: 11
A20: 12
A21: 13
A22: 14
A23: 15
... A28: 20
L32: Signature of the Contractor with Seal

Sheet Ded
A1: FORM XVI- REGISTER OF DEDUCTIONS FOR DAMAGE OR LOSS
A3: (Vide Rule 77(2) (d) (i) of Contract Labour (Regulation and Abolition) act Odisha Rules1975)
A4: Name and address of Contractor: GROTECH LANDSCAPE DEVELOPERS PVT.LTD. | D4: ='0422Master'!F5 -> Burgeon IT Services Pvt.Ltd. | E4: Name and address of the establishment in / under which contract is carried on:
B5: ='0422Master'!F6 -> Siri Mansion LIGB 436 Dr.A S Rao Nagar,Hyderabad
B6: ='0422Master'!F7 -> 0
A7: Nature and Location of Work: | D7: ='0422Master'!F8 -> IT SUPPORTIVE SERVICES & BHUBANESWAR | E7: Name and address of principal employer:
E8: ='0422Master'!AO8 -> INFOSYS LIMITED, IL BHUBANESHWAR-STP,UNIT-II
E9: ='0422Master'!AO10 -> Plot No E/4,Info city,Chandaka Industrial, Bhubaneswar,Odisha - 751024
A11: S.No | B11: Name of workman | C11: Father's / Husband's Name | D11: Designation / Nature of employment | E11: Particulars of damage or loss | F11: Date of Damage or loss | G11: Whether workman showed cause against deduction | H11: Name of person in whose presence employee's explanation was heard | I11: Amount of deduction impossed | J11: Date of recovery | M11: Remarks
J12: No.of Instalments | K12: First Instalment | L12: Last instalment
A13: 1 | B13: 2 | C13: 3 | D13: 4 | E13: 5 | F13: 6 | G13: 7 | H13: 8 | I13: 9 | J13: 10 | K13: 11 | L13: 12 | M13: 13
B16: NO EMPLOYEE WAS IMPOSED DEDUCTIONS FOR DAMAGE OR LOSS FOR THE MONTH OF | H16: ='0422Master'!D9 -> 44652
F37: Signature of the Contractor with Seal

Sheet Fines
A1: FORM XVII- REGISTER OF FINES
A3: (Vide Rule 77(2) (d) (i) of Contract Labour (Regulation and Abolition) Act Odisha Rules 1975)
A4: Name and address of Contractor: | D4: ='0422Master'!F5 -> Burgeon IT Services Pvt.Ltd. | E4: Name and address of the establishment in / under which contract is carried on:
B5: ='0422Master'!F6 -> Siri Mansion LIGB 436 Dr.A S Rao Nagar,Hyderabad
B6: ='0422Master'!F7 -> 0
A7: Nature and Location of Work: | D7: ='0422Master'!F8 -> IT SUPPORTIVE SERVICES & BHUBANESWAR | E7: Name and address of principal employer:
E8: ='0422Master'!AO8 -> INFOSYS LIMITED, IL BHUBANESHWAR-STP,UNIT-II
E9: ='0422Master'!AO10 -> Plot No E/4,Info city,Chandaka Industrial, Bhubaneswar,Odisha - 751024
A11: S.No | B11: Name of workman | C11: Father's / Husband's Name | D11: Designation / Nature of employment | E11: Act/Omission for which fine imposed | F11: Date of offence | G11: Whether workman showed cause against fine | H11: Name of person in whose presence employee's explanation was heard | I11: Wage-period and wge payable | J11: Amount of fine Imposed | K11: Date on which fine realised | L11: Remarks
A13: 1 | B13: 2 | C13: 3 | D13: 4 | E13: 5 | F13: 6 | G13: 7 | H13: 8 | I13: 9 | J13: 10 | K13: 11 | L13: 12
B16: NO EMPLOYEE WAS IMPOSED FINESFOR THE MONTH OF | H16: ='04-22M Roll'!D9 -> 44652
F37: Signature of the Contractor with Seal

Sheet Advances
A1: FORM XVIII- REGISTER OF ADVANCES
A3: (Vide Rule 77(2) (d) (i) of Contract Labour (Regulation and Abolition) Act Odisha Rules 1975)
A4: Name and address of Contractor: | D4: ='0422Master'!F5 -> Burgeon IT Services Pvt.Ltd. | E4: Name and address of the establishment in / under which contract is carried on:
B5: ='0422Master'!F6 -> Siri Mansion LIGB 436 Dr.A S Rao Nagar,Hyderabad
B6: ='0422Master'!F7 -> 0
A7: Nature and Location of Work: | D7: ='0422Master'!F8 -> IT SUPPORTIVE SERVICES & BHUBANESWAR | E7: Name and address of principal employer:
E8: ='0422Master'!AO8 -> INFOSYS LIMITED, IL BHUBANESHWAR-STP,UNIT-II
E9: ='0422Master'!AO10 -> Plot No E/4,Info city,Chandaka Industrial, Bhubaneswar,Odisha - 751024
A11: S.No | B11: Name of workman | C11: Father's / Husband's Name | D11: Designation / Nature of employment | E11: Wage period and wages payable | F11: Date and amount of advance given | G11: Purpose(s) for which advance made | H11: Number of instalments by which advance to be repaid | I11: Date and amount of each instalment repaid | J11: Date on which last instalment was repaid | K11: Remarks
A13: 1 | B13: 2 | C13: 3 | D13: 4 | E13: 5 | F13: 6 | G13: 7 | H13: 8 | I13: 9 | J13: 10 | K13: 11
B16: NO EMPLOYEE TAKEN ADVANCE FOR THE MONTH OF | F16: ='04-22M Roll'!D9 -> 44652
G41: Signature of the Contractor with Seal

Sheet Overtime
A1: FORM XIX- REGISTER OF OVERTIME
A3: (Vide Rule 77(2) (c) (i) of Contract Labour (Regulation and Abolition) Act Odisha Rules 1975)
A4: Name and address of Contractor: GROTECH LANDSCAPE DEVELOPERS PVT.LTD. E-35 GREATER KAILASH ENCLAVE-1 NEW DELHI | D4: ='0422Master'!F5 -> Burgeon IT Services Pvt.Ltd. | F4: Name and address of the establishment in which under contract is carried on:
B5: ='0422Master'!F6 -> Siri Mansion LIGB 436 Dr.A S Rao Nagar,Hyderabad
B6: ='0422Master'!F7 -> 0
A7: Nature and Location of Work: | D7: ='0422Master'!F8 -> IT SUPPORTIVE SERVICES & BHUBANESWAR | F7: Name and address of principal employer:
F8: ='0422Master'!AO8 -> INFOSYS LIMITED, IL BHUBANESHWAR-STP,UNIT-II
F9: ='0422Master'!AO10 -> Plot No E/4,Info city,Chandaka Industrial, Bhubaneswar,Odisha - 751024
A11: S.No | B11: Name of workman | C11: Father's / Husband's Name | D11: Sex | E11: Designation / Nature of employment | F11: Date on which overtime worked | G11: Total overtime worked or production in case of piece-rates | H11: Normal rate of wages | I11: Overtime rate of wages | J11: overtime earnings | K11: Total Earnings | L11: Date on which overtime wages paid
A13: 1 | B13: 2 | C13: 3 | D13: 4 | E13: 5 | F13: 6 | G13: 7 | H13: 8 | I13: 9 | J13: 10 | K13: 11 | L13: 12
B16: NO EMPLOYEE DONE OVERTIME FOR THE MONTH OF | F16: ='0422Master'!D9 -> 44652
G38: Signature of the Contractor with Seal

Sheet Accident
A1: FORM 11
A3: ACCIDENT BOOK
A4: EMPLOYEE STATE INSURANCE CORPORATION
B5: (Regulation 66)
A7: S.No | B7: Date of Notice | C7: Time of Notice | D7: Name and Address of the Injured Person | E7: Sex | F7: Age | H7: Shift,Department and occupation of employee | I7: Details of Injury | P7: Signature and designation of the person who makes the entry in the accident book | Q7: Name,address and occupation of the two witnesses | R7: Remarks if any
G8: Insurance Number | N8: What exactly was the injured person doing at the time of accident | O8: Name,Occupation,address and signature or the thumb impression of the person(s) giving notice
I9: Cause | J9: Nature | K9: Date | L9: Time | M9: Place
A10: 1 | B10: 2 | C10: 3 | D10: 4 | E10: 5 | F10: 6 | G10: 7 | H10: 8 | I10: 9 | J10: 10 | K10: 11 | L10: 12 | M10: 13 | N10: 14 | O10: 15 | P10: 16 | Q10: 17 | R10: 18
B12: NO ACCIDENT OCCURRED FOR THE MONTH OF | F12: ='0422Master'!D9 -> 44652
J27: Signature of the Contractor with Seal

Sheet ESI cards Reg
C1: ='0422Master'!F5 -> Burgeon IT Services Pvt.Ltd. | E1: ESI PAHECHAN CARDS ISSUE REGISTER
B2: S.No | C2: Name of the Employee | D2: ESI Number | E2: Issue Date | F2: Signature | G2: Remarks
B3: 1 | C3: ='0422Master'!U14 -> KRANTHI KUMAR VEDULLA | D3: ='0422Master'!T14 -> NA
B4: 2 | C4: ='0422Master'!U15 -> Vipin U.N | D4: ='0422Master'!T15 -> NA
B5: 3
B6: 4
B7: 5
B8: 6
B9: 7
B10: 8
B11: 9
B12: 10
B13: 11
B14: 12
B15: 13
B16: 14
... B20: 18

Sheet Form-I
B1: FORM I
B2: NOMINATION AND DECLARATION FORM
B3: (Vide Rule 3 of Payment of wages Act Central & A.P Rules, 1936)
B4: Name and Address of the Contractor | H4: Name and Address of the Establishment in/under which Contract is carried on:
B7: ='04-22M Roll'!D5 -> Burgeon IT Services Pvt.Ltd. | H7: ='04-22M Roll'!Z5 -> 0
B9: ='04-22M Roll'!D6 -> Siri Mansion LIGB 436 Dr.A S Rao Nagar,Hyderabad | H9: ='04-22M Roll'!Z6 -> 0
B12: Nature of work and location of work: | H12: Name and address of Principal Employer:
H15: ='04-22M Roll'!Z9 -> INFOSYS LIMITED, IL BHUBANESHWAR-STP,UNIT-II
B16: ='04-22M Roll'!D7 -> IT SUPPORTIVE SERVICES & BHUBANESWAR
H17: ='04-22M Roll'!Z10 -> Plot No E/4,Info city,Chandaka Industrial, Bhubaneswar,Odisha - 751024
B19: 1. Name of the person making nomination | H19: ='0422Master'!#REF! -> #REF!
B20: 2. Father's/Husband name | H20: ='0422Master'!#REF! -> #REF!
B21: 3. Date of Birth | H21: ='0422Master'!#REF! -> #REF!
B22: 4. Sex | H22: ='0422Master'!#REF! -> #REF!
B23: 5. Marital Status | H23: Un-Married
B24: 6.Address
B25: Permanent | H25: ='0422Master'!#REF! -> #REF!
H26: ='0422Master'!#REF! -> #REF!
H27: ='0422Master'!#REF! -> #REF!
B28: Temporary | H28: ='0422Master'!#REF! -> #REF!
H29: ='0422Master'!#REF! -> #REF!
H30: ='0422Master'!#REF! -> #REF!
B31: I hereby nominate the person(s)/cancel the nomination made by me previously and nominate the person(s) mentioned below to
B32: receive any amount due to me from the employer,in the event to my death.
B33: Name of the Nominee/nominees | E33: Address | G33: Nominee's relationship With the member | I33: Date of Birth | J33: Total amount of Share of accumulations | K33: If the nominee is minor,name,relationship and address of the guardian
B34: 1 | E34: 2 | G34: 3 | I34: 4 | J34: 5 | L34: 6
B35: ='0422Master'!#REF! -> #REF! | E35: Same as permanant address | G35: Father | I35: 54 years | J35: 1 | K35: N/A
B39: 1.Certified that I have no family and should I acquire a family hereafter,the above nomination shall be deemed as cancelled.
B40: 2.Certified that my father/mother is/ are dependent upon me.
B41: 3.Strike out whichever is not applicable.
I43: Signature or the thumb impression of the employed person
F44: CERTIFCATE BY EMPLOYER
A45: Certified that the above declaration and nomination has been signed/thumb impressed before me by Shri/Smt/Kum | K45: ='0422Master'!#REF! -> #REF!
A46: employed in my establishment after he/she has read the entry/entries have been read over to him/her by me and got confirmed by him/her.
F49: Signature or the employer or other authorized officer of the establiment and Designation
A50: Place | B50: Hyderabad | F50: ='0422Master'!AO5 -> Burgeon IT Services Pvt.Ltd.
A51: Date | B51: ='0422Master'!#REF! -> #REF! | F51: ='0422Master'!AO6 -> Siri Mansion LIGB 436 Dr.A S Rao Nagar,Hyderabad
B53: FORM I
B54: NOMINATION AND DECLARATION FORM
B55: (Vide Rule 3 of Payment of wages Act Central & A.P Rules, 1936)
...

Sheet Form-2
K1: (FORM 2 REVISED)
B2: NOMINATION AND DECLARATION FORM FOR UNEXEMPTED/EXEMPTED ESTABLISHMENTS
B3: Declaration and Nomination Form under the Employees Provident Funds and Employees Pension Schemes
B4: (Paragraph 33 and 61(1) of the Employees Provident Fund Scheme 1952 and Paragraph 18 of the Employees Pension Scheme 1995)
B6: 1. Name of the person making nomination | H6: ='0422Master'!#REF! -> #REF!
B7: 2. Father's/Husband name | H7: ='0422Master'!#REF! -> #REF!
B8: 3. Date of Birth | H8: ='0422Master'!#REF! -> #REF!
B9: 4. Sex | H9: ='0422Master'!#REF! -> #REF!
B10: 5. Marital Status | H10: Un-Married
B11: 6.Address
B12: Permanent | H12: ='0422Master'!#REF! -> #REF!
H13: ='0422Master'!#REF! -> #REF!
H14: ='0422Master'!#REF! -> #REF!
G15: PART-A(EPF)
B16: I hereby nominate the person(s)/cancel the nomination made by me previously and nominate the person(s) mentioned below to
B17: receive any amount due to me from the employer,in the event to my death.
B18: Name of the Nominee/nominees | E18: Address | G18: Nominee's relationship With the member | I18: Date of Birth | J18: Total amount of Share of accumulations | K18: If the nominee is minor,name,relationship and address of the guardian
B19: 1 | E19: 2 | G19: 3 | I19: 4 | J19: 5 | L19: 6
B20: ='0422Master'!#REF! -> #REF! | E20: Same as Permanant Address | G20: Father | I20: 55 Years | J20: 1 | K20: N/A
B24: 1.Certified that I have no family and should I acquire a family hereafter,the above nomination shall be deemed as cancelled.
B25: 2.Certified that my father/mother is/ are dependent upon me.
B26: Strike out whichever is not applicable | J26: Signature/or thumb impression of the subscriber
G27: PART (EPS)
G28: Para 18
B29: I hereby furnish below particulars of the members of my family who would be eligible to receive Widow/Children Pension in the event of
B30: my premature death in service
B31: S.No | C31: Name & Address of the Family Member | I31: Age | J31: Relationship with the member
B32: 1 | E32: 2 | I32: 3 | K32: 4
B37: Certified that I have no family as defined in para 2 (vii) of the Employees's Family Pension Scheme 1995 and should I acquire a family hereafter
B38: I shall furnish Particulars there on in the above form.
B39: I hereby nominate the following person for receiving the monthly widow pension (admissible under para 16 2 (a) (1) & (ii) in the even of my death
B40: without leaving any eligible member for receiving pension.
B41: Name and Address of the nominee | G41: Date of Birth | I41: Relationship with member
B47: Date | C47: ='0422Master'!#REF! -> #REF! | I47: Signature or thumb impression of the subscriber
F48: CERTIFCATE BY EMPLOYER
A49: Certified that the above declaration and nomination has been signed/thumb impressed before me by Shri/Smt/Kum | K49: ='0422Master'!#REF! -> #REF!
A50: employed in my establishment after he/she has read the entry/entries have been read over to him/her by me and got confirmed by him/her.
F52: Signature or the employer or other authorized officer of the establiment and Designation
A53: Place | B53: Hyderabad | F53: ='0422Master'!F5 -> Burgeon IT Services Pvt.Ltd.
A54: Date | B54: ='0422Master'!#REF! -> #REF! | F54: ='0422Master'!F6 -> Siri Mansion LIGB 436 Dr.A S Rao Nagar,Hyderabad
...

Sheet Form 11
I1: New Form No. 11 - Declaration Form
B2: (To be retained by t he employer for future reference)
D3: EMPLOYEES' PROVIDENT FUND ORGANIZATION | I3: Emp Code: | K3: ='0422Master'!#REF! -> #REF!
C4: Employees' Provident Funds Scheme, 1952 (Paragraph 34 & 57) & | I4: Company | J4: ='0422Master'!F5 -> Burgeon IT Services Pvt.Ltd.
C5: The Employees' Pension Scheme, 1995 (Paragraph 24) | I5: ='0422Master'!F6 -> Siri Mansion LIGB 436 Dr.A S Rao Nagar,Hyderabad
A8: 1 | B8: Name of the Member | H8: ='0422Master'!#REF! -> #REF!
A9: 2 | B9: Fathers' Name | F9: Husband's Name | H9: ='0422Master'!#REF! -> #REF!
B10: (Please tick whichever is applicable)
A11: 3 | B11: Date of Birth (DD/MM/YYYY) | H11: ='0422Master'!#REF! -> #REF!
A12: 4 | B12: Gender (Male/Female/Transgender) | H12: ='0422Master'!#REF! -> #REF!
A13: 5 | B13: Marital Status(married / Unmarried / Widow/divorce) | H13: UNMARRIED
A14: 6 | B14: (a) | C14: Email Id
B15: (b) | C15: Mobile No.
A16: 7 | B16: Whether earlier a member of the Employees' Provident Fund Scheme, 1952 ? | H16: Yes | K16: No
A17: 8 | B17: Whether earlier a member of the Employees' Pension Scheme, 1995? | H17: Yes | K17: No
F18: Previous employment details [if Yes to 7 &/or 8 above]
A19: 9 | B19: a) | C19: Universal Account Number
B20: b) | C20: Previous PF Account Number
B21: C) | C21: Date of exit from previous employment (DD/MM/YYYY)
B22: d) | C22: Scheme Certificate No. (if issued)
B23: e) | C23: Pension Payment Order (PPO) No. (if issued)
A24: 10 | B24: a) | C24: International Worker | H24: Yes | K24: No
B25: b) | C25: If yes, state country of origin(India/Name of other country)
B26: C) | C26: Passport No.
B27: d) | C27: Validity of passport [(DD/MM/YYYY) to (DD/MM/YYYY)]
E28: KYC Details (attach self attested copies of following KYCs)
A29: 11 | B29: a) | C29: Bank Account No. & IFS Code
B30: b) | C30: AADHAR No.
B31: c) | C31: Permanent Account No. (PAN), if available
F32: UNDERTAKING
B33: 1) | C33: Certified that the particulars are true to the best of my knowledge.
B34: 2) | C34: I authorize EPFO to use my Aadhar for verification/authentication/eKYC purpose for service delivery.
B35: 3) | C35: Kindly transfer the funds and service details, if applicable from the previous PF account as declared above to the present P.F. Account (The Transfer would be possible only if the identified KYC details approved by previous employer has been verified by present employer
B36: 4) | C36: In case of changes in above details, the same will be intimated to employer at the earliest.
C37: Date : | D37: ='0422Master'!#REF! -> #REF!
C38: Place: | D38: Hyderabad | J38: Signature of Member
F40: DECLARATION BY PRESENT EMPLOYER
A41: A) | B41: The member Mr./Ms./Mrs. | E41: ='0422Master'!#REF! -> #REF! | H41: has joined on | J41: ='0422Master'!#REF! -> #REF! | K41: and has been allotted PF Number
B42: ='0422Master'!#REF! -> #REF!
A43: B) | B43: In case the person was earlier not a member of EPF Scheme, 1952 and EPS, 1995:
...

Sheet Form-F
A1: F O R M – F
A2: [See sub-Rule (1) of Rule 6] The Payment of Gratuity Rules, 1973:
A3: NOMINATION
A4: To
A5: ='0422Master'!F5 -> Burgeon IT Services Pvt.Ltd.
A6: ='0422Master'!F6 -> Siri Mansion LIGB 436 Dr.A S Rao Nagar,Hyderabad
A8: 1. I, Shri / Shrimati / Kumari | C8: ='0422Master'!#REF! -> #REF!
A9: whose particulars are given in the statement below, hereby nominate the person(s) mentioned below to receive the gratuity payable after my death as also the gratuity standing to my credit in the event of my death before that amount has become payable, or having become payable has not been paid and direct that the said amount of gratuity shall be paid in proportion indicated against the name(s) of the nominee(s).
A11: 2. I hereby certify that the person(s) mentioned is a /are member(s) of my family within the meaning of clause (h) of Section 2 of the Payment of Gratuity Act, 1972.
A13: 3. I hereby declare that I have no family within the meaning of clause (h) of Section 2 of the said Act.
A15: 4. (a) My father/mother/parents is/are not dependent on me
A16: (b) My husband’s father/mother/parents is/are not dependent on my husband.
A18: 5. I have excluded my husband from my family by a notice dated the ……………. to the Controlling Authority in terms of the proviso to clause (h) of Section 2 of the said Act.
A20: 6. Nomination made herein invalidates my previous nomination.
A22: NOMINEE(S)
A23: Name in full with full address of nominee(s): | B23: Relationship with the empliyee | C23: Age of nominee: | D23: Proportion by which the gratuity will be shared:
A24: 1 | B24: 2 | C24: 3 | D24: 4
A25: ='0422Master'!#REF! -> #REF! | B25: Father | C25: 54 Years | D25: 1
A29: STATEMENT
A31: 1. Name of employee in full: | C31: ='0422Master'!#REF! -> #REF!
A32: 2. Sex: | C32: ='0422Master'!#REF! -> #REF!
A33: 3. Religion: | C33: Muslim
A34: 4. Whether unmarried/married/widow/widower: | C34: Un married
A35: 5. Department/Branch/Section where employed: | C35: ='0422Master'!#REF! -> #REF!
A36: 6. Post held with Ticket No. or Serial No. if any: | C36: ='0422Master'!#REF! -> #REF!
A37: 7. Date of appointment: | C37: ='0422Master'!#REF! -> #REF!
A38: 8. Permanent address:
C39: ='0422Master'!#REF! -> #REF!
C40: ='0422Master'!#REF! -> #REF!
C41: ='0422Master'!#REF! -> #REF!
A42: Place: | B42: Hyderabad
A43: Date: | B43: ='0422Master'!#REF! -> #REF! | C43: Signature/Thumb impression of the employee
A45: Declaration by witnesses:
A46: Nomination signed/thumb impressed before me:
A48: Name in full and full address of witnesses: | C48: Signature of witnesses:
A49: 1 | C49: 1
A50: 2 | C50: 2
C51: Certificate by the Employer
A52: Certified that the particulars of the above nomination have been verified and recorded in t his establishment
A53: Employer's reference No, if any
...

Sheet Serive Certificate
B4: FORM XV
B5: [Vide rule 77 of Contract Labour (Regul. & Abolition) Central & A.P. Rules, 1971]
B7: SERVICE CERTIFICATE
B9: Name and address of Contractor : | G9: Name and address of establishment in / under which contract is caried on :
B11: ='0422Master'!F5 -> Burgeon IT Services Pvt.Ltd. | G11: ='0422Master'!AO5 -> Burgeon IT Services Pvt.Ltd.
B13: ='0422Master'!F6 -> Siri Mansion LIGB 436 Dr.A S Rao Nagar,Hyderabad | G13: ='0422Master'!AO6 -> Siri Mansion LIGB 436 Dr.A S Rao Nagar,Hyderabad
B17: Nature and Location of work: | G17: Name and address of Principal Employer :
G19: ='0422Master'!AO8 -> INFOSYS LIMITED, IL BHUBANESHWAR-STP,UNIT-II
B21: ='0422Master'!F8 -> IT SUPPORTIVE SERVICES & BHUBANESWAR | G21: ='0422Master'!AO10 -> Plot No E/4,Info city,Chandaka Industrial, Bhubaneswar,Odisha - 751024
B26: Name and address of the workman :
B31: Age or date of Birth :
B33: Identification Marks :
B35: Father's / Husband's Name :
B38: Sl.No. | C38: Total period for which employed | E38: Nature of work done | G38: Rate of wage ( with particulars of units in case of piece work) | J38: Remarks
C40: From | D40: To
B41: 1 | C41: 2 | D41: 3 | E41: 4 | G41: 5 | J41: 6
H56: Signature of the Employer with Seal

Sheet Sheet1
