Workbook

Sheet GUREGOAN APRIL 22WM Reg
A1: FORM - XIII REGISTER OF WORKMEN EMPLOYED BY CONTRACTOR
A2: ='04-22Master'!B4 -> (Vide Rule 75 of Contract Labour (Regulation and Abolition) Central/Haryana 1971)
A3: Name and address of Contractor: | F3: ='04-22Master'!F5 -> Burgeon IT Services Pvt.Ltd. | J3: ='04-22Master'!AJ5 -> Burgeon IT Services Pvt.Ltd.
F4: ='04-22Master'!F6 -> Siri Mansion LIGB 436 Dr.A S Rao Nagar,Hyderabad | J4: ='04-22Master'!AJ6 -> Siri Mansion LIGB 436 Dr.A S Rao Nagar,Hyderabad
A5: Nature and location of work: | F5: ='04-22Master'!F8 -> IT SUPPORTIVE SERVICES | G5: Gurgaon
A7: Wage period: Monthly | J7: ='04-22Master'!AJ10 -> INFOSYS LTD.IL Hyderabad SEZ Unit-3
J8: ='04-22Master'!AJ11 -> Sy.No 42,Pocharam Village,Gatkesar Mandal
A11: Serial No. in the Register of Workmen | B11: Name of Workman | C11: Age | D11: Sex | E11: Father's /Husband Name | F11: Designation / Nature of Work Done | G11: Permanent Address | H11: Local Address | I11: Date of Commencement of Employment | J11: Signature or thumb impression of Workman | K11: Date of termination of Employment | L11: Reasons for termination | M11: Remarks
A13: 1 | B13: Gaunda Mohammad Arief | C13: 29048 | D13: Male | E13: abdul hameed | F13: Senior Consultant | G13: Flat No 311, vaddegeeri, Chand talkies road, Kurnool, Andhra Pradesh 518001 | H13: 12-2-790/11, Ayodhyanagar Cooperative housingg society, Flat G 2, span nest apts, Mehdipatnam, HYD 500028 | I13: 44169 | J13: OOOO | K13: OOOO | L13: OOOO | M13: OOOO

Sheet 04-22Master
A3: FORM - XIII REGISTER OF WORKMEN EMPLOYED BY CONTRACTOR
B4: (Vide Rule 75 of Contract Labour (Regulation and Abolition) Central/Haryana 1971)
A5: Name and address of Contractor: | F5: Burgeon IT Services Pvt.Ltd. | V5: Name and address of Establishemnt in/ under which contract is carried on: | AJ5: =F5 -> Burgeon IT Services Pvt.Ltd.
F6: Siri Mansion LIGB 436 Dr.A S Rao Nagar,Hyderabad | AJ6: =F6 -> Siri Mansion LIGB 436 Dr.A S Rao Nagar,Hyderabad
A8: Nature and location of work: | F8: IT SUPPORTIVE SERVICES
A10: Wage period: Monthly | D10: 44652 | AE10: Name and address of Principal Employer: | AJ10: INFOSYS LTD.IL Hyderabad SEZ Unit-3
AJ11: Sy.No 42,Pocharam Village,Gatkesar Mandal
A14: Serial No. in the Register of Workmen | B14: Name of Workman | C14: Age | D14: Sex | E14: Father's /Husband Name | F14: Designation / Nature of Work Done | G14: Permanent Address | H14: Local Address | I14: Date of Commencement of Employment | J14: Signature or thumb impression of Workman | K14: Date of termination of Employment | L14: Reasons for termination | M14: Remarks | N14: EPF Number | O14: ESI Number | P14: Name of Workman | Q14: No.of Days worked | R14: Unit of work done | S14: Monthly rate of wages/ piece rate | T14: Basic wages | U14: Dearness Allowances | V14: Over time | W14: Other cash payments (Nature of payments to be indicated) | X14: HRA | Y14: CONVEYANCE | Z14: MEDICAL ALLOWANCES | AA14: SPECIAL ALLOWNANCES | AB14: Total | AC14: BONUS | AD14: GRATUITY | AE14: LTA/L.E | AF14: ARREAR AMOUNT | AG14: TOTAL AMOUNT | AH14: Deductions, if any, (Indicate nature) | AN14: Net Amount paid | AO14: Time and Date of Payment | AP14: Place of Payment | AQ14: Signature/Thumb Impression of workman | AR14: Initial of Contractor or his representative
AH15: ESI | AI15: PF | AJ15: PT | AK15: TDS | AL15: MED | AM15: Total Deductions
A16: ='GUREGOAN APRIL 22WM Reg'!A13 -> 1 | B16: ='GUREGOAN APRIL 22WM Reg'!B13 -> Gaunda Mohammad Arief | C16: ='GUREGOAN APRIL 22WM Reg'!C13 -> 29048 | D16: ='GUREGOAN APRIL 22WM Reg'!D13 -> Male | E16: ='GUREGOAN APRIL 22WM Reg'!E13 -> abdul hameed | F16: ='GUREGOAN APRIL 22WM Reg'!F13 -> Senior Consultant | G16: ='GUREGOAN APRIL 22WM Reg'!G13 -> Flat No 311, vaddegeeri, Chand talkies road, Kurnool, Andhra Pradesh 518001 | H16: ='GUREGOAN APRIL 22WM Reg'!H13 -> 12-2-790/11, Ayodhyanagar Cooperative housingg society, Flat G 2, span nest apts, Mehdipatnam, HYD 500028 | I16: ='GUREGOAN APRIL 22WM Reg'!I13 -> 44169 | J16: ooOO | K16: ooOO | L16: ooOO | M16: ooOO | N16: 101647021660 | O16: N/A | P16: =B16 -> Gaunda Mohammad Arief | Q16: 30 | R16: 29 | S16: 80278 | T16: 46561.24 | U16: 0 | V16: 0 | W16: =U16+V16+X16+Y16+Z16+AA16 -> 31153.827 | X16: 18624.496 | Y16: 2014 | Z16: 2014 | AA16: 8501.3307 | AB16: =T16+U16+V16+X16+Y16+Z16+AA16 -> 77715.067 | AC16: 1555 | AD16: 2239.5956 | AE16: 3880.1033 | AF16: 0 | AG16: =SUBTOTAL(9,AC16:AF16)+AB16 -> 85389.766 | AH16: 0 | AI16: 1800 | AJ16: 200 | AK16: 0 | AL16: 440.76133 | AM16: =SUBTOTAL(9,AH16:AL16) -> 2440.7613 | AN16: =AG16-AM16 -> 82949.004 | AO16: 05.05.2022 | AP16: Bank of baroda | AQ16: A/C'24218100005896
AE20: 7773
AE21: 80278
AE22: =SUBTOTAL(9,AE20:AE21) -> 88051
H711: ='04-22Master'!I303 -> 0

Sheet Eql remn
A1: Form D
A2: (See rule 6)
A4: Register to be maintained by the employer under rule 6 of the Equal Remuneration Rules, 1976
D6: ='04-22Master'!D10 -> 44652
A8: Name and address of Contractor : | F8: ='04-22Master'!F5 -> Burgeon IT Services Pvt.Ltd.
A10: Name and address of establishment in/under which contract is carried on : | F10: ='04-22Master'!AJ5 -> Burgeon IT Services Pvt.Ltd.
F11: ='04-22Master'!AJ6 -> Siri Mansion LIGB 436 Dr.A S Rao Nagar,Hyderabad
A12: Name and address of Principal Employer : | F12: ='04-22Master'!AJ10 -> INFOSYS LTD.IL Hyderabad SEZ Unit-3
F13: ='04-22Master'!AJ11 -> Sy.No 42,Pocharam Village,Gatkesar Mandal
A14: Total number of men workers employed | C14: =D22 -> 1
A16: Total number of women workers employed | C16: =C22 -> 0
C18: Components of remuneration
A19: Category of workers | B19: Brief Description of work | C19: No of women employed | D19: No. of men employed | E19: Rate or remuneration paid | F19: Basic wage & Dearness Allowance | G19: House Rent allowance | H19: Other allowances | I19: Cash value of concessional supply of essential commodities | J19: Name of the Client | K19: Primary Work Place/ Location
A20: ='04-22Master'!F16 -> Senior Consultant | B20: IT SUPPORTIVE SERVICES | C20: 0 | D20: 1 | E20: ='04-22Master'!S16 -> 80278 | F20: ='04-22Master'!T16 -> 46561.24 | G20: ='04-22Master'!X16 -> 18624.496 | H20: =E20-(F20+G20) -> 15092.264 | I20: 0 | J20: Infosys Ltd | K20: Gurgoan
C22: =SUM(C20:C21) -> 0 | D22: =SUM(D20:D21) -> 1
H29: Signature of the Contractor with Seal

Sheet 04-22 Muster Roll
A3: FORM - XVI MUSTER ROLL [Vide Rule 78 (1) (a) (i) of Contract Labour (Reg. & Abolition) Central & Haryana Rules 1971]
A5: Name and address of Contractor: | D5: ='04-22Master'!F5 -> Burgeon IT Services Pvt.Ltd. | J5: Name and address of Establishemnt in/ under which contract is carried on: | Z5: ='04-22Master'!AJ5 -> Burgeon IT Services Pvt.Ltd.
D6: ='04-22Master'!F6 -> Siri Mansion LIGB 436 Dr.A S Rao Nagar,Hyderabad | Z6: ='04-22Master'!AJ6 -> Siri Mansion LIGB 436 Dr.A S Rao Nagar,Hyderabad
A7: Nature and location of work: | D7: ='04-22Master'!F8 -> IT SUPPORTIVE SERVICES
A9: Wage period: Monthly | D9: ='04-22Master'!D10 -> 44652 | M9: Name and address of Principal Employer: | Z9: ='04-22Master'!AJ10 -> INFOSYS LTD.IL Hyderabad SEZ Unit-3
Z10: ='04-22Master'!AJ11 -> Sy.No 42,Pocharam Village,Gatkesar Mandal
A13: S.No | B13: Name of Workman | C13: Father's/ Husband's Name | D13: Sex | AI13: Remarks
E14: 1 | F14: 2 | G14: 3 | H14: 4 | I14: 5 | J14: 6 | K14: 7 | L14: 8 | M14: 9 | N14: 10 | O14: 11 | P14: 12 | Q14: 13 | R14: 14 | S14: 15 | T14: 16 | U14: 17 | V14: 18 | W14: 19 | X14: 20 | Y14: 21 | Z14: 22 | AA14: 23 | AB14: 24 | AC14: 25 | AD14: 26 | AE14: 27 | AF14: 28 | AG14: 29 | AH14: 30
A15: 1 | B15: ='04-22Master'!P16 -> Gaunda Mohammad Arief | C15: ='04-22Master'!E16 -> abdul hameed | D15: ='04-22Master'!D16 -> Male | E15: P | F15: WO | G15: WO | H15: P | I15: P | J15: P | K15: P | L15: P | M15: WO | N15: WO | O15: P | P15: P | Q15: P | R15: P | S15: H | T15: WO | U15: WO | V15: EL | W15: A | X15: P | Y15: P | Z15: P | AA15: WO | AB15: WO | AC15: P | AD15: P | AE15: P | AF15: P | AG15: P | AH15: WO | AI15: ='04-22Master'!R16 -> 29
A16: 2
J23: Signature of the Contractor with Seal

Sheet 04-22Leave Regr
B1: FORM - I
B3: Register of Leave
B4: (See Rule 14 as per Delhi Shops and Establishment rules 1954)
B5: Name of the Establishment: | E5: ='04-22Master'!F5 -> Burgeon IT Services Pvt.Ltd. | I5: Name of the Employee:
E6: ='04-22Master'!AJ6 -> Siri Mansion LIGB 436 Dr.A S Rao Nagar,Hyderabad | I6: ='04-22Master'!B16 -> Gaunda Mohammad Arief
B8: Date of Employment : | D8: ='04-22Master'!I16 -> 44169
B11: Casual or Sickness Leave | G11: Privilege Leave
B12: Amount of Leave | C12: Date of Application if any | D12: Leave Availed From | E12: Leave Availed To | F12: Total Leave Availed | G12: Leave Accumelated | H12: Further Leave Added in the month | I12: No. of days | J12: Date of Application | K12: Whether Application Granted or Refused Fully or Partly | L12: Leave Availed From | M12: Leave Availed To | N12: Total Leave Availed | O12: Balance leave Carried | P12: Signature of the Employee | Q12: Signature of the Employer
B14: 1 | C14: 2 | D14: 3 | E14: 4 | F14: 5 | I14: 6 | J14: 7 | K14: 8 | L14: 9 | M14: 10 | N14: 11 | P14: 12 | Q14: 13
A15: JAN'22 | B15: 1 | C15: 0 | D15: 0 | E15: 0 | F15: 0 | G15: 15 | H15: 1.5 | I15: 0 | J15: 44564 | K15: 1 | L15: 44564 | M15: 44564 | N15: 1 | O15: 15.5
A16: FEB'22 | B16: 1 | C16: 44595 | D16: 44595 | E16: 44595 | F16: 1 | H16: 1.5 | I16: 0 | J16: 44595 | K16: 1 | L16: 44595 | M16: 44595 | N16: 1 | O16: =O15+H16-K16 -> 16
A17: 44621 | B17: 1 | C17: 44624 | D17: 44624 | E17: 44624 | F17: 1 | H17: 1.5 | I17: 0 | J17: 44624 | K17: 1 | L17: 44624 | M17: 44624 | N17: 1 | O17: =O16+H17-K17 -> 16.5
A18: APRIL;22 | B18: 1 | C18: 44669 | D18: 44669 | E18: 44669 | F18: 1 | H18: 1.5 | I18: 1 | J18: 44669 | K18: 1 | L18: 44669 | M18: 44669 | N18: 1 | O18: =O17+H18-K18 -> 17
J34: Signature of the Contractor with Seal
B42: FORM - I
B44: Register of Leave
B45: (See Rule 14 as per Delhi Shops and Establishment rules 1954)
B46: Name of the Establishment: | E46: ='04-22Master'!F5 -> Burgeon IT Services Pvt.Ltd. | I46: Name of the Employee:
E47: ='04-22Master'!F6 -> Siri Mansion LIGB 436 Dr.A S Rao Nagar,Hyderabad | I47: ='04-22Master'!B17 -> 0
B49: Date of Employment : | D49: ='04-22Master'!I17 -> 0
B52: Casual or Sickness Leave | G52: Privilege Leave
B53: Amount of Leave | C53: Date of Application if any | D53: Leave Availed From | E53: Leave Availed To | F53: Total Leave Availed | G53: Leave Accumelated | H53: Further Leave Added in the month | I53: No. of days | J53: Date of Application | K53: Whether Application Granted or Refused Fully or Partly | L53: Leave Availed From | M53: Leave Availed To | N53: Total Leave Availed | O53: Balance leave Carried | P53: Signature of the Employee | Q53: Signature of the Employer
B55: 1 | C55: 2 | D55: 3 | E55: 4 | F55: 5 | I55: 6 | J55: 7 | K55: 8 | L55: 9 | M55: 10 | N55: 11 | P55: 12 | Q55: 13
J71: Signature of the Contractor with Seal

Sheet wages Reg
A3: FORM - XVII REGISTER OF WAGES [Vide Rule 78 (1) (a) (i) of Contract Labour (Reg. & Abolition) Central & Haryana 1971]
A5: Name and address of Contractor: | D5: ='04-22Master'!F5 -> Burgeon IT Services Pvt.Ltd. | U5: Name and address of Establishemnt in/ under which contract is carried on: | AB5: ='04-22Master'!AJ5 -> Burgeon IT Services Pvt.Ltd.
D6: ='04-22Master'!F6 -> Siri Mansion LIGB 436 Dr.A S Rao Nagar,Hyderabad | AB6: ='04-22Master'!AJ6 -> Siri Mansion LIGB 436 Dr.A S Rao Nagar,Hyderabad
A7: Nature and location of work: | D7: ='04-22Master'!F8 -> IT SUPPORTIVE SERVICES
A9: Wage period: Monthly | D9: ='04-22Master'!D10 -> 44652 | V9: Name and address of Principal Employer: | AB9: ='04-22Master'!AJ10 -> INFOSYS LTD.IL Hyderabad SEZ Unit-3
AB10: ='04-22Master'!AJ11 -> Sy.No 42,Pocharam Village,Gatkesar Mandal
A13: S.No | B13: Name of Workman | C13: Serial No. in the Register of Workmen | D13: Designation / Nature of Work Done | E13: No.of Days worked | F13: Unit of work done | G13: Monthly rate of wages/ piece rate | H13: Basic wages | I13: Dearness Allowances | J13: Over time | K13: Other cash payments (Nature of payments to be indicated) | L13: HRA | M13: CONVEYANCE | N13: MEDICAL ALLOWANCES | O13: SPECIAL ALLOWNANCES | P13: Total | Q13: BONUS | R13: GRATUITY | S13: LTA/L.E | T13: ARREAR AMOUNT | U13: TOTAL AMOUNT | V13: Deductions, if any, (Indicate nature) | AC13: Net Amount paid | AD13: Time and Date of Payment | AE13: Place of Payment | AF13: Signature/Thumb Impression of workman | AG13: Initial of Contractor or his representative
V14: ESI | W14: PF | X14: PT | Y14: TDS | Z14: MED | AA14: Adjusted Amount | AB14: Total Deductions
A15: 1 | B15: ='04-22Master'!P16 -> Gaunda Mohammad Arief | C15: ='04-22Master'!A16 -> 1 | D15: ='04-22Master'!F16 -> Senior Consultant | E15: ='04-22Master'!Q16 -> 30 | F15: ='04-22Master'!R16 -> 29 | G15: ='04-22Master'!S16 -> 80278 | H15: ='04-22Master'!T16 -> 46561.24 | I15: ='04-22Master'!U16 -> 0 | J15: ='04-22Master'!V16 -> 0 | K15: =L15+M15+N15+O15 -> 31153.827 | L15: ='04-22Master'!X16 -> 18624.496 | M15: ='04-22Master'!Y16 -> 2014 | N15: ='04-22Master'!Z16 -> 2014 | O15: ='04-22Master'!AA16 -> 8501.3307 | P15: =H15+K15 -> 77715.067 | Q15: ='04-22Master'!AC16 -> 1555 | R15: ='04-22Master'!AD16 -> 2239.5956 | S15: ='04-22Master'!AE16 -> 3880.1033 | T15: ='04-22Master'!AF16 -> 0 | U15: =P15+Q15+R15+S15+T15 -> 85389.766 | V15: ='04-22Master'!AH16 -> 0 | W15: ='04-22Master'!AI16 -> 1800 | X15: ='04-22Master'!AJ16 -> 200 | Y15: ='04-22Master'!AK16 -> 0 | Z15: ='04-22Master'!AL16 -> 440.76133 | AA15: 0 | AB15: =V15+W15+X15+Y15+Z15+AA15 -> 2440.7613 | AC15: =U15-AB15 -> 82949.004 | AD15: ='04-22Master'!AO16 -> 05.05.2022 | AE15: ='04-22Master'!AP16 -> Bank of baroda | AF15: ='04-22Master'!AQ16 -> A/C'24218100005896
A16: 0
G17: =SUM(G15:G16) -> 80278 | H17: =SUM(H15:H16) -> 46561.24 | I17: =SUM(I15:I16) -> 0 | J17: =SUM(J15:J16) -> 0 | K17: =SUM(K15:K16) -> 31153.827 | L17: =SUM(L15:L16) -> 18624.496 | M17: =SUM(M15:M16) -> 2014 | N17: =SUM(N15:N16) -> 2014 | ... AC17: =SUM(AC15:AC16) -> 82949.004
J21: Signature of the Contractor with Seal

Sheet 04-22Empl Cards
B1: FORM XIV
B2: EMPLOYMENT CUM WAGE CARD
B3: (Vide Rule 76 of Contract Labour (R&A) Central & Haryana, 1971)
B4: Name and Address of the Contractor | H4: Name and Address of the Establishment in/under which Contract is carried on:
B7: ='04-22Master'!F5 -> Burgeon IT Services Pvt.Ltd. | H7: ='04-22Master'!AJ5 -> Burgeon IT Services Pvt.Ltd.
B9: ='04-22Master'!F6 -> Siri Mansion LIGB 436 Dr.A S Rao Nagar,Hyderabad | H9: ='04-22Master'!AJ6 -> Siri Mansion LIGB 436 Dr.A S Rao Nagar,Hyderabad
B12: Nature of work and location of work: | H12: Name and address of Principal Employer:
H15: ='04-22Master'!AJ10 -> INFOSYS LTD.IL Hyderabad SEZ Unit-3
B16: ='04-22Master'!F8 -> IT SUPPORTIVE SERVICES
H17: ='04-22Master'!AJ11 -> Sy.No 42,Pocharam Village,Gatkesar Mandal
B19: 1. Name of the Workman and address | H19: ='04-22Master'!B16 -> Gaunda Mohammad Arief
H20: ='04-22Master'!G16 -> Flat No 311, vaddegeeri, Chand talkies road, Kurnool, Andhra Pradesh 518001
B21: 2. S.No. in the Register of Workmen Employed | H21: ='04-22Master'!A16 -> 1
B22: 3. Nature of Employment /Designation | H22: ='04-22Master'!F16 -> Senior Consultant
B23: 4. Date of entry into service | H23: ='04-22Master'!I16 -> 44169
B24: 5. ESI No. | J24: ='04-22Master'!O16 -> N/A
B25: 6.PF No. | J25: ='04-22Master'!N16 -> 101647021660
B26: 7. Wage rate (With particulars of unit in case of piece - work) | H26: ='04-22Master'!S16 -> 80278
B27: 8. Wage period | H27: ='04-22Master'!D10 -> 44652
B28: 9. Tenure of Employment | H28: AS PER CONTRACT
B29: 10.No. of days worked in a month | J29: ='04-22Master'!Q16 -> 30
B30: 11. No. of units worked in case of piece rate workers | J30: N/A
B31: 12. Rate of daily wages / piece rate | J31: 0
B32: 13. Amount of overtime wages | J32: 0
B33: 14. Gross wages payable | J33: ='04-22Master'!AG16 -> 85389.766 | L33: MED
B34: 15. Deductions, if any, | D34: PF | E34: ='04-22Master'!AI16 -> 1800 | F34: ESI | G34: ='04-22Master'!AH16 -> 0 | H34: PT | I34: ='04-22Master'!AJ16 -> 200 | J34: TDS | K34: ='04-22Master'!AK16 -> 0 | L34: ='04-22Master'!AL16 -> 440.76133
B35: 16. Net amount of wages paid | J35: ='04-22Master'!AN16 -> 82949.004
B36: Signature of the Representative
B37: of Contractor
B51: FORM XIV
B52: EMPLOYMENT CUM WAGE CARD
B53: (Vide Rule 76 of Contract Labour (R&A) Central & Haryana, 1971)
B54: Name and Address of the Contractor | H54: Name and Address of the Establishment in/under which Contract is carried on:
B57: ='04-22Master'!F5 -> Burgeon IT Services Pvt.Ltd. | H57: ='04-22Master'!AJ5 -> Burgeon IT Services Pvt.Ltd.
B59: ='04-22Master'!F6 -> Siri Mansion LIGB 436 Dr.A S Rao Nagar,Hyderabad | H59: ='04-22Master'!AJ6 -> Siri Mansion LIGB 436 Dr.A S Rao Nagar,Hyderabad
B62: Nature of work and location of work: | H62: Name and address of Principal Employer:
H65: ='04-22Master'!AJ10 -> INFOSYS LTD.IL Hyderabad SEZ Unit-3
B66: ='04-22Master'!F8 -> IT SUPPORTIVE SERVICES
H67: ='04-22Master'!AJ11 -> Sy.No 42,Pocharam Village,Gatkesar Mandal
B69: 1. Name of the Workman and address | H69: ='04-22Master'!B17 -> 0
...

Sheet wage sllips
A1: Form XIX - WAGE SLIP | K1: Form XIX - WAGE SLIP
A2: [Vide rule 78 (1) (b) of the Contract Labour (Regulation and Abolition) Central and Haryana Rules, 1971] | K2: [Vide rule 78 (1) (b) of the Contract Labour (Regulation and Abolition) Central and Haryana Rules, 1971]
A4: Name and address of Contractor | D4: ='04-22Master'!F5 -> Burgeon IT Services Pvt.Ltd. | K4: Name and address of Contractor | O4: =D4 -> Burgeon IT Services Pvt.Ltd.
B5: ='04-22Master'!F6 -> Siri Mansion LIGB 436 Dr.A S Rao Nagar,Hyderabad | L5: =B5 -> Siri Mansion LIGB 436 Dr.A S Rao Nagar,Hyderabad
A7: Name and Father's / Husband's name of the workman | K7: Name and Father's / Husband's name of the workman
E8: ='04-22Master'!B16 -> Gaunda Mohammad Arief | H8: ='04-22Master'!E16 -> abdul hameed | O8: =E8 -> Gaunda Mohammad Arief | R8: =H8 -> abdul hameed
A10: Nature and location of work | E10: ='04-22Master'!F8 -> IT SUPPORTIVE SERVICES | K10: Nature and location of work | O10: =E10 -> IT SUPPORTIVE SERVICES
A12: For the Week / Fortnight / Month ending | E12: ='04-22Master'!D10 -> 44652 | K12: For the Week / Fortnight / Month ending | O12: =E12 -> 44652
A14: 1 | B14: No. of days worked | E14: ='04-22Master'!Q16 -> 30 | K14: 1 | L14: No. of days worked | O14: =E14 -> 30
A16: 2 | B16: No. of units worked in case of piece rate workers : | K16: 2 | L16: No. of units worked in case of piece rate workers :
E17: N/A | O17: N/A
A19: 3 | B19: Rate of daily wages / piece rate | E19: N/A | K19: 3 | L19: Rate of daily wages / piece rate | O19: =E19 -> N/A
A21: 4 | B21: Amount of overtime wages | E21: Nil | K21: 4 | L21: Amount of overtime wages | O21: Nil
A23: 5 | B23: Gross wages payble | E23: ='04-22Master'!AG16 -> 85389.766 | K23: 5 | L23: Gross wages payble | O23: =E23 -> 85389.766
D24: EPF | E24: ESI | F24: PT | G24: TDS | H24: MEDICAL | I24: TOTAL | N24: EPF | O24: ESI | P24: PT | Q24: TDS | R24: MEDICAL | S24: TOTAL
A25: 6 | B25: Deductions, if any | D25: ='04-22Master'!AI16 -> 1800 | E25: ='04-22Master'!AH16 -> 0 | F25: ='04-22Master'!AJ16 -> 200 | G25: ='04-22Master'!AK16 -> 0 | H25: ='04-22Master'!AL16 -> 440.76133 | I25: =D25+E25+F25+G25+H25 -> 2440.7613 | K25: 6 | L25: Deductions, if any | N25: =D25 -> 1800 | O25: =E25 -> 0 | P25: =F25 -> 200 | Q25: =G25 -> 0 | R25: =H25 -> 440.76133 | S25: =I25 -> 2440.7613
A27: 7 | B27: Net amount of wages paid | E27: =E23-I25 -> 82949.004 | K27: 7 | L27: Net amount of wages paid | O27: =E27 -> 82949.004
F31: Initial of the Contractor or his representative | P31: Initial of the Contractor or his representative
A49: Form XIX - WAGE SLIP | K49: Form XIX - WAGE SLIP
A50: [Vide rule 78 (1) (b) of the Contract Labour (Regulation and Abolition) Central and Haryana Rules, 1971] | K50: [Vide rule 78 (1) (b) of the Contract Labour (Regulation and Abolition) Central and Haryana Rules, 1971]
A52: Name and address of Contractor | D52: ='04-22Master'!F5 -> Burgeon IT Services Pvt.Ltd. | K52: Name and address of Contractor | O52: =D52 -> Burgeon IT Services Pvt.Ltd.
B53: ='04-22Master'!F6 -> Siri Mansion LIGB 436 Dr.A S Rao Nagar,Hyderabad | L53: =B53 -> Siri Mansion LIGB 436 Dr.A S Rao Nagar,Hyderabad
A55: Name and Father's / Husband's name of the workman | K55: Name and Father's / Husband's name of the workman
E56: ='04-22Master'!B17 -> 0 | O56: =E56 -> 0
A58: Nature and location of work | E58: ='04-22Master'!F8 -> IT SUPPORTIVE SERVICES | K58: Nature and location of work | O58: =E58 -> IT SUPPORTIVE SERVICES
A60: For the Week / Fortnight / Month ending | E60: ='04-22Master'!D10 -> 44652 | K60: For the Week / Fortnight / Month ending | O60: =E60 -> 44652
A62: 1 | B62: No. of days worked | E62: ='04-22Master'!Q17 -> 0 | K62: 1 | L62: No. of days worked | O62: =E62 -> 0
A64: 2 | B64: No. of units worked in case of piece rate workers : | K64: 2 | L64: No. of units worked in case of piece rate workers :
E65: N/A | O65: N/A
A67: 3 | B67: Rate of daily wages / piece rate | E67: N/A | K67: 3 | L67: Rate of daily wages / piece rate | O67: =E67 -> N/A
A69: 4 | B69: Amount of overtime wages | E69: Nil | K69: 4 | L69: Amount of overtime wages | O69: Nil
A71: 5 | B71: Gross wages payble | E71: ='04-22Master'!AG17 -> 0 | K71: 5 | L71: Gross wages payble | O71: =E71 -> 0
D72: EPF | E72: ESI | F72: PT | G72: TDS | H72: MEDICAL | I72: TOTAL | N72: EPF | O72: ESI | P72: PT | Q72: TDS | R72: MEDICAL | S72: TOTAL
A73: 6 | B73: Deductions, if any | D73: ='04-22Master'!AI17 -> 0 | E73: ='04-22Master'!AH17 -> 0 | F73: ='04-22Master'!AJ17 -> 0 | G73: ='04-22Master'!AK17 -> 0 | H73: ='04-22Master'!AL17 -> 0 | I73: =D73+E73+F73+G73+H73 -> 0 | K73: 6 | L73: Deductions, if any | N73: =D73 -> 0 | O73: =E73 -> 0 | P73: =F73 -> 0 | Q73: =G73 -> 0 | R73: =H73 -> 0 | S73: =I73 -> 0
A75: 7 | B75: Net amount of wages paid | E75: =E71-I73 -> 0 | K75: 7 | L75: Net amount of wages paid | O75: =E75 -> 0
F79: Initial of the Contractor or his representative | P79: Initial of the Contractor or his representative

Sheet 04-22Bonus
A1: BONUS REGISTER
A3: FORM "c" ( See rule 4 [c] )
K4: Wage Period | L4: ='04-22Master'!D10 -> 44652
A5: Name of the Establishment : _____________________________ | D5: ='04-22Master'!F5 -> Burgeon IT Services Pvt.Ltd. | K5: Financial year _____ | M5: 2022-2023
A7: Sr. No | B7: Name of the Employee | C7: Father's Name / Husband's Name | D7: Whether he has completed 15 yrs of age at the beginning of the accounting year | E7: Designation | F7: No. of days worked in the year | G7: Total Salary or wages in the year | H7: Amt. of bonus payable under section 10 or section 11 as the case may be Ex gratia | I7: DEDUCTIONS | L7: Total Sum Deducted (Col. 9,10 and 11) | M7: Net Amount payable (Col. 8 minus Col. 12) | N7: Amount Actually paid | O7: Date on which paid | P7: Signature / Thumb impression of the employee
I8: Puja Bonus or other customary bonus paid during the accounting year | J8: Interim Bonus or bonus paid in advance | K8: Deduction on account of financial loss if any caused by misconduct of the employee | Q8: Account Number
A9: 1 | B9: 2 | C9: 3 | D9: 4 | E9: 5 | F9: 6 | H9: 8 | I9: 9 | J9: 10 | K9: 11 | L9: 12 | M9: 13 | N9: 14 | O9: 15 | P9: 16
A10: 1 | B10: ='04-22Master'!P16 -> Gaunda Mohammad Arief | C10: ='04-22Master'!E16 -> abdul hameed | D10: YES | E10: ='04-22Master'!F16 -> Senior Consultant | F10: ='04-22Master'!Q16 -> 30 | G10: ='04-22Master'!AG16 -> 85389.766 | H10: ='04-22Master'!AC16 -> 1555 | I10: N/A | J10: N/A | K10: N/A | L10: N/A | M10: =H10 -> 1555 | N10: =M10 -> 1555 | O10: ='04-22Master'!AO16 -> 05.05.2022 | P10: ='04-22Master'!AP16 -> Bank of baroda | Q10: ='04-22Master'!AQ16 -> A/C'24218100005896
A11: 2
L35: Signature of the Contractor with Seal

Sheet Ser Certi
B4: FORM XV
B5: [Vide rule 77 of Contract Labour (Regul. & Abolition) Central & A.P. Rules, 1971]
B7: SERVICE CERTIFICATE
B9: Name and address of Contractor : | G9: Name and address of establishment in / under which contract is caried on :
B11: ='04-22Master'!F5 -> Burgeon IT Services Pvt.Ltd. | G11: ='04-22Master'!AJ5 -> Burgeon IT Services Pvt.Ltd.
B13: ='04-22Master'!F6 -> Siri Mansion LIGB 436 Dr.A S Rao Nagar,Hyderabad | G13: ='04-22Master'!AJ6 -> Siri Mansion LIGB 436 Dr.A S Rao Nagar,Hyderabad
B17: Nature and Location of work: | G17: Name and address of Principal Employer :
G19: ='04-22Master'!AJ10 -> INFOSYS LTD.IL Hyderabad SEZ Unit-3
B21: ='04-22Master'!F8 -> IT SUPPORTIVE SERVICES | G21: ='04-22Master'!AJ11 -> Sy.No 42,Pocharam Village,Gatkesar Mandal
B26: Name and address of the workman :
B31: Age or date of Birth :
B33: Identification Marks :
B35: Father's / Husband's Name :
B38: Sl.No. | C38: Total period for which employed | E38: Nature of work done | G38: Rate of wage ( with particulars of units in case of piece work) | J38: Remarks
C40: From | D40: To
B41: 1 | C41: 2 | D41: 3 | E41: 4 | G41: 5 | J41: 6
H56: Signature of the Employer with Seal

Sheet Deductions
A1: FORM XX- REGISTER OF DEDUCTIONS FOR DAMAGE OR LOSS
A3: (Vide Rule 78(1) (a) (i) of Contract Labour (Regulation and Abolition) Central /Haryana Rules 1971
A4: Name and address of Contractor: | D4: ='04-22Master'!F5 -> Burgeon IT Services Pvt.Ltd. | E4: Name and address of the establishment in / under which contract is carried on:
B5: ='04-22Master'!F6 -> Siri Mansion LIGB 436 Dr.A S Rao Nagar,Hyderabad
B6: ='04-22Master'!F7 -> 0
A7: Nature and Location of Work: | D7: ='04-22Master'!F8 -> IT SUPPORTIVE SERVICES | E7: Name and address of principal employer:
E8: ='04-22Master'!AJ10 -> INFOSYS LTD.IL Hyderabad SEZ Unit-3
E9: ='04-22Master'!AJ11 -> Sy.No 42,Pocharam Village,Gatkesar Mandal
A11: S.No | B11: Name of workman | C11: Father's / Husband's Name | D11: Designation / Nature of employment | E11: Particulars of damage or loss | F11: Date of Damage or loss | G11: Whether workman showed cause against deduction | H11: Name of person in whose presence employee's explanation was heard | I11: Amount of deduction impossed | J11: Date of recovery | M11: Remarks
J12: No.of Instalments | K12: First Instalment | L12: Last instalment
A13: 1 | B13: 2 | C13: 3 | D13: 4 | E13: 5 | F13: 6 | G13: 7 | H13: 8 | I13: 9 | J13: 10 | K13: 11 | L13: 12 | M13: 13
B16: NO EMPLOYEE WAS IMPOSED DEDUCTIONS FOR DAMAGE OR LOSS FOR THE MONTH OF | H16: ='04-22Master'!D10 -> 44652
J41: Signature of the Contractor with Seal

Sheet Fines
A1: FORM XXI- REGISTER OF FINES
A3: (Vide Rule 78(1) (a) (i) of Contract Labour (Regulation and Abolition) Central /A.P.Haryana1971
A4: Name and address of Contractor: | D4: ='04-22Master'!F5 -> Burgeon IT Services Pvt.Ltd. | E4: Name and address of the establishment in / under which contract is carried on:
B5: ='04-22Master'!F6 -> Siri Mansion LIGB 436 Dr.A S Rao Nagar,Hyderabad
B6: ='04-22Master'!F7 -> 0
A7: Nature and Location of Work: | D7: ='04-22Master'!F8 -> IT SUPPORTIVE SERVICES | E7: Name and address of principal employer:
E8: ='04-22Master'!AJ10 -> INFOSYS LTD.IL Hyderabad SEZ Unit-3
E9: ='04-22Master'!AJ11 -> Sy.No 42,Pocharam Village,Gatkesar Mandal
A11: S.No | B11: Name of workman | C11: Father's / Husband's Name | D11: Designation / Nature of employment | E11: Act/Omission for which fine imposed | F11: Date of offence | G11: Whether workman showed cause against fine | H11: Name of person in whose presence employee's explanation was heard | I11: Wage-period and wge payable | J11: Amount of fine Imposed | K11: Date on which fine realised | L11: Remarks
A13: 1 | B13: 2 | C13: 3 | D13: 4 | E13: 5 | F13: 6 | G13: 7 | H13: 8 | I13: 9 | J13: 10 | K13: 11 | L13: 12
B16: NO EMPLOYEE WAS IMPOSED FINESFOR THE MONTH OF | H16: ='04-22Master'!D10 -> 44652
F40: Signature of the Contractor with Seal

Sheet Advances
A1: FORM XXII- REGISTER OF ADVANCES
A3: (Vide Rule 78(1) (a) (i) of Contract Labour (Regulation and Abolition) Central /HaryanaRules 1971
A4: Name and address of Contractor: | D4: ='04-22Master'!F5 -> Burgeon IT Services Pvt.Ltd. | E4: Name and address of the establishment in / under which contract is carried on:
B5: ='04-22Master'!F6 -> Siri Mansion LIGB 436 Dr.A S Rao Nagar,Hyderabad
B6: ='04-22Master'!F7 -> 0
A7: Nature and Location of Work: | D7: ='04-22Master'!F8 -> IT SUPPORTIVE SERVICES | E7: Name and address of principal employer:
E8: ='04-22Master'!AJ10 -> INFOSYS LTD.IL Hyderabad SEZ Unit-3
E9: ='04-22Master'!AJ11 -> Sy.No 42,Pocharam Village,Gatkesar Mandal
A11: S.No | B11: Name of workman | C11: Father's / Husband's Name | D11: Designation / Nature of employment | E11: Wage period and wages payable | F11: Date and amount of advance given | G11: Purpose(s) for which advance made | H11: Number of instalments by which advance to be repaid | I11: Date and amount of each instalment repaid | J11: Date on which last instalment was repaid | K11: Remarks
A13: 1 | B13: 2 | C13: 3 | D13: 4 | E13: 5 | F13: 6 | G13: 7 | H13: 8 | I13: 9 | J13: 10 | K13: 11
B16: NO EMPLOYEE TAKEN ADVANCE FOR THE MONTH OF | F16: ='04-22Master'!D10 -> 44652
G37: Signature of the Contractor with Seal

Sheet Overtime
A1: FORM XXIII- REGISTER OF OVERTIME
A3: (Vide Rule 78(1) (a) (i) of Contract Labour (Regulation and Abolition) Central /Haryana Rules. 1971
A4: Name and address of Contractor: E-35 GREATER KAILASH ENCLAVE-1 NEW DELHI | D4: ='04-22Master'!F5 -> Burgeon IT Services Pvt.Ltd. | F4: Name and address of the establishment in which under contract is carried on:
B5: ='04-22Master'!F6 -> Siri Mansion LIGB 436 Dr.A S Rao Nagar,Hyderabad
B6: ='04-22Master'!F7 -> 0
A7: Nature and Location of Work: | D7: ='04-22Master'!F8 -> IT SUPPORTIVE SERVICES | F7: Name and address of principal employer:
F8: ='04-22Master'!AJ10 -> INFOSYS LTD.IL Hyderabad SEZ Unit-3
F9: ='04-22Master'!AJ11 -> Sy.No 42,Pocharam Village,Gatkesar Mandal
A11: S.No | B11: Name of workman | C11: Father's / Husband's Name | D11: Sex | E11: Designation / Nature of employment | F11: Date on which overtime worked | G11: Total overtime worked or production in case of piece-rates | H11: Normal rate of wages | I11: Overtime rate of wages | J11: overtime earnings | K11: Date on which overtime wages paid | L11: Remarks
A13: 1 | B13: 2 | C13: 3 | D13: 4 | E13: 5 | F13: 6 | G13: 7 | H13: 8 | I13: 9 | J13: 10 | K13: 11 | L13: 12
B16: NO EMPLOYEE DONE OVERTIME FOR THE MONTH OF | F16: ='04-22Master'!D10 -> 44652
I38: Signature of the Contractor with Seal

Sheet Accident
A1: FORM 11
A3: ACCIDENT BOOK
A4: EMPLOYEE STATE INSURANCE CORPORATION
B5: (Regulation 66)
A7: S.No | B7: Date of Notice | C7: Time of Notice | D7: Name and Address of the Injured Person | E7: Sex | F7: Age | H7: Shift,Department and occupation of employee | I7: Details of Injury | P7: Signature and designation of the person who makes the entry in the accident book | Q7: Name,address and occupation of the two witnesses | R7: Remarks if any
G8: Insurance Number | N8: What exactly was the injured person doing at the time of accident | O8: Name,Occupation,address and signature or the thumb impression of the person(s) giving notice
I9: Cause | J9: Nature | K9: Date | L9: Time | M9: Place
A10: 1 | B10: 2 | C10: 3 | D10: 4 | E10: 5 | F10: 6 | G10: 7 | H10: 8 | I10: 9 | J10: 10 | K10: 11 | L10: 12 | M10: 13 | N10: 14 | O10: 15 | P10: 16 | Q10: 17 | R10: 18
B12: NO ACCIDENT OCCURRED FOR THE MONTH OF | F12: ='04-22Master'!D10 -> 44652
J27: Signature of the Contractor with Seal

Sheet ESI cards Reg
C1: ='04-22Master'!F5 -> Burgeon IT Services Pvt.Ltd. | E1: ESI PAHECHAN CARDS ISSUE REGISTER
B2: S.No | C2: Name of the Employee | D2: ESI Number | E2: Issue Date | F2: Signature | G2: Remarks
B3: 1 | C3: ='04-22Master'!#REF! -> #REF! | D3: ='04-22Master'!#REF! -> #REF!
B4: 2 | C4: ='04-22Master'!#REF! -> #REF! | D4: ='04-22Master'!#REF! -> #REF!
B5: 3 | C5: ='04-22Master'!#REF! -> #REF! | D5: ='04-22Master'!#REF! -> #REF!
B6: 4 | C6: ='04-22Master'!#REF! -> #REF! | D6: ='04-22Master'!#REF! -> #REF!
B7: 5 | C7: ='04-22Master'!#REF! -> #REF! | D7: ='04-22Master'!#REF! -> #REF!
B8: 6 | C8: ='04-22Master'!#REF! -> #REF! | D8: ='04-22Master'!#REF! -> #REF!
B9: 7 | C9: ='04-22Master'!#REF! -> #REF! | D9: ='04-22Master'!#REF! -> #REF!
B10: 8 | C10: ='04-22Master'!#REF! -> #REF! | D10: ='04-22Master'!#REF! -> #REF!
B11: 9 | C11: ='04-22Master'!#REF! -> #REF! | D11: ='04-22Master'!#REF! -> #REF!
B12: 10 | C12: ='04-22Master'!#REF! -> #REF! | D12: ='04-22Master'!#REF! -> #REF!
B13: 11 | C13: ='04-22Master'!#REF! -> #REF! | D13: ='04-22Master'!#REF! -> #REF!
B14: 12 | C14: ='04-22Master'!#REF! -> #REF! | D14: ='04-22Master'!#REF! -> #REF!
B15: 13 | C15: =[1]LEFT!U3 -> Bharath Dommaraju | D15: =[1]LEFT!T3 -> N/A
B16: 14 | C16: =[1]LEFT!U4 -> #REF! | D16: =[1]LEFT!T4 -> #REF!
B17: 15 | C17: =[1]LEFT!U5 -> #REF! | D17: =[1]LEFT!T5 -> #REF!
B18: 16 | C18: =[1]LEFT!U6 -> #REF! | D18: =[1]LEFT!T6 -> #REF!
B19: 17 | C19: =[1]LEFT!U7 -> #REF! | D19: =[1]LEFT!T7 -> #REF!
B20: 18 | C20: =[1]LEFT!U8 -> #REF! | D20: =[1]LEFT!T8 -> #REF!
B21: 19 | C21: =[1]LEFT!U9 -> #REF! | D21: =[1]LEFT!T9 -> #REF!
B22: 20 | C22: =[1]LEFT!U10 -> #REF! | D22: =[1]LEFT!T10 -> #REF!

Sheet Form-I
B1: FORM I
B2: NOMINATION AND DECLARATION FORM
B3: (Vide Rule 3 of Payment of wages Act Central & A.P Rules, 1936)
B4: Name and Address of the Contractor | H4: Name and Address of the Establishment in/under which Contract is carried on:
B7: ='04-22 Muster Roll'!D5 -> Burgeon IT Services Pvt.Ltd. | H7: ='04-22 Muster Roll'!Z5 -> Burgeon IT Services Pvt.Ltd.
B9: ='04-22 Muster Roll'!D6 -> Siri Mansion LIGB 436 Dr.A S Rao Nagar,Hyderabad | H9: ='04-22 Muster Roll'!Z6 -> Siri Mansion LIGB 436 Dr.A S Rao Nagar,Hyderabad
B12: Nature of work and location of work: | H12: Name and address of Principal Employer:
H15: ='04-22 Muster Roll'!Z9 -> INFOSYS LTD.IL Hyderabad SEZ Unit-3
B16: ='04-22 Muster Roll'!D7 -> IT SUPPORTIVE SERVICES
H17: ='04-22 Muster Roll'!Z10 -> Sy.No 42,Pocharam Village,Gatkesar Mandal
B19: 1. Name of the person making nomination | H19: ='04-22Master'!#REF! -> #REF!
B20: 2. Father's/Husband name | H20: ='04-22Master'!#REF! -> #REF!
B21: 3. Date of Birth | H21: ='04-22Master'!#REF! -> #REF!
B22: 4. Sex | H22: ='04-22Master'!#REF! -> #REF!
B23: 5. Marital Status | H23: Un-Married
B24: 6.Address
B25: Permanent | H25: ='04-22Master'!#REF! -> #REF!
H26: ='04-22Master'!#REF! -> #REF!
H27: ='04-22Master'!#REF! -> #REF!
B28: Temporary | H28: ='04-22Master'!#REF! -> #REF!
H29: ='04-22Master'!#REF! -> #REF!
H30: ='04-22Master'!#REF! -> #REF!
B31: I hereby nominate the person(s)/cancel the nomination made by me previously and nominate the person(s) mentioned below to
B32: receive any amount due to me from the employer,in the event to my death.
B33: Name of the Nominee/nominees | E33: Address | G33: Nominee's relationship With the member | I33: Date of Birth | J33: Total amount of Share of accumulations | K33: If the nominee is minor,name,relationship and address of the guardian
B34: 1 | E34: 2 | G34: 3 | I34: 4 | J34: 5 | L34: 6
B35: ='04-22Master'!#REF! -> #REF! | E35: Same as permanant address | G35: Father | I35: 54 years | J35: 1 | K35: N/A
B39: 1.Certified that I have no family and should I acquire a family hereafter,the above nomination shall be deemed as cancelled.
B40: 2.Certified that my father/mother is/ are dependent upon me.
B41: 3.Strike out whichever is not applicable.
I43: Signature or the thumb impression of the employed person
F44: CERTIFCATE BY EMPLOYER
A45: Certified that the above declaration and nomination has been signed/thumb impressed before me by Shri/Smt/Kum | K45: ='04-22Master'!#REF! -> #REF!
A46: employed in my establishment after he/she has read the entry/entries have been read over to him/her by me and got confirmed by him/her.
F49: Signature or the employer or other authorized officer of the establiment and Designation
A50: Place | B50: Hyderabad | F50: ='04-22Master'!AJ5 -> Burgeon IT Services Pvt.Ltd.
A51: Date | B51: ='04-22Master'!#REF! -> #REF! | F51: ='04-22Master'!AJ6 -> Siri Mansion LIGB 436 Dr.A S Rao Nagar,Hyderabad
B53: FORM I
B54: NOMINATION AND DECLARATION FORM
B55: (Vide Rule 3 of Payment of wages Act Central & A.P Rules, 1936)
...

Sheet Form-2
K1: (FORM 2 REVISED)
B2: NOMINATION AND DECLARATION FORM FOR UNEXEMPTED/EXEMPTED ESTABLISHMENTS
B3: Declaration and Nomination Form under the Employees Provident Funds and Employees Pension Schemes
B4: (Paragraph 33 and 61(1) of the Employees Provident Fund Scheme 1952 and Paragraph 18 of the Employees Pension Scheme 1995)
B6: 1. Name of the person making nomination | H6: ='04-22Master'!#REF! -> #REF!
B7: 2. Father's/Husband name | H7: ='04-22Master'!#REF! -> #REF!
B8: 3. Date of Birth | H8: ='04-22Master'!#REF! -> #REF!
B9: 4. Sex | H9: ='04-22Master'!#REF! -> #REF!
B10: 5. Marital Status | H10: Un-Married
B11: 6.Address
B12: Permanent | H12: ='04-22Master'!#REF! -> #REF!
H13: ='04-22Master'!#REF! -> #REF!
H14: ='04-22Master'!#REF! -> #REF!
G15: PART-A(EPF)
B16: I hereby nominate the person(s)/cancel the nomination made by me previously and nominate the person(s) mentioned below to
B17: receive any amount due to me from the employer,in the event to my death.
B18: Name of the Nominee/nominees | E18: Address | G18: Nominee's relationship With the member | I18: Date of Birth | J18: Total amount of Share of accumulations | K18: If the nominee is minor,name,relationship and address of the guardian
B19: 1 | E19: 2 | G19: 3 | I19: 4 | J19: 5 | L19: 6
B20: ='04-22Master'!#REF! -> #REF! | E20: Same as Permanant Address | G20: Father | I20: 55 Years | J20: 1 | K20: N/A
B24: 1.Certified that I have no family and should I acquire a family hereafter,the above nomination shall be deemed as cancelled.
B25: 2.Certified that my father/mother is/ are dependent upon me.
B26: Strike out whichever is not applicable | J26: Signature/or thumb impression of the subscriber
G27: PART (EPS)
G28: Para 18
B29: I hereby furnish below particulars of the members of my family who would be eligible to receive Widow/Children Pension in the event of
B30: my premature death in service
B31: S.No | C31: Name & Address of the Family Member | I31: Age | J31: Relationship with the member
B32: 1 | E32: 2 | I32: 3 | K32: 4
B37: Certified that I have no family as defined in para 2 (vii) of the Employees's Family Pension Scheme 1995 and should I acquire a family hereafter
B38: I shall furnish Particulars there on in the above form.
B39: I hereby nominate the following person for receiving the monthly widow pension (admissible under para 16 2 (a) (1) & (ii) in the even of my death
B40: without leaving any eligible member for receiving pension.
B41: Name and Address of the nominee | G41: Date of Birth | I41: Relationship with member
B47: Date | C47: ='04-22Master'!#REF! -> #REF! | I47: Signature or thumb impression of the subscriber
F48: CERTIFCATE BY EMPLOYER
A49: Certified that the above declaration and nomination has been signed/thumb impressed before me by Shri/Smt/Kum | K49: ='04-22Master'!#REF! -> #REF!
A50: employed in my establishment after he/she has read the entry/entries have been read over to him/her by me and got confirmed by him/her.
F52: Signature or the employer or other authorized officer of the establiment and Designation
A53: Place | B53: Hyderabad | F53: ='04-22Master'!F5 -> Burgeon IT Services Pvt.Ltd.
A54: Date | B54: ='04-22Master'!#REF! -> #REF! | F54: ='04-22Master'!F6 -> Siri Mansion LIGB 436 Dr.A S Rao Nagar,Hyderabad
...

Sheet Form 11
I1: New Form No. 11 - Declaration Form
B2: (To be retained by t he employer for future reference)
D3: EMPLOYEES' PROVIDENT FUND ORGANIZATION | I3: Emp Code: | K3: ='04-22Master'!#REF! -> #REF!
C4: Employees' Provident Funds Scheme, 1952 (Paragraph 34 & 57) & | I4: Company | J4: ='04-22Master'!F5 -> Burgeon IT Services Pvt.Ltd.
C5: The Employees' Pension Scheme, 1995 (Paragraph 24) | I5: ='04-22Master'!F6 -> Siri Mansion LIGB 436 Dr.A S Rao Nagar,Hyderabad
A8: 1 | B8: Name of the Member | H8: ='04-22Master'!#REF! -> #REF!
A9: 2 | B9: Fathers' Name | F9: Husband's Name | H9: ='04-22Master'!#REF! -> #REF!
B10: (Please tick whichever is applicable)
A11: 3 | B11: Date of Birth (DD/MM/YYYY) | H11: ='04-22Master'!#REF! -> #REF!
A12: 4 | B12: Gender (Male/Female/Transgender) | H12: ='04-22Master'!#REF! -> #REF!
A13: 5 | B13: Marital Status(married / Unmarried / Widow/divorce) | H13: UNMARRIED
A14: 6 | B14: (a) | C14: Email Id
B15: (b) | C15: Mobile No.
A16: 7 | B16: Whether earlier a member of the Employees' Provident Fund Scheme, 1952 ? | H16: Yes | K16: No
A17: 8 | B17: Whether earlier a member of the Employees' Pension Scheme, 1995? | H17: Yes | K17: No
F18: Previous employment details [if Yes to 7 &/or 8 above]
A19: 9 | B19: a) | C19: Universal Account Number
B20: b) | C20: Previous PF Account Number
B21: C) | C21: Date of exit from previous employment (DD/MM/YYYY)
B22: d) | C22: Scheme Certificate No. (if issued)
B23: e) | C23: Pension Payment Order (PPO) No. (if issued)
A24: 10 | B24: a) | C24: International Worker | H24: Yes | K24: No
B25: b) | C25: If yes, state country of origin(India/Name of other country)
B26: C) | C26: Passport No.
B27: d) | C27: Validity of passport [(DD/MM/YYYY) to (DD/MM/YYYY)]
E28: KYC Details (attach self attested copies of following KYCs)
A29: 11 | B29: a) | C29: Bank Account No. & IFS Code
B30: b) | C30: AADHAR No.
B31: c) | C31: Permanent Account No. (PAN), if available
F32: UNDERTAKING
B33: 1) | C33: Certified that the particulars are true to the best of my knowledge.
B34: 2) | C34: I authorize EPFO to use my Aadhar for verification/authentication/eKYC purpose for service delivery.
B35: 3) | C35: Kindly transfer the funds and service details, if applicable from the previous PF account as declared above to the present P.F. Account (The Transfer would be possible only if the identified KYC details approved by previous employer has been verified by present employer
B36: 4) | C36: In case of changes in above details, the same will be intimated to employer at the earliest.
C37: Date : | D37: ='04-22Master'!#REF! -> #REF!
C38: Place: | D38: Hyderabad | J38: Signature of Member
F40: DECLARATION BY PRESENT EMPLOYER
A41: A) | B41: The member Mr./Ms./Mrs. | E41: ='04-22Master'!#REF! -> #REF! | H41: has joined on | J41: ='04-22Master'!#REF! -> #REF! | K41: and has been allotted PF Number
B42: ='04-22Master'!#REF! -> #REF!
A43: B) | B43: In case the person was earlier not a member of EPF Scheme, 1952 and EPS, 1995:
...

Sheet Form-F
A1: F O R M – F
A2: [See sub-Rule (1) of Rule 6] The Payment of Gratuity Rules, 1973:
A3: NOMINATION
A4: To
A5: ='04-22Master'!F5 -> Burgeon IT Services Pvt.Ltd.
A6: ='04-22Master'!F6 -> Siri Mansion LIGB 436 Dr.A S Rao Nagar,Hyderabad
A8: 1. I, Shri / Shrimati / Kumari | C8: ='04-22Master'!#REF! -> #REF!
A9: whose particulars are given in the statement below, hereby nominate the person(s) mentioned below to receive the gratuity payable after my death as also the gratuity standing to my credit in the event of my death before that amount has become payable, or having become payable has not been paid and direct that the said amount of gratuity shall be paid in proportion indicated against the name(s) of the nominee(s).
A11: 2. I hereby certify that the person(s) mentioned is a /are member(s) of my family within the meaning of clause (h) of Section 2 of the Payment of Gratuity Act, 1972.
A13: 3. I hereby declare that I have no family within the meaning of clause (h) of Section 2 of the said Act.
A15: 4. (a) My father/mother/parents is/are not dependent on me
A16: (b) My husband’s father/mother/parents is/are not dependent on my husband.
A18: 5. I have excluded my husband from my family by a notice dated the ……………. to the Controlling Authority in terms of the proviso to clause (h) of Section 2 of the said Act.
A20: 6. Nomination made herein invalidates my previous nomination.
A22: NOMINEE(S)
A23: Name in full with full address of nominee(s): | B23: Relationship with the empliyee | C23: Age of nominee: | D23: Proportion by which the gratuity will be shared:
A24: 1 | B24: 2 | C24: 3 | D24: 4
A25: ='04-22Master'!#REF! -> #REF! | B25: Father | C25: 54 Years | D25: 1
A29: STATEMENT
A31: 1. Name of employee in full: | C31: ='04-22Master'!#REF! -> #REF!
A32: 2. Sex: | C32: ='04-22Master'!#REF! -> #REF!
A33: 3. Religion: | C33: Muslim
A34: 4. Whether unmarried/married/widow/widower: | C34: Un married
A35: 5. Department/Branch/Section where employed: | C35: ='04-22Master'!#REF! -> #REF!
A36: 6. Post held with Ticket No. or Serial No. if any: | C36: ='04-22Master'!#REF! -> #REF!
A37: 7. Date of appointment: | C37: ='04-22Master'!#REF! -> #REF!
A38: 8. Permanent address:
C39: ='04-22Master'!#REF! -> #REF!
C40: ='04-22Master'!#REF! -> #REF!
C41: ='04-22Master'!#REF! -> #REF!
A42: Place: | B42: Hyderabad
A43: Date: | B43: ='04-22Master'!#REF! -> #REF! | C43: Signature/Thumb impression of the employee
A45: Declaration by witnesses:
A46: Nomination signed/thumb impressed before me:
A48: Name in full and full address of witnesses: | C48: Signature of witnesses:
A49: 1 | C49: 1
A50: 2 | C50: 2
C51: Certificate by the Employer
A52: Certified that the particulars of the above nomination have been verified and recorded in t his establishment
A53: Employer's reference No, if any
...

Sheet Sheet1
