Workbook

Sheet PUNJAB APRIL 22-WMn Reg
A1: FORM - XIII REGISTER OF WORKMEN EMPLOYED BY CONTRACTOR
E2: (Vide Rule 75 of Contract Labour (Regulation and Abolition) Central/Punjab Rules 1973)
A3: Name and address of Contractor: | F3: ='PUNJAB 04-22Master'!F5 -> Burgeon IT Services Pvt.Ltd. | L3: Name and address of Establishemnt in/ under which conctract is carried on: | O3: ='PUNJAB 04-22Master'!AO5 -> Burgeon IT Services Pvt.Ltd.
F4: ='PUNJAB 04-22Master'!F6 -> Siri Mansion LIGB 436 Dr.A S Rao Nagar,Hyderabad | O4: ='PUNJAB 04-22Master'!AO6 -> Siri Mansion LIGB 436 Dr.A S Rao Nagar,Hyderabad
A5: Nature and location of work: | F5: ='PUNJAB 04-22Master'!F8 -> IT SUPPORTIVE SERVICES&Chandigarh
L7: Name and address of Principal Employer: | O7: ='PUNJAB 04-22Master'!AO10 -> INFOSYS LTD.IL
O8: IL Chandigarh SEZ Unit - I Rajiv Gandhi Chandigarh tech Park, Kishangarh, Chandigarh-160101
A11: Serial No. in the Register of Workmen | B11: Name of Workman | C11: Age | D11: Sex | E11: Father's /Husband Name | F11: Designation / Nature of Work Done | G11: Permanent Address | J11: Local Address | N11: Date of Commencement of Employment | O11: Signature or thumb impression of Workman | P11: Date of termination of Employment | Q11: Reasons for termination | R11: Remarks
A13: 1 | B13: Dheeraj Miglani | C13: 29990 | D13: M | E13: Arjun Miglani | F13: Data Platform Lead | G13: 90B,NEW R-BLOCK, DILSHAD GARDEN,NEW DELHI-110095 | J13: 90B,NEW R-BLOCK, DILSHAD GARDEN,NEW DELHI-110095 | N13: 43885 | P13: Resignation | Q13: Resigned
A14: 2 | B14: Gopi reddy chirra | C14: 34495 | D14: M | E14: Madhava Reddy | F14: Technical Consultant | G14: 1-322,Erraguntlapadu,Guntur,Andhra pradesh 522529 | J14: 1-322,Erraguntlapadu,Guntur,Andhra pradesh 522529 | N14: 44454 | P14: Active | Q14: Active
A44: ='PUNJAB 04-22Master'!#REF! -> #REF! | B44: ='PUNJAB 04-22Master'!#REF! -> #REF! | C44: ='PUNJAB 04-22Master'!#REF! -> #REF! | D44: ='PUNJAB 04-22Master'!#REF! -> #REF! | E44: ='PUNJAB 04-22Master'!#REF! -> #REF! | F44: ='PUNJAB 04-22Master'!#REF! -> #REF! | G44: ='PUNJAB 04-22Master'!#REF! -> #REF! | H44: ='PUNJAB 04-22Master'!#REF! -> #REF! | ... Q44: ='PUNJAB 04-22Master'!#REF! -> #REF!
A45: ='PUNJAB 04-22Master'!#REF! -> #REF! | B45: ='PUNJAB 04-22Master'!#REF! -> #REF! | C45: ='PUNJAB 04-22Master'!#REF! -> #REF! | D45: ='PUNJAB 04-22Master'!#REF! -> #REF! | E45: ='PUNJAB 04-22Master'!#REF! -> #REF! | F45: ='PUNJAB 04-22Master'!#REF! -> #REF! | G45: ='PUNJAB 04-22Master'!#REF! -> #REF! | H45: ='PUNJAB 04-22Master'!#REF! -> #REF! | ... Q45: ='PUNJAB 04-22Master'!#REF! -> #REF!
A46: ='PUNJAB 04-22Master'!#REF! -> #REF! | B46: ='PUNJAB 04-22Master'!#REF! -> #REF! | C46: ='PUNJAB 04-22Master'!#REF! -> #REF! | D46: ='PUNJAB 04-22Master'!#REF! -> #REF! | E46: ='PUNJAB 04-22Master'!#REF! -> #REF! | F46: ='PUNJAB 04-22Master'!#REF! -> #REF! | G46: ='PUNJAB 04-22Master'!#REF! -> #REF! | H46: ='PUNJAB 04-22Master'!#REF! -> #REF! | ... Q46: ='PUNJAB 04-22Master'!#REF! -> #REF!
A47: ='PUNJAB 04-22Master'!#REF! -> #REF! | B47: ='PUNJAB 04-22Master'!#REF! -> #REF! | C47: ='PUNJAB 04-22Master'!#REF! -> #REF! | D47: ='PUNJAB 04-22Master'!#REF! -> #REF! | E47: ='PUNJAB 04-22Master'!#REF! -> #REF! | F47: ='PUNJAB 04-22Master'!#REF! -> #REF! | G47: ='PUNJAB 04-22Master'!#REF! -> #REF! | H47: ='PUNJAB 04-22Master'!#REF! -> #REF! | ... Q47: ='PUNJAB 04-22Master'!#REF! -> #REF!
A48: ='PUNJAB 04-22Master'!#REF! -> #REF! | B48: ='PUNJAB 04-22Master'!#REF! -> #REF! | C48: ='PUNJAB 04-22Master'!#REF! -> #REF! | D48: ='PUNJAB 04-22Master'!#REF! -> #REF! | E48: ='PUNJAB 04-22Master'!#REF! -> #REF! | F48: ='PUNJAB 04-22Master'!#REF! -> #REF! | G48: ='PUNJAB 04-22Master'!#REF! -> #REF! | H48: ='PUNJAB 04-22Master'!#REF! -> #REF! | ... Q48: ='PUNJAB 04-22Master'!#REF! -> #REF!
A49: ='PUNJAB 04-22Master'!#REF! -> #REF! | B49: ='PUNJAB 04-22Master'!#REF! -> #REF! | C49: ='PUNJAB 04-22Master'!#REF! -> #REF! | D49: ='PUNJAB 04-22Master'!#REF! -> #REF! | E49: ='PUNJAB 04-22Master'!#REF! -> #REF! | F49: ='PUNJAB 04-22Master'!#REF! -> #REF! | G49: ='PUNJAB 04-22Master'!#REF! -> #REF! | H49: ='PUNJAB 04-22Master'!#REF! -> #REF! | ... Q49: ='PUNJAB 04-22Master'!#REF! -> #REF!

Sheet PUNJAB 04-22Master
A3: FORM - XIII REGISTER OF WORKMEN EMPLOYED BY CONTRACTOR
B4: (Vide Rule 75 of Contract Labour (Regulation and Abolition) Central/Telangana/A.P. Rules 1971)
A5: Name and address of Contractor: | F5: Burgeon IT Services Pvt.Ltd. | AA5: Name and address of Establishemnt in/ under which contract is carried on: | AO5: Burgeon IT Services Pvt.Ltd.
F6: Siri Mansion LIGB 436 Dr.A S Rao Nagar,Hyderabad | AO6: Siri Mansion LIGB 436 Dr.A S Rao Nagar,Hyderabad
A8: Nature and location of work: | F8: IT SUPPORTIVE SERVICES&Chandigarh
A10: Wage period: Monthly | D10: 44652 | AJ10: Name and address of Principal Employer: | AO10: INFOSYS LTD.IL
AO11: No.45&46,3rd Cross,Electronic City,BANGALORE,KARNATAKA
AO12: IL Chandigarh SEZ Unit - I Rajiv Gandhi Chandigarh tech Park, Kishangarh, Chandigarh-160101
A14: Serial No. in the Register of Workmen | B14: Name of Workman | C14: Age | D14: Sex | E14: Father's /Husband Name | F14: Designation / Nature of Work Done | G14: Permanent Address | J14: Local Address | N14: Date of Commencement of Employment | O14: Signature or thumb impression of Workman | P14: Date of termination of Employment | Q14: Reasons for termination | R14: Remarks | S14: EPF Number | T14: ESI Number | U14: Name of Workman | V14: No.of Days worked | W14: Unit of work done | X14: Monthly rate of wages/ piece rate | Y14: Basic wages | Z14: Dearness Allowances | AA14: Over time | AB14: Other cash payments (Nature of payments to be indicated) | AC14: HRA | AD14: CONVEYANCE | AE14: MEDICAL ALLOWANCES | AF14: SPECIAL ALLOWNANCES | AG14: Total | AH14: BONUS | AI14: GRATUITY | AJ14: LTA/L.E | AK14: ARREAR AMOUNT | AL14: TOTAL AMOUNT | AM14: Deductions, if any, (Indicate nature) | AS14: Net Amount paid | AT14: Time and Date of Payment | AU14: Place of Payment | AV14: Signature/Thumb Impression of workman | AW14: Initial of Contractor or his representative
AM15: ESI | AN15: PF | AO15: PT | AP15: TDS | AQ15: INSURANCE | AR15: Total Deductions
A16: ='PUNJAB APRIL 22-WMn Reg'!A14 -> 2 | B16: ='PUNJAB APRIL 22-WMn Reg'!B14 -> Gopi reddy chirra | C16: ='PUNJAB APRIL 22-WMn Reg'!C14 -> 34495 | D16: ='PUNJAB APRIL 22-WMn Reg'!D14 -> M | E16: ='PUNJAB APRIL 22-WMn Reg'!E14 -> Madhava Reddy | F16: ='PUNJAB APRIL 22-WMn Reg'!F14 -> Technical Consultant | G16: ='PUNJAB APRIL 22-WMn Reg'!G14 -> 1-322,Erraguntlapadu,Guntur,Andhra pradesh 522529 | H16: ='PUNJAB APRIL 22-WMn Reg'!H14 -> 0 | ... M16: ='PUNJAB APRIL 22-WMn Reg'!M14 -> 0 | N16: 44454 | S16: 101739082876 | T16: N/A | U16: =B16 -> Gopi reddy chirra | V16: 30 | W16: 0 | X16: 58032 | Y16: 34819 | Z16: 0 | AA16: 0 | AB16: =AF16+AE16+AD16+AC16 -> 23325.68 | AC16: 13927.68 | AD16: 2083 | AE16: 2083 | AF16: 5232 | AG16: =Y16+Z16+AA16+AC16+AD16+AE16+AF16 -> 58144.68 | AH16: 1554.609 | AI16: 1674.8035 | AJ16: 2901.6 | AK16: 0 | AL16: =AG16+AH16+AI16+AJ16+AK16 -> 64275.693 | AM16: 0 | AN16: 1800 | AO16: 200 | AP16: 0 | AQ16: 224 | AR16: =SUM(AM16:AQ16) -> 2224 | AS16: =AL16-AR16 -> 62051.693 | AT16: 44686 | AU16: ICICI Bank | AV16: A/C No.285201500195

Sheet Eq reM 
A1: Form D
A2: (See rule 6)
A4: Register to be maintained by the employer under rule 6 of the Equal Remuneration Rules, 1976
D6: ='PUNJAB 04-22Master'!D10 -> 44652
A8: Name and address of Contractor : | D8: ='PUNJAB 04-22Master'!F5 -> Burgeon IT Services Pvt.Ltd.
D9: ='PUNJAB 04-22Master'!F6 -> Siri Mansion LIGB 436 Dr.A S Rao Nagar,Hyderabad
A10: Name and address of establishment in/under which contract is carried on : | F10: ='PUNJAB 04-22Master'!AO5 -> Burgeon IT Services Pvt.Ltd.
F11: ='PUNJAB 04-22Master'!AO6 -> Siri Mansion LIGB 436 Dr.A S Rao Nagar,Hyderabad
A12: Name and address of Principal Employer : | F12: =[1]Master!AO10 -> INFOSYS LIMITED
F13: ='PUNJAB 04-22Master'!AO12 -> IL Chandigarh SEZ Unit - I Rajiv Gandhi Chandigarh tech Park, Kishangarh, Chandigarh-160101
A14: Total number of men workers employed | C14: =D21 -> 1
A16: Total number of women workers employed | C16: =C219 -> 0
C18: Components of remuneration
A19: Category of workers | B19: Brief Description of work | C19: No of women employed | D19: No. of men employed | E19: Rate or remuneration paid | F19: Basic wage & Dearness Allowance | G19: House Rent allowance | H19: Other allowances | I19: Cash value of concessional supply of essential commodities | J19: Name of the Client | K19: Primary Work Place/ Location
A20: =+'PUNJAB 04-22Master'!F16 -> Technical Consultant | B20: PROVIDING IT SUPPORTIVE | C20: 0 | D20: 1 | E20: ='PUNJAB 04-22Master'!AL16 -> 64275.693 | F20: ='PUNJAB 04-22Master'!Y16 -> 34819 | G20: ='PUNJAB 04-22Master'!AC16 -> 13927.68 | H20: =E20-(F20+G20) -> 15529.013 | I20: 0 | J20: Infosys Limited | K20: Chandigarh
C21: =SUM(C33:C33) -> 0 | D21: =SUM(D20:D20) -> 1
E25: Signature of the Contractor with Seal
A33: =+'PUNJAB 04-22Master'!#REF! -> #REF! | B33: PROVIDING IT SUPPORTIVE | C33: 0 | D33: 0 | E33: ='PUNJAB 04-22Master'!#REF! -> #REF! | F33: 87096.714 | G33: 35009.333 | H33: =E33-(F33+G33) -> #REF! | I33: 0 | J33: Infosys Limited | K33: Chandigarh

Sheet 04-22 Muster Roll
A3: FORM - XVI MUSTER ROLL [Vide Rule 78 (1) (a) (i) of Contract Labour (Reg. & Abolition) Central & Punjab Rules 1973]
A5: Name and address of Contractor: | D5: ='PUNJAB 04-22Master'!F5 -> Burgeon IT Services Pvt.Ltd. | J5: Name and address of Establishemnt in/ under which contract is carried on: | X5: ='PUNJAB 04-22Master'!AO5 -> Burgeon IT Services Pvt.Ltd.
D6: ='PUNJAB 04-22Master'!F6 -> Siri Mansion LIGB 436 Dr.A S Rao Nagar,Hyderabad | X6: ='PUNJAB 04-22Master'!AO6 -> Siri Mansion LIGB 436 Dr.A S Rao Nagar,Hyderabad
A7: Nature and location of work: | D7: ='PUNJAB 04-22Master'!F8 -> IT SUPPORTIVE SERVICES&Chandigarh
A9: Wage period: Monthly | D9: ='PUNJAB 04-22Master'!D10 -> 44652 | M9: Name and address of Principal Employer: | Z9: ='PUNJAB 04-22Master'!AO10 -> INFOSYS LTD.IL
Z10: ='PUNJAB APRIL 22-WMn Reg'!O8 -> IL Chandigarh SEZ Unit - I Rajiv Gandhi Chandigarh tech Park, Kishangarh, Chandigarh-160101
A13: S.No | B13: Name of Workman | C13: Father's/ Husband's Name | D13: Sex | AI13: Remarks
E14: 1 | F14: 2 | G14: 3 | H14: 4 | I14: 5 | J14: 6 | K14: 7 | L14: 8 | M14: 9 | N14: 10 | O14: 11 | P14: 12 | Q14: 13 | R14: 14 | S14: 15 | T14: 16 | U14: 17 | V14: 18 | W14: 19 | X14: 20 | Y14: 21 | Z14: 22 | AA14: 23 | AB14: 24 | AC14: 25 | AD14: 26 | AE14: 27 | AF14: 28 | AG14: 29 | AH14: 30
A15: 1 | B15: ='PUNJAB 04-22Master'!U16 -> Gopi reddy chirra | C15: ='PUNJAB 04-22Master'!E16 -> Madhava Reddy | D15: ='PUNJAB 04-22Master'!D16 -> M | E15: P | F15: WO | G15: WO | H15: P | I15: P | J15: P | K15: P | L15: P | M15: WO | N15: WO | O15: P | P15: P | Q15: P | R15: P | S15: H | T15: WO | U15: WO | V15: EL | W15: P | X15: P | Y15: P | Z15: P | AA15: WO | AB15: WO | AC15: P | AD15: P | AE15: P | AF15: P | AG15: P | AH15: WO | AI15: ='PUNJAB 04-22Master'!V16 -> 30
J19: Signature of the Contractor with Seal

Sheet Leave Reg
B4: FORM XV- REGISTER OF LEAVE
B6: (As per Shops and Establishment Punjab rules, 1954)
B7: Name of the Establishment: | E7: ='PUNJAB 04-22Master'!F5 -> Burgeon IT Services Pvt.Ltd. | I7: Name of the Employee:
C8: ='PUNJAB 04-22Master'!F6 -> Siri Mansion LIGB 436 Dr.A S Rao Nagar,Hyderabad | I8: ='PUNJAB 04-22Master'!B16 -> Gopi reddy chirra
B10: Registration Number:
I11: Father’s / Husband’s Name:
I12: ='PUNJAB 04-22Master'!E16 -> Madhava Reddy
I13: Date of appointment : | L13: ='PUNJAB 04-22Master'!N16 -> 44454
B14: Date of Application | C14: Applied From | D14: To | E14: No. of Days | F14: No. of Days to which the employee is entitled | G14: Leave granted from | H14: TO | I14: No. of days | J14: Balance | K14: If refused in part or full From | L14: TO | M14: No. of Days | N14: REASONS | O14: Signature of the Employee | P14: Signature of the Employer
B16: 1 | C16: 2 | D16: 3 | E16: 4 | F16: 5 | G16: 6 | H16: 7 | I16: 8 | J16: 9 | K16: 10 | L16: 11 | P16: 12
B18: JAN'22 | C18: 44564 | D18: 44564 | E18: 1 | G18: 44564 | H18: 44564 | I18: 2 | J18: 2
B19: FEB'22 | C19: 44596 | D19: 44596 | E19: 1 | G19: 44596 | H19: 44596 | I19: 2 | J19: =J18+1.5-E19 -> 2.5
B20: MAR'22 | C20: 44634 | D20: 44634 | E20: 1 | G20: 44634 | H20: 44634 | I20: 1 | J20: =J19+1.5-E20 -> 3
B21: ARIL'22 | C21: 44669 | D21: 44669 | E21: 1 | G21: 44669 | H21: 44669 | I21: 1 | J21: =J20+1.5-E21 -> 3.5
J42: Signature of the Contractor with Seal

Sheet 04-22wages Reg
A3: FORM - XVII REGISTER OF WAGES [Vide Rule 78 (1) (a) (i) of Contract Labour (Reg. & Abolition) Central & Punjab Rules 1973]
A5: Name and address of Contractor: | D5: ='PUNJAB 04-22Master'!F5 -> Burgeon IT Services Pvt.Ltd. | U5: Name and address of Establishemnt in/ under which contract is carried on: | AA5: ='PUNJAB 04-22Master'!AO5 -> Burgeon IT Services Pvt.Ltd.
D6: ='PUNJAB 04-22Master'!F6 -> Siri Mansion LIGB 436 Dr.A S Rao Nagar,Hyderabad | AA6: ='PUNJAB 04-22Master'!AO6 -> Siri Mansion LIGB 436 Dr.A S Rao Nagar,Hyderabad
A7: Nature and location of work: | D7: ='PUNJAB 04-22Master'!F8 -> IT SUPPORTIVE SERVICES&Chandigarh
A9: Wage period: Monthly | D9: ='PUNJAB 04-22Master'!D10 -> 44652 | V9: Name and address of Principal Employer: | AA9: ='PUNJAB 04-22Master'!AO10 -> INFOSYS LTD.IL
AA10: ='PUNJAB APRIL 22-WMn Reg'!O8 -> IL Chandigarh SEZ Unit - I Rajiv Gandhi Chandigarh tech Park, Kishangarh, Chandigarh-160101
A13: S.No | B13: Name of Workman | C13: Serial No. in the Register of Workmen | D13: Designation / Nature of Work Done | E13: No.of Days worked | F13: Unit of work done | G13: Monthly rate of wages/ piece rate | H13: Basic wages | I13: Dearness Allowances | J13: Over time | K13: Other cash payments (Nature of payments to be indicated) | L13: HRA | M13: CONVEYANCE | N13: MEDICAL ALLOWANCES | O13: SPECIAL ALLOWNANCES | P13: Total | Q13: BONUS | R13: GRATUITY | S13: LTA/L.E | T13: ARREAR AMOUNT | U13: TOTAL AMOUNT | V13: Deductions, if any, (Indicate nature) | AB13: Net Amount paid | AC13: Time and Date of Payment | AD13: Place of Payment | AE13: Signature/Thumb Impression of workman | AF13: Initial of Contractor or his representative
V14: ESI | W14: PF | X14: PT | Y14: TDS | Z14: MED | AA14: Total Deductions
A15: 1 | B15: ='PUNJAB 04-22Master'!U16 -> Gopi reddy chirra | C15: ='PUNJAB 04-22Master'!A16 -> 2 | D15: ='PUNJAB 04-22Master'!F16 -> Technical Consultant | E15: ='PUNJAB 04-22Master'!V16 -> 30 | F15: ='PUNJAB 04-22Master'!W16 -> 0 | G15: ='PUNJAB 04-22Master'!X16 -> 58032 | H15: ='PUNJAB 04-22Master'!Y16 -> 34819 | I15: ='PUNJAB 04-22Master'!Z16 -> 0 | J15: ='PUNJAB 04-22Master'!AA16 -> 0 | K15: =L15+M15+N15+O15 -> 23325.68 | L15: ='PUNJAB 04-22Master'!AC16 -> 13927.68 | M15: ='PUNJAB 04-22Master'!AD16 -> 2083 | N15: ='PUNJAB 04-22Master'!AE16 -> 2083 | O15: ='PUNJAB 04-22Master'!AF16 -> 5232 | P15: =H15+K15 -> 58144.68 | Q15: ='PUNJAB 04-22Master'!AH16 -> 1554.609 | R15: ='PUNJAB 04-22Master'!AI16 -> 1674.8035 | S15: ='PUNJAB 04-22Master'!AJ16 -> 2901.6 | T15: ='PUNJAB 04-22Master'!AK16 -> 0 | U15: =P15+Q15+R15+S15+T15 -> 64275.693 | V15: ='PUNJAB 04-22Master'!AM16 -> 0 | W15: ='PUNJAB 04-22Master'!AN16 -> 1800 | X15: ='PUNJAB 04-22Master'!AO16 -> 200 | Y15: ='PUNJAB 04-22Master'!AP16 -> 0 | Z15: ='PUNJAB 04-22Master'!AQ16 -> 224 | AA15: =V15+W15+X15+Y15+Z15 -> 2224 | AB15: ='PUNJAB 04-22Master'!AS16 -> 62051.693 | AC15: ='PUNJAB 04-22Master'!AT16 -> 44686 | AD15: ='PUNJAB 04-22Master'!AU16 -> ICICI Bank | AE15: ='PUNJAB 04-22Master'!AV16 -> A/C No.285201500195
H25: =SUM(H15:H24) -> 34819 | I25: =SUM(I15:I24) -> 0 | J25: =SUM(J15:J24) -> 0 | K25: =SUM(K15:K24) -> 23325.68 | L25: =SUM(L15:L24) -> 13927.68 | M25: =SUM(M15:M24) -> 2083 | N25: =SUM(N15:N24) -> 2083 | O25: =SUM(O15:O24) -> 5232 | ... AB25: =SUM(AB15:AB24) -> 62051.693
J26: Signature of the Contractor with Seal

Sheet Emp  Cards
B1: FORM XIV
B2: EMPLOYMENT CUM WAGE CARD
B3: (Vide Rule 76 of Contract Labour (R&A) Punjab Rules, 1973)
B4: Name and Address of the Contractor | H4: Name and Address of the Establishment in/under which Contract is carried on:
B7: ='PUNJAB 04-22Master'!F5 -> Burgeon IT Services Pvt.Ltd. | H7: ='PUNJAB 04-22Master'!AO10 -> INFOSYS LTD.IL
B9: ='PUNJAB 04-22Master'!F6 -> Siri Mansion LIGB 436 Dr.A S Rao Nagar,Hyderabad | H9: ='PUNJAB 04-22Master'!AO11 -> No.45&46,3rd Cross,Electronic City,BANGALORE,KARNATAKA
B12: Nature of work and location of work: | H12: Name and address of Principal Employer:
H15: ='PUNJAB 04-22Master'!AO10 -> INFOSYS LTD.IL
B16: ='PUNJAB 04-22Master'!F8 -> IT SUPPORTIVE SERVICES&Chandigarh
H17: ='PUNJAB APRIL 22-WMn Reg'!O8 -> IL Chandigarh SEZ Unit - I Rajiv Gandhi Chandigarh tech Park, Kishangarh, Chandigarh-160101
B19: 1. Name of the Workman and address | H19: ='PUNJAB 04-22Master'!B16 -> Gopi reddy chirra
H20: ='PUNJAB 04-22Master'!G16 -> 1-322,Erraguntlapadu,Guntur,Andhra pradesh 522529
B21: 2. S.No. in the Register of Workmen Employed | H21: ='PUNJAB 04-22Master'!A16 -> 2
B22: 3. Nature of Employment /Designation | H22: ='PUNJAB 04-22Master'!F16 -> Technical Consultant
B23: 4. Date of entry into service | H23: ='PUNJAB 04-22Master'!N16 -> 44454
B24: 5. ESI No. | H24: ='PUNJAB 04-22Master'!T67 -> 0
B25: 6.PF No. | H25: ='PUNJAB 04-22Master'!S16 -> 101739082876
B26: 7. Wage rate (With particulars of unit in case of piece - work) | H26: ='PUNJAB 04-22Master'!X16 -> 58032
B27: 8. Wage period | H27: ='PUNJAB 04-22Master'!D10 -> 44652
B28: 9. Tenure of Employment | H28: AS PER CONTRACT
B29: 10.No. of days worked in a month | J29: ='PUNJAB 04-22Master'!V16 -> 30
B30: 11. No. of units worked in case of piece rate workers | J30: N/A
B31: 12. Rate of daily wages / piece rate | J31: 0
B32: 13. Amount of overtime wages | J32: 0
B33: 14. Gross wages payable | J33: ='PUNJAB 04-22Master'!AL16 -> 64275.693 | L33: MED
B34: 15. Deductions, if any, | D34: PF | E34: ='PUNJAB 04-22Master'!AN16 -> 1800 | F34: ESI | G34: ='PUNJAB 04-22Master'!AM16 -> 0 | H34: PT | I34: ='PUNJAB 04-22Master'!AO16 -> 200 | J34: TDS | K34: ='PUNJAB 04-22Master'!AP16 -> 0 | L34: ='PUNJAB 04-22Master'!AQ16 -> 224
B35: 16. Net amount of wages paid | J35: =J33-(E34+G34+I34+K34+L34) -> 62051.693
B36: Signature of the Representative
B37: of Contractor

Sheet wage sllips
A1: Form XIX - WAGE SLIP | K1: Form XIX - WAGE SLIP
A2: [Vide rule 78 (1) (b) of the Contract Labour (Regulation and Abolition) Central and Punjab Rules, 1973] | K2: =A2 -> [Vide rule 78 (1) (b) of the Contract Labour (Regulation and Abolition) Central and Punjab Rules, 1973]
A4: Name and address of Contractor | D4: ='PUNJAB 04-22Master'!F5 -> Burgeon IT Services Pvt.Ltd. | K4: Name and address of Contractor | N4: =D4 -> Burgeon IT Services Pvt.Ltd.
B5: ='PUNJAB 04-22Master'!F6 -> Siri Mansion LIGB 436 Dr.A S Rao Nagar,Hyderabad | L5: =B5 -> Siri Mansion LIGB 436 Dr.A S Rao Nagar,Hyderabad
B6: ='PUNJAB 04-22Master'!F7 -> 0 | L6: =B6 -> 0
A7: Name and Father's / Husband's name of the workman | K7: Name and Father's / Husband's name of the workman
E8: ='PUNJAB 04-22Master'!B16 -> Gopi reddy chirra | H8: ='PUNJAB 04-22Master'!E16 -> Madhava Reddy | O8: =E8 -> Gopi reddy chirra | R8: =H8 -> Madhava Reddy
A10: Nature and location of work | E10: ='PUNJAB 04-22Master'!F8 -> IT SUPPORTIVE SERVICES&Chandigarh | K10: Nature and location of work | O10: =E10 -> IT SUPPORTIVE SERVICES&Chandigarh
A12: For the Week / Fortnight / Month ending | E12: ='PUNJAB 04-22Master'!D10 -> 44652 | K12: For the Week / Fortnight / Month ending | O12: =E12 -> 44652
A14: 1 | B14: No. of days worked | E14: ='PUNJAB 04-22Master'!V16 -> 30 | K14: 1 | L14: No. of days worked | O14: =E14 -> 30
A16: 2 | B16: No. of units worked in case of piece rate workers : | K16: 2 | L16: No. of units worked in case of piece rate workers :
E17: N/A | O17: N/A
A19: 3 | B19: Rate of daily wages / piece rate | E19: N/A | K19: 3 | L19: Rate of daily wages / piece rate | O19: =E19 -> N/A
A21: 4 | B21: Amount of overtime wages | E21: Nil | K21: 4 | L21: Amount of overtime wages | O21: Nil
A23: 5 | B23: Gross wages payble | E23: ='PUNJAB 04-22Master'!AL16 -> 64275.693 | K23: 5 | L23: Gross wages payble | O23: =E23 -> 64275.693
D24: EPF | E24: ESI | F24: PT | G24: TDS | H24: MEDICAL | I24: TOTAL | N24: EPF | O24: ESI | P24: PT | Q24: TDS | R24: MEDICAL | S24: TOTAL
A25: 6 | B25: Deductions, if any | D25: ='PUNJAB 04-22Master'!AN16 -> 1800 | E25: ='PUNJAB 04-22Master'!AM16 -> 0 | F25: ='PUNJAB 04-22Master'!AO16 -> 200 | G25: ='PUNJAB 04-22Master'!AP16 -> 0 | H25: ='PUNJAB 04-22Master'!AQ16 -> 224 | I25: =D25+E25+F25+G25+H25 -> 2224 | K25: 6 | L25: Deductions, if any | N25: =D25 -> 1800 | O25: =E25 -> 0 | P25: =F25 -> 200 | Q25: =G25 -> 0 | R25: =H25 -> 224 | S25: =I25 -> 2224
A27: 7 | B27: Net amount of wages paid | E27: =E23-I25 -> 62051.693 | K27: 7 | L27: Net amount of wages paid | O27: =E27 -> 62051.693
F31: Initial of the Contractor or his representative | P31: Initial of the Contractor or his representative

Sheet Ser  Cer .
B4: FORM XV
B5: [Vide rule 77 of Contract Labour (Regul. & Abolition) Central &Punjab Rules, 1973]
B7: SERVICE CERTIFICATE
B9: Name and address of Contractor : | G9: Name and address of establishment in / under which contract is caried on :
B11: ='PUNJAB 04-22Master'!F5 -> Burgeon IT Services Pvt.Ltd.
B13: ='PUNJAB 04-22Master'!F6 -> Siri Mansion LIGB 436 Dr.A S Rao Nagar,Hyderabad
B17: Nature and Location of work: | G17: Name and address of Principal Employer :
G19: ='PUNJAB 04-22Master'!AO10 -> INFOSYS LTD.IL
B21: ='PUNJAB 04-22Master'!F8 -> IT SUPPORTIVE SERVICES&Chandigarh | G21: ='PUNJAB 04-22Master'!AO11 -> No.45&46,3rd Cross,Electronic City,BANGALORE,KARNATAKA
B26: Name and address of the workman : | F26: ='PUNJAB 04-22Master'!B19 -> 0
G27: ='PUNJAB 04-22Master'!G19 -> 0
B31: Age or date of Birth : | F31: =+'PUNJAB 04-22Master'!C19 -> 0
B33: Identification Marks :
B35: Father's / Husband's Name : | F35: ='PUNJAB 04-22Master'!E19 -> 0
B38: Sl.No. | C38: Total period for which employed | E38: Nature of work done | G38: Rate of wage ( with particulars of units in case of piece work) | J38: Remarks
C40: From | D40: To
B41: 1 | C41: 2 | D41: 3 | E41: 4 | G41: 5 | J41: 6
B42: ='PUNJAB 04-22Master'!A19 -> 0 | C42: ='PUNJAB 04-22Master'!N19 -> 0 | D42: ='PUNJAB 04-22Master'!P19 -> 0 | E42: ='PUNJAB 04-22Master'!F19 -> 0 | G42: ='PUNJAB 04-22Master'!X19 -> 0 | J42: ='PUNJAB 04-22Master'!Q19 -> 0
H56: Signature of the Employer with Seal

Sheet Deductions
A1: FORM XX- REGISTER OF DEDUCTIONS FOR DAMAGE OR LOSS
A3: (Vide Rule 78(1) (a) (ii) of Contract Labour (Regulation and Abolition) Central /Punjab Rules 1973)
A4: Name and address of Contractor: | D4: ='PUNJAB 04-22Master'!F5 -> Burgeon IT Services Pvt.Ltd. | E4: Name and address of the establishment in / under which contract is carried on:
B5: ='PUNJAB 04-22Master'!F6 -> Siri Mansion LIGB 436 Dr.A S Rao Nagar,Hyderabad
B6: ='PUNJAB 04-22Master'!F7 -> 0
A7: Nature and Location of Work: | D7: ='PUNJAB 04-22Master'!F8 -> IT SUPPORTIVE SERVICES&Chandigarh | E7: Name and address of principal employer:
E8: ='PUNJAB 04-22Master'!AO10 -> INFOSYS LTD.IL
E9: ='PUNJAB APRIL 22-WMn Reg'!O8 -> IL Chandigarh SEZ Unit - I Rajiv Gandhi Chandigarh tech Park, Kishangarh, Chandigarh-160101
A11: S.No | B11: Name of workman | C11: Father's / Husband's Name | D11: Designation / Nature of employment | E11: Particulars of damage or loss | F11: Date of Damage or loss | G11: Whether workman showed cause against deduction | H11: Name of person in whose presence employee's explanation was heard | I11: Amount of deduction impossed | J11: Date of recovery | M11: Remarks
J12: No.of Instalments | K12: First Instalment | L12: Last instalment
A13: 1 | B13: 2 | C13: 3 | D13: 4 | E13: 5 | F13: 6 | G13: 7 | H13: 8 | I13: 9 | J13: 10 | K13: 11 | L13: 12 | M13: 13
B16: NO EMPLOYEE WAS IMPOSED DEDUCTIONS FOR DAMAGE OR LOSS FOR THE MONTH OF | H16: ='PUNJAB 04-22Master'!D10 -> 44652
F37: Signature of the Contractor with Seal

Sheet Fines
A1: FORM XXI- REGISTER OF FINES
A3: (Vide Rule 78(1) (a) (ii) of Contract Labour (Regulation and Abolition) Central /Punjab Rules 1973)
A4: Name and address of Contractor: | D4: ='PUNJAB 04-22Master'!F5 -> Burgeon IT Services Pvt.Ltd. | E4: Name and address of the establishment in / under which contract is carried on:
B5: ='PUNJAB 04-22Master'!F6 -> Siri Mansion LIGB 436 Dr.A S Rao Nagar,Hyderabad | E5: ='PUNJAB 04-22Master'!AO5 -> Burgeon IT Services Pvt.Ltd.
B6: ='PUNJAB 04-22Master'!F7 -> 0 | E6: ='PUNJAB 04-22Master'!AO6 -> Siri Mansion LIGB 436 Dr.A S Rao Nagar,Hyderabad
A7: Nature and Location of Work: | D7: ='PUNJAB 04-22Master'!F8 -> IT SUPPORTIVE SERVICES&Chandigarh | E7: Name and address of principal employer:
E8: ='PUNJAB 04-22Master'!AO10 -> INFOSYS LTD.IL
E9: ='PUNJAB APRIL 22-WMn Reg'!O8 -> IL Chandigarh SEZ Unit - I Rajiv Gandhi Chandigarh tech Park, Kishangarh, Chandigarh-160101
A11: S.No | B11: Name of workman | C11: Father's / Husband's Name | D11: Designation / Nature of employment | E11: Act/Omission for which fine imposed | F11: Date of offence | G11: Whether workman showed cause against fine | H11: Name of person in whose presence employee's explanation was heard | I11: Wage-period and wge payable | J11: Amount of fine Imposed | K11: Date on which fine realised | L11: Remarks
A13: 1 | B13: 2 | C13: 3 | D13: 4 | E13: 5 | F13: 6 | G13: 7 | H13: 8 | I13: 9 | J13: 10 | K13: 11 | L13: 12
B16: NO EMPLOYEE WAS IMPOSED FINESFOR THE MONTH OF | H16: ='PUNJAB 04-22Master'!D10 -> 44652
F37: Signature of the Contractor with Seal

Sheet Advances
A1: FORM XXII- REGISTER OF ADVANCES
A3: (Vide Rule 78(1) (a) (ii) of Contract Labour (Regulation and Abolition) Central /Punjab Rules 1973)
A4: Name and address of Contractor: | D4: ='PUNJAB 04-22Master'!F5 -> Burgeon IT Services Pvt.Ltd. | E4: Name and address of the establishment in / under which contract is carried on:
B5: ='PUNJAB 04-22Master'!F6 -> Siri Mansion LIGB 436 Dr.A S Rao Nagar,Hyderabad | E5: ='PUNJAB 04-22Master'!AO5 -> Burgeon IT Services Pvt.Ltd.
B6: ='PUNJAB 04-22Master'!F7 -> 0 | E6: ='PUNJAB 04-22Master'!AO6 -> Siri Mansion LIGB 436 Dr.A S Rao Nagar,Hyderabad
A7: Nature and Location of Work: | D7: ='PUNJAB 04-22Master'!F8 -> IT SUPPORTIVE SERVICES&Chandigarh | E7: Name and address of principal employer:
E8: ='PUNJAB 04-22Master'!AO10 -> INFOSYS LTD.IL
E9: ='PUNJAB APRIL 22-WMn Reg'!O8 -> IL Chandigarh SEZ Unit - I Rajiv Gandhi Chandigarh tech Park, Kishangarh, Chandigarh-160101
A11: S.No | B11: Name of workman | C11: Father's / Husband's Name | D11: Designation / Nature of employment | E11: Wage period and wages payable | F11: Date and amount of advance given | G11: Purpose(s) for which advance made | H11: Number of instalments by which advance to be repaid | I11: Date and amount of each instalment repaid | J11: Date on which last instalment was repaid | K11: Remarks
A13: 1 | B13: 2 | C13: 3 | D13: 4 | E13: 5 | F13: 6 | G13: 7 | H13: 8 | I13: 9 | J13: 10 | K13: 11
B16: NO EMPLOYEE TAKEN ADVANCE FOR THE MONTH OF | F16: ='PUNJAB 04-22Master'!D10 -> 44652
G36: Signature of the Contractor with Seal

Sheet Overtime
A1: FORM XXIII- REGISTER OF OVERTIME
A3: (Vide Rule 78(1) (a) (iii) of Contract Labour (Regulation and Abolition) Central /Punjab Rules 1973)
A4: Name and address of Contractor: | D4: ='PUNJAB 04-22Master'!F5 -> Burgeon IT Services Pvt.Ltd. | F4: Name and address of the establishment in which under contract is carried on:
B5: ='PUNJAB 04-22Master'!F6 -> Siri Mansion LIGB 436 Dr.A S Rao Nagar,Hyderabad | F5: ='PUNJAB 04-22Master'!AO5 -> Burgeon IT Services Pvt.Ltd.
B6: ='PUNJAB 04-22Master'!F7 -> 0 | F6: ='PUNJAB 04-22Master'!AO6 -> Siri Mansion LIGB 436 Dr.A S Rao Nagar,Hyderabad
A7: Nature and Location of Work: | D7: ='PUNJAB 04-22Master'!F8 -> IT SUPPORTIVE SERVICES&Chandigarh | F7: Name and address of principal employer:
F8: ='PUNJAB 04-22Master'!AO10 -> INFOSYS LTD.IL
F9: ='PUNJAB APRIL 22-WMn Reg'!O8 -> IL Chandigarh SEZ Unit - I Rajiv Gandhi Chandigarh tech Park, Kishangarh, Chandigarh-160101
A11: S.No | B11: Name of workman | C11: Father's / Husband's Name | D11: Sex | E11: Designation / Nature of employment | F11: Date on which overtime worked | G11: Total overtime worked or production in case of piece-rates | H11: Normal rate of wages | I11: Overtime rate of wages | J11: overtime earnings | K11: Date on which overtime wages paid | L11: Remarks
A13: 1 | B13: 2 | C13: 3 | D13: 4 | E13: 5 | F13: 6 | G13: 7 | H13: 8 | I13: 9 | J13: 10 | K13: 11 | L13: 12
B16: NO EMPLOYEE DONE OVERTIME FOR THE MONTH OF | F16: ='PUNJAB 04-22Master'!D10 -> 44652
G38: Signature of the Contractor with Seal

Sheet Accident
A1: FORM 11
A3: ACCIDENT BOOK
A4: EMPLOYEE STATE INSURANCE CORPORATION
B5: (Regulation 66)
A7: S.No | B7: Date of Notice | C7: Time of Notice | D7: Name and Address of the Injured Person | E7: Sex | F7: Age | H7: Shift,Department and occupation of employee | I7: Details of Injury | P7: Signature and designation of the person who makes the entry in the accident book | Q7: Name,address and occupation of the two witnesses | R7: Remarks if any
G8: Insurance Number | N8: What exactly was the injured person doing at the time of accident | O8: Name,Occupation,address and signature or the thumb impression of the person(s) giving notice
I9: Cause | J9: Nature | K9: Date | L9: Time | M9: Place
A10: 1 | B10: 2 | C10: 3 | D10: 4 | E10: 5 | F10: 6 | G10: 7 | H10: 8 | I10: 9 | J10: 10 | K10: 11 | L10: 12 | M10: 13 | N10: 14 | O10: 15 | P10: 16 | Q10: 17 | R10: 18
B12: NO ACCIDENT OCCURRED FOR THE MONTH OF | F12: ='PUNJAB 04-22Master'!D10 -> 44652

Sheet Form-I
B1: FORM I
B2: NOMINATION AND DECLARATION FORM
B3: (Vide Rule 3 of Payment of wages Act Central & A.P Rules, 1936)
B4: Name and Address of the Contractor | H4: Name and Address of the Establishment in/under which Contract is carried on:
B7: ='04-22 Muster Roll'!D5 -> Burgeon IT Services Pvt.Ltd. | H7: ='04-22 Muster Roll'!X5 -> Burgeon IT Services Pvt.Ltd.
B9: ='04-22 Muster Roll'!D6 -> Siri Mansion LIGB 436 Dr.A S Rao Nagar,Hyderabad | H9: ='04-22 Muster Roll'!X6 -> Siri Mansion LIGB 436 Dr.A S Rao Nagar,Hyderabad
B12: Nature of work and location of work: | H12: Name and address of Principal Employer:
H15: ='04-22 Muster Roll'!Z9 -> INFOSYS LTD.IL
B16: ='04-22 Muster Roll'!D7 -> IT SUPPORTIVE SERVICES&Chandigarh
H17: ='04-22 Muster Roll'!Z10 -> IL Chandigarh SEZ Unit - I Rajiv Gandhi Chandigarh tech Park, Kishangarh, Chandigarh-160101
B19: 1. Name of the person making nomination | H19: ='PUNJAB 04-22Master'!#REF! -> #REF!
B20: 2. Father's/Husband name | H20: ='PUNJAB 04-22Master'!#REF! -> #REF!
B21: 3. Date of Birth | H21: ='PUNJAB 04-22Master'!#REF! -> #REF!
B22: 4. Sex | H22: ='PUNJAB 04-22Master'!#REF! -> #REF!
B23: 5. Marital Status | H23: Un-Married
B24: 6.Address
B25: Permanent | H25: ='PUNJAB 04-22Master'!#REF! -> #REF!
H26: ='PUNJAB 04-22Master'!#REF! -> #REF!
H27: ='PUNJAB 04-22Master'!#REF! -> #REF!
B28: Temporary | H28: ='PUNJAB 04-22Master'!#REF! -> #REF!
H29: ='PUNJAB 04-22Master'!#REF! -> #REF!
H30: ='PUNJAB 04-22Master'!#REF! -> #REF!
B31: I hereby nominate the person(s)/cancel the nomination made by me previously and nominate the person(s) mentioned below to
B32: receive any amount due to me from the employer,in the event to my death.
B33: Name of the Nominee/nominees | E33: Address | G33: Nominee's relationship With the member | I33: Date of Birth | J33: Total amount of Share of accumulations | K33: If the nominee is minor,name,relationship and address of the guardian
B34: 1 | E34: 2 | G34: 3 | I34: 4 | J34: 5 | L34: 6
B35: ='PUNJAB 04-22Master'!#REF! -> #REF! | E35: Same as permanant address | G35: Father | I35: 54 years | J35: 1 | K35: N/A
B39: 1.Certified that I have no family and should I acquire a family hereafter,the above nomination shall be deemed as cancelled.
B40: 2.Certified that my father/mother is/ are dependent upon me.
B41: 3.Strike out whichever is not applicable.
I43: Signature or the thumb impression of the employed person
F44: CERTIFCATE BY EMPLOYER
A45: Certified that the above declaration and nomination has been signed/thumb impressed before me by Shri/Smt/Kum | K45: ='PUNJAB 04-22Master'!#REF! -> #REF!
A46: employed in my establishment after he/she has read the entry/entries have been read over to him/her by me and got confirmed by him/her.
F49: Signature or the employer or other authorized officer of the establiment and Designation
A50: Place | B50: Hyderabad | F50: ='PUNJAB 04-22Master'!AO5 -> Burgeon IT Services Pvt.Ltd.
A51: Date | B51: ='PUNJAB 04-22Master'!#REF! -> #REF! | F51: ='PUNJAB 04-22Master'!AO6 -> Siri Mansion LIGB 436 Dr.A S Rao Nagar,Hyderabad
B53: FORM I
B54: NOMINATION AND DECLARATION FORM
B55: (Vide Rule 3 of Payment of wages Act Central & A.P Rules, 1936)
...

Sheet Form-2
K1: (FORM 2 REVISED)
B2: NOMINATION AND DECLARATION FORM FOR UNEXEMPTED/EXEMPTED ESTABLISHMENTS
B3: Declaration and Nomination Form under the Employees Provident Funds and Employees Pension Schemes
B4: (Paragraph 33 and 61(1) of the Employees Provident Fund Scheme 1952 and Paragraph 18 of the Employees Pension Scheme 1995)
B6: 1. Name of the person making nomination | H6: ='PUNJAB 04-22Master'!#REF! -> #REF!
B7: 2. Father's/Husband name | H7: ='PUNJAB 04-22Master'!#REF! -> #REF!
B8: 3. Date of Birth | H8: ='PUNJAB 04-22Master'!#REF! -> #REF!
B9: 4. Sex | H9: ='PUNJAB 04-22Master'!#REF! -> #REF!
B10: 5. Marital Status | H10: Un-Married
B11: 6.Address
B12: Permanent | H12: ='PUNJAB 04-22Master'!#REF! -> #REF!
H13: ='PUNJAB 04-22Master'!#REF! -> #REF!
H14: ='PUNJAB 04-22Master'!#REF! -> #REF!
G15: PART-A(EPF)
B16: I hereby nominate the person(s)/cancel the nomination made by me previously and nominate the person(s) mentioned below to
B17: receive any amount due to me from the employer,in the event to my death.
B18: Name of the Nominee/nominees | E18: Address | G18: Nominee's relationship With the member | I18: Date of Birth | J18: Total amount of Share of accumulations | K18: If the nominee is minor,name,relationship and address of the guardian
B19: 1 | E19: 2 | G19: 3 | I19: 4 | J19: 5 | L19: 6
B20: ='PUNJAB 04-22Master'!#REF! -> #REF! | E20: Same as Permanant Address | G20: Father | I20: 55 Years | J20: 1 | K20: N/A
B24: 1.Certified that I have no family and should I acquire a family hereafter,the above nomination shall be deemed as cancelled.
B25: 2.Certified that my father/mother is/ are dependent upon me.
B26: Strike out whichever is not applicable | J26: Signature/or thumb impression of the subscriber
G27: PART (EPS)
G28: Para 18
B29: I hereby furnish below particulars of the members of my family who would be eligible to receive Widow/Children Pension in the event of
B30: my premature death in service
B31: S.No | C31: Name & Address of the Family Member | I31: Age | J31: Relationship with the member
B32: 1 | E32: 2 | I32: 3 | K32: 4
B37: Certified that I have no family as defined in para 2 (vii) of the Employees's Family Pension Scheme 1995 and should I acquire a family hereafter
B38: I shall furnish Particulars there on in the above form.
B39: I hereby nominate the following person for receiving the monthly widow pension (admissible under para 16 2 (a) (1) & (ii) in the even of my death
B40: without leaving any eligible member for receiving pension.
B41: Name and Address of the nominee | G41: Date of Birth | I41: Relationship with member
B47: Date | C47: ='PUNJAB 04-22Master'!#REF! -> #REF! | I47: Signature or thumb impression of the subscriber
F48: CERTIFCATE BY EMPLOYER
A49: Certified that the above declaration and nomination has been signed/thumb impressed before me by Shri/Smt/Kum | K49: ='PUNJAB 04-22Master'!#REF! -> #REF!
A50: employed in my establishment after he/she has read the entry/entries have been read over to him/her by me and got confirmed by him/her.
F52: Signature or the employer or other authorized officer of the establiment and Designation
A53: Place | B53: Hyderabad | F53: ='PUNJAB 04-22Master'!F5 -> Burgeon IT Services Pvt.Ltd.
A54: Date | B54: ='PUNJAB 04-22Master'!#REF! -> #REF! | F54: ='PUNJAB 04-22Master'!F6 -> Siri Mansion LIGB 436 Dr.A S Rao Nagar,Hyderabad
...

Sheet Form 11
I1: New Form No. 11 - Declaration Form
B2: (To be retained by t he employer for future reference)
D3: EMPLOYEES' PROVIDENT FUND ORGANIZATION | I3: Emp Code: | K3: ='PUNJAB 04-22Master'!#REF! -> #REF!
C4: Employees' Provident Funds Scheme, 1952 (Paragraph 34 & 57) & | I4: Company | J4: ='PUNJAB 04-22Master'!F5 -> Burgeon IT Services Pvt.Ltd.
C5: The Employees' Pension Scheme, 1995 (Paragraph 24) | I5: ='PUNJAB 04-22Master'!F6 -> Siri Mansion LIGB 436 Dr.A S Rao Nagar,Hyderabad
A8: 1 | B8: Name of the Member | H8: ='PUNJAB 04-22Master'!#REF! -> #REF!
A9: 2 | B9: Fathers' Name | F9: Husband's Name | H9: ='PUNJAB 04-22Master'!#REF! -> #REF!
B10: (Please tick whichever is applicable)
A11: 3 | B11: Date of Birth (DD/MM/YYYY) | H11: ='PUNJAB 04-22Master'!#REF! -> #REF!
A12: 4 | B12: Gender (Male/Female/Transgender) | H12: ='PUNJAB 04-22Master'!#REF! -> #REF!
A13: 5 | B13: Marital Status(married / Unmarried / Widow/divorce) | H13: UNMARRIED
A14: 6 | B14: (a) | C14: Email Id
B15: (b) | C15: Mobile No.
A16: 7 | B16: Whether earlier a member of the Employees' Provident Fund Scheme, 1952 ? | H16: Yes | K16: No
A17: 8 | B17: Whether earlier a member of the Employees' Pension Scheme, 1995? | H17: Yes | K17: No
F18: Previous employment details [if Yes to 7 &/or 8 above]
A19: 9 | B19: a) | C19: Universal Account Number
B20: b) | C20: Previous PF Account Number
B21: C) | C21: Date of exit from previous employment (DD/MM/YYYY)
B22: d) | C22: Scheme Certificate No. (if issued)
B23: e) | C23: Pension Payment Order (PPO) No. (if issued)
A24: 10 | B24: a) | C24: International Worker | H24: Yes | K24: No
B25: b) | C25: If yes, state country of origin(India/Name of other country)
B26: C) | C26: Passport No.
B27: d) | C27: Validity of passport [(DD/MM/YYYY) to (DD/MM/YYYY)]
E28: KYC Details (attach self attested copies of following KYCs)
A29: 11 | B29: a) | C29: Bank Account No. & IFS Code
B30: b) | C30: AADHAR No.
B31: c) | C31: Permanent Account No. (PAN), if available
F32: UNDERTAKING
B33: 1) | C33: Certified that the particulars are true to the best of my knowledge.
B34: 2) | C34: I authorize EPFO to use my Aadhar for verification/authentication/eKYC purpose for service delivery.
B35: 3) | C35: Kindly transfer the funds and service details, if applicable from the previous PF account as declared above to the present P.F. Account (The Transfer would be possible only if the identified KYC details approved by previous employer has been verified by present employer
B36: 4) | C36: In case of changes in above details, the same will be intimated to employer at the earliest.
C37: Date : | D37: ='PUNJAB 04-22Master'!#REF! -> #REF!
C38: Place: | D38: Hyderabad | J38: Signature of Member
F40: DECLARATION BY PRESENT EMPLOYER
A41: A) | B41: The member Mr./Ms./Mrs. | E41: ='PUNJAB 04-22Master'!#REF! -> #REF! | H41: has joined on | J41: ='PUNJAB 04-22Master'!#REF! -> #REF! | K41: and has been allotted PF Number
B42: ='PUNJAB 04-22Master'!#REF! -> #REF!
A43: B) | B43: In case the person was earlier not a member of EPF Scheme, 1952 and EPS, 1995:
...

Sheet Form-F
A1: F O R M – F
A2: [See sub-Rule (1) of Rule 6] The Payment of Gratuity Rules, 1973:
A3: NOMINATION
A4: To
A5: ='PUNJAB 04-22Master'!F5 -> Burgeon IT Services Pvt.Ltd.
A6: ='PUNJAB 04-22Master'!F6 -> Siri Mansion LIGB 436 Dr.A S Rao Nagar,Hyderabad
A8: 1. I, Shri / Shrimati / Kumari | C8: ='PUNJAB 04-22Master'!#REF! -> #REF!
A9: whose particulars are given in the statement below, hereby nominate the person(s) mentioned below to receive the gratuity payable after my death as also the gratuity standing to my credit in the event of my death before that amount has become payable, or having become payable has not been paid and direct that the said amount of gratuity shall be paid in proportion indicated against the name(s) of the nominee(s).
A11: 2. I hereby certify that the person(s) mentioned is a /are member(s) of my family within the meaning of clause (h) of Section 2 of the Payment of Gratuity Act, 1972.
A13: 3. I hereby declare that I have no family within the meaning of clause (h) of Section 2 of the said Act.
A15: 4. (a) My father/mother/parents is/are not dependent on me
A16: (b) My husband’s father/mother/parents is/are not dependent on my husband.
A18: 5. I have excluded my husband from my family by a notice dated the ……………. to the Controlling Authority in terms of the proviso to clause (h) of Section 2 of the said Act.
A20: 6. Nomination made herein invalidates my previous nomination.
A22: NOMINEE(S)
A23: Name in full with full address of nominee(s): | B23: Relationship with the empliyee | C23: Age of nominee: | D23: Proportion by which the gratuity will be shared:
A24: 1 | B24: 2 | C24: 3 | D24: 4
A25: ='PUNJAB 04-22Master'!#REF! -> #REF! | B25: Father | C25: 54 Years | D25: 1
A29: STATEMENT
A31: 1. Name of employee in full: | C31: ='PUNJAB 04-22Master'!#REF! -> #REF!
A32: 2. Sex: | C32: ='PUNJAB 04-22Master'!#REF! -> #REF!
A33: 3. Religion: | C33: Muslim
A34: 4. Whether unmarried/married/widow/widower: | C34: Un married
A35: 5. Department/Branch/Section where employed: | C35: ='PUNJAB 04-22Master'!#REF! -> #REF!
A36: 6. Post held with Ticket No. or Serial No. if any: | C36: ='PUNJAB 04-22Master'!#REF! -> #REF!
A37: 7. Date of appointment: | C37: ='PUNJAB 04-22Master'!#REF! -> #REF!
A38: 8. Permanent address:
C39: ='PUNJAB 04-22Master'!#REF! -> #REF!
C40: ='PUNJAB 04-22Master'!#REF! -> #REF!
C41: ='PUNJAB 04-22Master'!#REF! -> #REF!
A42: Place: | B42: Hyderabad
A43: Date: | B43: ='PUNJAB 04-22Master'!#REF! -> #REF! | C43: Signature/Thumb impression of the employee
A45: Declaration by witnesses:
A46: Nomination signed/thumb impressed before me:
A48: Name in full and full address of witnesses: | C48: Signature of witnesses:
A49: 1 | C49: 1
A50: 2 | C50: 2
C51: Certificate by the Employer
A52: Certified that the particulars of the above nomination have been verified and recorded in t his establishment
A53: Employer's reference No, if any
...

Sheet Form-E
D4: TO
D5: The Welfare commissioner,
D6: Telangana Welfare Board,Labour department
D7: RTC X road,Hyderabad 500023
C8: FORM E
C9: [See sub-rule (2) of Rule 4]
D10: Register of Fines Realised and unpaid accumulations for the year 2019
C12: Sl. No. | E12: During
E13: Quarter ending 31st March | F13: Quarter ending 30th June | G13: Quarter ending 30th September | H13: Quarter ending 31st December
C14: 1 | D14: 2 | E14: 3 | F14: 4 | G14: 5 | H14: 6
C15: 1 | D15: Total realisation under fines | F15: NIL
C16: 2 | D16: Total amount becoming unpaid accumulations* of
D17: (i) Basic Wage | F17: NIL
D18: (ii) Overtime | F18: NIL
D19: (iii) Dearness Allowance and other allowances | F19: NIL
D22: Total of (1) and (2) ………….
C23: *See definition of “unpaid Accumulation” under sub-section (11) of Section 2 of the Act.
D24: Saransh Software Solutions Private Limited
D25: Modern Profound Techpark Office No: 201, 2nd Floor, Kondapur,Hyderabad 500032 Telangana
F28: Signature of the Employer with Seal
