Workbook

Sheet PUNE ASC-APRIL 22WM REG
A1: FORM IX- REGISTER OF PERSONS EMPLOYED | N1: 44501
A3: (Vide Rule 78(1) (a) (i) of Contract Labour (Regulation and Abolition) Central /Maharastra.Rules 1974
A4: Name and address of Contractor:Burgeon IT services Pvt.Ltd. | F4: Name and address of the establishment in / under which contract is carried on: burgeon IT services Pvt.Ltd. Siri mansion LIGH 436 DR.A S Rao nagar,Hyderabad
B5: ='4-22MASTER'!G6 -> Siri Mansion LIGB 436 Dr.A S Rao Nagar,Hyderabad
A7: Name and address of Contractor:burgeon IT services Pvt.Ltd. | F7: Name and address of principal employer:
F8: ='4-22MASTER'!AQ10 -> INFOSYS LTD.IL Ascendas SEZ Unit,Building Juniper
F9: International Tech Park,Rajiv Gandhi Infotech Park,Hinjawadi,Pune,Maharashtra
A11: S.No | B11: Name and Surname of workman | C11: Age and Sex | E11: Father's/Husband's name | F11: Nature of Employement/Designation | G11: Permanent Home Address of worken | H11: Local Address | I11: Date of commencement of Employment | J11: Signature or Thumb impression of workman | K11: Date of Temination of Employment | M11: Remarks
L12: Reason for Termination
A13: 1 | B13: Rajkumar Samui | C13: 31900 | D13: MALE | E13: Tapan Samui | F13: Technical Consultant | G13: S.NO. 28/2 Keerthi Classic, Marunji Road,Hinjawadi Pune, MH 411057 | H13: S.NO. 28/2 Keerthi Classic, Marunji Road,Hinjawadi Pune, MH 411057 | I13: 42782 | K13: 43695 | L13: Resignation
A14: 2 | B14: Mohammed Mudassir | C14: 29382 | D14: MALE | E14: Abdullah ansari | F14: Technical Consultant | G14: 401, Simone Terrace, Lane 9, salunke Vihar,Rd kondhwa, Pune 411048 | H14: 401, Simone Terrace, Lane 9, salunke Vihar,Rd kondhwa, Pune 411048 | I14: 43206 | K14: 43700 | L14: Resignation
A15: 3 | B15: Abhishek Kumar | C15: 22/09/1987 | D15: MALE | E15: Vishwakarma | F15: Technical Consultant | G15: 210 skylite vesta villas, sarjapura, bangalore | H15: 210 skylite vesta villas, sarjapura, bangalore | I15: 43206 | K15: 43812 | L15: Resignation
A16: 4 | B16: Varsha Anket | C16: 32707 | D16: FEMALE | E16: Aniket Ajit pATil | F16: Technical Consultant | G16: A-492, Gondhalpada,Plot 5, alibagh, Raigadh, MH 402201 | H16: A-492, Gondhalpada,Plot 5, alibagh, Raigadh, MH 402201 | I16: 43228 | K16: 43672 | L16: Resignation
A17: 5 | B17: Ishita Debnath | C17: 33329 | D17: FEMALE | E17: Manoranjan debnath | F17: Technical Consultant | G17: Kiran Pathology, shivaji park,PO renukot, Sonebhadra dist UP 231217 | H17: Kiran Pathology, shivaji park,PO renukot, Sonebhadra dist UP 231217 | I17: 43228 | K17: 43517 | L17: Resignation
A18: 6 | B18: Subodh Vendikonda | C18: 28/05/1989 | D18: MALE | E18: Prakash | F18: Technical Consultant | G18: 5-183/4, Teachers colony, Ichoda,Adilababd 504307 | H18: 5-183/4, Teachers colony, Ichoda,Adilababd 504307 | I18: 43272 | K18: 43672 | L18: Resignation
A19: 7 | B19: Dilip Lillaney | C19: 29800 | D19: MALE | E19: Raju Arjandas Lillaney | F19: Technical Consultant | G19: 503-I1, jasminium, Magarpatta city, Hadapsar Pune 411013 | H19: 503-I1, jasminium, Magarpatta city, Hadapsar Pune 411013 | I19: 43297 | K19: 43637 | L19: Resignation
A20: 8 | B20: Shantanu Mukherjee | C20: 32942 | D20: MALE | E20: Samarnath Mukherjee | F20: Technical Consultant | G20: Musabani No.1, Near Shishu Mandir School, East Singhbhum, Jharkhand 632104 East Singhbhum, Jharkhand - 832104 | H20: Musabani No.1, Near Shishu Mandir School, East Singhbhum, Jharkhand 632104 East Singhbhum, Jharkhand - 832104 | I20: 43377 | K20: 43636 | L20: Resignation
A21: 9 | B21: Vamshi Krishna Billakanto | C21: 32665 | D21: MALE | E21: Lakshmi Narayana | F21: Technical Consultant | G21: 149/5/G4, Uppal Depot, Near Ravindra Bharati school, Mallikarjuna Nagar, Boduppal, KV rangareddy, Telangana 500092 | H21: 149/5/G4, Uppal Depot, Near Ravindra Bharati school, Mallikarjuna Nagar, Boduppal, KV rangareddy, Telangana 500092 | I21: 43398 | K21: 43546 | L21: Resignation
A22: 10 | B22: Dilip Arjun Kanabar | C22: 32750 | D22: MALE | E22: Arjun Kanabar | F22: Technical Consultant | G22: A/105, Prakash Bhavan, Khau Gali, Station Road. Bhayandar west. District-Thane 401101 | H22: 594/B Wing, 144 Wakadkar Wasti, Nisarg Vishwa, Wakad. Pune 411057 | I22: 43448 | K22: 43652 | L22: Resignation
A23: 11 | B23: Swati Sinha | C23: 34282 | D23: FEMALE | E23: Subodh kumar | F23: Technical Consultant | G23: POSTAL PARK ROAD NO 3 B PATNA BIHAR-800001 | H23: SAI NIVAS WAKAD KARVVASTI PUNE-411057 | I23: 43451 | K23: 43714 | L23: Resignation
A24: 12 | B24: Aparna Khaire | C24: 31088 | D24: FEMALE | E24: Kisan Khaire | F24: Technical Consultant | G24: C1202, DattSai CHSL, Krishna Borker Marg, Thane East - 400603 | H24: 1004, Orchids, Ashok Meadows, Hinjewadi Pahse 1, Pune, MH | I24: 43468 | K24: 43602 | L24: Resignation
A25: 13 | B25: Kiran Krishna Gondhali | C25: 33336 | D25: MALE | E25: krishna s | F25: Technical Consultant | G25: 1/5 saikrupa chaal,opp.ikon plaza,near R.T.O OFFICE,Kalyan(west),421301 | H25: 1/5 saikrupa chaal,opp.ikon plaza,near R.T.O OFFICE,Kalyan(west),421301 | I25: 43528 | K25: 43812 | L25: Resignation
A26: 14 | B26: Shwetha Thorat | C26: 24/11/1986 | D26: FEMALE | E26: Prabhakar deo ram | F26: Technical Consultant | G26: A/302,RAJESWAR TOER,NEAR PRATHAP CINEMA,KOLBAD,THANE WEST,400601 | H26: E/901,PARK IOD BULDING,PARK STREAT,SOC,WAKAD,PUNE,411057 | I26: 43556 | K26: 43854 | L26: Resignation
A27: 15 | B27: Mugesh R | C27: 34644 | D27: MALE | E27: RAJARATNAM A | F27: Senior Network Engineer L2 | G27: NO.44 ESWARAN KOVIL STREAT,MANAPARAI,TREACHY DISR,THAMILNADU,621306 | H27: 3RD FLOUR,OLD MADIVAALA,CHIKKAMADIVAALA,FISRT STAGE,BTM LAY OUT,BANGALURE,560076 | I27: 43742 | K27: 44420 | L27: Resignation
A28: 16 | B28: RAHOOL MORAY | C28: 16/6/1973 | D28: MALE | E28: M. B. More | F28: Program Manager | G28: Spring Valley, Lavender B-303, Next to Magarpatta City, Hadapsar, Pune 411013 | H28: Spring Valley, Lavender B-303, Next to Magarpatta City, Hadapsar, Pune 411013 | I28: 44172 | K28: 44408 | L28: Resignation
A29: 17 | B29: Mansidutt Sharma | C29: 28345 | D29: MALE | E29: J S Bhardwaj | F29: Senior Consultant | G29: Flat No : I1006, SPS Residency, Vaibhav Khand, Indirapuram, Ghaziabad, UP - 201014 | H29: Flat No : I1006, SPS Residency, Vaibhav Khand, Indirapuram, Ghaziabad, UP - 201014 | I29: 28/12/2020 | K29: 44384 | L29: Resignation
A30: 18 | B30: Sandeep Dange | C30: 32295 | D30: Male | E30: Shrikrishna Narayana rao | F30: Project Manager | G30: ND42, Flat No 21,Sambaji chowk, CICDO, Kautha, Nanded, MH 431003 | H30: ND42, Flat No 21,Sambaji chowk, CICDO, Kautha, Nanded, MH 431003 | I30: 44294 | K30: 44475 | L30: Resignation
A31: 19 | B31: Haneef | C31: 34715 | D31: Male | E31: D.Subahan | F31: System Administrator | G31: Sri Sai vaishnavi pg, 2nd cross, near Rajapalya, Hoodi, 560048 | H31: 6-1-356A, Lakshminagar, near Ramalayam Temple, Anantapur, 515004 | I31: 44298 | K31: ACTIVE | L31: ACTIVE | N31: 1
A32: 20 | B32: Y.Hemanth Kumar Reddy | C32: 30190 | D32: Male | E32: Y Venkatramana Reddy | F32: VMWare Admin | G32: #72B 1St Floor, 1st Bolck, 5th Main, Devasandra Main Road, Ayyappa Nagar, kr Puram, Bangalore, KA 560036 | H32: 15-5-5-B2, RRN main road, RRN colony, Madnapalle -517325, Chittoor Dis, AP | I32: 44298 | K32: 44508 | L32: Resignation | N32: 2
A33: 21 | B33: DevKant Shukla | C33: 31873 | D33: Male | E33: Late. Shri Surendra Kumar Shukla | F33: Project Manager | G33: Flat no-37; Pocket-5; Sector-2; Rohini; Delhi 110085 | H33: Flat no-37; Pocket-5; Sector-2; Rohini; Delhi 110085 | I33: 44301 | K33: ACTIVE | L33: ACTIVE
A34: 22 | B34: KAPIL KHADSE | C34: 33359 | D34: Male | E34: Harshada Khadse | F34: Sr. Project Coordinator | G34: 119, Gurukunj nagar, Near MIG colony, Besa Road, Manewada, Nagpur- 440034 | H34: 119, Gurukunj nagar, Near MIG colony, Besa Road, Manewada, Nagpur- 440034 | I34: 44296 | K34: 44439 | L34: Resignation
A35: 23 | B35: Rajaram Raosaheb Gusale | C35: 33767 | D35: MALE | E35: Supriya Rajaram Gusale | F35: Project Manager | G35: A/P: Chandolewadi,Sangola, Behind Sutgirni,Tal- Sangola, Dist-Solapur-413307 | I35: 4th May 2021 | K35: 44524 | L35: Resignation | N35: 4
B36: Nilesh Baviskar | C36: 33030 | D36: Male | E36: Ashok Bhavisar | F36: Project Manager | G36: Mukam post, Kanalda,Taluka,Jalgaon, Kanvashramroad, new Busstand, Kanalde, Jalgaon,MH 425002 | H36: Mukam post, Kanalda,Taluka,Jalgaon, Kanvashramroad, new Busstand, Kanalde, Jalgaon,MH 425002 | I36: 4th May 2021 | K36: ACTIVE | L36: ACTIVE
A37: 25 | B37: Ved Prakash | C37: 30321 | D37: Male | E37: J N Gupta | F37: Project Manager | G37: Flat No. A 203, Silver Palm Grove, Ravet, Pune 412101 | H37: Flat No. A 203, Silver Palm Grove, Ravet, Pune 412101 | I37: 4th May 2021 | K37: ACTIVE | L37: ACTIVE | N37: 2
A38: 26 | B38: Prashant Gangadharrao Hambarde | C38: 31554 | D38: MALE | E38: Gangadhar Avadhut rao | F38: Project Manager | G38: H No ND 42, P2 8/2, Near indira gandhi High school, Hudco, New Nanded, Maharashtra, 431603 | H38: H No ND 42, P2 8/2, Near indira gandhi High school, Hudco, New Nanded, Maharashtra, 431603 | I38: 4th May 2021 | K38: 44526 | L38: Resignation | N38: 7
A39: 27 | B39: GauravVispute | C39: 33721 | D39: MALE | E39: Bhika Jagannath | F39: Project Coordinator | G39: 5/2, Trimurti Housing Socieity,Central bank colony road, Pimprala,Jalgaon 425002 | H39: H No ND 42, P2 8/2, Near indira gandhi High school, Hudco, New Nanded, Maharashtra, 431603 | I39: 4th May 2021 | K39: ACTIVE | L39: ACTIVE | N39: 3
A40: 28 | B40: Sneha Panhalkar | C40: 23/11/1990 | D40: Male | E40: Kashinath Panhalkar | F40: Project Manager | G40: 502, Sai Sarth Residency, Adarsh Nagar, Famous Chawk, New Sanghavi, Pune-411027 | H40: 502, Sai Sarth Residency, Adarsh Nagar, Famous Chawk, New Sanghavi, Pune-411027 | I40: 10th May 2021 | K40: resigantion | L40: Resignation
A41: 29 | B41: SACHIN NANDKISHORPATIL | C41: 29/09/1992 | D41: Male | E41: NANDKISHOR PATIL | F41: Project Coordinator L2 | G41: FL-206, A wing, Orient Plaza, Keshsv Nagar chinchwad, Pune-411033 | H41: FL-206, A wing, Orient Plaza, Keshsv Nagar chinchwad, Pune-411033 | I41: 10th May 2021 | K41: 44512 | L41: Resignation | N41: 9
A42: 30 | B42: Rohit Mahalankar | C42: 31560 | D42: Male | E42: Deelip Rao sakharam | F42: Project Manager | G42: Flat No 305, Shalan Heights, Sai park Road, Opp Kamalraj Bajaj, Dighi, Pune, 411015 | H42: A/P, Satala(KHU), Ahmedpur Dist, Latur MH 413523 | I42: 31st May 2021 | K42: ACTIVE | L42: ACTIVE
A43: 31 | B43: AYESHA BANU.I | C43: 33951 | D43: FEMALE | E43: Ishaka | F43: Project Manager | G43: 2-36,Muslim street,Poothagaram,Thirupattur tq,Taminadu-635851 | H43: 2-36,Muslim street,Poothagaram,Thirupattur tq,Taminadu-635851 | I43: 44358 | J43: OO | K43: 44516 | L43: Resignation | N43: 11
...

Sheet 4-22MASTER
A3: FORM - XIII REGISTER OF WORKMEN EMPLOYED BY CONTRACTOR
C4: (Vide Rule 75 of Contract Labour (Regulation and Abolition) Central/Maharastra Rules 1974)
A5: Name and address of Contractor: | G5: Burgeon IT Services Pvt.Ltd. | AC5: Name and address of Establishemnt in/ under which contract is carried on: | AQ5: =G5 -> Burgeon IT Services Pvt.Ltd.
G6: Siri Mansion LIGB 436 Dr.A S Rao Nagar,Hyderabad | AQ6: =G6 -> Siri Mansion LIGB 436 Dr.A S Rao Nagar,Hyderabad
AQ7: =G7 -> 0
A8: Nature and location of work: | G8: IT SUPPORTIVE SERVICES & PUNE ASC SEZ
A10: Wage period: Monthly | E10: 44652 | AL10: Name and address of Principal Employer: | AQ10: INFOSYS LTD.IL Ascendas SEZ Unit,Building Juniper
AQ11: International Tech Park,Rajiv Gandhi Infotech Park,Hinjawadi,Pune,Maharashtra
A14: Serial No. in the Register of Workmen | B14: Employee ID | C14: Name of Workman | D14: Age | E14: Sex | F14: Father's /Husband Name | G14: Designation / Nature of Work Done | H14: Permanent Address | K14: Local Address | O14: Date of Commencement of Employment | P14: Signature or thumb impression of Workman | Q14: Date of termination of Employment | R14: Reasons for termination | S14: Remarks | T14: EPF Number | U14: ESI Number | V14: Name of Workman | X14: No.of Days worked | Y14: Unit of work done | Z14: Monthly rate of wages/ piece rate | AA14: Basic wages | AB14: Dearness Allowances | AC14: Over time | AD14: Other cash payments (Nature of payments to be indicated) | AE14: HRA | AF14: CONVEYANCE | AG14: MEDICAL ALLOWANCES | AH14: SPECIAL ALLOWNANCES | AI14: Total | AJ14: BONUS | AK14: GRATUITY | AL14: LTA/L.E | AM14: ARREAR AMOUNT | AN14: TOTAL AMOUNT | AO14: Deductions, if any, (Indicate nature) | AU14: Net Amount paid | AV14: Time and Date of Payment | AW14: Place of Payment | AX14: Signature/Thumb Impression of workman | AY14: Initial of Contractor or his representative
AO15: ESI | AP15: PF | AQ15: PT | AR15: TDS | AS15: MED | AT15: Total Deductions
A17: 19 | B17: BITS-542 | C17: Haneef | D17: 34715 | E17: MALE | F17: D.Subahan | G17: System Administrator | H17: Sri Sai vaishnavi pg, 2nd cross, near Rajapalya, Hoodi, 560048 | K17: 6-1-356A, Lakshminagar, near Ramalayam Temple, Anantapur, 515004 | O17: 44298 | T17: 100947550505 | U17: N/A | V17: =C17 -> Haneef | W17: 30 | X17: =VLOOKUP(B17,'[1]Pay sheet-APRIL- 2022'!$C$12:$AF$139,10,0) -> 30 | Y17: N/A | Z17: =VLOOKUP(B17,'[2]Pay sheet-JAN- 2021'!$C$18:$AF$125,6,0) -> 61740 | AA17: =VLOOKUP(B17,'[1]Pay sheet-APRIL- 2022'!$C$12:$AF$139,11,0) -> 37044 | AB17: 0 | AC17: 0 | AD17: =AE17+AF17+AG17+AH17 -> 24809 | AE17: =VLOOKUP(B17,'[1]Pay sheet-APRIL- 2022'!$C$12:$AF$139,12,0) -> 14817.6 | AF17: =VLOOKUP(B17,'[1]Pay sheet-APRIL- 2022'!$C$12:$AF$139,13,0) -> 2083 | AG17: =VLOOKUP(B17,'[1]Pay sheet-APRIL- 2022'!$C$12:$AF$139,14,0) -> 2083 | AH17: =VLOOKUP(B17,'[1]Pay sheet-APRIL- 2022'!$C$12:$AF$139,15,0) -> 5825.4 | AI17: =AA17+AB17+AC17+AE17+AF17+AG17+AH17 -> 61853 | AJ17: =VLOOKUP(B17,'[1]Pay sheet-APRIL- 2022'!$C$12:$AF$139,18,0) -> 1554.609 | AK17: =VLOOKUP(B17,'[1]Pay sheet-APRIL- 2022'!$C$12:$AF$139,19,0) -> 1781.8164 | AL17: =VLOOKUP(B17,'[1]Pay sheet-APRIL- 2022'!$C$12:$AF$139,20,0) -> 3087 | AM17: 0 | AN17: =AI17+AJ17+AK17+AL17+AM17 -> 68276.425 | AO17: 0 | AP17: =VLOOKUP(B17,'[1]Pay sheet-APRIL- 2022'!$C$12:$AF$139,26,0) -> 1800 | AQ17: =VLOOKUP(B17,'[1]Pay sheet-APRIL- 2022'!$C$12:$AF$139,25,0) -> 200 | AR17: =VLOOKUP(B17,'[1]Pay sheet-APRIL- 2022'!$C$12:$AF$139,24,0) -> 0 | AS17: =VLOOKUP(B17,'[1]Pay sheet-APRIL- 2022'!$C$12:$AF$139,27,0) -> 391.78785 | AT17: =AP17+AQ17+AR17+AS17 -> 2391.7878 | AU17: =AN17-AT17 -> 65884.638 | AV17: 05.05.2022 | AW17: SBI | AX17: A/C'20434252219 | BA17: 1
A18: 25 | B18: BITS-557 | C18: Ved Prakash | D18: 30321 | E18: MALE | F18: J N Gupta | G18: Project Manager | H18: Flat No. A 203, Silver Palm Grove, Ravet, Pune 412101 | K18: Flat No. A 203, Silver Palm Grove, Ravet, Pune 412101 | O18: 4th May 2021 | T18: 100457474727 | U18: N/A | V18: =C18 -> Ved Prakash | W18: 30 | X18: =VLOOKUP(B18,'[1]Pay sheet-APRIL- 2022'!$C$12:$AF$139,10,0) -> 20 | Y18: N/A | Z18: =VLOOKUP(B18,'[2]Pay sheet-JAN- 2021'!$C$18:$AF$125,6,0) -> 71009 | AA18: =VLOOKUP(B18,'[1]Pay sheet-APRIL- 2022'!$C$12:$AF$139,11,0) -> 28403.6 | AB18: 0 | AC18: 0 | AD18: =AE18+AF18+AG18+AH18 -> 19048.733 | AE18: =VLOOKUP(B18,'[1]Pay sheet-APRIL- 2022'!$C$12:$AF$139,12,0) -> 11361.44 | AF18: =VLOOKUP(B18,'[1]Pay sheet-APRIL- 2022'!$C$12:$AF$139,13,0) -> 1389 | AG18: =VLOOKUP(B18,'[1]Pay sheet-APRIL- 2022'!$C$12:$AF$139,14,0) -> 1389 | AH18: =VLOOKUP(B18,'[1]Pay sheet-APRIL- 2022'!$C$12:$AF$139,15,0) -> 4909.2933 | AI18: =AA18+AB18+AC18+AE18+AF18+AG18+AH18 -> 47452.333 | AJ18: =VLOOKUP(B18,'[1]Pay sheet-APRIL- 2022'!$C$12:$AF$139,18,0) -> 1554.609 | AK18: =VLOOKUP(B18,'[1]Pay sheet-APRIL- 2022'!$C$12:$AF$139,19,0) -> 1366.2132 | AL18: =VLOOKUP(B18,'[1]Pay sheet-APRIL- 2022'!$C$12:$AF$139,20,0) -> 2366.9667 | AM18: 0 | AN18: =AI18+AJ18+AK18+AL18+AM18 -> 52740.122 | AO18: 0 | AP18: =VLOOKUP(B18,'[1]Pay sheet-APRIL- 2022'!$C$12:$AF$139,26,0) -> 1800 | AQ18: =VLOOKUP(B18,'[1]Pay sheet-APRIL- 2022'!$C$12:$AF$139,25,0) -> 200 | AR18: =VLOOKUP(B18,'[1]Pay sheet-APRIL- 2022'!$C$12:$AF$139,24,0) -> 0 | AS18: =VLOOKUP(B18,'[1]Pay sheet-APRIL- 2022'!$C$12:$AF$139,27,0) -> 440.76133 | AT18: =AP18+AQ18+AR18+AS18 -> 2440.7613 | AU18: =AN18-AT18 -> 50299.361 | AV18: 05.05.2022 | AW18: HDFC | AX18: A/C'50100052341452 | BA18: 3
A19: 27 | B19: BITS-559 | C19: GauravVispute | D19: 33721 | E19: MALE | F19: Bhika Jagannath | G19: Project Coordinator | H19: 5/2, Trimurti Housing Socieity,Central bank colony road, Pimprala,Jalgaon 425002 | O19: 4th May 2021 | T19: 101012347201 | U19: N/A | V19: =C19 -> GauravVispute | W19: 30 | X19: =VLOOKUP(B19,'[1]Pay sheet-APRIL- 2022'!$C$12:$AF$139,10,0) -> 29 | Y19: N/A | Z19: =VLOOKUP(B19,'[2]Pay sheet-JAN- 2021'!$C$18:$AF$125,6,0) -> 43202 | AA19: =VLOOKUP(B19,'[1]Pay sheet-APRIL- 2022'!$C$12:$AF$139,11,0) -> 25057.16 | AB19: 0 | AC19: 0 | AD19: =AE19+AF19+AG19+AH19 -> 16817.773 | AE19: =VLOOKUP(B19,'[1]Pay sheet-APRIL- 2022'!$C$12:$AF$139,12,0) -> 10022.864 | AF19: =VLOOKUP(B19,'[1]Pay sheet-APRIL- 2022'!$C$12:$AF$139,13,0) -> 2014 | AG19: =VLOOKUP(B19,'[1]Pay sheet-APRIL- 2022'!$C$12:$AF$139,14,0) -> 2014 | AH19: =VLOOKUP(B19,'[1]Pay sheet-APRIL- 2022'!$C$12:$AF$139,15,0) -> 2766.9093 | AI19: =AA19+AB19+AC19+AE19+AF19+AG19+AH19 -> 41874.933 | AJ19: =VLOOKUP(B19,'[1]Pay sheet-APRIL- 2022'!$C$12:$AF$139,18,0) -> 1554.609 | AK19: =VLOOKUP(B19,'[1]Pay sheet-APRIL- 2022'!$C$12:$AF$139,19,0) -> 1205.2494 | AL19: =VLOOKUP(B19,'[1]Pay sheet-APRIL- 2022'!$C$12:$AF$139,20,0) -> 2088.0967 | AM19: 0 | AN19: =AI19+AJ19+AK19+AL19+AM19 -> 46722.888 | AO19: 0 | AP19: =VLOOKUP(B19,'[1]Pay sheet-APRIL- 2022'!$C$12:$AF$139,26,0) -> 1800 | AQ19: =VLOOKUP(B19,'[1]Pay sheet-APRIL- 2022'!$C$12:$AF$139,25,0) -> 200 | AR19: =VLOOKUP(B19,'[1]Pay sheet-APRIL- 2022'!$C$12:$AF$139,24,0) -> 0 | AS19: =VLOOKUP(B19,'[1]Pay sheet-APRIL- 2022'!$C$12:$AF$139,27,0) -> 391.78785 | AT19: =AP19+AQ19+AR19+AS19 -> 2391.7878 | AU19: =AN19-AT19 -> 44331.101 | AV19: 05.05.2022 | AW19: SBI | AX19: A/C'31443937313 | BA19: 4
A20: 35 | B20: BITS-658 | C20: Anjali Dubey | D20: 27-12-1990 | E20: FEMALE | F20: Ravindra Nath Dubey | G20: Project Engineer | H20: H.N. 376/16, Behind P.K. School, Ravindra nagar Urrahat Rewa M.P. 486001 | K20: H.N. 376/16, Behind P.K. School, Ravindra nagar Urrahat Rewa M.P. 486001 | L20: OO | M20: OO | N20: OO | O20: 44487 | T20: 100514943656 | U20: N/A | V20: Anjali Dubey | W20: 30 | X20: =VLOOKUP(B20,'[1]Pay sheet-APRIL- 2022'!$C$12:$AF$139,10,0) -> 28 | Y20: N/A | Z20: =VLOOKUP(B20,'[2]Pay sheet-JAN- 2021'!$C$18:$AF$125,6,0) -> 58959 | AA20: =VLOOKUP(B20,'[1]Pay sheet-APRIL- 2022'!$C$12:$AF$139,11,0) -> 33017.04 | AB20: 0 | AC20: 0 | AD20: =AE20+AF20+AG20+AH20 -> 22124.36 | AE20: =VLOOKUP(B20,'[1]Pay sheet-APRIL- 2022'!$C$12:$AF$139,12,0) -> 13206.816 | AF20: =VLOOKUP(B20,'[1]Pay sheet-APRIL- 2022'!$C$12:$AF$139,13,0) -> 1944 | AG20: =VLOOKUP(B20,'[1]Pay sheet-APRIL- 2022'!$C$12:$AF$139,14,0) -> 1944 | AH20: =VLOOKUP(B20,'[1]Pay sheet-APRIL- 2022'!$C$12:$AF$139,15,0) -> 5029.544 | AI20: =AA20+AB20+AC20+AE20+AF20+AG20+AH20 -> 55141.4 | AJ20: =VLOOKUP(B20,'[1]Pay sheet-APRIL- 2022'!$C$12:$AF$139,18,0) -> 1554.609 | AK20: =VLOOKUP(B20,'[1]Pay sheet-APRIL- 2022'!$C$12:$AF$139,19,0) -> 1588.1196 | AL20: =VLOOKUP(B20,'[1]Pay sheet-APRIL- 2022'!$C$12:$AF$139,20,0) -> 2751.42 | AM20: 0 | AN20: =AI20+AJ20+AK20+AL20+AM20 -> 61035.549 | AO20: 0 | AP20: =VLOOKUP(B20,'[1]Pay sheet-APRIL- 2022'!$C$12:$AF$139,26,0) -> 1800 | AQ20: =VLOOKUP(B20,'[1]Pay sheet-APRIL- 2022'!$C$12:$AF$139,25,0) -> 200 | AR20: =VLOOKUP(B20,'[1]Pay sheet-APRIL- 2022'!$C$12:$AF$139,24,0) -> 0 | AS20: =VLOOKUP(B20,'[1]Pay sheet-APRIL- 2022'!$C$12:$AF$139,27,0) -> 254 | AT20: =AP20+AQ20+AR20+AS20 -> 2254 | AU20: =AN20-AT20 -> 58781.549 | AV20: 05.05.2022 | AW20: Union bank of India | AX20: 631302010000771 | BA20: 7
A21: 38 | B21: BITS-683 | C21: TUSHAR UCHAGAONKAR | D21: 33656 | E21: MALE | F21: Pundalik Uchagaonkar | G21: Network Engineer | H21: Plot No 5,Sy No 140,Parijath colony,Hindwadi,Belgam,Karnataka 590011 | I21: Plot No 5,Sy No 140,Parijath colony,Hindwadi,Belgam,Karnataka 590011 | L21: OOOO | M21: OOOO | N21: OOOO | O21: 44546 | T21: 100593810783 | U21: N/A | V21: TUSHAR UCHAGAONKAR | W21: 30 | X21: =VLOOKUP(B21,'[1]Pay sheet-APRIL- 2022'!$C$12:$AF$139,10,0) -> 30 | Y21: N/A | Z21: =VLOOKUP(B21,'[2]Pay sheet-JAN- 2021'!$C$18:$AF$125,6,0) -> 77497 | AA21: =VLOOKUP(B21,'[1]Pay sheet-APRIL- 2022'!$C$12:$AF$139,11,0) -> 46498.2 | AB21: 0 | AC21: 0 | AD21: =AE21+AF21+AG21+AH21 -> 31111.8 | AE21: =VLOOKUP(B21,'[1]Pay sheet-APRIL- 2022'!$C$12:$AF$139,12,0) -> 18599.28 | AF21: =VLOOKUP(B21,'[1]Pay sheet-APRIL- 2022'!$C$12:$AF$139,13,0) -> 2083 | AG21: =VLOOKUP(B21,'[1]Pay sheet-APRIL- 2022'!$C$12:$AF$139,14,0) -> 2083 | AH21: =VLOOKUP(B21,'[1]Pay sheet-APRIL- 2022'!$C$12:$AF$139,15,0) -> 8346.52 | AI21: =AA21+AB21+AC21+AE21+AF21+AG21+AH21 -> 77610 | AJ21: =VLOOKUP(B21,'[1]Pay sheet-APRIL- 2022'!$C$12:$AF$139,18,0) -> 1554.609 | AK21: =VLOOKUP(B21,'[1]Pay sheet-APRIL- 2022'!$C$12:$AF$139,19,0) -> 2236.5634 | AL21: =VLOOKUP(B21,'[1]Pay sheet-APRIL- 2022'!$C$12:$AF$139,20,0) -> 3874.85 | AM21: 0 | AN21: =AI21+AJ21+AK21+AL21+AM21 -> 85276.022 | AO21: 0 | AP21: =VLOOKUP(B21,'[1]Pay sheet-APRIL- 2022'!$C$12:$AF$139,26,0) -> 1800 | AQ21: =VLOOKUP(B21,'[1]Pay sheet-APRIL- 2022'!$C$12:$AF$139,25,0) -> 200 | AR21: =VLOOKUP(B21,'[1]Pay sheet-APRIL- 2022'!$C$12:$AF$139,24,0) -> 0 | AS21: =VLOOKUP(B21,'[1]Pay sheet-APRIL- 2022'!$C$12:$AF$139,27,0) -> 283 | AT21: =AP21+AQ21+AR21+AS21 -> 2283 | AU21: =AN21-AT21 -> 82993.022 | AV21: 05.05.2022 | AW21: ICICI BANK | AX21: 042401536750 | BA21: 8
A22: 39 | B22: BITS-692 | C22: Sneha Hande | D22: 09/11/1994 | E22: FEMALE | F22: Ramchandra Nathu Hande | G22: Project manager | H22: Ascendas,hinjawadi,phase 3 ,Hinjawadi Rajiv Gandhi Infotech Park. | I22: OOOO | J22: OOOO | K22: 35/A Hande niwas ,ganesh chawl,vasrang ,Khopoli,410203 | L22: OOOO | M22: OOOO | N22: OOOO | O22: 44566 | T22: 101257132190 | U22: N/A | V22: =C22 -> Sneha Hande | W22: 30 | X22: =VLOOKUP(B22,'[1]Pay sheet-APRIL- 2022'!$C$12:$AF$139,10,0) -> 30 | Y22: N/A | Z22: =VLOOKUP(B22,'[2]Pay sheet-JAN- 2021'!$C$18:$AF$125,6,0) -> 50617 | AA22: =VLOOKUP(B22,'[1]Pay sheet-APRIL- 2022'!$C$12:$AF$139,11,0) -> 30370.2 | AB22: 0 | AC22: 0 | AD22: =AE22+AF22+AG22+AH22 -> 20359.8 | AE22: =VLOOKUP(B22,'[1]Pay sheet-APRIL- 2022'!$C$12:$AF$139,12,0) -> 12148.08 | AF22: =VLOOKUP(B22,'[1]Pay sheet-APRIL- 2022'!$C$12:$AF$139,13,0) -> 2083 | AG22: =VLOOKUP(B22,'[1]Pay sheet-APRIL- 2022'!$C$12:$AF$139,14,0) -> 2083 | AH22: =VLOOKUP(B22,'[1]Pay sheet-APRIL- 2022'!$C$12:$AF$139,15,0) -> 4045.72 | AI22: =AA22+AB22+AC22+AE22+AF22+AG22+AH22 -> 50730 | AJ22: =VLOOKUP(B22,'[1]Pay sheet-APRIL- 2022'!$C$12:$AF$139,18,0) -> 1554.609 | AK22: =VLOOKUP(B22,'[1]Pay sheet-APRIL- 2022'!$C$12:$AF$139,19,0) -> 1460.8066 | AL22: =VLOOKUP(B22,'[1]Pay sheet-APRIL- 2022'!$C$12:$AF$139,20,0) -> 2530.85 | AM22: 0 | AN22: =AI22+AJ22+AK22+AL22+AM22 -> 56276.266 | AO22: 0 | AP22: =VLOOKUP(B22,'[1]Pay sheet-APRIL- 2022'!$C$12:$AF$139,26,0) -> 1800 | AQ22: =VLOOKUP(B22,'[1]Pay sheet-APRIL- 2022'!$C$12:$AF$139,25,0) -> 200 | AR22: =VLOOKUP(B22,'[1]Pay sheet-APRIL- 2022'!$C$12:$AF$139,24,0) -> 0 | AS22: =VLOOKUP(B22,'[1]Pay sheet-APRIL- 2022'!$C$12:$AF$139,27,0) -> 283 | AT22: =AP22+AQ22+AR22+AS22 -> 2283 | AU22: =AN22-AT22 -> 53993.266 | AV22: 05.05.2022 | AW22: ICICI BANK | AX22: 148001513263 | BA22: 9
A23: 40 | B23: BITS-698 | C23: Amol Gole | D23: 01/06/1991 | E23: MALE | F23: Harishchandra Gole | G23: Project Manager | H23: Shri ,Gurudatta krupa housing socity hill road, Sion,Chunabhatti ,Mumbai, Maharashtra, 400022 | I23: OOOO | J23: OOOO | K23: Nilgiri socity Building no 27,4th floor /4th room ,C-5,Sector 5, CBD Belapur ,Navi Mumbai, Maharashtra, 400614 | L23: OOOO | M23: OOOO | N23: OOOO | O23: 44579 | T23: 100769441289 | U23: N/A | V23: =C23 -> Amol Gole | W23: 30 | X23: =VLOOKUP(B23,'[1]Pay sheet-APRIL- 2022'!$C$12:$AF$139,10,0) -> 30 | Y23: N/A | Z23: =VLOOKUP(B23,'[2]Pay sheet-JAN- 2021'!$C$18:$AF$125,6,0) -> 66374 | AA23: =VLOOKUP(B23,'[1]Pay sheet-APRIL- 2022'!$C$12:$AF$139,11,0) -> 39824.4 | AB23: 0 | AC23: 0 | AD23: =AE23+AF23+AG23+AH23 -> 26662.6 | AE23: =VLOOKUP(B23,'[1]Pay sheet-APRIL- 2022'!$C$12:$AF$139,12,0) -> 15929.76 | AF23: =VLOOKUP(B23,'[1]Pay sheet-APRIL- 2022'!$C$12:$AF$139,13,0) -> 2083 | AG23: =VLOOKUP(B23,'[1]Pay sheet-APRIL- 2022'!$C$12:$AF$139,14,0) -> 2083 | AH23: =VLOOKUP(B23,'[1]Pay sheet-APRIL- 2022'!$C$12:$AF$139,15,0) -> 6566.84 | AI23: =AA23+AB23+AC23+AE23+AF23+AG23+AH23 -> 66487 | AJ23: =VLOOKUP(B23,'[1]Pay sheet-APRIL- 2022'!$C$12:$AF$139,18,0) -> 1554.609 | AK23: =VLOOKUP(B23,'[1]Pay sheet-APRIL- 2022'!$C$12:$AF$139,19,0) -> 1915.5536 | AL23: =VLOOKUP(B23,'[1]Pay sheet-APRIL- 2022'!$C$12:$AF$139,20,0) -> 3318.7 | AM23: 0 | AN23: =AI23+AJ23+AK23+AL23+AM23 -> 73275.863 | AO23: 0 | AP23: =VLOOKUP(B23,'[1]Pay sheet-APRIL- 2022'!$C$12:$AF$139,26,0) -> 1800 | AQ23: =VLOOKUP(B23,'[1]Pay sheet-APRIL- 2022'!$C$12:$AF$139,25,0) -> 200 | AR23: =VLOOKUP(B23,'[1]Pay sheet-APRIL- 2022'!$C$12:$AF$139,24,0) -> 0 | AS23: =VLOOKUP(B23,'[1]Pay sheet-APRIL- 2022'!$C$12:$AF$139,27,0) -> 283 | AT23: =AP23+AQ23+AR23+AS23 -> 2283 | AU23: =AN23-AT23 -> 70992.863 | AV23: 05.05.2022 | AW23: ICICI BANK | AX23: 623901548420 | BA23: 10
A24: 41 | B24: BITS-700 | C24: Sandeep Dixit | D24: 28764 | E24: MALE | F24: Surendra Singh | G24: Sr. Project Manager | H24: 782,sector 46 | I24: Gurgoan | J24: Haryana 122002 | K24: 782,Sector 46,Gurgaon,Haryana 122002 | L24: OOOO | M24: OOOO | N24: OOOO | O24: 44593 | T24: 100378934992 | U24: N/A | V24: Sandeep Dixit | W24: 30 | X24: =VLOOKUP(B24,'[1]Pay sheet-APRIL- 2022'!$C$12:$AF$139,10,0) -> 30 | Y24: N/A | Z24: 172968 | AA24: =VLOOKUP(B24,'[1]Pay sheet-APRIL- 2022'!$C$12:$AF$139,11,0) -> 103780.8 | AB24: 0 | AC24: 0 | AD24: =AE24+AF24+AG24+AH24 -> 69300.2 | AE24: =VLOOKUP(B24,'[1]Pay sheet-APRIL- 2022'!$C$12:$AF$139,12,0) -> 41512.32 | AF24: =VLOOKUP(B24,'[1]Pay sheet-APRIL- 2022'!$C$12:$AF$139,13,0) -> 2083 | AG24: =VLOOKUP(B24,'[1]Pay sheet-APRIL- 2022'!$C$12:$AF$139,14,0) -> 2083 | AH24: =VLOOKUP(B24,'[1]Pay sheet-APRIL- 2022'!$C$12:$AF$139,15,0) -> 23621.88 | AI24: =AA24+AB24+AC24+AE24+AF24+AG24+AH24 -> 173081 | AJ24: =VLOOKUP(B24,'[1]Pay sheet-APRIL- 2022'!$C$12:$AF$139,18,0) -> 1554.609 | AK24: =VLOOKUP(B24,'[1]Pay sheet-APRIL- 2022'!$C$12:$AF$139,19,0) -> 4991.8565 | AL24: =VLOOKUP(B24,'[1]Pay sheet-APRIL- 2022'!$C$12:$AF$139,20,0) -> 8648.4 | AM24: 0 | AN24: =AI24+AJ24+AK24+AL24+AM24 -> 188275.87 | AP24: =VLOOKUP(B24,'[1]Pay sheet-APRIL- 2022'!$C$12:$AF$139,26,0) -> 1800 | AQ24: =VLOOKUP(B24,'[1]Pay sheet-APRIL- 2022'!$C$12:$AF$139,25,0) -> 200 | AR24: =VLOOKUP(B24,'[1]Pay sheet-APRIL- 2022'!$C$12:$AF$139,24,0) -> 0 | AS24: =VLOOKUP(B24,'[1]Pay sheet-APRIL- 2022'!$C$12:$AF$139,27,0) -> 283 | AT24: =AP24+AQ24+AR24+AS24 -> 2283 | AU24: =AN24-AT24 -> 185992.87 | AV24: 05.05.2022 | AW24: Punjab National Bank | AX24: 12372191001001 | BA24: 11
A25: 42 | B25: BITS-717 | C25: Jaikesh Upadhyay | D25: 31778 | E25: MALE | F25: Ashok Upadhyay | G25: Sr. Project Coordinator | H25: H No 134,Pratap nagar | I25: Ratlam | J25: Madhya pradesh 457001 | K25: Sri vathsava house,SR no. 261/1/1,Sri dharshan colony,Kalvad road,Dhanori,Pune,MH,411015 | L25: OOOO | M25: OOOO | N25: OOOO | O25: 44609 | T25: 100448275999 | U25: N/A | V25: Jaikesh Upadhyay | W25: 30 | X25: =VLOOKUP(B25,'[1]Pay sheet-APRIL- 2022'!$C$12:$AF$139,10,0) -> 30 | Y25: N/A | Z25: 112719 | AA25: =VLOOKUP(B25,'[1]Pay sheet-APRIL- 2022'!$C$12:$AF$139,11,0) -> 67631.4 | AB25: 0 | AC25: 0 | AD25: =AE25+AF25+AG25+AH25 -> 45200.6 | AE25: =VLOOKUP(B25,'[1]Pay sheet-APRIL- 2022'!$C$12:$AF$139,12,0) -> 27052.56 | AF25: =VLOOKUP(B25,'[1]Pay sheet-APRIL- 2022'!$C$12:$AF$139,13,0) -> 2083 | AG25: =VLOOKUP(B25,'[1]Pay sheet-APRIL- 2022'!$C$12:$AF$139,14,0) -> 2083 | AH25: =VLOOKUP(B25,'[1]Pay sheet-APRIL- 2022'!$C$12:$AF$139,15,0) -> 13982.04 | AI25: =AA25+AB25+AC25+AE25+AF25+AG25+AH25 -> 112832 | AJ25: =VLOOKUP(B25,'[1]Pay sheet-APRIL- 2022'!$C$12:$AF$139,18,0) -> 1554.609 | AK25: =VLOOKUP(B25,'[1]Pay sheet-APRIL- 2022'!$C$12:$AF$139,19,0) -> 3253.0703 | AL25: =VLOOKUP(B25,'[1]Pay sheet-APRIL- 2022'!$C$12:$AF$139,20,0) -> 5635.95 | AM25: 0 | AN25: =AI25+AJ25+AK25+AL25+AM25 -> 123275.63 | AP25: =VLOOKUP(B25,'[1]Pay sheet-APRIL- 2022'!$C$12:$AF$139,26,0) -> 1800 | AQ25: =VLOOKUP(B25,'[1]Pay sheet-APRIL- 2022'!$C$12:$AF$139,25,0) -> 200 | AR25: =VLOOKUP(B25,'[1]Pay sheet-APRIL- 2022'!$C$12:$AF$139,24,0) -> 0 | AS25: =VLOOKUP(B25,'[1]Pay sheet-APRIL- 2022'!$C$12:$AF$139,27,0) -> 283 | AT25: =AP25+AQ25+AR25+AS25 -> 2283 | AU25: =AN25-AT25 -> 120992.63 | AV25: 05.05.2022 | AW25: ICICI BANK | AX25: 338201500480 | BA25: 12
A26: 43 | B26: BITS-720 | C26: Jyoti Singh | D26: 34895 | E26: FEMALE | F26: Ashok Kumar Singh | G26: Sr.Security analyst | H26: Room F1,C 38,Sai apartments,JBTS gardens,Chhatrapur,New Delhi 110074 | I26: JBTS gardens,Chhatrapur | J26: New Delhi 110074 | K26: Room F1,C 38,Sai apartments,JBTS gardens,Chhatrapur,New Delhi 110074 | L26: OOOO | M26: OOOO | N26: OOOO | O26: 44613 | T26: OOOO | U26: N/A | V26: Jyoti Singh | W26: 30 | X26: =VLOOKUP(B26,'[1]Pay sheet-APRIL- 2022'!$C$12:$AF$139,10,0) -> 30 | Y26: N/A | Z26: 103450 | AA26: =VLOOKUP(B26,'[1]Pay sheet-APRIL- 2022'!$C$12:$AF$139,11,0) -> 62070 | AB26: 0 | AC26: 0 | AD26: =AE26+AF26+AG26+AH26 -> 41493 | AE26: =VLOOKUP(B26,'[1]Pay sheet-APRIL- 2022'!$C$12:$AF$139,12,0) -> 24828 | AF26: =VLOOKUP(B26,'[1]Pay sheet-APRIL- 2022'!$C$12:$AF$139,13,0) -> 2083 | AG26: =VLOOKUP(B26,'[1]Pay sheet-APRIL- 2022'!$C$12:$AF$139,14,0) -> 2083 | AH26: =VLOOKUP(B26,'[1]Pay sheet-APRIL- 2022'!$C$12:$AF$139,15,0) -> 12499 | AI26: =AA26+AB26+AC26+AE26+AF26+AG26+AH26 -> 103563 | AJ26: =VLOOKUP(B26,'[1]Pay sheet-APRIL- 2022'!$C$12:$AF$139,18,0) -> 1554.609 | AK26: =VLOOKUP(B26,'[1]Pay sheet-APRIL- 2022'!$C$12:$AF$139,19,0) -> 2985.567 | AL26: =VLOOKUP(B26,'[1]Pay sheet-APRIL- 2022'!$C$12:$AF$139,20,0) -> 5172.5 | AM26: 0 | AN26: =AI26+AJ26+AK26+AL26+AM26 -> 113275.68 | AP26: =VLOOKUP(B26,'[1]Pay sheet-APRIL- 2022'!$C$12:$AF$139,26,0) -> 0 | AQ26: =VLOOKUP(B26,'[1]Pay sheet-APRIL- 2022'!$C$12:$AF$139,25,0) -> 200 | AR26: =VLOOKUP(B26,'[1]Pay sheet-APRIL- 2022'!$C$12:$AF$139,24,0) -> 0 | AS26: =VLOOKUP(B26,'[1]Pay sheet-APRIL- 2022'!$C$12:$AF$139,27,0) -> 283 | AT26: =AP26+AQ26+AR26+AS26 -> 483 | AU26: =AN26-AT26 -> 112792.68 | AV26: 05.05.2022 | AW26: ICICI BANK | AX26: 341901505420 | BA26: 13
A27: 44 | B27: BITS-733 | C27: Chandrashekar Patil | D27: 34710 | E27: MALE | F27: Shivraj Patil | G27: Project Manager | H27: At post Malegaon,Maqta,Taluq Deglur,Nanded district,Maharastra 431718 | I27: Q-198,Govt Quarters,Sastry nagar,Erawada,Pune 411006 | J27: qqqq | K27: qqqq | L27: qqqq | M27: qqqq | N27: qqqq | O27: 44634 | T27: 100783283673 | U27: N/A | V27: Chandrashekar Patil | W27: 30 | X27: =VLOOKUP(B27,'[1]Pay sheet-APRIL- 2022'!$C$12:$AF$139,10,0) -> 27 | Y27: N/A | Z27: 73789 | AA27: =VLOOKUP(B27,'[1]Pay sheet-APRIL- 2022'!$C$12:$AF$139,11,0) -> 39846.06 | AB27: 0 | AC27: 0 | AD27: =AE27+AF27+AG27+AH27 -> 26677.04 | AE27: =VLOOKUP(B27,'[1]Pay sheet-APRIL- 2022'!$C$12:$AF$139,12,0) -> 15938.424 | AF27: =VLOOKUP(B27,'[1]Pay sheet-APRIL- 2022'!$C$12:$AF$139,13,0) -> 1875 | AG27: =VLOOKUP(B27,'[1]Pay sheet-APRIL- 2022'!$C$12:$AF$139,14,0) -> 1875 | AH27: =VLOOKUP(B27,'[1]Pay sheet-APRIL- 2022'!$C$12:$AF$139,15,0) -> 6988.616 | AI27: =AA27+AB27+AC27+AE27+AF27+AG27+AH27 -> 66523.1 | AJ27: =VLOOKUP(B27,'[1]Pay sheet-APRIL- 2022'!$C$12:$AF$139,18,0) -> 1554.609 | AK27: =VLOOKUP(B27,'[1]Pay sheet-APRIL- 2022'!$C$12:$AF$139,19,0) -> 1916.5955 | AL27: =VLOOKUP(B27,'[1]Pay sheet-APRIL- 2022'!$C$12:$AF$139,20,0) -> 3320.505 | AM27: 0 | AN27: =AI27+AJ27+AK27+AL27+AM27 -> 73314.809 | AP27: =VLOOKUP(B27,'[1]Pay sheet-APRIL- 2022'!$C$12:$AF$139,26,0) -> 1800 | AQ27: =VLOOKUP(B27,'[1]Pay sheet-APRIL- 2022'!$C$12:$AF$139,25,0) -> 200 | AR27: =VLOOKUP(B27,'[1]Pay sheet-APRIL- 2022'!$C$12:$AF$139,24,0) -> 0 | AS27: =VLOOKUP(B27,'[1]Pay sheet-APRIL- 2022'!$C$12:$AF$139,27,0) -> 283 | AT27: =AP27+AQ27+AR27+AS27 -> 2283 | AU27: =AN27-AT27 -> 71031.809 | AV27: 05.05.2022 | AW27: HDFC | AX27: 100783283673 | BA27: 14
A28: 45 | B28: BITS-734 | C28: ShaikFarooq Basha | D28: 33370 | E28: MALE | F28: Shaik Mabu Subahan | G28: Software Engineer | H28: 2-112,Kakkalapally colony,Ananthapur,AP 515001 | I28: 2-112,Kakkalapally colony,Ananthapur,AP 515001 | J28: qqqq | K28: qqqq | L28: qqqq | M28: qqqq | N28: qqqq | O28: 44636 | T28: 101625103757 | U28: N/A | V28: ShaikFarooq Basha | W28: 30 | X28: =VLOOKUP(B28,'[1]Pay sheet-APRIL- 2022'!$C$12:$AF$139,10,0) -> 30 | Y28: N/A | Z28: 103450 | AA28: =VLOOKUP(B28,'[1]Pay sheet-APRIL- 2022'!$C$12:$AF$139,11,0) -> 62070 | AB28: 0 | AC28: 0 | AD28: =AE28+AF28+AG28+AH28 -> 41493 | AE28: =VLOOKUP(B28,'[1]Pay sheet-APRIL- 2022'!$C$12:$AF$139,12,0) -> 24828 | AF28: =VLOOKUP(B28,'[1]Pay sheet-APRIL- 2022'!$C$12:$AF$139,13,0) -> 2083 | AG28: =VLOOKUP(B28,'[1]Pay sheet-APRIL- 2022'!$C$12:$AF$139,14,0) -> 2083 | AH28: =VLOOKUP(B28,'[1]Pay sheet-APRIL- 2022'!$C$12:$AF$139,15,0) -> 12499 | AI28: =AA28+AB28+AC28+AE28+AF28+AG28+AH28 -> 103563 | AJ28: =VLOOKUP(B28,'[1]Pay sheet-APRIL- 2022'!$C$12:$AF$139,18,0) -> 1554.609 | AK28: =VLOOKUP(B28,'[1]Pay sheet-APRIL- 2022'!$C$12:$AF$139,19,0) -> 2985.567 | AL28: =VLOOKUP(B28,'[1]Pay sheet-APRIL- 2022'!$C$12:$AF$139,20,0) -> 5172.5 | AM28: 0 | AN28: =AI28+AJ28+AK28+AL28+AM28 -> 113275.68 | AP28: =VLOOKUP(B28,'[1]Pay sheet-APRIL- 2022'!$C$12:$AF$139,26,0) -> 1800 | AQ28: =VLOOKUP(B28,'[1]Pay sheet-APRIL- 2022'!$C$12:$AF$139,25,0) -> 200 | AR28: =VLOOKUP(B28,'[1]Pay sheet-APRIL- 2022'!$C$12:$AF$139,24,0) -> 7419 | AS28: =VLOOKUP(B28,'[1]Pay sheet-APRIL- 2022'!$C$12:$AF$139,27,0) -> 283 | AT28: =AP28+AQ28+AR28+AS28 -> 9702 | AU28: =AN28-AT28 -> 103573.68 | AV28: 05.05.2022 | AW28: HDFC | AX28: 50100383537784 | BA28: 15
A29: 46 | B29: BITS-738 | C29: NILOTPAL BHOWAL | D29: 31584 | E29: MALE | F29: Dwijendra Kumar Bhowal | G29: VM ware consultant | H29: P-53,Niva park extension,Badam Talad,Brahmapur,Kolkatta-700096 | I29: Sri laxmi PG narayan nagar,Hinjewadi phase I,Pune 411057 | J29: qqqq | K29: qqqq | L29: qqqq | M29: qqqq | N29: qqqq | O29: 44650 | T29: 101804644762 | U29: N/A | V29: NILOTPAL BHOWAL | W29: 30 | X29: =VLOOKUP(B29,'[1]Pay sheet-APRIL- 2022'!$C$12:$AF$139,10,0) -> 30 | Y29: N/A | Z29: 121988 | AA29: =VLOOKUP(B29,'[1]Pay sheet-APRIL- 2022'!$C$12:$AF$139,11,0) -> 73192.8 | AB29: 0 | AC29: 0 | AD29: =AE29+AF29+AG29+AH29 -> 48908.2 | AE29: =VLOOKUP(B29,'[1]Pay sheet-APRIL- 2022'!$C$12:$AF$139,12,0) -> 29277.12 | AF29: =VLOOKUP(B29,'[1]Pay sheet-APRIL- 2022'!$C$12:$AF$139,13,0) -> 2083 | AG29: =VLOOKUP(B29,'[1]Pay sheet-APRIL- 2022'!$C$12:$AF$139,14,0) -> 2083 | AH29: =VLOOKUP(B29,'[1]Pay sheet-APRIL- 2022'!$C$12:$AF$139,15,0) -> 15465.08 | AI29: =AA29+AB29+AC29+AE29+AF29+AG29+AH29 -> 122101 | AJ29: =VLOOKUP(B29,'[1]Pay sheet-APRIL- 2022'!$C$12:$AF$139,18,0) -> 1554.609 | AK29: =VLOOKUP(B29,'[1]Pay sheet-APRIL- 2022'!$C$12:$AF$139,19,0) -> 3520.5737 | AL29: =VLOOKUP(B29,'[1]Pay sheet-APRIL- 2022'!$C$12:$AF$139,20,0) -> 6099.4 | AM29: 0 | AN29: =AI29+AJ29+AK29+AL29+AM29 -> 133275.58 | AP29: =VLOOKUP(B29,'[1]Pay sheet-APRIL- 2022'!$C$12:$AF$139,26,0) -> 1800 | AQ29: =VLOOKUP(B29,'[1]Pay sheet-APRIL- 2022'!$C$12:$AF$139,25,0) -> 200 | AR29: =VLOOKUP(B29,'[1]Pay sheet-APRIL- 2022'!$C$12:$AF$139,24,0) -> 0 | AS29: =VLOOKUP(B29,'[1]Pay sheet-APRIL- 2022'!$C$12:$AF$139,27,0) -> 283 | AT29: =AP29+AQ29+AR29+AS29 -> 2283 | AU29: =AN29-AT29 -> 130992.58 | AV29: 05.05.2022 | AW29: ICICI bank | AX29: 272301504703 | BA29: 16
A30: 47 | B30: BITS-751 | C30: Varsha Amit Kadam | D30: 31018 | E30: FEMALE | F30: Amit Kadam | G30: Program Manager | H30: 1/87,Ramdut building,currey Road,Mumbai | I30: Mumbai | J30: Maharastra 400012 | K30: Flat No.204,Melody Appts,Waked | L30: Pune | M30: Maharastra | N30: 411057 | O30: 44676 | T30: 101012347096 | U30: N/A | V30: Varsha AmitKadam | W30: 30 | X30: =VLOOKUP(B30,'[1]Pay sheet-APRIL- 2022'!$C$12:$AF$139,10,0) -> 6 | Z30: 54324 | AA30: =VLOOKUP(B30,'[1]Pay sheet-APRIL- 2022'!$C$12:$AF$139,11,0) -> 6518.88 | AB30: 0 | AC30: 0 | AE30: =VLOOKUP(B30,'[1]Pay sheet-APRIL- 2022'!$C$12:$AF$139,12,0) -> 2607.552 | AF30: =VLOOKUP(B30,'[1]Pay sheet-APRIL- 2022'!$C$12:$AF$139,13,0) -> 417 | AG30: =VLOOKUP(B30,'[1]Pay sheet-APRIL- 2022'!$C$12:$AF$139,14,0) -> 417 | AH30: =VLOOKUP(B30,'[1]Pay sheet-APRIL- 2022'!$C$12:$AF$139,15,0) -> 1017.368 | AI30: =AA30+AB30+AC30+AE30+AF30+AG30+AH30 -> 10977.8 | AJ30: =VLOOKUP(B30,'[1]Pay sheet-APRIL- 2022'!$C$12:$AF$139,18,0) -> 1554.609 | AK30: =VLOOKUP(B30,'[1]Pay sheet-APRIL- 2022'!$C$12:$AF$139,19,0) -> 313.55813 | AL30: =VLOOKUP(B30,'[1]Pay sheet-APRIL- 2022'!$C$12:$AF$139,20,0) -> 543.24 | AM30: 0 | AN30: =AI30+AJ30+AK30+AL30+AM30 -> 13389.207 | AP30: =VLOOKUP(B30,'[1]Pay sheet-APRIL- 2022'!$C$12:$AF$139,26,0) -> 782 | AQ30: =VLOOKUP(B30,'[1]Pay sheet-APRIL- 2022'!$C$12:$AF$139,25,0) -> 0 | AR30: =VLOOKUP(B30,'[1]Pay sheet-APRIL- 2022'!$C$12:$AF$139,24,0) -> 0 | AS30: =VLOOKUP(B30,'[1]Pay sheet-APRIL- 2022'!$C$12:$AF$139,27,0) -> 0 | AT30: =AP30+AQ30+AR30+AS30 -> 782 | AU30: =AN30-AT30 -> 12607.207 | AV30: 05.05.2022 | AW30: Kotak Mahindra Bank | AX30: 7311156365
X31: =SUM(X17:X30) -> 380 | AA31: =SUM(AA17:AA30) -> 655324.54 | AE31: =SUM(AE17:AE30) -> 262129.82 | AF31: =SUM(AF17:AF30) -> 26386 | AG31: =SUM(AG17:AG30) -> 26386 | AH31: =SUM(AH17:AH30) -> 123563.21 | AI31: =SUM(AI17:AI30) -> 1093789.6 | AJ31: =SUM(AJ17:AJ30) -> 21764.526 | AK31: =SUM(AK17:AK30) -> 31521.11 | AL31: =SUM(AL17:AL30) -> 54610.378 | AP31: =SUM(AP17:AP30) -> 22382 | AQ31: =SUM(AQ17:AQ30) -> 2600 | AR31: =SUM(AR17:AR30) -> 7419 | AS31: =SUM(AS17:AS30) -> 4025.337 | AT31: =SUM(AT17:AT30) -> 36426.337 | AU31: =SUM(AU17:AU30) -> 1165259.2
A39: 24 | B39: BITS-556 | D39: 33030 | E39: MALE | F39: Ashok Bhavisar | H39: Mukam post, Kanalda,Taluka,Jalgaon, Kanvashramroad, new Busstand, Kanalde, Jalgaon,MH 425002 | K39: Mukam post, Kanalda,Taluka,Jalgaon, Kanvashramroad, new Busstand, Kanalde, Jalgaon,MH 425002 | O39: 4th May 2021 | T39: 100973367737 | U39: N/A | V39: =C39 -> 0 | W39: 31 | X39: =VLOOKUP(B39,'[3]Pay sheet-MARCH- 2022'!$C$13:$AF$146,10,0) -> 16 | Y39: N/A | Z39: =VLOOKUP(B39,'[2]Pay sheet-JAN- 2021'!$C$18:$AF$125,6,0) -> 68228 | AA39: =VLOOKUP(B39,'[3]Pay sheet-MARCH- 2022'!$C$13:$AF$146,11,0) -> 21128.671 | AB39: 0 | AC39: 0 | AD39: =AE39+AF39+AG39+AH39 -> 14085.781 | AE39: =VLOOKUP(B39,'[3]Pay sheet-MARCH- 2022'!$C$13:$AF$146,12,0) -> 8451.4684 | AF39: =VLOOKUP(B39,'[3]Pay sheet-MARCH- 2022'!$C$13:$AF$146,13,0) -> 1075 | AG39: =VLOOKUP(B39,'[3]Pay sheet-MARCH- 2022'!$C$13:$AF$146,14,0) -> 1075 | AH39: =VLOOKUP(B39,'[3]Pay sheet-MARCH- 2022'!$C$13:$AF$146,15,0) -> 3484.3123 | AI39: =AA39+AB39+AC39+AE39+AF39+AG39+AH39 -> 35214.452 | AJ39: =VLOOKUP(B39,'[3]Pay sheet-MARCH- 2022'!$C$13:$AF$146,18,0) -> 1441.609 | AK39: =VLOOKUP(B39,'[3]Pay sheet-MARCH- 2022'!$C$13:$AF$146,19,0) -> 1016.2891 | AL39: =VLOOKUP(B39,'[3]Pay sheet-MARCH- 2022'!$C$13:$AF$146,20,0) -> 1760.7226 | AM39: =VLOOKUP(B39,'[3]Pay sheet-MARCH- 2022'!$C$13:$AF$146,22,0) -> #REF! | AO39: 0 | AP39: =VLOOKUP(B39,'[3]Pay sheet-MARCH- 2022'!$C$13:$AF$146,26,0) -> 1800 | AQ39: =VLOOKUP(B39,'[3]Pay sheet-MARCH- 2022'!$C$13:$AF$146,25,0) -> 200 | AR39: =VLOOKUP(B39,'[3]Pay sheet-MARCH- 2022'!$C$13:$AF$146,24,0) -> 3232 | AS39: =VLOOKUP(B39,'[3]Pay sheet-MARCH- 2022'!$C$13:$AF$146,27,0) -> 391.78785 | AT39: =AP39+AQ39+AR39+AS39 -> 5623.7878 | AU39: =AN39-AT39 -> -5623.7878 | AV39: 05.05.2022 | AW39: SBI | AX39: A/C'20163843796 | BA39: 2
A40: 33 | B40: BITS-651 | D40: 32523 | E40: FEMALE | F40: Sumit Dongare | H40: Pno.22A Snehswapna Padma Colony Opp SSC Board Kolhapur 416008 | K40: MB92 New Indira colony Near public school Burhanpur 450331 | L40: OO | M40: OO | N40: OO | O40: 44481 | T40: 100812322217 | U40: N/A | V40: Snehal Shirsat | W40: 31 | X40: =VLOOKUP(B40,'[3]Pay sheet-MARCH- 2022'!$C$13:$AF$146,10,0) -> 31 | Y40: N/A | Z40: =VLOOKUP(B40,'[2]Pay sheet-JAN- 2021'!$C$18:$AF$125,6,0) -> 58959 | AA40: =VLOOKUP(B40,'[3]Pay sheet-MARCH- 2022'!$C$13:$AF$146,11,0) -> 35375.4 | AB40: 0 | AC40: 0 | AD40: =AE40+AF40+AG40+AH40 -> 23583.6 | AE40: =VLOOKUP(B40,'[3]Pay sheet-MARCH- 2022'!$C$13:$AF$146,12,0) -> 14150.16 | AF40: =VLOOKUP(B40,'[3]Pay sheet-MARCH- 2022'!$C$13:$AF$146,13,0) -> 2083 | AG40: =VLOOKUP(B40,'[3]Pay sheet-MARCH- 2022'!$C$13:$AF$146,14,0) -> 2083 | AH40: =VLOOKUP(B40,'[3]Pay sheet-MARCH- 2022'!$C$13:$AF$146,15,0) -> 5267.44 | AI40: =AA40+AB40+AC40+AE40+AF40+AG40+AH40 -> 58959 | AJ40: =VLOOKUP(B40,'[3]Pay sheet-MARCH- 2022'!$C$13:$AF$146,18,0) -> 1441.609 | AK40: =VLOOKUP(B40,'[3]Pay sheet-MARCH- 2022'!$C$13:$AF$146,19,0) -> 1701.5567 | AL40: =VLOOKUP(B40,'[3]Pay sheet-MARCH- 2022'!$C$13:$AF$146,20,0) -> 2947.95 | AM40: =VLOOKUP(B40,'[3]Pay sheet-MARCH- 2022'!$C$13:$AF$146,22,0) -> #REF! | AO40: 0 | AP40: =VLOOKUP(B40,'[3]Pay sheet-MARCH- 2022'!$C$13:$AF$146,26,0) -> 1800 | AQ40: =VLOOKUP(B40,'[3]Pay sheet-MARCH- 2022'!$C$13:$AF$146,25,0) -> 200 | AR40: =VLOOKUP(B40,'[3]Pay sheet-MARCH- 2022'!$C$13:$AF$146,24,0) -> #REF! | AS40: =VLOOKUP(B40,'[3]Pay sheet-MARCH- 2022'!$C$13:$AF$146,27,0) -> 254 | AT40: =AP40+AQ40+AR40+AS40 -> #REF! | AU40: =AN40-AT40 -> #REF! | AV40: 05.05.2022 | AW40: HDFC BANK | AX40: 50100083666209 | BA40: 5
A41: 34 | B41: BITS-657 | D41: 33253 | E41: FEMALE | F41: sharad shukla | H41: 15/A chandra colony Rajanandgaon Chhattisgarh | K41: 15/A chandra colony Rajanandgaon Chhattisgarh | L41: OO | M41: OO | N41: OO | O41: 44481 | T41: 100533606039 | U41: N/A | V41: Shashanki Mishra | W41: 31 | X41: =VLOOKUP(B41,'[3]Pay sheet-MARCH- 2022'!$C$13:$AF$146,10,0) -> 15 | Y41: N/A | Z41: =VLOOKUP(B41,'[2]Pay sheet-JAN- 2021'!$C$18:$AF$125,6,0) -> 47836 | AA41: =VLOOKUP(B41,'[3]Pay sheet-MARCH- 2022'!$C$13:$AF$146,11,0) -> 13887.871 | AB41: 0 | AC41: 0 | AD41: =AE41+AF41+AG41+AH41 -> 9258.5806 | AE41: =VLOOKUP(B41,'[3]Pay sheet-MARCH- 2022'!$C$13:$AF$146,12,0) -> 5555.1484 | AF41: =VLOOKUP(B41,'[3]Pay sheet-MARCH- 2022'!$C$13:$AF$146,13,0) -> 1008 | AG41: =VLOOKUP(B41,'[3]Pay sheet-MARCH- 2022'!$C$13:$AF$146,14,0) -> 1008 | AH41: =VLOOKUP(B41,'[3]Pay sheet-MARCH- 2022'!$C$13:$AF$146,15,0) -> 1687.4323 | AI41: =AA41+AB41+AC41+AE41+AF41+AG41+AH41 -> 23146.452 | AJ41: =VLOOKUP(B41,'[3]Pay sheet-MARCH- 2022'!$C$13:$AF$146,18,0) -> 1441.609 | AK41: =VLOOKUP(B41,'[3]Pay sheet-MARCH- 2022'!$C$13:$AF$146,19,0) -> 668.00659 | AL41: =VLOOKUP(B41,'[3]Pay sheet-MARCH- 2022'!$C$13:$AF$146,20,0) -> 1157.3226 | AM41: =VLOOKUP(B41,'[3]Pay sheet-MARCH- 2022'!$C$13:$AF$146,22,0) -> #REF! | AO41: 0 | AP41: =VLOOKUP(B41,'[3]Pay sheet-MARCH- 2022'!$C$13:$AF$146,26,0) -> 1667 | AQ41: =VLOOKUP(B41,'[3]Pay sheet-MARCH- 2022'!$C$13:$AF$146,25,0) -> 200 | AR41: =VLOOKUP(B41,'[3]Pay sheet-MARCH- 2022'!$C$13:$AF$146,24,0) -> #REF! | AS41: =VLOOKUP(B41,'[3]Pay sheet-MARCH- 2022'!$C$13:$AF$146,27,0) -> 254 | AT41: =AP41+AQ41+AR41+AS41 -> #REF! | AU41: =AN41-AT41 -> #REF! | AV41: 05.05.2022 | AW41: ICIC | AX41: 624001562353 | BA41: 6

Sheet 4-22Eq Rrem
A1: Form D
A2: (See rule 6)
A4: Register to be maintained by the employer under rule 6 of the Equal Remuneration Rules, 1976
E6: ='4-22MASTER'!E10 -> 44652
A8: Name and address of Contractor : | G8: ='4-22MASTER'!G5 -> Burgeon IT Services Pvt.Ltd.
A10: Name and address of establishment in/under which contract is carried on : | G10: ='4-22MASTER'!AQ5 -> Burgeon IT Services Pvt.Ltd.
G11: ='4-22MASTER'!AQ6 -> Siri Mansion LIGB 436 Dr.A S Rao Nagar,Hyderabad
A12: Name and address of Principal Employer : | G12: ='4-22MASTER'!AQ10 -> INFOSYS LTD.IL Ascendas SEZ Unit,Building Juniper
G13: ='4-22MASTER'!AQ11 -> International Tech Park,Rajiv Gandhi Infotech Park,Hinjawadi,Pune,Maharashtra
A14: Total number of men workers employed | D14: =E34 -> 10
A16: Total number of women workers employed | D16: =D34 -> 4
D18: Components of remuneration
A19: Category of workers | B19: Brief Description of work | D19: No of women employed | E19: No. of men employed | F19: Rate or remuneration paid | G19: Basic wage & Dearness Allowance | H19: House Rent allowance | I19: Other allowances | J19: Cash value of concessional supply of essential commodities | K19: Name of the Client | L19: Primary Work Place/ Location
A20: ='4-22MASTER'!G17 -> System Administrator | B20: IT SUPPORTIVE SERVICES | D20: 0 | E20: 1 | F20: ='4-22MASTER'!Z17 -> 61740 | G20: ='4-22MASTER'!AA17 -> 37044 | H20: ='4-22MASTER'!AE17 -> 14817.6 | I20: =F20-(G20+H20) -> 9878.4 | J20: 0
A21: ='4-22MASTER'!G18 -> Project Manager | B21: IT SUPPORTIVE SERVICES | D21: 0 | E21: 1 | F21: ='4-22MASTER'!Z18 -> 71009 | G21: ='4-22MASTER'!AA18 -> 28403.6 | H21: ='4-22MASTER'!AE18 -> 11361.44 | I21: =F21-(G21+H21) -> 31243.96 | J21: 0
A22: ='4-22MASTER'!G19 -> Project Coordinator | B22: IT SUPPORTIVE SERVICES | D22: 0 | E22: 1 | F22: ='4-22MASTER'!Z19 -> 43202 | G22: ='4-22MASTER'!AA19 -> 25057.16 | H22: ='4-22MASTER'!AE19 -> 10022.864 | I22: =F22-(G22+H22) -> 8121.976 | J22: 0
A23: ='4-22MASTER'!G20 -> Project Engineer | B23: IT SUPPORTIVE SERVICES | D23: 1 | E23: 0 | F23: ='4-22MASTER'!Z20 -> 58959 | G23: ='4-22MASTER'!AA20 -> 33017.04 | H23: ='4-22MASTER'!AE20 -> 13206.816 | I23: =F23-(G23+H23) -> 12735.144 | J23: 0
A24: ='4-22MASTER'!G21 -> Network Engineer | B24: IT SUPPORTIVE SERVICES | D24: 0 | E24: 1 | F24: ='4-22MASTER'!Z21 -> 77497 | G24: ='4-22MASTER'!AA21 -> 46498.2 | H24: ='4-22MASTER'!AE21 -> 18599.28 | I24: =F24-(G24+H24) -> 12399.52 | J24: 0
A25: ='4-22MASTER'!G22 -> Project manager | B25: IT SUPPORTIVE SERVICES | D25: 1 | E25: 0 | F25: ='4-22MASTER'!Z22 -> 50617 | G25: ='4-22MASTER'!AA22 -> 30370.2 | H25: ='4-22MASTER'!AE22 -> 12148.08 | I25: =F25-(G25+H25) -> 8098.72 | J25: 0
A26: ='4-22MASTER'!G23 -> Project Manager | B26: IT SUPPORTIVE SERVICES | D26: 0 | E26: 1 | F26: ='4-22MASTER'!Z23 -> 66374 | G26: ='4-22MASTER'!AA23 -> 39824.4 | H26: ='4-22MASTER'!AE23 -> 15929.76 | I26: =F26-(G26+H26) -> 10619.84 | J26: 0
A27: ='4-22MASTER'!G24 -> Sr. Project Manager | B27: IT SUPPORTIVE SERVICES | D27: 0 | E27: 1 | F27: ='4-22MASTER'!Z24 -> 172968 | G27: ='4-22MASTER'!AA24 -> 103780.8 | H27: ='4-22MASTER'!AE24 -> 41512.32 | I27: =F27-(G27+H27) -> 27674.88 | J27: 0
A28: ='4-22MASTER'!G25 -> Sr. Project Coordinator | B28: IT SUPPORTIVE SERVICES | D28: 0 | E28: 1 | F28: ='4-22MASTER'!Z25 -> 112719 | G28: ='4-22MASTER'!AA25 -> 67631.4 | H28: ='4-22MASTER'!AE25 -> 27052.56 | I28: =F28-(G28+H28) -> 18035.04 | J28: 0
A29: ='4-22MASTER'!G26 -> Sr.Security analyst | B29: IT SUPPORTIVE SERVICES | D29: 1 | E29: 0 | F29: ='4-22MASTER'!Z26 -> 103450 | G29: ='4-22MASTER'!AA26 -> 62070 | H29: ='4-22MASTER'!AE26 -> 24828 | I29: =F29-(G29+H29) -> 16552 | J29: 0
A30: ='4-22MASTER'!G27 -> Project Manager | B30: IT SUPPORTIVE SERVICES | D30: 0 | E30: 1 | F30: ='4-22MASTER'!Z27 -> 73789 | G30: ='4-22MASTER'!AA27 -> 39846.06 | H30: ='4-22MASTER'!AE27 -> 15938.424 | I30: =F30-(G30+H30) -> 18004.516 | J30: 0
A31: ='4-22MASTER'!G28 -> Software Engineer | B31: IT SUPPORTIVE SERVICES | D31: 0 | E31: 1 | F31: ='4-22MASTER'!Z28 -> 103450 | G31: ='4-22MASTER'!AA28 -> 62070 | H31: ='4-22MASTER'!AE28 -> 24828 | I31: =F31-(G31+H31) -> 16552 | J31: 0
... A33: ='4-22MASTER'!G30 -> Program Manager | B33: IT SUPPORTIVE SERVICES | D33: 1 | E33: 0 | F33: ='4-22MASTER'!Z30 -> 54324 | G33: ='4-22MASTER'!AA30 -> 6518.88 | H33: ='4-22MASTER'!AE30 -> 2607.552 | I33: =F33-(G33+H33) -> 45197.568 | J33: 0
D34: =SUM(D20:D33) -> 4 | E34: =SUM(E20:E33) -> 10
F48: Signature of the Contractor with Seal

Sheet APRIL  22 MH_MusT
A1: Form No. II
A2: [M. W. Rules under Maharashtra Contract Labour (Regulation and Abolition)1963 Rule 27 (I)]
A3: Muster Roll cum Wages Register for the month of APRIL 2022
A4: Name and Address of Contractor : BURGEON IT SERVICES PVT.LTD. SIRI MANSION LIG 436 DR.A S RAO NAGAR,HYDERABAD 500 060
H5: Working Hours | J5: Interval for Rest | L5: No. of Hours Worked
A6: Sl.No. | B6: Employee Code | C6: Full Name of Employee | D6: Date of Birth | E6: Gender | F6: Date of Entry into Service | G6: Nature of Work & Designation | H6: From | I6: To | J6: From | K6: To | L6: 1 | M6: 2 | N6: 3 | O6: 4 | P6: 5 | Q6: 6 | R6: 7 | S6: 8 | T6: 9 | U6: 10 | V6: 11 | W6: 12 | X6: 13 | Y6: 14 | Z6: 15 | AA6: 16 | AB6: 17 | AC6: 18 | AD6: 19 | AE6: 20 | AF6: 21 | AG6: 22 | AH6: 23 | AI6: 24 | AJ6: 25 | AK6: 26 | AL6: 27 | AM6: 28 | AN6: 29 | AO6: 30 | AP6: MONTH DAYS
A7: 1 | B7: ='4-22MASTER'!B17 -> BITS-542 | C7: ='4-22MASTER'!C17 -> Haneef | D7: ='4-22MASTER'!D17 -> 34715 | E7: ='4-22MASTER'!E17 -> MALE | F7: ='4-22MASTER'!O17 -> 44298 | G7: ='4-22MASTER'!G17 -> System Administrator | L7: P | M7: WO | N7: WO | O7: P | P7: P | Q7: P | R7: P | S7: P | T7: WO | U7: WO | V7: P | W7: P | X7: P | Y7: P | Z7: H | AA7: WO | AB7: WO | AC7: P | AD7: P | AE7: P | AF7: P | AG7: P | AH7: WO | AI7: WO | AJ7: P | AK7: P | AL7: P | AM7: P | AN7: P | AO7: WO | AP7: ='4-22MASTER'!X17 -> 30
A8: 2 | B8: ='4-22MASTER'!B18 -> BITS-557 | C8: ='4-22MASTER'!C18 -> Ved Prakash | D8: ='4-22MASTER'!D18 -> 30321 | E8: ='4-22MASTER'!E18 -> MALE | F8: ='4-22MASTER'!O18 -> 4th May 2021 | G8: ='4-22MASTER'!G18 -> Project Manager | L8: P | M8: WO | N8: WO | O8: P | P8: P | Q8: P | R8: P | S8: P | T8: WO | U8: WO | V8: P | W8: P | X8: P | Y8: P | Z8: H | AA8: WO | AB8: WO | AC8: P | AD8: P | AE8: P | AP8: ='4-22MASTER'!X18 -> 20
A9: 3 | B9: ='4-22MASTER'!B19 -> BITS-559 | C9: ='4-22MASTER'!C19 -> GauravVispute | D9: ='4-22MASTER'!D19 -> 33721 | E9: ='4-22MASTER'!E19 -> MALE | F9: ='4-22MASTER'!O19 -> 4th May 2021 | G9: ='4-22MASTER'!G19 -> Project Coordinator | L9: P | M9: WO | N9: WO | O9: P | P9: P | Q9: P | R9: P | S9: P | T9: WO | U9: WO | V9: P | W9: P | X9: P | Y9: P | Z9: H | AA9: WO | AB9: WO | AC9: EL | AD9: A | AE9: P | AF9: P | AG9: P | AH9: WO | AI9: WO | AJ9: P | AK9: P | AL9: P | AM9: P | AN9: P | AO9: WO | AP9: ='4-22MASTER'!X19 -> 29
A10: 4 | B10: ='4-22MASTER'!B20 -> BITS-658 | C10: ='4-22MASTER'!C20 -> Anjali Dubey | D10: ='4-22MASTER'!D20 -> 27-12-1990 | E10: ='4-22MASTER'!E20 -> FEMALE | F10: ='4-22MASTER'!O20 -> 44487 | G10: ='4-22MASTER'!G20 -> Project Engineer | L10: P | M10: WO | N10: WO | O10: P | P10: P | Q10: P | R10: P | S10: P | T10: WO | U10: WO | V10: P | W10: P | X10: P | Y10: P | Z10: H | AA10: WO | AB10: WO | AC10: P | AD10: P | AE10: P | AF10: P | AG10: P | AH10: WO | AI10: WO | AJ10: EL | AK10: A | AL10: A | AM10: P | AN10: P | AO10: WO | AP10: ='4-22MASTER'!X20 -> 28
A11: 5 | B11: ='4-22MASTER'!B21 -> BITS-683 | C11: ='4-22MASTER'!C21 -> TUSHAR UCHAGAONKAR | D11: ='4-22MASTER'!D21 -> 33656 | E11: ='4-22MASTER'!E21 -> MALE | F11: ='4-22MASTER'!O21 -> 44546 | G11: ='4-22MASTER'!G21 -> Network Engineer | L11: P | M11: WO | N11: WO | O11: P | P11: P | Q11: P | R11: P | S11: EL | T11: WO | U11: WO | V11: P | W11: P | X11: P | Y11: P | Z11: H | AA11: WO | AB11: WO | AC11: P | AD11: P | AE11: P | AF11: P | AG11: P | AH11: WO | AI11: WO | AJ11: P | AK11: P | AL11: P | AM11: P | AN11: P | AO11: WO | AP11: ='4-22MASTER'!X21 -> 30
A12: 6 | B12: ='4-22MASTER'!B22 -> BITS-692 | C12: ='4-22MASTER'!C22 -> Sneha Hande | D12: ='4-22MASTER'!D22 -> 09/11/1994 | E12: ='4-22MASTER'!E22 -> FEMALE | F12: ='4-22MASTER'!O22 -> 44566 | G12: ='4-22MASTER'!G22 -> Project manager | L12: P | M12: WO | N12: WO | O12: P | P12: P | Q12: P | R12: P | S12: P | T12: WO | U12: WO | V12: P | W12: P | X12: P | Y12: P | Z12: H | AA12: WO | AB12: WO | AC12: P | AD12: P | AE12: P | AF12: P | AG12: P | AH12: WO | AI12: WO | AJ12: P | AK12: P | AL12: P | AM12: P | AN12: P | AO12: WO | AP12: ='4-22MASTER'!X22 -> 30
A13: 7 | B13: ='4-22MASTER'!B23 -> BITS-698 | C13: ='4-22MASTER'!C23 -> Amol Gole | D13: ='4-22MASTER'!D23 -> 01/06/1991 | E13: ='4-22MASTER'!E23 -> MALE | F13: ='4-22MASTER'!O23 -> 44579 | G13: ='4-22MASTER'!G23 -> Project Manager | L13: P | M13: WO | N13: WO | O13: P | P13: P | Q13: P | R13: P | S13: P | T13: WO | U13: WO | V13: P | W13: P | X13: P | Y13: EL | Z13: H | AA13: WO | AB13: WO | AC13: P | AD13: P | AE13: P | AF13: P | AG13: P | AH13: WO | AI13: WO | AJ13: P | AK13: P | AL13: P | AM13: P | AN13: P | AO13: WO | AP13: ='4-22MASTER'!X23 -> 30
A14: 8 | B14: ='4-22MASTER'!B24 -> BITS-700 | C14: ='4-22MASTER'!C24 -> Sandeep Dixit | D14: ='4-22MASTER'!D24 -> 28764 | E14: ='4-22MASTER'!E24 -> MALE | F14: ='4-22MASTER'!O24 -> 44593 | G14: ='4-22MASTER'!G24 -> Sr. Project Manager | L14: P | M14: WO | N14: WO | O14: P | P14: P | Q14: P | R14: P | S14: P | T14: WO | U14: WO | V14: P | W14: P | X14: P | Y14: P | Z14: H | AA14: WO | AB14: WO | AC14: P | AD14: P | AE14: P | AF14: P | AG14: P | AH14: WO | AI14: WO | AJ14: P | AK14: P | AL14: P | AM14: P | AN14: P | AO14: WO | AP14: ='4-22MASTER'!X24 -> 30
A15: 9 | B15: ='4-22MASTER'!B25 -> BITS-717 | C15: ='4-22MASTER'!C25 -> Jaikesh Upadhyay | D15: ='4-22MASTER'!D25 -> 31778 | E15: ='4-22MASTER'!E25 -> MALE | F15: ='4-22MASTER'!O25 -> 44609 | G15: ='4-22MASTER'!G25 -> Sr. Project Coordinator | L15: P | M15: WO | N15: WO | O15: P | P15: P | Q15: P | R15: P | S15: P | T15: WO | U15: WO | V15: P | W15: P | X15: P | Y15: P | Z15: H | AA15: WO | AB15: WO | AC15: EL | AD15: P | AE15: P | AF15: P | AG15: P | AH15: WO | AI15: WO | AJ15: P | AK15: P | AL15: P | AM15: P | AN15: P | AO15: WO | AP15: ='4-22MASTER'!X25 -> 30
A16: 10 | B16: ='4-22MASTER'!B26 -> BITS-720 | C16: ='4-22MASTER'!C26 -> Jyoti Singh | D16: ='4-22MASTER'!D26 -> 34895 | E16: ='4-22MASTER'!E26 -> FEMALE | F16: ='4-22MASTER'!O26 -> 44613 | G16: ='4-22MASTER'!G26 -> Sr.Security analyst | L16: P | M16: WO | N16: WO | O16: P | P16: P | Q16: P | R16: P | S16: P | T16: WO | U16: WO | V16: P | W16: P | X16: P | Y16: P | Z16: H | AA16: WO | AB16: WO | AC16: P | AD16: P | AE16: P | AF16: P | AG16: P | AH16: WO | AI16: WO | AJ16: P | AK16: P | AL16: P | AM16: P | AN16: P | AO16: WO | AP16: ='4-22MASTER'!X26 -> 30
A17: 11 | B17: ='4-22MASTER'!B27 -> BITS-733 | C17: ='4-22MASTER'!C27 -> Chandrashekar Patil | D17: ='4-22MASTER'!D27 -> 34710 | E17: ='4-22MASTER'!E27 -> MALE | F17: ='4-22MASTER'!O27 -> 44634 | G17: ='4-22MASTER'!G27 -> Project Manager | L17: P | M17: WO | N17: WO | O17: P | P17: P | Q17: P | R17: P | S17: P | T17: WO | U17: WO | V17: P | W17: P | X17: P | Y17: P | Z17: H | AA17: WO | AB17: WO | AC17: P | AD17: P | AE17: P | AF17: P | AG17: EL | AH17: WO | AI17: WO | AJ17: A | AK17: A | AL17: A | AM17: P | AN17: P | AO17: WO | AP17: ='4-22MASTER'!X27 -> 27
A18: 12 | B18: ='4-22MASTER'!B28 -> BITS-734 | C18: ='4-22MASTER'!C28 -> ShaikFarooq Basha | D18: ='4-22MASTER'!D28 -> 33370 | E18: ='4-22MASTER'!E28 -> MALE | F18: ='4-22MASTER'!O28 -> 44636 | G18: ='4-22MASTER'!G28 -> Software Engineer | L18: P | M18: WO | N18: WO | O18: P | P18: P | Q18: P | R18: P | S18: P | T18: WO | U18: WO | V18: P | W18: P | X18: P | Y18: P | Z18: H | AA18: WO | AB18: WO | AC18: P | AD18: P | AE18: P | AF18: P | AG18: P | AH18: WO | AI18: WO | AJ18: P | AK18: P | AL18: P | AM18: P | AN18: P | AO18: WO | AP18: ='4-22MASTER'!X28 -> 30
A19: 13 | B19: ='4-22MASTER'!B29 -> BITS-738 | C19: ='4-22MASTER'!C29 -> NILOTPAL BHOWAL | D19: ='4-22MASTER'!D29 -> 31584 | E19: ='4-22MASTER'!E29 -> MALE | F19: ='4-22MASTER'!O29 -> 44650 | G19: ='4-22MASTER'!G29 -> VM ware consultant | L19: P | M19: WO | N19: WO | O19: P | P19: P | Q19: P | R19: P | S19: P | T19: WO | U19: WO | V19: P | W19: P | X19: P | Y19: P | Z19: H | AA19: WO | AB19: WO | AC19: P | AD19: P | AE19: P | AF19: P | AG19: P | AH19: WO | AI19: WO | AJ19: P | AK19: P | AL19: P | AM19: P | AN19: P | AO19: WO | AP19: ='4-22MASTER'!X29 -> 30
A20: 14 | B20: ='4-22MASTER'!B30 -> BITS-751 | C20: ='4-22MASTER'!C30 -> Varsha Amit Kadam | D20: ='4-22MASTER'!D30 -> 31018 | E20: ='4-22MASTER'!E30 -> FEMALE | F20: ='4-22MASTER'!O30 -> 44676 | G20: ='4-22MASTER'!G30 -> Program Manager | AJ20: P | AK20: P | AL20: P | AM20: P | AN20: P | AO20: WO | AP20: ='4-22MASTER'!X30 -> 6
AP21: =SUM(AP7:AP20) -> 380
AL32: Signature of the Contractor with Seal

Sheet F-M Leav
A1: FORM M- LEAVE REGISTER
A3: (Vide Rule 78(1) (a) (i) of Maharastra Shops&Establishment Act /Maharastra.Rules 1988
A4: Name of the Employer / Establishment: | E4: Name of the Employee:
B5: ='4-22MASTER'!G5 -> Burgeon IT Services Pvt.Ltd. | G5: ='4-22MASTER'!C17 -> Haneef
B6: ='4-22MASTER'!G6 -> Siri Mansion LIGB 436 Dr.A S Rao Nagar,Hyderabad
A7: Description of the dapartment if applicable: | E7: Date of entry into service | G7: ='4-22MASTER'!O17 -> 44298
C8: ='4-22MASTER'!G8 -> IT SUPPORTIVE SERVICES & PUNE ASC SEZ
A11: S.No | B11: Accumalation of Leave | D11: Leave allowed | F11: Balance of Leave Carried Over | G11: Payment of Leave made on | I11: Refusal of Leave | L11: Payment of Leave on Discharge of an employee quitting employment if a admissible | P11: Remarks
A13: 1 | F13: 6 | I13: 9 | L13: 9
B14: Leave due on | C14: No of Days | D14: From | E14: To | G14: 1st month | H14: 2nd month | I14: Date of Application | J14: Date of Refusal | K14: Amount of Leave refused | L14: Date of Discharge | M14: Date of Amount Paid | N14: Signature or Left hand thumb impression of employee
A15: JAN'22 | B15: 1.5 | C15: 1 | D15: 44589 | E15: 44589 | F15: 8.5 | J15: NO | K15: NO | L15: NO | M15: NO
A16: FEB'22 | B16: 1.5 | C16: 0 | D16: 0 | E16: 0 | F16: =F15+B16-C16 -> 10 | J16: NO | K16: NO | L16: NO | M16: NO
A17: MAR'22 | B17: 0 | C17: 0 | D17: 0 | E17: 0 | F17: =F16+B17-C17 -> 10 | J17: NO | K17: LESS DAYS | L17: NO | M17: NO
A18: APRIL'22 | B18: 1.5 | C18: 0 | D18: 0 | E18: 0 | F18: =F17+B18-C18 -> 11.5 | J18: NO | K18: NO | L18: NO | M18: NO
G42: Signature of the Contractor with Seal
A48: FORM M- LEAVE REGISTER
A50: (Vide Rule 78(1) (a) (i) of Maharastra Shops&Establishment Act /Maharastra.Rules 1988
A51: Name of the Employer / Establishment: | E51: Name of the Employee:
B52: ='4-22MASTER'!G5 -> Burgeon IT Services Pvt.Ltd. | G52: ='PUNE ASC-APRIL 22WM REG'!B37 -> Ved Prakash
B53: ='4-22MASTER'!G6 -> Siri Mansion LIGB 436 Dr.A S Rao Nagar,Hyderabad
A54: Description of the dapartment if applicable: | E54: Date of entry into service | G54: ='PUNE ASC-APRIL 22WM REG'!I37 -> 4th May 2021
C55: ='4-22MASTER'!G8 -> IT SUPPORTIVE SERVICES & PUNE ASC SEZ
A58: S.No | B58: Accumalation of Leave | D58: Leave allowed | F58: Balance of Leave Carried Over | G58: Payment of Leave made on | I58: Refusal of Leave | L58: Payment of Leave on Discharge of an employee quitting employment if a admissible | P58: Remarks
A60: 1 | F60: 6 | I60: 9 | L60: 9
B61: Leave due on | C61: No of Days | D61: From | E61: To | G61: 1st month | H61: 2nd month | I61: Date of Application | J61: Date of Refusal | K61: Amount of Leave refused | L61: Date of Discharge | M61: Date of Amount Paid | N61: Signature or Left hand thumb impression of employee
A62: JAN'22 | B62: 1.5 | F62: 9.5 | J62: NO | K62: NO | L62: NO | M62: NO
A63: FEB'22 | B63: 1.5 | C63: 1 | D63: 44603 | E63: 44603 | F63: =F62+B63-C63 -> 10 | J63: NO | K63: NO | L63: NO | M63: NO
A64: MAR'22 | B64: 1.5 | C64: 1 | D64: 44648 | E64: 44620 | F64: =F63+B64-C64 -> 10.5 | J64: NO | K64: NO | L64: NO | M64: NO
A65: APRIL'22 | B65: 1.5 | C65: 0 | D65: 0 | E65: 0 | F65: =F64+B65-C65 -> 12 | J65: NO | K65: NO | L65: NO | M65: NO
G89: Signature of the Contractor with Seal
A95: FORM M- LEAVE REGISTER
A97: (Vide Rule 78(1) (a) (i) of Maharastra Shops&Establishment Act /Maharastra.Rules 1988
A98: Name of the Employer / Establishment: | E98: Name of the Employee:
B99: ='4-22MASTER'!G5 -> Burgeon IT Services Pvt.Ltd. | G99: ='PUNE ASC-APRIL 22WM REG'!B39 -> GauravVispute
B100: ='4-22MASTER'!G6 -> Siri Mansion LIGB 436 Dr.A S Rao Nagar,Hyderabad
A101: Description of the dapartment if applicable: | E101: Date of entry into service | G101: ='PUNE ASC-APRIL 22WM REG'!I39 -> 4th May 2021
C102: ='4-22MASTER'!G8 -> IT SUPPORTIVE SERVICES & PUNE ASC SEZ
A105: S.No | B105: Accumalation of Leave | D105: Leave allowed | F105: Balance of Leave Carried Over | G105: Payment of Leave made on | I105: Refusal of Leave | L105: Payment of Leave on Discharge of an employee quitting employment if a admissible | P105: Remarks
