Workbook

Sheet PUNE STP APRIL 22 W M Reg
A1: FORM IX- REGISTER OF PERSONS EMPLOYED
A3: (Vide Rule 78(1) (a) (i) of Contract Labour (Regulation and Abolition) Central /Maharastra.Rules 1974
A4: Name and address of Contractor:burgeon IT services Pvt.Ltd. | F4: Name and address of the establishment in / under which contract is carried on: burgeon IT services Pvt.Ltd. Siri mansion LIGH 436 DR.A S Rao nagar,Hyderabad
B5: Siri Mansion LIGB 436 Dr.A S Rao Nagar,Hyderabad
A7: Name and address of Contractor:burgeon IT services Pvt.Ltd. | F7: Name and address of principal employer:
F8: INFOSYS LIMITED
F9: Rajiv gandhi Info tech park,Hinjawadi,Taluk Mulshi,Pune,Maharashtra 411057
A11: S.No | B11: Name and Surname of workman | C11: Age and Sex | E11: Father's/Husband's name | F11: Nature of Employement/Designation | G11: Permanent Home Address of worken | H11: Local Address | I11: Date of commencement of Employment | J11: Signature or Thumb impression of workman | K11: Date of Temination of Employment | M11: Remarks
L12: Reason for Termination
A13: 1 | B13: 2 | C13: 3 | E13: 4 | F13: 5 | G13: 6 | H13: 7 | I13: 8 | J13: 9 | K13: 10 | M13: 11
A14: 1 | B14: Milan Jain | C14: 31356 | D14: M | E14: Mahesh Chand jain | F14: Technical Consultant | G14: 492/1, shivloxpuri, konkerkhem, Meerat contonment UP250001 | H14: 492/1, shivloxpuri, konkerkhem, Meerat contonment UP250001 | I14: 43222 | K14: 43532 | L14: Resignation
A15: 2 | B15: Vishu Batra | C15: 32014 | D15: M | E15: Rattanlal | F15: Technical Consultant | G15: E-404, Spectra Casabella gold, Palava, Kalyanshill road, Dombivili East 421204 | H15: E-404, Spectra Casabella gold, Palava, Kalyanshill road, Dombivili East 421204 | I15: 43334 | K15: 43714 | L15: Resignation
A16: 3 | B16: Prasad Iyer | C16: 33240 | D16: M | E16: Balasubramanian Srinivasan | F16: Technical Consultant | G16: Plot no-295,Sector no-21,Yamunanagar,Nigdi,Pune-411044 | H16: Plot no-295,Sector no-21,Yamunanagar,Nigdi,Pune-411044 | I16: 43409 | K16: 43546 | L16: Resignation
A17: 4 | B17: Venkat Datla | C17: 31783 | D17: M | E17: Rama Krishna Reddy D | F17: Technical Consultant | G17: Ambapuram, Gurazala mandal Guntur dist Andhra Pradsh, 522415 | H17: C/O KotiReddy Datla. Hno 8-7-55/VEC/22EP ZP Road, Sri Venkateswara Colony, Hastina Puram, Hyderabad 500079. | I17: 43472 | K17: 43630 | L17: Resignation
A18: 5 | B18: Shubham Asthana - | C18: 30/5/1989 | D18: F | E18: Ajay kumar asthana | F18: Senior Software Developer | G18: D - 204 RAJGRUHA B SOCIETY , SALUNKHE VIHAR ROAD , KONDHWA KH , PUNE , MH 411048 | H18: D - 204 RAJGRUHA B SOCIETY , SALUNKHE VIHAR ROAD , KONDHWA KH , PUNE , MH 411048 | I18: 16/6/2020
A19: 6 | B19: Vinay Koleti | C19: 30474 | D19: M | E19: Shankar Koleti | F19: SENIOR DATABASE ADMIN | G19: FLAT NO 412 FOURTH FLOOR,LAKERIDGE APPARTMENTS,NIZAMPET,NALLAPOCHAMA TEMPLE ROAD,HYDERABAD,TS,PIN 500090 | H19: FLAT NO 412 FOURTH FLOOR,LAKERIDGE APPARTMENTS,NIZAMPET,NALLAPOCHAMA TEMPLE ROAD,HYDERABAD,TS,PIN 500090 | I19: 44060 | L19: 0 | M19: 0
A20: 7 | B20: RAJEEV MUTHINENI | C20: 25-08-1993 | D20: M | E20: Veeraiah | F20: Oracle DBA | G20: H.no.11-40/1, ramachandra puram,ponugodu.post,suryapet,508201 | H20: H.no.11-40/1, ramachandra puram,ponugodu.post,suryapet,508201 | I20: 44109
A21: 8 | B21: Karthik Hanumantharaju | C21: 28740 | D21: M | E21: Hanumantharaju | F21: Senior Oracle DBA | G21: 37, Munireddy Layout, 3rd main hosur road, Garvebhavipallya, Bengaluru 560068 karnataka India | H21: 37, Munireddy Layout, 3rd main hosur road, Garvebhavipallya, Bengaluru 560068 karnataka India | I21: 44158 | K21: 44348 | L21: Resignation
A22: 9 | B22: Prakash Kendre | C22: 26/11/1986 | D22: M | E22: RAMKISHAN KENDRE | F22: Application Support Engineer | G22: SHREYAS B/202 SAMARTH RAMDAS NAGAR,NAVGHAR VASAI EAST DIST-PALGHAR, PIN-401202 | H22: SHREYAS B/202 SAMARTH RAMDAS NAGAR,NAVGHAR VASAI EAST DIST-PALGHAR, PIN-401202 | I22: 44298
A23: 10 | B23: Amith a | C23: 29351 | D23: M | E23: Ananda | F23: Technology Consultant | G23: MIG 102,I Block,2nd stage,V cross,Ramakrishna nagar,Mysore,Karnataka 570022 | H23: 3-3/33,1st Main road,Prasantha nagar,Behind Derabail church,Mangalore,Karnataka 575006 | I23: 44326
A24: 11 | B24: Dhrubajyoti Goswami | C24: 30723 | D24: M | E24: Swapan kumar goswami | F24: Business Analyst | G24: LV8 Laxmi Krupa Apts, Church Road, Murugeshpalya, Bangalore 560017 | H24: 1108/1, Kankpul post, ashok nagar, 24 Paraganas Dist. Habra, WB 743272 | I24: 44333
H30: Signature of the Contractor with Seal

Sheet 4-22Master
A3: FORM - XIII REGISTER OF WORKMEN EMPLOYED BY CONTRACTOR
C4: (Vide Rule 75 of Contract Labour (Regulation and Abolition) Central/Karnataka Rules 1974)
A5: Name and address of Contractor: | G5: Burgeon IT Services Pvt.Ltd. | AC5: Name and address of Establishemnt in/ under which contract is carried on: | AQ5: =G5 -> Burgeon IT Services Pvt.Ltd.
G6: Siri Mansion LIGB 436 Dr.A S Rao Nagar,Hyderabad | AQ6: =G6 -> Siri Mansion LIGB 436 Dr.A S Rao Nagar,Hyderabad
AQ7: =G7 -> 0
A8: Nature and location of work: | G8: IT SUPPORTIVE SERVICES& PUNE STP
A10: Wage period: Monthly | E10: 44652 | AL10: Name and address of Principal Employer: | AQ10: INFOSYS LTD.IL Pune STP Unit,Plot No.1
AQ11: Rajiv gandhi Info tech park,Hinjawadi,Taluk Mulshi,Pune,Maharashtra 411057
A14: Serial No. in the Register of Workmen | B14: Employee ID | C14: Name of Workman | D14: Age | E14: Sex | F14: Father's /Husband Name | G14: Designation / Nature of Work Done | H14: Permanent Address | K14: Local Address | O14: Date of Commencement of Employment | P14: Signature or thumb impression of Workman | Q14: Date of termination of Employment | R14: Reasons for termination | S14: Remarks | T14: EPF Number | U14: ESI Number | V14: Name of Workman | W14: NO OF DAYS | X14: No.of Days worked | Y14: Unit of work done | Z14: Monthly rate of wages/ piece rate | AA14: Basic wages | AB14: Dearness Allowances | AC14: Over time | AD14: Other cash payments (Nature of payments to be indicated) | AE14: HRA | AF14: CONVEYANCE | AG14: MEDICAL ALLOWANCES | AH14: SPECIAL ALLOWNANCES | AI14: Total | AJ14: BONUS | AK14: GRATUITY | AL14: LTA/L.E | AM14: ARREAR AMOUNT | AN14: TOTAL AMOUNT | AO14: Deductions, if any, (Indicate nature) | AU14: Net Amount paid | AV14: Time and Date of Payment | AW14: Place of Payment | AX14: Signature/Thumb Impression of workman | AY14: Initial of Contractor or his representative
AO15: ESI | AP15: PF | AQ15: PT | AR15: TDS | AS15: MED | AT15: Total Deductions
A18: 10 | B18: BITS-564 | C18: Amith a | D18: 29351 | E18: Male | F18: N.Ananda | G18: Technology Consultant | H18: Door no - 3-3/33, 1st main road, Prasantha Nagara, Derabail, Mangaluru- 575006 | I18: OOO | J18: OOO | K18: MIG-109, i Block, 2nd Stage, 5th Cross, Ramakrishana-Nagara, Mysuru, Karnataka-570022 | L18: OOO | M18: OOO | N18: OOO | O18: 44326 | P18: OOO | Q18: OOO | R18: OOO | S18: OOO | T18: 100081114505 | U18: N/A | V18: =C18 -> Amith a | W18: 31 | X18: 30 | Y18: N/A | Z18: 57105 | AA18: 34263 | AB18: 0 | AC18: 0 | AD18: =AE18+AF18+AG18+AH18 -> 22955.2 | AE18: 13705.2 | AF18: 2083 | AG18: 2083 | AH18: 5084 | AI18: =AA18+AD18 -> 57218.2 | AJ18: 1555 | AK18: 1648.0503 | AL18: 2855.25 | AN18: =AI18+AJ18+AK18+AL18+AM18 -> 63276.5 | AO18: 0 | AP18: =VLOOKUP(B18,'[1]Pay sheet-Dec- 2021'!$C$5:$AF$38,26,0) -> 1800 | AQ18: =VLOOKUP(B18,'[1]Pay sheet-Dec- 2021'!$C$5:$AF$38,25,0) -> 200 | AR18: 0 | AS18: =VLOOKUP(B18,'[1]Pay sheet-Dec- 2021'!$C$5:$AF$38,27,0) -> 440.76133 | AT18: =AO18+AP18+AQ18+AR18+AS18 -> 2440.7613 | AU18: =ROUND((AI18-AT18),0)+AJ18+AK18+AL18 -> 60835.3 | AV18: 5-05-2022 | AW18: ICICI Bank | AX18: 115601503688

Sheet Eql rem
A1: Form D
A2: (See rule 6)
A4: Register to be maintained by the employer under rule 6 of the Equal Remuneration Rules, 1976
D6: ='4-22Master'!E10 -> 44652
A8: Name and address of Contractor : | F8: ='4-22Master'!G5 -> Burgeon IT Services Pvt.Ltd.
A10: Name and address of establishment in/under which contract is carried on : | F10: ='4-22Master'!AQ5 -> Burgeon IT Services Pvt.Ltd.
F11: ='4-22Master'!AQ6 -> Siri Mansion LIGB 436 Dr.A S Rao Nagar,Hyderabad
A12: Name and address of Principal Employer : | F12: ='4-22Master'!AQ10 -> INFOSYS LTD.IL Pune STP Unit,Plot No.1
F13: ='4-22Master'!AQ11 -> Rajiv gandhi Info tech park,Hinjawadi,Taluk Mulshi,Pune,Maharashtra 411057
A14: Total number of men workers employed | C14: =D22 -> 1
A16: Total number of women workers employed | C16: =C22 -> 0
C18: Components of remuneration
A19: Category of workers | B19: Brief Description of work | C19: No of women employed | D19: No. of men employed | E19: Rate or remuneration paid | F19: Basic wage & Dearness Allowance | G19: House Rent allowance | H19: Other allowances | I19: Cash value of concessional supply of essential commodities | J19: Name of the Client | K19: Primary Work Place/ Location
A20: ='4-22Master'!G18 -> Technology Consultant | B20: IT SUPPORTIVE SERVICES | C20: 0 | D20: 1 | E20: ='4-22Master'!AN18 -> 63276.5 | F20: ='4-22Master'!AA18 -> 34263 | G20: ='4-22Master'!AE18 -> 13705.2 | H20: =E20-(F20+G20) -> 15308.3 | I20: 0 | J20: INSOSYS LTD | K20: PUNE
K21: STP
C22: =SUM(C20:C21) -> 0 | D22: =SUM(D20:D21) -> 1 | E22: =SUM(E20:E21) -> 63276.5 | F22: =SUM(F20:F21) -> 34263 | G22: =SUM(G20:G21) -> 13705.2 | H22: =SUM(H20:H21) -> 15308.3
E29: Signature of the Contractor with Seal
A35: ='4-22Master'!#REF! -> #REF! | B35: ='4-22Master'!#REF! -> #REF! | C35: 0 | D35: 0 | E35: 0 | F35: 0 | G35: 0 | H35: 0 | I35: 0 | J35: 0 | K35: 0

Sheet 04-22MH_Must-JULY
A2: Form No. II
A3: [M. W. Rules under Maharashtra Contract Labour (Regulation and Abolition)1963 Rule 27 (I)]
A4: Muster Roll cum Wages Register for the month of APRIL 2022
A5: Name and Address of Contractor : BURGEON IT SERVICES PVT.LTD. SIRI MANSION LIG 436 DR.A S RAO NAGAR,HYDERABAD 500 060
I6: Working Hours | K6: Interval for Rest | M6: No. of Hours Worked
A7: Sl.No. | B7: Deputy ID | C7: Employee Code | D7: Full Name of Employee | E7: Date of Birth | F7: Gender | G7: Date of Entry into Service | H7: Nature of Work & Designation | I7: From | J7: To | K7: From | L7: To | M7: 1 | N7: 2 | O7: 3 | P7: 4 | Q7: 5 | R7: 6 | S7: 7 | T7: 8 | U7: 9 | V7: 10 | W7: 11 | X7: 12 | Y7: 13 | Z7: 14 | AA7: 15 | AB7: 16 | AC7: 17 | AD7: 18 | AE7: 19 | AF7: 20 | AG7: 21 | AH7: 22 | AI7: 23 | AJ7: 24 | AK7: 25 | AL7: 26 | AM7: 27 | AN7: 28 | AO7: 29 | AP7: 30 | AQ7: MONTH DAYS
A8: 3 | C8: ='4-22Master'!B18 -> BITS-564 | D8: ='4-22Master'!C18 -> Amith a | E8: ='4-22Master'!D18 -> 29351 | F8: ='4-22Master'!E18 -> Male | G8: ='4-22Master'!O18 -> 44326 | H8: ='4-22Master'!G18 -> Technology Consultant | M8: P | N8: WO | O8: WO | P8: P | Q8: P | R8: P | S8: P | T8: P | U8: WO | V8: WO | W8: P | X8: P | Y8: P | Z8: P | AA8: H | AB8: WO | AC8: WO | AD8: P | AE8: P | AF8: P | AG8: P | AH8: P | AI8: WO | AJ8: WO | AK8: P | AL8: P | AM8: P | AN8: P | AO8: P | AP8: WO | AQ8: ='4-22Master'!X18 -> 30
P15: Signature of the Contractor with Seal

Sheet 04-22 F- M LEAV Reg
A1: FORM M- LEAVE REGISTER
A3: (Vide Rule 78(1) (a) (i) of Maharastra Shops&Establishment Act /Maharastra.Rules 1988
A4: Name of the Employer / Establishment: | E4: Name of the Employee:
B5: ='4-22Master'!G5 -> Burgeon IT Services Pvt.Ltd. | G5: ='4-22Master'!C18 -> Amith a
B6: ='4-22Master'!G6 -> Siri Mansion LIGB 436 Dr.A S Rao Nagar,Hyderabad
A7: Description of the dapartment if applicable: | E7: Date of entry into service | G7: ='4-22Master'!O18 -> 44326
C8: ='4-22Master'!G40 -> 0
A11: S.No | B11: Accumalation of Leave | D11: Leave allowed | F11: Balance of Leave Carried Over | G11: Payment of Leave made on | I11: Refusal of Leave | L11: Payment of Leave on Discharge of an employee quitting employment if a admissible | O11: Signature or the Thumb impression of employee on Receipt of Leave Book in Form N | P11: Remarks
A13: 1 | F13: 6 | I13: 9 | L13: 9 | O13: Impression of
B14: Leave due on | C14: No of Days | D14: From | E14: To | G14: 1st month | H14: 2nd month | I14: Date of Application | J14: Date of Refusal | K14: Amount of Leave refused | L14: Date of Discharge | M14: Date of Amount Paid | N14: Signature or Left hand thumb impression of employee
A18: JAN'22 | B18: 1.5 | C18: 0 | D18: 0 | E18: 0 | F18: 7.5 | I18: NO | J18: NO | K18: NO
A19: FEB'22 | B19: 1.5 | C19: 1 | D19: 44596 | E19: 44596 | F19: =F18+B19-C19 -> 8 | I19: NO | J19: NO | K19: NO
A20: MAR'22 | B20: 1.5 | C20: 1 | D20: 44624 | E20: 44624 | F20: =F19+B20-C20 -> 8.5 | I20: NO | J20: NO | K20: NO
A21: APRIL'22 | B21: 1.5 | C21: 0 | D21: 0 | E21: 0 | F21: =F20+B21-C21 -> 10 | I21: NO | J21: NO | K21: NO
G45: Signature of the Contractor with Seal
A48: FORM M- LEAVE REGISTER
A50: (Vide Rule 78(1) (a) (i) of Maharastra Shops&Establishment Act /Maharastra.Rules 1988
A51: Name of the Employer / Establishment: | E51: Name of the Employee:
B52: ='4-22Master'!G5 -> Burgeon IT Services Pvt.Ltd.
B53: ='4-22Master'!G6 -> Siri Mansion LIGB 436 Dr.A S Rao Nagar,Hyderabad
A54: Description of the dapartment if applicable: | E54: Date of entry into service
C55: ='4-22Master'!G92 -> 0
A58: S.No | B58: Accumalation of Leave | D58: Leave allowed | F58: Balance of Leave Carried Over | G58: Payment of Leave made on | I58: Refusal of Leave | L58: Payment of Leave on Discharge of an employee quitting employment if a admissible | O58: Signature or the Thumb impression of employee on Receipt of Leave Book in Form N | P58: Remarks
A60: 1 | F60: 6 | I60: 9 | L60: 9 | O60: Impression of
B61: Leave due on | C61: No of Days | D61: From | E61: To | G61: 1st month | H61: 2nd month | I61: Date of Application | J61: Date of Refusal | K61: Amount of Leave refused | L61: Date of Discharge | M61: Date of Amount Paid | N61: Signature or Left hand thumb impression of employee
G88: Signature of the Contractor with Seal

Sheet MH_Regf W
B2: Form No. II
B3: [M. W. Rules under Maharashtra Contract Labour (Regulation and Abolition)1963 Rule 27 (I)]
B4: Muster Roll cum Wages Register for the month of APRIL 2022
B5: Name and Address of Contractor : BURGEON IT SERVICES PVT.LTD. SIRI MANSION LIG 436 DR.A S RAO NAGAR,HYDERABAD 500 060
P6: Deductions | W6: Leave with Wages
B7: Sl.No. | C7: Deputy ID | D7: Employee Code | E7: Name of the Workmen | F7: Minimum Rate of Wages Payable Basic | G7: Actual Rate of Wages Payable HRA | H7: Conveyance | I7: Bonus | J7: Special Allowances | K7: Medical Allowances | L7: Total Production in Case of Piece Rate Other Allow | M7: Normal Earnings | N7: Overtime Earnings | O7: Gross Wages Payable | P7: Income Tax | Q7: Other Deduction(Med) | R7: Proff / Income Tax | S7: PF | T7: ESIC | U7: Total Deduction | V7: Net Wages Paid | W7: Previous Balance | X7: Further Enjoyed | Y7: Refused | Z7: Accumulated | AA7: Date Payment of Wages | AB7: Signature or the Thumb Impression of the Employee | AC7: Account Number
B8: 1 | D8: ='4-22Master'!B18 -> BITS-564 | E8: ='4-22Master'!C18 -> Amith a | F8: ='4-22Master'!AA18 -> 34263 | G8: ='4-22Master'!AE18 -> 13705.2 | H8: ='4-22Master'!AF18 -> 2083 | I8: ='4-22Master'!AJ18 -> 1555 | J8: ='4-22Master'!AH18 -> 5084 | K8: ='4-22Master'!AG18 -> 2083 | M8: ='4-22Master'!AN18 -> 63276.5 | N8: 0 | O8: ='4-22Master'!AN18 -> 63276.5 | P8: ='4-22Master'!AR18 -> 0 | Q8: ='4-22Master'!AS18 -> 440.76133 | R8: ='4-22Master'!AQ18 -> 200 | S8: ='4-22Master'!AP18 -> 1800 | T8: ='4-22Master'!AO18 -> 0 | U8: ='4-22Master'!AT18 -> 2440.7613 | V8: ='4-22Master'!AU18 -> 60835.3 | W8: 8 | X8: 1 | Y8: 0 | Z8: 8.5 | AA8: ='4-22Master'!AV18 -> 5-05-2022 | AB8: ='4-22Master'!AW18 -> ICICI Bank | AC8: ='4-22Master'!AX18 -> 115601503688
F10: =SUM(F8:F9) -> 34263 | G10: =SUM(G8:G9) -> 13705.2 | H10: =SUM(H8:H9) -> 2083 | I10: =SUM(I8:I9) -> 1555 | J10: =SUM(J8:J9) -> 5084 | K10: =SUM(K8:K9) -> 2083 | M10: =SUM(M8:M9) -> 63276.5 | N10: =SUM(N8:N9) -> 0 | O10: =SUM(O8:O9) -> 63276.5 | P10: =SUM(P8:P9) -> 0 | Q10: =SUM(Q8:Q9) -> 440.76133 | R10: =SUM(R8:R9) -> 200 | S10: =SUM(S8:S9) -> 1800 | T10: =SUM(T8:T9) -> 0 | ... V10: =SUM(V8:V9) -> 60835.3
I12: =243055+I10 -> 244610
U17: Signature of the Contractor with Seal

Sheet EmP Cards
B1: FORM X
B2: EMPLOYMENT CUM WAGE CARD
B3: (Vide Rule 76 of Contract Labour (R&A) Central & Maharashtra, 1971)
B4: Name and Address of the Contractor | H4: Name and Address of the Establishment in/under which Contract is carried on:
B7: ='4-22Master'!G5 -> Burgeon IT Services Pvt.Ltd. | H7: ='4-22Master'!AQ5 -> Burgeon IT Services Pvt.Ltd.
B9: ='4-22Master'!G6 -> Siri Mansion LIGB 436 Dr.A S Rao Nagar,Hyderabad | H9: =B9 -> Siri Mansion LIGB 436 Dr.A S Rao Nagar,Hyderabad
B12: Nature of work and location of work: | H12: Name and address of Principal Employer:
H15: ='4-22Master'!AQ10 -> INFOSYS LTD.IL Pune STP Unit,Plot No.1
B16: ='4-22Master'!G8 -> IT SUPPORTIVE SERVICES& PUNE STP
H17: ='4-22Master'!AQ11 -> Rajiv gandhi Info tech park,Hinjawadi,Taluk Mulshi,Pune,Maharashtra 411057
B19: 1. Name of the Workman and address | H19: ='4-22Master'!C18 -> Amith a
B20: 2. S.No. in the Register of Workmen Employed | H20: ='4-22Master'!A18 -> 10
B21: 3. Nature of Employment /Designation | H21: ='4-22Master'!G18 -> Technology Consultant
B22: 4. Date of entry into service | H22: ='4-22Master'!O18 -> 44326
B23: 5. ESI No. | J23: ='4-22Master'!U18 -> N/A
B24: 6.PF No. | J24: ='4-22Master'!T18 -> 100081114505
B25: 7. Wage rate (With particulars of unit in case of piece - work) | H25: ='4-22Master'!Z18 -> 57105
B26: 8. Wage period | H26: ='4-22Master'!E10 -> 44652
B27: 9. Tenure of Employment | H27: AS PER CONTRACT
B28: 10.No. of days worked in a month | J28: ='4-22Master'!X18 -> 30
B29: 11. No. of units worked in case of piece rate workers | J29: N/A
B30: 12. Rate of daily wages / piece rate | J30: 0
B31: 13. Amount of overtime wages | J31: 0
B32: 14. Gross wages payable | J32: ='4-22Master'!AN18 -> 63276.5 | L32: MED
B33: 15. Deductions, if any, | D33: PF | E33: ='4-22Master'!AP18 -> 1800 | F33: ESI | G33: ='4-22Master'!AO18 -> 0 | H33: PT | I33: ='4-22Master'!AQ18 -> 200 | J33: TDS | K33: ='4-22Master'!AR18 -> 0 | L33: ='4-22Master'!AS18 -> 440.76133
B34: 16. Net amount of wages paid | J34: =J32-(E33+G33+I33+K33+L33) -> 60835.739
B35: Signature of the Representative
B36: of Contractor
B55: FORM XIV
B56: EMPLOYMENT CUM WAGE CARD
B57: (Vide Rule 76 of Contract Labour (R&A) Central & Karnataka Rules, 1974)
B58: Name and Address of the Contractor | H58: Name and Address of the Establishment in/under which Contract is carried on:
B61: =#REF! -> #REF! | H61: =#REF! -> #REF!
B63: =#REF! -> #REF! | H63: =#REF! -> #REF!
B66: Nature of work and location of work: | H66: Name and address of Principal Employer:
H69: =#REF! -> #REF!
B70: =#REF! -> #REF!
H71: =#REF! -> #REF!
B73: 1. Name of the Workman and address | H73: ='4-22Master'!C408 -> 0
B74: 2. S.No. in the Register of Workmen Employed | H74: ='4-22Master'!A408 -> 0
...

Sheet wage sllips
A1: Form XV - WAGE SLIP | K1: =A1 -> Form XV - WAGE SLIP
A2: [Vide rule 78 (1) (b) of the Contract Labour (Regulation and Abolition) and Maharashtra Rules, 1971] | K2: =A2 -> [Vide rule 78 (1) (b) of the Contract Labour (Regulation and Abolition) and Maharashtra Rules, 1971]
A4: Name and address of Contractor | D4: ='4-22Master'!G5 -> Burgeon IT Services Pvt.Ltd. | K4: Name and address of Contractor | N4: =D4 -> Burgeon IT Services Pvt.Ltd.
B5: ='4-22Master'!G6 -> Siri Mansion LIGB 436 Dr.A S Rao Nagar,Hyderabad | L5: =B5 -> Siri Mansion LIGB 436 Dr.A S Rao Nagar,Hyderabad
B6: ='4-22Master'!G7 -> 0 | L6: =B6 -> 0
A7: Name and Father's / Husband's name of the workman | K7: Name and Father's / Husband's name of the workman
E8: ='4-22Master'!C18 -> Amith a | G8: ='4-22Master'!F18 -> N.Ananda | O8: =E8 -> Amith a | Q8: =G8 -> N.Ananda
A10: Nature and location of work | E10: ='4-22Master'!G8 -> IT SUPPORTIVE SERVICES& PUNE STP | K10: Nature and location of work | O10: =E10 -> IT SUPPORTIVE SERVICES& PUNE STP
A12: For the Week / Fortnight / Month ending | E12: ='4-22Master'!E10 -> 44652 | K12: For the Week / Fortnight / Month ending | O12: =E12 -> 44652
A14: 1 | B14: No. of days worked | E14: ='4-22Master'!X18 -> 30 | K14: 1 | L14: No. of days worked | O14: =E14 -> 30
A16: 2 | B16: No. of units worked in case of piece rate workers : | K16: 2 | L16: No. of units worked in case of piece rate workers :
E17: N/A | O17: N/A
A19: 3 | B19: Rate of daily wages / piece rate | E19: N/A | K19: 3 | L19: Rate of daily wages / piece rate | O19: =E19 -> N/A
A21: 4 | B21: Amount of overtime wages | E21: Nil | K21: 4 | L21: Amount of overtime wages | O21: Nil
A23: 5 | B23: Gross wages payble | E23: ='4-22Master'!AN18 -> 63276.5 | K23: 5 | L23: Gross wages payble | O23: =E23 -> 63276.5
D24: EPF | E24: ESI | F24: PT | G24: TDS | H24: MEDICAL | I24: TOTAL | N24: EPF | O24: ESI | P24: PT | Q24: TDS | R24: MEDICAL | S24: TOTAL
A25: 6 | B25: Deductions, if any | D25: ='4-22Master'!AP18 -> 1800 | E25: 0 | F25: ='4-22Master'!AQ18 -> 200 | G25: ='4-22Master'!AR18 -> 0 | H25: ='4-22Master'!AS18 -> 440.76133 | I25: =D25+E25+F25+G25+H25 -> 2440.7613 | K25: 6 | L25: Deductions, if any | N25: =D25 -> 1800 | O25: =E25 -> 0 | P25: =F25 -> 200 | Q25: =G25 -> 0 | R25: =H25 -> 440.76133 | S25: =I25 -> 2440.7613
A27: 7 | B27: Net amount of wages paid | E27: =E23-I25 -> 60835.739 | K27: 7 | L27: Net amount of wages paid | O27: =E27 -> 60835.739
F31: Initial of the Contractor or his representative | P31: Initial of the Contractor or his representative
A44: Form XV - WAGE SLIP | K44: =A44 -> Form XV - WAGE SLIP
A45: [Vide rule 78 (1) (b) of the Contract Labour (Regulation and Abolition) and Maharashtra Rules, 1971] | K45: =A45 -> [Vide rule 78 (1) (b) of the Contract Labour (Regulation and Abolition) and Maharashtra Rules, 1971]
A47: Name and address of Contractor | D47: ='4-22Master'!G5 -> Burgeon IT Services Pvt.Ltd. | K47: Name and address of Contractor | N47: =D47 -> Burgeon IT Services Pvt.Ltd.
B48: ='4-22Master'!G6 -> Siri Mansion LIGB 436 Dr.A S Rao Nagar,Hyderabad | L48: =B48 -> Siri Mansion LIGB 436 Dr.A S Rao Nagar,Hyderabad
B49: ='4-22Master'!G7 -> 0 | L49: =B49 -> 0
A50: Name and Father's / Husband's name of the workman | K50: Name and Father's / Husband's name of the workman
E51: ='4-22Master'!#REF! -> #REF! | O51: =E51 -> #REF!
A53: Nature and location of work | E53: ='4-22Master'!G8 -> IT SUPPORTIVE SERVICES& PUNE STP | K53: Nature and location of work | O53: =E53 -> IT SUPPORTIVE SERVICES& PUNE STP
A55: For the Week / Fortnight / Month ending | E55: ='4-22Master'!E10 -> 44652 | K55: For the Week / Fortnight / Month ending | O55: =E55 -> 44652
A57: 1 | B57: No. of days worked | E57: ='4-22Master'!#REF! -> #REF! | K57: 1 | L57: No. of days worked | O57: =E57 -> #REF!
A59: 2 | B59: No. of units worked in case of piece rate workers : | K59: 2 | L59: No. of units worked in case of piece rate workers :
E60: N/A | O60: N/A
A62: 3 | B62: Rate of daily wages / piece rate | E62: N/A | K62: 3 | L62: Rate of daily wages / piece rate | O62: =E62 -> N/A
A64: 4 | B64: Amount of overtime wages | E64: Nil | K64: 4 | L64: Amount of overtime wages | O64: Nil
A66: 5 | B66: Gross wages payble | E66: ='4-22Master'!#REF! -> #REF! | K66: 5 | L66: Gross wages payble | O66: =E66 -> #REF!
D67: EPF | E67: ESI | F67: PT | G67: TDS | H67: MEDICAL | I67: TOTAL | N67: EPF | O67: ESI | P67: PT | Q67: TDS | R67: MEDICAL | S67: TOTAL
A68: 6 | B68: Deductions, if any | D68: ='4-22Master'!#REF! -> #REF! | E68: ='4-22Master'!#REF! -> #REF! | F68: ='4-22Master'!#REF! -> #REF! | G68: ='4-22Master'!#REF! -> #REF! | H68: ='4-22Master'!#REF! -> #REF! | I68: =D68+E68+F68+G68+H68 -> #REF! | K68: 6 | L68: Deductions, if any | N68: =D68 -> #REF! | O68: =E68 -> #REF! | P68: =F68 -> #REF! | Q68: =G68 -> #REF! | R68: =H68 -> #REF! | S68: =I68 -> #REF!
A70: 7 | B70: Net amount of wages paid | E70: =E66-I68 -> #REF! | K70: 7 | L70: Net amount of wages paid | O70: =E70 -> #REF!
F74: Initial of the Contractor or his representative | P74: Initial of the Contractor or his representative
A88: Form XV - WAGE SLIP | K88: =A88 -> Form XV - WAGE SLIP
A89: [Vide rule 78 (1) (b) of the Contract Labour (Regulation and Abolition) and Maharashtra Rules, 1971] | K89: =A89 -> [Vide rule 78 (1) (b) of the Contract Labour (Regulation and Abolition) and Maharashtra Rules, 1971]
...

Sheet 4-22Bonus
A1: BONUS REGISTER
A3: FORM "c" ( See rule 4 [c] )
K4: Wage Period | L4: ='4-22Master'!E10 -> 44652
A5: Name of the Establishment : _____________________________ | D5: ='4-22Master'!G5 -> Burgeon IT Services Pvt.Ltd. | K5: Financial year _____ | M5: 2022-23
A6: ='4-22Master'!G6 -> Siri Mansion LIGB 436 Dr.A S Rao Nagar,Hyderabad
A7: Sr. No | B7: Name of the Employee | C7: Father's Name / Husband's Name | D7: Whether he has completed 15 yrs of age at the beginning of the accounting year | E7: Designation | F7: No. of days worked in the year | G7: Total Salary or wages in the Month | H7: Amt. of bonus payable under section 10 or section 11 as the case may be Ex gratia | I7: DEDUCTIONS | L7: Total Sum Deducted (Col. 9,10 and 11) | M7: Net Amount payable (Col. 8 minus Col. 12) | N7: Amount Actually paid | O7: Date on which paid | P7: Signature / Thumb impression of the employee
I8: Puja Bonus or other customary bonus paid during the accounting year | J8: Interim Bonus or bonus paid in advance | K8: Deduction on account of financial loss if any caused by misconduct of the employee | Q8: Account Number
A9: 1 | B9: 2 | C9: 3 | D9: 4 | E9: 5 | F9: 6 | H9: 8 | I9: 9 | J9: 10 | K9: 11 | L9: 12 | M9: 13 | N9: 14 | O9: 15 | P9: 16
A10: 3 | B10: ='4-22Master'!V18 -> Amith a | C10: ='4-22Master'!F18 -> N.Ananda | D10: YES | E10: ='4-22Master'!G18 -> Technology Consultant | F10: ='4-22Master'!X18 -> 30 | G10: ='4-22Master'!AN18 -> 63276.5 | H10: ='4-22Master'!AJ18 -> 1555 | I10: N/A | J10: N/A | K10: N/A | L10: N/A | M10: =H10 -> 1555 | N10: =H10 -> 1555 | O10: ='4-22Master'!AV18 -> 5-05-2022 | P10: ='4-22Master'!AW18 -> ICICI Bank | Q10: ='4-22Master'!AX18 -> 115601503688
L17: Signature of the Contractor with Seal

Sheet Deductions
A1: FORM XVI- REGISTER OF DEDUCTIONS FOR DAMAGE OR LOSS
A3: (Vide Rule 78(1) (a) (i) of Contract Labour (Regulation and Abolition) Maharashtra Rules 1971.
A4: Name and address of Contractor: GROTECH LANDSCAPE DEVELOPERS PVT.LTD. | D4: ='4-22Master'!G5 -> Burgeon IT Services Pvt.Ltd. | E4: Name and address of the establishment in / under which contract is carried on:
B5: ='4-22Master'!G6 -> Siri Mansion LIGB 436 Dr.A S Rao Nagar,Hyderabad | E5: ='4-22Master'!AQ5 -> Burgeon IT Services Pvt.Ltd.
B6: ='4-22Master'!G7 -> 0 | E6: ='4-22Master'!AQ6 -> Siri Mansion LIGB 436 Dr.A S Rao Nagar,Hyderabad
A7: Nature and Location of Work: | D7: ='4-22Master'!G8 -> IT SUPPORTIVE SERVICES& PUNE STP | E7: Name and address of principal employer:
E8: ='4-22Master'!AQ10 -> INFOSYS LTD.IL Pune STP Unit,Plot No.1
E9: ='4-22Master'!AQ11 -> Rajiv gandhi Info tech park,Hinjawadi,Taluk Mulshi,Pune,Maharashtra 411057
A11: S.No | B11: Name of workman | C11: Father's / Husband's Name | D11: Designation / Nature of employment | E11: Particulars of damage or loss | F11: Date of Damage or loss | G11: Whether workman showed cause against deduction | H11: Name of person in whose presence employee's explanation was heard | I11: Amount of deduction impossed | J11: Date of recovery | M11: Remarks
J12: No.of Instalments | K12: First Instalment | L12: Last instalment
A13: 1 | B13: 2 | C13: 3 | D13: 4 | E13: 5 | F13: 6 | G13: 7 | H13: 8 | I13: 9 | J13: 10 | K13: 11 | L13: 12 | M13: 13
B16: NO EMPLOYEE WAS IMPOSED DEDUCTIONS FOR DAMAGE OR LOSS FOR THE MONTH OF | H16: ='4-22Master'!E10 -> 44652
F36: Signature of the Contractor with Seal

Sheet Fines
A1: FORM XVII- REGISTER OF FINES
A3: (Vide Rule 78(1) (a) (i) of Contract Labour (Regulation and Abolition) Maharashtra Rules 1971
A4: Name and address of Contractor: | D4: ='4-22Master'!G5 -> Burgeon IT Services Pvt.Ltd. | E4: Name and address of the establishment in / under which contract is carried on:
B5: ='4-22Master'!G6 -> Siri Mansion LIGB 436 Dr.A S Rao Nagar,Hyderabad | E5: ='4-22Master'!AQ5 -> Burgeon IT Services Pvt.Ltd.
B6: ='4-22Master'!G7 -> 0 | E6: ='4-22Master'!AQ6 -> Siri Mansion LIGB 436 Dr.A S Rao Nagar,Hyderabad
A7: Nature and Location of Work: | D7: ='4-22Master'!G8 -> IT SUPPORTIVE SERVICES& PUNE STP | E7: Name and address of principal employer:
E8: ='4-22Master'!AQ10 -> INFOSYS LTD.IL Pune STP Unit,Plot No.1
E9: ='4-22Master'!AQ11 -> Rajiv gandhi Info tech park,Hinjawadi,Taluk Mulshi,Pune,Maharashtra 411057
A11: S.No | B11: Name of workman | C11: Father's / Husband's Name | D11: Designation / Nature of employment | E11: Act/Omission for which fine imposed | F11: Date of offence | G11: Whether workman showed cause against fine | H11: Name of person in whose presence employee's explanation was heard | I11: Wage-period and wge payable | J11: Amount of fine Imposed | K11: Date on which fine realised | L11: Remarks
A13: 1 | B13: 2 | C13: 3 | D13: 4 | E13: 5 | F13: 6 | G13: 7 | H13: 8 | I13: 9 | J13: 10 | K13: 11 | L13: 12
B16: NO EMPLOYEE WAS IMPOSED FINESFOR THE MONTH OF | H16: ='4-22Master'!E10 -> 44652
F35: Signature of the Contractor with Seal

Sheet Advances
A1: FORM XVIII- REGISTER OF ADVANCES
A3: (Vide Rule 78(1) (a) (i) of Contract Labour (Regulation and Abolition) Maharashtra Rules 1971
A4: Name and address of Contractor: | D4: ='4-22Master'!G5 -> Burgeon IT Services Pvt.Ltd. | E4: Name and address of the establishment in / under which contract is carried on:
B5: ='4-22Master'!G6 -> Siri Mansion LIGB 436 Dr.A S Rao Nagar,Hyderabad | E5: ='4-22Master'!AQ5 -> Burgeon IT Services Pvt.Ltd.
B6: ='4-22Master'!G7 -> 0 | E6: ='4-22Master'!AQ6 -> Siri Mansion LIGB 436 Dr.A S Rao Nagar,Hyderabad
A7: Nature and Location of Work: | D7: ='4-22Master'!G8 -> IT SUPPORTIVE SERVICES& PUNE STP | E7: Name and address of principal employer:
E8: ='4-22Master'!AQ10 -> INFOSYS LTD.IL Pune STP Unit,Plot No.1
E9: ='4-22Master'!AQ11 -> Rajiv gandhi Info tech park,Hinjawadi,Taluk Mulshi,Pune,Maharashtra 411057
A11: S.No | B11: Name of workman | C11: Father's / Husband's Name | D11: Designation / Nature of employment | E11: Wage period and wages payable | F11: Date and amount of advance given | G11: Purpose(s) for which advance made | H11: Number of instalments by which advance to be repaid | I11: Date and amount of each instalment repaid | J11: Date on which last instalment was repaid | K11: Remarks
A13: 1 | B13: 2 | C13: 3 | D13: 4 | E13: 5 | F13: 6 | G13: 7 | H13: 8 | I13: 9 | J13: 10 | K13: 11
B16: NO EMPLOYEE TAKEN ADVANCE FOR THE MONTH OF | F16: ='4-22Master'!E10 -> 44652
G41: Signature of the Contractor with Seal

Sheet Overtime
A1: FORM XIX- REGISTER OF OVERTIME
A3: (Vide Rule 78(1) (a) (i) of Contract Labour (Regulation and Abolition) Maharashtra Rules 1971
A4: Name and address of Contractor: GROTECH LANDSCAPE DEVELOPERS PVT.LTD. E-35 GREATER KAILASH ENCLAVE-1 NEW DELHI | D4: ='4-22Master'!G5 -> Burgeon IT Services Pvt.Ltd. | F4: Name and address of the establishment in which under contract is carried on:
B5: ='4-22Master'!G6 -> Siri Mansion LIGB 436 Dr.A S Rao Nagar,Hyderabad | F5: ='4-22Master'!AQ5 -> Burgeon IT Services Pvt.Ltd.
B6: ='4-22Master'!G7 -> 0 | F6: ='4-22Master'!AQ6 -> Siri Mansion LIGB 436 Dr.A S Rao Nagar,Hyderabad
A7: Nature and Location of Work: | D7: ='4-22Master'!G8 -> IT SUPPORTIVE SERVICES& PUNE STP | F7: Name and address of principal employer:
F8: ='4-22Master'!AQ10 -> INFOSYS LTD.IL Pune STP Unit,Plot No.1
F9: ='4-22Master'!AQ11 -> Rajiv gandhi Info tech park,Hinjawadi,Taluk Mulshi,Pune,Maharashtra 411057
A11: S.No | B11: Name of workman | C11: Father's / Husband's Name | D11: Sex | E11: Designation / Nature of employment | F11: Date on which overtime worked | G11: Total overtime worked or production in case of piece-rates | H11: Normal rate of wages | I11: Overtime rate of wages | J11: overtime earnings | K11: Date on which overtime wages paid | L11: Remarks
A13: 1 | B13: 2 | C13: 3 | D13: 4 | E13: 5 | F13: 6 | G13: 7 | H13: 8 | I13: 9 | J13: 10 | K13: 11 | L13: 12
B16: NO EMPLOYEE DONE OVERTIME FOR THE MONTH OF | F16: ='4-22Master'!E10 -> 44652
G37: Signature of the Contractor with Seal

Sheet Accident
A1: ACCIDENT BOOK& REGISTER OF ACCIDENTS & DANGEROUS OCCURRENCES
A3: (Vide Form 15 under Rule 66 of E.S.I. Regulations & Form 26 under Rule 104 of A.P.Factories Rules, 1950)
A4: Name and address of Contractor: | D4: ='4-22Master'!G5 -> Burgeon IT Services Pvt.Ltd. | F4: Name and address of the establishment in / under which contract is carried on:
B5: ='4-22Master'!G6 -> Siri Mansion LIGB 436 Dr.A S Rao Nagar,Hyderabad | F5: ='4-22Master'!AQ5 -> Burgeon IT Services Pvt.Ltd.
B6: ='4-22Master'!G7 -> 0 | F6: ='4-22Master'!AQ6 -> Siri Mansion LIGB 436 Dr.A S Rao Nagar,Hyderabad
A7: Employer's Code No. 52000570900001099 | F7: Name and address of principal employer:
F8: ='4-22Master'!AQ10 -> INFOSYS LTD.IL Pune STP Unit,Plot No.1
F9: ='4-22Master'!AQ11 -> Rajiv gandhi Info tech park,Hinjawadi,Taluk Mulshi,Pune,Maharashtra 411057
A11: S.No | B11: Date and time of notice in Form 16 u/E.S.I. Regulations or date of report ( in form 18 u/Factories Rules) to Inspector of Factories | C11: Name and address of the Injured Person | D11: Sex | E11: Age | F11: Insurance Number | G11: Shift,Department and occupation of employee | H11: Name,occupation,address and signature or the thumb impression of the persons giving notice | L11: Signature and designation of the person who makes the entry | M11: Name,address and occupation of the two witnesses | N11: No.of days injured person was absent from work | O11: Remarks
B13: Date and time | G13: Dept. Shift Occupation | H13: Date of the accident | I13: Time of Injury | J13: Place of Injury | K13: Cause of Injury
B16: NO ACCIDENT OCCURRED FOR THE MONTH OF | F16: ='4-22Master'!E10 -> 44652
J34: Signature of the Contractor with Seal

Sheet FORM A
B1: FORM A
B2: [See Rule 3 of Maternity Act Rules, 1965]
B3: MUSTER ROLL
B4: Name of [mine or circus]: | D4: ='4-22Master'!G5 -> Burgeon IT Services Pvt.Ltd. | E4: ='4-22Master'!G6 -> Siri Mansion LIGB 436 Dr.A S Rao Nagar,Hyderabad
B5: 1 | C5: Serial Number.
B6: 2 | C6: Name of woman and her father's (or, if married, husband's) name.
B7: 3 | C7: Date of appointment.
B8: 4 | C8: Nature of work.
B9: 5 | C9: Dates with month and year in which she is employed, laid off and not employed.
C10: Month | D10: No.of days employed | E10: No.of days laid off | F10: No.of days not employed | G10: Remarks
B17: 6 | C17: Date on which the woman gives notice under section 6.
B18: 7 | C18: Date of discharge/dismissal, if any.
B19: 8 | C19: Date of production of proof of pregnancy under section 6.
B20: 9 | C20: Date of birth of child.
B21: 10 | C21: Date of production of proof of delivery/miscarriage/ 1[Medical Termination of pregnancy/ tubectomy operation/death.]
B22: 11 | C22: Date of production of proof of illness referred to in section 10.
B23: 12 | C23: Date with the amount of maternity benefit paid in advance of expected delivery.
B24: 13 | C24: Date with the amount of subsequent payment of maternity benefit.
B25: 14 | C25: Date with the amount of bonus, if paid, under section 8.
B26: 15 | C26: Date with the amount of wages paid on account of leave under section 9.
B27: 15A | C27: Date with the amount of wages paid on account of leave under section 9A
B28: 16 | C28: Date with the amount of wages paid on account of leave under section 10 and period of leave granted
B29: 17 | C29: Name of the person nominated by the woman under section 6.
B30: 18 | C30: If the woman dies, the date of her death, the name of the person to whom maternity benefit and/or other amount was paid, the amount thereof, and the date of payment.
B31: 19 | C31: If the woman dies and the child survives, the name of the person to whom the amount of maternity benefit was paid on behalf of the child and the period for which it was paid.
B32: 20 | C32: Signature of the employer of 3[the mine or circus] authenticating the entries in the muster-roll.
B33: 21 | C33: Remarks column for the use of the Inspector.
B34: Certifited that no pregnant employee worked for the month of | G34: ='4-22Master'!E10 -> 44652
E36: For | F36: ='4-22Master'!G5 -> Burgeon IT Services Pvt.Ltd.
F38: Authorized Signatory

Sheet FORM B
B1: FORM B
B2: [See Rule 4(1) of Maternity Act Rules, 1965]
B3: Name of [mine or circus]: | D3: ='4-22Master'!G5 -> Burgeon IT Services Pvt.Ltd. | E3: ='4-22Master'!G6 -> Siri Mansion LIGB 436 Dr.A S Rao Nagar,Hyderabad
B6: This is to certify that I examined…. wife /daughter of ….. a woman employee in name of Mine or Circus on (Date)
D7: and found/ cannot discover that she is pregnant and is expected to be delivered of a child within (month/days) from the above
B8: mentioned date date/has undergone miscarriage/[Medical termination of pregnancy or tubectomy operation]/has been delivered
B9: of a child on….. (date) or is suffering from…..(date) from illness arising out of pregnancy/delivery/premature birth of a child or miscarriage/
B10: [Medical termination of pregnancy or tubectomy operation ].
D12: Signature, qualifications and designation of Medical Officer/Medical Practitioner.
B15: Date…..
B16: Definitions of "child" and "miscarriage" as in the Maternity Benefit Act, 1961.-
B17: 1. "Child" includes a still-born child.
B18: 2. "Miscarriage" means expulsion of the contents of a pregnant uterus at any period prior to or during the twenty-sixth week of pregnancy
B19: but does not include any miscarriage,the causing of which is punishable under the Indian Penal Code.
B20: Ins. by G.S.R. 70(E), dated 31st January, 1996 (w.e.f. 31-1-1996).
B22: Certifited that no pregnant employee worked for the month of | G22: ='4-22Master'!E10 -> 44652
E25: For | F25: ='4-22Master'!G5 -> Burgeon IT Services Pvt.Ltd.
F27: Authorized Signatory

Sheet FORM C
B1: FORM C
B2: [See Rule 4(4) of Maternity Act Rules, 1965]
B4: Name of [mine or circus]: | D4: ='4-22Master'!G5 -> Burgeon IT Services Pvt.Ltd. | E4: ='4-22Master'!G6 -> Siri Mansion LIGB 436 Dr.A S Rao Nagar,Hyderabad
B7: This is to certify that
B8: Smt……………………………….wife/daughter of ……………………….employed in ……………….(name of [Mine or Circus]
B9: expired on ……………………..before/during/after confinement. The child died on …./survives her.
D13: Signature, qualifications and designation of Medical Officer/Medical Practitioner.
C15: Ins. by G.S.R. 70(E), dated 31st January, 1996 (w.e.f. 31-1-1996).
B17: Certifited that no pregnant employee worked for the month of | G17: ='4-22Master'!E10 -> 44652
E20: For | F20: ='4-22Master'!G5 -> Burgeon IT Services Pvt.Ltd.
F22: Authorized Signatory

Sheet FORM D
B1: FORM D
B2: [See Rule 4(5) of Maternity Act Rules, 1965]
B4: Name of [mine or circus]: | D4: ='4-22Master'!G5 -> Burgeon IT Services Pvt.Ltd. | E4: ='4-22Master'!G6 -> Siri Mansion LIGB 436 Dr.A S Rao Nagar,Hyderabad
B7: This is to certify that I examined……………..wife/daughter of ……….a woman employed in ………..(name of [Mine or Circus ]
B8: and found that she has been delivered of a child/has undergone miscarriage on ….(date)
E11: Signature of registered Midwife
C13: Date….
C14: Definitions of "child" and "miscarriage" as in the Maternity Benefit Act, 1961-
C15: 1. "Child" includes a still-born child.
C16: 2. "Miscarriage" means expulsion of the contents of a pregnant uterus at any period prior to or during the twenty-sixth
C17: week of pregnancy but does not include any miscarriage, the causing of which is punishable under the Indian Penal Code.
C20: Subs. by G.S.R. 59(E), dated 27th February, 1975 (w.e.f. 1-3-1975).
B22: Certifited that no pregnant employee worked for the month of | G22: ='4-22Master'!E10 -> 44652
E25: For | F25: ='4-22Master'!G5 -> Burgeon IT Services Pvt.Ltd.
F27: Authorized Signatory

Sheet ESI cards Reg
C1: ='4-22Master'!G5 -> Burgeon IT Services Pvt.Ltd. | E1: ESI PAHECHAN CARDS ISSUE REGISTER
B2: S.No | C2: Name of the Employee | D2: ESI Number | E2: Issue Date | F2: Signature | G2: Remarks
B3: 2 | C3: ='4-22Master'!#REF! -> #REF! | D3: ='4-22Master'!#REF! -> #REF!
B4: 5 | C4: ='4-22Master'!#REF! -> #REF! | D4: ='4-22Master'!#REF! -> #REF!
B5: 6 | C5: ='4-22Master'!#REF! -> #REF! | D5: ='4-22Master'!#REF! -> #REF!
B6: 7 | C6: ='4-22Master'!V18 -> Amith a | D6: ='4-22Master'!U18 -> N/A
B7: 8 | C7: ='4-22Master'!#REF! -> #REF! | D7: ='4-22Master'!#REF! -> #REF!
B8: 9 | C8: ='4-22Master'!#REF! -> #REF! | D8: ='4-22Master'!#REF! -> #REF!
B9: 10 | C9: ='4-22Master'!#REF! -> #REF! | D9: ='4-22Master'!#REF! -> #REF!
B10: 11 | C10: ='4-22Master'!#REF! -> #REF! | D10: ='4-22Master'!#REF! -> #REF!
B11: 12 | C11: ='4-22Master'!#REF! -> #REF! | D11: ='4-22Master'!#REF! -> #REF!
B12: 13 | C12: ='4-22Master'!#REF! -> #REF! | D12: ='4-22Master'!#REF! -> #REF!
B13: 14 | C13: ='4-22Master'!#REF! -> #REF! | D13: ='4-22Master'!#REF! -> #REF!
B14: 15 | C14: ='4-22Master'!#REF! -> #REF! | D14: ='4-22Master'!#REF! -> #REF!
B15: 16 | C15: ='4-22Master'!#REF! -> #REF! | D15: ='4-22Master'!#REF! -> #REF!
B16: 17 | C16: ='4-22Master'!#REF! -> #REF! | D16: ='4-22Master'!#REF! -> #REF!
B17: 18 | C17: ='4-22Master'!#REF! -> #REF! | D17: ='4-22Master'!#REF! -> #REF!
B18: 19 | C18: ='4-22Master'!#REF! -> #REF! | D18: ='4-22Master'!#REF! -> #REF!
B19: 20 | C19: ='4-22Master'!#REF! -> #REF! | D19: ='4-22Master'!#REF! -> #REF!

Sheet Form-I
B1: FORM I
B2: NOMINATION AND DECLARATION FORM
B3: (Vide Rule 3 of Payment of wages Act Central & A.P Rules, 1936)
B4: Name and Address of the Contractor | H4: Name and Address of the Establishment in/under which Contract is carried on:
B7: =#REF! -> #REF! | H7: =#REF! -> #REF!
B9: =#REF! -> #REF! | H9: =#REF! -> #REF!
B12: Nature of work and location of work: | H12: Name and address of Principal Employer:
H15: =#REF! -> #REF!
B16: =#REF! -> #REF!
H17: =#REF! -> #REF!
B19: 1. Name of the person making nomination | H19: ='4-22Master'!#REF! -> #REF!
B20: 2. Father's/Husband name | H20: ='4-22Master'!#REF! -> #REF!
B21: 3. Date of Birth | H21: ='4-22Master'!#REF! -> #REF!
B22: 4. Sex | H22: ='4-22Master'!#REF! -> #REF!
B23: 5. Marital Status | H23: Un-Married
B24: 6.Address
B25: Permanent | H25: ='4-22Master'!#REF! -> #REF!
H26: ='4-22Master'!#REF! -> #REF!
H27: ='4-22Master'!#REF! -> #REF!
B28: Temporary | H28: ='4-22Master'!#REF! -> #REF!
H29: ='4-22Master'!#REF! -> #REF!
H30: ='4-22Master'!#REF! -> #REF!
B31: I hereby nominate the person(s)/cancel the nomination made by me previously and nominate the person(s) mentioned below to
B32: receive any amount due to me from the employer,in the event to my death.
B33: Name of the Nominee/nominees | E33: Address | G33: Nominee's relationship With the member | I33: Date of Birth | J33: Total amount of Share of accumulations | K33: If the nominee is minor,name,relationship and address of the guardian
B34: 1 | E34: 2 | G34: 3 | I34: 4 | J34: 5 | L34: 6
B35: ='4-22Master'!#REF! -> #REF! | E35: Same as permanant address | G35: Father | I35: 54 years | J35: 1 | K35: N/A
B39: 1.Certified that I have no family and should I acquire a family hereafter,the above nomination shall be deemed as cancelled.
B40: 2.Certified that my father/mother is/ are dependent upon me.
B41: 3.Strike out whichever is not applicable.
I43: Signature or the thumb impression of the employed person
F44: CERTIFCATE BY EMPLOYER
A45: Certified that the above declaration and nomination has been signed/thumb impressed before me by Shri/Smt/Kum | K45: ='4-22Master'!#REF! -> #REF!
A46: employed in my establishment after he/she has read the entry/entries have been read over to him/her by me and got confirmed by him/her.
F49: Signature or the employer or other authorized officer of the establiment and Designation
A50: Place | B50: Hyderabad | F50: ='4-22Master'!AQ5 -> Burgeon IT Services Pvt.Ltd.
A51: Date | B51: ='4-22Master'!#REF! -> #REF! | F51: ='4-22Master'!AQ6 -> Siri Mansion LIGB 436 Dr.A S Rao Nagar,Hyderabad
B53: FORM I
B54: NOMINATION AND DECLARATION FORM
B55: (Vide Rule 3 of Payment of wages Act Central & A.P Rules, 1936)
...

Sheet Form-2
K1: (FORM 2 REVISED)
B2: NOMINATION AND DECLARATION FORM FOR UNEXEMPTED/EXEMPTED ESTABLISHMENTS
B3: Declaration and Nomination Form under the Employees Provident Funds and Employees Pension Schemes
B4: (Paragraph 33 and 61(1) of the Employees Provident Fund Scheme 1952 and Paragraph 18 of the Employees Pension Scheme 1995)
B6: 1. Name of the person making nomination | H6: ='4-22Master'!#REF! -> #REF!
B7: 2. Father's/Husband name | H7: ='4-22Master'!#REF! -> #REF!
B8: 3. Date of Birth | H8: ='4-22Master'!#REF! -> #REF!
B9: 4. Sex | H9: ='4-22Master'!#REF! -> #REF!
B10: 5. Marital Status | H10: Un-Married
B11: 6.Address
B12: Permanent | H12: ='4-22Master'!#REF! -> #REF!
H13: ='4-22Master'!#REF! -> #REF!
H14: ='4-22Master'!#REF! -> #REF!
G15: PART-A(EPF)
B16: I hereby nominate the person(s)/cancel the nomination made by me previously and nominate the person(s) mentioned below to
B17: receive any amount due to me from the employer,in the event to my death.
B18: Name of the Nominee/nominees | E18: Address | G18: Nominee's relationship With the member | I18: Date of Birth | J18: Total amount of Share of accumulations | K18: If the nominee is minor,name,relationship and address of the guardian
B19: 1 | E19: 2 | G19: 3 | I19: 4 | J19: 5 | L19: 6
B20: ='4-22Master'!#REF! -> #REF! | E20: Same as Permanant Address | G20: Father | I20: 55 Years | J20: 1 | K20: N/A
B24: 1.Certified that I have no family and should I acquire a family hereafter,the above nomination shall be deemed as cancelled.
B25: 2.Certified that my father/mother is/ are dependent upon me.
B26: Strike out whichever is not applicable | J26: Signature/or thumb impression of the subscriber
G27: PART (EPS)
G28: Para 18
B29: I hereby furnish below particulars of the members of my family who would be eligible to receive Widow/Children Pension in the event of
B30: my premature death in service
B31: S.No | C31: Name & Address of the Family Member | I31: Age | J31: Relationship with the member
B32: 1 | E32: 2 | I32: 3 | K32: 4
B37: Certified that I have no family as defined in para 2 (vii) of the Employees's Family Pension Scheme 1995 and should I acquire a family hereafter
B38: I shall furnish Particulars there on in the above form.
B39: I hereby nominate the following person for receiving the monthly widow pension (admissible under para 16 2 (a) (1) & (ii) in the even of my death
B40: without leaving any eligible member for receiving pension.
B41: Name and Address of the nominee | G41: Date of Birth | I41: Relationship with member
B47: Date | C47: ='4-22Master'!#REF! -> #REF! | I47: Signature or thumb impression of the subscriber
F48: CERTIFCATE BY EMPLOYER
A49: Certified that the above declaration and nomination has been signed/thumb impressed before me by Shri/Smt/Kum | K49: ='4-22Master'!#REF! -> #REF!
A50: employed in my establishment after he/she has read the entry/entries have been read over to him/her by me and got confirmed by him/her.
F52: Signature or the employer or other authorized officer of the establiment and Designation
A53: Place | B53: Hyderabad | F53: ='4-22Master'!G5 -> Burgeon IT Services Pvt.Ltd.
A54: Date | B54: ='4-22Master'!#REF! -> #REF! | F54: ='4-22Master'!G6 -> Siri Mansion LIGB 436 Dr.A S Rao Nagar,Hyderabad
...

Sheet Form 11
I1: New Form No. 11 - Declaration Form
B2: (To be retained by t he employer for future reference)
D3: EMPLOYEES' PROVIDENT FUND ORGANIZATION | I3: Emp Code: | K3: ='4-22Master'!#REF! -> #REF!
C4: Employees' Provident Funds Scheme, 1952 (Paragraph 34 & 57) & | I4: Company | J4: ='4-22Master'!G5 -> Burgeon IT Services Pvt.Ltd.
C5: The Employees' Pension Scheme, 1995 (Paragraph 24) | I5: ='4-22Master'!G6 -> Siri Mansion LIGB 436 Dr.A S Rao Nagar,Hyderabad
A8: 1 | B8: Name of the Member | H8: ='4-22Master'!#REF! -> #REF!
A9: 2 | B9: Fathers' Name | F9: Husband's Name | H9: ='4-22Master'!#REF! -> #REF!
B10: (Please tick whichever is applicable)
A11: 3 | B11: Date of Birth (DD/MM/YYYY) | H11: ='4-22Master'!#REF! -> #REF!
A12: 4 | B12: Gender (Male/Female/Transgender) | H12: ='4-22Master'!#REF! -> #REF!
A13: 5 | B13: Marital Status(married / Unmarried / Widow/divorce) | H13: UNMARRIED
A14: 6 | B14: (a) | C14: Email Id
B15: (b) | C15: Mobile No.
A16: 7 | B16: Whether earlier a member of the Employees' Provident Fund Scheme, 1952 ? | H16: Yes | K16: No
A17: 8 | B17: Whether earlier a member of the Employees' Pension Scheme, 1995? | H17: Yes | K17: No
F18: Previous employment details [if Yes to 7 &/or 8 above]
A19: 9 | B19: a) | C19: Universal Account Number
B20: b) | C20: Previous PF Account Number
B21: C) | C21: Date of exit from previous employment (DD/MM/YYYY)
B22: d) | C22: Scheme Certificate No. (if issued)
B23: e) | C23: Pension Payment Order (PPO) No. (if issued)
A24: 10 | B24: a) | C24: International Worker | H24: Yes | K24: No
B25: b) | C25: If yes, state country of origin(India/Name of other country)
B26: C) | C26: Passport No.
B27: d) | C27: Validity of passport [(DD/MM/YYYY) to (DD/MM/YYYY)]
E28: KYC Details (attach self attested copies of following KYCs)
A29: 11 | B29: a) | C29: Bank Account No. & IFS Code
B30: b) | C30: AADHAR No.
B31: c) | C31: Permanent Account No. (PAN), if available
F32: UNDERTAKING
B33: 1) | C33: Certified that the particulars are true to the best of my knowledge.
B34: 2) | C34: I authorize EPFO to use my Aadhar for verification/authentication/eKYC purpose for service delivery.
B35: 3) | C35: Kindly transfer the funds and service details, if applicable from the previous PF account as declared above to the present P.F. Account (The Transfer would be possible only if the identified KYC details approved by previous employer has been verified by present employer
B36: 4) | C36: In case of changes in above details, the same will be intimated to employer at the earliest.
C37: Date : | D37: ='4-22Master'!#REF! -> #REF!
C38: Place: | D38: Hyderabad | J38: Signature of Member
F40: DECLARATION BY PRESENT EMPLOYER
A41: A) | B41: The member Mr./Ms./Mrs. | E41: ='4-22Master'!#REF! -> #REF! | H41: has joined on | J41: ='4-22Master'!#REF! -> #REF! | K41: and has been allotted PF Number
B42: ='4-22Master'!#REF! -> #REF!
A43: B) | B43: In case the person was earlier not a member of EPF Scheme, 1952 and EPS, 1995:
...

Sheet Form-F
A1: F O R M – F
A2: [See sub-Rule (1) of Rule 6] The Payment of Gratuity Rules, 1973:
A3: NOMINATION
A4: To
A5: ='4-22Master'!G5 -> Burgeon IT Services Pvt.Ltd.
A6: ='4-22Master'!G6 -> Siri Mansion LIGB 436 Dr.A S Rao Nagar,Hyderabad
A8: 1. I, Shri / Shrimati / Kumari | C8: ='4-22Master'!#REF! -> #REF!
A9: whose particulars are given in the statement below, hereby nominate the person(s) mentioned below to receive the gratuity payable after my death as also the gratuity standing to my credit in the event of my death before that amount has become payable, or having become payable has not been paid and direct that the said amount of gratuity shall be paid in proportion indicated against the name(s) of the nominee(s).
A11: 2. I hereby certify that the person(s) mentioned is a /are member(s) of my family within the meaning of clause (h) of Section 2 of the Payment of Gratuity Act, 1972.
A13: 3. I hereby declare that I have no family within the meaning of clause (h) of Section 2 of the said Act.
A15: 4. (a) My father/mother/parents is/are not dependent on me
A16: (b) My husband’s father/mother/parents is/are not dependent on my husband.
A18: 5. I have excluded my husband from my family by a notice dated the ……………. to the Controlling Authority in terms of the proviso to clause (h) of Section 2 of the said Act.
A20: 6. Nomination made herein invalidates my previous nomination.
A22: NOMINEE(S)
A23: Name in full with full address of nominee(s): | B23: Relationship with the empliyee | C23: Age of nominee: | D23: Proportion by which the gratuity will be shared:
A24: 1 | B24: 2 | C24: 3 | D24: 4
A25: ='4-22Master'!#REF! -> #REF! | B25: Father | C25: 54 Years | D25: 1
A29: STATEMENT
A31: 1. Name of employee in full: | C31: ='4-22Master'!#REF! -> #REF!
A32: 2. Sex: | C32: ='4-22Master'!#REF! -> #REF!
A33: 3. Religion: | C33: Muslim
A34: 4. Whether unmarried/married/widow/widower: | C34: Un married
A35: 5. Department/Branch/Section where employed: | C35: ='4-22Master'!#REF! -> #REF!
A36: 6. Post held with Ticket No. or Serial No. if any: | C36: ='4-22Master'!#REF! -> #REF!
A37: 7. Date of appointment: | C37: ='4-22Master'!#REF! -> #REF!
A38: 8. Permanent address:
C39: ='4-22Master'!#REF! -> #REF!
C40: ='4-22Master'!#REF! -> #REF!
C41: ='4-22Master'!#REF! -> #REF!
A42: Place: | B42: Hyderabad
A43: Date: | B43: ='4-22Master'!#REF! -> #REF! | C43: Signature/Thumb impression of the employee
A45: Declaration by witnesses:
A46: Nomination signed/thumb impressed before me:
A48: Name in full and full address of witnesses: | C48: Signature of witnesses:
A49: 1 | C49: 1
A50: 2 | C50: 2
C51: Certificate by the Employer
A52: Certified that the particulars of the above nomination have been verified and recorded in t his establishment
A53: Employer's reference No, if any
...

Sheet Serive Certificate
B4: FORM XV
B5: [Vide rule 77 of Contract Labour (Regul. & Abolition) Central & A.P. Rules, 1971]
B7: SERVICE CERTIFICATE
B9: Name and address of Contractor : | G9: Name and address of establishment in / under which contract is caried on :
B11: ='4-22Master'!G5 -> Burgeon IT Services Pvt.Ltd. | G11: ='4-22Master'!AQ5 -> Burgeon IT Services Pvt.Ltd.
B13: ='4-22Master'!G6 -> Siri Mansion LIGB 436 Dr.A S Rao Nagar,Hyderabad | G13: ='4-22Master'!AQ6 -> Siri Mansion LIGB 436 Dr.A S Rao Nagar,Hyderabad
B17: Nature and Location of work: | G17: Name and address of Principal Employer :
G19: ='4-22Master'!AQ10 -> INFOSYS LTD.IL Pune STP Unit,Plot No.1
B21: ='4-22Master'!G8 -> IT SUPPORTIVE SERVICES& PUNE STP | G21: ='4-22Master'!AQ11 -> Rajiv gandhi Info tech park,Hinjawadi,Taluk Mulshi,Pune,Maharashtra 411057
B26: Name and address of the workman :
B31: Age or date of Birth :
B33: Identification Marks :
B35: Father's / Husband's Name :
B38: Sl.No. | C38: Total period for which employed | E38: Nature of work done | G38: Rate of wage ( with particulars of units in case of piece work) | J38: Remarks
C40: From | D40: To
B41: 1 | C41: 2 | D41: 3 | E41: 4 | G41: 5 | J41: 6
H56: Signature of the Employer with Seal
