Workbook

Sheet PUNE SEZ UNIt-1-APRIL22WM Reg
A1: FORM IX- REGISTER OF PERSONS EMPLOYED
A3: (Vide Rule 78(1) (a) (i) of Contract Labour (Regulation and Abolition) Central /Maharastra.Rules 1974
A4: Name and address of Contractor:burgeon IT services Pvt.Ltd. | F4: Name and address of the establishment in / under which contract is carried on: burgeon IT services Pvt.Ltd. Siri mansion LIGH 436 DR.A S Rao nagar,Hyderabad
A5: Siri Mansion LIGB 436 Dr.A S Rao Nagar,Hyderabad
A7: Name and address of Contractor:burgeon IT services Pvt.Ltd. | F7: Name and address of principal employer:
F8: ='04-221Master'!AP10 -> INFOSYS LTD.IL Pune SEZ Unit-I,Plot No. 24/3
F9: Rajiv gandhi Info tech park,Village Mann,Pune,Maharashtra 411057
A11: S.No | B11: Name and Surname of workman | C11: Age | D11: SEX | E11: Father's/Husband's name | F11: Nature of Employement/Designation | G11: Permanent Home Address of worken | H11: Local Address | I11: Date of commencement of Employment | J11: Signature or Thumb impression of workman | K11: Date of Temination of Employment | L11: Reason for Termination | M11: Remarks
A13: 1 | B13: 2 | C13: 3 | E13: 4 | F13: 5 | G13: 6 | H13: 7 | I13: 8 | J13: 9 | K13: 10 | M13: 11
A14: 1 | B14: Asish kumar satapathy | C14: 33571 | D14: Male | E14: Kamal Kishore Gupta | F14: Technical Consultant | G14: 289/A Mangalwar Peth behind kamla nehru hospital Pune 11 | H14: E-4, MIG-II , BDA COLONY, C.S PUR, Bhubaneshwar 751016 | I14: 43283 | K14: 28.06.2019 | L14: Resigned
A15: 2 | B15: Shreyash Gupta | C15: 33571 | D15: Male | E15: Kamal Kishore Gupta | F15: Software Developer | G15: 289/A Mangalwar Peth behind kamla nehru hospital Pune 11 | H15: 289/A Mangalwar Peth behind kamla nehru hospital Pune 11 | I15: 43515 | K15: 26.12.2019 | L15: Resigned
A16: 3 | B16: Mahendra shiva das more | C16: 29587 | D16: Male | E16: MINAL MAHENDRA MORE | F16: Senior Software Engineer | G16: FLOT NO.B-905,OXY VOLI2,GATE NO.744 BAKORI ROAD,BIHIND JUNG COLLGE,GADHE VASTI WAGHOLI,PUNE 412207 | H16: FLOT NO.A 304,SLNO.32/3 SUMAN SILPHA,NEAR SIDHI LAWNS,NARHE GAON,PUNE,411041 | I16: 27/5/2019 | L16: Resigned
A17: 4 | B17: Amodh Kamble | C17: 34630 | D17: MALE | E17: NANDU KAMBLE | F17: Technical Consultant | G17: FL.NO-16, BLDG- 3, QUARTER GATE HOUSING SOCIETY, NANAPETH, PUNE-411002 | H17: FL.NO-16, BLDG- 3, QUARTER GATE HOUSING SOCIETY, NANAPETH, PUNE-411002 | I17: 43871 | K17: 31.may.2020 | L17: Resigned
A18: 5 | B18: Tanmay Saxena | C18: 33431 | D18: Female | E18: Alok Saxena | F18: Senior Software Developer | G18: h.no-51 shubhalay villas barkheda pathani BHEL Bhopal MP, 462023 | H18: h.no-51 shubhalay villas barkheda pathani BHEL Bhopal MP, 462023 | I18: 44021 | L18: Resigned
A19: 6 | B19: Venegella Kanaka durga | C19: 31669 | D19: Female | E19: Venkateshwar Rao | F19: Senior Software Engineer | G19: Dr no-115,Sujatha nagar, vinjamur SPSR Nellore ,Andra Pradesh,pincode:560066 | H19: No.3,Malempati Homes,8th A cross, Manjunatha Layout, Munekollala, Maratahalli, Bangalore - 560037 | I19: 44021 | K19: Active | L19: Active | N19: 1
A20: 7 | B20: A Achyuthram Kumar | C20: 35595 | D20: MALE | E20: naredra Babu | F20: AS400 Consultant | G20: c/4-3, Near Nagarpamma Temple, Vadaku, Nellore, AP 524415 | H20: c/4-3, Near Nagarpamma Temple, Vadaku, Nellore, AP 524415 | I20: 44021 | L20: Resigned
A21: 8 | B21: Prakash Tammishetty | C21: 33034 | D21: MALE | E21: Thammisetti Narasimhulu | F21: Senior Software Engineer | G21: Vadde Agraharam vli,Rachayapet Post,Gopavaram mandal,Kadapa dist,Andhrapradesh.Pin-516233. | H21: Khavyasree Mens Pg,Cyberhills Colony,Near Magnum oppus,Gachibowli,Hyderabad,Telangana,500032 | I21: 44020 | L21: Resigned
A22: 9 | B22: TARANNUM MUDASSAR IDRIS RAUT | C22: 33301 | D22: MALE | E22: Mudassar Idris Raut | F22: Software Engineer | G22: Plot no.16,St ni45/1A/part 1,Joshi Colony,Shahunagar,Belagavi | H22: Flat no.18,wing b1,Libera Garden,NIBM,Pune | I22: 44034 | L22: Resigned
A23: 10 | B23: Moeenahmed Shakilahmed Shaikh | C23: 30310 | D23: MALE | E23: Shaik Azara Shakilahmed | F23: Splunk Developer | G23: 967 Ravivarpet, Ghulamali,Chambers laxmi Road, Pune, MH 411002 | H23: 967 Ravivarpet, Ghulamali,Chambers laxmi Road, Pune, MH 411002 | I23: 44034 | K23: Active | L23: Active | N23: 2
A24: 11 | B24: Swati Panjwani | C24: 33523 | D24: Female | E24: Niranjan Kumar Panjwani | F24: SENIOR SOFTWARE ENGINEER | G24: 168 ADM LIne , Acharya Kriplani Ward Madhav Nagar Katni 483504 | H24: R2 9 Samdariya City, ahead parth health club, Madhav Nagar , Katni MP -483501 | I24: 44048 | L24: Resigned
A25: 12 | B25: Pravin Dattatray Karde | C25: 32053 | D25: MALE | E25: Dattatray | F25: Solution Architect Cloud | G25: Saakar Almond Park, B 402, Near Kumar Meadows, off solapur Highway, Manjari BK . 412307 | H25: Saakar Almond Park, B 402, Near Kumar Meadows, off solapur Highway, Manjari BK . 412307 | I25: 44064 | L25: Resigned
A26: 13 | B26: SHARJEEL REHMANY | C26: 33552 | D26: MALE | E26: Javed Akhtar Rehmany | F26: Analyst System Administrator | G26: 9/D, 2nd floor, Madina compound,80 tenaments, B.J Road , Jacob circle,mumbai :- 400011 | H26: 9/D, 2nd floor, Madina compound,80 tenaments, B.J Road , Jacob circle,mumbai :- 400011 | I26: 44123 | L26: Resigned
A27: 14 | B27: Jagdish Salian | C27: 27051 | D27: MALE | E27: Babita Jagdish Salian | F27: Senior Project Manager | G27: 2/26, Mehta Chambers, Seth Motishah Marg, Mazgaon, Mumbai - 400010 | H27: C-404, Vardhaman Heights, Survey No.66/2, Chatrapati Chowk, Gopinath Munde Marg, Rahatani-Kalewadi Link Road, Kalewadi, Pune - 411017 | I27: 44145 | K27: Active | L27: Active
A28: 15 | B28: Shaik Naseer | C28: 31968 | D28: MALE | E28: Shaik Nanne Sab | F28: Senior Technical Consultant | G28: #12-199-a,Narayana rao Street ,Valisab Road,kadiri-515591,Anantapur dist,AP | H28: Door No: 302,CKB Layout,munnekollla,Marathahalli-560037,Bangalore,Karnataka | I28: 44249 | K28: Active | L28: Active
A29: 16 | B29: Apurva Kumari | C29: 32603 | D29: Female | E29: sunil kumar thakur | F29: Senior Support analyst | G29: VILL POST BHARWARA POLICE STATION SINGHWARA DIST DARBHNGA BIHAR 847104 | H29: VILL POST BHARWARA POLICE STATION SINGHWARA DIST DARBHNGA BIHAR 847104 | I29: 44264 | L29: Resigned
A30: 17 | B30: Mahesh babu | C30: 32150 | D30: Male | E30: Muralikrishna | F30: ITPM Servicenow | G30: 16-178,Pamarru, Krishna Dist, AP 521157 | H30: 16-178,Pamarru, Krishna Dist, AP 521157 | I30: 44292 | K30: Active | L30: Active
A31: 18 | B31: AMARDEEP BORKAR | C31: 29174 | D31: Male | E31: TUKARAM | F31: Technical Consultant | G31: SR.NO.317,PLOT NO.314,LANE NO.3,RUTUJA PARK, BEHIND BHARAT VAJAN KATA, URULI DEVACHI,PUNE - 412308 | H31: SR.NO.317,PLOT NO.314,LANE NO.3,RUTUJA PARK, BEHIND BHARAT VAJAN KATA, URULI DEVACHI,PUNE - 412308 | I31: 44312 | K31: Active | L31: Active
A32: 19 | B32: Yarramaddu Raveendra Reddy | C32: 32972 | D32: Male | E32: Ramachandra Reddy | F32: Sr Citrix Administrator | G32: 11/25,Baddipally village,Mudivedu post,Kura Balakota mandal,Chittor district,AP 517350 | H32: 11/25,Baddipally village,Mudivedu post,Kura Balakota mandal,Chittor district,AP 517350 | I32: 44335 | K32: Active | L32: Active | N32: 3
A33: 20 | B33: Chitra Kulkarni | C33: 32113 | D33: Female | E33: Nirbay Gopal | F33: Project Manager | G33: H No 479,Sy No 39,Road no.5, Mathenagar,Vadgaon sheri,Pune,Maharastra 411014 | H33: H No 479,Sy No 39,Road no.5, Mathenagar,Vadgaon sheri,Pune,Maharastra 411014 | I33: 44390 | K33: Active | L33: Active | N33: 4
A34: 21 | B34: Reddiah Gumitha | C34: OOOO | D34: Male | E34: ZZZ | F34: Sr. Software Engineer | G34: WWWW | H34: WWWW | I34: 44409 | K34: Active | L34: Active
A35: 22 | B35: Sunnapalli Anil | C35: 32813 | D35: Male | E35: Narsingam | F35: Sr. Software Engineer | G35: 16-9-239,Puppalagutta,Railway flyover bridge,Chital,Warangal,TS 506002 | H35: 16-9-239,Puppalagutta,Railway flyover bridge,Chital,Warangal,TS 506002 | I35: 44409 | K35: Active | L35: Active | N35: 5
A36: 23 | B36: Viswanath B | C36: 34917 | D36: Male | E36: Jayachandra Reddy | F36: SQL DBA Administrator | G36: H No 3-59,Shiva sandhya nagar,KSRM engineering college,CK Dinne Mandal,Kadapa,AP 516003 | H36: H No 3-59,Shiva sandhya nagar,KSRM engineering college,CK Dinne Mandal,Kadapa,AP 516003 | I36: 44420 | K36: RESIGNATION | L36: Resigned
A37: 24 | B37: Himanshu Anand | C37: 31328 | D37: Male | E37: A.K. Gupta | F37: Sr. DBA / Sr. Administrator | G37: 25-B Radha Nagar, Rohini complex, Mathura, UP 281004 | H37: J-901 City Apartments,aditya world city, Gaziabad, UP 201002 | I37: 44432 | K37: Active | L37: Active | N37: 6
A38: 25 | B38: Kanchupati Kondaiah | C38: 32669 | D38: Male | E38: U MALLESWARAMMA | F38: SQL DATABASE ADMINISTRATOR | G38: CHENNAVARAM Village, Rachayapost, gopavaram mandal, YSR Kadapa, AP 516233 | H38: CHENNAVARAM Village, Rachayapost, gopavaram mandal, YSR Kadapa, AP 516233 | I38: 44434 | K38: Active | L38: Active | N38: 7
A39: 26 | B39: Santosh Patel | C39: 32336 | D39: Male | E39: Kishorilal Patel | F39: Senior Support Engineer | G39: RNA- Plaza, Bldg R-6, Flat 714,Shree Ganesh CHS,Somani Gram, Rammandr road, Goregaon (west), Mumbai 400104. | H39: RNA- Plaza, Bldg R-6, Flat 714,Shree Ganesh CHS,Somani Gram, Rammandr road, Goregaon (west), Mumbai 400104. | I39: 44438 | K39: Active | L39: Active | N39: 8
A40: 27 | B40: Basweshwar Pawar | C40: 31899 | D40: Male | E40: Nandakumar eknath pawar | F40: Lead PMO | G40: H-302, Kohinoor Abhimaan Homes, somatane-Kasarai Road,Near Sai Temple, Mawal, PUNE 410506 | H40: H-302, Kohinoor Abhimaan Homes, somatane-Kasarai Road,Near Sai Temple, Mawal, PUNE 410506 | I40: 44446 | K40: Active | L40: Active | N40: 9
A41: 28 | B41: Swati Bhattacharya | C41: 29587 | D41: Female | E41: Madhav singnapurkar | F41: Service Manager -Cyber security | G41: B-605, gagan adira, Siraj Bokadia Road, Wagholi, Pune 412207 | H41: B-605, gagan adira, Siraj Bokadia Road, Wagholi, Pune 412207 | I41: 44466 | K41: Active | L41: Active
A42: 29 | B42: Hemanth Mishra | C42: 17/10/1976 | D42: MALE | E42: Satish Chandra Mishra | F42: Technology Analyst | G42: 16 B,Braj Nagar,Rameshwar Ward, opp. Anima Ubeja's Banglow, KHANDWA Pin-450001, Madhra Pradesh | H42: 16 B,Braj Nagar,Rameshwar Ward, opp. Anima Ubeja's Banglow, KHANDWA Pin-450001, Madhra Pradesh | I42: 44490 | K42: Active | L42: Active | N42: 10
A43: 30 | B43: FAZALAHMED IRKAL | C43: 32932 | D43: MALE | E43: CHANDSAHEB IRKAL | F43: SENIOR HADOOP ADMIN | G43: 558, 37/133 New Paccha Peth, Ashok Chowk, Behind Taj Medical Solapur | H43: 201, Sunaina Apartment, Near Poona College Camp Pune-411001 | I43: 44494 | K43: Active | L43: Active | N43: 11
A44: 31 | B44: SUKRUTH YELLAMBOTLA | C44: 34146 | D44: MALE | E44: Yellambotla Vijay Kumar | F44: SENIOR APPLICATION CONSULTANT | G44: H No 6-311/1/B/1,Sri krishna nagar,Qutubullapur,Suchitra,Hyderabad | H44: H No 6-311/1/B/1,Sri krishna nagar,Qutubullapur,Suchitra,Hyderabad | I44: 44509 | K44: Active | L44: Active | N44: 12
...

Sheet 04-221Master
A3: FORM - XIII REGISTER OF WORKMEN EMPLOYED BY CONTRACTOR
B4: (Vide Rule 75 of Contract Labour (Regulation and Abolition) Central/Karnataka Rules 1974)
A5: Name and address of Contractor: | F5: Burgeon IT Services Pvt.Ltd. | AB5: Name and address of Establishemnt in/ under which contract is carried on: | AP5: =F5 -> Burgeon IT Services Pvt.Ltd.
F6: Siri Mansion LIGB 436 Dr.A S Rao Nagar,Hyderabad | AP6: =F6 -> Siri Mansion LIGB 436 Dr.A S Rao Nagar,Hyderabad
AP7: =F7 -> 0
A8: Nature and location of work: | F8: IT SUPPORTIVE SERVICES& Pune SEZ Unit-1
A10: Wage period: Monthly | D10: 44652 | AK10: Name and address of Principal Employer: | AP10: INFOSYS LTD.IL Pune SEZ Unit-I,Plot No. 24/3
AP11: Rajiv gandhi Info tech park,Village Mann,Pune,Maharashtra 411057
B13: 1 | C13: 2 | D13: 3 | E13: 4 | F13: 5 | G13: 6 | H13: 7 | I13: 8 | J13: 9 | K13: 10 | L13: 11 | M13: 12 | N13: 13 | O13: 14 | P13: 15 | Q13: 16 | R13: 17 | S13: 18 | T13: 19 | U13: 20 | V13: 21 | W13: 22 | X13: 23 | Y13: 24 | Z13: 25 | AA13: 26 | AB13: 27 | AC13: 28 | AD13: 29 | AE13: 30 | AF13: 31 | AG13: 32 | AH13: 33 | AI13: 34 | AJ13: 35 | AK13: 36 | AL13: 37 | AM13: 38 | AN13: 39 | AO13: 40 | AP13: 41 | AQ13: 42 | AR13: 43 | AS13: 44 | AT13: 45
B14: Name of Workman | C14: Age | D14: Sex | E14: Father's /Husband Name | F14: Designation / Nature of Work Done | G14: Permanent Address | J14: Local Address | N14: Date of Commencement of Employment | O14: Signature or thumb impression of Workman | P14: Date of termination of Employment | Q14: Reasons for termination | R14: Remarks | S14: EPF Number | T14: ESI Number | U14: Name of Workman | V14: NO.OF DAYS | W14: No.of Days worked | X14: Unit of work done | Y14: Monthly rate of wages/ piece rate | Z14: Basic wages | AA14: Dearness Allowances | AB14: Over time | AC14: Other cash payments (Nature of payments to be indicated) | AD14: HRA | AE14: CONVEYANCE | AF14: MEDICAL ALLOWANCES | AG14: SPECIAL ALLOWNANCES | AH14: Total | AI14: BONUS | AJ14: GRATUITY | AK14: LTA/L.E | AL14: ARREAR AMOUNT | AM14: TOTAL AMOUNT | AN14: Deductions, if any, (Indicate nature) | AT14: Net Amount paid | AU14: Time and Date of Payment | AV14: Place of Payment | AW14: Signature/Thumb Impression of workman | AX14: Initial of Contractor or his representative | AY14: Serial No. in the Register of Workmen
AN15: ESI | AO15: PF | AP15: PT | AQ15: TDS | AR15: MED | AS15: Total Deductions
A16: BITS-461 | B16: Venegella Kanaka durga | C16: 31669 | D16: Female | E16: Venkateshwar Rao | F16: Senior Software Engineer | G16: Dr no-115,Sujatha nagar, vinjamur SPSR Nellore ,Andra Pradesh,pincode:560066 | J16: No.3,Malempati Homes,8th A cross, Manjunatha Layout, Munekollala, Maratahalli, Bangalore - 560037 | N16: 44021 | S16: 100748390738 | T16: N/A | U16: =B16 -> Venegella Kanaka durga | V16: 30 | W16: =VLOOKUP(A16,'[1]Pay sheet-APRIL- 2022'!$C$5:$AF$134,10,0) -> 30 | X16: N/A | Y16: 75643 | Z16: =VLOOKUP(A16,'[1]Pay sheet-APRIL- 2022'!$C$5:$AF$134,11,0) -> 45385.8 | AA16: 0 | AB16: 0 | AC16: =AD16+AE16+AF16+AG16 -> 30370.2 | AD16: =VLOOKUP(A16,'[1]Pay sheet-APRIL- 2022'!$C$5:$AF$134,12,0) -> 18154.32 | AE16: =VLOOKUP(A16,'[1]Pay sheet-APRIL- 2022'!$C$5:$AF$134,13,0) -> 2083 | AF16: =VLOOKUP(A16,'[1]Pay sheet-APRIL- 2022'!$C$5:$AF$134,14,0) -> 2083 | AG16: =VLOOKUP(A16,'[1]Pay sheet-APRIL- 2022'!$C$5:$AF$134,15,0) -> 8049.88 | AH16: =Z16+AC16 -> 75756 | AI16: =VLOOKUP(A16,'[1]Pay sheet-APRIL- 2022'!$C$5:$AF$134,18,0) -> 1554.609 | AJ16: =VLOOKUP(A16,'[1]Pay sheet-APRIL- 2022'!$C$5:$AF$134,19,0) -> 2183.057 | AK16: =VLOOKUP(A16,'[1]Pay sheet-APRIL- 2022'!$C$5:$AF$134,20,0) -> 3782.15 | AL16: =VLOOKUP(A16,'[1]Pay sheet-APRIL- 2022'!$C$5:$AF$134,22,0) -> 0 | AM16: =Z16+AD16+AE16+AF16+AG16+AI16+AJ16+AK16 -> 83275.816 | AO16: =VLOOKUP(A16,'[1]Pay sheet-APRIL- 2022'!$C$5:$AF$134,26,0) -> 1800 | AP16: =VLOOKUP(A16,'[1]Pay sheet-APRIL- 2022'!$C$5:$AF$134,25,0) -> 200 | AQ16: =VLOOKUP(A16,'[1]Pay sheet-APRIL- 2022'!$C$5:$AF$134,24,0) -> 0 | AR16: =VLOOKUP(A16,'[1]Pay sheet-APRIL- 2022'!$C$5:$AF$134,27,0) -> 391.78785 | AS16: =SUM(AO16:AR16) -> 2391.7878 | AT16: =AM16-AS16 -> 80884.028 | AU16: 05.05.2022 | AV16: KVBL | AW16: A/C'1498155000027380 | AY16: 6 | AZ16: 1
A17: BITS-469 | B17: Moeenahmed Shakilahmed Shaikh | C17: 30310 | D17: MALE | E17: Shaik Azara Shakilahmed | F17: Splunk Developer | G17: 967 Ravivarpet, Ghulamali,Chambers laxmi Road, Pune, MH 411002 | J17: 967 Ravivarpet, Ghulamali,Chambers laxmi Road, Pune, MH 411002 | N17: 44041 | S17: 101607851856 | T17: N/A | U17: =B17 -> Moeenahmed Shakilahmed Shaikh | V17: 30 | W17: =VLOOKUP(A17,'[1]Pay sheet-APRIL- 2022'!$C$5:$AF$134,10,0) -> 30 | X17: N/A | Y17: 149795 | Z17: =VLOOKUP(A17,'[1]Pay sheet-APRIL- 2022'!$C$5:$AF$134,11,0) -> 89877 | AA17: 0 | AB17: 0 | AC17: =AD17+AE17+AF17+AG17 -> 60031 | AD17: =VLOOKUP(A17,'[1]Pay sheet-APRIL- 2022'!$C$5:$AF$134,12,0) -> 35950.8 | AE17: =VLOOKUP(A17,'[1]Pay sheet-APRIL- 2022'!$C$5:$AF$134,13,0) -> 2083 | AF17: =VLOOKUP(A17,'[1]Pay sheet-APRIL- 2022'!$C$5:$AF$134,14,0) -> 2083 | AG17: =VLOOKUP(A17,'[1]Pay sheet-APRIL- 2022'!$C$5:$AF$134,15,0) -> 19914.2 | AH17: =Z17+AC17 -> 149908 | AI17: =VLOOKUP(A17,'[1]Pay sheet-APRIL- 2022'!$C$5:$AF$134,18,0) -> 1554.609 | AJ17: =VLOOKUP(A17,'[1]Pay sheet-APRIL- 2022'!$C$5:$AF$134,19,0) -> 4323.0837 | AK17: =VLOOKUP(A17,'[1]Pay sheet-APRIL- 2022'!$C$5:$AF$134,20,0) -> 7489.75 | AL17: =VLOOKUP(A17,'[1]Pay sheet-APRIL- 2022'!$C$5:$AF$134,22,0) -> 0 | AM17: =Z17+AD17+AE17+AF17+AG17+AI17+AJ17+AK17 -> 163275.44 | AO17: =VLOOKUP(A17,'[1]Pay sheet-APRIL- 2022'!$C$5:$AF$134,26,0) -> 6000 | AP17: =VLOOKUP(A17,'[1]Pay sheet-APRIL- 2022'!$C$5:$AF$134,25,0) -> 200 | AQ17: =VLOOKUP(A17,'[1]Pay sheet-APRIL- 2022'!$C$5:$AF$134,24,0) -> 0 | AR17: =VLOOKUP(A17,'[1]Pay sheet-APRIL- 2022'!$C$5:$AF$134,27,0) -> 440.76133 | AS17: =SUM(AO17:AR17) -> 6640.7613 | AT17: =AM17-AS17 -> 156634.68 | AU17: 05.05.2022 | AV17: KKBK | AW17: A/C'7311230416 | AY17: 10 | AZ17: 2
A18: BITS-572 | B18: Yarramaddu Raveendra Reddy | C18: 32972 | D18: Male | E18: Ramachandra Reddy | F18: Sr Citrix Administrator | G18: 11/25,Baddipally village,Mudivedu post,Kura Balakota mandal,Chittor district,AP 517350 | J18: 11/25,Baddipally village,Mudivedu post,Kura Balakota mandal,Chittor district,AP 517350 | N18: 44335 | S18: 101695261757 | T18: N/A | U18: Yarramaddu Raveendra Reddy | V18: 30 | W18: =VLOOKUP(A18,'[1]Pay sheet-APRIL- 2022'!$C$5:$AF$134,10,0) -> 30 | X18: N/A | Y18: 61740 | Z18: =VLOOKUP(A18,'[1]Pay sheet-APRIL- 2022'!$C$5:$AF$134,11,0) -> 37044 | AA18: 0 | AB18: 0 | AC18: =AD18+AE18+AF18+AG18 -> 24809 | AD18: =VLOOKUP(A18,'[1]Pay sheet-APRIL- 2022'!$C$5:$AF$134,12,0) -> 14817.6 | AE18: =VLOOKUP(A18,'[1]Pay sheet-APRIL- 2022'!$C$5:$AF$134,13,0) -> 2083 | AF18: =VLOOKUP(A18,'[1]Pay sheet-APRIL- 2022'!$C$5:$AF$134,14,0) -> 2083 | AG18: =VLOOKUP(A18,'[1]Pay sheet-APRIL- 2022'!$C$5:$AF$134,15,0) -> 5825.4 | AH18: =Z18+AC18 -> 61853 | AI18: =VLOOKUP(A18,'[1]Pay sheet-APRIL- 2022'!$C$5:$AF$134,18,0) -> 1554.609 | AJ18: =VLOOKUP(A18,'[1]Pay sheet-APRIL- 2022'!$C$5:$AF$134,19,0) -> 1781.8164 | AK18: =VLOOKUP(A18,'[1]Pay sheet-APRIL- 2022'!$C$5:$AF$134,20,0) -> 3087 | AL18: =VLOOKUP(A18,'[1]Pay sheet-APRIL- 2022'!$C$5:$AF$134,22,0) -> 0 | AM18: =Z18+AD18+AE18+AF18+AG18+AI18+AJ18+AK18 -> 68276.425 | AO18: =VLOOKUP(A18,'[1]Pay sheet-APRIL- 2022'!$C$5:$AF$134,26,0) -> 1800 | AP18: =VLOOKUP(A18,'[1]Pay sheet-APRIL- 2022'!$C$5:$AF$134,25,0) -> 200 | AQ18: =VLOOKUP(A18,'[1]Pay sheet-APRIL- 2022'!$C$5:$AF$134,24,0) -> 0 | AR18: =VLOOKUP(A18,'[1]Pay sheet-APRIL- 2022'!$C$5:$AF$134,27,0) -> 391.78785 | AS18: =SUM(AO18:AR18) -> 2391.7878 | AT18: =AM18-AS18 -> 65884.638 | AU18: 05.05.2022 | AV18: HDFC BANK | AW18: A/C'50100313077055 | AY18: 19 | AZ18: 3
A19: BITS-605 | B19: Chitra Kulkarni | C19: 32113 | D19: Female | E19: Nirbay Gopal | F19: Project Manager | G19: H No 479,Sy No 39,Road no.5, Mathenagar,Vadgaon sheri,Pune,Maharastra 411014 | J19: H No 479,Sy No 39,Road no.5, Mathenagar,Vadgaon sheri,Pune,Maharastra 411014 | N19: 44390 | S19: 100126170346 | T19: N/A | U19: Chitra Kulkarni | V19: 30 | W19: =VLOOKUP(A19,'[1]Pay sheet-APRIL- 2022'!$C$5:$AF$134,10,0) -> 30 | X19: N/A | Y19: 82132 | Z19: =VLOOKUP(A19,'[1]Pay sheet-APRIL- 2022'!$C$5:$AF$134,11,0) -> 49279.2 | AA19: 0 | AB19: 0 | AC19: =AD19+AE19+AF19+AG19 -> 32965.8 | AD19: =VLOOKUP(A19,'[1]Pay sheet-APRIL- 2022'!$C$5:$AF$134,12,0) -> 19711.68 | AE19: =VLOOKUP(A19,'[1]Pay sheet-APRIL- 2022'!$C$5:$AF$134,13,0) -> 2083 | AF19: =VLOOKUP(A19,'[1]Pay sheet-APRIL- 2022'!$C$5:$AF$134,14,0) -> 2083 | AG19: =VLOOKUP(A19,'[1]Pay sheet-APRIL- 2022'!$C$5:$AF$134,15,0) -> 9088.12 | AH19: =Z19+AC19 -> 82245 | AI19: =VLOOKUP(A19,'[1]Pay sheet-APRIL- 2022'!$C$5:$AF$134,18,0) -> 1554.609 | AJ19: =VLOOKUP(A19,'[1]Pay sheet-APRIL- 2022'!$C$5:$AF$134,19,0) -> 2370.3295 | AK19: =VLOOKUP(A19,'[1]Pay sheet-APRIL- 2022'!$C$5:$AF$134,20,0) -> 4106.6 | AL19: =VLOOKUP(A19,'[1]Pay sheet-APRIL- 2022'!$C$5:$AF$134,22,0) -> 0 | AM19: =Z19+AD19+AE19+AF19+AG19+AI19+AJ19+AK19 -> 90276.539 | AO19: =VLOOKUP(A19,'[1]Pay sheet-APRIL- 2022'!$C$5:$AF$134,26,0) -> 1800 | AP19: =VLOOKUP(A19,'[1]Pay sheet-APRIL- 2022'!$C$5:$AF$134,25,0) -> 200 | AQ19: =VLOOKUP(A19,'[1]Pay sheet-APRIL- 2022'!$C$5:$AF$134,24,0) -> 0 | AR19: =VLOOKUP(A19,'[1]Pay sheet-APRIL- 2022'!$C$5:$AF$134,27,0) -> 335 | AS19: =SUM(AO19:AR19) -> 2335 | AT19: =AM19-AS19 -> 87941.539 | AU19: 05.05.2022 | AV19: ICICI | AW19: A/C' 055801521228 | AY19: 20 | AZ19: 4
A20: BITS-617 | B20: Sunnapalli Anil | C20: 32813 | D20: Male | E20: Narsingam | F20: Sr. Software Engineer | G20: 16-9-239,Puppalagutta,Railway flyover bridge,Chital,Warangal,TS 506002 | J20: 16-9-239,Puppalagutta,Railway flyover bridge,Chital,Warangal,TS 506002 | N20: 44409 | S20: 100051658997 | T20: N/A | U20: Sunnapalli Anil | V20: 30 | W20: =VLOOKUP(A20,'[1]Pay sheet-APRIL- 2022'!$C$5:$AF$134,10,0) -> 30 | X20: N/A | Y20: 69580 | Z20: =VLOOKUP(A20,'[1]Pay sheet-APRIL- 2022'!$C$5:$AF$134,11,0) -> 41748 | AA20: 0 | AB20: 0 | AC20: =AD20+AE20+AF20+AG20 -> 27945 | AD20: =VLOOKUP(A20,'[1]Pay sheet-APRIL- 2022'!$C$5:$AF$134,12,0) -> 16699.2 | AE20: =VLOOKUP(A20,'[1]Pay sheet-APRIL- 2022'!$C$5:$AF$134,13,0) -> 2083 | AF20: =VLOOKUP(A20,'[1]Pay sheet-APRIL- 2022'!$C$5:$AF$134,14,0) -> 2083 | AG20: =VLOOKUP(A20,'[1]Pay sheet-APRIL- 2022'!$C$5:$AF$134,15,0) -> 7079.8 | AH20: =Z20+AC20 -> 69693 | AI20: =VLOOKUP(A20,'[1]Pay sheet-APRIL- 2022'!$C$5:$AF$134,18,0) -> 1554.609 | AJ20: =VLOOKUP(A20,'[1]Pay sheet-APRIL- 2022'!$C$5:$AF$134,19,0) -> 2008.0788 | AK20: =VLOOKUP(A20,'[1]Pay sheet-APRIL- 2022'!$C$5:$AF$134,20,0) -> 3479 | AL20: =VLOOKUP(A20,'[1]Pay sheet-APRIL- 2022'!$C$5:$AF$134,22,0) -> 0 | AM20: =Z20+AD20+AE20+AF20+AG20+AI20+AJ20+AK20 -> 76734.688 | AO20: =VLOOKUP(A20,'[1]Pay sheet-APRIL- 2022'!$C$5:$AF$134,26,0) -> 1800 | AP20: =VLOOKUP(A20,'[1]Pay sheet-APRIL- 2022'!$C$5:$AF$134,25,0) -> 200 | AQ20: =VLOOKUP(A20,'[1]Pay sheet-APRIL- 2022'!$C$5:$AF$134,24,0) -> 0 | AR20: =VLOOKUP(A20,'[1]Pay sheet-APRIL- 2022'!$C$5:$AF$134,27,0) -> 335 | AS20: =SUM(AO20:AR20) -> 2335 | AT20: =AM20-AS20 -> 74399.688 | AU20: 05.05.2022 | AV20: STATE BANK OF INDIA | AW20: 20222665512 | AY20: 22 | AZ20: 5
A21: BITS-632 | B21: Himanshu Anand | C21: 31328 | D21: Male | E21: A.K. Gupta | F21: Sr. DBA / Sr. Administrator | G21: 25-B Radha Nagar, Rohini complex, Mathura, UP 281004 | J21: J-901 City Apartments,aditya world city, Gaziabad, UP 201002 | N21: 44432 | S21: 100582540876 | T21: N/A | U21: Himanshu Anand | V21: 30 | W21: =VLOOKUP(A21,'[1]Pay sheet-APRIL- 2022'!$C$5:$AF$134,10,0) -> 30 | X21: N/A | Y21: 98501 | Z21: =VLOOKUP(A21,'[1]Pay sheet-APRIL- 2022'!$C$5:$AF$134,11,0) -> 59100.6 | AA21: 0 | AB21: 0 | AC21: =AD21+AE21+AF21+AG21 -> 39513.4 | AD21: =VLOOKUP(A21,'[1]Pay sheet-APRIL- 2022'!$C$5:$AF$134,12,0) -> 23640.24 | AE21: =VLOOKUP(A21,'[1]Pay sheet-APRIL- 2022'!$C$5:$AF$134,13,0) -> 2083 | AF21: =VLOOKUP(A21,'[1]Pay sheet-APRIL- 2022'!$C$5:$AF$134,14,0) -> 2083 | AG21: =VLOOKUP(A21,'[1]Pay sheet-APRIL- 2022'!$C$5:$AF$134,15,0) -> 11707.16 | AH21: =Z21+AC21 -> 98614 | AI21: =VLOOKUP(A21,'[1]Pay sheet-APRIL- 2022'!$C$5:$AF$134,18,0) -> 1554.609 | AJ21: =VLOOKUP(A21,'[1]Pay sheet-APRIL- 2022'!$C$5:$AF$134,19,0) -> 2842.7389 | AK21: =VLOOKUP(A21,'[1]Pay sheet-APRIL- 2022'!$C$5:$AF$134,20,0) -> 4925.05 | AL21: =VLOOKUP(A21,'[1]Pay sheet-APRIL- 2022'!$C$5:$AF$134,22,0) -> 0 | AM21: =Z21+AD21+AE21+AF21+AG21+AI21+AJ21+AK21 -> 107936.4 | AO21: =VLOOKUP(A21,'[1]Pay sheet-APRIL- 2022'!$C$5:$AF$134,26,0) -> 1800 | AP21: =VLOOKUP(A21,'[1]Pay sheet-APRIL- 2022'!$C$5:$AF$134,25,0) -> 200 | AQ21: =VLOOKUP(A21,'[1]Pay sheet-APRIL- 2022'!$C$5:$AF$134,24,0) -> 0 | AR21: =VLOOKUP(A21,'[1]Pay sheet-APRIL- 2022'!$C$5:$AF$134,27,0) -> 336 | AS21: =SUM(AO21:AR21) -> 2336 | AT21: =AM21-AS21 -> 105600.4 | AU21: 05.05.2022 | AV21: HDFC BANK | AW21: A/C 07281140023731 | AY21: 24 | AZ21: 6
A22: BITS-633 | B22: Kanchupati Kondaiah | C22: 32669 | D22: Male | E22: U MALLESWARAMMA | F22: SQL DATABASE ADMINISTRATOR | G22: CHENNAVARAM Village, Rachayapost, gopavaram mandal, YSR Kadapa, AP 516233 | J22: CHENNAVARAM Village, Rachayapost, gopavaram mandal, YSR Kadapa, AP 516233 | N22: 44434 | S22: 101439478209 | T22: N/A | U22: Kanchupati Kondaiah | V22: 30 | W22: =VLOOKUP(A22,'[1]Pay sheet-APRIL- 2022'!$C$5:$AF$134,10,0) -> 30 | X22: N/A | Y22: 46909 | Z22: =VLOOKUP(A22,'[1]Pay sheet-APRIL- 2022'!$C$5:$AF$134,11,0) -> 28145.4 | AA22: 0 | AB22: 0 | AC22: =AD22+AE22+AF22+AG22 -> 18876.6 | AD22: =VLOOKUP(A22,'[1]Pay sheet-APRIL- 2022'!$C$5:$AF$134,12,0) -> 11258.16 | AE22: =VLOOKUP(A22,'[1]Pay sheet-APRIL- 2022'!$C$5:$AF$134,13,0) -> 2083 | AF22: =VLOOKUP(A22,'[1]Pay sheet-APRIL- 2022'!$C$5:$AF$134,14,0) -> 2083 | AG22: =VLOOKUP(A22,'[1]Pay sheet-APRIL- 2022'!$C$5:$AF$134,15,0) -> 3452.44 | AH22: =Z22+AC22 -> 47022 | AI22: =VLOOKUP(A22,'[1]Pay sheet-APRIL- 2022'!$C$5:$AF$134,18,0) -> 1554.609 | AJ22: =VLOOKUP(A22,'[1]Pay sheet-APRIL- 2022'!$C$5:$AF$134,19,0) -> 1353.7937 | AK22: =VLOOKUP(A22,'[1]Pay sheet-APRIL- 2022'!$C$5:$AF$134,20,0) -> 2345.45 | AL22: =VLOOKUP(A22,'[1]Pay sheet-APRIL- 2022'!$C$5:$AF$134,22,0) -> 0 | AM22: =Z22+AD22+AE22+AF22+AG22+AI22+AJ22+AK22 -> 52275.853 | AO22: =VLOOKUP(A22,'[1]Pay sheet-APRIL- 2022'!$C$5:$AF$134,26,0) -> 1800 | AP22: =VLOOKUP(A22,'[1]Pay sheet-APRIL- 2022'!$C$5:$AF$134,25,0) -> 200 | AQ22: =VLOOKUP(A22,'[1]Pay sheet-APRIL- 2022'!$C$5:$AF$134,24,0) -> 0 | AR22: =VLOOKUP(A22,'[1]Pay sheet-APRIL- 2022'!$C$5:$AF$134,27,0) -> 336 | AS22: =SUM(AO22:AR22) -> 2336 | AT22: =AM22-AS22 -> 49939.853 | AU22: 05.05.2022 | AV22: UCO | AW22: A/c no 16280110106877 | AY22: 25 | AZ22: 7
A23: BITS-634 | B23: Santosh Patel | C23: 32336 | D23: Male | E23: Kishorilal Patel | F23: Senior Support Engineer | G23: RNA- Plaza, Bldg R-6, Flat 714,Shree Ganesh CHS,Somani Gram, Rammandr road, Goregaon (west), Mumbai 400104. | J23: RNA- Plaza, Bldg R-6, Flat 714,Shree Ganesh CHS,Somani Gram, Rammandr road, Goregaon (west), Mumbai 400104. | N23: 44438 | S23: 100893476080 | T23: N/A | U23: Santosh Patel | V23: 30 | W23: =VLOOKUP(A23,'[1]Pay sheet-APRIL- 2022'!$C$5:$AF$134,10,0) -> 30 | X23: N/A | Y23: 131257 | Z23: =VLOOKUP(A23,'[1]Pay sheet-APRIL- 2022'!$C$5:$AF$134,11,0) -> 78754.2 | AA23: 0 | AB23: 0 | AC23: =AD23+AE23+AF23+AG23 -> 52615.8 | AD23: =VLOOKUP(A23,'[1]Pay sheet-APRIL- 2022'!$C$5:$AF$134,12,0) -> 31501.68 | AE23: =VLOOKUP(A23,'[1]Pay sheet-APRIL- 2022'!$C$5:$AF$134,13,0) -> 2083 | AF23: =VLOOKUP(A23,'[1]Pay sheet-APRIL- 2022'!$C$5:$AF$134,14,0) -> 2083 | AG23: =VLOOKUP(A23,'[1]Pay sheet-APRIL- 2022'!$C$5:$AF$134,15,0) -> 16948.12 | AH23: =Z23+AC23 -> 131370 | AI23: =VLOOKUP(A23,'[1]Pay sheet-APRIL- 2022'!$C$5:$AF$134,18,0) -> 1554.609 | AJ23: =VLOOKUP(A23,'[1]Pay sheet-APRIL- 2022'!$C$5:$AF$134,19,0) -> 3788.077 | AK23: =VLOOKUP(A23,'[1]Pay sheet-APRIL- 2022'!$C$5:$AF$134,20,0) -> 6562.85 | AL23: =VLOOKUP(A23,'[1]Pay sheet-APRIL- 2022'!$C$5:$AF$134,22,0) -> 0 | AM23: =Z23+AD23+AE23+AF23+AG23+AI23+AJ23+AK23 -> 143275.54 | AO23: =VLOOKUP(A23,'[1]Pay sheet-APRIL- 2022'!$C$5:$AF$134,26,0) -> 1800 | AP23: =VLOOKUP(A23,'[1]Pay sheet-APRIL- 2022'!$C$5:$AF$134,25,0) -> 200 | AQ23: =VLOOKUP(A23,'[1]Pay sheet-APRIL- 2022'!$C$5:$AF$134,24,0) -> 0 | AR23: =VLOOKUP(A23,'[1]Pay sheet-APRIL- 2022'!$C$5:$AF$134,27,0) -> 336 | AS23: =SUM(AO23:AR23) -> 2336 | AT23: =AM23-AS23 -> 140939.54 | AU23: 05.05.2022 | AV23: Axis Bank | AW23: A/c No: 919010057225623 | AY23: 26 | AZ23: 8
A24: BITS-638 | B24: Basweshwar Pawar | C24: 31899 | D24: Male | E24: Nandakumar eknath pawar | F24: Lead PMO | G24: H-302, Kohinoor Abhimaan Homes, somatane-Kasarai Road,Near Sai Temple, Mawal, PUNE 410506 | I24: OOOO | J24: H-302, Kohinoor Abhimaan Homes, somatane-Kasarai Road,Near Sai Temple, Mawal, PUNE 410506 | K24: OOOO | L24: OOOO | M24: OOOO | N24: 44446 | O24: OOOO | P24: OOOO | Q24: OOOO | R24: OOOO | S24: 100233436495 | T24: N/A | U24: Basweshwar Pawar | V24: 30 | W24: =VLOOKUP(A24,'[1]Pay sheet-APRIL- 2022'!$C$5:$AF$134,10,0) -> 30 | X24: N/A | Y24: 89547 | Z24: =VLOOKUP(A24,'[1]Pay sheet-APRIL- 2022'!$C$5:$AF$134,11,0) -> 53728.2 | AA24: 0 | AB24: 0 | AC24: =AD24+AE24+AF24+AG24 -> 35931.8 | AD24: =VLOOKUP(A24,'[1]Pay sheet-APRIL- 2022'!$C$5:$AF$134,12,0) -> 21491.28 | AE24: =VLOOKUP(A24,'[1]Pay sheet-APRIL- 2022'!$C$5:$AF$134,13,0) -> 2083 | AF24: =VLOOKUP(A24,'[1]Pay sheet-APRIL- 2022'!$C$5:$AF$134,14,0) -> 2083 | AG24: =VLOOKUP(A24,'[1]Pay sheet-APRIL- 2022'!$C$5:$AF$134,15,0) -> 10274.52 | AH24: =Z24+AC24 -> 89660 | AI24: =VLOOKUP(A24,'[1]Pay sheet-APRIL- 2022'!$C$5:$AF$134,18,0) -> 1554.609 | AJ24: =VLOOKUP(A24,'[1]Pay sheet-APRIL- 2022'!$C$5:$AF$134,19,0) -> 2584.3264 | AK24: =VLOOKUP(A24,'[1]Pay sheet-APRIL- 2022'!$C$5:$AF$134,20,0) -> 4477.35 | AL24: =VLOOKUP(A24,'[1]Pay sheet-APRIL- 2022'!$C$5:$AF$134,22,0) -> 0 | AM24: =Z24+AD24+AE24+AF24+AG24+AI24+AJ24+AK24 -> 98276.285 | AO24: =VLOOKUP(A24,'[1]Pay sheet-APRIL- 2022'!$C$5:$AF$134,26,0) -> 1800 | AP24: =VLOOKUP(A24,'[1]Pay sheet-APRIL- 2022'!$C$5:$AF$134,25,0) -> 200 | AQ24: =VLOOKUP(A24,'[1]Pay sheet-APRIL- 2022'!$C$5:$AF$134,24,0) -> 0 | AR24: =VLOOKUP(A24,'[1]Pay sheet-APRIL- 2022'!$C$5:$AF$134,27,0) -> 224 | AS24: =SUM(AO24:AR24) -> 2224 | AT24: =AM24-AS24 -> 96052.285 | AU24: 05.05.2022 | AV24: ICICI BANK | AW24: 042401535769 | AY24: 27 | AZ24: 9
A25: BITS-661 | B25: Hemanth Mishra | C25: 17/10/1976 | D25: MALE | E25: Satish Chandra Mishra | F25: Technology Analyst | G25: 16 B,Braj Nagar,Rameshwar Ward, opp. Anima Ubeja's Banglow, KHANDWA Pin-450001, Madhra Pradesh | H25: OOOO | I25: OOOO | J25: 16 B,Braj Nagar,Rameshwar Ward, opp. Anima Ubeja's Banglow, KHANDWA Pin-450001, Madhra Pradesh | K25: OOOO | L25: OOOO | M25: OOOO | N25: 44490 | O25: OOOO | P25: OOOO | Q25: OOOO | R25: OOOO | S25: 100163951857 | T25: N/A | U25: Hemanth Mishra | V25: 30 | W25: =VLOOKUP(A25,'[1]Pay sheet-APRIL- 2022'!$C$5:$AF$134,10,0) -> 30 | X25: N/A | Y25: 98816 | Z25: =VLOOKUP(A25,'[1]Pay sheet-APRIL- 2022'!$C$5:$AF$134,11,0) -> 59289.6 | AA25: 0 | AB25: 0 | AC25: =AD25+AE25+AF25+AG25 -> 39639.4 | AD25: =VLOOKUP(A25,'[1]Pay sheet-APRIL- 2022'!$C$5:$AF$134,12,0) -> 23715.84 | AE25: =VLOOKUP(A25,'[1]Pay sheet-APRIL- 2022'!$C$5:$AF$134,13,0) -> 2083 | AF25: =VLOOKUP(A25,'[1]Pay sheet-APRIL- 2022'!$C$5:$AF$134,14,0) -> 2083 | AG25: =VLOOKUP(A25,'[1]Pay sheet-APRIL- 2022'!$C$5:$AF$134,15,0) -> 11757.56 | AH25: =Z25+AC25 -> 98929 | AI25: =VLOOKUP(A25,'[1]Pay sheet-APRIL- 2022'!$C$5:$AF$134,18,0) -> 1554.609 | AJ25: =VLOOKUP(A25,'[1]Pay sheet-APRIL- 2022'!$C$5:$AF$134,19,0) -> 2851.8298 | AK25: =VLOOKUP(A25,'[1]Pay sheet-APRIL- 2022'!$C$5:$AF$134,20,0) -> 4940.8 | AL25: =VLOOKUP(A25,'[1]Pay sheet-APRIL- 2022'!$C$5:$AF$134,22,0) -> 0 | AM25: =Z25+AD25+AE25+AF25+AG25+AI25+AJ25+AK25 -> 108276.24 | AO25: =VLOOKUP(A25,'[1]Pay sheet-APRIL- 2022'!$C$5:$AF$134,26,0) -> 1800 | AP25: =VLOOKUP(A25,'[1]Pay sheet-APRIL- 2022'!$C$5:$AF$134,25,0) -> 200 | AQ25: =VLOOKUP(A25,'[1]Pay sheet-APRIL- 2022'!$C$5:$AF$134,24,0) -> 0 | AR25: =VLOOKUP(A25,'[1]Pay sheet-APRIL- 2022'!$C$5:$AF$134,27,0) -> 254 | AS25: =SUM(AO25:AR25) -> 2254 | AT25: =AM25-AS25 -> 106022.24 | AU25: 05.05.2022 | AV25: ICICI BANK | AW25: 057001509856 | AY25: 29 | AZ25: 10
A26: BITS-663 | B26: FAZALAHMED IRKAL | C26: 32932 | D26: MALE | E26: CHANDSAHEB IRKAL | F26: SENIOR HADOOP ADMIN | G26: 558, 37/133 New Paccha Peth, Ashok Chowk, Behind Taj Medical Solapur | H26: OOOO | I26: OOOO | J26: 201, Sunaina Apartment, Near Poona College Camp Pune-411001 | K26: OOOO | L26: OOOO | M26: OOOO | N26: 44494 | O26: OOOO | P26: OOOO | Q26: OOOO | R26: OOOO | S26: 101148301276 | T26: N/A | U26: CHANDSAHEB IRKA FAZALA | V26: 30 | W26: =VLOOKUP(A26,'[1]Pay sheet-APRIL- 2022'!$C$5:$AF$134,10,0) -> 22 | X26: N/A | Y26: 59886 | Z26: =VLOOKUP(A26,'[1]Pay sheet-APRIL- 2022'!$C$5:$AF$134,11,0) -> 26349.84 | AA26: 0 | AB26: 0 | AC26: =AD26+AE26+AF26+AG26 -> 17679.56 | AD26: =VLOOKUP(A26,'[1]Pay sheet-APRIL- 2022'!$C$5:$AF$134,12,0) -> 10539.936 | AE26: =VLOOKUP(A26,'[1]Pay sheet-APRIL- 2022'!$C$5:$AF$134,13,0) -> 1528 | AF26: =VLOOKUP(A26,'[1]Pay sheet-APRIL- 2022'!$C$5:$AF$134,14,0) -> 1528 | AG26: =VLOOKUP(A26,'[1]Pay sheet-APRIL- 2022'!$C$5:$AF$134,15,0) -> 4083.624 | AH26: =Z26+AC26 -> 44029.4 | AI26: =VLOOKUP(A26,'[1]Pay sheet-APRIL- 2022'!$C$5:$AF$134,18,0) -> 1554.609 | AJ26: =VLOOKUP(A26,'[1]Pay sheet-APRIL- 2022'!$C$5:$AF$134,19,0) -> 1267.4273 | AK26: =VLOOKUP(A26,'[1]Pay sheet-APRIL- 2022'!$C$5:$AF$134,20,0) -> 2195.82 | AL26: =VLOOKUP(A26,'[1]Pay sheet-APRIL- 2022'!$C$5:$AF$134,22,0) -> 0 | AM26: =Z26+AD26+AE26+AF26+AG26+AI26+AJ26+AK26 -> 49047.256 | AO26: =VLOOKUP(A26,'[1]Pay sheet-APRIL- 2022'!$C$5:$AF$134,26,0) -> 1800 | AP26: =VLOOKUP(A26,'[1]Pay sheet-APRIL- 2022'!$C$5:$AF$134,25,0) -> 200 | AQ26: =VLOOKUP(A26,'[1]Pay sheet-APRIL- 2022'!$C$5:$AF$134,24,0) -> 0 | AR26: =VLOOKUP(A26,'[1]Pay sheet-APRIL- 2022'!$C$5:$AF$134,27,0) -> 254 | AS26: =SUM(AO26:AR26) -> 2254 | AT26: =AM26-AS26 -> 46793.256 | AU26: 05.05.2022 | AV26: SBI | AW26: 32722181716 | AY26: 30 | AZ26: 11
A27: BITS-667 | B27: SUKRUTH YELLAMBOTLA | C27: 34146 | D27: MALE | E27: Yellambotla Vijay Kumar | F27: SENIOR APPLICATION CONSULTANT | G27: H No 6-311/1/B/1,Sri krishna nagar,Qutubullapur,Suchitra,Hyderabad | I27: OOOO | J27: H No 6-311/1/B/1,Sri krishna nagar,Qutubullapur,Suchitra,Hyderabad | K27: OOOO | L27: OOOO | M27: OOOO | N27: 44509 | O27: OOOO | P27: OOOO | Q27: OOOO | R27: OOOO | S27: 100627572976 | T27: N/A | U27: SUKRUTH YELLAMBOTLA | V27: 30 | W27: =VLOOKUP(A27,'[1]Pay sheet-APRIL- 2022'!$C$5:$AF$134,10,0) -> 30 | X27: N/A | Y27: 35786 | Z27: =VLOOKUP(A27,'[1]Pay sheet-APRIL- 2022'!$C$5:$AF$134,11,0) -> 21471.6 | AA27: 0 | AB27: 0 | AC27: =AD27+AE27+AF27+AG27 -> 14427.4 | AD27: =VLOOKUP(A27,'[1]Pay sheet-APRIL- 2022'!$C$5:$AF$134,12,0) -> 8588.64 | AE27: =VLOOKUP(A27,'[1]Pay sheet-APRIL- 2022'!$C$5:$AF$134,13,0) -> 2083 | AF27: =VLOOKUP(A27,'[1]Pay sheet-APRIL- 2022'!$C$5:$AF$134,14,0) -> 2083 | AG27: =VLOOKUP(A27,'[1]Pay sheet-APRIL- 2022'!$C$5:$AF$134,15,0) -> 1672.76 | AH27: =Z27+AC27 -> 35899 | AI27: =VLOOKUP(A27,'[1]Pay sheet-APRIL- 2022'!$C$5:$AF$134,18,0) -> 1554.609 | AJ27: =VLOOKUP(A27,'[1]Pay sheet-APRIL- 2022'!$C$5:$AF$134,19,0) -> 1032.784 | AK27: =VLOOKUP(A27,'[1]Pay sheet-APRIL- 2022'!$C$5:$AF$134,20,0) -> 1789.3 | AL27: =VLOOKUP(A27,'[1]Pay sheet-APRIL- 2022'!$C$5:$AF$134,22,0) -> 0 | AM27: =Z27+AD27+AE27+AF27+AG27+AI27+AJ27+AK27 -> 40275.693 | AO27: =VLOOKUP(A27,'[1]Pay sheet-APRIL- 2022'!$C$5:$AF$134,26,0) -> 1800 | AP27: =VLOOKUP(A27,'[1]Pay sheet-APRIL- 2022'!$C$5:$AF$134,25,0) -> 200 | AQ27: =VLOOKUP(A27,'[1]Pay sheet-APRIL- 2022'!$C$5:$AF$134,24,0) -> 0 | AR27: =VLOOKUP(A27,'[1]Pay sheet-APRIL- 2022'!$C$5:$AF$134,27,0) -> 252 | AS27: =SUM(AO27:AR27) -> 2252 | AT27: =AM27-AS27 -> 38023.693 | AU27: 05.05.2022 | AV27: HDFC0000486 | AW27: 50100468093660 | AY27: 31 | AZ27: 12
A28: BITS-682 | B28: Ajay Singh | C28: 33635 | D28: MALE | E28: Santhosh Singh | F28: Sr.Cloud Network Engineer | G28: EM-36,Indus Town,Phase II,Ratanpur,Missrod,Bhopal,Madhya pradesh 462047 | I28: OOOO | J28: EM-36,Indus Town,Phase II,Ratanpur,Missrod,Bhopal,Madhya pradesh 462047 | K28: OOOO | L28: OOOO | M28: OOOO | N28: 44538 | O28: OOOO | P28: OOOO | Q28: OOOO | R28: OOOO | S28: 101265633203 | T28: N/A | U28: Ajay Singh | V28: 30 | W28: =VLOOKUP(A28,'[1]Pay sheet-APRIL- 2022'!$C$5:$AF$134,10,0) -> 30 | X28: N/A | Y28: 128477 | Z28: =VLOOKUP(A28,'[1]Pay sheet-APRIL- 2022'!$C$5:$AF$134,11,0) -> 77086.2 | AA28: 0 | AB28: 0 | AC28: =AD28+AE28+AF28+AG28 -> 51503.8 | AD28: =VLOOKUP(A28,'[1]Pay sheet-APRIL- 2022'!$C$5:$AF$134,12,0) -> 30834.48 | AE28: =VLOOKUP(A28,'[1]Pay sheet-APRIL- 2022'!$C$5:$AF$134,13,0) -> 2083 | AF28: =VLOOKUP(A28,'[1]Pay sheet-APRIL- 2022'!$C$5:$AF$134,14,0) -> 2083 | AG28: =VLOOKUP(A28,'[1]Pay sheet-APRIL- 2022'!$C$5:$AF$134,15,0) -> 16503.32 | AH28: =Z28+AC28 -> 128590 | AI28: =VLOOKUP(A28,'[1]Pay sheet-APRIL- 2022'!$C$5:$AF$134,18,0) -> 1554.609 | AJ28: =VLOOKUP(A28,'[1]Pay sheet-APRIL- 2022'!$C$5:$AF$134,19,0) -> 3707.8462 | AK28: =VLOOKUP(A28,'[1]Pay sheet-APRIL- 2022'!$C$5:$AF$134,20,0) -> 6423.85 | AL28: =VLOOKUP(A28,'[1]Pay sheet-APRIL- 2022'!$C$5:$AF$134,22,0) -> 0 | AM28: =Z28+AD28+AE28+AF28+AG28+AI28+AJ28+AK28 -> 140276.31 | AO28: =VLOOKUP(A28,'[1]Pay sheet-APRIL- 2022'!$C$5:$AF$134,26,0) -> 1800 | AP28: =VLOOKUP(A28,'[1]Pay sheet-APRIL- 2022'!$C$5:$AF$134,25,0) -> 200 | AQ28: =VLOOKUP(A28,'[1]Pay sheet-APRIL- 2022'!$C$5:$AF$134,24,0) -> 0 | AR28: =VLOOKUP(A28,'[1]Pay sheet-APRIL- 2022'!$C$5:$AF$134,27,0) -> 283 | AS28: =SUM(AO28:AR28) -> 2283 | AT28: =AM28-AS28 -> 137993.31 | AU28: 05.05.2022 | AV28: Axis Bank | AW28: 916010061379733 | AY28: 32 | AZ28: 13
A29: BITS-697 | B29: Rajesh Dhumal | C29: 15-03-1990 | D29: MALE | E29: Ramakrishna | F29: Senior network security analyst. | G29: Deshpande Galli, Kholeshwar Collage Samor, Ambejogai, Bid, Maharashtra 431517 | H29: OOOO | I29: OOOO | J29: Deshpande Galli, Kholeshwar Collage Samor, Ambejogai, Bid, Maharashtra 431517 | K29: OOOO | L29: OOOO | M29: OOOO | N29: 44579 | O29: OOOO | P29: OOOO | Q29: OOOO | R29: OOOO | S29: 100637149311 | T29: N/A | U29: Rajesh Dhumal | V29: 30 | W29: =VLOOKUP(A29,'[1]Pay sheet-APRIL- 2022'!$C$5:$AF$134,10,0) -> 30 | X29: N/A | Y29: 74716 | Z29: =VLOOKUP(A29,'[1]Pay sheet-APRIL- 2022'!$C$5:$AF$134,11,0) -> 44829.6 | AA29: 0 | AB29: 0 | AC29: =AD29+AE29+AF29+AG29 -> 29999.4 | AD29: =VLOOKUP(A29,'[1]Pay sheet-APRIL- 2022'!$C$5:$AF$134,12,0) -> 17931.84 | AE29: =VLOOKUP(A29,'[1]Pay sheet-APRIL- 2022'!$C$5:$AF$134,13,0) -> 2083 | AF29: =VLOOKUP(A29,'[1]Pay sheet-APRIL- 2022'!$C$5:$AF$134,14,0) -> 2083 | AG29: =VLOOKUP(A29,'[1]Pay sheet-APRIL- 2022'!$C$5:$AF$134,15,0) -> 7901.56 | AH29: =Z29+AC29 -> 74829 | AI29: =VLOOKUP(A29,'[1]Pay sheet-APRIL- 2022'!$C$5:$AF$134,18,0) -> 1554.609 | AJ29: =VLOOKUP(A29,'[1]Pay sheet-APRIL- 2022'!$C$5:$AF$134,19,0) -> 2156.3038 | AK29: =VLOOKUP(A29,'[1]Pay sheet-APRIL- 2022'!$C$5:$AF$134,20,0) -> 3735.8 | AL29: =VLOOKUP(A29,'[1]Pay sheet-APRIL- 2022'!$C$5:$AF$134,22,0) -> 0 | AM29: =Z29+AD29+AE29+AF29+AG29+AI29+AJ29+AK29 -> 82275.713 | AO29: =VLOOKUP(A29,'[1]Pay sheet-APRIL- 2022'!$C$5:$AF$134,26,0) -> 1800 | AP29: =VLOOKUP(A29,'[1]Pay sheet-APRIL- 2022'!$C$5:$AF$134,25,0) -> 200 | AQ29: =VLOOKUP(A29,'[1]Pay sheet-APRIL- 2022'!$C$5:$AF$134,24,0) -> 0 | AR29: =VLOOKUP(A29,'[1]Pay sheet-APRIL- 2022'!$C$5:$AF$134,27,0) -> 283 | AS29: =SUM(AO29:AR29) -> 2283 | AT29: =AM29-AS29 -> 79992.713 | AU29: 05.05.2022 | AV29: AXIS BANK | AW29: 921010021808628 | AY29: 33 | AZ29: 14
A30: BITS-704 | B30: Ajay Pal Singh | C30: 31491 | D30: MALE | E30: kunwar rohitash singh | F30: Network security consultant | G30: H No 32,Jalalpur-Raghunadhpur,Murad nagar,Gaziyabad,UP 201206 | H30: OOOO | I30: OOOO | J30: H No 66,New Gandhi layout,Jaffar nagar,Nagpur,Maharastra 440013 | K30: OOOO | L30: OOOO | M30: OOOO | N30: 44601 | O30: OOOO | P30: OOOO | Q30: OOOO | R30: OOOO | S30: 100897320115 | T30: N/A | U30: Ajay Pal Singh | V30: 30 | W30: =VLOOKUP(A30,'[1]Pay sheet-APRIL- 2022'!$C$5:$AF$134,10,0) -> 30 | X30: N/A | Y30: 71009 | Z30: =VLOOKUP(A30,'[1]Pay sheet-APRIL- 2022'!$C$5:$AF$134,11,0) -> 42605.4 | AA30: 0 | AB30: 0 | AC30: =AD30+AE30+AF30+AG30 -> 28516.6 | AD30: =VLOOKUP(A30,'[1]Pay sheet-APRIL- 2022'!$C$5:$AF$134,12,0) -> 17042.16 | AE30: =VLOOKUP(A30,'[1]Pay sheet-APRIL- 2022'!$C$5:$AF$134,13,0) -> 2083 | AF30: =VLOOKUP(A30,'[1]Pay sheet-APRIL- 2022'!$C$5:$AF$134,14,0) -> 2083 | AG30: =VLOOKUP(A30,'[1]Pay sheet-APRIL- 2022'!$C$5:$AF$134,15,0) -> 7308.44 | AH30: =Z30+AC30 -> 71122 | AI30: =VLOOKUP(A30,'[1]Pay sheet-APRIL- 2022'!$C$5:$AF$134,18,0) -> 1554.609 | AJ30: =VLOOKUP(A30,'[1]Pay sheet-APRIL- 2022'!$C$5:$AF$134,19,0) -> 2049.3197 | AK30: =VLOOKUP(A30,'[1]Pay sheet-APRIL- 2022'!$C$5:$AF$134,20,0) -> 3550.45 | AL30: =VLOOKUP(A30,'[1]Pay sheet-APRIL- 2022'!$C$5:$AF$134,22,0) -> 0 | AM30: =Z30+AD30+AE30+AF30+AG30+AI30+AJ30+AK30 -> 78276.379 | AO30: =VLOOKUP(A30,'[1]Pay sheet-APRIL- 2022'!$C$5:$AF$134,26,0) -> 1800 | AP30: =VLOOKUP(A30,'[1]Pay sheet-APRIL- 2022'!$C$5:$AF$134,25,0) -> 200 | AQ30: =VLOOKUP(A30,'[1]Pay sheet-APRIL- 2022'!$C$5:$AF$134,24,0) -> 0 | AR30: =VLOOKUP(A30,'[1]Pay sheet-APRIL- 2022'!$C$5:$AF$134,27,0) -> 283 | AS30: =SUM(AO30:AR30) -> 2283 | AT30: =AM30-AS30 -> 75993.379 | AU30: 05.05.2022 | AV30: DBS Bank | AW30: 881015838995 | AY30: 34 | AZ30: 15
A31: BITS-716 | B31: PAVANKUMAR | C31: 35211 | D31: MALE | E31: P YELLAIAH | F31: SAP Basis consultant | G31: 7-8/1, palmakole(V), shamshabad(M), RR Dist,509325 | H31: OOOO | I31: OOOO | J31: 7-8/1, palmakole(V), shamshabad(M), RR Dist,509325 | K31: OOOO | L31: OOOO | M31: OOOO | N31: 44602 | O31: OOOO | P31: OOOO | Q31: OOOO | R31: OOOO | S31: 101593987074 | T31: N/A | U31: PAVANKUMAR | V31: 30 | W31: =VLOOKUP(A31,'[1]Pay sheet-APRIL- 2022'!$C$5:$AF$134,10,0) -> 30 | X31: N/A | Y31: 38567 | Z31: =VLOOKUP(A31,'[1]Pay sheet-APRIL- 2022'!$C$5:$AF$134,11,0) -> 23140.2 | AA31: 0 | AB31: 0 | AC31: =AD31+AE31+AF31+AG31 -> 15539.8 | AD31: =VLOOKUP(A31,'[1]Pay sheet-APRIL- 2022'!$C$5:$AF$134,12,0) -> 9256.08 | AE31: =VLOOKUP(A31,'[1]Pay sheet-APRIL- 2022'!$C$5:$AF$134,13,0) -> 2083 | AF31: =VLOOKUP(A31,'[1]Pay sheet-APRIL- 2022'!$C$5:$AF$134,14,0) -> 2083 | AG31: =VLOOKUP(A31,'[1]Pay sheet-APRIL- 2022'!$C$5:$AF$134,15,0) -> 2117.72 | AH31: =Z31+AC31 -> 38680 | AI31: =VLOOKUP(A31,'[1]Pay sheet-APRIL- 2022'!$C$5:$AF$134,18,0) -> 1554.609 | AJ31: =VLOOKUP(A31,'[1]Pay sheet-APRIL- 2022'!$C$5:$AF$134,19,0) -> 1113.0436 | AK31: =VLOOKUP(A31,'[1]Pay sheet-APRIL- 2022'!$C$5:$AF$134,20,0) -> 1928.35 | AL31: =VLOOKUP(A31,'[1]Pay sheet-APRIL- 2022'!$C$5:$AF$134,22,0) -> 0 | AM31: =Z31+AD31+AE31+AF31+AG31+AI31+AJ31+AK31 -> 43276.003 | AO31: =VLOOKUP(A31,'[1]Pay sheet-APRIL- 2022'!$C$5:$AF$134,26,0) -> 1800 | AP31: =VLOOKUP(A31,'[1]Pay sheet-APRIL- 2022'!$C$5:$AF$134,25,0) -> 200 | AQ31: =VLOOKUP(A31,'[1]Pay sheet-APRIL- 2022'!$C$5:$AF$134,24,0) -> 0 | AR31: =VLOOKUP(A31,'[1]Pay sheet-APRIL- 2022'!$C$5:$AF$134,27,0) -> 283 | AS31: =SUM(AO31:AR31) -> 2283 | AT31: =AM31-AS31 -> 40993.003 | AU31: 05.05.2022 | AV31: STATE BANK OF INDIA | AW31: 62318158569 | AY31: 35 | AZ31: 16
A32: BITS-729 | B32: Rahul Suryawanshi | C32: 35236 | D32: MALE | E32: Tarun Suryawanshi | F32: Sr.Network security Analyst | G32: H No 53,Near Durga mandir,at po sarra,gram sarra,tahsil multai dist bethul,Madhya pradesh 460661 | H32: H No 53,Near Durga mandir,at po sarra,gram sarra,tahsil multai dist bethul,Madhya pradesh 460661 | I32: OOOO | J32: OOOO | K32: OOOO | L32: OOOO | M32: OOOO | N32: 44624 | O32: OOOO | P32: OOOO | Q32: OOOO | R32: OOOO | S32: 101274942480 | T32: N/A | U32: Rahul Suryawanshi | V32: 30 | W32: =VLOOKUP(A32,'[1]Pay sheet-APRIL- 2022'!$C$5:$AF$134,10,0) -> 30 | X32: N/A | Y32: 80278 | Z32: =VLOOKUP(A32,'[1]Pay sheet-APRIL- 2022'!$C$5:$AF$134,11,0) -> 48166.8 | AA32: 0 | AB32: 0 | AC32: =AD32+AE32+AF32+AG32 -> 32224.2 | AD32: =VLOOKUP(A32,'[1]Pay sheet-APRIL- 2022'!$C$5:$AF$134,12,0) -> 19266.72 | AE32: =VLOOKUP(A32,'[1]Pay sheet-APRIL- 2022'!$C$5:$AF$134,13,0) -> 2083 | AF32: =VLOOKUP(A32,'[1]Pay sheet-APRIL- 2022'!$C$5:$AF$134,14,0) -> 2083 | AG32: =VLOOKUP(A32,'[1]Pay sheet-APRIL- 2022'!$C$5:$AF$134,15,0) -> 8791.48 | AH32: =Z32+AC32 -> 80391 | AI32: =VLOOKUP(A32,'[1]Pay sheet-APRIL- 2022'!$C$5:$AF$134,18,0) -> 1554.609 | AJ32: =VLOOKUP(A32,'[1]Pay sheet-APRIL- 2022'!$C$5:$AF$134,19,0) -> 2316.8231 | AK32: =VLOOKUP(A32,'[1]Pay sheet-APRIL- 2022'!$C$5:$AF$134,20,0) -> 4013.9 | AL32: =VLOOKUP(A32,'[1]Pay sheet-APRIL- 2022'!$C$5:$AF$134,22,0) -> 0 | AM32: =Z32+AD32+AE32+AF32+AG32+AI32+AJ32+AK32 -> 88276.332 | AO32: =VLOOKUP(A32,'[1]Pay sheet-APRIL- 2022'!$C$5:$AF$134,26,0) -> 1800 | AP32: =VLOOKUP(A32,'[1]Pay sheet-APRIL- 2022'!$C$5:$AF$134,25,0) -> 200 | AQ32: =VLOOKUP(A32,'[1]Pay sheet-APRIL- 2022'!$C$5:$AF$134,24,0) -> 0 | AR32: =VLOOKUP(A32,'[1]Pay sheet-APRIL- 2022'!$C$5:$AF$134,27,0) -> 283 | AS32: =SUM(AO32:AR32) -> 2283 | AT32: =AM32-AS32 -> 85993.332 | AU32: 05.05.2022 | AV32: standard chartered | AW32: 27011616110 | AY32: 36 | AZ32: 17
A33: BITS-730 | B33: Shantanu Patankar | C33: 32959 | D33: MALE | E33: shivajirao balasaheb | F33: Network security consultant | G33: Patankar house,kuntharwada,at post patan,taluq patan,dist satare,maharastra 415206 | H33: 204,Gaurav roy appts,tirangachowk,bharati vidyapitt,katray,pune,Maharastra 411046 | I33: OOOO | J33: OOOO | K33: OOOO | L33: OOOO | M33: OOOO | N33: 44629 | O33: OOOO | P33: OOOO | Q33: OOOO | R33: OOOO | S33: 100894664218 | T33: N/A | U33: Shantanu Patankar | V33: 30 | W33: =VLOOKUP(A33,'[1]Pay sheet-APRIL- 2022'!$C$5:$AF$134,10,0) -> 30 | X33: N/A | Y33: 112719 | Z33: =VLOOKUP(A33,'[1]Pay sheet-APRIL- 2022'!$C$5:$AF$134,11,0) -> 67631.4 | AA33: 0 | AB33: 0 | AC33: =AD33+AE33+AF33+AG33 -> 45200.6 | AD33: =VLOOKUP(A33,'[1]Pay sheet-APRIL- 2022'!$C$5:$AF$134,12,0) -> 27052.56 | AE33: =VLOOKUP(A33,'[1]Pay sheet-APRIL- 2022'!$C$5:$AF$134,13,0) -> 2083 | AF33: =VLOOKUP(A33,'[1]Pay sheet-APRIL- 2022'!$C$5:$AF$134,14,0) -> 2083 | AG33: =VLOOKUP(A33,'[1]Pay sheet-APRIL- 2022'!$C$5:$AF$134,15,0) -> 13982.04 | AH33: =Z33+AC33 -> 112832 | AI33: =VLOOKUP(A33,'[1]Pay sheet-APRIL- 2022'!$C$5:$AF$134,18,0) -> 1554.609 | AJ33: =VLOOKUP(A33,'[1]Pay sheet-APRIL- 2022'!$C$5:$AF$134,19,0) -> 3253.0703 | AK33: =VLOOKUP(A33,'[1]Pay sheet-APRIL- 2022'!$C$5:$AF$134,20,0) -> 5635.95 | AL33: =VLOOKUP(A33,'[1]Pay sheet-APRIL- 2022'!$C$5:$AF$134,22,0) -> 0 | AM33: =Z33+AD33+AE33+AF33+AG33+AI33+AJ33+AK33 -> 123275.63 | AO33: =VLOOKUP(A33,'[1]Pay sheet-APRIL- 2022'!$C$5:$AF$134,26,0) -> 1800 | AP33: =VLOOKUP(A33,'[1]Pay sheet-APRIL- 2022'!$C$5:$AF$134,25,0) -> 200 | AQ33: =VLOOKUP(A33,'[1]Pay sheet-APRIL- 2022'!$C$5:$AF$134,24,0) -> 0 | AR33: =VLOOKUP(A33,'[1]Pay sheet-APRIL- 2022'!$C$5:$AF$134,27,0) -> 283 | AS33: =SUM(AO33:AR33) -> 2283 | AT33: =AM33-AS33 -> 120992.63 | AU33: 05.05.2022 | AV33: ICICI bank | AW33: 239001508763 | AY33: 37 | AZ33: 18
A34: BITS-736 | B34: Varalakshmi Vijay | C34: 29711 | D34: Female | E34: Vijay srinivasan | F34: Network security consultant | G34: 902,Link view appts,sethia complex-2, opp MG road,Motilal nagar,Road no.3,Goregaon west,Mumbai,Maharastra 400104 | H34: 902,Link view appts,sethia complex-2, opp MG road,Motilal nagar,Road no.3,Goregaon west,Mumbai,Maharastra 400104 | I34: OOOO | J34: OOOO | K34: OOOO | L34: OOOO | M34: OOOO | N34: 44641 | O34: OOOO | P34: OOOO | Q34: OOOO | R34: OOOO | S34: 101804644758 | T34: N/A | U34: Varalakshmi Vijay | V34: 30 | W34: =VLOOKUP(A34,'[1]Pay sheet-APRIL- 2022'!$C$5:$AF$134,10,0) -> 30 | X34: N/A | Y34: 66374 | Z34: =VLOOKUP(A34,'[1]Pay sheet-APRIL- 2022'!$C$5:$AF$134,11,0) -> 39824.4 | AA34: 0 | AB34: 0 | AC34: =AD34+AE34+AF34+AG34 -> 26662.6 | AD34: =VLOOKUP(A34,'[1]Pay sheet-APRIL- 2022'!$C$5:$AF$134,12,0) -> 15929.76 | AE34: =VLOOKUP(A34,'[1]Pay sheet-APRIL- 2022'!$C$5:$AF$134,13,0) -> 2083 | AF34: =VLOOKUP(A34,'[1]Pay sheet-APRIL- 2022'!$C$5:$AF$134,14,0) -> 2083 | AG34: =VLOOKUP(A34,'[1]Pay sheet-APRIL- 2022'!$C$5:$AF$134,15,0) -> 6566.84 | AH34: =Z34+AC34 -> 66487 | AI34: =VLOOKUP(A34,'[1]Pay sheet-APRIL- 2022'!$C$5:$AF$134,18,0) -> 1554.609 | AJ34: =VLOOKUP(A34,'[1]Pay sheet-APRIL- 2022'!$C$5:$AF$134,19,0) -> 1915.5536 | AK34: =VLOOKUP(A34,'[1]Pay sheet-APRIL- 2022'!$C$5:$AF$134,20,0) -> 3318.7 | AL34: =VLOOKUP(A34,'[1]Pay sheet-APRIL- 2022'!$C$5:$AF$134,22,0) -> 0 | AM34: =Z34+AD34+AE34+AF34+AG34+AI34+AJ34+AK34 -> 73275.863 | AO34: =VLOOKUP(A34,'[1]Pay sheet-APRIL- 2022'!$C$5:$AF$134,26,0) -> 1800 | AP34: =VLOOKUP(A34,'[1]Pay sheet-APRIL- 2022'!$C$5:$AF$134,25,0) -> 200 | AQ34: =VLOOKUP(A34,'[1]Pay sheet-APRIL- 2022'!$C$5:$AF$134,24,0) -> 0 | AR34: =VLOOKUP(A34,'[1]Pay sheet-APRIL- 2022'!$C$5:$AF$134,27,0) -> 283 | AS34: =SUM(AO34:AR34) -> 2283 | AT34: =AM34-AS34 -> 70992.863 | AU34: 05.05.2022 | AV34: ICICI bank | AW34: 055501503361 | AY34: 38 | AZ34: 19
A35: BITS-744 | B35: OMPRAKASH PURI | C35: 31427 | D35: Male | E35: Shankarnath Singh | F35: CONSULTANT | G35: LIG-162,2nd floor,7th phase,KPHB,Near basket ball ground,Hyderabad,TS 500085 | H35: LIG-162,2nd floor,7th phase,KPHB,Near basket ball ground,Hyderabad,TS 500085 | I35: QQQQQ | J35: QQQQQ | K35: QQQQQ | L35: QQQQQ | M35: QQQQQ | N35: 44652 | O35: OOOO | P35: OOOO | Q35: OOOO | R35: OOOO | S35: 100260928334 | T35: N/A | U35: OMPRAKASH PURI | V35: 30 | W35: =VLOOKUP(A35,'[1]Pay sheet-APRIL- 2022'!$C$5:$AF$134,10,0) -> 30 | X35: N/A | Y35: 108085 | Z35: =VLOOKUP(A35,'[1]Pay sheet-APRIL- 2022'!$C$5:$AF$134,11,0) -> 64851 | AA35: 0 | AB35: 0 | AC35: =AD35+AE35+AF35+AG35 -> 43347 | AD35: =VLOOKUP(A35,'[1]Pay sheet-APRIL- 2022'!$C$5:$AF$134,12,0) -> 25940.4 | AE35: =VLOOKUP(A35,'[1]Pay sheet-APRIL- 2022'!$C$5:$AF$134,13,0) -> 2083 | AF35: =VLOOKUP(A35,'[1]Pay sheet-APRIL- 2022'!$C$5:$AF$134,14,0) -> 2083 | AG35: =VLOOKUP(A35,'[1]Pay sheet-APRIL- 2022'!$C$5:$AF$134,15,0) -> 13240.6 | AH35: =Z35+AC35 -> 108198 | AI35: =VLOOKUP(A35,'[1]Pay sheet-APRIL- 2022'!$C$5:$AF$134,18,0) -> 1554.609 | AJ35: =VLOOKUP(A35,'[1]Pay sheet-APRIL- 2022'!$C$5:$AF$134,19,0) -> 3119.3331 | AK35: =VLOOKUP(A35,'[1]Pay sheet-APRIL- 2022'!$C$5:$AF$134,20,0) -> 5404.25 | AL35: =VLOOKUP(A35,'[1]Pay sheet-APRIL- 2022'!$C$5:$AF$134,22,0) -> 0 | AM35: =Z35+AD35+AE35+AF35+AG35+AI35+AJ35+AK35 -> 118276.19 | AO35: =VLOOKUP(A35,'[1]Pay sheet-APRIL- 2022'!$C$5:$AF$134,26,0) -> 1800 | AP35: =VLOOKUP(A35,'[1]Pay sheet-APRIL- 2022'!$C$5:$AF$134,25,0) -> 200 | AQ35: =VLOOKUP(A35,'[1]Pay sheet-APRIL- 2022'!$C$5:$AF$134,24,0) -> 0 | AR35: =VLOOKUP(A35,'[1]Pay sheet-APRIL- 2022'!$C$5:$AF$134,27,0) -> 0 | AS35: =SUM(AO35:AR35) -> 2000 | AT35: =AM35-AS35 -> 116276.19 | AU35: 05.05.2022 | AV35: STATE BANK OF INDIA | AW35: 30067197155 | AY35: 39 | AZ35: 20
A36: BITS-746 | B36: DiptiRanjan Dikhit | C36: 31991 | D36: Female | E36: Purna chandra | F36: Network Security Engineer | G36: At-Sanakanjiya nuva sahi,IV Irrigation Market colony,Gate No.2,PO Satyardhi,near sakhi gopi bus stand,Puri,Odissa 752014 | I36: QQQQQ | J36: At-Sanakanjiya nuva sahi,IV Irrigation Market colony,Gate No.2,PO Satyardhi,near sakhi gopi bus stand,Puri,Odissa 752014 | K36: QQQQQ | L36: QQQQQ | M36: QQQQQ | N36: 44655 | O36: OOOO | P36: OOOO | Q36: OOOO | R36: OOOO | S36: 101345259957 | T36: N/A | U36: DiptiRanjan Dikhit | V36: 30 | W36: =VLOOKUP(A36,'[1]Pay sheet-APRIL- 2022'!$C$5:$AF$134,10,0) -> 27 | X36: N/A | Y36: 62667 | Z36: =VLOOKUP(A36,'[1]Pay sheet-APRIL- 2022'!$C$5:$AF$134,11,0) -> 33840.18 | AA36: 0 | AB36: 0 | AC36: =AD36+AE36+AF36+AG36 -> 22673.12 | AD36: =VLOOKUP(A36,'[1]Pay sheet-APRIL- 2022'!$C$5:$AF$134,12,0) -> 13536.072 | AE36: =VLOOKUP(A36,'[1]Pay sheet-APRIL- 2022'!$C$5:$AF$134,13,0) -> 1875 | AF36: =VLOOKUP(A36,'[1]Pay sheet-APRIL- 2022'!$C$5:$AF$134,14,0) -> 1875 | AG36: =VLOOKUP(A36,'[1]Pay sheet-APRIL- 2022'!$C$5:$AF$134,15,0) -> 5387.048 | AH36: =Z36+AC36 -> 56513.3 | AI36: =VLOOKUP(A36,'[1]Pay sheet-APRIL- 2022'!$C$5:$AF$134,18,0) -> 1554.609 | AJ36: =VLOOKUP(A36,'[1]Pay sheet-APRIL- 2022'!$C$5:$AF$134,19,0) -> 1627.7127 | AK36: =VLOOKUP(A36,'[1]Pay sheet-APRIL- 2022'!$C$5:$AF$134,20,0) -> 2820.015 | AL36: =VLOOKUP(A36,'[1]Pay sheet-APRIL- 2022'!$C$5:$AF$134,22,0) -> 0 | AM36: =Z36+AD36+AE36+AF36+AG36+AI36+AJ36+AK36 -> 62515.637 | AO36: =VLOOKUP(A36,'[1]Pay sheet-APRIL- 2022'!$C$5:$AF$134,26,0) -> 1800 | AP36: =VLOOKUP(A36,'[1]Pay sheet-APRIL- 2022'!$C$5:$AF$134,25,0) -> 200 | AQ36: =VLOOKUP(A36,'[1]Pay sheet-APRIL- 2022'!$C$5:$AF$134,24,0) -> 0 | AR36: =VLOOKUP(A36,'[1]Pay sheet-APRIL- 2022'!$C$5:$AF$134,27,0) -> 0 | AS36: =SUM(AO36:AR36) -> 2000 | AT36: =AM36-AS36 -> 60515.637 | AU36: 05.05.2022 | AV36: State Bank Of India | AW36: 31162392468 | AY36: 40 | AZ36: 21
W37: =SUM(W16:W36) -> 619 | X37: =SUM(X16:X36) -> 0 | Y37: =SUM(Y16:Y36) -> 1742484 | Z37: =SUM(Z16:Z36) -> 1032148.6 | AA37: =SUM(AA16:AA36) -> 0 | AB37: =SUM(AB16:AB36) -> 0 | AC37: =SUM(AC16:AC36) -> 690472.08 | AD37: =SUM(AD16:AD36) -> 412859.45 | ... AL37: =SUM(AL16:AL36) -> 0 | AM37: =Z37+AD37+AE37+AF37+AG37+AI37+AJ37+AK37 -> 1890926.2 | AN37: =SUM(AN16:AN36) -> 0 | AO37: =SUM(AO16:AO36) -> 42000 | AP37: =SUM(AP16:AP36) -> 4200 | AQ37: =SUM(AQ16:AQ36) -> 0 | AR37: =SUM(AR16:AR36) -> 5867.337 | AS37: =SUM(AS16:AS36) -> 52067.337 | AT37: =SUM(AT16:AT36) -> 1838858.9

Sheet 04-22 eq ren
A1: Form D
A2: (See rule 6)
A4: Register to be maintained by the employer under rule 6 of the Equal Remuneration Rules, 1976
D6: ='04-221Master'!D10 -> 44652
A8: Name and address of Contractor : | F8: ='04-221Master'!F5 -> Burgeon IT Services Pvt.Ltd.
A10: Name and address of establishment in/under which contract is carried on : | F10: ='04-221Master'!AP5 -> Burgeon IT Services Pvt.Ltd.
F11: ='04-221Master'!AP6 -> Siri Mansion LIGB 436 Dr.A S Rao Nagar,Hyderabad
A12: Name and address of Principal Employer : | F12: ='04-221Master'!AP10 -> INFOSYS LTD.IL Pune SEZ Unit-I,Plot No. 24/3
F13: ='04-221Master'!AP11 -> Rajiv gandhi Info tech park,Village Mann,Pune,Maharashtra 411057
A14: Total number of men workers employed | C14: =D41 -> 17
A16: Total number of women workers employed | C16: =C41 -> 4
C18: Components of remuneration
A19: Category of workers | B19: Brief Description of work | C19: No of women employed | D19: No. of men employed | E19: Rate or remuneration paid | F19: Basic wage & Dearness Allowance | G19: House Rent allowance | H19: Other allowances | I19: Cash value of concessional supply of essential commodities | J19: Name of the Client | K19: Primary Work Place/ Location
A20: ='04-221Master'!F16 -> Senior Software Engineer | B20: IT SUPPORTIVE SERICE | C20: 1 | D20: 0 | E20: ='04-221Master'!Y16 -> 75643 | F20: ='04-221Master'!Z16 -> 45385.8 | G20: ='04-221Master'!AD16 -> 18154.32 | H20: =E20-(F20+G20) -> 12102.88 | I20: 0 | J20: INFOSYS LTD | K20: PUNE
A21: ='04-221Master'!F17 -> Splunk Developer | B21: IT SUPPORTIVE SERICE | C21: 0 | D21: 1 | E21: ='04-221Master'!Y17 -> 149795 | F21: ='04-221Master'!Z17 -> 89877 | G21: ='04-221Master'!AD17 -> 35950.8 | H21: =E21-(F21+G21) -> 23967.2 | I21: 0 | K21: SEZ 1
A22: ='04-221Master'!F18 -> Sr Citrix Administrator | B22: IT SUPPORTIVE SERICE | C22: 0 | D22: 1 | E22: ='04-221Master'!Y18 -> 61740 | F22: ='04-221Master'!Z18 -> 37044 | G22: ='04-221Master'!AD18 -> 14817.6 | H22: =E22-(F22+G22) -> 9878.4 | I22: 0
A23: ='04-221Master'!F19 -> Project Manager | B23: IT SUPPORTIVE SERICE | C23: 1 | D23: 0 | E23: ='04-221Master'!Y19 -> 82132 | F23: ='04-221Master'!Z19 -> 49279.2 | G23: ='04-221Master'!AD19 -> 19711.68 | H23: =E23-(F23+G23) -> 13141.12 | I23: 0
A24: ='04-221Master'!F20 -> Sr. Software Engineer | B24: IT SUPPORTIVE SERICE | C24: 0 | D24: 1 | E24: ='04-221Master'!Y20 -> 69580 | F24: ='04-221Master'!Z20 -> 41748 | G24: ='04-221Master'!AD20 -> 16699.2 | H24: =E24-(F24+G24) -> 11132.8 | I24: 0
A25: ='04-221Master'!F21 -> Sr. DBA / Sr. Administrator | B25: IT SUPPORTIVE SERICE | C25: 0 | D25: 1 | E25: ='04-221Master'!Y21 -> 98501 | F25: ='04-221Master'!Z21 -> 59100.6 | G25: ='04-221Master'!AD21 -> 23640.24 | H25: =E25-(F25+G25) -> 15760.16 | I25: 0
A26: ='04-221Master'!F22 -> SQL DATABASE ADMINISTRATOR | B26: IT SUPPORTIVE SERICE | C26: 0 | D26: 1 | E26: ='04-221Master'!Y22 -> 46909 | F26: ='04-221Master'!Z22 -> 28145.4 | G26: ='04-221Master'!AD22 -> 11258.16 | H26: =E26-(F26+G26) -> 7505.44 | I26: 0
A27: ='04-221Master'!F23 -> Senior Support Engineer | B27: IT SUPPORTIVE SERICE | C27: 0 | D27: 1 | E27: ='04-221Master'!Y23 -> 131257 | F27: ='04-221Master'!Z23 -> 78754.2 | G27: ='04-221Master'!AD23 -> 31501.68 | H27: =E27-(F27+G27) -> 21001.12 | I27: 0
A28: ='04-221Master'!F24 -> Lead PMO | B28: IT SUPPORTIVE SERICE | C28: 0 | D28: 1 | E28: ='04-221Master'!Y24 -> 89547 | F28: ='04-221Master'!Z24 -> 53728.2 | G28: ='04-221Master'!AD24 -> 21491.28 | H28: =E28-(F28+G28) -> 14327.52 | I28: 0
A29: ='04-221Master'!F25 -> Technology Analyst | B29: IT SUPPORTIVE SERICE | C29: 0 | D29: 1 | E29: ='04-221Master'!Y25 -> 98816 | F29: ='04-221Master'!Z25 -> 59289.6 | G29: ='04-221Master'!AD25 -> 23715.84 | H29: =E29-(F29+G29) -> 15810.56 | I29: 0
A30: ='04-221Master'!F26 -> SENIOR HADOOP ADMIN | B30: IT SUPPORTIVE SERICE | C30: 0 | D30: 1 | E30: ='04-221Master'!Y26 -> 59886 | F30: ='04-221Master'!Z26 -> 26349.84 | G30: ='04-221Master'!AD26 -> 10539.936 | H30: =E30-(F30+G30) -> 22996.224 | I30: 0
A31: ='04-221Master'!F27 -> SENIOR APPLICATION CONSULTANT | B31: IT SUPPORTIVE SERICE | C31: 0 | D31: 1 | E31: ='04-221Master'!Y27 -> 35786 | F31: ='04-221Master'!Z27 -> 21471.6 | G31: ='04-221Master'!AD27 -> 8588.64 | H31: =E31-(F31+G31) -> 5725.76 | I31: 0
A32: ='04-221Master'!F28 -> Sr.Cloud Network Engineer | B32: IT SUPPORTIVE SERICE | C32: 0 | D32: 1 | E32: ='04-221Master'!Y28 -> 128477 | F32: ='04-221Master'!Z28 -> 77086.2 | G32: ='04-221Master'!AD28 -> 30834.48 | H32: =E32-(F32+G32) -> 20556.32 | I32: 0
A33: ='04-221Master'!F29 -> Senior network security analyst. | B33: IT SUPPORTIVE SERICE | C33: 0 | D33: 1 | E33: ='04-221Master'!Y29 -> 74716 | F33: ='04-221Master'!Z29 -> 44829.6 | G33: ='04-221Master'!AD29 -> 17931.84 | H33: =E33-(F33+G33) -> 11954.56 | I33: 0
... A35: ='04-221Master'!F31 -> SAP Basis consultant | B35: IT SUPPORTIVE SERICE | C35: 0 | D35: 1 | E35: ='04-221Master'!Y31 -> 38567 | F35: ='04-221Master'!Z31 -> 23140.2 | G35: ='04-221Master'!AD31 -> 9256.08 | H35: =E35-(F35+G35) -> 6170.72 | I35: 0
A36: ='04-221Master'!G32 -> H No 53,Near Durga mandir,at po sarra,gram sarra,tahsil multai dist bethul,Madhya pradesh 460661 | B36: IT SUPPORTIVE SERICE | C36: 0 | D36: 1 | E36: ='04-221Master'!Y32 -> 80278 | F36: ='04-221Master'!Z32 -> 48166.8 | G36: ='04-221Master'!AD32 -> 19266.72 | H36: =E36-(F36+G36) -> 12844.48 | I36: 0
A37: ='04-221Master'!F33 -> Network security consultant | B37: IT SUPPORTIVE SERICE | C37: 0 | D37: 1 | E37: ='04-221Master'!Y33 -> 112719 | F37: ='04-221Master'!Z33 -> 67631.4 | G37: ='04-221Master'!AD33 -> 27052.56 | H37: =E37-(F37+G37) -> 18035.04 | I37: 0
A38: ='04-221Master'!F34 -> Network security consultant | B38: IT SUPPORTIVE SERICE | C38: 1 | D38: 0 | E38: ='04-221Master'!Y34 -> 66374 | F38: ='04-221Master'!Z34 -> 39824.4 | G38: ='04-221Master'!AD34 -> 15929.76 | H38: =E38-(F38+G38) -> 10619.84 | I38: 0
A39: ='04-221Master'!F35 -> CONSULTANT | B39: IT SUPPORTIVE SERICE | C39: 0 | D39: 1 | E39: ='04-221Master'!Y35 -> 108085 | F39: ='04-221Master'!Z35 -> 64851 | G39: ='04-221Master'!AD35 -> 25940.4 | H39: =E39-(F39+G39) -> 17293.6 | I39: 0
A40: ='04-221Master'!F36 -> Network Security Engineer | B40: IT SUPPORTIVE SERICE | C40: 1 | D40: 0 | E40: ='04-221Master'!Y36 -> 62667 | F40: ='04-221Master'!Z36 -> 33840.18 | G40: ='04-221Master'!AD36 -> 13536.072 | H40: =E40-(F40+G40) -> 15290.748 | I40: 0
C41: =SUM(C20:C40) -> 4 | D41: =SUM(D20:D40) -> 17
E48: Signature of the Contractor with Seal

Sheet MH_Must Roll
A1: Form No. II
A2: [M. W. Rules under Maharashtra Contract Labour (Regulation and Abolition)1963 Rule 27 (I)]
A3: Muster Roll cum Wages Register for the month of APRIL 2022
A4: Name and Address of Contractor : BURGEON IT SERVICES PVT.LTD. SIRI MANSION LIG 436 DR.A S RAO NAGAR,HYDERABAD 500 060
G5: Working Hours | I5: Interval for Rest | K5: No. of Hours Worked
A6: Sl.No. | B6: Full Name of Employee | C6: Date of Birth | D6: Gender | E6: Date of Entry into Service | F6: Nature of Work & Designation | G6: From | H6: To | I6: From | J6: To | K6: 1 | L6: 2 | M6: 3 | N6: 4 | O6: 5 | P6: 6 | Q6: 7 | R6: 8 | S6: 9 | T6: 10 | U6: 11 | V6: 12 | W6: 13 | X6: 14 | Y6: 15 | Z6: 16 | AA6: 17 | AB6: 18 | AC6: 19 | AD6: 20 | AE6: 21 | AF6: 22 | AG6: 23 | AH6: 24 | AI6: 25 | AJ6: 26 | AK6: 27 | AL6: 28 | AM6: 29 | AN6: 30 | AO6: MONTH DAYS
