Workbook

Sheet APRIL2 PUNE SEZ UNIT-2 WM Reg
A1: FORM IX- REGISTER OF PERSONS EMPLOYED
A3: (Vide Rule 78(1) (a) (i) of Contract Labour (Regulation and Abolition) Central /Maharastra.Rules 1974
A4: Name and address of Contractor:burgeon IT services Pvt.Ltd. | F4: Name and address of the establishment in / under which contract is carried on: burgeon IT services Pvt.Ltd. Siri mansion LIGH 436 DR.A S Rao nagar,Hyderabad
A5: Siri Mansion LIGB 436 Dr.A S Rao Nagar,Hyderabad
A7: Name and address of Contractor:burgeon IT services Pvt.Ltd. | F7: Name and address of principal employer:
F8: ='0422Master'!AP10 -> INFOSYS LTD.IL Pune SEZ Unit-II,Plot No. 24/3
F9: Rajiv gandhi Info tech park,Village Mann,Pune,Maharashtra 411057
A11: S.No | B11: Name and Surname of workman | C11: Age | D11: SEX | E11: Father's/Husband's name | F11: Nature of Employement/Designation | G11: Permanent Home Address of worken | H11: Local Address | I11: Date of commencement of Employment | J11: Signature or Thumb impression of workman | K11: Date of Temination of Employment | M11: Remarks
L12: Reason for Termination
A13: 1 | B13: 2 | C13: 3 | E13: 4 | F13: 5 | G13: 6 | H13: 7 | I13: 8 | J13: 9 | K13: 10 | M13: 11
A14: 1 | B14: Sumith Sharma | C14: 31356 | D14: MALE | E14: Mahesh Chand jain | F14: Project Manager | G14: 492/1, shivloxpuri, konkerkhem, Meerat contonment UP250001 | H14: 492/1, shivloxpuri, konkerkhem, Meerat contonment UP250001 | I14: 43160 | K14: 43630 | L14: RESIGNATION
A15: 2 | B15: Prithvi Raj Patil | C15: 24/06/1980 | D15: MALE | E15: shripati vittal patil | F15: Project Manager | G15: flat no 304, D wing, B Building ramakrishna paradise, Survey No 113, Near Bhairavnath Temple, Dhayan, Pune city 411041 | H15: flat no 304, D wing, B Building ramakrishna paradise, Survey No 113, Near Bhairavnath Temple, Dhayan, Pune city 411041 | I15: 43160 | K15: 43644 | L15: RESIGNATION
A16: 3 | B16: Nikhil Ghaikwad | C16: 29/03/1985 | D16: MALE | E16: shrikanth govind | F16: Project Coordinator | G16: 5th Floor, 113/114, nanapet, Nawawada, pune 411002 | H16: 5th Floor, 113/114, nanapet, Nawawada, pune 411002 | I16: 43160 | K16: 43553 | L16: RESIGNATION
A17: 4 | B17: Abhik Pandit | C17: 31870 | D17: MALE | E17: Amarnath Pandit | F17: Project Coordinator | G17: Flat B2, Niharika apts, Vivekanand nagar, podrah, Howrah,WB 711109 | H17: Flat B2, Niharika apts, Vivekanand nagar, podrah, Howrah,WB 711109 | I17: 43193 | K17: 43496 | L17: RESIGNATION
A18: 5 | B18: Neha Verma | C18: 27/10/1988 | D18: MALE | E18: Pramod kumar verma | F18: Project Coordinator | G18: post shewra ps patory ward no 7, Hazrat shiura, Samastipur, Bihar 848504 | H18: post shewra ps patory ward no 7, Hazrat shiura, Samastipur, Bihar 848504 | I18: 43194 | K18: 43511 | L18: RESIGNATION
A19: 6 | B19: Kavita Gosavi | C19: 23/08/1985 | D19: MALE | E19: Govindgeer vikramgeer | F19: Project Coordinator | G19: B1-303, saptashri CHS, Anand Nagar, Manpada Road, Dombivalli, MH Thane 421201 | H19: B1-303, saptashri CHS, Anand Nagar, Manpada Road, Dombivalli, MH Thane 421201 | I19: 43208 | K19: 43560 | L19: RESIGNATION
A20: 7 | B20: Bhumika Sachdeva | C20: 19/05/1984 | D20: MALE | E20: Vikram sachdeva | F20: Technical Consultant | G20: 8/416, Anbu Illam, Pilliyar koli street,pozhichellur, chennai, TN 600074 | H20: 8/416, Anbu Illam, Pilliyar koli street,pozhichellur, chennai, TN 600074 | I20: 43194 | K20: 43599 | L20: RESIGNATION
A21: 8 | B21: Vivek Hariharan | C21: 31206 | D21: MALE | E21: P C Hariharan | F21: Project Coordinator | G21: A-10/1, Telco Soc No 9, Sector-24, Pradhikaran, Pune, MH 411044 | H21: A-10/1, Telco Soc No 9, Sector-24, Pradhikaran, Pune, MH 411044 | I21: 43221 | K21: 43552 | L21: RESIGNATION
A22: 9 | B22: Vishaka Salvi | C22: 31513 | D22: MALE | E22: shivaji ganpat | F22: Client Delivery Manager | G22: 302, New Ekta CHS, sector -8, airholi, NAVI MUMBAI 400708 | H22: 302, New Ekta CHS, sector -8, airholi, NAVI MUMBAI 400708 | I22: 43236 | K22: 43644 | L22: RESIGNATION
A23: 10 | B23: DHANANJAY RAMESH GHODMARE | C23: 25/03/1984 | D23: MALE | E23: Ramesh ramji ghodmare | F23: Associate Lead | G23: F37, Indraprastha Apts, pawansuth nagar, nandangan, nagpur, 440009 | H23: F37, Indraprastha Apts, pawansuth nagar, nandangan, nagpur, 440009 | I23: 43241 | K23: 43539 | L23: RESIGNATION
A24: 11 | B24: KAPIL SOPANRAO RASAL | C24: 30804 | D24: MALE | E24: sopan srimant rasal | F24: Project Coordinator | G24: vivekanand puram,kokat f nagar,Latur,413512 | H24: vivekanand puram,kokat f nagar,Latur,413512 | I24: 43248 | K24: 43532 | L24: RESIGNATION
A25: 12 | B25: PRERNA NARAYAN | C25: 28/02/1987 | D25: MALE | E25: Roop Krishen Narayan | F25: Project Manager | G25: Flat no 1302, Towerr-12, Asbridge c, Lodha belmondo gahunje, OPP MCA cricket stadium, Pune MH 412021 | H25: Flat no 1302, Towerr-12, Asbridge c, Lodha belmondo gahunje, OPP MCA cricket stadium, Pune MH 412021 | I25: 43248 | K25: 43602 | L25: RESIGNATION
A26: 13 | B26: VYANKATESH NANDAPURKAR | C26: 19/10/1969 | D26: MALE | E26: Devidas keshavrao | F26: Project Manager | G26: Flat No 402, Wamen Ganesh Paradise, shinde nagar, maratha mandir,Bavdhan pune MH 411021 | H26: Flat No 402, Wamen Ganesh Paradise, shinde nagar, maratha mandir,Bavdhan pune MH 411021 | I26: 43258 | K26: 43595 | L26: RESIGNATION
A27: 14 | B27: PRAVIN PANDURANG WAJE | C27: 31233 | D27: MALE | E27: pandurang dhondu waje | F27: Wintel Administrator | G27: shree society building no D-9, Room no 1/3, Sector 22, Near Matabaai hospital,koper khairne, Navi mumbai, thane , MH 400.079 | H27: shree society building no D-9, Room no 1/3, Sector 22, Near Matabaai hospital,koper khairne, Navi mumbai, thane , MH 400.079 | I27: 43262 | K27: 43630 | L27: RESIGNATION
A28: 15 | B28: PRIYA BASWANT MORE | C28: 18/04/1990 | D28: MALE | E28: Baswant More | F28: Project Coordinator | G28: At Post Rajgoli khurd, Tal Chandgad, Dist kolhapur, Maharashtra 416508 | H28: At Post Rajgoli khurd, Tal Chandgad, Dist kolhapur, Maharashtra 416508 | I28: 43263 | K28: 43504 | L28: RESIGNATION
A29: 16 | B29: VINITA SAWANT | C29: 19/01/1989 | D29: MALE | E29: Anand rao | F29: Project Manager | G29: B12/1 6, Trimurti CHS, sec-24, JUI Nagar, Navi mumbai, 400705 | H29: B12/1 6, Trimurti CHS, sec-24, JUI Nagar, Navi mumbai, 400705 | I29: 43271 | K29: 43623 | L29: RESIGNATION
A30: 17 | B30: SUMIT SANJAY JOSHI | C30: 23/06/1988 | D30: MALE | E30: Sanjay joshi | F30: Project Coordinator | G30: 127 A/P Bahirewadi, Tal-ajara,Dist kolhapur, MH 416220 | H30: 127 A/P Bahirewadi, Tal-ajara,Dist kolhapur, MH 416220 | I30: 43271 | K30: 43490 | L30: RESIGNATION
A31: 18 | B31: BHAGYASHRI awtare | C31: 17/09/1992 | D31: MALE | E31: Bhagwan nathu awate | F31: Project Coordinator | G31: Gangapur, BK Tal ambegaon, shiroli, Pune 410516 | H31: Gangapur, BK Tal ambegaon, shiroli, Pune 410516 | I31: 43276 | K31: 43616 | L31: RESIGNATION
A32: 19 | B32: RAHUL CHAKRADHARE | C32: 17/11/1991 | D32: MALE | E32: vasant moreshwar chakradhare | F32: Project Coordinator | G32: flat no 1001, R- Building, 10th floor, Tanish orchid phase -3, charholi patha pune MH 412105 | H32: flat no 1001, R- Building, 10th floor, Tanish orchid phase -3, charholi patha pune MH 412105 | I32: 43276 | K32: 43616 | L32: RESIGNATION
A33: 20 | B33: Kazi Sayyedsalman Jalaluddin | C33: 23/05/1991 | D33: MALE | E33: Jalaluddin Rashid Kazi | F33: Project Manager | G33: A - 702, Suyog Leher, Near Sai Service, Kondhwa Budruk, Pune - 411048. | H33: A - 702, Suyog Leher, Near Sai Service, Kondhwa Budruk, Pune - 411048. | I33: 43285 | K33: 43630 | L33: RESIGNATION
A34: 21 | B34: Asish kumar satapathy | C34: 33851 | D34: MALE | E34: Harshad Trivedi | F34: SR.Project Coordinator | G34: AT/P-MUNGURWADI,TAL-GADHINGLAJ,DIST-KOLHAPUR, MAHARASHTRA 416503 | H34: AT/P-MUNGURWADI,TAL-GADHINGLAJ,DIST-KOLHAPUR, MAHARASHTRA 416503 | I34: 43286 | K34: 43644 | L34: RESIGNATION
A35: 22 | B35: Pritanjali Patil | C35: 33189 | D35: MALE | E35: Narendra Singh Patil | F35: Project Coordinator | G35: 52, Vidyanagar, Bodwad, Jalgaon Dist, MH | H35: 52, Vidyanagar, Bodwad, Jalgaon Dist, MH | I35: 43283 | K35: 43665 | L35: RESIGNATION
A36: 23 | B36: Madhura Divekar | C36: 24/05/1990 | D36: MALE | E36: Shaunak Divekar | F36: Project Coordinator | G36: Flat No M104, Ramyanagri, Opp Central bank, Bibvewadi, Pune 411037 | H36: Flat No M104, Ramyanagri, Opp Central bank, Bibvewadi, Pune 411037 | I36: 43290 | K36: 43707 | L36: RESIGNATION
A37: 24 | B37: Yash Trivedi | C37: 23/03/1992 | D37: MALE | E37: Harshad Trivedi | F37: Project Coordinator | G37: G/7, Jayambe Colony, Babul Pada,achole road, nalasopara E 401209 | H37: G/7, Jayambe Colony, Babul Pada,achole road, nalasopara E 401209 | I37: 43293 | K37: 43623 | L37: RESIGNATION
A38: 25 | B38: Sumit pande | C38: 25/09/1991 | D38: MALE | E38: Janardhan pande | F38: Project Coordinator | G38: SS/499, SECTOR N1 ALIGANJ LUCKNOW UTTAR PRADESH 226024 | H38: SS/499, SECTOR N1 ALIGANJ LUCKNOW UTTAR PRADESH 226024 | I38: 43297 | K38: 43658 | L38: RESIGNATION
A39: 26 | B39: Rahul Patil | C39: 33851 | D39: MALE | E39: Maruti T patil | F39: Project Coordinator | G39: AT/P-MUNGURWADI,TAL-GADHINGLAJ,DIST-KOLHAPUR, MAHARASHTRA 416503 | H39: AT/P-MUNGURWADI,TAL-GADHINGLAJ,DIST-KOLHAPUR, MAHARASHTRA 416503 | I39: 43297 | K39: 43623 | L39: RESIGNATION
A40: 27 | B40: Prachi Duble | C40: 33096 | D40: MALE | E40: pandurang shantaram duble | F40: Project Coordinator | G40: H No 661,C/o Sateri Medical stores, Aronda, Tal-sawantwadi, Dist-Sindhudurg, Maharashtra 416513 | H40: H No 661,C/o Sateri Medical stores, Aronda, Tal-sawantwadi, Dist-Sindhudurg, Maharashtra 416513 | I40: 43299 | K40: 43630 | L40: RESIGNATION
A41: 28 | B41: Rohit Shellar | C41: 17/07/1994 | D41: MALE | E41: Shivaji Babanrao Shelar | F41: Project Coordinator | G41: plot no. 126 Mohininagar , kedgaon , Ahmednagar,414005 | H41: plot no. 126 Mohininagar , kedgaon , Ahmednagar,414005 | I41: 43300 | K41: 43637 | L41: RESIGNATION
A42: 29 | B42: Harshad Daphane | C42: 32697 | D42: MALE | E42: Dinakar Balaji | F42: Project Coordinator | G42: Rh No.A-5,Renuka Puram,Satara Parisar,Beed Bypass,Aurangabad-431010 | H42: Rh No.A-5,Renuka Puram,Satara Parisar,Beed Bypass,Aurangabad-431010 | I42: 43304 | K42: 43630 | L42: RESIGNATION
A43: 30 | B43: Raj Prakash Pandya | C43: 34094 | D43: MALE | E43: Prakash Pandya | F43: Project Delivery Manager | G43: 1B/42, Kalpataru Gardens, Ashok Nagar, Kanoivali E Mumbai 400101 | H43: 1B/42, Kalpataru Gardens, Ashok Nagar, Kanoivali E Mumbai 400101 | I43: 43306 | K43: 43637 | L43: RESIGNATION
...

Sheet 0422Master
A3: FORM - XIII REGISTER OF WORKMEN EMPLOYED BY CONTRACTOR
B4: (Vide Rule 75 of Contract Labour (Regulation and Abolition) Central/Karnataka Rules 1974)
A5: Name and address of Contractor: | F5: Burgeon IT Services Pvt.Ltd. | AB5: Name and address of Establishemnt in/ under which contract is carried on: | AP5: =F5 -> Burgeon IT Services Pvt.Ltd.
F6: Siri Mansion LIGB 436 Dr.A S Rao Nagar,Hyderabad | AP6: =F6 -> Siri Mansion LIGB 436 Dr.A S Rao Nagar,Hyderabad
AP7: =F7 -> 0
A8: Nature and location of work: | F8: IT SUPPORTIVE SERVICES& PUNE SEZ UNIT-II
A10: Wage period: Monthly | D10: 44652 | AK10: Name and address of Principal Employer: | AP10: INFOSYS LTD.IL Pune SEZ Unit-II,Plot No. 24/3
AP11: Rajiv gandhi Info tech park,Village Mann,Pune,Maharashtra 411057
B13: 1 | C13: 2 | D13: 3 | E13: 4 | F13: 5 | G13: 6 | H13: 7 | I13: 8 | J13: 9 | K13: 10 | L13: 11 | M13: 12 | N13: 13 | O13: 14 | P13: 15 | Q13: 16 | R13: 17 | S13: 18 | T13: 19 | U13: 20 | V13: 21 | W13: 22 | X13: 23 | Y13: 24 | Z13: 25 | AA13: 26 | AB13: 27 | AC13: 28 | AD13: 29 | AE13: 30 | AF13: 31 | AG13: 32 | AH13: 33 | AI13: 34 | AJ13: 35 | AK13: 36 | AL13: 37 | AM13: 38 | AN13: 39 | AO13: 40 | AP13: 41 | AQ13: 42 | AR13: 43 | AS13: 44 | AT13: 45 | AU13: 46
B14: Name of Workman | C14: Age | D14: Sex | E14: Father's /Husband Name | F14: Designation / Nature of Work Done | G14: Permanent Address | J14: Local Address | N14: Date of Commencement of Employment | O14: Signature or thumb impression of Workman | P14: Date of termination of Employment | Q14: Reasons for termination | R14: Remarks | S14: EPF Number | T14: ESI Number | U14: Name of Workman | V14: NO.OF DAYS | W14: No.of Days worked | X14: Unit of work done | Y14: Monthly rate of wages/ piece rate | Z14: Basic wages | AA14: Dearness Allowances | AB14: Over time | AC14: Other cash payments (Nature of payments to be indicated) | AD14: HRA | AE14: CONVEYANCE | AF14: MEDICAL ALLOWANCES | AG14: SPECIAL ALLOWNANCES | AH14: Total | AI14: BONUS | AJ14: GRATUITY | AK14: LTA/L.E | AL14: ARREAR AMOUNT | AM14: TOTAL AMOUNT | AN14: Deductions, if any, (Indicate nature) | AT14: Net Amount paid | AU14: Time and Date of Payment | AV14: Place of Payment | AW14: Signature/Thumb Impression of workman | AX14: Initial of Contractor or his representative | AY14: Serial No. in the Register of Workmen
AN15: ESI | AO15: PF | AP15: PT | AQ15: TDS | AR15: MED | AS15: Total Deductions
A16: BITS-652 | B16: Shaikh Mohammed Sartaj | C16: 31453 | D16: MALE | E16: Shaikh Mohammad Rafique | F16: Network Security Admin | G16: plot no 110, Sadatnagar, Near Railway station, Aurangabad, 431001 | J16: plot no 110, Sadatnagar, Near Railway station, Aurangabad, 431001 | N16: 44470 | S16: 100468499225 | T16: N/A | U16: Shaikh Mohammed Sartaj | V16: 30 | W16: =VLOOKUP(A16,'[1]Pay sheet-APRIL- 2022'!$C$57:$AF$129,10,0) -> 30 | X16: N/A | Y16: 80278 | Z16: =VLOOKUP(A16,'[1]Pay sheet-APRIL- 2022'!$C$57:$AF$129,11,0) -> 48166.8 | AA16: 0 | AB16: 0 | AC16: =AD16+AE16+AF16+AG16 -> 32224.2 | AD16: =VLOOKUP(A16,'[1]Pay sheet-APRIL- 2022'!$C$57:$AF$129,12,0) -> 19266.72 | AE16: =VLOOKUP(A16,'[1]Pay sheet-APRIL- 2022'!$C$57:$AF$129,13,0) -> 2083 | AF16: =VLOOKUP(A16,'[1]Pay sheet-APRIL- 2022'!$C$57:$AF$129,14,0) -> 2083 | AG16: =VLOOKUP(A16,'[1]Pay sheet-APRIL- 2022'!$C$57:$AF$129,15,0) -> 8791.48 | AH16: =Z16+AC16 -> 80391 | AI16: =VLOOKUP(A16,'[1]Pay sheet-APRIL- 2022'!$C$57:$AF$129,18,0) -> 1554.609 | AJ16: =VLOOKUP(A16,'[1]Pay sheet-APRIL- 2022'!$C$57:$AF$129,19,0) -> 2316.8231 | AK16: =VLOOKUP(A16,'[1]Pay sheet-APRIL- 2022'!$C$57:$AF$129,20,0) -> 4013.9 | AL16: =VLOOKUP(A16,'[1]Pay sheet-APRIL- 2022'!$C$57:$AF$129,22,0) -> 0 | AM16: =Z16+AD16+AE16+AF16+AG16+AI16+AJ16+AK16 -> 88276.332 | AN16: 0 | AO16: =VLOOKUP(A16,'[1]Pay sheet-APRIL- 2022'!$C$57:$AF$129,26,0) -> 1800 | AP16: =VLOOKUP(A16,'[1]Pay sheet-APRIL- 2022'!$C$57:$AF$129,25,0) -> 200 | AQ16: =VLOOKUP(A16,'[1]Pay sheet-APRIL- 2022'!$C$57:$AF$129,24,0) -> 0 | AR16: =VLOOKUP(A16,'[1]Pay sheet-APRIL- 2022'!$C$57:$AF$129,27,0) -> 254 | AS16: =SUM(AO16:AR16) -> 2254 | AT16: =AM16+AL16+-AS16 -> 86022.332 | AU16: 05.05.2022 | AV16: HDFC BANK | AW16: 50100405646907 | AY16: 53 | AZ16: 1
A17: BITS-660 | B17: Moin Ahemad Jahur Ahemad Kumarkiri | C17: 31507 | D17: MALE | E17: Jahur Ahemad Kumarkiri | F17: Infrastructure Lead | G17: E 111, Ace City Police Chowki, Sector-1, Bishrak, Greater Noida West, Yatharth Hospital, Noida, 201306 | J17: River Residency, Chikhali , Pune | N17: 44491 | S17: 100505159752 | T17: N/A | U17: Moin Ahemad Jahur Ahemad Kumarkiri | V17: 30 | W17: =VLOOKUP(A17,'[1]Pay sheet-APRIL- 2022'!$C$57:$AF$129,10,0) -> 30 | X17: N/A | Y17: 143307 | Z17: =VLOOKUP(A17,'[1]Pay sheet-APRIL- 2022'!$C$57:$AF$129,11,0) -> 85984.2 | AA17: 0 | AB17: 0 | AC17: =AD17+AE17+AF17+AG17 -> 57435.8 | AD17: =VLOOKUP(A17,'[1]Pay sheet-APRIL- 2022'!$C$57:$AF$129,12,0) -> 34393.68 | AE17: =VLOOKUP(A17,'[1]Pay sheet-APRIL- 2022'!$C$57:$AF$129,13,0) -> 2083 | AF17: =VLOOKUP(A17,'[1]Pay sheet-APRIL- 2022'!$C$57:$AF$129,14,0) -> 2083 | AG17: =VLOOKUP(A17,'[1]Pay sheet-APRIL- 2022'!$C$57:$AF$129,15,0) -> 18876.12 | AH17: =Z17+AC17 -> 143420 | AI17: =VLOOKUP(A17,'[1]Pay sheet-APRIL- 2022'!$C$57:$AF$129,18,0) -> 1554.609 | AJ17: =VLOOKUP(A17,'[1]Pay sheet-APRIL- 2022'!$C$57:$AF$129,19,0) -> 4135.84 | AK17: =VLOOKUP(A17,'[1]Pay sheet-APRIL- 2022'!$C$57:$AF$129,20,0) -> 7165.35 | AL17: =VLOOKUP(A17,'[1]Pay sheet-APRIL- 2022'!$C$57:$AF$129,22,0) -> 0 | AM17: =Z17+AD17+AE17+AF17+AG17+AI17+AJ17+AK17 -> 156275.8 | AN17: 0 | AO17: =VLOOKUP(A17,'[1]Pay sheet-APRIL- 2022'!$C$57:$AF$129,26,0) -> 1800 | AP17: =VLOOKUP(A17,'[1]Pay sheet-APRIL- 2022'!$C$57:$AF$129,25,0) -> 200 | AQ17: =VLOOKUP(A17,'[1]Pay sheet-APRIL- 2022'!$C$57:$AF$129,24,0) -> 0 | AR17: =VLOOKUP(A17,'[1]Pay sheet-APRIL- 2022'!$C$57:$AF$129,27,0) -> 254 | AS17: =SUM(AO17:AR17) -> 2254 | AT17: =AM17+AL17+-AS17 -> 154021.8 | AU17: 05.05.2022 | AV17: HDFC BANK | AW17: 50100103229547 | AY17: 54 | AZ17: 2
A18: BITS-664 | B18: Savana Saritha Dora | C18: 29965 | D18: FEMALE | E18: Laxman gupta | F18: ASSISTANT PROJECT MANAGER | G18: Shafa Nagar Ausa, Dist- Latur, Maharashtra | J18: E 111, Ace City Police Chowki, Sector-1, Bishrak, Greater Noida West, Yatharth Hospital, Noida, 201306 | N18: 44495 | S18: 101749326014 | T18: N/A | U18: Savana Saritha Dora | V18: 30 | W18: =VLOOKUP(A18,'[1]Pay sheet-APRIL- 2022'!$C$57:$AF$129,10,0) -> 30 | X18: N/A | Y18: 55251 | Z18: =VLOOKUP(A18,'[1]Pay sheet-APRIL- 2022'!$C$57:$AF$129,11,0) -> 33150.6 | AA18: 0 | AB18: 0 | AC18: =AD18+AE18+AF18+AG18 -> 22213.4 | AD18: =VLOOKUP(A18,'[1]Pay sheet-APRIL- 2022'!$C$57:$AF$129,12,0) -> 13260.24 | AE18: =VLOOKUP(A18,'[1]Pay sheet-APRIL- 2022'!$C$57:$AF$129,13,0) -> 2083 | AF18: =VLOOKUP(A18,'[1]Pay sheet-APRIL- 2022'!$C$57:$AF$129,14,0) -> 2083 | AG18: =VLOOKUP(A18,'[1]Pay sheet-APRIL- 2022'!$C$57:$AF$129,15,0) -> 4787.16 | AH18: =Z18+AC18 -> 55364 | AI18: =VLOOKUP(A18,'[1]Pay sheet-APRIL- 2022'!$C$57:$AF$129,18,0) -> 1554.609 | AJ18: =VLOOKUP(A18,'[1]Pay sheet-APRIL- 2022'!$C$57:$AF$129,19,0) -> 1594.5439 | AK18: =VLOOKUP(A18,'[1]Pay sheet-APRIL- 2022'!$C$57:$AF$129,20,0) -> 2762.55 | AL18: =VLOOKUP(A18,'[1]Pay sheet-APRIL- 2022'!$C$57:$AF$129,22,0) -> 0 | AM18: =Z18+AD18+AE18+AF18+AG18+AI18+AJ18+AK18 -> 61275.703 | AN18: 0 | AO18: =VLOOKUP(A18,'[1]Pay sheet-APRIL- 2022'!$C$57:$AF$129,26,0) -> 1800 | AP18: =VLOOKUP(A18,'[1]Pay sheet-APRIL- 2022'!$C$57:$AF$129,25,0) -> 200 | AQ18: =VLOOKUP(A18,'[1]Pay sheet-APRIL- 2022'!$C$57:$AF$129,24,0) -> 0 | AR18: =VLOOKUP(A18,'[1]Pay sheet-APRIL- 2022'!$C$57:$AF$129,27,0) -> 286 | AS18: =SUM(AO18:AR18) -> 2286 | AT18: =AM18+AL18+-AS18 -> 58989.703 | AU18: 05.05.2022 | AV18: SBI | AW18: 20101763786 | AY18: 55 | AZ18: 3
A19: BITS-668 | B19: Mandar Shetty | C19: 31205 | D19: MALE | E19: Vijay Shetty | F19: Project Manager | G19: B-301,Hemarold Isle,Wagholi-Lohegaon,Behind Wagheshwar Temple,Wagholi,Pune 412207 | H19: B-301,Hemarold Isle,Wagholi-Lohegaon,Behind Wagheshwar Temple,Wagholi,Pune 412207 | J19: B-301,Hemarold Isle,Wagholi-Lohegaon,Behind Wagheshwar Temple,Wagholi,Pune 412207 | N19: 44509 | S19: 100217449855 | T19: N/A | U19: Mandar Shetty | V19: 30 | W19: =VLOOKUP(A19,'[1]Pay sheet-APRIL- 2022'!$C$57:$AF$129,10,0) -> 30 | X19: N/A | Y19: 104377 | Z19: =VLOOKUP(A19,'[1]Pay sheet-APRIL- 2022'!$C$57:$AF$129,11,0) -> 62626.2 | AA19: 0 | AB19: 0 | AC19: =AD19+AE19+AF19+AG19 -> 41863.8 | AD19: =VLOOKUP(A19,'[1]Pay sheet-APRIL- 2022'!$C$57:$AF$129,12,0) -> 25050.48 | AE19: =VLOOKUP(A19,'[1]Pay sheet-APRIL- 2022'!$C$57:$AF$129,13,0) -> 2083 | AF19: =VLOOKUP(A19,'[1]Pay sheet-APRIL- 2022'!$C$57:$AF$129,14,0) -> 2083 | AG19: =VLOOKUP(A19,'[1]Pay sheet-APRIL- 2022'!$C$57:$AF$129,15,0) -> 12647.32 | AH19: =Z19+AC19 -> 104490 | AI19: =VLOOKUP(A19,'[1]Pay sheet-APRIL- 2022'!$C$57:$AF$129,18,0) -> 1554.609 | AJ19: =VLOOKUP(A19,'[1]Pay sheet-APRIL- 2022'!$C$57:$AF$129,19,0) -> 3012.3202 | AK19: =VLOOKUP(A19,'[1]Pay sheet-APRIL- 2022'!$C$57:$AF$129,20,0) -> 5218.85 | AL19: =VLOOKUP(A19,'[1]Pay sheet-APRIL- 2022'!$C$57:$AF$129,22,0) -> 0 | AM19: =Z19+AD19+AE19+AF19+AG19+AI19+AJ19+AK19 -> 114275.78 | AN19: 0 | AO19: =VLOOKUP(A19,'[1]Pay sheet-APRIL- 2022'!$C$57:$AF$129,26,0) -> 1800 | AP19: =VLOOKUP(A19,'[1]Pay sheet-APRIL- 2022'!$C$57:$AF$129,25,0) -> 200 | AQ19: =VLOOKUP(A19,'[1]Pay sheet-APRIL- 2022'!$C$57:$AF$129,24,0) -> 0 | AR19: =VLOOKUP(A19,'[1]Pay sheet-APRIL- 2022'!$C$57:$AF$129,27,0) -> 283 | AS19: =SUM(AO19:AR19) -> 2283 | AT19: =AM19+AL19+-AS19 -> 111992.78 | AU19: 05.05.2022 | AV19: Axis Bank | AW19: 910010033970009 | AY19: 57 | AZ19: 4
A20: BITS-672 | B20: Vivek Dongre | C20: 32931 | D20: MALE | E20: Purushottam Dongre | F20: Project Manager | G20: B-8,Good will Samwrudhi,Gokul nagar,Dhanuri road No.15,Pune 411015 | J20: B-8,Good will Samwrudhi,Gokul nagar,Dhanuri road No.15,Pune 411015 | N20: 44515 | S20: 100857629834 | T20: N/A | U20: Vivek Dongre | V20: 30 | W20: =VLOOKUP(A20,'[1]Pay sheet-APRIL- 2022'!$C$57:$AF$129,10,0) -> 30 | X20: N/A | Y20: 66374 | Z20: =VLOOKUP(A20,'[1]Pay sheet-APRIL- 2022'!$C$57:$AF$129,11,0) -> 39824.4 | AA20: 0 | AB20: 0 | AC20: =AD20+AE20+AF20+AG20 -> 26662.6 | AD20: =VLOOKUP(A20,'[1]Pay sheet-APRIL- 2022'!$C$57:$AF$129,12,0) -> 15929.76 | AE20: =VLOOKUP(A20,'[1]Pay sheet-APRIL- 2022'!$C$57:$AF$129,13,0) -> 2083 | AF20: =VLOOKUP(A20,'[1]Pay sheet-APRIL- 2022'!$C$57:$AF$129,14,0) -> 2083 | AG20: =VLOOKUP(A20,'[1]Pay sheet-APRIL- 2022'!$C$57:$AF$129,15,0) -> 6566.84 | AH20: =Z20+AC20 -> 66487 | AI20: =VLOOKUP(A20,'[1]Pay sheet-APRIL- 2022'!$C$57:$AF$129,18,0) -> 1554.609 | AJ20: =VLOOKUP(A20,'[1]Pay sheet-APRIL- 2022'!$C$57:$AF$129,19,0) -> 1915.5536 | AK20: =VLOOKUP(A20,'[1]Pay sheet-APRIL- 2022'!$C$57:$AF$129,20,0) -> 3318.7 | AL20: =VLOOKUP(A20,'[1]Pay sheet-APRIL- 2022'!$C$57:$AF$129,22,0) -> 0 | AM20: =Z20+AD20+AE20+AF20+AG20+AI20+AJ20+AK20 -> 73275.863 | AN20: 0 | AO20: =VLOOKUP(A20,'[1]Pay sheet-APRIL- 2022'!$C$57:$AF$129,26,0) -> 1800 | AP20: =VLOOKUP(A20,'[1]Pay sheet-APRIL- 2022'!$C$57:$AF$129,25,0) -> 200 | AQ20: =VLOOKUP(A20,'[1]Pay sheet-APRIL- 2022'!$C$57:$AF$129,24,0) -> 0 | AR20: =VLOOKUP(A20,'[1]Pay sheet-APRIL- 2022'!$C$57:$AF$129,27,0) -> 252 | AS20: =SUM(AO20:AR20) -> 2252 | AT20: =AM20+AL20+-AS20 -> 71023.863 | AU20: 05.05.2022 | AV20: CITI Bank | AW20: 5297131705 | AY20: 58 | AZ20: 5
A21: BITS-674 | B21: Amit Chawadi | C21: 31279 | D21: MALE | E21: Veerendra | F21: Sr.Software Engineer | G21: Block No.C-9/10,Bhagyodhaya housing society,Opp Parsi vihar,Nai zindagi road,Solapur,Maharastra 413003 | J21: Block No.C-9/10,Bhagyodhaya housing society,Opp Parsi vihar,Nai zindagi road,Solapur,Maharastra 413003 | N21: 44522 | S21: 100930453611 | T21: N/A | U21: Amit Chawadi | V21: 30 | W21: =VLOOKUP(A21,'[1]Pay sheet-APRIL- 2022'!$C$57:$AF$129,10,0) -> 30 | X21: N/A | Y21: 80278 | Z21: =VLOOKUP(A21,'[1]Pay sheet-APRIL- 2022'!$C$57:$AF$129,11,0) -> 48166.8 | AA21: 0 | AB21: 0 | AC21: =AD21+AE21+AF21+AG21 -> 32224.2 | AD21: =VLOOKUP(A21,'[1]Pay sheet-APRIL- 2022'!$C$57:$AF$129,12,0) -> 19266.72 | AE21: =VLOOKUP(A21,'[1]Pay sheet-APRIL- 2022'!$C$57:$AF$129,13,0) -> 2083 | AF21: =VLOOKUP(A21,'[1]Pay sheet-APRIL- 2022'!$C$57:$AF$129,14,0) -> 2083 | AG21: =VLOOKUP(A21,'[1]Pay sheet-APRIL- 2022'!$C$57:$AF$129,15,0) -> 8791.48 | AH21: =Z21+AC21 -> 80391 | AI21: =VLOOKUP(A21,'[1]Pay sheet-APRIL- 2022'!$C$57:$AF$129,18,0) -> 1554.609 | AJ21: =VLOOKUP(A21,'[1]Pay sheet-APRIL- 2022'!$C$57:$AF$129,19,0) -> 2316.8231 | AK21: =VLOOKUP(A21,'[1]Pay sheet-APRIL- 2022'!$C$57:$AF$129,20,0) -> 4013.9 | AL21: =VLOOKUP(A21,'[1]Pay sheet-APRIL- 2022'!$C$57:$AF$129,22,0) -> 0 | AM21: =Z21+AD21+AE21+AF21+AG21+AI21+AJ21+AK21 -> 88276.332 | AN21: 0 | AO21: =VLOOKUP(A21,'[1]Pay sheet-APRIL- 2022'!$C$57:$AF$129,26,0) -> 1800 | AP21: =VLOOKUP(A21,'[1]Pay sheet-APRIL- 2022'!$C$57:$AF$129,25,0) -> 200 | AQ21: =VLOOKUP(A21,'[1]Pay sheet-APRIL- 2022'!$C$57:$AF$129,24,0) -> 0 | AR21: =VLOOKUP(A21,'[1]Pay sheet-APRIL- 2022'!$C$57:$AF$129,27,0) -> 283 | AS21: =SUM(AO21:AR21) -> 2283 | AT21: =AM21+AL21+-AS21 -> 85993.332 | AU21: 05.05.2022 | AV21: ICICI Bank | AW21: 007401540582 | AY21: 59 | AZ21: 6
A22: BITS-677 | B22: Ashwini Nanaware | C22: 33778 | D22: MALE | E22: Suresh Sadashiv Male | F22: Project Manager | G22: Flat No 305,Pandarinath Appartments,Sanath nagar lane,No7,Lohegaon,Pune 411047 | I22: OOO | J22: Flat No 305,Pandarinath Appartments,Sanath nagar lane,No7,Lohegaon,Pune 411047 | K22: OOO | L22: OOO | M22: OOO | N22: 44536 | S22: 100734752719 | T22: N/A | U22: Ashwini Nanaware | V22: 30 | W22: =VLOOKUP(A22,'[1]Pay sheet-APRIL- 2022'!$C$57:$AF$129,10,0) -> 30 | X22: N/A | Y22: 54324 | Z22: =VLOOKUP(A22,'[1]Pay sheet-APRIL- 2022'!$C$57:$AF$129,11,0) -> 32594.4 | AA22: 0 | AB22: 0 | AC22: =AD22+AE22+AF22+AG22 -> 21842.6 | AD22: =VLOOKUP(A22,'[1]Pay sheet-APRIL- 2022'!$C$57:$AF$129,12,0) -> 13037.76 | AE22: =VLOOKUP(A22,'[1]Pay sheet-APRIL- 2022'!$C$57:$AF$129,13,0) -> 2083 | AF22: =VLOOKUP(A22,'[1]Pay sheet-APRIL- 2022'!$C$57:$AF$129,14,0) -> 2083 | AG22: =VLOOKUP(A22,'[1]Pay sheet-APRIL- 2022'!$C$57:$AF$129,15,0) -> 4638.84 | AH22: =Z22+AC22 -> 54437 | AI22: =VLOOKUP(A22,'[1]Pay sheet-APRIL- 2022'!$C$57:$AF$129,18,0) -> 1554.609 | AJ22: =VLOOKUP(A22,'[1]Pay sheet-APRIL- 2022'!$C$57:$AF$129,19,0) -> 1567.7906 | AK22: =VLOOKUP(A22,'[1]Pay sheet-APRIL- 2022'!$C$57:$AF$129,20,0) -> 2716.2 | AL22: =VLOOKUP(A22,'[1]Pay sheet-APRIL- 2022'!$C$57:$AF$129,22,0) -> 0 | AM22: =Z22+AD22+AE22+AF22+AG22+AI22+AJ22+AK22 -> 60275.6 | AN22: 0 | AO22: =VLOOKUP(A22,'[1]Pay sheet-APRIL- 2022'!$C$57:$AF$129,26,0) -> 1800 | AP22: =VLOOKUP(A22,'[1]Pay sheet-APRIL- 2022'!$C$57:$AF$129,25,0) -> 200 | AQ22: =VLOOKUP(A22,'[1]Pay sheet-APRIL- 2022'!$C$57:$AF$129,24,0) -> 0 | AR22: =VLOOKUP(A22,'[1]Pay sheet-APRIL- 2022'!$C$57:$AF$129,27,0) -> 283 | AS22: =SUM(AO22:AR22) -> 2283 | AT22: =AM22+AL22+-AS22 -> 57992.6 | AU22: 05.05.2022 | AV22: HDFC Bank | AW22: 50100191546051 | AY22: 60 | AZ22: 7
A23: BITS-678 | B23: Kaushal Sushil Sharma | C23: 35033 | D23: MALE | E23: Sushil Sharma | F23: Network Engineer L2 | G23: Room No.2, Ambica singh Chawl,New Deepak wadi,Khar east,Mumbai,400051 | I23: OOO | J23: Room No.2, Ambica singh Chawl,New Deepak wadi,Khar east,Mumbai,400051 | K23: OOO | L23: OOO | M23: OOO | N23: 44536 | S23: 100779324583 | T23: N/A | U23: Kaushal Sushil Sharma | V23: 30 | W23: =VLOOKUP(A23,'[1]Pay sheet-APRIL- 2022'!$C$57:$AF$129,10,0) -> 30 | X23: N/A | Y23: 61740 | Z23: =VLOOKUP(A23,'[1]Pay sheet-APRIL- 2022'!$C$57:$AF$129,11,0) -> 37044 | AA23: 0 | AB23: 0 | AC23: =AD23+AE23+AF23+AG23 -> 24809 | AD23: =VLOOKUP(A23,'[1]Pay sheet-APRIL- 2022'!$C$57:$AF$129,12,0) -> 14817.6 | AE23: =VLOOKUP(A23,'[1]Pay sheet-APRIL- 2022'!$C$57:$AF$129,13,0) -> 2083 | AF23: =VLOOKUP(A23,'[1]Pay sheet-APRIL- 2022'!$C$57:$AF$129,14,0) -> 2083 | AG23: =VLOOKUP(A23,'[1]Pay sheet-APRIL- 2022'!$C$57:$AF$129,15,0) -> 5825.4 | AH23: =Z23+AC23 -> 61853 | AI23: =VLOOKUP(A23,'[1]Pay sheet-APRIL- 2022'!$C$57:$AF$129,18,0) -> 1554.609 | AJ23: =VLOOKUP(A23,'[1]Pay sheet-APRIL- 2022'!$C$57:$AF$129,19,0) -> 1781.8164 | AK23: =VLOOKUP(A23,'[1]Pay sheet-APRIL- 2022'!$C$57:$AF$129,20,0) -> 3087 | AL23: =VLOOKUP(A23,'[1]Pay sheet-APRIL- 2022'!$C$57:$AF$129,22,0) -> 0 | AM23: =Z23+AD23+AE23+AF23+AG23+AI23+AJ23+AK23 -> 68276.425 | AN23: 0 | AO23: =VLOOKUP(A23,'[1]Pay sheet-APRIL- 2022'!$C$57:$AF$129,26,0) -> 1800 | AP23: =VLOOKUP(A23,'[1]Pay sheet-APRIL- 2022'!$C$57:$AF$129,25,0) -> 200 | AQ23: =VLOOKUP(A23,'[1]Pay sheet-APRIL- 2022'!$C$57:$AF$129,24,0) -> 0 | AR23: =VLOOKUP(A23,'[1]Pay sheet-APRIL- 2022'!$C$57:$AF$129,27,0) -> 283 | AS23: =SUM(AO23:AR23) -> 2283 | AT23: =AM23+AL23+-AS23 -> 65993.425 | AU23: 05.05.2022 | AV23: ICICI Bank | AW23: 001901524778 | AY23: 61 | AZ23: 8
A24: BITS-680 | B24: Arvind Akhare | C24: 32329 | D24: MALE | E24: Vasanth Rao Ramkishan Akhare | F24: Project Manager | G24: AP.Shelgaon Deshmukh sub distruct,Mehkar,District Buldana,Maharastra 443303 | I24: OOO | J24: AP.Shelgaon Deshmukh sub distruct,Mehkar,District Buldana,Maharastra 443303 | K24: OOO | L24: OOO | M24: OOO | N24: 44537 | S24: 100743126845 | T24: N/A | U24: Arvind Akhare | V24: 30 | W24: =VLOOKUP(A24,'[1]Pay sheet-APRIL- 2022'!$C$57:$AF$129,10,0) -> 28 | X24: N/A | Y24: 84912 | Z24: =VLOOKUP(A24,'[1]Pay sheet-APRIL- 2022'!$C$57:$AF$129,11,0) -> 47550.72 | AA24: 0 | AB24: 0 | AC24: =AD24+AE24+AF24+AG24 -> 31813.48 | AD24: =VLOOKUP(A24,'[1]Pay sheet-APRIL- 2022'!$C$57:$AF$129,12,0) -> 19020.288 | AE24: =VLOOKUP(A24,'[1]Pay sheet-APRIL- 2022'!$C$57:$AF$129,13,0) -> 1944 | AF24: =VLOOKUP(A24,'[1]Pay sheet-APRIL- 2022'!$C$57:$AF$129,14,0) -> 1944 | AG24: =VLOOKUP(A24,'[1]Pay sheet-APRIL- 2022'!$C$57:$AF$129,15,0) -> 8905.192 | AH24: =Z24+AC24 -> 79364.2 | AI24: =VLOOKUP(A24,'[1]Pay sheet-APRIL- 2022'!$C$57:$AF$129,18,0) -> 1554.609 | AJ24: =VLOOKUP(A24,'[1]Pay sheet-APRIL- 2022'!$C$57:$AF$129,19,0) -> 2287.1896 | AK24: =VLOOKUP(A24,'[1]Pay sheet-APRIL- 2022'!$C$57:$AF$129,20,0) -> 3962.56 | AL24: =VLOOKUP(A24,'[1]Pay sheet-APRIL- 2022'!$C$57:$AF$129,22,0) -> 0 | AM24: =Z24+AD24+AE24+AF24+AG24+AI24+AJ24+AK24 -> 87168.559 | AN24: 0 | AO24: =VLOOKUP(A24,'[1]Pay sheet-APRIL- 2022'!$C$57:$AF$129,26,0) -> 1800 | AP24: =VLOOKUP(A24,'[1]Pay sheet-APRIL- 2022'!$C$57:$AF$129,25,0) -> 200 | AQ24: =VLOOKUP(A24,'[1]Pay sheet-APRIL- 2022'!$C$57:$AF$129,24,0) -> 0 | AR24: =VLOOKUP(A24,'[1]Pay sheet-APRIL- 2022'!$C$57:$AF$129,27,0) -> 283 | AS24: =SUM(AO24:AR24) -> 2283 | AT24: =AM24+AL24+-AS24 -> 84885.559 | AU24: 05.05.2022 | AV24: HDFC Bank | AW24: 50100150364960 | AY24: 62 | AZ24: 9
A25: BITS-681 | B25: Pallavi Rishikesh Naik | C25: 34094 | D25: Female | E25: Rishikesh Naik | F25: Project Manager | G25: C/3,Ekta Housing Society,MIDC,G Block,Sambajinagar,Chinchiwad,Pune 411019 | I25: OOO | J25: C/O Prameela Savath,Suryasirvad society,Flat No.5,Near Waghere wada,Priyadarshini school,Nehru nagar,Pimpri,Pune 411048 | K25: OOO | L25: OOO | M25: OOO | N25: 44538 | S25: 100905532909 | T25: N/A | U25: Pallavi Rishikesh Naik | V25: 30 | W25: =VLOOKUP(A25,'[1]Pay sheet-APRIL- 2022'!$C$57:$AF$129,10,0) -> 30 | X25: N/A | Y25: 71009 | Z25: =VLOOKUP(A25,'[1]Pay sheet-APRIL- 2022'!$C$57:$AF$129,11,0) -> 42605.4 | AA25: 0 | AB25: 0 | AC25: =AD25+AE25+AF25+AG25 -> 28516.6 | AD25: =VLOOKUP(A25,'[1]Pay sheet-APRIL- 2022'!$C$57:$AF$129,12,0) -> 17042.16 | AE25: =VLOOKUP(A25,'[1]Pay sheet-APRIL- 2022'!$C$57:$AF$129,13,0) -> 2083 | AF25: =VLOOKUP(A25,'[1]Pay sheet-APRIL- 2022'!$C$57:$AF$129,14,0) -> 2083 | AG25: =VLOOKUP(A25,'[1]Pay sheet-APRIL- 2022'!$C$57:$AF$129,15,0) -> 7308.44 | AH25: =Z25+AC25 -> 71122 | AI25: =VLOOKUP(A25,'[1]Pay sheet-APRIL- 2022'!$C$57:$AF$129,18,0) -> 1554.609 | AJ25: =VLOOKUP(A25,'[1]Pay sheet-APRIL- 2022'!$C$57:$AF$129,19,0) -> 2049.3197 | AK25: =VLOOKUP(A25,'[1]Pay sheet-APRIL- 2022'!$C$57:$AF$129,20,0) -> 3550.45 | AL25: =VLOOKUP(A25,'[1]Pay sheet-APRIL- 2022'!$C$57:$AF$129,22,0) -> 0 | AM25: =Z25+AD25+AE25+AF25+AG25+AI25+AJ25+AK25 -> 78276.379 | AN25: 0 | AO25: =VLOOKUP(A25,'[1]Pay sheet-APRIL- 2022'!$C$57:$AF$129,26,0) -> 1800 | AP25: =VLOOKUP(A25,'[1]Pay sheet-APRIL- 2022'!$C$57:$AF$129,25,0) -> 200 | AQ25: =VLOOKUP(A25,'[1]Pay sheet-APRIL- 2022'!$C$57:$AF$129,24,0) -> 0 | AR25: =VLOOKUP(A25,'[1]Pay sheet-APRIL- 2022'!$C$57:$AF$129,27,0) -> 283 | AS25: =SUM(AO25:AR25) -> 2283 | AT25: =AM25+AL25+-AS25 -> 75993.379 | AU25: 05.05.2022 | AV25: CITI Bank | AW25: 5696586708 | AY25: 63 | AZ25: 10
A26: BITS-686 | B26: Amit Kumar | C26: 31700 | D26: MALE | E26: Yadram | F26: Linux Administrator | G26: 525,Galli No.1,Sector 44,Chalera,Noida,Gowtham Budda nagar,Uttarpradesh 201301 | I26: OOO | J26: 525,Galli No.1,Sector 44,Chalera,Noida,Gowtham Budda nagar,Uttarpradesh 201301 | K26: OOO | L26: OOO | M26: OOO | N26: 44557 | S26: 100986290999 | T26: N/A | U26: Amit Kumar | V26: 30 | W26: =VLOOKUP(A26,'[1]Pay sheet-APRIL- 2022'!$C$57:$AF$129,10,0) -> 30 | X26: N/A | Y26: 94181 | Z26: =VLOOKUP(A26,'[1]Pay sheet-APRIL- 2022'!$C$57:$AF$129,11,0) -> 56508.6 | AA26: 0 | AB26: 0 | AC26: =AD26+AE26+AF26+AG26 -> 37785.4 | AD26: =VLOOKUP(A26,'[1]Pay sheet-APRIL- 2022'!$C$57:$AF$129,12,0) -> 22603.44 | AE26: =VLOOKUP(A26,'[1]Pay sheet-APRIL- 2022'!$C$57:$AF$129,13,0) -> 2083 | AF26: =VLOOKUP(A26,'[1]Pay sheet-APRIL- 2022'!$C$57:$AF$129,14,0) -> 2083 | AG26: =VLOOKUP(A26,'[1]Pay sheet-APRIL- 2022'!$C$57:$AF$129,15,0) -> 11015.96 | AH26: =Z26+AC26 -> 94294 | AI26: =VLOOKUP(A26,'[1]Pay sheet-APRIL- 2022'!$C$57:$AF$129,18,0) -> 1554.609 | AJ26: =VLOOKUP(A26,'[1]Pay sheet-APRIL- 2022'!$C$57:$AF$129,19,0) -> 2718.0637 | AK26: =VLOOKUP(A26,'[1]Pay sheet-APRIL- 2022'!$C$57:$AF$129,20,0) -> 4709.05 | AL26: =VLOOKUP(A26,'[1]Pay sheet-APRIL- 2022'!$C$57:$AF$129,22,0) -> 0 | AM26: =Z26+AD26+AE26+AF26+AG26+AI26+AJ26+AK26 -> 103275.72 | AN26: 0 | AO26: =VLOOKUP(A26,'[1]Pay sheet-APRIL- 2022'!$C$57:$AF$129,26,0) -> 1800 | AP26: =VLOOKUP(A26,'[1]Pay sheet-APRIL- 2022'!$C$57:$AF$129,25,0) -> 200 | AQ26: =VLOOKUP(A26,'[1]Pay sheet-APRIL- 2022'!$C$57:$AF$129,24,0) -> 0 | AR26: =VLOOKUP(A26,'[1]Pay sheet-APRIL- 2022'!$C$57:$AF$129,27,0) -> 283 | AS26: =SUM(AO26:AR26) -> 2283 | AT26: =AM26+AL26+-AS26 -> 100992.72 | AU26: 05.05.2022 | AV26: HDFC Bank | AW26: 05121140023169 | AY26: 64 | AZ26: 11
A27: BITS-688 | B27: Pranav Thakare | C27: 34393 | D27: MALE | E27: Pramod Motiram Thakare | F27: Project Manager | G27: B-78, State Employees Society,Ashoknagar,Satpur,Nashik | I27: OOO | J27: B-78, State Employees Society,Ashoknagar,Satpur,Nashik | K27: OOO | L27: OOO | M27: OOO | N27: 44564 | O27: OOO | P27: OOO | Q27: OOO | R27: OOO | S27: 100716206034 | T27: N/A | U27: Pranav Thakare | V27: 30 | W27: =VLOOKUP(A27,'[1]Pay sheet-APRIL- 2022'!$C$57:$AF$129,10,0) -> 27 | X27: N/A | Y27: 75643 | Z27: =VLOOKUP(A27,'[1]Pay sheet-APRIL- 2022'!$C$57:$AF$129,11,0) -> 40847.22 | AA27: 0 | AB27: 0 | AC27: =AD27+AE27+AF27+AG27 -> 27344.48 | AD27: =VLOOKUP(A27,'[1]Pay sheet-APRIL- 2022'!$C$57:$AF$129,12,0) -> 16338.888 | AE27: =VLOOKUP(A27,'[1]Pay sheet-APRIL- 2022'!$C$57:$AF$129,13,0) -> 1875 | AF27: =VLOOKUP(A27,'[1]Pay sheet-APRIL- 2022'!$C$57:$AF$129,14,0) -> 1875 | AG27: =VLOOKUP(A27,'[1]Pay sheet-APRIL- 2022'!$C$57:$AF$129,15,0) -> 7255.592 | AH27: =Z27+AC27 -> 68191.7 | AI27: =VLOOKUP(A27,'[1]Pay sheet-APRIL- 2022'!$C$57:$AF$129,18,0) -> 1554.609 | AJ27: =VLOOKUP(A27,'[1]Pay sheet-APRIL- 2022'!$C$57:$AF$129,19,0) -> 1964.7513 | AK27: =VLOOKUP(A27,'[1]Pay sheet-APRIL- 2022'!$C$57:$AF$129,20,0) -> 3403.935 | AL27: =VLOOKUP(A27,'[1]Pay sheet-APRIL- 2022'!$C$57:$AF$129,22,0) -> 0 | AM27: =Z27+AD27+AE27+AF27+AG27+AI27+AJ27+AK27 -> 75114.995 | AN27: 0 | AO27: =VLOOKUP(A27,'[1]Pay sheet-APRIL- 2022'!$C$57:$AF$129,26,0) -> 1800 | AP27: =VLOOKUP(A27,'[1]Pay sheet-APRIL- 2022'!$C$57:$AF$129,25,0) -> 200 | AQ27: =VLOOKUP(A27,'[1]Pay sheet-APRIL- 2022'!$C$57:$AF$129,24,0) -> 0 | AR27: =VLOOKUP(A27,'[1]Pay sheet-APRIL- 2022'!$C$57:$AF$129,27,0) -> 283 | AS27: =SUM(AO27:AR27) -> 2283 | AT27: =AM27+AL27+-AS27 -> 72831.995 | AU27: 05.05.2022 | AV27: ICICI BANK | AW27: 056601532765 | AY27: 65 | AZ27: 12
A28: BITS-694 | B28: Asita Kumar Sahoo | C28: 28308 | D28: MALE | E28: Dambarudar Sahoo | F28: Network Admin | G28: Airforce station, Achalgarh, Delwara, Abu road, Sirohi, Rajasthan 307501 | H28: OOO | I28: OOO | J28: Airforce station, Achalgarh, Delwara, Abu road, Sirohi, Rajasthan 307501 | K28: OOO | L28: OOO | M28: OOO | N28: 44567 | O28: OOO | P28: OOO | Q28: OOO | R28: OOO | S28: 100716206034 | T28: N/A | U28: Asita Kumar Sahoo | V28: 30 | W28: =VLOOKUP(A28,'[1]Pay sheet-APRIL- 2022'!$C$57:$AF$129,10,0) -> 30 | X28: N/A | Y28: 52471 | Z28: =VLOOKUP(A28,'[1]Pay sheet-APRIL- 2022'!$C$57:$AF$129,11,0) -> 31482.6 | AA28: 0 | AB28: 0 | AC28: =AD28+AE28+AF28+AG28 -> 21101.4 | AD28: =VLOOKUP(A28,'[1]Pay sheet-APRIL- 2022'!$C$57:$AF$129,12,0) -> 12593.04 | AE28: =VLOOKUP(A28,'[1]Pay sheet-APRIL- 2022'!$C$57:$AF$129,13,0) -> 2083 | AF28: =VLOOKUP(A28,'[1]Pay sheet-APRIL- 2022'!$C$57:$AF$129,14,0) -> 2083 | AG28: =VLOOKUP(A28,'[1]Pay sheet-APRIL- 2022'!$C$57:$AF$129,15,0) -> 4342.36 | AH28: =Z28+AC28 -> 52584 | AI28: =VLOOKUP(A28,'[1]Pay sheet-APRIL- 2022'!$C$57:$AF$129,18,0) -> 1554.609 | AJ28: =VLOOKUP(A28,'[1]Pay sheet-APRIL- 2022'!$C$57:$AF$129,19,0) -> 1514.3131 | AK28: =VLOOKUP(A28,'[1]Pay sheet-APRIL- 2022'!$C$57:$AF$129,20,0) -> 2623.55 | AL28: =VLOOKUP(A28,'[1]Pay sheet-APRIL- 2022'!$C$57:$AF$129,22,0) -> 0 | AM28: =Z28+AD28+AE28+AF28+AG28+AI28+AJ28+AK28 -> 58276.472 | AN28: 0 | AO28: =VLOOKUP(A28,'[1]Pay sheet-APRIL- 2022'!$C$57:$AF$129,26,0) -> 1800 | AP28: =VLOOKUP(A28,'[1]Pay sheet-APRIL- 2022'!$C$57:$AF$129,25,0) -> 200 | AQ28: =VLOOKUP(A28,'[1]Pay sheet-APRIL- 2022'!$C$57:$AF$129,24,0) -> 0 | AR28: =VLOOKUP(A28,'[1]Pay sheet-APRIL- 2022'!$C$57:$AF$129,27,0) -> 283 | AS28: =SUM(AO28:AR28) -> 2283 | AT28: =AM28+AL28+-AS28 -> 55993.472 | AU28: 05.05.2022 | AV28: ICICI BANK | AW28: 056601532765 | AY28: 66 | AZ28: 13
A29: BITS-706 | B29: Arun Arra | C29: 34378 | D29: MALE | E29: Anjam Raju | F29: SAP Basis consultant | G29: 1-52/3, Suryanager Colony, Uppal, HYD 500039 | H29: OOO | I29: OOO | J29: H.No: 2-3-226, Dubbawada, Metpally, 505325 | K29: OOO | L29: OOO | M29: OOO | N29: 44602 | O29: OOO | P29: OOO | Q29: OOO | R29: OOO | S29: 101377758010 | T29: N/A | U29: Arun Arra | V29: 30 | W29: =VLOOKUP(A29,'[1]Pay sheet-APRIL- 2022'!$C$57:$AF$129,10,0) -> 30 | X29: N/A | Y29: 38567 | Z29: =VLOOKUP(A29,'[1]Pay sheet-APRIL- 2022'!$C$57:$AF$129,11,0) -> 23140.2 | AA29: 0 | AB29: 0 | AC29: =AD29+AE29+AF29+AG29 -> 15539.8 | AD29: =VLOOKUP(A29,'[1]Pay sheet-APRIL- 2022'!$C$57:$AF$129,12,0) -> 9256.08 | AE29: =VLOOKUP(A29,'[1]Pay sheet-APRIL- 2022'!$C$57:$AF$129,13,0) -> 2083 | AF29: =VLOOKUP(A29,'[1]Pay sheet-APRIL- 2022'!$C$57:$AF$129,14,0) -> 2083 | AG29: =VLOOKUP(A29,'[1]Pay sheet-APRIL- 2022'!$C$57:$AF$129,15,0) -> 2117.72 | AH29: =Z29+AC29 -> 38680 | AI29: =VLOOKUP(A29,'[1]Pay sheet-APRIL- 2022'!$C$57:$AF$129,18,0) -> 1554.609 | AJ29: =VLOOKUP(A29,'[1]Pay sheet-APRIL- 2022'!$C$57:$AF$129,19,0) -> 1113.0436 | AK29: =VLOOKUP(A29,'[1]Pay sheet-APRIL- 2022'!$C$57:$AF$129,20,0) -> 1928.35 | AL29: =VLOOKUP(A29,'[1]Pay sheet-APRIL- 2022'!$C$57:$AF$129,22,0) -> 0 | AM29: =Z29+AD29+AE29+AF29+AG29+AI29+AJ29+AK29 -> 43276.003 | AO29: =VLOOKUP(A29,'[1]Pay sheet-APRIL- 2022'!$C$57:$AF$129,26,0) -> 1800 | AP29: =VLOOKUP(A29,'[1]Pay sheet-APRIL- 2022'!$C$57:$AF$129,25,0) -> 200 | AQ29: =VLOOKUP(A29,'[1]Pay sheet-APRIL- 2022'!$C$57:$AF$129,24,0) -> 0 | AR29: =VLOOKUP(A29,'[1]Pay sheet-APRIL- 2022'!$C$57:$AF$129,27,0) -> 283 | AS29: =SUM(AO29:AR29) -> 2283 | AT29: =AM29+AL29+-AS29 -> 40993.003 | AU29: 05.05.2022 | AV29: SBI | AW29: A/C No : 32523021338, | AY29: 67 | AZ29: 14
A30: BITS-707 | B30: Ramya Nalla | C30: 22-03-1998 | D30: FEMALE | E30: W/O Chitharanjan Allem | F30: SAP Basis consultant | G30: C-101, Akruthi Arcade, Anand Nagar, GB road, Thane West, Mumbai, Maharashtra,400615 | H30: OOO | I30: OOO | J30: C-101, Akruthi Arcade, Anand Nagar, GB road, Thane West, Mumbai, Maharashtra,400615 | K30: OOO | L30: OOO | M30: OOO | N30: 10/2/2022 | O30: OOO | P30: OOO | Q30: OOO | R30: OOO | S30: 10179269235 | T30: N/A | U30: Ramya Nalla | V30: 30 | W30: =VLOOKUP(A30,'[1]Pay sheet-APRIL- 2022'!$C$57:$AF$129,10,0) -> 30 | X30: N/A | Y30: 38567 | Z30: =VLOOKUP(A30,'[1]Pay sheet-APRIL- 2022'!$C$57:$AF$129,11,0) -> 23140.2 | AA30: 0 | AB30: 0 | AC30: =AD30+AE30+AF30+AG30 -> 15539.8 | AD30: =VLOOKUP(A30,'[1]Pay sheet-APRIL- 2022'!$C$57:$AF$129,12,0) -> 9256.08 | AE30: =VLOOKUP(A30,'[1]Pay sheet-APRIL- 2022'!$C$57:$AF$129,13,0) -> 2083 | AF30: =VLOOKUP(A30,'[1]Pay sheet-APRIL- 2022'!$C$57:$AF$129,14,0) -> 2083 | AG30: =VLOOKUP(A30,'[1]Pay sheet-APRIL- 2022'!$C$57:$AF$129,15,0) -> 2117.72 | AH30: =Z30+AC30 -> 38680 | AI30: =VLOOKUP(A30,'[1]Pay sheet-APRIL- 2022'!$C$57:$AF$129,18,0) -> 1554.609 | AJ30: =VLOOKUP(A30,'[1]Pay sheet-APRIL- 2022'!$C$57:$AF$129,19,0) -> 1113.0436 | AK30: =VLOOKUP(A30,'[1]Pay sheet-APRIL- 2022'!$C$57:$AF$129,20,0) -> 1928.35 | AL30: =VLOOKUP(A30,'[1]Pay sheet-APRIL- 2022'!$C$57:$AF$129,22,0) -> 0 | AM30: =Z30+AD30+AE30+AF30+AG30+AI30+AJ30+AK30 -> 43276.003 | AO30: =VLOOKUP(A30,'[1]Pay sheet-APRIL- 2022'!$C$57:$AF$129,26,0) -> 1800 | AP30: =VLOOKUP(A30,'[1]Pay sheet-APRIL- 2022'!$C$57:$AF$129,25,0) -> 200 | AQ30: =VLOOKUP(A30,'[1]Pay sheet-APRIL- 2022'!$C$57:$AF$129,24,0) -> 0 | AR30: =VLOOKUP(A30,'[1]Pay sheet-APRIL- 2022'!$C$57:$AF$129,27,0) -> 283 | AS30: =SUM(AO30:AR30) -> 2283 | AT30: =AM30+AL30+-AS30 -> 40993.003 | AU30: 05.05.2022 | AV30: SBI | AW30: A/C no: 37660478448 | AY30: 68 | AZ30: 15
A31: BITS-709 | B31: Uma Mahesh P | C31: 35748 | D31: MALE | E31: PENTAKOTA LAKSHI | F31: SAP Basis consultant | G31: D.NO: 1-1 , PENTAKOTA VARI STREET , CHUCHUKONDA (VILLAGE),MUNAGAPAKA (MANDAL),VISHAKAPATNAM(DISTRICT),PIN CODE:531055 | H31: OOO | I31: OOO | J31: D.NO: 1-1 , PENTAKOTA VARI STREET , CHUCHUKONDA(VILLAGE),MUNAGAPAKA(MANDAL),VISHAKAPATNAM(DISTRICT),PINCODE:531055 | K31: OOO | L31: OOO | M31: OOO | N31: 10/2/2022 | O31: OOO | P31: OOO | Q31: OOO | R31: OOO | S31: 101792969226 | T31: N/A | U31: Uma Mahesh P | V31: 30 | W31: =VLOOKUP(A31,'[1]Pay sheet-APRIL- 2022'!$C$57:$AF$129,10,0) -> 29 | X31: N/A | Y31: 38567 | Z31: =VLOOKUP(A31,'[1]Pay sheet-APRIL- 2022'!$C$57:$AF$129,11,0) -> 22368.86 | AA31: 0 | AB31: 0 | AC31: =AD31+AE31+AF31+AG31 -> 15025.573 | AD31: =VLOOKUP(A31,'[1]Pay sheet-APRIL- 2022'!$C$57:$AF$129,12,0) -> 8947.544 | AE31: =VLOOKUP(A31,'[1]Pay sheet-APRIL- 2022'!$C$57:$AF$129,13,0) -> 2014 | AF31: =VLOOKUP(A31,'[1]Pay sheet-APRIL- 2022'!$C$57:$AF$129,14,0) -> 2014 | AG31: =VLOOKUP(A31,'[1]Pay sheet-APRIL- 2022'!$C$57:$AF$129,15,0) -> 2050.0293 | AH31: =Z31+AC31 -> 37394.433 | AI31: =VLOOKUP(A31,'[1]Pay sheet-APRIL- 2022'!$C$57:$AF$129,18,0) -> 1554.609 | AJ31: =VLOOKUP(A31,'[1]Pay sheet-APRIL- 2022'!$C$57:$AF$129,19,0) -> 1075.9422 | AK31: =VLOOKUP(A31,'[1]Pay sheet-APRIL- 2022'!$C$57:$AF$129,20,0) -> 1864.0717 | AL31: =VLOOKUP(A31,'[1]Pay sheet-APRIL- 2022'!$C$57:$AF$129,22,0) -> 0 | AM31: =Z31+AD31+AE31+AF31+AG31+AI31+AJ31+AK31 -> 41889.056 | AO31: =VLOOKUP(A31,'[1]Pay sheet-APRIL- 2022'!$C$57:$AF$129,26,0) -> 1800 | AP31: =VLOOKUP(A31,'[1]Pay sheet-APRIL- 2022'!$C$57:$AF$129,25,0) -> 200 | AQ31: =VLOOKUP(A31,'[1]Pay sheet-APRIL- 2022'!$C$57:$AF$129,24,0) -> 0 | AR31: =VLOOKUP(A31,'[1]Pay sheet-APRIL- 2022'!$C$57:$AF$129,27,0) -> 283 | AS31: =SUM(AO31:AR31) -> 2283 | AT31: =AM31+AL31+-AS31 -> 39606.056 | AU31: 05.05.2022 | AV31: HDFC BANK | AW31: A/C NO 50100444213458 | AY31: 70 | AZ31: 16
A32: BITS-713 | B32: NAGA SAI TEJA NUTHI | C32: 33292 | D32: MALE | E32: G seshaiah | F32: SAP Basis consultant | G32: Hno 15-21-237/1,Flat no G2,sattenapally towers,Balaji Nagar,Kukatpally,Hyderabad,500072 | H32: OOOO | I32: OOOO | J32: Hno 15-21-237/1,Flat no G2,sattenapally towers,Balaji Nagar,Kukatpally,Hyderabad,500072 | K32: OOOO | L32: OOOO | M32: OOOO | N32: 44602 | O32: OOO | P32: OOO | Q32: OOO | R32: OOO | S32: 101756843175 | T32: N/A | U32: NAGA SAI TEJA NUTHI | V32: 30 | W32: =VLOOKUP(A32,'[1]Pay sheet-APRIL- 2022'!$C$57:$AF$129,10,0) -> 27 | X32: N/A | Y32: 43202 | Z32: =VLOOKUP(A32,'[1]Pay sheet-APRIL- 2022'!$C$57:$AF$129,11,0) -> 23329.08 | AA32: 0 | AB32: 0 | AC32: =AD32+AE32+AF32+AG32 -> 15665.72 | AD32: =VLOOKUP(A32,'[1]Pay sheet-APRIL- 2022'!$C$57:$AF$129,12,0) -> 9331.632 | AE32: =VLOOKUP(A32,'[1]Pay sheet-APRIL- 2022'!$C$57:$AF$129,13,0) -> 1875 | AF32: =VLOOKUP(A32,'[1]Pay sheet-APRIL- 2022'!$C$57:$AF$129,14,0) -> 1875 | AG32: =VLOOKUP(A32,'[1]Pay sheet-APRIL- 2022'!$C$57:$AF$129,15,0) -> 2584.088 | AH32: =Z32+AC32 -> 38994.8 | AI32: =VLOOKUP(A32,'[1]Pay sheet-APRIL- 2022'!$C$57:$AF$129,18,0) -> 1554.609 | AJ32: =VLOOKUP(A32,'[1]Pay sheet-APRIL- 2022'!$C$57:$AF$129,19,0) -> 1122.1287 | AK32: =VLOOKUP(A32,'[1]Pay sheet-APRIL- 2022'!$C$57:$AF$129,20,0) -> 1944.09 | AL32: =VLOOKUP(A32,'[1]Pay sheet-APRIL- 2022'!$C$57:$AF$129,22,0) -> 0 | AM32: =Z32+AD32+AE32+AF32+AG32+AI32+AJ32+AK32 -> 43615.628 | AO32: =VLOOKUP(A32,'[1]Pay sheet-APRIL- 2022'!$C$57:$AF$129,26,0) -> 1800 | AP32: =VLOOKUP(A32,'[1]Pay sheet-APRIL- 2022'!$C$57:$AF$129,25,0) -> 200 | AQ32: =VLOOKUP(A32,'[1]Pay sheet-APRIL- 2022'!$C$57:$AF$129,24,0) -> 0 | AR32: =VLOOKUP(A32,'[1]Pay sheet-APRIL- 2022'!$C$57:$AF$129,27,0) -> 283 | AS32: =SUM(AO32:AR32) -> 2283 | AT32: =AM32+AL32+-AS32 -> 41332.628 | AU32: 05.05.2022 | AV32: SBI | AW32: A/C NO 20297714176 | AY32: 74 | AZ32: 17
A33: BITS-714 | B33: Mani Krishna Nandineedi | C33: 35088 | D33: MALE | E33: N Srinivasu | F33: SAP Basis consultant | G33: 204-7-343, Nagireddy Nagar, Near Three temples | H33: OOOO | I33: OOOO | J33: 3-542, 10th street RK Nagar, Rajahmundry 533107 | K33: OOOO | L33: OOOO | M33: OOOO | N33: 44602 | O33: OOO | P33: OOO | Q33: OOO | R33: OOO | S33: 101589884490 | T33: N/A | U33: Mani Krishna Nandineedi | V33: 30 | W33: =VLOOKUP(A33,'[1]Pay sheet-APRIL- 2022'!$C$57:$AF$129,10,0) -> 30 | X33: N/A | Y33: 38567 | Z33: =VLOOKUP(A33,'[1]Pay sheet-APRIL- 2022'!$C$57:$AF$129,11,0) -> 23140.2 | AA33: 0 | AB33: 0 | AC33: =AD33+AE33+AF33+AG33 -> 15539.8 | AD33: =VLOOKUP(A33,'[1]Pay sheet-APRIL- 2022'!$C$57:$AF$129,12,0) -> 9256.08 | AE33: =VLOOKUP(A33,'[1]Pay sheet-APRIL- 2022'!$C$57:$AF$129,13,0) -> 2083 | AF33: =VLOOKUP(A33,'[1]Pay sheet-APRIL- 2022'!$C$57:$AF$129,14,0) -> 2083 | AG33: =VLOOKUP(A33,'[1]Pay sheet-APRIL- 2022'!$C$57:$AF$129,15,0) -> 2117.72 | AH33: =Z33+AC33 -> 38680 | AI33: =VLOOKUP(A33,'[1]Pay sheet-APRIL- 2022'!$C$57:$AF$129,18,0) -> 1554.609 | AJ33: =VLOOKUP(A33,'[1]Pay sheet-APRIL- 2022'!$C$57:$AF$129,19,0) -> 1113.0436 | AK33: =VLOOKUP(A33,'[1]Pay sheet-APRIL- 2022'!$C$57:$AF$129,20,0) -> 1928.35 | AL33: =VLOOKUP(A33,'[1]Pay sheet-APRIL- 2022'!$C$57:$AF$129,22,0) -> 0 | AM33: =Z33+AD33+AE33+AF33+AG33+AI33+AJ33+AK33 -> 43276.003 | AO33: =VLOOKUP(A33,'[1]Pay sheet-APRIL- 2022'!$C$57:$AF$129,26,0) -> 1800 | AP33: =VLOOKUP(A33,'[1]Pay sheet-APRIL- 2022'!$C$57:$AF$129,25,0) -> 200 | AQ33: =VLOOKUP(A33,'[1]Pay sheet-APRIL- 2022'!$C$57:$AF$129,24,0) -> 0 | AR33: =VLOOKUP(A33,'[1]Pay sheet-APRIL- 2022'!$C$57:$AF$129,27,0) -> 283 | AS33: =SUM(AO33:AR33) -> 2283 | AT33: =AM33+AL33+-AS33 -> 40993.003 | AU33: 05.05.2022 | AV33: HDFC BANK | AW33: A/C NO 50100360114888 | AY33: 75 | AZ33: 18
A34: BITS-715 | B34: Sushma P | C34: 32638 | D34: FEMALE | E34: Veeraswamy | F34: SAP Basis consultant | G34: H No 5-11/1, Janakipuram, bonakal,Khammam, Telangana 507204 | H34: OOOO | I34: OOOO | J34: H No 5-11/1, Janakipuram, bonakal,Khammam, Telangana 507204 | K34: OOOO | L34: OOOO | M34: OOOO | N34: 44602 | O34: OOO | P34: OOO | Q34: OOO | R34: OOO | S34: 100542320584 | T34: N/A | U34: Sushma P | V34: 30 | W34: =VLOOKUP(A34,'[1]Pay sheet-APRIL- 2022'!$C$57:$AF$129,10,0) -> 30 | X34: N/A | Y34: 38567 | Z34: =VLOOKUP(A34,'[1]Pay sheet-APRIL- 2022'!$C$57:$AF$129,11,0) -> 23140.2 | AA34: 0 | AB34: 0 | AC34: =AD34+AE34+AF34+AG34 -> 15539.8 | AD34: =VLOOKUP(A34,'[1]Pay sheet-APRIL- 2022'!$C$57:$AF$129,12,0) -> 9256.08 | AE34: =VLOOKUP(A34,'[1]Pay sheet-APRIL- 2022'!$C$57:$AF$129,13,0) -> 2083 | AF34: =VLOOKUP(A34,'[1]Pay sheet-APRIL- 2022'!$C$57:$AF$129,14,0) -> 2083 | AG34: =VLOOKUP(A34,'[1]Pay sheet-APRIL- 2022'!$C$57:$AF$129,15,0) -> 2117.72 | AH34: =Z34+AC34 -> 38680 | AI34: =VLOOKUP(A34,'[1]Pay sheet-APRIL- 2022'!$C$57:$AF$129,18,0) -> 1554.609 | AJ34: =VLOOKUP(A34,'[1]Pay sheet-APRIL- 2022'!$C$57:$AF$129,19,0) -> 1113.0436 | AK34: =VLOOKUP(A34,'[1]Pay sheet-APRIL- 2022'!$C$57:$AF$129,20,0) -> 1928.35 | AL34: =VLOOKUP(A34,'[1]Pay sheet-APRIL- 2022'!$C$57:$AF$129,22,0) -> 0 | AM34: =Z34+AD34+AE34+AF34+AG34+AI34+AJ34+AK34 -> 43276.003 | AO34: =VLOOKUP(A34,'[1]Pay sheet-APRIL- 2022'!$C$57:$AF$129,26,0) -> 1800 | AP34: =VLOOKUP(A34,'[1]Pay sheet-APRIL- 2022'!$C$57:$AF$129,25,0) -> 200 | AQ34: =VLOOKUP(A34,'[1]Pay sheet-APRIL- 2022'!$C$57:$AF$129,24,0) -> 0 | AR34: =VLOOKUP(A34,'[1]Pay sheet-APRIL- 2022'!$C$57:$AF$129,27,0) -> 283 | AS34: =SUM(AO34:AR34) -> 2283 | AT34: =AM34+AL34+-AS34 -> 40993.003 | AU34: 05.05.2022 | AV34: SBI | AW34: A/C NO 62111073370 | AY34: 76 | AZ34: 19
A35: BITS-741 | B35: susheelKumar Gandla | C35: 30056 | D35: MALE | E35: Narayana Gandla | F35: Sr.Software Engineer | G35: Flat no.308,Block A,Akruthi srinivasan Appts,Balaji nagar,Road.3,Nizampet,Hyderabad,TS 500090 | I35: OOOO | J35: Flat no.308,Block A,Akruthi srinivasan Appts,Balaji nagar,Road.3,Nizampet,Hyderabad,TS 500090 | K35: OOOO | L35: OOOO | M35: OOOO | N35: 44652 | O35: OOOO | P35: OOOO | Q35: OOOO | R35: OOOO | S35: N/A | T35: N/A | U35: susheelKumar Gabndla | V35: 30 | W35: =VLOOKUP(A35,'[1]Pay sheet-APRIL- 2022'!$C$57:$AF$129,10,0) -> 30 | X35: N/A | Y35: =AH35/W35*31 -> 83070.7 | Z35: =VLOOKUP(A35,'[1]Pay sheet-APRIL- 2022'!$C$57:$AF$129,11,0) -> 48166.8 | AA35: 0 | AB35: 0 | AC35: =AD35+AE35+AF35+AG35 -> 32224.2 | AD35: =VLOOKUP(A35,'[1]Pay sheet-APRIL- 2022'!$C$57:$AF$129,12,0) -> 19266.72 | AE35: =VLOOKUP(A35,'[1]Pay sheet-APRIL- 2022'!$C$57:$AF$129,13,0) -> 2083 | AF35: =VLOOKUP(A35,'[1]Pay sheet-APRIL- 2022'!$C$57:$AF$129,14,0) -> 2083 | AG35: =VLOOKUP(A35,'[1]Pay sheet-APRIL- 2022'!$C$57:$AF$129,15,0) -> 8791.48 | AH35: =Z35+AC35 -> 80391 | AI35: =VLOOKUP(A35,'[1]Pay sheet-APRIL- 2022'!$C$57:$AF$129,18,0) -> 1554.609 | AJ35: =VLOOKUP(A35,'[1]Pay sheet-APRIL- 2022'!$C$57:$AF$129,19,0) -> 2316.8231 | AK35: =VLOOKUP(A35,'[1]Pay sheet-APRIL- 2022'!$C$57:$AF$129,20,0) -> 4013.9 | AL35: =VLOOKUP(A35,'[1]Pay sheet-APRIL- 2022'!$C$57:$AF$129,22,0) -> 0 | AM35: =Z35+AD35+AE35+AF35+AG35+AI35+AJ35+AK35 -> 88276.332 | AO35: =VLOOKUP(A35,'[1]Pay sheet-APRIL- 2022'!$C$57:$AF$129,26,0) -> 0 | AP35: =VLOOKUP(A35,'[1]Pay sheet-APRIL- 2022'!$C$57:$AF$129,25,0) -> 200 | AQ35: =VLOOKUP(A35,'[1]Pay sheet-APRIL- 2022'!$C$57:$AF$129,24,0) -> 0 | AR35: =VLOOKUP(A35,'[1]Pay sheet-APRIL- 2022'!$C$57:$AF$129,27,0) -> 0 | AS35: =SUM(AO35:AR35) -> 200 | AT35: =AM35+AL35+-AS35 -> 88076.332 | AU35: 05.05.2022 | AV35: ICICI BANK | AW35: A/C NO 007601548378 | AY35: 77 | AZ35: 20
W36: =SUM(W16:W35) -> 591 | Z36: =SUM(Z16:Z35) -> 792977.48 | AA36: =SUM(AA16:AA35) -> 0 | AB36: =SUM(AB16:AB35) -> 0 | AC36: =SUM(AC16:AC35) -> 530911.65 | AD36: =SUM(AD16:AD35) -> 317190.99 | AE36: =SUM(AE16:AE35) -> 41036 | AF36: =SUM(AF16:AF35) -> 41036 | AG36: =SUM(AG16:AG35) -> 131648.66 | ... AK36: =SUM(AK16:AK35) -> 66081.457 | AL36: 0 | AM36: =SUM(AM16:AM35) -> 1459205 | AN36: =SUM(AN16:AN35) -> 0 | AO36: =SUM(AO16:AO35) -> 34200 | AP36: =SUM(AP16:AP35) -> 4000 | AQ36: =SUM(AQ16:AQ35) -> 0 | AR36: =SUM(AR16:AR35) -> 5291 | AS36: =SUM(AS16:AS35) -> 43491 | AT36: =SUM(AT16:AT35) -> 1415714
C48: 30222 | D48: MALE | E48: Brijou Gopalan Koipurath | G48: 1753,Jayaram colony,Behind Holy family,Vidyanagar,Karad district Satara,Maharastra 415124 | J48: F-803,Mount Vert Vesta,Urawade,Pirangut,Pune 412108 | N48: 44390 | S48: 100142924932 | T48: N/A | U48: =B48 -> 0 | V48: 31 | W48: =VLOOKUP(A48,'[2]Pay sheet-MARCH- 2022'!$C$34:$AF$122,10,0) -> #N/A | X48: N/A | Y48: 100670 | Z48: =VLOOKUP(A48,'[2]Pay sheet-MARCH- 2022'!$C$34:$AF$122,11,0) -> #N/A | AA48: 0 | AB48: 0 | AC48: =AD48+AE48+AF48+AG48 -> #N/A | AD48: =VLOOKUP(A48,'[2]Pay sheet-MARCH- 2022'!$C$34:$AF$122,12,0) -> #N/A | AE48: =VLOOKUP(A48,'[2]Pay sheet-MARCH- 2022'!$C$34:$AF$122,13,0) -> #N/A | AF48: =VLOOKUP(A48,'[2]Pay sheet-MARCH- 2022'!$C$34:$AF$122,14,0) -> #N/A | AY48: 52 | AZ48: 1
C49: 33172 | D49: MALE | E49: SYED MOHAMMED NASEER | G49: 11-5-205 Flat No 202 2nd Floor Beside Red Hills Poly Clinic Nampally Hyderabad , Telangana - 500 004 | H49: OOO | I49: OOO | J49: 11-5-205 Flat No 202 2nd Floor Beside Red Hills Poly Clinic Nampally Hyderabad , Telangana - 500 004 | K49: OOO | L49: OOO | M49: OOO | N49: 10/2/2022 | O49: OOO | P49: OOO | Q49: OOO | R49: OOO | S49: 101081477079 | T49: N/A | U49: SYED MOHAMMED AZHER | V49: 31 | W49: =VLOOKUP(A49,'[2]Pay sheet-MARCH- 2022'!$C$34:$AF$122,10,0) -> #N/A | X49: N/A | Y49: 38567 | Z49: =VLOOKUP(A49,'[2]Pay sheet-MARCH- 2022'!$C$34:$AF$122,11,0) -> #N/A | AA49: 0 | AB49: 0 | AC49: =AD49+AE49+AF49+AG49 -> #N/A | AD49: =VLOOKUP(A49,'[2]Pay sheet-MARCH- 2022'!$C$34:$AF$122,12,0) -> #N/A | AE49: =VLOOKUP(A49,'[2]Pay sheet-MARCH- 2022'!$C$34:$AF$122,13,0) -> #N/A | AF49: =VLOOKUP(A49,'[2]Pay sheet-MARCH- 2022'!$C$34:$AF$122,14,0) -> #N/A | AY49: 69 | AZ49: 17
C50: 35895 | D50: MALE | E50: GONTHINI SATTIBABU | G50: Falt: 202, Pecan Creek,Plot 790, Road no 4c, Gopal Nagar, Gokul Enclave, Venkata Ramana Colony, Kukatpally, Hyderabad, Telangana 500085, India | H50: OOO | I50: OOO | J50: D.NO: 4-65, YADAGIRIPALEM VILLAGE, MELUPAKA POST, MUNAGAPAKA MANDAL, VISAKHAPATNAM, A.P. PINCODE -531055. | K50: OOO | L50: OOO | M50: OOO | N50: 10-2-2022 | O50: OOO | P50: OOO | Q50: OOO | R50: OOO | S50: 101478192192 | T50: N/A | U50: GONTHINI SAIBABU | V50: 31 | W50: =VLOOKUP(A50,'[2]Pay sheet-MARCH- 2022'!$C$34:$AF$122,10,0) -> #N/A | X50: N/A | Y50: 38567 | Z50: =VLOOKUP(A50,'[2]Pay sheet-MARCH- 2022'!$C$34:$AF$122,11,0) -> #N/A | AA50: 0 | AB50: 0 | AC50: =AD50+AE50+AF50+AG50 -> #N/A | AD50: =VLOOKUP(A50,'[2]Pay sheet-MARCH- 2022'!$C$34:$AF$122,12,0) -> #N/A | AE50: =VLOOKUP(A50,'[2]Pay sheet-MARCH- 2022'!$C$34:$AF$122,13,0) -> #N/A | AF50: =VLOOKUP(A50,'[2]Pay sheet-MARCH- 2022'!$C$34:$AF$122,14,0) -> #N/A | AY50: 71 | AZ50: 19
C51: 36086 | D51: MALE | E51: TATINA PULLARAO | G51: Dr no:1-73,near high school,lingapalem,west godavari district-534462 | J51: Dr no:1-73,near high school,lingapalem,west godavari district-534462 | K51: OOO | L51: OOO | M51: OOO | N51: 44602 | O51: OOO | P51: OOO | Q51: OOO | R51: OOO | S51: 101793033196 | T51: N/A | U51: Pavan Nagendra Tatina | V51: 31 | W51: =VLOOKUP(A51,'[2]Pay sheet-MARCH- 2022'!$C$34:$AF$122,10,0) -> #N/A | X51: N/A | Y51: 29298 | Z51: =VLOOKUP(A51,'[2]Pay sheet-MARCH- 2022'!$C$34:$AF$122,11,0) -> #N/A | AA51: 0 | AB51: 0 | AC51: =AD51+AE51+AF51+AG51 -> #N/A | AD51: =VLOOKUP(A51,'[2]Pay sheet-MARCH- 2022'!$C$34:$AF$122,12,0) -> #N/A | AE51: =VLOOKUP(A51,'[2]Pay sheet-MARCH- 2022'!$C$34:$AF$122,13,0) -> #N/A | AF51: =VLOOKUP(A51,'[2]Pay sheet-MARCH- 2022'!$C$34:$AF$122,14,0) -> #N/A | AY51: 72 | AZ51: 20
C52: 31019 | D52: MALE | E52: Mohd Mazhar Shareer | G52: 4-3-90/1,Attapur,Kanganagar,Near SNR function hall,Pillar no 123,Hyderabad,TS 500048 | H52: OOOO | I52: OOOO | J52: 4-3-90/1,Attapur,Kanganagar,Near SNR function hall,Pillar no 123,Hyderabad,TS 500048 | K52: OOOO | L52: OOOO | M52: OOOO | N52: 44602 | O52: OOO | P52: OOO | Q52: OOO | R52: OOO | S52: OOO | T52: N/A | U52: Mohd Azhar Shareef | V52: 31 | W52: =VLOOKUP(A52,'[2]Pay sheet-MARCH- 2022'!$C$34:$AF$122,10,0) -> #N/A | X52: N/A | Y52: 38567 | Z52: =VLOOKUP(A52,'[2]Pay sheet-MARCH- 2022'!$C$34:$AF$122,11,0) -> #N/A | AA52: 0 | AB52: 0 | AC52: =AD52+AE52+AF52+AG52 -> #N/A | AD52: =VLOOKUP(A52,'[2]Pay sheet-MARCH- 2022'!$C$34:$AF$122,12,0) -> #N/A | AE52: =VLOOKUP(A52,'[2]Pay sheet-MARCH- 2022'!$C$34:$AF$122,13,0) -> #N/A | AF52: =VLOOKUP(A52,'[2]Pay sheet-MARCH- 2022'!$C$34:$AF$122,14,0) -> #N/A | AY52: 73 | AZ52: 21

Sheet 04-22Eq Remu
A1: Form D
A2: (See rule 6)
A4: Register to be maintained by the employer under rule 6 of the Equal Remuneration Rules, 1976
D6: ='0422Master'!D10 -> 44652
A8: Name and address of Contractor : | F8: ='0422Master'!F5 -> Burgeon IT Services Pvt.Ltd.
A10: Name and address of establishment in/under which contract is carried on : | F10: ='0422Master'!AP5 -> Burgeon IT Services Pvt.Ltd.
F11: ='0422Master'!AP6 -> Siri Mansion LIGB 436 Dr.A S Rao Nagar,Hyderabad
A12: Name and address of Principal Employer : | F12: ='0422Master'!AP10 -> INFOSYS LTD.IL Pune SEZ Unit-II,Plot No. 24/3
F13: ='0422Master'!AP11 -> Rajiv gandhi Info tech park,Village Mann,Pune,Maharashtra 411057
A14: Total number of men workers employed | C14: =D40 -> 16
A16: Total number of women workers employed | C16: =C40 -> 4
C18: Components of remuneration
A19: Category of workers | B19: Brief Description of work | C19: No of women employed | D19: No. of men employed | E19: Rate or remuneration paid | F19: Basic wage & Dearness Allowance | G19: House Rent allowance | H19: Other allowances | I19: Cash value of concessional supply of essential commodities | J19: Name of the Client | K19: Primary Work Place/ Location
A20: ='0422Master'!F16 -> Network Security Admin | B20: IT SUPPORTIVE SERICE | C20: 0 | D20: 1 | E20: ='0422Master'!AM16 -> 88276.332 | F20: ='0422Master'!Z16 -> 48166.8 | G20: ='0422Master'!AD16 -> 19266.72 | H20: =E20-(F20+G20) -> 20842.812 | I20: 0 | K20: SEZ UNIT-II
A21: ='0422Master'!F17 -> Infrastructure Lead | B21: IT SUPPORTIVE SERICE | C21: 0 | D21: 1 | E21: ='0422Master'!AM17 -> 156275.8 | F21: ='0422Master'!Z17 -> 85984.2 | G21: ='0422Master'!AD17 -> 34393.68 | H21: =E21-(F21+G21) -> 35897.919 | I21: 0
A22: ='0422Master'!F18 -> ASSISTANT PROJECT MANAGER | B22: IT SUPPORTIVE SERICE | C22: 1 | D22: 0 | E22: ='0422Master'!AM18 -> 61275.703 | F22: ='0422Master'!Z18 -> 33150.6 | G22: ='0422Master'!AD18 -> 13260.24 | H22: =E22-(F22+G22) -> 14864.863 | I22: 0
A23: ='0422Master'!F19 -> Project Manager | B23: IT SUPPORTIVE SERICE | C23: 0 | D23: 1 | E23: ='0422Master'!AM19 -> 114275.78 | F23: ='0422Master'!Z19 -> 62626.2 | G23: ='0422Master'!AD19 -> 25050.48 | H23: =E23-(F23+G23) -> 26599.099 | I23: 0
A24: ='0422Master'!F20 -> Project Manager | B24: IT SUPPORTIVE SERICE | C24: 0 | D24: 1 | E24: ='0422Master'!AM20 -> 73275.863 | F24: ='0422Master'!Z20 -> 39824.4 | G24: ='0422Master'!AD20 -> 15929.76 | H24: =E24-(F24+G24) -> 17521.703 | I24: 0
A25: ='0422Master'!F21 -> Sr.Software Engineer | B25: IT SUPPORTIVE SERICE | C25: 0 | D25: 1 | E25: ='0422Master'!AM21 -> 88276.332 | F25: ='0422Master'!Z21 -> 48166.8 | G25: ='0422Master'!AD21 -> 19266.72 | H25: =E25-(F25+G25) -> 20842.812 | I25: 0
A26: ='0422Master'!F22 -> Project Manager | B26: IT SUPPORTIVE SERICE | C26: 0 | D26: 1 | E26: ='0422Master'!AM22 -> 60275.6 | F26: ='0422Master'!Z22 -> 32594.4 | G26: ='0422Master'!AD22 -> 13037.76 | H26: =E26-(F26+G26) -> 14643.44 | I26: 0
A27: ='0422Master'!F23 -> Network Engineer L2 | B27: IT SUPPORTIVE SERICE | C27: 0 | D27: 1 | E27: ='0422Master'!AM23 -> 68276.425 | F27: ='0422Master'!Z23 -> 37044 | G27: ='0422Master'!AD23 -> 14817.6 | H27: =E27-(F27+G27) -> 16414.825 | I27: 0
A28: ='0422Master'!F24 -> Project Manager | B28: IT SUPPORTIVE SERICE | C28: 0 | D28: 1 | E28: ='0422Master'!AM24 -> 87168.559 | F28: ='0422Master'!Z24 -> 47550.72 | G28: ='0422Master'!AD24 -> 19020.288 | H28: =E28-(F28+G28) -> 20597.551 | I28: 0
A29: ='0422Master'!F25 -> Project Manager | B29: IT SUPPORTIVE SERICE | C29: 1 | D29: 0 | E29: ='0422Master'!AM25 -> 78276.379 | F29: ='0422Master'!Z25 -> 42605.4 | G29: ='0422Master'!AD25 -> 17042.16 | H29: =E29-(F29+G29) -> 18628.819 | I29: 0
A30: ='0422Master'!F26 -> Linux Administrator | B30: IT SUPPORTIVE SERICE | C30: 0 | D30: 1 | E30: ='0422Master'!AM26 -> 103275.72 | F30: ='0422Master'!Z26 -> 56508.6 | G30: ='0422Master'!AD26 -> 22603.44 | H30: =E30-(F30+G30) -> 24163.683 | I30: 0
A31: ='0422Master'!F27 -> Project Manager | B31: IT SUPPORTIVE SERICE | C31: 0 | D31: 1 | E31: ='0422Master'!AM27 -> 75114.995 | F31: ='0422Master'!Z27 -> 40847.22 | G31: ='0422Master'!AD27 -> 16338.888 | H31: =E31-(F31+G31) -> 17928.887 | I31: 0
A32: ='0422Master'!F28 -> Network Admin | B32: IT SUPPORTIVE SERICE | C32: 0 | D32: 1 | E32: ='0422Master'!AM28 -> 58276.472 | F32: ='0422Master'!Z28 -> 31482.6 | G32: ='0422Master'!AD28 -> 12593.04 | H32: =E32-(F32+G32) -> 14200.832 | I32: 0
... A39: ='0422Master'!F35 -> Sr.Software Engineer | B39: IT SUPPORTIVE SERICE | C39: 0 | D39: 1 | E39: ='0422Master'!AM35 -> 88276.332 | F39: ='0422Master'!Z35 -> 48166.8 | G39: ='0422Master'!AD35 -> 19266.72 | H39: =E39-(F39+G39) -> 20842.812 | I39: 0
C40: =SUM(C20:C39) -> 4 | D40: =SUM(D20:D39) -> 16
E48: Signature of the Contractor with Seal

Sheet MH_Must Roll
A2: Form No. II
A3: [M. W. Rules under Maharashtra Contract Labour (Regulation and Abolition)1963 Rule 27 (I)]
A4: Muster Roll cum Wage Register for the month of APRIL 2022
A5: Name and Address of Contractor : BURGEON IT SERVICES PVT.LTD. SIRI MANSION LIG 436 DR.A S RAO NAGAR,HYDERABAD 500 060
G6: Working Hours | I6: Interval for Rest | K6: No. of Hours Worked
