Workbook

Sheet BGLR STP APRIL 22-WM Reg
B1: 44531
A2: FORM - XIII REGISTER OF WORKMEN EMPLOYED BY CONTRACTOR
A4: Name and address of Contractor: | F4: ='04-22Master'!F5 -> Burgeon IT Services Pvt.Ltd. | I4: Name and address of Establishemnt in/ under which conctract is carried on: | L4: ='04-22Master'!AK5 -> Burgeon IT Services Pvt.Ltd.
F5: ='04-22Master'!F6 -> Siri Mansion LIGB 436 Dr.A S Rao Nagar,Hyderabad | L5: ='04-22Master'!AK6 -> Siri Mansion LIGB 436 Dr.A S Rao Nagar,Hyderabad
A6: Nature and location of work: | F6: ='04-22Master'!F8 -> IT SUPPORTIVE SERVICES & BANGALORE STP
I8: Name and address of Principal Employer: | L8: ='04-22Master'!AK10 -> INFOSYS LTD.IL Bangalore STP Park - I
L9: ='04-22Master'!AK11 -> No.45&46,3rd Cross,Electronic City,BANGALORE,KARNATAKA
A12: Serial No. in the Register of Workmen | B12: Name of Workman | C12: Age | D12: Sex | E12: Father's /Husband Name | F12: Designation / Nature of Work Done | G12: Permanent Address | H12: Local Address | I12: Date of Commencement of Employment | J12: Signature or thumb impression of Workman | K12: Date of termination of Employment | L12: Reasons for termination | M12: Remarks | N12: TOTAL EMPLOYESIN JULY 21
A14: =[1]Master!A16 -> 1 | B14: =[1]Master!B16 -> Kameswara Rao .M | C14: =[1]Master!C16 -> 03.07.1981 | D14: =[1]Master!D16 -> M | E14: =[1]Master!E16 -> Joga Rao | F14: =[1]Master!F16 -> TECHNICAL CONSULTATNT | G14: VENKATA SAI NILAYAM,OPP:LIG-1-39,APHB COLONY,SRIKAKULAM,A.P. 582001 | H14: GROUND FLOOR,NAGAPA ROY ,BLOCK NO 3 THUMBALA HALDI, BANGALORE, KARNATAKA STATE | I14: =[1]Master!N16 -> 11.04.2018 | K14: 30.01.2019 | L14: RESIGNED
A15: 2 | B15: Yogesh Rao | C15: 09.05.1983 | D15: M | E15: Bhaskar Rao | F15: TECHNICAL CONSULTATNT | G15: 874, 2ND C MAIN 8TH BLOCK,KORAMANGALA,BANGALORE | H15: 204, 2ND FLOOR,JPARVATHI BLK,SHRI TIRUMALA APPTS.SINGA SANDRA,BANGALAORE,KARNATAKA STATE | I15: 21.05.2018 | K15: 17.05.2019 | L15: RESIGNED
A16: =[2]Master!A16 -> 3 | B16: =[2]Master!B16 -> Rahul Balachandran | C16: =[2]Master!C16 -> 15.04.1983 | D16: =[2]Master!D16 -> M | E16: =[2]Master!E16 -> Balachandran S P | F16: =[2]Master!F16 -> TECHNICAL CONSULTATNT | G16: KARTHIKA KB NAGAR,72 WEST ADIKADU TEMPLE ERAVIPURAM POST KOLLAM,KERALA 691011 | H16: SHANTHI APPRTS.PLOT NO 25/4 KUMARAN STREET,SELAIVUR ,CHENNAI,TAMILNADU | I16: =[2]Master!I16 -> 06.09.2018 | K16: 04.09.2019 | L16: RESIGNED
A17: =[3]Master!A19 -> 4 | B17: =[3]Master!B19 -> Satyaprasanna Das | C17: =[3]Master!C19 -> 05.05.1981 | D17: =[3]Master!D19 -> M | E17: =[3]Master!E19 -> Bhajan Kumar Das | F17: =[3]Master!F19 -> TECHNICAL CONSULTATNT | G17: Meena Glory B 5/A , Dasadrone, Kolkata 700136 | H17: 123 PVR Building 5th Cross KEB road Vittal Nagar Bangalore 560078 | I17: =[3]Master!N19 -> 10.09.2018 | K17: 14.12.2018 | L17: RESIGNED
A18: 5 | B18: Avishek Singh Rathaur | C18: 01.04.1991 | D18: M | E18: Rama Shankar Singh | F18: TECHNICAL CONSULTATNT | G18: VICE- PACHRUKHIYA,POHS-EKHA,DIST CHAPARA,BIHAR 841208 | H18: RZH -745,Flat no -102,Street-14,H Block RajnagarII,Palam colony,Bangalore Karnataka | I18: 25.03.2019 | K18: 13.05.2019 | L18: RESIGNED
A19: 6 | B19: =[2]Master!B17 -> ELLALACHERUVU MOHAMMAD IMRAN | C19: 10.07.1991 | D19: =[2]Master!D17 -> M | E19: Mubarak Ali | F19: TECHNICAL CONSULTATNT | G19: 6-106, small mosque street, Rompicherla, Chittoor, AP 517192 | H19: Meenasri PG Electronic city Bangalore | I19: =[2]Master!I17 -> 01.06.2019 | K19: 31.12.2019 | L19: RESIGNED
A20: 7 | B20: Anil Kumar.B | C20: 29392 | D20: M | E20: Pitchaiah | F20: Senior Associate | G20: 2-194, Machavaram, Ponnur(MD), Guntur(DT), AP - 522315 | H20: #28, Deccon Flats, Flat no.G11,LIC Colony, East Tambaram, Chennai-59 | I20: 02.13.2020 | L20: RESIGNED
A21: 8 | B21: Yateesh Kumar | C21: 17.06.1989 | D21: M | E21: K. Amaranatha Reddy | F21: Senior Consultant | G21: No 36a, Chokkanathan Nagar, 3rd Street, Maduravoyal,Ch-95 | H21: No 36a, Chokkanathan Nagar, 3rd Street, Maduravoyal,Ch-95 | I21: 43950 | L21: RESIGNED
A22: 9 | B22: Nagarjuna Animireddy | C22: 33241 | D22: M | E22: SRILATHA P | F22: Support Lead | G22: H.No 2-40,Ravigunta Palli Village, Pamuru Mandal, Prakasam District, Andhra Pradesh Pin -523230 | H22: H.NO 2209,Vaddarapet, doddaballapur, Bangalore Rural, Karnataka PIN-561203 | I22: 43957 | K22: 29.05.2020 | L22: RESIGNED
A23: 10 | B23: Aswartha Narayana Guptha | C23: 21-03-1984 | D23: MALE | E23: Nagaraju J | F23: Associate Manager | G23: H.No-14/405, kamalanagar, S.L.V garments, Anantapur - 515001 | H23: F.No-101, Mayura E-city Apartment, Doddathogur, Electronic city Ph-1, Opp. Four Points Super market, Bangalore - 560100 | I23: 44126 | K23: 44403 | L23: RESIGNED
A24: 11 | B24: RAMESH DHAYALAN | C24: 31799 | D24: M | E24: Dhayalan. D | F24: Senior Windows Administration | G24: No 180, 3rd Cross st, MGR St, Bharathi Nagar, Mettuthandalam, Thiruporur, Chengalpattu District Pincode=603110 | H24: No 180, 3rd Cross st, MGR St, Bharathi Nagar, Mettuthandalam, Thiruporur, Chengalpattu District Pincode=603110 | I24: 44117 | K24: 44187 | L24: RESIGNED
A25: 12 | B25: AKASH DEEP CHUNAP | C25: 33695 | D25: MALE | E25: Priyanka Chunap | F25: Network security engineer | G25: H.No 4-3-216/2A,Narasimha Nagar, Bhainsa, Nirmal District, 504 103 | H25: Selene Court, Sree Vensai Projects, Flat 404, Kompally, 500014 | I25: 44105 | K25: ACTIVE | L25: ACTIVE | N25: 1
A26: 13 | B26: Kotravel Balasubramaniam | C26: 30142 | D26: MALE | E26: Balasubramaniam K | F26: Senior Technical Specialist | G26: 3/442,Vasantha Nagar,Nathakadaiyur,Kangeyam(TK),Tirupur(DT),TamilNadu | H26: #195 TRC Paradise, 6stage,5th mainBEML Layout ,Bangalore | I26: 44139 | J26: OOOO | K26: 44440 | L26: RESIGNED
A27: 14 | B27: SUDALAI KANNAN M | C27: 31571 | D27: MALE | E27: Mohandass T | F27: Sr Solaris Administrator | G27: 449/6 Selva Nagar Main Road, LRG Nagar backside, Vadivel Nagar, Karur -639008. Tamilnadu | H27: 83. 8th Cross, 2nd Main Road, Manjunath Nagar, Chikkalsandra, Uttarahalli - 560061, Bangalore - Karnataka | I27: 44147 | J27: OOOO | K27: 44359 | L27: RESIGNED
A28: 15 | B28: Parteek Arora | C28: 32111 | D28: MALE | E28: Lovejeet Kour | F28: Active Directory Architect | G28: A-207, Sainik Colony, Sector 49, Faridabad, Haryana, 121001 | H28: A-207, Sainik Colony, Sector 49, Faridabad, Haryana, 121001 | I28: 44159 | J28: OOOO | K28: ACTIVE | L28: ACTIVE
A29: 16 | B29: Gudipati Ravi Teja | C29: 29048 | D29: M | E29: G Abdul Hameed | F29: Senior Software Engineer | G29: Flat 311,Hyder Chand Plaza,Vadeegeri,Kurnool.A.P | H29: H.No.12-2-790/11,Flat G2,Span Nest Appartments,Ayodha Nagar Colony,Mehdipatnam,Hyderabad. | I29: 44166 | K29: 44253 | L29: RESIGNED
A30: 17 | B30: Aniket Shankar Bamane | C30: 32826 | D30: MALE | E30: SHANKAR BAMANE | F30: Solution Architect | G30: 101, LAXMI KRUPA SADAN, NEAR GAONDEVI MANDIR, TALAVALI NAKA, NAVI MUMBAI - 400708 | H30: G-3, MATRUCHAYA BUILDING, NEAR RAM MARATHE BUNGLOW, KOPARI COLONY, THANE (E) - 400603 | I30: 44181 | J30: OOOO | K30: 44412 | L30: RESIGNED
A31: 18 | B31: Roshan Ravinder Vannam | C31: 29/6/1986 | D31: M | E31: Ravinder Vannam | F31: Sales force Business Analyst | G31: 1-8-700/29, Padma Colony,Hydebad- 500044, Telangana | H31: Flat#501, KBR Sai Akshaya Residency,2-2-18/15, DD Colony, Hyderabad-500013,TS | I31: 44210 | K31: 44258 | L31: RESIGNED
A32: 19 | B32: Naveena Kura | C32: 31573 | D32: F | E32: A.Rajesh | F32: Associate Consultant | G32: 2-72,Rompicherls cross,Challavaripalle(p),Rompicherla(M),Chittoor(dt),Andhrapradesh-517192 | H32: 102,1st floor,K.L.Regency,Sai Brindavana Layout,3rd cross,Medahalli,Bangalore-560049 | I32: 44214 | K32: 44253 | L32: RESIGNED
A33: 20 | B33: SantoshKumar KA | C33: 30101 | D33: M | E33: K J Arunachalam | F33: Senior Manager-Projects | G33: No.13, Flat F-1, Kurinji Flats, Mahalakshmi Nagar 2nd Street, Madipakkam, Chennai - 600091 | H33: No.13, Flat F-1, Kurinji Flats, Mahalakshmi Nagar 2nd Street, Madipakkam, Chennai - 600091 | I33: 44214 | K33: 44286 | L33: RESIGNED
A34: 21 | B34: Damodar Medara | C34: 25/7/1990 | D34: MALE | E34: M.Rajgopal | F34: Senior Technial Consultant | G34: s/o Rajgopal medara, 16/21, Mohammediya, cowal Bazar, 1st gate, bellary-583102 | H34: s/o Rajgopal medara, 16/21, Mohammediya, cowal Bazar, 1st gate, bellary-583102 | I34: 44214 | K34: 44439 | L34: RESIGNED
A35: 22 | B35: Shaikmahaboob vali | C35: 33030 | D35: MALE | E35: shaik mahaboob basha | F35: Technical Consultant | G35: 3-16,uppalapdu owk mandal banaganapalli taluk kurnool ap 51812 | H35: 3-16,uppalapdu owk mandal banaganapalli taluk kurnool ap 51812 | I35: 44249 | K35: 44408 | L35: RESIGNED
A36: 23 | B36: Kuldeep Singh | C36: 30/1/1990 | D36: M | E36: Ankita Singh | F36: Client Delievary Manager | G36: Flat no 302, Sai park Phase 1, Keshav nagar, Pune 4110136 | H36: Flat no 302, Sai park Phase 1, Keshav nagar, Pune 4110136 | I36: 44252 | J36: OOOO | K36: 43329 | L36: RESIGNED
A37: 24 | B37: VarunKumar AVS | C37: 29/3/1988 | D37: MALE | E37: Aida Krishna Rao | F37: Windows VMware Engineer | G37: H.No.8-2-310/A/76/1, IbrahimNagar, Banjara Hills Road No.10 Hyderabad 500034 | H37: H.No.8-2-310/A/76/1, IbrahimNagar, Banjara Hills Road No.10 Hyderabad 500034 | I37: 44256 | K37: 44393 | L37: RESIGNED
A38: 25 | B38: Akhila Surineni | C38: 25/6/1990 | D38: MALE | E38: Srinivasa Rao Surineni | G38: Plot no: 149, Road No:7,Plot no: 149, Road No:7,Harivillu township, Patelguda,Ameenpur, Sangareddy- 502319 | H38: Plot no: 149, Road No:7 Harivillu township, Patelguda, Ameenpur, Sangareddy- 502319 | I38: 44256 | J38: OOOO | K38: 44362 | L38: RESIGNED
A39: 26 | B39: Obulreddy Desam | C39: 33978 | D39: MALE | E39: Ramakrishna Reddy | F39: Linux System Administrator | G39: D-NO 1-7, Polepalli post,Durgi mondal,Guntur dist,Andhrapradesh 522612 | H39: D-NO 1-7, Polepalli post,Durgi mondal,Guntur dist,Andhrapradesh 522612 | I39: 44274 | J39: OOOO | K39: ACTIVE | L39: ACTIVE
A40: 27 | B40: Aiesha Nabi | C40: 22/07/1994 | D40: FEMALE | E40: D P Nabirasool | F40: Linux System Administrator | G40: 107, 1st floor, Sri Shravya PG, 6th cross, thulasi theater road, Marathahalli -560037 | H40: 9-246, Hindupur,kirikera, Ananthapur, AP-515211 | I40: 44274 | K40: ACTIVE | L40: ACTIVE
A41: 28 | B41: Nikath Banu | C41: 32785 | D41: FEMALE | E41: ABDUL KADAR | F41: Technical Consultant | G41: 112B Ist Floor, manohar nagar, | H41: 112B Ist Floor, manohar nagar, | I41: 44279 | K41: ACTIVE | L41: ACTIVE
A42: 29 | B42: RAMBABU PYDI | C42: 30804 | D42: MALE | E42: PYDI. DHANA LAKSHMI | F42: Major Incident Manager | G42: H.NO - 20-72/3. GOUTHAM NAGAR, MALKAJGIRI., MEDCHAL - 500047 | H42: H.NO - 20-72/3. GOUTHAM NAGAR, MALKAJGIRI., MEDCHAL - 500047 | I42: 44279 | J42: OOOO | K42: ACTIVE | L42: ACTIVE
A43: 30 | B43: Srinivasulu Boyapati | C43: 32787 | D43: MALE | E43: Subbarayudu | F43: Salesforce Vlocity Consultant | G43: Flat no#301,ss Fecility homes, Berewell Road, White field, Bangloor | H43: Sanjeeva Nagar, Gowraram, anatnthsagaram, TS | I43: 44284 | K43: 44455 | L43: RESIGNED
A44: 31 | B44: Vijay kola | C44: 17-06-1993 | D44: MALE | E44: Kola Sathish babu | F44: Senior Associate | G44: 11-139/6, Yogimallavaram, Tiruchanoor, Tirupati, 517503 | H44: 11-139/6, Yogimallavaram, Tiruchanoor, Tirupati, 517503 | I44: 44287 | J44: OOOO | K44: 44469 | L44: RESIGNED
A45: 32 | B45: Venkadesh Pounraj | C45: 30839 | D45: MALE | E45: Pounraj | F45: Technical Consultant | G45: 1/242A, Perumal Kovil street, Thalai vasal street, Salem,Tamil Nadu 636112 | H45: 1/242A, Perumal Kovil street, Thalai vasal street, Salem,Tamil Nadu 636112 | I45: 44287 | K45: 44333 | L45: RESIGNED
...

Sheet 04-22Master
A3: FORM - XIII REGISTER OF WORKMEN EMPLOYED BY CONTRACTOR
B4: (Vide Rule 75 of Contract Labour (Regulation and Abolition) Central/Karnataka Rules 1974)
A5: Name and address of Contractor: | F5: Burgeon IT Services Pvt.Ltd. | W5: Name and address of Establishemnt in/ under which contract is carried on: | AK5: =F5 -> Burgeon IT Services Pvt.Ltd.
F6: Siri Mansion LIGB 436 Dr.A S Rao Nagar,Hyderabad | AK6: =F6 -> Siri Mansion LIGB 436 Dr.A S Rao Nagar,Hyderabad
AK7: =F7 -> 0
A8: Nature and location of work: | F8: IT SUPPORTIVE SERVICES & BANGALORE STP | AU8: to paste on left side in "A" column.
A10: Wage period: Monthly | D10: 44652 | AF10: Name and address of Principal Employer: | AK10: INFOSYS LTD.IL Bangalore STP Park - I
AK11: No.45&46,3rd Cross,Electronic City,BANGALORE,KARNATAKA
A13: 1 | B13: 2 | C13: 3 | D13: 4 | E13: 5 | F13: 6 | G13: 7 | H13: 8 | I13: 9 | J13: 10 | K13: 11 | L13: 12 | M13: 13 | N13: 14 | O13: 15 | P13: 16 | Q13: 17 | R13: 18 | S13: 19 | T13: 20 | U13: 21 | V13: 22 | W13: 23 | X13: 24 | Y13: 25 | Z13: 26 | AA13: 27 | AB13: 28 | AC13: 29 | AD13: 30 | AE13: 31 | AF13: 32 | AG13: 33 | AH13: 34 | AI13: 35 | AJ13: 36 | AK13: 37 | AL13: 38 | AM13: 39 | AN13: 40 | AO13: 41 | AP13: 42 | AQ13: 43 | AR13: 44 | AS13: 45
B14: Name of Workman | C14: Age | D14: Sex | E14: Father's /Husband Name | F14: Designation / Nature of Work Done | G14: Permanent Address | H14: Local Address | I14: Date of Commencement of Employment | J14: Signature or thumb impression of Workman | K14: Date of termination of Employment | L14: Reasons for termination | M14: Remarks | N14: EPF Number | O14: ESI Number | P14: Name of Workman | Q14: NO.OF DAYS | R14: NO OF DAYS PAYABLE | S14: Unit of work done | T14: Monthly rate of wages/ piece rate | U14: Basic wages | V14: Dearness Allowances | W14: Over time | X14: Other cash payments (Nature of payments to be indicated) | Y14: HRA | Z14: CONVEYANCE | AA14: MEDICAL ALLOWANCES | AB14: SPECIAL ALLOWNANCES | AC14: Total | AD14: BONUS | AE14: GRATUITY | AF14: LTA/L.E | AG14: ARREAR AMOUNT | AH14: TOTAL AMOUNT | AI14: Deductions, if any, (Indicate nature) | AO14: Net Amount paid | AP14: Time and Date of Payment | AQ14: Place of Payment | AR14: Signature/Thumb Impression of workman | AS14: Initial of Contractor or his representative | AU14: Serial No. in the Register of Workmen
AI15: ESI | AJ15: PF | AK15: PT | AL15: TDS | AM15: MED | AN15: Total Deductions
A16: BITS-485 | B16: AKASH DEEP CHUNAP | C16: 33695 | D16: MALE | E16: Priyanka Chunap | F16: Network security engineer | G16: H.No 4-3-216/2A,Narasimha Nagar, Bhainsa, Nirmal District, 504 103 | H16: Selene Court, Sree Vensai Projects, Flat 404, Kompally, 500014 | I16: 44105 | N16: 101629256413 | O16: N/A | P16: =B16 -> AKASH DEEP CHUNAP | Q16: 30 | R16: =VLOOKUP(A16,'[5]Pay sheet-APRIL- 2022'!$C$7:$AF$137,10,0) -> 30 | S16: N/A | T16: 135892 | U16: =VLOOKUP(A16,'[5]Pay sheet-APRIL- 2022'!$C$7:$AF$137,11,0) -> 81535.2 | V16: 0 | W16: 0 | X16: =Y16+Z16+AA16+AB16 -> 54469.8 | Y16: =VLOOKUP(A16,'[5]Pay sheet-APRIL- 2022'!$C$7:$AF$137,12,0) -> 32614.08 | Z16: =VLOOKUP(A16,'[5]Pay sheet-APRIL- 2022'!$C$7:$AF$137,13,0) -> 2083 | AA16: =VLOOKUP(A16,'[5]Pay sheet-APRIL- 2022'!$C$7:$AF$137,14,0) -> 2083 | AB16: =VLOOKUP(A16,'[5]Pay sheet-APRIL- 2022'!$C$7:$AF$137,15,0) -> 17689.72 | AC16: =U16+X16 -> 136005 | AD16: =VLOOKUP(A16,'[5]Pay sheet-APRIL- 2022'!$C$7:$AF$137,18,0) -> 1554.609 | AE16: =VLOOKUP(A16,'[5]Pay sheet-APRIL- 2022'!$C$7:$AF$137,19,0) -> 3921.8431 | AF16: =VLOOKUP(A16,'[5]Pay sheet-APRIL- 2022'!$C$7:$AF$137,20,0) -> 6794.6 | AG16: =VLOOKUP(A16,'[5]Pay sheet-APRIL- 2022'!$C$7:$AF$137,22,0) -> 0 | AH16: =AC16+AD16+AE16+AF16+AG16 -> 148276.05 | AJ16: =VLOOKUP(A16,'[4]Pay sheet-MARCH- 2022'!$C$7:$AF$147,26,0) -> 1800 | AK16: =VLOOKUP(A16,'[4]Pay sheet-MARCH- 2022'!$C$7:$AF$147,25,0) -> 200 | AL16: =VLOOKUP(A16,'[5]Pay sheet-APRIL- 2022'!$C$7:$AF$137,24,0) -> 0 | AM16: =VLOOKUP(A16,'[4]Pay sheet-MARCH- 2022'!$C$7:$AF$147,27,0) -> 0 | AN16: =AI16+AJ16+AK16+AL16+AM16 -> 2000 | AO16: =AH16-AN16 -> 146276.05 | AP16: 44686 | AQ16: SBIN | AR16: A/C 621 732 836 92 | AU16: 12 | AV16: 1
A17: BITS-565 | B17: RajasekharReddy KN | C17: 30837 | D17: MALE | E17: Narayana Reddy | F17: Citrix Administrator | G17: 3-48, Boorlapalli, PTM Madalam, Tamballapalli, Boorlapalle, Chittoor, AP 517370 | H17: 3-48, Boorlapalli, PTM Madalam, Tamballapalli, Boorlapalle, Chittoor, AP 517370 | I17: 44326 | N17: 100432313742 | O17: N/A | P17: =B17 -> RajasekharReddy KN | Q17: 30 | R17: =VLOOKUP(A17,'[5]Pay sheet-APRIL- 2022'!$C$7:$AF$137,10,0) -> 30 | S17: N/A | T17: 66374 | U17: =VLOOKUP(A17,'[5]Pay sheet-APRIL- 2022'!$C$7:$AF$137,11,0) -> 39824.4 | V17: 0 | W17: 0 | X17: =Y17+Z17+AA17+AB17 -> 26662.6 | Y17: =VLOOKUP(A17,'[5]Pay sheet-APRIL- 2022'!$C$7:$AF$137,12,0) -> 15929.76 | Z17: =VLOOKUP(A17,'[5]Pay sheet-APRIL- 2022'!$C$7:$AF$137,13,0) -> 2083 | AA17: =VLOOKUP(A17,'[5]Pay sheet-APRIL- 2022'!$C$7:$AF$137,14,0) -> 2083 | AB17: =VLOOKUP(A17,'[5]Pay sheet-APRIL- 2022'!$C$7:$AF$137,15,0) -> 6566.84 | AC17: =U17+X17 -> 66487 | AD17: =VLOOKUP(A17,'[5]Pay sheet-APRIL- 2022'!$C$7:$AF$137,18,0) -> 1554.609 | AE17: =VLOOKUP(A17,'[5]Pay sheet-APRIL- 2022'!$C$7:$AF$137,19,0) -> 1915.5536 | AF17: =VLOOKUP(A17,'[5]Pay sheet-APRIL- 2022'!$C$7:$AF$137,20,0) -> 3318.7 | AG17: =VLOOKUP(A17,'[5]Pay sheet-APRIL- 2022'!$C$7:$AF$137,22,0) -> 0 | AH17: =AC17+AD17+AE17+AF17+AG17 -> 73275.863 | AI17: 0 | AJ17: =VLOOKUP(A17,'[4]Pay sheet-MARCH- 2022'!$C$7:$AF$147,26,0) -> 1800 | AK17: =VLOOKUP(A17,'[4]Pay sheet-MARCH- 2022'!$C$7:$AF$147,25,0) -> 200 | AL17: =VLOOKUP(A17,'[5]Pay sheet-APRIL- 2022'!$C$7:$AF$137,24,0) -> 0 | AM17: =VLOOKUP(A17,'[4]Pay sheet-MARCH- 2022'!$C$7:$AF$147,27,0) -> 391.78785 | AN17: =AI17+AJ17+AK17+AL17+AM17 -> 2391.7878 | AO17: =AH17-AN17 -> 70884.075 | AP17: 44686 | AQ17: ICICI | AR17: 272601504387 | AU17: 37 | AV17: 2
A18: BITS-566 | B18: Moulika GM | C18: 35558 | D18: FEMALE | E18: Maniganda Charan Kumar | F18: Ansible Developer | G18: 12A/22A,METTU,TIRUTTANI | H18: BANGALORE, ELECTRONIC CITY,PHASE1 | I18: 44327 | N18: 101695261774 | O18: N/A | P18: =B18 -> Moulika GM | Q18: 30 | R18: =VLOOKUP(A18,'[5]Pay sheet-APRIL- 2022'!$C$7:$AF$137,10,0) -> 30 | S18: N/A | T18: 20029 | U18: =VLOOKUP(A18,'[5]Pay sheet-APRIL- 2022'!$C$7:$AF$137,11,0) -> 12017.4 | V18: 0 | W18: 0 | X18: =Y18+Z18+AA18+AB18 -> 8124.6 | Y18: =VLOOKUP(A18,'[5]Pay sheet-APRIL- 2022'!$C$7:$AF$137,12,0) -> 4806.96 | Z18: =VLOOKUP(A18,'[5]Pay sheet-APRIL- 2022'!$C$7:$AF$137,13,0) -> 2083 | AA18: =VLOOKUP(A18,'[5]Pay sheet-APRIL- 2022'!$C$7:$AF$137,14,0) -> 2083 | AB18: =VLOOKUP(A18,'[5]Pay sheet-APRIL- 2022'!$C$7:$AF$137,15,0) -> -848.36 | AC18: =U18+X18 -> 20142 | AD18: =VLOOKUP(A18,'[5]Pay sheet-APRIL- 2022'!$C$7:$AF$137,18,0) -> 1554.609 | AE18: =VLOOKUP(A18,'[5]Pay sheet-APRIL- 2022'!$C$7:$AF$137,19,0) -> 578.03694 | AF18: =VLOOKUP(A18,'[5]Pay sheet-APRIL- 2022'!$C$7:$AF$137,20,0) -> 1001.45 | AG18: =VLOOKUP(A18,'[5]Pay sheet-APRIL- 2022'!$C$7:$AF$137,22,0) -> 0 | AH18: =AC18+AD18+AE18+AF18+AG18 -> 23276.096 | AI18: 0 | AJ18: =VLOOKUP(A18,'[4]Pay sheet-MARCH- 2022'!$C$7:$AF$147,26,0) -> 1442 | AK18: =VLOOKUP(A18,'[4]Pay sheet-MARCH- 2022'!$C$7:$AF$147,25,0) -> 200 | AL18: =VLOOKUP(A18,'[5]Pay sheet-APRIL- 2022'!$C$7:$AF$137,24,0) -> 0 | AM18: =VLOOKUP(A18,'[4]Pay sheet-MARCH- 2022'!$C$7:$AF$147,27,0) -> 391.78785 | AN18: =AI18+AJ18+AK18+AL18+AM18 -> 2033.7878 | AO18: =AH18-AN18 -> 21242.308 | AP18: 44686 | AQ18: Indian Bank | AR18: 6685853376 | AU18: 38 | AV18: 3
A19: BITS-567 | B19: AsokKumar J | C19: 32274 | D19: MALE | E19: J.Prabhakar Reddt | F19: Senior Middleware Administrator (MQ & Kafka) | G19: #303, Dhanunjaya Apartment, Dasarahalli Main Road, Hebbal,Bangalore-560024. | H19: 2-88, S/o Juturu Prabhakar Reddy, Gunipalli, Bukkapatnam, Anantapur, Andra Pradesh-515154 | I19: 44328 | N19: 101695261742 | O19: N/A | P19: =B19 -> AsokKumar J | Q19: 30 | R19: =VLOOKUP(A19,'[5]Pay sheet-APRIL- 2022'!$C$7:$AF$137,10,0) -> 28 | S19: N/A | T19: 121988 | U19: =VLOOKUP(A19,'[5]Pay sheet-APRIL- 2022'!$C$7:$AF$137,11,0) -> 68313.28 | V19: 0 | W19: 0 | X19: =Y19+Z19+AA19+AB19 -> 45655.187 | Y19: =VLOOKUP(A19,'[5]Pay sheet-APRIL- 2022'!$C$7:$AF$137,12,0) -> 27325.312 | Z19: =VLOOKUP(A19,'[5]Pay sheet-APRIL- 2022'!$C$7:$AF$137,13,0) -> 1944 | AA19: =VLOOKUP(A19,'[5]Pay sheet-APRIL- 2022'!$C$7:$AF$137,14,0) -> 1944 | AB19: =VLOOKUP(A19,'[5]Pay sheet-APRIL- 2022'!$C$7:$AF$137,15,0) -> 14441.875 | AC19: =U19+X19 -> 113968.47 | AD19: =VLOOKUP(A19,'[5]Pay sheet-APRIL- 2022'!$C$7:$AF$137,18,0) -> 1554.609 | AE19: =VLOOKUP(A19,'[5]Pay sheet-APRIL- 2022'!$C$7:$AF$137,19,0) -> 3285.8688 | AF19: =VLOOKUP(A19,'[5]Pay sheet-APRIL- 2022'!$C$7:$AF$137,20,0) -> 5692.7733 | AG19: =VLOOKUP(A19,'[5]Pay sheet-APRIL- 2022'!$C$7:$AF$137,22,0) -> 0 | AH19: =AC19+AD19+AE19+AF19+AG19 -> 124501.72 | AI19: 0 | AJ19: =VLOOKUP(A19,'[4]Pay sheet-MARCH- 2022'!$C$7:$AF$147,26,0) -> 1800 | AK19: =VLOOKUP(A19,'[4]Pay sheet-MARCH- 2022'!$C$7:$AF$147,25,0) -> 200 | AL19: =VLOOKUP(A19,'[5]Pay sheet-APRIL- 2022'!$C$7:$AF$137,24,0) -> 0 | AM19: =VLOOKUP(A19,'[4]Pay sheet-MARCH- 2022'!$C$7:$AF$147,27,0) -> 391.78785 | AN19: =AI19+AJ19+AK19+AL19+AM19 -> 2391.7878 | AO19: =AH19-AN19 -> 122109.93 | AP19: 44686 | AQ19: HDFC | AR19: 50100397382442 | AU19: 39 | AV19: 4
A20: BITS-577 | B20: Majed Khan | C20: 32203 | D20: MALE | E20: Habeeb Khan | F20: Oracle/SAP DBA | G20: H NO 4-11-44/1, Kareem colony, OP, Narsa Hotel,Roshan Gate, Aurangabad, MH 431001 | H20: H NO 4-11-44/1, Kareem colony, OP, Narsa Hotel,Roshan Gate, Aurangabad, MH 431001 | I20: 44344 | N20: 100240675169 | O20: N/A | P20: =B20 -> Majed Khan | Q20: 30 | R20: =VLOOKUP(A20,'[5]Pay sheet-APRIL- 2022'!$C$7:$AF$137,10,0) -> 30 | S20: N/A | T20: 135892 | U20: =VLOOKUP(A20,'[5]Pay sheet-APRIL- 2022'!$C$7:$AF$137,11,0) -> 81535.2 | V20: 0 | W20: 0 | X20: =Y20+Z20+AA20+AB20 -> 54469.8 | Y20: =VLOOKUP(A20,'[5]Pay sheet-APRIL- 2022'!$C$7:$AF$137,12,0) -> 32614.08 | Z20: =VLOOKUP(A20,'[5]Pay sheet-APRIL- 2022'!$C$7:$AF$137,13,0) -> 2083 | AA20: =VLOOKUP(A20,'[5]Pay sheet-APRIL- 2022'!$C$7:$AF$137,14,0) -> 2083 | AB20: =VLOOKUP(A20,'[5]Pay sheet-APRIL- 2022'!$C$7:$AF$137,15,0) -> 17689.72 | AC20: =U20+X20 -> 136005 | AD20: =VLOOKUP(A20,'[5]Pay sheet-APRIL- 2022'!$C$7:$AF$137,18,0) -> 1554.609 | AE20: =VLOOKUP(A20,'[5]Pay sheet-APRIL- 2022'!$C$7:$AF$137,19,0) -> 3921.8431 | AF20: =VLOOKUP(A20,'[5]Pay sheet-APRIL- 2022'!$C$7:$AF$137,20,0) -> 6794.6 | AG20: =VLOOKUP(A20,'[5]Pay sheet-APRIL- 2022'!$C$7:$AF$137,22,0) -> 0 | AH20: =AC20+AD20+AE20+AF20+AG20 -> 148276.05 | AI20: 0 | AJ20: =VLOOKUP(A20,'[4]Pay sheet-MARCH- 2022'!$C$7:$AF$147,26,0) -> 1800 | AK20: =VLOOKUP(A20,'[4]Pay sheet-MARCH- 2022'!$C$7:$AF$147,25,0) -> 200 | AL20: =VLOOKUP(A20,'[5]Pay sheet-APRIL- 2022'!$C$7:$AF$137,24,0) -> 0 | AM20: =VLOOKUP(A20,'[4]Pay sheet-MARCH- 2022'!$C$7:$AF$147,27,0) -> 391.78785 | AN20: =AI20+AJ20+AK20+AL20+AM20 -> 2391.7878 | AO20: =AH20-AN20 -> 145884.26 | AP20: 44686 | AQ20: HDFC | AR20: 07941610141597 | AU20: 42 | AV20: 5
A21: BITS-587 | B21: MADAN DH | C21: 25-05-1988 | D21: MALE | E21: Dayanand H | F21: Principal Storage Consultant | G21: #402, Supreme Sunrise, Wellington Layout, Singasandra, Hosur road, Bangalore-68 | H21: #402, Supreme Sunrise, Wellington Layout, Singasandra, Hosur road, Bangalore-68 | I21: 44362 | N21: 100632443174 | O21: N/A | P21: =B21 -> MADAN DH | Q21: 30 | R21: =VLOOKUP(A21,'[5]Pay sheet-APRIL- 2022'!$C$7:$AF$137,10,0) -> 30 | S21: N/A | T21: 94181 | U21: =VLOOKUP(A21,'[5]Pay sheet-APRIL- 2022'!$C$7:$AF$137,11,0) -> 56508.6 | V21: 0 | W21: 0 | X21: =Y21+Z21+AA21+AB21 -> 37785.4 | Y21: =VLOOKUP(A21,'[5]Pay sheet-APRIL- 2022'!$C$7:$AF$137,12,0) -> 22603.44 | Z21: =VLOOKUP(A21,'[5]Pay sheet-APRIL- 2022'!$C$7:$AF$137,13,0) -> 2083 | AA21: =VLOOKUP(A21,'[5]Pay sheet-APRIL- 2022'!$C$7:$AF$137,14,0) -> 2083 | AB21: =VLOOKUP(A21,'[5]Pay sheet-APRIL- 2022'!$C$7:$AF$137,15,0) -> 11015.96 | AC21: =U21+X21 -> 94294 | AD21: =VLOOKUP(A21,'[5]Pay sheet-APRIL- 2022'!$C$7:$AF$137,18,0) -> 1554.609 | AE21: =VLOOKUP(A21,'[5]Pay sheet-APRIL- 2022'!$C$7:$AF$137,19,0) -> 2718.0637 | AF21: =VLOOKUP(A21,'[5]Pay sheet-APRIL- 2022'!$C$7:$AF$137,20,0) -> 4709.05 | AG21: =VLOOKUP(A21,'[5]Pay sheet-APRIL- 2022'!$C$7:$AF$137,22,0) -> 0 | AH21: =AC21+AD21+AE21+AF21+AG21 -> 103275.72 | AI21: 0 | AJ21: =VLOOKUP(A21,'[4]Pay sheet-MARCH- 2022'!$C$7:$AF$147,26,0) -> 1800 | AK21: =VLOOKUP(A21,'[4]Pay sheet-MARCH- 2022'!$C$7:$AF$147,25,0) -> 200 | AL21: =VLOOKUP(A21,'[5]Pay sheet-APRIL- 2022'!$C$7:$AF$137,24,0) -> 0 | AM21: =VLOOKUP(A21,'[4]Pay sheet-MARCH- 2022'!$C$7:$AF$147,27,0) -> 391.78785 | AN21: =AI21+AJ21+AK21+AL21+AM21 -> 2391.7878 | AO21: =AH21-AN21 -> 100883.93 | AP21: 44686 | AQ21: HDFC Bank | AR21: 50100122835737 | AU21: 47 | AV21: 6
A22: BITS-592 | B22: Sachin | C22: 21/09/1983 | D22: MALE | E22: POONAM SACHIN MESHRAM | F22: Windows Administrator | G22: T4 KUNAL RESIDENCY 2 BEHIND VITTHAL MANDIR BELTARODI NAGPUR 441108 | H22: 403 BHAKTI HEIGHTS ADHIRAJ CLUSTER 2 BEHIND DAWLAT PETROL PUMP BHUGAON PUNE 411023 | I22: 44368 | N22: 101090261210 | O22: N/A | P22: =B22 -> Sachin | Q22: 30 | R22: =VLOOKUP(A22,'[5]Pay sheet-APRIL- 2022'!$C$7:$AF$137,10,0) -> 13 | S22: N/A | T22: 84912 | U22: =VLOOKUP(A22,'[5]Pay sheet-APRIL- 2022'!$C$7:$AF$137,11,0) -> 22077.12 | V22: 0 | W22: 0 | X22: =Y22+Z22+AA22+AB22 -> 14831.08 | Y22: =VLOOKUP(A22,'[5]Pay sheet-APRIL- 2022'!$C$7:$AF$137,12,0) -> 8830.848 | Z22: =VLOOKUP(A22,'[5]Pay sheet-APRIL- 2022'!$C$7:$AF$137,13,0) -> 903 | AA22: =VLOOKUP(A22,'[5]Pay sheet-APRIL- 2022'!$C$7:$AF$137,14,0) -> 903 | AB22: =VLOOKUP(A22,'[5]Pay sheet-APRIL- 2022'!$C$7:$AF$137,15,0) -> 4194.232 | AC22: =U22+X22 -> 36908.2 | AD22: =VLOOKUP(A22,'[5]Pay sheet-APRIL- 2022'!$C$7:$AF$137,18,0) -> 1554.609 | AE22: =VLOOKUP(A22,'[5]Pay sheet-APRIL- 2022'!$C$7:$AF$137,19,0) -> 1061.9095 | AF22: =VLOOKUP(A22,'[5]Pay sheet-APRIL- 2022'!$C$7:$AF$137,20,0) -> 1839.76 | AG22: =VLOOKUP(A22,'[5]Pay sheet-APRIL- 2022'!$C$7:$AF$137,22,0) -> 0 | AH22: =AC22+AD22+AE22+AF22+AG22 -> 41364.478 | AI22: 0 | AJ22: =VLOOKUP(A22,'[4]Pay sheet-MARCH- 2022'!$C$7:$AF$147,26,0) -> 1800 | AK22: =VLOOKUP(A22,'[4]Pay sheet-MARCH- 2022'!$C$7:$AF$147,25,0) -> 200 | AL22: =VLOOKUP(A22,'[5]Pay sheet-APRIL- 2022'!$C$7:$AF$137,24,0) -> 0 | AM22: =VLOOKUP(A22,'[4]Pay sheet-MARCH- 2022'!$C$7:$AF$147,27,0) -> 391.78785 | AN22: =AI22+AJ22+AK22+AL22+AM22 -> 2391.7878 | AO22: =AH22-AN22 -> 38972.691 | AP22: 44686 | AQ22: STATE BANK OF INDIA | AR22: 20079696052 | AU22: 49 | AV22: 7
A23: BITS-606 | B23: Barathiyar A | C23: 03.05.1981 | D23: MALE | E23: Arumugam | F23: VMware & Wintel Admin | G23: 3/148,New Street,Mundiyampakkam & PO,Vikkravandi Taluk,Villupuram Dist,PIN 605601 | H23: 3/148,New Street,Mundiyampakkam & PO,Vikkravandi Taluk,Villupuram Dist,PIN 605601 | I23: 44396 | N23: 100583941709 | O23: N/A | P23: =B23 -> Barathiyar A | Q23: 30 | R23: =VLOOKUP(A23,'[5]Pay sheet-APRIL- 2022'!$C$7:$AF$137,10,0) -> 13 | S23: N/A | T23: 58959 | U23: =VLOOKUP(A23,'[5]Pay sheet-APRIL- 2022'!$C$7:$AF$137,11,0) -> 15329.34 | V23: 0 | W23: 0 | X23: =Y23+Z23+AA23+AB23 -> 10332.56 | Y23: =VLOOKUP(A23,'[5]Pay sheet-APRIL- 2022'!$C$7:$AF$137,12,0) -> 6131.736 | Z23: =VLOOKUP(A23,'[5]Pay sheet-APRIL- 2022'!$C$7:$AF$137,13,0) -> 903 | AA23: =VLOOKUP(A23,'[5]Pay sheet-APRIL- 2022'!$C$7:$AF$137,14,0) -> 903 | AB23: =VLOOKUP(A23,'[5]Pay sheet-APRIL- 2022'!$C$7:$AF$137,15,0) -> 2394.824 | AC23: =U23+X23 -> 25661.9 | AD23: =VLOOKUP(A23,'[5]Pay sheet-APRIL- 2022'!$C$7:$AF$137,18,0) -> 1554.609 | AE23: =VLOOKUP(A23,'[5]Pay sheet-APRIL- 2022'!$C$7:$AF$137,19,0) -> 737.34125 | AF23: =VLOOKUP(A23,'[5]Pay sheet-APRIL- 2022'!$C$7:$AF$137,20,0) -> 1277.445 | AG23: =VLOOKUP(A23,'[5]Pay sheet-APRIL- 2022'!$C$7:$AF$137,22,0) -> 0 | AH23: =AC23+AD23+AE23+AF23+AG23 -> 29231.295 | AI23: 0 | AJ23: =VLOOKUP(A23,'[4]Pay sheet-MARCH- 2022'!$C$7:$AF$147,26,0) -> 1800 | AK23: =VLOOKUP(A23,'[4]Pay sheet-MARCH- 2022'!$C$7:$AF$147,25,0) -> 200 | AL23: =VLOOKUP(A23,'[5]Pay sheet-APRIL- 2022'!$C$7:$AF$137,24,0) -> 0 | AM23: =VLOOKUP(A23,'[4]Pay sheet-MARCH- 2022'!$C$7:$AF$147,27,0) -> 335 | AN23: =AI23+AJ23+AK23+AL23+AM23 -> 2335 | AO23: =AH23-AN23 -> 26896.295 | AP23: 44686 | AQ23: ICICI BANK | AR23: 602601522530 | AU23: 52 | AV23: 8
A24: BITS-607 | B24: Kumaravel M | C24: 30142 | D24: MALE | E24: Madhavaraj | F24: Sr. Network Administrator | G24: NO 88, Arvind Nagar, 5th Street, Madambakkam, Chennai, 600126 | H24: NO 88, Arvind Nagar, 5th Street, Madambakkam, Chennai, 600126 | I24: 44396 | N24: 101273936714 | O24: N/A | P24: =B24 -> Kumaravel M | Q24: 30 | R24: =VLOOKUP(A24,'[5]Pay sheet-APRIL- 2022'!$C$7:$AF$137,10,0) -> 30 | S24: N/A | T24: 47836 | U24: =VLOOKUP(A24,'[5]Pay sheet-APRIL- 2022'!$C$7:$AF$137,11,0) -> 28701.6 | V24: 0 | W24: 0 | X24: =Y24+Z24+AA24+AB24 -> 19247.4 | Y24: =VLOOKUP(A24,'[5]Pay sheet-APRIL- 2022'!$C$7:$AF$137,12,0) -> 11480.64 | Z24: =VLOOKUP(A24,'[5]Pay sheet-APRIL- 2022'!$C$7:$AF$137,13,0) -> 2083 | AA24: =VLOOKUP(A24,'[5]Pay sheet-APRIL- 2022'!$C$7:$AF$137,14,0) -> 2083 | AB24: =VLOOKUP(A24,'[5]Pay sheet-APRIL- 2022'!$C$7:$AF$137,15,0) -> 3600.76 | AC24: =U24+X24 -> 47949 | AD24: =VLOOKUP(A24,'[5]Pay sheet-APRIL- 2022'!$C$7:$AF$137,18,0) -> 1554.609 | AE24: =VLOOKUP(A24,'[5]Pay sheet-APRIL- 2022'!$C$7:$AF$137,19,0) -> 1380.547 | AF24: =VLOOKUP(A24,'[5]Pay sheet-APRIL- 2022'!$C$7:$AF$137,20,0) -> 2391.8 | AG24: =VLOOKUP(A24,'[5]Pay sheet-APRIL- 2022'!$C$7:$AF$137,22,0) -> 0 | AH24: =AC24+AD24+AE24+AF24+AG24 -> 53275.956 | AI24: 0 | AJ24: =VLOOKUP(A24,'[4]Pay sheet-MARCH- 2022'!$C$7:$AF$147,26,0) -> 1800 | AK24: =VLOOKUP(A24,'[4]Pay sheet-MARCH- 2022'!$C$7:$AF$147,25,0) -> 200 | AL24: =VLOOKUP(A24,'[5]Pay sheet-APRIL- 2022'!$C$7:$AF$137,24,0) -> 0 | AM24: =VLOOKUP(A24,'[4]Pay sheet-MARCH- 2022'!$C$7:$AF$147,27,0) -> 335 | AN24: =AI24+AJ24+AK24+AL24+AM24 -> 2335 | AO24: =AH24-AN24 -> 50940.956 | AP24: 44686 | AQ24: Indian Bank | AR24: 443843855 | AU24: 53 | AV24: 9
A25: BITS-609 | B25: CHANDRASEHARAN GERORGE | C25: 27181 | D25: MALE | E25: George | F25: SENIOR TECHNICAL SPECIALIST | G25: PLOT NO.88, KAMALALAYAM 2, M.G.NAGAR 2, URAPAKKAM - 603211 | H25: PLOT NO.88, KAMALALAYAM 2, M.G.NAGAR 2, URAPAKKAM - 603211 | I25: 44396 | N25: 100123005976 | O25: N/A | P25: =B25 -> CHANDRASEHARAN GERORGE | Q25: 30 | R25: =VLOOKUP(A25,'[5]Pay sheet-APRIL- 2022'!$C$7:$AF$137,10,0) -> 15 | S25: N/A | T25: 50617 | U25: =VLOOKUP(A25,'[5]Pay sheet-APRIL- 2022'!$C$7:$AF$137,11,0) -> 15185.1 | V25: 0 | W25: 0 | X25: =Y25+Z25+AA25+AB25 -> 10236.4 | Y25: =VLOOKUP(A25,'[5]Pay sheet-APRIL- 2022'!$C$7:$AF$137,12,0) -> 6074.04 | Z25: =VLOOKUP(A25,'[5]Pay sheet-APRIL- 2022'!$C$7:$AF$137,13,0) -> 1042 | AA25: =VLOOKUP(A25,'[5]Pay sheet-APRIL- 2022'!$C$7:$AF$137,14,0) -> 1042 | AB25: =VLOOKUP(A25,'[5]Pay sheet-APRIL- 2022'!$C$7:$AF$137,15,0) -> 2078.36 | AC25: =U25+X25 -> 25421.5 | AD25: =VLOOKUP(A25,'[5]Pay sheet-APRIL- 2022'!$C$7:$AF$137,18,0) -> 1554.609 | AE25: =VLOOKUP(A25,'[5]Pay sheet-APRIL- 2022'!$C$7:$AF$137,19,0) -> 730.40331 | AF25: =VLOOKUP(A25,'[5]Pay sheet-APRIL- 2022'!$C$7:$AF$137,20,0) -> 1265.425 | AG25: =VLOOKUP(A25,'[5]Pay sheet-APRIL- 2022'!$C$7:$AF$137,22,0) -> 0 | AH25: =AC25+AD25+AE25+AF25+AG25 -> 28971.937 | AI25: 0 | AJ25: =VLOOKUP(A25,'[4]Pay sheet-MARCH- 2022'!$C$7:$AF$147,26,0) -> 1800 | AK25: =VLOOKUP(A25,'[4]Pay sheet-MARCH- 2022'!$C$7:$AF$147,25,0) -> 200 | AL25: =VLOOKUP(A25,'[5]Pay sheet-APRIL- 2022'!$C$7:$AF$137,24,0) -> 0 | AM25: =VLOOKUP(A25,'[4]Pay sheet-MARCH- 2022'!$C$7:$AF$147,27,0) -> 335 | AN25: =AI25+AJ25+AK25+AL25+AM25 -> 2335 | AO25: =AH25-AN25 -> 26636.937 | AP25: 44686 | AQ25: Standard Charter Bank | AR25: 42610387037 | AU25: 55 | AV25: 10
A26: BITS-611 | B26: VISHNUPRASATH T | C26: 33729 | D26: MALE | E26: Thavamani | F26: Sr. Network Engineer | G26: 1/97, Kilmettu st, Villvarani PO, Kalasapakkam taluk, Tiruvannamalai dt, Tamilnadu PIN-606906 | H26: 1/97, Kilmettu st, Villvarani PO, Kalasapakkam taluk, Tiruvannamalai dt, Tamilnadu PIN-606906 | I26: 44396 | N26: 100910953478 | O26: N/A | P26: =B26 -> VISHNUPRASATH T | Q26: 30 | R26: =VLOOKUP(A26,'[5]Pay sheet-APRIL- 2022'!$C$7:$AF$137,10,0) -> 30 | S26: N/A | T26: 47836 | U26: =VLOOKUP(A26,'[5]Pay sheet-APRIL- 2022'!$C$7:$AF$137,11,0) -> 28701.6 | V26: 0 | W26: 0 | X26: =Y26+Z26+AA26+AB26 -> 19247.4 | Y26: =VLOOKUP(A26,'[5]Pay sheet-APRIL- 2022'!$C$7:$AF$137,12,0) -> 11480.64 | Z26: =VLOOKUP(A26,'[5]Pay sheet-APRIL- 2022'!$C$7:$AF$137,13,0) -> 2083 | AA26: =VLOOKUP(A26,'[5]Pay sheet-APRIL- 2022'!$C$7:$AF$137,14,0) -> 2083 | AB26: =VLOOKUP(A26,'[5]Pay sheet-APRIL- 2022'!$C$7:$AF$137,15,0) -> 3600.76 | AC26: =U26+X26 -> 47949 | AD26: =VLOOKUP(A26,'[5]Pay sheet-APRIL- 2022'!$C$7:$AF$137,18,0) -> 1554.609 | AE26: =VLOOKUP(A26,'[5]Pay sheet-APRIL- 2022'!$C$7:$AF$137,19,0) -> 1380.547 | AF26: =VLOOKUP(A26,'[5]Pay sheet-APRIL- 2022'!$C$7:$AF$137,20,0) -> 2391.8 | AG26: =VLOOKUP(A26,'[5]Pay sheet-APRIL- 2022'!$C$7:$AF$137,22,0) -> 0 | AH26: =AC26+AD26+AE26+AF26+AG26 -> 53275.956 | AI26: 0 | AJ26: =VLOOKUP(A26,'[4]Pay sheet-MARCH- 2022'!$C$7:$AF$147,26,0) -> 1800 | AK26: =VLOOKUP(A26,'[4]Pay sheet-MARCH- 2022'!$C$7:$AF$147,25,0) -> 200 | AL26: =VLOOKUP(A26,'[5]Pay sheet-APRIL- 2022'!$C$7:$AF$137,24,0) -> 0 | AM26: =VLOOKUP(A26,'[4]Pay sheet-MARCH- 2022'!$C$7:$AF$147,27,0) -> 335 | AN26: =AI26+AJ26+AK26+AL26+AM26 -> 2335 | AO26: =AH26-AN26 -> 50940.956 | AP26: 44686 | AQ26: ICICI BANK | AR26: 270401504431 | AU26: 57 | AV26: 11
A27: BITS-612 | B27: Nagaranjan S | C27: 19.06.1981 | D27: MALE | E27: SUBBIAH G | F27: Linux Administrator | G27: 4\122,V.Sundaralingapuram,Pavali(PO),Virudhunagar(DT)-626103 | H27: 5\1, 1st floor,3rd cross street,BalajiNagar,Kolathur,Chennai-600099 | I27: 44396 | N27: 100363582963 | O27: N/A | P27: =B27 -> Nagaranjan S | Q27: 30 | R27: =VLOOKUP(A27,'[5]Pay sheet-APRIL- 2022'!$C$7:$AF$137,10,0) -> 30 | S27: N/A | T27: 47836 | U27: =VLOOKUP(A27,'[5]Pay sheet-APRIL- 2022'!$C$7:$AF$137,11,0) -> 28701.6 | V27: 0 | W27: 0 | X27: =Y27+Z27+AA27+AB27 -> 19247.4 | Y27: =VLOOKUP(A27,'[5]Pay sheet-APRIL- 2022'!$C$7:$AF$137,12,0) -> 11480.64 | Z27: =VLOOKUP(A27,'[5]Pay sheet-APRIL- 2022'!$C$7:$AF$137,13,0) -> 2083 | AA27: =VLOOKUP(A27,'[5]Pay sheet-APRIL- 2022'!$C$7:$AF$137,14,0) -> 2083 | AB27: =VLOOKUP(A27,'[5]Pay sheet-APRIL- 2022'!$C$7:$AF$137,15,0) -> 3600.76 | AC27: =U27+X27 -> 47949 | AD27: =VLOOKUP(A27,'[5]Pay sheet-APRIL- 2022'!$C$7:$AF$137,18,0) -> 1554.609 | AE27: =VLOOKUP(A27,'[5]Pay sheet-APRIL- 2022'!$C$7:$AF$137,19,0) -> 1380.547 | AF27: =VLOOKUP(A27,'[5]Pay sheet-APRIL- 2022'!$C$7:$AF$137,20,0) -> 2391.8 | AG27: =VLOOKUP(A27,'[5]Pay sheet-APRIL- 2022'!$C$7:$AF$137,22,0) -> 0 | AH27: =AC27+AD27+AE27+AF27+AG27 -> 53275.956 | AI27: 0 | AJ27: =VLOOKUP(A27,'[4]Pay sheet-MARCH- 2022'!$C$7:$AF$147,26,0) -> 1800 | AK27: =VLOOKUP(A27,'[4]Pay sheet-MARCH- 2022'!$C$7:$AF$147,25,0) -> 200 | AL27: =VLOOKUP(A27,'[5]Pay sheet-APRIL- 2022'!$C$7:$AF$137,24,0) -> 0 | AM27: =VLOOKUP(A27,'[4]Pay sheet-MARCH- 2022'!$C$7:$AF$147,27,0) -> 335 | AN27: =AI27+AJ27+AK27+AL27+AM27 -> 2335 | AO27: =AH27-AN27 -> 50940.956 | AP27: 44686 | AQ27: IDBI BANK | AR27: 005104000198752 | AU27: 58 | AV27: 12
A28: BITS-613 | B28: ELAMPARITHI SB | C28: 20-02-1986 | D28: MALE | E28: Balasubramanian.S | F28: Senior Network Engineer | G28: 77 - Mela Dhasappa Nayakkan Street , Kanagam Thottam ,East Gate,Thanjavur-613001 | H28: C5 - Orchid Screne Moovendar Nagar Extension, Old Perungalathur , Chennai - 600063 | I28: 44396 | N28: 100500123608 | O28: N/A | P28: =B28 -> ELAMPARITHI SB | Q28: 30 | R28: =VLOOKUP(A28,'[5]Pay sheet-APRIL- 2022'!$C$7:$AF$137,10,0) -> 20 | S28: N/A | T28: 47836 | U28: =VLOOKUP(A28,'[5]Pay sheet-APRIL- 2022'!$C$7:$AF$137,11,0) -> 19134.4 | V28: 0 | W28: 0 | X28: =Y28+Z28+AA28+AB28 -> 12869.267 | Y28: =VLOOKUP(A28,'[5]Pay sheet-APRIL- 2022'!$C$7:$AF$137,12,0) -> 7653.76 | Z28: =VLOOKUP(A28,'[5]Pay sheet-APRIL- 2022'!$C$7:$AF$137,13,0) -> 1389 | AA28: =VLOOKUP(A28,'[5]Pay sheet-APRIL- 2022'!$C$7:$AF$137,14,0) -> 1389 | AB28: =VLOOKUP(A28,'[5]Pay sheet-APRIL- 2022'!$C$7:$AF$137,15,0) -> 2437.5067 | AC28: =U28+X28 -> 32003.667 | AD28: =VLOOKUP(A28,'[5]Pay sheet-APRIL- 2022'!$C$7:$AF$137,18,0) -> 1554.609 | AE28: =VLOOKUP(A28,'[5]Pay sheet-APRIL- 2022'!$C$7:$AF$137,19,0) -> 920.36464 | AF28: =VLOOKUP(A28,'[5]Pay sheet-APRIL- 2022'!$C$7:$AF$137,20,0) -> 1594.5333 | AG28: =VLOOKUP(A28,'[5]Pay sheet-APRIL- 2022'!$C$7:$AF$137,22,0) -> 0 | AH28: =AC28+AD28+AE28+AF28+AG28 -> 36073.174 | AI28: 0 | AJ28: =VLOOKUP(A28,'[4]Pay sheet-MARCH- 2022'!$C$7:$AF$147,26,0) -> 1800 | AK28: =VLOOKUP(A28,'[4]Pay sheet-MARCH- 2022'!$C$7:$AF$147,25,0) -> 200 | AL28: =VLOOKUP(A28,'[5]Pay sheet-APRIL- 2022'!$C$7:$AF$137,24,0) -> 0 | AM28: =VLOOKUP(A28,'[4]Pay sheet-MARCH- 2022'!$C$7:$AF$147,27,0) -> 335 | AN28: =AI28+AJ28+AK28+AL28+AM28 -> 2335 | AO28: =AH28-AN28 -> 33738.174 | AP28: 44686 | AQ28: ICICI | AR28: 060701514623 | AU28: 59 | AV28: 13
A29: BITS-624 | B29: Karthick G | C29: 32831 | D29: MALE | E29: Ganesan | F29: Senior EUC Analyst | G29: 47A,Vallaneri,Koothandan Post,Melavaniyankudi,Sivaganga,Tamil Nadu-630561 | H29: G-02,Teja Residency-01,Coconut Garden Layout,Kodigehalli Main Road, Ayyappa Nagar,KR Puram, Bangalore-560036 | I29: 44419 | N29: 100874601152 | O29: N/A | P29: =B29 -> Karthick G | Q29: 30 | R29: =VLOOKUP(A29,'[5]Pay sheet-APRIL- 2022'!$C$7:$AF$137,10,0) -> 30 | S29: N/A | T29: 89547 | U29: =VLOOKUP(A29,'[5]Pay sheet-APRIL- 2022'!$C$7:$AF$137,11,0) -> 53728.2 | V29: 0 | W29: 0 | X29: =Y29+Z29+AA29+AB29 -> 35931.8 | Y29: =VLOOKUP(A29,'[5]Pay sheet-APRIL- 2022'!$C$7:$AF$137,12,0) -> 21491.28 | Z29: =VLOOKUP(A29,'[5]Pay sheet-APRIL- 2022'!$C$7:$AF$137,13,0) -> 2083 | AA29: =VLOOKUP(A29,'[5]Pay sheet-APRIL- 2022'!$C$7:$AF$137,14,0) -> 2083 | AB29: =VLOOKUP(A29,'[5]Pay sheet-APRIL- 2022'!$C$7:$AF$137,15,0) -> 10274.52 | AC29: =U29+X29 -> 89660 | AD29: =VLOOKUP(A29,'[5]Pay sheet-APRIL- 2022'!$C$7:$AF$137,18,0) -> 1554.609 | AE29: =VLOOKUP(A29,'[5]Pay sheet-APRIL- 2022'!$C$7:$AF$137,19,0) -> 2584.3264 | AF29: =VLOOKUP(A29,'[5]Pay sheet-APRIL- 2022'!$C$7:$AF$137,20,0) -> 4477.35 | AG29: =VLOOKUP(A29,'[5]Pay sheet-APRIL- 2022'!$C$7:$AF$137,22,0) -> 0 | AH29: =AC29+AD29+AE29+AF29+AG29 -> 98276.285 | AI29: 0 | AJ29: =VLOOKUP(A29,'[4]Pay sheet-MARCH- 2022'!$C$7:$AF$147,26,0) -> 1800 | AK29: =VLOOKUP(A29,'[4]Pay sheet-MARCH- 2022'!$C$7:$AF$147,25,0) -> 200 | AL29: =VLOOKUP(A29,'[5]Pay sheet-APRIL- 2022'!$C$7:$AF$137,24,0) -> 0 | AM29: =VLOOKUP(A29,'[4]Pay sheet-MARCH- 2022'!$C$7:$AF$147,27,0) -> 336 | AN29: =AI29+AJ29+AK29+AL29+AM29 -> 2336 | AO29: =AH29-AN29 -> 95940.285 | AP29: 44686 | AQ29: HDFC BANK | AR29: 50100072083437 | AU29: 61 | AV29: 14
A30: BITS-640 | B30: K V Kannan | C30: 29774 | D30: MALE | E30: K C Venkata Kumar | F30: Windows and Assure Administrator | G30: New No.1,old no 43/351,Jyothi ramalingam street,Rajajipuram,Thiruvallur,TN 602001 | H30: New No.1,old no 43/351,Jyothi ramalingam street,Rajajipuram,Thiruvallur,TN 602001 | I30: 44446 | N30: 101275235803 | O30: N/A | P30: K V Kannan | Q30: 30 | R30: =VLOOKUP(A30,'[5]Pay sheet-APRIL- 2022'!$C$7:$AF$137,10,0) -> 30 | S30: N/A | T30: 36713 | U30: =VLOOKUP(A30,'[5]Pay sheet-APRIL- 2022'!$C$7:$AF$137,11,0) -> 22027.8 | V30: 0 | W30: 0 | X30: =Y30+Z30+AA30+AB30 -> 14798.2 | Y30: =VLOOKUP(A30,'[5]Pay sheet-APRIL- 2022'!$C$7:$AF$137,12,0) -> 8811.12 | Z30: =VLOOKUP(A30,'[5]Pay sheet-APRIL- 2022'!$C$7:$AF$137,13,0) -> 2083 | AA30: =VLOOKUP(A30,'[5]Pay sheet-APRIL- 2022'!$C$7:$AF$137,14,0) -> 2083 | AB30: =VLOOKUP(A30,'[5]Pay sheet-APRIL- 2022'!$C$7:$AF$137,15,0) -> 1821.08 | AC30: =U30+X30 -> 36826 | AD30: =VLOOKUP(A30,'[5]Pay sheet-APRIL- 2022'!$C$7:$AF$137,18,0) -> 1554.609 | AE30: =VLOOKUP(A30,'[5]Pay sheet-APRIL- 2022'!$C$7:$AF$137,19,0) -> 1059.5372 | AF30: =VLOOKUP(A30,'[5]Pay sheet-APRIL- 2022'!$C$7:$AF$137,20,0) -> 1835.65 | AG30: =VLOOKUP(A30,'[5]Pay sheet-APRIL- 2022'!$C$7:$AF$137,22,0) -> 0 | AH30: =AC30+AD30+AE30+AF30+AG30 -> 41275.796 | AI30: 0 | AJ30: =VLOOKUP(A30,'[4]Pay sheet-MARCH- 2022'!$C$7:$AF$147,26,0) -> 1800 | AK30: =VLOOKUP(A30,'[4]Pay sheet-MARCH- 2022'!$C$7:$AF$147,25,0) -> 200 | AL30: =VLOOKUP(A30,'[5]Pay sheet-APRIL- 2022'!$C$7:$AF$137,24,0) -> 0 | AM30: =VLOOKUP(A30,'[4]Pay sheet-MARCH- 2022'!$C$7:$AF$147,27,0) -> 252 | AN30: =AI30+AJ30+AK30+AL30+AM30 -> 2252 | AO30: =AH30-AN30 -> 39023.796 | AP30: 44686 | AQ30: INDUSIND BANK | AR30: 100062052877 | AU30: 65 | AV30: 15
A31: BITS-641 | B31: Thanigaivel.J | C31: 34698 | D31: MALE | E31: Jayavelu | F31: Network Engineer | G31: No 6,Load man street,varadharajan nagar,changalpet,chengalpattu,kanchipuram,TN 603002 | H31: No 6,Load man street,varadharajan nagar,changalpet,chengalpattu,kanchipuram,TN 603002 | I31: 44446 | N31: 101131863380 | O31: N/A | P31: Thanigaivel.J | Q31: 30 | R31: =VLOOKUP(A31,'[5]Pay sheet-APRIL- 2022'!$C$7:$AF$137,10,0) -> 30 | S31: N/A | T31: 36713 | U31: =VLOOKUP(A31,'[5]Pay sheet-APRIL- 2022'!$C$7:$AF$137,11,0) -> 22027.8 | V31: 0 | W31: 0 | X31: =Y31+Z31+AA31+AB31 -> 14798.2 | Y31: =VLOOKUP(A31,'[5]Pay sheet-APRIL- 2022'!$C$7:$AF$137,12,0) -> 8811.12 | Z31: =VLOOKUP(A31,'[5]Pay sheet-APRIL- 2022'!$C$7:$AF$137,13,0) -> 2083 | AA31: =VLOOKUP(A31,'[5]Pay sheet-APRIL- 2022'!$C$7:$AF$137,14,0) -> 2083 | AB31: =VLOOKUP(A31,'[5]Pay sheet-APRIL- 2022'!$C$7:$AF$137,15,0) -> 1821.08 | AC31: =U31+X31 -> 36826 | AD31: =VLOOKUP(A31,'[5]Pay sheet-APRIL- 2022'!$C$7:$AF$137,18,0) -> 1554.609 | AE31: =VLOOKUP(A31,'[5]Pay sheet-APRIL- 2022'!$C$7:$AF$137,19,0) -> 1059.5372 | AF31: =VLOOKUP(A31,'[5]Pay sheet-APRIL- 2022'!$C$7:$AF$137,20,0) -> 1835.65 | AG31: =VLOOKUP(A31,'[5]Pay sheet-APRIL- 2022'!$C$7:$AF$137,22,0) -> 0 | AH31: =AC31+AD31+AE31+AF31+AG31 -> 41275.796 | AI31: 0 | AJ31: =VLOOKUP(A31,'[5]Pay sheet-APRIL- 2022'!$C$7:$AF$137,26,0) -> 1800 | AK31: =VLOOKUP(A31,'[5]Pay sheet-APRIL- 2022'!$C$7:$AF$137,25,0) -> 200 | AL31: =VLOOKUP(A31,'[5]Pay sheet-APRIL- 2022'!$C$7:$AF$137,24,0) -> 0 | AM31: =VLOOKUP(A31,'[5]Pay sheet-APRIL- 2022'!$C$7:$AF$137,27,0) -> 224 | AN31: =AI31+AJ31+AK31+AL31+AM31 -> 2224 | AO31: =AH31-AN31 -> 39051.796 | AP31: 44686 | AQ31: AXIS BANK | AR31: 917010045864654 | AU31: 66 | AV31: 16
A32: BITS-659 | B32: Manzoor Ahamed | C32: 31191 | D32: MALE | E32: Syed Rahim | F32: Lead Devops Engineer | G32: D No 426,Karuppanannan house,T B Road,Sankari,Selam,Tamilnadu 637301 | H32: Ground floor,Padmalayam site No 24,4th cross,Vellinganton paradise layout,singa sandra,Bangalore 560068,Karnataka | I32: 44487 | N32: 100551348435 | O32: N/A | P32: =B32 -> Manzoor Ahamed | Q32: 30 | R32: =VLOOKUP(A32,'[5]Pay sheet-APRIL- 2022'!$C$7:$AF$137,10,0) -> 30 | S32: N/A | T32: 223948 | U32: =VLOOKUP(A32,'[5]Pay sheet-APRIL- 2022'!$C$7:$AF$137,11,0) -> 134368.8 | V32: 0 | W32: 0 | X32: =Y32+Z32+AA32+AB32 -> 89692.2 | Y32: =VLOOKUP(A32,'[5]Pay sheet-APRIL- 2022'!$C$7:$AF$137,12,0) -> 53747.52 | Z32: =VLOOKUP(A32,'[5]Pay sheet-APRIL- 2022'!$C$7:$AF$137,13,0) -> 2083 | AA32: =VLOOKUP(A32,'[5]Pay sheet-APRIL- 2022'!$C$7:$AF$137,14,0) -> 2083 | AB32: =VLOOKUP(A32,'[5]Pay sheet-APRIL- 2022'!$C$7:$AF$137,15,0) -> 31778.68 | AC32: =U32+X32 -> 224061 | AD32: =VLOOKUP(A32,'[5]Pay sheet-APRIL- 2022'!$C$7:$AF$137,18,0) -> 1554.609 | AE32: =VLOOKUP(A32,'[5]Pay sheet-APRIL- 2022'!$C$7:$AF$137,19,0) -> 6463.1393 | AF32: =VLOOKUP(A32,'[5]Pay sheet-APRIL- 2022'!$C$7:$AF$137,20,0) -> 11197.4 | AG32: =VLOOKUP(A32,'[5]Pay sheet-APRIL- 2022'!$C$7:$AF$137,22,0) -> 0 | AH32: =AC32+AD32+AE32+AF32+AG32 -> 243276.15 | AI32: 0 | AJ32: =VLOOKUP(A32,'[5]Pay sheet-APRIL- 2022'!$C$7:$AF$137,26,0) -> 1800 | AK32: =VLOOKUP(A32,'[5]Pay sheet-APRIL- 2022'!$C$7:$AF$137,25,0) -> 200 | AL32: =VLOOKUP(A32,'[5]Pay sheet-APRIL- 2022'!$C$7:$AF$137,24,0) -> 0 | AM32: =VLOOKUP(A32,'[5]Pay sheet-APRIL- 2022'!$C$7:$AF$137,27,0) -> 286 | AN32: =AI32+AJ32+AK32+AL32+AM32 -> 2286 | AO32: =AH32-AN32 -> 240990.15 | AP32: 44686 | AQ32: CITI Bank | AR32: 5153635813 | AU32: 70 | AV32: 17
A33: BITS-671 | B33: Ramakrishna J Reddy | C33: 33048 | D33: MALE | E33: Satyanarayana Reddy | F33: SENIOR SAP ABAP CONSULTANT | G33: 7-20-1092/A,28th line,Sarada colony,Guntur 522002,AP | H33: 7-20-1092/A,28th line,Sarada colony,Guntur 522002,AP | I33: 44512 | N33: 100453787600 | O33: N/A | P33: =B33 -> Ramakrishna J Reddy | Q33: 30 | R33: =VLOOKUP(A33,'[5]Pay sheet-APRIL- 2022'!$C$7:$AF$137,10,0) -> 28 | S33: N/A | T33: 191506 | U33: =VLOOKUP(A33,'[5]Pay sheet-APRIL- 2022'!$C$7:$AF$137,11,0) -> 107243.36 | V33: 0 | W33: 0 | X33: =Y33+Z33+AA33+AB33 -> 71608.573 | Y33: =VLOOKUP(A33,'[5]Pay sheet-APRIL- 2022'!$C$7:$AF$137,12,0) -> 42897.344 | Z33: =VLOOKUP(A33,'[5]Pay sheet-APRIL- 2022'!$C$7:$AF$137,13,0) -> 1944 | AA33: =VLOOKUP(A33,'[5]Pay sheet-APRIL- 2022'!$C$7:$AF$137,14,0) -> 1944 | AB33: =VLOOKUP(A33,'[5]Pay sheet-APRIL- 2022'!$C$7:$AF$137,15,0) -> 24823.229 | AC33: =U33+X33 -> 178851.93 | AD33: =VLOOKUP(A33,'[5]Pay sheet-APRIL- 2022'!$C$7:$AF$137,18,0) -> 1554.609 | AE33: =VLOOKUP(A33,'[5]Pay sheet-APRIL- 2022'!$C$7:$AF$137,19,0) -> 5158.4056 | AF33: =VLOOKUP(A33,'[5]Pay sheet-APRIL- 2022'!$C$7:$AF$137,20,0) -> 8936.9467 | AG33: =VLOOKUP(A33,'[5]Pay sheet-APRIL- 2022'!$C$7:$AF$137,22,0) -> 0 | AH33: =AC33+AD33+AE33+AF33+AG33 -> 194501.89 | AI33: 0 | AJ33: =VLOOKUP(A33,'[5]Pay sheet-APRIL- 2022'!$C$7:$AF$137,26,0) -> 1800 | AK33: =VLOOKUP(A33,'[5]Pay sheet-APRIL- 2022'!$C$7:$AF$137,25,0) -> 200 | AL33: =VLOOKUP(A33,'[5]Pay sheet-APRIL- 2022'!$C$7:$AF$137,24,0) -> 0 | AM33: =VLOOKUP(A33,'[5]Pay sheet-APRIL- 2022'!$C$7:$AF$137,27,0) -> 252 | AN33: =AI33+AJ33+AK33+AL33+AM33 -> 2252 | AO33: =AH33-AN33 -> 192249.89 | AP33: 44686 | AQ33: HDFC BANK | AR33: 50100216035976 | AU33: 71 | AV33: 18
A34: BITS-645 | B34: Anil kumar Reddy kusam | C34: 32974 | D34: MALE | E34: Pulla Reddy | F34: Associate Consultant | G34: 2-36,B.Jwalapuram,Singamavula Mandal,Ananthapur,AP 515435 | H34: 2-36,B.Jwalapuram,Singamavula Mandal,Ananthapur,AP 515435 | I34: 44459 | N34: 101182432317 | O34: N/A | P34: =B34 -> Anil kumar Reddy kusam | Q34: 30 | R34: =VLOOKUP(A34,'[5]Pay sheet-APRIL- 2022'!$C$7:$AF$137,10,0) -> 30 | S34: N/A | T34: 80278 | U34: 48167 | V34: 0 | W34: 0 | X34: =Y34+Z34+AA34+AB34 -> 32224 | Y34: 19267 | Z34: =VLOOKUP(A34,'[5]Pay sheet-APRIL- 2022'!$C$7:$AF$137,13,0) -> 2083 | AA34: =VLOOKUP(A34,'[5]Pay sheet-APRIL- 2022'!$C$7:$AF$137,14,0) -> 2083 | AB34: 8791 | AC34: =U34+X34 -> 80391 | AD34: =VLOOKUP(A34,'[5]Pay sheet-APRIL- 2022'!$C$7:$AF$137,18,0) -> 1554.609 | AE34: 2317 | AF34: 4014 | AG34: =VLOOKUP(A34,'[5]Pay sheet-APRIL- 2022'!$C$7:$AF$137,22,0) -> 0 | AH34: =AC34+AD34+AE34+AF34+AG34 -> 88276.609 | AI34: 0 | AJ34: =VLOOKUP(A34,'[5]Pay sheet-APRIL- 2022'!$C$7:$AF$137,26,0) -> 1800 | AK34: =VLOOKUP(A34,'[5]Pay sheet-APRIL- 2022'!$C$7:$AF$137,25,0) -> 200 | AL34: =VLOOKUP(A34,'[5]Pay sheet-APRIL- 2022'!$C$7:$AF$137,24,0) -> 0 | AM34: 224 | AN34: =AI34+AJ34+AK34+AL34+AM34 -> 2224 | AO34: =AH34-AN34 -> 86052.609 | AP34: 44686 | AQ34: ICICI BANK | AR34: 020201566128 | AU34: 68 | AV34: 19 | AW34: v-lookkup troubling
A35: BITS-679 | B35: Praveen Kumar Tandra | C35: 30287 | D35: MALE | E35: Ram reddy Tandra | F35: Sr.Linux Admin | G35: 1-156,Boinapally,Midjil,Mahabubnagar District,Telangan 509357 | H35: 303,CBR Enclave2,Road No.2,Triveni nagar,Balapur cross roads,Hyderabad,Telangana 500097 | I35: 44536 | J35: OOOO | K35: OOOO | L35: OOOO | M35: OOOO | N35: 100279367972 | O35: N/A | P35: Praveen Kumar Tandra | Q35: 30 | R35: =VLOOKUP(A35,'[5]Pay sheet-APRIL- 2022'!$C$7:$AF$137,10,0) -> 30 | S35: N/A | T35: 98816 | U35: =VLOOKUP(A35,'[5]Pay sheet-APRIL- 2022'!$C$7:$AF$137,11,0) -> 59289.6 | V35: 0 | W35: 0 | X35: =Y35+Z35+AA35+AB35 -> 39639.4 | Y35: =VLOOKUP(A35,'[5]Pay sheet-APRIL- 2022'!$C$7:$AF$137,12,0) -> 23715.84 | Z35: =VLOOKUP(A35,'[5]Pay sheet-APRIL- 2022'!$C$7:$AF$137,13,0) -> 2083 | AA35: =VLOOKUP(A35,'[5]Pay sheet-APRIL- 2022'!$C$7:$AF$137,14,0) -> 2083 | AB35: =VLOOKUP(A35,'[5]Pay sheet-APRIL- 2022'!$C$7:$AF$137,15,0) -> 11757.56 | AC35: =U35+X35 -> 98929 | AD35: =VLOOKUP(A35,'[5]Pay sheet-APRIL- 2022'!$C$7:$AF$137,18,0) -> 1554.609 | AE35: =VLOOKUP(A35,'[5]Pay sheet-APRIL- 2022'!$C$7:$AF$137,19,0) -> 2851.8298 | AF35: =VLOOKUP(A35,'[5]Pay sheet-APRIL- 2022'!$C$7:$AF$137,20,0) -> 4940.8 | AG35: =VLOOKUP(A35,'[5]Pay sheet-APRIL- 2022'!$C$7:$AF$137,22,0) -> 0 | AH35: =AC35+AD35+AE35+AF35+AG35 -> 108276.24 | AI35: 0 | AJ35: =VLOOKUP(A35,'[5]Pay sheet-APRIL- 2022'!$C$7:$AF$137,26,0) -> 1800 | AK35: =VLOOKUP(A35,'[5]Pay sheet-APRIL- 2022'!$C$7:$AF$137,25,0) -> 200 | AL35: =VLOOKUP(A35,'[5]Pay sheet-APRIL- 2022'!$C$7:$AF$137,24,0) -> 0 | AM35: =VLOOKUP(A35,'[5]Pay sheet-APRIL- 2022'!$C$7:$AF$137,27,0) -> 283 | AN35: =AI35+AJ35+AK35+AL35+AM35 -> 2283 | AO35: =AH35-AN35 -> 105993.24 | AP35: 44686 | AQ35: HDFC BANK | AR35: 00008099320 | AU35: 72 | AV35: 20
A36: BITS-689 | B36: Nagarjun KV | C36: 31644 | D36: MALE | E36: Arpitha R | F36: Technical Consultant | G36: #66\E, 3rd C Main, Raghavendra Layout, Hulimavu, Bangalore - 560076 | H36: #66\E, 3rd C Main, Raghavendra Layout, Hulimavu, Bangalore - 560076 | I36: 44564 | J36: OOOO | K36: OOOO | L36: OOOO | M36: OOOO | N36: 100247870639 | O36: N/A | P36: Nagarjun KV | Q36: 30 | R36: =VLOOKUP(A36,'[5]Pay sheet-APRIL- 2022'!$C$7:$AF$137,10,0) -> 30 | S36: N/A | T36: 75643 | U36: =VLOOKUP(A36,'[5]Pay sheet-APRIL- 2022'!$C$7:$AF$137,11,0) -> 45385.8 | V36: 0 | W36: 0 | X36: =Y36+Z36+AA36+AB36 -> 30370.2 | Y36: =VLOOKUP(A36,'[5]Pay sheet-APRIL- 2022'!$C$7:$AF$137,12,0) -> 18154.32 | Z36: =VLOOKUP(A36,'[5]Pay sheet-APRIL- 2022'!$C$7:$AF$137,13,0) -> 2083 | AA36: =VLOOKUP(A36,'[5]Pay sheet-APRIL- 2022'!$C$7:$AF$137,14,0) -> 2083 | AB36: =VLOOKUP(A36,'[5]Pay sheet-APRIL- 2022'!$C$7:$AF$137,15,0) -> 8049.88 | AC36: =U36+X36 -> 75756 | AD36: =VLOOKUP(A36,'[5]Pay sheet-APRIL- 2022'!$C$7:$AF$137,18,0) -> 1554.609 | AE36: =VLOOKUP(A36,'[5]Pay sheet-APRIL- 2022'!$C$7:$AF$137,19,0) -> 2183.057 | AF36: =VLOOKUP(A36,'[5]Pay sheet-APRIL- 2022'!$C$7:$AF$137,20,0) -> 3782.15 | AG36: =VLOOKUP(A36,'[5]Pay sheet-APRIL- 2022'!$C$7:$AF$137,22,0) -> 0 | AH36: =AC36+AD36+AE36+AF36+AG36 -> 83275.816 | AI36: 0 | AJ36: =VLOOKUP(A36,'[5]Pay sheet-APRIL- 2022'!$C$7:$AF$137,26,0) -> 1800 | AK36: =VLOOKUP(A36,'[5]Pay sheet-APRIL- 2022'!$C$7:$AF$137,25,0) -> 200 | AL36: =VLOOKUP(A36,'[5]Pay sheet-APRIL- 2022'!$C$7:$AF$137,24,0) -> 0 | AM36: =VLOOKUP(A36,'[5]Pay sheet-APRIL- 2022'!$C$7:$AF$137,27,0) -> 283 | AN36: =AI36+AJ36+AK36+AL36+AM36 -> 2283 | AO36: =AH36-AN36 -> 80992.816 | AP36: 44686 | AQ36: STATE BANK OF INDIA | AR36: 20174267977 | AU36: 74 | AV36: 21
A37: BITS-691 | B37: Boopathi Palani | C37: 33749 | D37: MALE | E37: M.Palani | F37: Senior Technology Analyst | G37: kadayapatti village, Thippampatti PO, Dharmapuri Dist 635202 | H37: kadayapatti village, Thippampatti PO, Dharmapuri Dist 635202 | I37: 44564 | J37: OOOO | K37: OOOO | L37: OOOO | M37: OOOO | N37: 101153836004 | O37: N/A | P37: Boopathi Palani | Q37: 30 | R37: =VLOOKUP(A37,'[5]Pay sheet-APRIL- 2022'!$C$7:$AF$137,10,0) -> 30 | S37: N/A | T37: 75643 | U37: =VLOOKUP(A37,'[5]Pay sheet-APRIL- 2022'!$C$7:$AF$137,11,0) -> 45385.8 | V37: 0 | W37: 0 | X37: =Y37+Z37+AA37+AB37 -> 30370.2 | Y37: =VLOOKUP(A37,'[5]Pay sheet-APRIL- 2022'!$C$7:$AF$137,12,0) -> 18154.32 | Z37: =VLOOKUP(A37,'[5]Pay sheet-APRIL- 2022'!$C$7:$AF$137,13,0) -> 2083 | AA37: =VLOOKUP(A37,'[5]Pay sheet-APRIL- 2022'!$C$7:$AF$137,14,0) -> 2083 | AB37: =VLOOKUP(A37,'[5]Pay sheet-APRIL- 2022'!$C$7:$AF$137,15,0) -> 8049.88 | AC37: =U37+X37 -> 75756 | AD37: =VLOOKUP(A37,'[5]Pay sheet-APRIL- 2022'!$C$7:$AF$137,18,0) -> 1554.609 | AE37: =VLOOKUP(A37,'[5]Pay sheet-APRIL- 2022'!$C$7:$AF$137,19,0) -> 2183.057 | AF37: =VLOOKUP(A37,'[5]Pay sheet-APRIL- 2022'!$C$7:$AF$137,20,0) -> 3782.15 | AG37: =VLOOKUP(A37,'[5]Pay sheet-APRIL- 2022'!$C$7:$AF$137,22,0) -> 0 | AH37: =AC37+AD37+AE37+AF37+AG37 -> 83275.816 | AI37: 0 | AJ37: =VLOOKUP(A37,'[5]Pay sheet-APRIL- 2022'!$C$7:$AF$137,26,0) -> 1800 | AK37: =VLOOKUP(A37,'[5]Pay sheet-APRIL- 2022'!$C$7:$AF$137,25,0) -> 200 | AL37: =VLOOKUP(A37,'[5]Pay sheet-APRIL- 2022'!$C$7:$AF$137,24,0) -> 0 | AM37: =VLOOKUP(A37,'[5]Pay sheet-APRIL- 2022'!$C$7:$AF$137,27,0) -> 283 | AN37: =AI37+AJ37+AK37+AL37+AM37 -> 2283 | AO37: =AH37-AN37 -> 80992.816 | AP37: 44686 | AQ37: ICICI BANK | AR37: 603601537940 | AU37: 75 | AV37: 22
A38: BITS-693 | B38: JNANESWARARAO G | C38: 31527 | D38: MALE | E38: Subba Rao | F38: SENIOR SOFTWARE ENGINEER- MongoDB DBA | G38: H No 1-57/338,Sreeram nagar,Kondapur,Hyderabad 500084 | H38: H No 1-57/338,Sreeram nagar,Kondapur,Hyderabad 500084 | I38: 44562 | J38: OOOO | K38: OOOO | L38: OOOO | M38: OOOO | N38: 100848702184 | O38: N/A | P38: JNANESWARARAO G | Q38: 30 | R38: =VLOOKUP(A38,'[5]Pay sheet-APRIL- 2022'!$C$7:$AF$137,10,0) -> 30 | S38: N/A | T38: 96962 | U38: =VLOOKUP(A38,'[5]Pay sheet-APRIL- 2022'!$C$7:$AF$137,11,0) -> 58177.2 | V38: 0 | W38: 0 | X38: =Y38+Z38+AA38+AB38 -> 38897.8 | Y38: =VLOOKUP(A38,'[5]Pay sheet-APRIL- 2022'!$C$7:$AF$137,12,0) -> 23270.88 | Z38: =VLOOKUP(A38,'[5]Pay sheet-APRIL- 2022'!$C$7:$AF$137,13,0) -> 2083 | AA38: =VLOOKUP(A38,'[5]Pay sheet-APRIL- 2022'!$C$7:$AF$137,14,0) -> 2083 | AB38: =VLOOKUP(A38,'[5]Pay sheet-APRIL- 2022'!$C$7:$AF$137,15,0) -> 11460.92 | AC38: =U38+X38 -> 97075 | AD38: =VLOOKUP(A38,'[5]Pay sheet-APRIL- 2022'!$C$7:$AF$137,18,0) -> 1554.609 | AE38: =VLOOKUP(A38,'[5]Pay sheet-APRIL- 2022'!$C$7:$AF$137,19,0) -> 2798.3233 | AF38: =VLOOKUP(A38,'[5]Pay sheet-APRIL- 2022'!$C$7:$AF$137,20,0) -> 4848.1 | AG38: =VLOOKUP(A38,'[5]Pay sheet-APRIL- 2022'!$C$7:$AF$137,22,0) -> 14400 | AH38: =AC38+AD38+AE38+AF38+AG38 -> 120676.03 | AI38: 0 | AJ38: =VLOOKUP(A38,'[5]Pay sheet-APRIL- 2022'!$C$7:$AF$137,26,0) -> 1800 | AK38: =VLOOKUP(A38,'[5]Pay sheet-APRIL- 2022'!$C$7:$AF$137,25,0) -> 200 | AL38: =VLOOKUP(A38,'[5]Pay sheet-APRIL- 2022'!$C$7:$AF$137,24,0) -> 0 | AM38: =VLOOKUP(A38,'[5]Pay sheet-APRIL- 2022'!$C$7:$AF$137,27,0) -> 283 | AN38: =AI38+AJ38+AK38+AL38+AM38 -> 2283 | AO38: =AH38-AN38 -> 118393.03 | AP38: 44686 | AQ38: STATE BANK OF INDIA | AR38: 62404945568 | AU38: 76 | AV38: 23
A39: BITS-701 | B39: Shridhar Madlur | C39: 33977 | D39: MALE | E39: Hanamantappa Madlur | F39: Network Engineer | G39: Devaraj Aras Colony, Behind Eshwar Park, Koppal - 583231,Bangalore | H39: No. 36, Hari Nivas, 1st Block, 1st Main, BEL L/O, Vidyaranyapura Bengaluru-560097. | I39: 44594 | J39: OOOO | K39: OOOO | L39: OOOO | M39: OOOO | N39: 101364625395 | O39: N/A | P39: Shridhar Madlur | Q39: 30 | R39: =VLOOKUP(A39,'[5]Pay sheet-APRIL- 2022'!$C$7:$AF$137,10,0) -> 30 | S39: N/A | T39: 50617 | U39: =VLOOKUP(A39,'[5]Pay sheet-APRIL- 2022'!$C$7:$AF$137,11,0) -> 30370.2 | V39: 0 | W39: 0 | X39: =Y39+Z39+AA39+AB39 -> 20359.8 | Y39: =VLOOKUP(A39,'[5]Pay sheet-APRIL- 2022'!$C$7:$AF$137,12,0) -> 12148.08 | Z39: =VLOOKUP(A39,'[5]Pay sheet-APRIL- 2022'!$C$7:$AF$137,13,0) -> 2083 | AA39: =VLOOKUP(A39,'[5]Pay sheet-APRIL- 2022'!$C$7:$AF$137,14,0) -> 2083 | AB39: =VLOOKUP(A39,'[5]Pay sheet-APRIL- 2022'!$C$7:$AF$137,15,0) -> 4045.72 | AC39: =U39+X39 -> 50730 | AD39: =VLOOKUP(A39,'[5]Pay sheet-APRIL- 2022'!$C$7:$AF$137,18,0) -> 1554.609 | AE39: =VLOOKUP(A39,'[5]Pay sheet-APRIL- 2022'!$C$7:$AF$137,19,0) -> 1460.8066 | AF39: =VLOOKUP(A39,'[5]Pay sheet-APRIL- 2022'!$C$7:$AF$137,20,0) -> 2530.85 | AG39: =VLOOKUP(A39,'[5]Pay sheet-APRIL- 2022'!$C$7:$AF$137,22,0) -> 0 | AH39: =AC39+AD39+AE39+AF39+AG39 -> 56276.266 | AI39: 0 | AJ39: =VLOOKUP(A39,'[5]Pay sheet-APRIL- 2022'!$C$7:$AF$137,26,0) -> 1800 | AK39: =VLOOKUP(A39,'[5]Pay sheet-APRIL- 2022'!$C$7:$AF$137,25,0) -> 200 | AL39: =VLOOKUP(A39,'[5]Pay sheet-APRIL- 2022'!$C$7:$AF$137,24,0) -> 0 | AM39: =VLOOKUP(A39,'[5]Pay sheet-APRIL- 2022'!$C$7:$AF$137,27,0) -> 283 | AN39: =AI39+AJ39+AK39+AL39+AM39 -> 2283 | AO39: =AH39-AN39 -> 53993.266 | AP39: 44686 | AQ39: ICICI Bank | AR39: 93701529580 | AU39: 77 | AV39: 24
A40: BITS-702 | B40: Samarjit Saha | C40: 09-05-1978 | D40: MALE | E40: Gopal Chandra Saha | F40: Devopers Specialist | G40: 110,Sucheta Nagar-2, Rajmahal Apartment, 3rd floor,P.O:Haltu, Dist: South 24 Paraganas,City:Kolkata. State:West Bengal | H40: 110,Sucheta Nagar-2, Rajmahal Apartment, 3rd floor,P.O:Haltu, Dist: South 24 Paraganas,City:Kolkata. State:West Bengal | I40: 44594 | J40: OOOO | K40: OOOO | L40: OOOO | M40: OOOO | N40: 100329306766 | O40: N/A | P40: Samarjit Saha | Q40: 30 | R40: =VLOOKUP(A40,'[5]Pay sheet-APRIL- 2022'!$C$7:$AF$137,10,0) -> 30 | S40: N/A | T40: 126623 | U40: =VLOOKUP(A40,'[5]Pay sheet-APRIL- 2022'!$C$7:$AF$137,11,0) -> 75973.8 | V40: 0 | W40: 0 | X40: =Y40+Z40+AA40+AB40 -> 50762.2 | Y40: =VLOOKUP(A40,'[5]Pay sheet-APRIL- 2022'!$C$7:$AF$137,12,0) -> 30389.52 | Z40: =VLOOKUP(A40,'[5]Pay sheet-APRIL- 2022'!$C$7:$AF$137,13,0) -> 2083 | AA40: =VLOOKUP(A40,'[5]Pay sheet-APRIL- 2022'!$C$7:$AF$137,14,0) -> 2083 | AB40: =VLOOKUP(A40,'[5]Pay sheet-APRIL- 2022'!$C$7:$AF$137,15,0) -> 16206.68 | AC40: =U40+X40 -> 126736 | AD40: =VLOOKUP(A40,'[5]Pay sheet-APRIL- 2022'!$C$7:$AF$137,18,0) -> 1554.609 | AE40: =VLOOKUP(A40,'[5]Pay sheet-APRIL- 2022'!$C$7:$AF$137,19,0) -> 3654.3398 | AF40: =VLOOKUP(A40,'[5]Pay sheet-APRIL- 2022'!$C$7:$AF$137,20,0) -> 6331.15 | AG40: =VLOOKUP(A40,'[5]Pay sheet-APRIL- 2022'!$C$7:$AF$137,22,0) -> 0 | AH40: =AC40+AD40+AE40+AF40+AG40 -> 138276.1 | AI40: 0 | AJ40: =VLOOKUP(A40,'[5]Pay sheet-APRIL- 2022'!$C$7:$AF$137,26,0) -> 1800 | AK40: =VLOOKUP(A40,'[5]Pay sheet-APRIL- 2022'!$C$7:$AF$137,25,0) -> 200 | AL40: =VLOOKUP(A40,'[5]Pay sheet-APRIL- 2022'!$C$7:$AF$137,24,0) -> 0 | AM40: =VLOOKUP(A40,'[5]Pay sheet-APRIL- 2022'!$C$7:$AF$137,27,0) -> 283 | AN40: =AI40+AJ40+AK40+AL40+AM40 -> 2283 | AO40: =AH40-AN40 -> 135993.1 | AP40: 44686 | AQ40: HDFC | AR40: 5161140000905 | AU40: 78 | AV40: 25
A41: BITS-705 | B41: Narasimha rao Gurazala | C41: 33292 | D41: MALE | E41: G seshaiah | F41: Software Developer | G41: Hno 15-21-237/1,Flat no G2,sattenapally towers,Balaji Nagar,Kukatpally,Hyderabad,500072 | H41: Hno 15-21-237/1,Flat no G2,sattenapally towers,Balaji Nagar,Kukatpally,Hyderabad,500072 | I41: 44602 | J41: OOOO | K41: OOOO | L41: OOOO | M41: OOOO | N41: 100250029678 | O41: N/A | P41: Narasimha rao Gurazala | Q41: 30 | R41: =VLOOKUP(A41,'[5]Pay sheet-APRIL- 2022'!$C$7:$AF$137,10,0) -> 30 | S41: N/A | T41: 89547 | U41: =VLOOKUP(A41,'[5]Pay sheet-APRIL- 2022'!$C$7:$AF$137,11,0) -> 53728.2 | V41: 0 | W41: 0 | X41: =Y41+Z41+AA41+AB41 -> 35931.8 | Y41: =VLOOKUP(A41,'[5]Pay sheet-APRIL- 2022'!$C$7:$AF$137,12,0) -> 21491.28 | Z41: =VLOOKUP(A41,'[5]Pay sheet-APRIL- 2022'!$C$7:$AF$137,13,0) -> 2083 | AA41: =VLOOKUP(A41,'[5]Pay sheet-APRIL- 2022'!$C$7:$AF$137,14,0) -> 2083 | AB41: =VLOOKUP(A41,'[5]Pay sheet-APRIL- 2022'!$C$7:$AF$137,15,0) -> 10274.52 | AC41: =U41+X41 -> 89660 | AD41: =VLOOKUP(A41,'[5]Pay sheet-APRIL- 2022'!$C$7:$AF$137,18,0) -> 1554.609 | AE41: =VLOOKUP(A41,'[5]Pay sheet-APRIL- 2022'!$C$7:$AF$137,19,0) -> 2584.3264 | AF41: =VLOOKUP(A41,'[5]Pay sheet-APRIL- 2022'!$C$7:$AF$137,20,0) -> 4477.35 | AG41: =VLOOKUP(A41,'[5]Pay sheet-APRIL- 2022'!$C$7:$AF$137,22,0) -> 0 | AH41: =AC41+AD41+AE41+AF41+AG41 -> 98276.285 | AI41: 0 | AJ41: =VLOOKUP(A41,'[5]Pay sheet-APRIL- 2022'!$C$7:$AF$137,26,0) -> 1800 | AK41: =VLOOKUP(A41,'[5]Pay sheet-APRIL- 2022'!$C$7:$AF$137,25,0) -> 200 | AL41: =VLOOKUP(A41,'[5]Pay sheet-APRIL- 2022'!$C$7:$AF$137,24,0) -> 0 | AM41: =VLOOKUP(A41,'[5]Pay sheet-APRIL- 2022'!$C$7:$AF$137,27,0) -> 283 | AN41: =AI41+AJ41+AK41+AL41+AM41 -> 2283 | AO41: =AH41-AN41 -> 95993.285 | AP41: 44686 | AQ41: SBI | AR41: 33272355244 | AU41: 79 | AV41: 26
