Workbook

Sheet BOMBAY APRIL  22-WM  Reg
A1: FORM IX- REGISTER OF PERSONS EMPLOYED
A3: (Vide Rule 78(1) (a) (i) of Contract Labour (Regulation and Abolition) Central /Maharastra.Rules 1974
A4: Name and address of Contractor:burgeon IT services Pvt.Ltd. | F4: Name and address of the establishment in / under which contract is carried on: burgeon IT services Pvt.Ltd. Siri mansion LIGH 436 DR.A S Rao nagar,Hyderabad
A5: Siri Mansion LIGB 436 Dr.A S Rao Nagar,Hyderabad
A7: Name and address of Contractor:burgeon IT services Pvt.Ltd. | F7: Name and address of principal employer:
F8: ='BOM 04 22Master'!AP10 -> INFOSYS LTD.85-C Mittal Towers
F9: 8th flour Nariman Point,Maharashtra,400021
A11: S.No | B11: Name and Surname of workman | C11: Age | D11: SEX | E11: Father's/Husband's name | F11: Nature of Employement/Designation | G11: Permanent Home Address of worken | H11: Local Address | I11: Date of commencement of Employment | J11: Signature or Thumb impression of workman | K11: Date of Temination of Employment | M11: Remarks
L12: Reason for Termination
A13: 1 | B13: 2 | C13: 3 | E13: 4 | F13: 5 | G13: 6 | H13: 7 | I13: 8 | J13: 9 | K13: 10 | M13: 11
A14: 1 | B14: Naresh Kumar Kandula | C14: 30263 | D14: M | E14: Lankadasari Saritha | F14: Senior Software Engineer | G14: Flat B-309, H.no 7-1-3 , Shanthi Bagh Apts, Opp to Country Club, Begumpet, Hyd -500016 | H14: Flat B-309, H.no 7-1-3 , Shanthi Bagh Apts, Opp to Country Club, Begumpet, Hyd -500016 | I14: 13-04-2020 | K14: Resigned
A15: 2 | B15: Siddhartha Ambawade | C15: 06.10.1987 | D15: M | E15: Shamrao Ambavade | F15: Project Manager | G15: C-37/0:2, Ajinkyatara CHS, Sector-24, Juinagar, Navi Mumbai-400705 | H15: C-37/0:2, Ajinkyatara CHS, Sector-24, Juinagar, Navi Mumbai-400705 | I15: 43955 | K15: Resigned
A16: 3 | B16: Aniket Kadam | C16: 06.09.1991 | D16: M | E16: Motiram Kadam | F16: Senior Oracle Admin | G16: 303, Sagar Darshan, Juhu versova link road, Andheri W , Mumbai | H16: 303, Sagar Darshan, Juhu versova link road, Andheri W , Mumbai | I16: 44011 | K16: Resigned
A17: 4 | B17: Deepak Suryakanth Gaikwad | C17: 30593 | D17: M | E17: Suryakant gaikwad | F17: Senior Oracle DBA | G17: 1002, D, Dosti Vihar, Vartak Nagar, Thane West, Maharashtra, 400606 | H17: 1002, D, Dosti Vihar, Vartak Nagar, Thane West, Maharashtra, 400606 | I17: 44025 | K17: Resigned
A18: 5 | B18: Jeetendra H. Patil | C18: 29802 | D18: M | E18: Himmat k patil | F18: Senior Consultant | G18: House No. 34 New Balaji Nagar Chorwad Road Parola Dist Jalgaon 425111 | H18: House No. 34 New Balaji Nagar Chorwad Road Parola Dist Jalgaon 425111 | I18: 44025 | K18: Resigned
A19: 6 | B19: Mohammed Sharique Shaikh | C19: 27788 | D19: M | E19: Nilofur Nasim | F19: Sybase DBA | G19: A/5 Eversweet Apartments, 7 Bungalows, Outside Versova Metro Station, Andheri (W), Mumbai 400053 | H19: Mohammed Shaikh, Flat B, 1st Floor, Tower 3, Mughal Compound, Thokar 3, near Shaheen Academy, | I19: 44123 | K19: 44422 | L19: Resinged
A20: 7 | B20: ShyamReddy Kandula | C20: 25-06-1992 | D20: M | E20: Ram Reddy | F20: Oracle DBA | G20: 4-58, Kondaigudem, Garidepally, Suryapet, Telangana - 508201 | H20: 4-58, Kondaigudem, Garidepally, Suryapet, Telangana - 508201 | I20: 44298 | K20: Resigned | L20: Resinged
A21: 8 | B21: Naresh Kumar Kandula | C21: 30263 | D21: M | E21: Lankadasari Saritha | F21: Senior Software Engineer | G21: Flat B-309, H.no 7-1-3 , Shanthi Bagh Apts, Opp to Country Club, Begumpet, Hyd -500016 | H21: Flat B-309, H.no 7-1-3 , Shanthi Bagh Apts, Opp to Country Club, Begumpet, Hyd -500016 | I21: 44340 | K21: Active | L21: Active
J29: Signature of the Contractor with Seal

Sheet BOM 04 22Master
A3: FORM - XIII REGISTER OF WORKMEN EMPLOYED BY CONTRACTOR
B4: (Vide Rule 75 of Contract Labour (Regulation and Abolition) Central/Karnataka Rules 1974)
A5: Name and address of Contractor: | F5: Burgeon IT Services Pvt.Ltd. | AB5: Name and address of Establishemnt in/ under which contract is carried on: | AP5: =F5 -> Burgeon IT Services Pvt.Ltd.
F6: Siri Mansion LIGB 436 Dr.A S Rao Nagar,Hyderabad | AP6: =F6 -> Siri Mansion LIGB 436 Dr.A S Rao Nagar,Hyderabad
AP7: =F7 -> 0
A8: Nature and location of work: | F8: IT SUPPORTIVE SERVICES&MUMBAI
A10: Wage period: Monthly | D10: 44652 | AK10: Name and address of Principal Employer: | AP10: INFOSYS LTD.85-C Mittal Towers
AP11: 8th flour Nariman Point,Maharashtra,400021
A14: Serial No. in the Register of Workmen | B14: Name of Workman | C14: Age | D14: Sex | E14: Father's /Husband Name | F14: Designation / Nature of Work Done | G14: Permanent Address | J14: Local Address | N14: Date of Commencement of Employment | O14: Signature or thumb impression of Workman | P14: Date of termination of Employment | Q14: Reasons for termination | R14: Remarks | S14: EPF Number | T14: ESI Number | U14: Name of Workman | V14: NO.OF DAYS | W14: No.of Days worked | X14: Unit of work done | Y14: Monthly rate of wages/ piece rate | Z14: Basic wages | AA14: Dearness Allowances | AB14: Over time | AC14: Other cash payments (Nature of payments to be indicated) | AD14: HRA | AE14: CONVEYANCE | AF14: MEDICAL ALLOWANCES | AG14: SPECIAL ALLOWNANCES | AH14: Total | AI14: BONUS | AJ14: GRATUITY | AK14: LTA/L.E | AL14: ARREAR AMOUNT | AM14: TOTAL AMOUNT | AN14: Deductions, if any, (Indicate nature) | AT14: Net Amount paid | AU14: Time and Date of Payment | AV14: Place of Payment | AW14: Signature/Thumb Impression of workman | AX14: Initial of Contractor or his representative
AN15: ESI | AO15: PF | AP15: PT | AQ15: TDS | AR15: MED | AS15: Total Deductions
A17: ='BOMBAY APRIL 22-WM Reg'!A21 -> 8 | B17: ='BOMBAY APRIL 22-WM Reg'!B21 -> Naresh Kumar Kandula | C17: ='BOMBAY APRIL 22-WM Reg'!C21 -> 30263 | D17: ='BOMBAY APRIL 22-WM Reg'!D21 -> M | E17: ='BOMBAY APRIL 22-WM Reg'!E21 -> Lankadasari Saritha | F17: ='BOMBAY APRIL 22-WM Reg'!F21 -> Senior Software Engineer | G17: ='BOMBAY APRIL 22-WM Reg'!G21 -> Flat B-309, H.no 7-1-3 , Shanthi Bagh Apts, Opp to Country Club, Begumpet, Hyd -500016 | J17: ='BOMBAY APRIL 22-WM Reg'!H21 -> Flat B-309, H.no 7-1-3 , Shanthi Bagh Apts, Opp to Country Club, Begumpet, Hyd -500016 | N17: 44340 | S17: 101579607071 | T17: N/A | U17: =B17 -> Naresh Kumar Kandula | V17: 30 | W17: 30 | X17: N/A | Y17: 112719 | Z17: 67631.4 | AA17: 0 | AB17: 0 | AC17: =AD17+AE17+AF17+AG17 -> 45200.56 | AD17: 27052.56 | AE17: 2083 | AF17: 2083 | AG17: 13982 | AH17: =Z17+AC17 -> 112831.96 | AI17: 1555 | AJ17: 3253.0703 | AK17: 5635.95 | AL17: 0 | AM17: =Z17+AD17+AE17+AF17+AG17+AI17+AJ17+AK17+AL17 -> 123275.98 | AN17: 0 | AO17: =ROUND(IF(Z17<15000,(Z17*12%),(15000*12%)),0) -> 1800 | AP17: 200 | AR17: 441 | AS17: =SUM(AO17:AR17) -> 2441 | AT17: =AM17-AS17 -> 120834.98 | AU17: 44686 | AV17: ICICI | AW17: A/C'018301591417
Y18: =SUM(Y16:Y17) -> 112719 | Z18: =SUM(Z16:Z17) -> 67631.4 | AA18: =SUM(AA16:AA17) -> 0 | AB18: =SUM(AB16:AB17) -> 0 | AC18: =SUM(AC16:AC17) -> 45200.56 | AD18: =SUM(AD16:AD17) -> 27052.56 | AE18: =SUM(AE16:AE17) -> 2083 | AF18: =SUM(AF16:AF17) -> 2083 | AG18: =SUM(AG16:AG17) -> 13982 | AI18: =SUM(AI16:AI17) -> 1555 | AJ18: =SUM(AJ16:AJ17) -> 3253.0703 | AK18: =SUM(AK16:AK17) -> 5635.95 | AL18: =SUM(AL16:AL17) -> 0 | AM18: =SUM(AM16:AM17) -> 123275.98 | AN18: =SUM(AN16:AN17) -> 0 | AO18: =SUM(AO16:AO17) -> 1800 | AP18: =SUM(AP16:AP17) -> 200 | ... AT18: =SUM(AT16:AT17) -> 120834.98
AH19: =SUM(AH16:AH18) -> 112831.96
A31: ='BOMBAY APRIL 22-WM Reg'!A20 -> 7 | B31: ='BOMBAY APRIL 22-WM Reg'!B20 -> ShyamReddy Kandula | C31: ='BOMBAY APRIL 22-WM Reg'!C20 -> 25-06-1992 | D31: ='BOMBAY APRIL 22-WM Reg'!D20 -> M | E31: ='BOMBAY APRIL 22-WM Reg'!E20 -> Ram Reddy | F31: ='BOMBAY APRIL 22-WM Reg'!F20 -> Oracle DBA | G31: ='BOMBAY APRIL 22-WM Reg'!G20 -> 4-58, Kondaigudem, Garidepally, Suryapet, Telangana - 508201 | J31: ='BOMBAY APRIL 22-WM Reg'!H20 -> 4-58, Kondaigudem, Garidepally, Suryapet, Telangana - 508201 | N31: ='BOMBAY APRIL 22-WM Reg'!I20 -> 44298 | S31: 100491173386 | T31: N/A | U31: =B31 -> ShyamReddy Kandula | V31: 31 | W31: 13 | X31: N/A | Y31: 89547 | Z31: 22531.181 | AA31: 0 | AB31: 0 | AC31: =AD31+AE31+AF31+AG31 -> 15020.787 | AD31: 9012.4723 | AE31: 874 | AF31: 874 | AG31: 4260.3148 | AH31: =Z31+AC31 -> 37551.968 | AI31: 1441.609 | AJ31: 0 | AK31: 0 | AL31: 0 | AM31: 0 | AN31: 0 | AO31: 0 | AP31: 0 | AQ31: 0 | AR31: 0 | AS31: 0 | AT31: 0 | AU31: 44505 | AV31: SBI | AW31: A/C'62246573312

Sheet 04-22 Eql rem
A1: Form D
A2: (See rule 6)
A4: Register to be maintained by the employer under rule 6 of the Equal Remuneration Rules, 1976
D6: ='BOM 04 22Master'!D10 -> 44652
A8: Name and address of Contractor : | F8: ='BOM 04 22Master'!F5 -> Burgeon IT Services Pvt.Ltd.
A10: Name and address of establishment in/under which contract is carried on : | F10: ='BOM 04 22Master'!AP5 -> Burgeon IT Services Pvt.Ltd.
F11: ='BOM 04 22Master'!AP6 -> Siri Mansion LIGB 436 Dr.A S Rao Nagar,Hyderabad
A12: Name and address of Principal Employer : | F12: ='BOM 04 22Master'!AP10 -> INFOSYS LTD.85-C Mittal Towers
F13: ='BOM 04 22Master'!AP11 -> 8th flour Nariman Point,Maharashtra,400021
A14: Total number of men workers employed | C14: =D22 -> 1
A16: Total number of women workers employed | C16: =C22 -> 0
C18: Components of remuneration
A19: Category of workers | B19: Brief Description of work | C19: No of women employed | D19: No. of men employed | E19: Rate or remuneration paid | F19: Basic wage & Dearness Allowance | G19: House Rent allowance | H19: Other allowances | I19: Cash value of concessional supply of essential commodities | J19: Name of the Client | K19: Primary Work Place/ Location
A21: ='BOM 04 22Master'!F17 -> Senior Software Engineer | B21: IT SUPPORTIVE SERICE | C21: 0 | D21: 1 | E21: ='BOM 04 22Master'!Y17 -> 112719 | F21: ='BOM 04 22Master'!Z17 -> 67631.4 | G21: ='BOM 04 22Master'!AD17 -> 27052.56 | H21: =E21-(F21+G21) -> 18035.04 | I21: 0
C22: =SUM(C20:C21) -> 0 | D22: =SUM(D20:D21) -> 1 | E22: =SUM(E20:E21) -> 112719 | F22: =SUM(F20:F21) -> 67631.4 | G22: =SUM(G20:G21) -> 27052.56 | H22: =SUM(H20:H21) -> 18035.04 | I22: =SUM(I20:I21) -> 0
E30: Signature of the Contractor with Seal

Sheet MH_Muster Roll
A2: Form No. II
A3: [M. W. Rules under Maharashtra Contract Labour (Regulation and Abolition)1963 Rule 27 (I)]
A4: Muster Roll cum Wages Register for the month of APRIL 2022
A5: Name and Address of Contractor : BURGEON IT SERVICES PVT.LTD. SIRI MANSION LIG 436 DR.A S RAO NAGAR,HYDERABAD 500 060
G6: Working Hours | I6: Interval for Rest | K6: No. of Hours Worked
A7: Sl.No. | B7: Full Name of Employee | C7: Date of Birth | D7: Gender | E7: Date of Entry into Service | F7: Nature of Work & Designation | G7: From | H7: To | I7: From | J7: To | K7: 1 | L7: 2 | M7: 3 | N7: 4 | O7: 5 | P7: 6 | Q7: 7 | R7: 8 | S7: 9 | T7: 10 | U7: 11 | V7: 12 | W7: 13 | X7: 14 | Y7: 15 | Z7: 16 | AA7: 17 | AB7: 18 | AC7: 19 | AD7: 20 | AE7: 21 | AF7: 22 | AG7: 23 | AH7: 24 | AI7: 25 | AJ7: 26 | AK7: 27 | AL7: 28 | AM7: 29 | AN7: 30 | AO7: MONTH DAYS
A8: 1 | B8: ='BOM 04 22Master'!B17 -> Naresh Kumar Kandula | C8: ='BOM 04 22Master'!C17 -> 30263 | D8: ='BOM 04 22Master'!D17 -> M | E8: ='BOM 04 22Master'!N17 -> 44340 | F8: ='BOM 04 22Master'!F17 -> Senior Software Engineer | K8: P | L8: WO | M8: WO | N8: P | O8: P | P8: P | Q8: P | R8: P | S8: WO | T8: WO | U8: P | V8: P | W8: P | X8: P | Y8: H | Z8: WO | AA8: WO | AB8: P | AC8: P | AD8: P | AE8: P | AF8: P | AG8: WO | AH8: WO | AI8: P | AJ8: P | AK8: P | AL8: P | AM8: P | AN8: WO | AO8: ='BOM 04 22Master'!W17 -> 30
AC17: Signature of the Contractor with Seal

Sheet Form M Leave Regi
A1: FORM M- LEAVE REGISTER
A3: (Vide Rule 78(1) (a) (i) of Maharastra Shops&Establishment Act /Maharastra.Rules 1988
A4: Name of the Employer / Establishment: | E4: Name of the Employee:
B5: ='BOM 04 22Master'!F5 -> Burgeon IT Services Pvt.Ltd. | G5: ='BOM 04 22Master'!B17 -> Naresh Kumar Kandula
B6: ='BOM 04 22Master'!F6 -> Siri Mansion LIGB 436 Dr.A S Rao Nagar,Hyderabad
A7: Description of the dapartment if applicable: | E7: Date of entry into service | G7: ='BOM 04 22Master'!N17 -> 44340
A11: S.No | B11: Accumalation of Leave | D11: Leave allowed | F11: Balance of Leave Carried Over | G11: Payment of Leave made on | I11: Refusal of Leave | L11: Payment of Leave on Discharge of an employee quitting employment if a admissible | O11: Signature or the Thumb impression of employee on Receipt of Leave Book in Form N | P11: Remarks
A13: 1 | F13: 6 | I13: 9 | L13: 9 | O13: Impression of
B14: Leave due on | C14: No of Days | D14: From | E14: To | G14: 1st month | H14: 2nd month | I14: Date of Application | J14: Date of Refusal | K14: Amount of Leave refused | L14: Date of Discharge | M14: Date of Amount Paid | N14: Signature or Left hand thumb impression of employee
A15: JAN'22 | B15: 0 | C15: 1 | D15: 44571 | E15: 44571 | F15: 9 | I15: NO | J15: NO | K15: NO
A16: FEB'22 | B16: 0 | C16: 0 | D16: 0 | E16: 0 | F16: =F15+1.5-C16 -> 10.5 | I16: NO | J16: NO | K16: NO
A17: MAR'22 | B17: 0 | C17: 0 | D17: 0 | E17: 0 | F17: =F16+1.5-C17 -> 12 | I17: NO | J17: NO | K17: NO
A18: APRIL'22 | B18: 0 | C18: 0 | D18: 0 | E18: 0 | F18: =F17+1.5-C18 -> 13.5 | I18: NO | J18: NO | K18: NO
G44: Signature of the Contractor with Seal

Sheet MH_Regi Wages
A2: Form No. II
A3: [M. W. Rules under Maharashtra Contract Labour (Regulation and Abolition)1963 Rule 27 (I)]
A4: Muster Roll cum Wages Register for the month of APRIL -2022
A5: Name and Address of Contractor : BURGEON IT SERVICES PVT.LTD. SIRI MANSION LIG 436 DR.A S RAO NAGAR,HYDERABAD 500 060
O6: Deductions | V6: Leave with Wages
A7: Sl.No. | B7: Deputy ID | C7: Employee Code | D7: Name of the Workmen | E7: Minimum Rate of Wages Payable Basic | F7: Actual Rate of Wages Payable HRA | G7: Conveyance | H7: Bonus | I7: Special Allowances | J7: Medical Allowances | K7: Total Production in Case of Piece Rate Other Allow | L7: Normal Earnings | M7: Overtime Earnings | N7: Gross Wages Payable | O7: Income Tax | P7: Other Deduction(Med) | Q7: Proff / Income Tax | R7: PF | S7: ESIC | T7: Total Deduction | U7: Net Wages Paid | V7: Previous Balance | W7: Further Enjoyed | X7: Refused | Y7: Accumulated | Z7: Date Payment of Wages | AA7: Signature or the Thumb Impression of the Employee | AB7: Account Number
A8: 3 | C8: BITS-548 | D8: ='BOM 04 22Master'!B17 -> Naresh Kumar Kandula | E8: ='BOM 04 22Master'!Z17 -> 67631.4 | F8: ='BOM 04 22Master'!AD17 -> 27052.56 | G8: ='BOM 04 22Master'!AE17 -> 2083 | H8: ='BOM 04 22Master'!AI17 -> 1555 | I8: ='BOM 04 22Master'!AG17 -> 13982 | J8: ='BOM 04 22Master'!AF17 -> 2083 | L8: ='BOM 04 22Master'!AH17 -> 112831.96 | M8: 0 | N8: ='BOM 04 22Master'!AM17 -> 123275.98 | O8: ='BOM 04 22Master'!AQ17 -> 0 | P8: ='BOM 04 22Master'!AR17 -> 441 | Q8: ='BOM 04 22Master'!AP17 -> 200 | R8: ='BOM 04 22Master'!AO17 -> 1800 | S8: ='BOM 04 22Master'!AN17 -> 0 | T8: ='BOM 04 22Master'!AS17 -> 2441 | U8: ='BOM 04 22Master'!AT17 -> 120834.98 | V8: 12 | W8: 0 | X8: 0 | Y8: 13.5 | Z8: ='BOM 04 22Master'!AU17 -> 44686 | AA8: ='BOM 04 22Master'!AV17 -> ICICI | AB8: ='BOM 04 22Master'!AW17 -> A/C'018301591417
E9: =SUM(E8:E8) -> 67631.4 | F9: =SUM(F8:F8) -> 27052.56 | G9: =SUM(G8:G8) -> 2083 | H9: =SUM(H8:H8) -> 1555 | I9: =SUM(I8:I8) -> 13982 | J9: =SUM(J8:J8) -> 2083 | L9: =SUM(L8:L8) -> 112831.96 | M9: =SUM(M8:M8) -> 0 | N9: =SUM(N8:N8) -> 123275.98 | O9: =SUM(O8:O8) -> 0 | P9: =SUM(P8:P8) -> 441 | Q9: =SUM(Q8:Q8) -> 200 | R9: =SUM(R8:R8) -> 1800 | S9: =SUM(S8:S8) -> 0 | ... X9: =SUM(X8:X8) -> 0
U23: Signature of the Contractor with Seal

Sheet Empt Cards
B1: FORM XIV
B2: EMPLOYMENT CUM WAGE CARD
B3: (Vide Rule 76 of Contract Labour (R&A) Central & Maharastra Rules, 1974)
B4: Name and Address of the Contractor | H4: Name and Address of the Establishment in/under which Contract is carried on:
B7: ='BOM 04 22Master'!F5 -> Burgeon IT Services Pvt.Ltd. | H7: ='BOM 04 22Master'!AP5 -> Burgeon IT Services Pvt.Ltd.
B9: ='BOM 04 22Master'!F6 -> Siri Mansion LIGB 436 Dr.A S Rao Nagar,Hyderabad | H9: ='BOM 04 22Master'!AP6 -> Siri Mansion LIGB 436 Dr.A S Rao Nagar,Hyderabad
B12: Nature of work and location of work: | H12: Name and address of Principal Employer:
H15: ='BOM 04 22Master'!AP10 -> INFOSYS LTD.85-C Mittal Towers
B16: ='BOM 04 22Master'!F8 -> IT SUPPORTIVE SERVICES&MUMBAI
H17: ='BOM 04 22Master'!AP11 -> 8th flour Nariman Point,Maharashtra,400021
B19: 1. Name of the Workman and address | H19: ='BOM 04 22Master'!B17 -> Naresh Kumar Kandula
H20: ='BOM 04 22Master'!G17 -> Flat B-309, H.no 7-1-3 , Shanthi Bagh Apts, Opp to Country Club, Begumpet, Hyd -500016
B21: 2. S.No. in the Register of Workmen Employed | H21: ='BOM 04 22Master'!A17 -> 8
B22: 3. Nature of Employment /Designation | H22: ='BOM 04 22Master'!F17 -> Senior Software Engineer
B23: 4. Date of entry into service | H23: ='BOM 04 22Master'!N17 -> 44340
B24: 5. ESI No. | J24: ='BOM 04 22Master'!T17 -> N/A
B25: 6.PF No. | J25: ='BOM 04 22Master'!S17 -> 101579607071
B26: 7. Wage rate (With particulars of unit in case of piece - work) | H26: ='BOM 04 22Master'!Y17 -> 112719
B27: 8. Wage period | H27: ='BOM 04 22Master'!D10 -> 44652
B28: 9. Tenure of Employment | H28: AS PER CONTRACT
B29: 10.No. of days worked in a month | J29: ='BOM 04 22Master'!W17 -> 30
B30: 11. No. of units worked in case of piece rate workers | J30: N/A
B31: 12. Rate of daily wages / piece rate | J31: 0
B32: 13. Amount of overtime wages | J32: 0
B33: 14. Gross wages payable | J33: ='BOM 04 22Master'!AM17 -> 123275.98 | L33: MED
B34: 15. Deductions, if any, | D34: PF | E34: ='BOM 04 22Master'!AO17 -> 1800 | F34: ESI | G34: ='BOM 04 22Master'!AN17 -> 0 | H34: PT | I34: ='BOM 04 22Master'!AP17 -> 200 | J34: TDS | K34: ='BOM 04 22Master'!AQ17 -> 0 | L34: ='BOM 04 22Master'!AR17 -> 441
B35: 16. Net amount of wages paid | J35: =J33-(E34+G34+I34+K34+L34) -> 120834.98
B36: Signature of the Representative
B37: of Contractor
B53: FORM XIV
B54: EMPLOYMENT CUM WAGE CARD
B55: (Vide Rule 76 of Contract Labour (R&A) Central & Karnataka Rules, 1974)
B56: Name and Address of the Contractor | H56: Name and Address of the Establishment in/under which Contract is carried on:
B59: =#REF! -> #REF! | H59: =#REF! -> #REF!
B61: =#REF! -> #REF! | H61: =#REF! -> #REF!
B64: Nature of work and location of work: | H64: Name and address of Principal Employer:
H67: =#REF! -> #REF!
B68: =#REF! -> #REF!
H69: =#REF! -> #REF!
B71: 1. Name of the Workman and address | H71: ='BOM 04 22Master'!B440 -> 0
...

Sheet wage sllips
A1: Form XIX - WAGE SLIP | K1: Form XIX - WAGE SLIP
A2: [Vide rule 78 (1) (b) of the Contract Labour (Regulation and Abolition) Central and Maharashtra, 1971] | K2: [Vide rule 78 (1) (b) of the Contract Labour (Regulation and Abolition) Central and Maharashtra, 1971]
A4: Name and address of Contractor | D4: ='BOM 04 22Master'!F5 -> Burgeon IT Services Pvt.Ltd. | K4: Name and address of Contractor | N4: =D4 -> Burgeon IT Services Pvt.Ltd.
B5: ='BOM 04 22Master'!F6 -> Siri Mansion LIGB 436 Dr.A S Rao Nagar,Hyderabad | L5: =B5 -> Siri Mansion LIGB 436 Dr.A S Rao Nagar,Hyderabad
B6: ='BOM 04 22Master'!F7 -> 0 | L6: =B6 -> 0
A7: Name and Father's / Husband's name of the workman | K7: Name and Father's / Husband's name of the workman
E8: ='BOM 04 22Master'!B17 -> Naresh Kumar Kandula | H8: ='BOM 04 22Master'!E17 -> Lankadasari Saritha | O8: =E8 -> Naresh Kumar Kandula | R8: =H8 -> Lankadasari Saritha
A10: Nature and location of work | E10: ='BOM 04 22Master'!F8 -> IT SUPPORTIVE SERVICES&MUMBAI | K10: Nature and location of work | O10: =E10 -> IT SUPPORTIVE SERVICES&MUMBAI
A12: For the Week / Fortnight / Month ending | E12: ='BOM 04 22Master'!D10 -> 44652 | K12: For the Week / Fortnight / Month ending | O12: =E12 -> 44652
A14: 1 | B14: No. of days worked | E14: ='BOM 04 22Master'!W17 -> 30 | K14: 1 | L14: No. of days worked | O14: =E14 -> 30
A16: 2 | B16: No. of units worked in case of piece rate workers : | K16: 2 | L16: No. of units worked in case of piece rate workers :
E17: N/A | O17: N/A
A19: 3 | B19: Rate of daily wages / piece rate | E19: N/A | K19: 3 | L19: Rate of daily wages / piece rate | O19: =E19 -> N/A
A21: 4 | B21: Amount of overtime wages | E21: Nil | K21: 4 | L21: Amount of overtime wages | O21: Nil
A23: 5 | B23: Gross wages payble | E23: ='BOM 04 22Master'!AM17 -> 123275.98 | K23: 5 | L23: Gross wages payble | O23: =E23 -> 123275.98
D24: EPF | E24: ESI | F24: PT | G24: TDS | H24: MEDICAL | I24: TOTAL | N24: EPF | O24: ESI | P24: PT | Q24: TDS | R24: MEDICAL | S24: TOTAL
A25: 6 | B25: Deductions, if any | D25: ='BOM 04 22Master'!AO17 -> 1800 | E25: ='BOM 04 22Master'!AN17 -> 0 | F25: ='BOM 04 22Master'!AP17 -> 200 | G25: ='BOM 04 22Master'!AQ17 -> 0 | H25: ='BOM 04 22Master'!AR17 -> 441 | I25: =D25+E25+F25+G25+H25 -> 2441 | K25: 6 | L25: Deductions, if any | N25: =D25 -> 1800 | O25: =E25 -> 0 | P25: =F25 -> 200 | Q25: =G25 -> 0 | R25: =H25 -> 441 | S25: =I25 -> 2441
A27: 7 | B27: Net amount of wages paid | E27: =E23-I25 -> 120834.98 | K27: 7 | L27: Net amount of wages paid | O27: =E27 -> 120834.98
F31: Initial of the Contractor or his representative | P31: Initial of the Contractor or his representative
A61: Form XIX - WAGE SLIP | K61: Form XIX - WAGE SLIP
A62: [Vide rule 78 (1) (b) of the Contract Labour (Regulation and Abolition) Central and A.P Rules, 1971] | K62: [Vide rule 78 (1) (b) of the Contract Labour (Regulation and Abolition) Central and A.P Rules, 1971]
A64: Name and address of Contractor | D64: ='BOM 04 22Master'!F5 -> Burgeon IT Services Pvt.Ltd. | K64: Name and address of Contractor | N64: =D64 -> Burgeon IT Services Pvt.Ltd.
B65: ='BOM 04 22Master'!F6 -> Siri Mansion LIGB 436 Dr.A S Rao Nagar,Hyderabad | L65: =B65 -> Siri Mansion LIGB 436 Dr.A S Rao Nagar,Hyderabad
B66: ='BOM 04 22Master'!F7 -> 0 | L66: =B66 -> 0
A67: Name and Father's / Husband's name of the workman | K67: Name and Father's / Husband's name of the workman
E68: ='BOM 04 22Master'!#REF! -> #REF! | O68: =E68 -> #REF!
A70: Nature and location of work | E70: ='BOM 04 22Master'!F8 -> IT SUPPORTIVE SERVICES&MUMBAI | K70: Nature and location of work | O70: =E70 -> IT SUPPORTIVE SERVICES&MUMBAI
A72: For the Week / Fortnight / Month ending | E72: ='BOM 04 22Master'!D10 -> 44652 | K72: For the Week / Fortnight / Month ending | O72: =E72 -> 44652
A74: 1 | B74: No. of days worked | E74: ='BOM 04 22Master'!#REF! -> #REF! | K74: 1 | L74: No. of days worked | O74: =E74 -> #REF!
A76: 2 | B76: No. of units worked in case of piece rate workers : | K76: 2 | L76: No. of units worked in case of piece rate workers :
E77: N/A | O77: N/A
A79: 3 | B79: Rate of daily wages / piece rate | E79: N/A | K79: 3 | L79: Rate of daily wages / piece rate | O79: =E79 -> N/A
A81: 4 | B81: Amount of overtime wages | E81: Nil | K81: 4 | L81: Amount of overtime wages | O81: Nil
A83: 5 | B83: Gross wages payble | E83: ='BOM 04 22Master'!#REF! -> #REF! | K83: 5 | L83: Gross wages payble | O83: =E83 -> #REF!
D84: EPF | E84: ESI | F84: PT | G84: TDS | H84: MEDICAL | I84: TOTAL | N84: EPF | O84: ESI | P84: PT | Q84: TDS | R84: MEDICAL | S84: TOTAL
A85: 6 | B85: Deductions, if any | D85: ='BOM 04 22Master'!#REF! -> #REF! | E85: ='BOM 04 22Master'!#REF! -> #REF! | F85: ='BOM 04 22Master'!#REF! -> #REF! | G85: ='BOM 04 22Master'!#REF! -> #REF! | H85: ='BOM 04 22Master'!#REF! -> #REF! | I85: =D85+E85+F85+G85+H85 -> #REF! | K85: 6 | L85: Deductions, if any | N85: =D85 -> #REF! | O85: =E85 -> #REF! | P85: =F85 -> #REF! | Q85: =G85 -> #REF! | R85: =H85 -> #REF! | S85: =I85 -> #REF!
A87: 7 | B87: Net amount of wages paid | E87: =E83-I85 -> #REF! | K87: 7 | L87: Net amount of wages paid | O87: =E87 -> #REF!
F91: Initial of the Contractor or his representative | P91: Initial of the Contractor or his representative
A105: Form XIX - WAGE SLIP | K105: Form XIX - WAGE SLIP
A106: [Vide rule 78 (1) (b) of the Contract Labour (Regulation and Abolition) Central and A.P Rules, 1971] | K106: [Vide rule 78 (1) (b) of the Contract Labour (Regulation and Abolition) Central and A.P Rules, 1971]
...

Sheet 4-22Bonus
A1: BONUS REGISTER
A3: FORM "c" ( See rule 4 [c] )
K4: Wage Period | L4: ='BOM 04 22Master'!D10 -> 44652
A5: Name of the Establishment : _____________________________ | D5: ='BOM 04 22Master'!F5 -> Burgeon IT Services Pvt.Ltd. | K5: Financial year _____ | M5: 2022-23
A6: ='BOM 04 22Master'!F6 -> Siri Mansion LIGB 436 Dr.A S Rao Nagar,Hyderabad
A7: Sr. No | B7: Name of the Employee | C7: Father's Name / Husband's Name | D7: Whether he has completed 15 yrs of age at the beginning of the accounting year | E7: Designation | F7: No. of days worked in the year | G7: Total Salary or wages in the Month | H7: Amt. of bonus payable under section 10 or section 11 as the case may be Ex gratia | I7: DEDUCTIONS | L7: Total Sum Deducted (Col. 9,10 and 11) | M7: Net Amount payable (Col. 8 minus Col. 12) | N7: Amount Actually paid | O7: Date on which paid | P7: Signature / Thumb impression of the employee
I8: Puja Bonus or other customary bonus paid during the accounting year | J8: Interim Bonus or bonus paid in advance | K8: Deduction on account of financial loss if any caused by misconduct of the employee | Q8: Account Number
A9: 1 | B9: 2 | C9: 3 | D9: 4 | E9: 5 | F9: 6 | H9: 8 | I9: 9 | J9: 10 | K9: 11 | L9: 12 | M9: 13 | N9: 14 | O9: 15 | P9: 16
A10: 3 | B10: ='BOM 04 22Master'!B17 -> Naresh Kumar Kandula | C10: ='BOM 04 22Master'!E17 -> Lankadasari Saritha | D10: YES | E10: ='BOM 04 22Master'!F17 -> Senior Software Engineer | F10: ='BOM 04 22Master'!W17 -> 30 | G10: ='BOM 04 22Master'!Z17 -> 67631.4 | H10: ='BOM 04 22Master'!AI17 -> 1555 | I10: N/A | J10: N/A | K10: N/A | L10: N/A | M10: =H10 -> 1555 | N10: =H10 -> 1555 | O10: ='BOM 04 22Master'!AU17 -> 44686 | P10: ='BOM 04 22Master'!AV17 -> ICICI | Q10: ='BOM 04 22Master'!AW17 -> A/C'018301591417
L12: Signature of the Contractor with Seal

Sheet Serive Certificate
B4: FORM XV
B5: [Vide rule 77 of Contract Labour (Regul. & Abolition) Central & A.P. Rules, 1971]
B7: SERVICE CERTIFICATE
B9: Name and address of Contractor : | G9: Name and address of establishment in / under which contract is caried on :
B11: ='BOM 04 22Master'!F5 -> Burgeon IT Services Pvt.Ltd. | G11: ='BOM 04 22Master'!AP5 -> Burgeon IT Services Pvt.Ltd.
B13: ='BOM 04 22Master'!F6 -> Siri Mansion LIGB 436 Dr.A S Rao Nagar,Hyderabad | G13: ='BOM 04 22Master'!AP6 -> Siri Mansion LIGB 436 Dr.A S Rao Nagar,Hyderabad
B17: Nature and Location of work: | G17: Name and address of Principal Employer :
G19: ='BOM 04 22Master'!AP10 -> INFOSYS LTD.85-C Mittal Towers
B21: ='BOM 04 22Master'!F8 -> IT SUPPORTIVE SERVICES&MUMBAI | G21: ='BOM 04 22Master'!AP11 -> 8th flour Nariman Point,Maharashtra,400021
B26: Name and address of the workman :
B31: Age or date of Birth :
B33: Identification Marks :
B35: Father's / Husband's Name :
B38: Sl.No. | C38: Total period for which employed | E38: Nature of work done | G38: Rate of wage ( with particulars of units in case of piece work) | J38: Remarks
C40: From | D40: To
B41: 1 | C41: 2 | D41: 3 | E41: 4 | G41: 5 | J41: 6
H56: Signature of the Employer with Seal

Sheet Deductions
A1: FORM XVI- REGISTER OF DEDUCTIONS FOR DAMAGE OR LOSS
A3: (Vide Rule 78(1) (a) (i) of Contract Labour (Regulation and Abolition) Maharashtra Rules 1971.
A4: Name and address of Contractor: GROTECH LANDSCAPE DEVELOPERS PVT.LTD. | D4: ='BOM 04 22Master'!F5 -> Burgeon IT Services Pvt.Ltd. | E4: Name and address of the establishment in / under which contract is carried on:
B5: ='BOM 04 22Master'!F6 -> Siri Mansion LIGB 436 Dr.A S Rao Nagar,Hyderabad
B6: ='BOM 04 22Master'!F7 -> 0
A7: Nature and Location of Work: | D7: ='BOM 04 22Master'!F8 -> IT SUPPORTIVE SERVICES&MUMBAI | E7: Name and address of principal employer:
E8: ='BOM 04 22Master'!AP10 -> INFOSYS LTD.85-C Mittal Towers
E9: ='BOM 04 22Master'!AP11 -> 8th flour Nariman Point,Maharashtra,400021
A11: S.No | B11: Name of workman | C11: Father's / Husband's Name | D11: Designation / Nature of employment | E11: Particulars of damage or loss | F11: Date of Damage or loss | G11: Whether workman showed cause against deduction | H11: Name of person in whose presence employee's explanation was heard | I11: Amount of deduction impossed | J11: Date of recovery | M11: Remarks
J12: No.of Instalments | K12: First Instalment | L12: Last instalment
A13: 1 | B13: 2 | C13: 3 | D13: 4 | E13: 5 | F13: 6 | G13: 7 | H13: 8 | I13: 9 | J13: 10 | K13: 11 | L13: 12 | M13: 13
B16: NO EMPLOYEE WAS IMPOSED DEDUCTIONS FOR DAMAGE OR LOSS FOR THE MONTH OF | H16: ='BOM 04 22Master'!D10 -> 44652
F32: Signature of the Contractor with Seal

Sheet Fines
A1: FORM XVII- REGISTER OF FINES
A3: (Vide Rule 78(1) (a) (i) of Contract Labour (Regulation and Abolition) Maharashtra Rules 1971
A4: Name and address of Contractor: | D4: ='BOM 04 22Master'!F5 -> Burgeon IT Services Pvt.Ltd. | E4: Name and address of the establishment in / under which contract is carried on:
B5: ='BOM 04 22Master'!F6 -> Siri Mansion LIGB 436 Dr.A S Rao Nagar,Hyderabad
B6: ='BOM 04 22Master'!F7 -> 0
A7: Nature and Location of Work: | D7: ='BOM 04 22Master'!F8 -> IT SUPPORTIVE SERVICES&MUMBAI | E7: Name and address of principal employer:
E8: ='BOM 04 22Master'!AP10 -> INFOSYS LTD.85-C Mittal Towers
E9: ='BOM 04 22Master'!AP11 -> 8th flour Nariman Point,Maharashtra,400021
A11: S.No | B11: Name of workman | C11: Father's / Husband's Name | D11: Designation / Nature of employment | E11: Act/Omission for which fine imposed | F11: Date of offence | G11: Whether workman showed cause against fine | H11: Name of person in whose presence employee's explanation was heard | I11: Wage-period and wge payable | J11: Amount of fine Imposed | K11: Date on which fine realised | L11: Remarks
A13: 1 | B13: 2 | C13: 3 | D13: 4 | E13: 5 | F13: 6 | G13: 7 | H13: 8 | I13: 9 | J13: 10 | K13: 11 | L13: 12
B17: NO EMPLOYEE WAS IMPOSED FINESFOR THE MONTH OF | H17: ='BOM 04 22Master'!D10 -> 44652
F33: Signature of the Contractor with Seal

Sheet Advances
A1: FORM XVIII- REGISTER OF ADVANCES
A3: (Vide Rule 78(1) (a) (i) of Contract Labour (Regulation and Abolition) Maharashtra Rules 1971
A4: Name and address of Contractor: | D4: ='BOM 04 22Master'!F5 -> Burgeon IT Services Pvt.Ltd. | E4: Name and address of the establishment in / under which contract is carried on:
B5: ='BOM 04 22Master'!F6 -> Siri Mansion LIGB 436 Dr.A S Rao Nagar,Hyderabad
B6: ='BOM 04 22Master'!F7 -> 0
A7: Nature and Location of Work: | D7: ='BOM 04 22Master'!F8 -> IT SUPPORTIVE SERVICES&MUMBAI | E7: Name and address of principal employer:
E8: ='BOM 04 22Master'!AP10 -> INFOSYS LTD.85-C Mittal Towers
E9: ='BOM 04 22Master'!AP11 -> 8th flour Nariman Point,Maharashtra,400021
A11: S.No | B11: Name of workman | C11: Father's / Husband's Name | D11: Designation / Nature of employment | E11: Wage period and wages payable | F11: Date and amount of advance given | G11: Purpose(s) for which advance made | H11: Number of instalments by which advance to be repaid | I11: Date and amount of each instalment repaid | J11: Date on which last instalment was repaid | K11: Remarks
A13: 1 | B13: 2 | C13: 3 | D13: 4 | E13: 5 | F13: 6 | G13: 7 | H13: 8 | I13: 9 | J13: 10 | K13: 11
B20: NO EMPLOYEE TAKEN ADVANCE FOR THE MONTH OF | F20: ='BOM 04 22Master'!D10 -> 44652
G36: Signature of the Contractor with Seal

Sheet Overtime
A1: FORM XIX- REGISTER OF OVERTIME
A3: (Vide Rule 78(1) (a) (i) of Contract Labour (Regulation and Abolition) Maharashtra Rules 1971
A4: Name and address of Contractor: GROTECH LANDSCAPE DEVELOPERS PVT.LTD. E-35 GREATER KAILASH ENCLAVE-1 NEW DELHI | D4: ='BOM 04 22Master'!F5 -> Burgeon IT Services Pvt.Ltd. | F4: Name and address of the establishment in which under contract is carried on:
B5: ='BOM 04 22Master'!F6 -> Siri Mansion LIGB 436 Dr.A S Rao Nagar,Hyderabad
B6: ='BOM 04 22Master'!F7 -> 0
A7: Nature and Location of Work: | D7: ='BOM 04 22Master'!F8 -> IT SUPPORTIVE SERVICES&MUMBAI | F7: Name and address of principal employer:
F8: ='BOM 04 22Master'!AP10 -> INFOSYS LTD.85-C Mittal Towers
F9: ='BOM 04 22Master'!AP11 -> 8th flour Nariman Point,Maharashtra,400021
A11: S.No | B11: Name of workman | C11: Father's / Husband's Name | D11: Sex | E11: Designation / Nature of employment | F11: Date on which overtime worked | G11: Total overtime worked or production in case of piece-rates | H11: Normal rate of wages | I11: Overtime rate of wages | J11: overtime earnings | K11: Date on which overtime wages paid | L11: Remarks
A13: 1 | B13: 2 | C13: 3 | D13: 4 | E13: 5 | F13: 6 | G13: 7 | H13: 8 | I13: 9 | J13: 10 | K13: 11 | L13: 12
B21: NO EMPLOYEE DONE OVERTIME FOR THE MONTH OF | F21: ='BOM 04 22Master'!D10 -> 44652
G38: Signature of the Contractor with Seal

Sheet Accident
A1: FORM 11
A3: ACCIDENT BOOK
A4: EMPLOYEE STATE INSURANCE CORPORATION
B5: (Regulation 66)
A7: S.No | B7: Date of Notice | C7: Time of Notice | D7: Name and Address of the Injured Person | E7: Sex | F7: Age | H7: Shift,Department and occupation of employee | I7: Details of Injury | P7: Signature and designation of the person who makes the entry in the accident book | Q7: Name,address and occupation of the two witnesses | R7: Remarks if any
G8: Insurance Number | N8: What exactly was the injured person doing at the time of accident | O8: Name,Occupation,address and signature or the thumb impression of the person(s) giving notice
I9: Cause | J9: Nature | K9: Date | L9: Time | M9: Place
A10: 1 | B10: 2 | C10: 3 | D10: 4 | E10: 5 | F10: 6 | G10: 7 | H10: 8 | I10: 9 | J10: 10 | K10: 11 | L10: 12 | M10: 13 | N10: 14 | O10: 15 | P10: 16 | Q10: 17 | R10: 18
B15: NO ACCIDENT OCCURRED FOR THE MONTH OF | F15: ='BOM 04 22Master'!D10 -> 44652
J32: Signature of the Contractor with Seal

Sheet ESI cards Reg
C1: ='BOM 04 22Master'!F5 -> Burgeon IT Services Pvt.Ltd. | E1: ESI PAHECHAN CARDS ISSUE REGISTER
B2: S.No | C2: Name of the Employee | D2: ESI Number | E2: Issue Date | F2: Signature | G2: Remarks
B3: 1 | C3: ='BOM 04 22Master'!#REF! -> #REF! | D3: ='BOM 04 22Master'!#REF! -> #REF!
B4: 2 | C4: ='BOM 04 22Master'!#REF! -> #REF! | D4: ='BOM 04 22Master'!#REF! -> #REF!
B5: 3 | C5: ='BOM 04 22Master'!#REF! -> #REF! | D5: ='BOM 04 22Master'!#REF! -> #REF!
B6: 4 | C6: ='BOM 04 22Master'!#REF! -> #REF! | D6: ='BOM 04 22Master'!#REF! -> #REF!
B7: 5 | C7: ='BOM 04 22Master'!#REF! -> #REF! | D7: ='BOM 04 22Master'!#REF! -> #REF!
B8: 6 | C8: ='BOM 04 22Master'!#REF! -> #REF! | D8: ='BOM 04 22Master'!#REF! -> #REF!
B9: 7 | C9: ='BOM 04 22Master'!#REF! -> #REF! | D9: ='BOM 04 22Master'!#REF! -> #REF!
B10: 8 | C10: ='BOM 04 22Master'!#REF! -> #REF! | D10: ='BOM 04 22Master'!#REF! -> #REF!
B11: 9 | C11: ='BOM 04 22Master'!#REF! -> #REF! | D11: ='BOM 04 22Master'!#REF! -> #REF!
B12: 10 | C12: ='BOM 04 22Master'!#REF! -> #REF! | D12: ='BOM 04 22Master'!#REF! -> #REF!
B13: 11 | C13: ='BOM 04 22Master'!#REF! -> #REF! | D13: ='BOM 04 22Master'!#REF! -> #REF!
B14: 12 | C14: ='BOM 04 22Master'!#REF! -> #REF! | D14: ='BOM 04 22Master'!#REF! -> #REF!
... B22: 20 | C22: ='BOM 04 22Master'!#REF! -> #REF! | D22: ='BOM 04 22Master'!#REF! -> #REF!

Sheet Form-I
B1: FORM I
B2: NOMINATION AND DECLARATION FORM
B3: (Vide Rule 3 of Payment of wages Act Central & A.P Rules, 1936)
B4: Name and Address of the Contractor | H4: Name and Address of the Establishment in/under which Contract is carried on:
B7: =#REF! -> #REF! | H7: =#REF! -> #REF!
B9: =#REF! -> #REF! | H9: =#REF! -> #REF!
B12: Nature of work and location of work: | H12: Name and address of Principal Employer:
H15: =#REF! -> #REF!
B16: =#REF! -> #REF!
H17: =#REF! -> #REF!
B19: 1. Name of the person making nomination | H19: ='BOM 04 22Master'!#REF! -> #REF!
B20: 2. Father's/Husband name | H20: ='BOM 04 22Master'!#REF! -> #REF!
B21: 3. Date of Birth | H21: ='BOM 04 22Master'!#REF! -> #REF!
B22: 4. Sex | H22: ='BOM 04 22Master'!#REF! -> #REF!
B23: 5. Marital Status | H23: Un-Married
B24: 6.Address
B25: Permanent | H25: ='BOM 04 22Master'!#REF! -> #REF!
H26: ='BOM 04 22Master'!#REF! -> #REF!
H27: ='BOM 04 22Master'!#REF! -> #REF!
B28: Temporary | H28: ='BOM 04 22Master'!#REF! -> #REF!
H29: ='BOM 04 22Master'!#REF! -> #REF!
H30: ='BOM 04 22Master'!#REF! -> #REF!
B31: I hereby nominate the person(s)/cancel the nomination made by me previously and nominate the person(s) mentioned below to
B32: receive any amount due to me from the employer,in the event to my death.
B33: Name of the Nominee/nominees | E33: Address | G33: Nominee's relationship With the member | I33: Date of Birth | J33: Total amount of Share of accumulations | K33: If the nominee is minor,name,relationship and address of the guardian
B34: 1 | E34: 2 | G34: 3 | I34: 4 | J34: 5 | L34: 6
B35: ='BOM 04 22Master'!#REF! -> #REF! | E35: Same as permanant address | G35: Father | I35: 54 years | J35: 1 | K35: N/A
B39: 1.Certified that I have no family and should I acquire a family hereafter,the above nomination shall be deemed as cancelled.
B40: 2.Certified that my father/mother is/ are dependent upon me.
B41: 3.Strike out whichever is not applicable.
I43: Signature or the thumb impression of the employed person
F44: CERTIFCATE BY EMPLOYER
A45: Certified that the above declaration and nomination has been signed/thumb impressed before me by Shri/Smt/Kum | K45: ='BOM 04 22Master'!#REF! -> #REF!
A46: employed in my establishment after he/she has read the entry/entries have been read over to him/her by me and got confirmed by him/her.
F49: Signature or the employer or other authorized officer of the establiment and Designation
A50: Place | B50: Hyderabad | F50: ='BOM 04 22Master'!AP5 -> Burgeon IT Services Pvt.Ltd.
A51: Date | B51: ='BOM 04 22Master'!#REF! -> #REF! | F51: ='BOM 04 22Master'!AP6 -> Siri Mansion LIGB 436 Dr.A S Rao Nagar,Hyderabad
B53: FORM I
B54: NOMINATION AND DECLARATION FORM
B55: (Vide Rule 3 of Payment of wages Act Central & A.P Rules, 1936)
...

Sheet Form-2
K1: (FORM 2 REVISED)
B2: NOMINATION AND DECLARATION FORM FOR UNEXEMPTED/EXEMPTED ESTABLISHMENTS
B3: Declaration and Nomination Form under the Employees Provident Funds and Employees Pension Schemes
B4: (Paragraph 33 and 61(1) of the Employees Provident Fund Scheme 1952 and Paragraph 18 of the Employees Pension Scheme 1995)
B6: 1. Name of the person making nomination | H6: ='BOM 04 22Master'!#REF! -> #REF!
B7: 2. Father's/Husband name | H7: ='BOM 04 22Master'!#REF! -> #REF!
B8: 3. Date of Birth | H8: ='BOM 04 22Master'!#REF! -> #REF!
B9: 4. Sex | H9: ='BOM 04 22Master'!#REF! -> #REF!
B10: 5. Marital Status | H10: Un-Married
B11: 6.Address
B12: Permanent | H12: ='BOM 04 22Master'!#REF! -> #REF!
H13: ='BOM 04 22Master'!#REF! -> #REF!
H14: ='BOM 04 22Master'!#REF! -> #REF!
G15: PART-A(EPF)
B16: I hereby nominate the person(s)/cancel the nomination made by me previously and nominate the person(s) mentioned below to
B17: receive any amount due to me from the employer,in the event to my death.
B18: Name of the Nominee/nominees | E18: Address | G18: Nominee's relationship With the member | I18: Date of Birth | J18: Total amount of Share of accumulations | K18: If the nominee is minor,name,relationship and address of the guardian
B19: 1 | E19: 2 | G19: 3 | I19: 4 | J19: 5 | L19: 6
B20: ='BOM 04 22Master'!#REF! -> #REF! | E20: Same as Permanant Address | G20: Father | I20: 55 Years | J20: 1 | K20: N/A
B24: 1.Certified that I have no family and should I acquire a family hereafter,the above nomination shall be deemed as cancelled.
B25: 2.Certified that my father/mother is/ are dependent upon me.
B26: Strike out whichever is not applicable | J26: Signature/or thumb impression of the subscriber
G27: PART (EPS)
G28: Para 18
B29: I hereby furnish below particulars of the members of my family who would be eligible to receive Widow/Children Pension in the event of
B30: my premature death in service
B31: S.No | C31: Name & Address of the Family Member | I31: Age | J31: Relationship with the member
B32: 1 | E32: 2 | I32: 3 | K32: 4
B37: Certified that I have no family as defined in para 2 (vii) of the Employees's Family Pension Scheme 1995 and should I acquire a family hereafter
B38: I shall furnish Particulars there on in the above form.
B39: I hereby nominate the following person for receiving the monthly widow pension (admissible under para 16 2 (a) (1) & (ii) in the even of my death
B40: without leaving any eligible member for receiving pension.
B41: Name and Address of the nominee | G41: Date of Birth | I41: Relationship with member
B47: Date | C47: ='BOM 04 22Master'!#REF! -> #REF! | I47: Signature or thumb impression of the subscriber
F48: CERTIFCATE BY EMPLOYER
A49: Certified that the above declaration and nomination has been signed/thumb impressed before me by Shri/Smt/Kum | K49: ='BOM 04 22Master'!#REF! -> #REF!
A50: employed in my establishment after he/she has read the entry/entries have been read over to him/her by me and got confirmed by him/her.
F52: Signature or the employer or other authorized officer of the establiment and Designation
A53: Place | B53: Hyderabad | F53: ='BOM 04 22Master'!F5 -> Burgeon IT Services Pvt.Ltd.
A54: Date | B54: ='BOM 04 22Master'!#REF! -> #REF! | F54: ='BOM 04 22Master'!F6 -> Siri Mansion LIGB 436 Dr.A S Rao Nagar,Hyderabad
...

Sheet Form 11
I1: New Form No. 11 - Declaration Form
B2: (To be retained by t he employer for future reference)
D3: EMPLOYEES' PROVIDENT FUND ORGANIZATION | I3: Emp Code: | K3: ='BOM 04 22Master'!#REF! -> #REF!
C4: Employees' Provident Funds Scheme, 1952 (Paragraph 34 & 57) & | I4: Company | J4: ='BOM 04 22Master'!F5 -> Burgeon IT Services Pvt.Ltd.
C5: The Employees' Pension Scheme, 1995 (Paragraph 24) | I5: ='BOM 04 22Master'!F6 -> Siri Mansion LIGB 436 Dr.A S Rao Nagar,Hyderabad
A8: 1 | B8: Name of the Member | H8: ='BOM 04 22Master'!#REF! -> #REF!
A9: 2 | B9: Fathers' Name | F9: Husband's Name | H9: ='BOM 04 22Master'!#REF! -> #REF!
B10: (Please tick whichever is applicable)
A11: 3 | B11: Date of Birth (DD/MM/YYYY) | H11: ='BOM 04 22Master'!#REF! -> #REF!
A12: 4 | B12: Gender (Male/Female/Transgender) | H12: ='BOM 04 22Master'!#REF! -> #REF!
A13: 5 | B13: Marital Status(married / Unmarried / Widow/divorce) | H13: UNMARRIED
A14: 6 | B14: (a) | C14: Email Id
B15: (b) | C15: Mobile No.
A16: 7 | B16: Whether earlier a member of the Employees' Provident Fund Scheme, 1952 ? | H16: Yes | K16: No
A17: 8 | B17: Whether earlier a member of the Employees' Pension Scheme, 1995? | H17: Yes | K17: No
F18: Previous employment details [if Yes to 7 &/or 8 above]
A19: 9 | B19: a) | C19: Universal Account Number
B20: b) | C20: Previous PF Account Number
B21: C) | C21: Date of exit from previous employment (DD/MM/YYYY)
B22: d) | C22: Scheme Certificate No. (if issued)
B23: e) | C23: Pension Payment Order (PPO) No. (if issued)
A24: 10 | B24: a) | C24: International Worker | H24: Yes | K24: No
B25: b) | C25: If yes, state country of origin(India/Name of other country)
B26: C) | C26: Passport No.
B27: d) | C27: Validity of passport [(DD/MM/YYYY) to (DD/MM/YYYY)]
E28: KYC Details (attach self attested copies of following KYCs)
A29: 11 | B29: a) | C29: Bank Account No. & IFS Code
B30: b) | C30: AADHAR No.
B31: c) | C31: Permanent Account No. (PAN), if available
F32: UNDERTAKING
B33: 1) | C33: Certified that the particulars are true to the best of my knowledge.
B34: 2) | C34: I authorize EPFO to use my Aadhar for verification/authentication/eKYC purpose for service delivery.
B35: 3) | C35: Kindly transfer the funds and service details, if applicable from the previous PF account as declared above to the present P.F. Account (The Transfer would be possible only if the identified KYC details approved by previous employer has been verified by present employer
B36: 4) | C36: In case of changes in above details, the same will be intimated to employer at the earliest.
C37: Date : | D37: ='BOM 04 22Master'!#REF! -> #REF!
C38: Place: | D38: Hyderabad | J38: Signature of Member
F40: DECLARATION BY PRESENT EMPLOYER
A41: A) | B41: The member Mr./Ms./Mrs. | E41: ='BOM 04 22Master'!#REF! -> #REF! | H41: has joined on | J41: ='BOM 04 22Master'!#REF! -> #REF! | K41: and has been allotted PF Number
B42: ='BOM 04 22Master'!#REF! -> #REF!
A43: B) | B43: In case the person was earlier not a member of EPF Scheme, 1952 and EPS, 1995:
...

Sheet Form-F
A1: F O R M – F
A2: [See sub-Rule (1) of Rule 6] The Payment of Gratuity Rules, 1973:
A3: NOMINATION
A4: To
A5: ='BOM 04 22Master'!F5 -> Burgeon IT Services Pvt.Ltd.
A6: ='BOM 04 22Master'!F6 -> Siri Mansion LIGB 436 Dr.A S Rao Nagar,Hyderabad
A8: 1. I, Shri / Shrimati / Kumari | C8: ='BOM 04 22Master'!#REF! -> #REF!
A9: whose particulars are given in the statement below, hereby nominate the person(s) mentioned below to receive the gratuity payable after my death as also the gratuity standing to my credit in the event of my death before that amount has become payable, or having become payable has not been paid and direct that the said amount of gratuity shall be paid in proportion indicated against the name(s) of the nominee(s).
A11: 2. I hereby certify that the person(s) mentioned is a /are member(s) of my family within the meaning of clause (h) of Section 2 of the Payment of Gratuity Act, 1972.
A13: 3. I hereby declare that I have no family within the meaning of clause (h) of Section 2 of the said Act.
A15: 4. (a) My father/mother/parents is/are not dependent on me
A16: (b) My husband’s father/mother/parents is/are not dependent on my husband.
A18: 5. I have excluded my husband from my family by a notice dated the ……………. to the Controlling Authority in terms of the proviso to clause (h) of Section 2 of the said Act.
A20: 6. Nomination made herein invalidates my previous nomination.
A22: NOMINEE(S)
A23: Name in full with full address of nominee(s): | B23: Relationship with the empliyee | C23: Age of nominee: | D23: Proportion by which the gratuity will be shared:
A24: 1 | B24: 2 | C24: 3 | D24: 4
A25: ='BOM 04 22Master'!#REF! -> #REF! | B25: Father | C25: 54 Years | D25: 1
A29: STATEMENT
A31: 1. Name of employee in full: | C31: ='BOM 04 22Master'!#REF! -> #REF!
A32: 2. Sex: | C32: ='BOM 04 22Master'!#REF! -> #REF!
A33: 3. Religion: | C33: Muslim
A34: 4. Whether unmarried/married/widow/widower: | C34: Un married
A35: 5. Department/Branch/Section where employed: | C35: ='BOM 04 22Master'!#REF! -> #REF!
A36: 6. Post held with Ticket No. or Serial No. if any: | C36: ='BOM 04 22Master'!#REF! -> #REF!
A37: 7. Date of appointment: | C37: ='BOM 04 22Master'!#REF! -> #REF!
A38: 8. Permanent address:
C39: ='BOM 04 22Master'!#REF! -> #REF!
C40: ='BOM 04 22Master'!#REF! -> #REF!
C41: ='BOM 04 22Master'!#REF! -> #REF!
A42: Place: | B42: Hyderabad
A43: Date: | B43: ='BOM 04 22Master'!#REF! -> #REF! | C43: Signature/Thumb impression of the employee
A45: Declaration by witnesses:
A46: Nomination signed/thumb impressed before me:
A48: Name in full and full address of witnesses: | C48: Signature of witnesses:
A49: 1 | C49: 1
A50: 2 | C50: 2
C51: Certificate by the Employer
A52: Certified that the particulars of the above nomination have been verified and recorded in t his establishment
A53: Employer's reference No, if any
...

Sheet Sheet1
